ts_recv,ts_event,rtype,publisher_id,instrument_id,action,side,depth,price,size,flags,ts_in_delta,sequence,bid_px_00,ask_px_00,bid_sz_00,ask_sz_00,bid_ct_00,ask_ct_00,bid_px_01,ask_px_01,bid_sz_01,ask_sz_01,bid_ct_01,ask_ct_01,bid_px_02,ask_px_02,bid_sz_02,ask_sz_02,bid_ct_02,ask_ct_02,bid_px_03,ask_px_03,bid_sz_03,ask_sz_03,bid_ct_03,ask_ct_03,bid_px_04,ask_px_04,bid_sz_04,ask_sz_04,bid_ct_04,ask_ct_04,bid_px_05,ask_px_05,bid_sz_05,ask_sz_05,bid_ct_05,ask_ct_05,bid_px_06,ask_px_06,bid_sz_06,ask_sz_06,bid_ct_06,ask_ct_06,bid_px_07,ask_px_07,bid_sz_07,ask_sz_07,bid_ct_07,ask_ct_07,bid_px_08,ask_px_08,bid_sz_08,ask_sz_08,bid_ct_08,ask_ct_08,bid_px_09,ask_px_09,bid_sz_09,ask_sz_09,bid_ct_09,ask_ct_09,symbol
2025-01-03T10:30:00.058104540Z,2025-01-03T10:30:00.057938557Z,10,2,17709,C,A,1,107.940000000,17,130,165983,4825026,107.660000000,107.880000000,15,400,1,2,107.640000000,107.950000000,100,10,1,1,107.600000000,108.000000000,50,150,1,2,107.000000000,108.300000000,1,50,1,1,106.240000000,108.550000000,28,50,1,1,106.000000000,108.800000000,15,50,2,1,105.870000000,108.880000000,141,28,1,1,103.180000000,109.450000000,16,137,1,1,103.000000000,109.500000000,3,100,1,1,102.000000000,111.000000000,2,10,1,1,XOM
2025-01-03T10:30:00.058205915Z,2025-01-03T10:30:00.058039541Z,10,2,17709,A,A,2,107.960000000,16,130,166374,4825027,107.660000000,107.880000000,15,400,1,2,107.640000000,107.950000000,100,10,1,1,107.600000000,107.960000000,50,16,1,1,107.000000000,108.000000000,1,150,1,2,106.240000000,108.300000000,28,50,1,1,106.000000000,108.550000000,15,50,2,1,105.870000000,108.800000000,141,50,1,1,103.180000000,108.880000000,16,28,1,1,103.000000000,109.450000000,3,137,1,1,102.000000000,109.500000000,2,100,1,1,XOM
2025-01-03T10:30:00.121104581Z,2025-01-03T10:30:00.120938407Z,10,2,6905,C,A,1,91.960000000,100,130,166174,4825418,91.520000000,91.930000000,7,7,1,1,91.480000000,93.000000000,150,1,1,1,91.440000000,94.000000000,100,1,1,1,90.000000000,95.000000000,122,2,1,2,89.000000000,96.000000000,1,1,1,1,83.810000000,97.000000000,100,2,1,2,83.400000000,99.950000000,100,100,1,1,,100.360000000,0,100,0,1,,,0,0,0,0,,,0,0,0,0,GILD
2025-01-03T10:30:00.121118315Z,2025-01-03T10:30:00.120951956Z,10,2,6905,A,A,1,92.040000000,100,130,166359,4825419,91.520000000,91.930000000,7,7,1,1,91.480000000,92.040000000,150,100,1,1,91.440000000,93.000000000,100,1,1,1,90.000000000,94.000000000,122,1,1,1,89.000000000,95.000000000,1,2,1,2,83.810000000,96.000000000,100,1,1,1,83.400000000,97.000000000,100,2,1,2,,99.950000000,0,100,0,1,,100.360000000,0,100,0,1,,,0,0,0,0,GILD
2025-01-03T10:30:00.122933807Z,2025-01-03T10:30:00.122767682Z,10,2,6905,C,A,0,91.930000000,7,130,166125,4825429,91.520000000,92.040000000,7,100,1,1,91.480000000,93.000000000,150,1,1,1,91.440000000,94.000000000,100,1,1,1,90.000000000,95.000000000,122,2,1,2,89.000000000,96.000000000,1,1,1,1,83.810000000,97.000000000,100,2,1,2,83.400000000,99.950000000,100,100,1,1,,100.360000000,0,100,0,1,,,0,0,0,0,,,0,0,0,0,GILD
2025-01-03T10:30:00.122997978Z,2025-01-03T10:30:00.122831666Z,10,2,6905,A,A,0,91.940000000,7,130,166312,4825431,91.520000000,91.940000000,7,7,1,1,91.480000000,92.040000000,150,100,1,1,91.440000000,93.000000000,100,1,1,1,90.000000000,94.000000000,122,1,1,1,89.000000000,95.000000000,1,2,1,2,83.810000000,96.000000000,100,1,1,1,83.400000000,97.000000000,100,2,1,2,,99.950000000,0,100,0,1,,100.360000000,0,100,0,1,,,0,0,0,0,GILD
2025-01-03T10:30:00.132223106Z,2025-01-03T10:30:00.132057097Z,10,2,6905,C,B,0,91.520000000,7,130,166009,4825461,91.480000000,91.940000000,150,7,1,1,91.440000000,92.040000000,100,100,1,1,90.000000000,93.000000000,122,1,1,1,89.000000000,94.000000000,1,1,1,1,83.810000000,95.000000000,100,2,1,2,83.400000000,96.000000000,100,1,1,1,,97.000000000,0,2,0,2,,99.950000000,0,100,0,1,,100.360000000,0,100,0,1,,,0,0,0,0,GILD
2025-01-03T10:30:00.132284264Z,2025-01-03T10:30:00.132117518Z,10,2,6905,A,B,2,91.430000000,7,130,166746,4825462,91.480000000,91.940000000,150,7,1,1,91.440000000,92.040000000,100,100,1,1,91.430000000,93.000000000,7,1,1,1,90.000000000,94.000000000,122,1,1,1,89.000000000,95.000000000,1,2,1,2,83.810000000,96.000000000,100,1,1,1,83.400000000,97.000000000,100,2,1,2,,99.950000000,0,100,0,1,,100.360000000,0,100,0,1,,,0,0,0,0,GILD
2025-01-03T10:30:00.158721091Z,2025-01-03T10:30:00.158555208Z,10,2,17709,C,B,0,107.660000000,15,130,165883,4825555,107.640000000,107.880000000,100,400,1,2,107.600000000,107.950000000,50,10,1,1,107.000000000,107.960000000,1,16,1,1,106.240000000,108.000000000,28,150,1,2,106.000000000,108.300000000,15,50,2,1,105.870000000,108.550000000,141,50,1,1,103.180000000,108.800000000,16,50,1,1,103.000000000,108.880000000,3,28,1,1,102.000000000,109.450000000,2,137,1,1,101.000000000,109.500000000,1,100,1,1,XOM
2025-01-03T10:30:00.158779618Z,2025-01-03T10:30:00.158613120Z,10,2,17709,A,B,0,107.680000000,16,130,166498,4825556,107.680000000,107.880000000,16,400,1,2,107.640000000,107.950000000,100,10,1,1,107.600000000,107.960000000,50,16,1,1,107.000000000,108.000000000,1,150,1,2,106.240000000,108.300000000,28,50,1,1,106.000000000,108.550000000,15,50,2,1,105.870000000,108.800000000,141,50,1,1,103.180000000,108.880000000,16,28,1,1,103.000000000,109.450000000,3,137,1,1,102.000000000,109.500000000,2,100,1,1,XOM
2025-01-03T10:30:00.180719955Z,2025-01-03T10:30:00.180553822Z,10,2,6905,A,A,1,92.000000000,100,130,166133,4825768,91.480000000,91.940000000,150,7,1,1,91.440000000,92.000000000,100,100,1,1,91.430000000,93.000000000,7,1,1,1,90.000000000,94.000000000,122,1,1,1,89.000000000,95.000000000,1,2,1,2,83.810000000,96.000000000,100,1,1,1,83.400000000,97.000000000,100,2,1,2,,99.950000000,0,100,0,1,,100.360000000,0,100,0,1,,,0,0,0,0,GILD
2025-01-03T10:30:00.230342154Z,2025-01-03T10:30:00.230176242Z,10,2,17709,C,B,0,107.680000000,16,130,165912,4825928,107.640000000,107.880000000,100,400,1,2,107.600000000,107.950000000,50,10,1,1,107.000000000,107.960000000,1,16,1,1,106.240000000,108.000000000,28,150,1,2,106.000000000,108.300000000,15,50,2,1,105.870000000,108.550000000,141,50,1,1,103.180000000,108.800000000,16,50,1,1,103.000000000,108.880000000,3,28,1,1,102.000000000,109.450000000,2,137,1,1,101.000000000,109.500000000,1,100,1,1,XOM
2025-01-03T10:30:00.269689882Z,2025-01-03T10:30:00.269523481Z,10,2,9155,A,A,1,242.460000000,8,130,166401,4826017,242.020000000,242.400000000,120,485,1,1,242.000000000,242.460000000,200,8,1,1,241.670000000,242.500000000,2,8,1,1,241.000000000,242.850000000,100,300,1,2,240.000000000,242.900000000,10,100,1,1,238.000000000,243.000000000,30,92,1,2,236.000000000,243.310000000,6,10,1,1,235.500000000,243.700000000,5,100,1,1,235.000000000,246.810000000,5,100,1,1,232.880000000,262.740000000,1,100,1,1,JPM
2025-01-03T10:30:00.269723921Z,2025-01-03T10:30:00.269557924Z,10,2,9155,C,A,2,242.500000000,8,130,165997,4826018,242.020000000,242.400000000,120,485,1,1,242.000000000,242.460000000,200,8,1,1,241.670000000,242.850000000,2,300,1,2,241.000000000,242.900000000,100,100,1,1,240.000000000,243.000000000,10,92,1,2,238.000000000,243.310000000,30,10,1,1,236.000000000,243.700000000,6,100,1,1,235.500000000,246.810000000,5,100,1,1,235.000000000,262.740000000,5,100,1,1,232.880000000,263.830000000,1,100,1,1,JPM
2025-01-03T10:30:00.533926749Z,2025-01-03T10:30:00.533760395Z,10,2,10888,C,B,0,420.730000000,200,130,166354,4826450,420.620000000,421.250000000,15,200,1,1,420.580000000,421.310000000,10,13,1,1,420.520000000,421.490000000,1,6,1,1,420.400000000,421.570000000,858,40,1,1,420.380000000,421.600000000,100,10,1,1,420.100000000,421.700000000,100,359,1,1,420.000000000,422.100000000,534,7,7,1,419.730000000,422.400000000,3,500,1,1,418.650000000,422.500000000,1,200,1,1,418.500000000,423.500000000,1,600,1,2,MSFT
2025-01-03T10:30:00.533940017Z,2025-01-03T10:30:00.533773233Z,10,2,10888,A,B,0,420.690000000,200,130,166784,4826451,420.690000000,421.250000000,200,200,1,1,420.620000000,421.310000000,15,13,1,1,420.580000000,421.490000000,10,6,1,1,420.520000000,421.570000000,1,40,1,1,420.400000000,421.600000000,858,10,1,1,420.380000000,421.700000000,100,359,1,1,420.100000000,422.100000000,100,7,1,1,420.000000000,422.400000000,534,500,7,1,419.730000000,422.500000000,3,200,1,1,418.650000000,423.500000000,1,600,1,2,MSFT
2025-01-03T10:30:00.534044225Z,2025-01-03T10:30:00.533878528Z,10,2,10888,C,B,0,420.690000000,200,130,165697,4826452,420.620000000,421.250000000,15,200,1,1,420.580000000,421.310000000,10,13,1,1,420.520000000,421.490000000,1,6,1,1,420.400000000,421.570000000,858,40,1,1,420.380000000,421.600000000,100,10,1,1,420.100000000,421.700000000,100,359,1,1,420.000000000,422.100000000,534,7,7,1,419.730000000,422.400000000,3,500,1,1,418.650000000,422.500000000,1,200,1,1,418.500000000,423.500000000,1,600,1,2,MSFT
2025-01-03T10:30:00.534056838Z,2025-01-03T10:30:00.533890197Z,10,2,10888,A,B,0,420.660000000,200,130,166641,4826453,420.660000000,421.250000000,200,200,1,1,420.620000000,421.310000000,15,13,1,1,420.580000000,421.490000000,10,6,1,1,420.520000000,421.570000000,1,40,1,1,420.400000000,421.600000000,858,10,1,1,420.380000000,421.700000000,100,359,1,1,420.100000000,422.100000000,100,7,1,1,420.000000000,422.400000000,534,500,7,1,419.730000000,422.500000000,3,200,1,1,418.650000000,423.500000000,1,600,1,2,MSFT
2025-01-03T10:30:00.865950028Z,2025-01-03T10:30:00.865781973Z,10,2,10888,C,B,0,420.660000000,200,130,168055,4826632,420.620000000,421.250000000,15,200,1,1,420.580000000,421.310000000,10,13,1,1,420.520000000,421.490000000,1,6,1,1,420.400000000,421.570000000,858,40,1,1,420.380000000,421.600000000,100,10,1,1,420.100000000,421.700000000,100,359,1,1,420.000000000,422.100000000,534,7,7,1,419.730000000,422.400000000,3,500,1,1,418.650000000,422.500000000,1,200,1,1,418.500000000,423.500000000,1,600,1,2,MSFT
2025-01-03T10:30:00.946403704Z,2025-01-03T10:30:00.946237498Z,10,2,17709,A,B,0,107.750000000,8,130,166206,4826678,107.750000000,107.880000000,8,400,1,2,107.640000000,107.950000000,100,10,1,1,107.600000000,107.960000000,50,16,1,1,107.000000000,108.000000000,1,150,1,2,106.240000000,108.300000000,28,50,1,1,106.000000000,108.550000000,15,50,2,1,105.870000000,108.800000000,141,50,1,1,103.180000000,108.880000000,16,28,1,1,103.000000000,109.450000000,3,137,1,1,102.000000000,109.500000000,2,100,1,1,XOM
2025-01-03T10:30:00.959794652Z,2025-01-03T10:30:00.959628354Z,10,2,17709,C,B,0,107.750000000,8,130,166298,4826683,107.640000000,107.880000000,100,400,1,2,107.600000000,107.950000000,50,10,1,1,107.000000000,107.960000000,1,16,1,1,106.240000000,108.000000000,28,150,1,2,106.000000000,108.300000000,15,50,2,1,105.870000000,108.550000000,141,50,1,1,103.180000000,108.800000000,16,50,1,1,103.000000000,108.880000000,3,28,1,1,102.000000000,109.450000000,2,137,1,1,101.000000000,109.500000000,1,100,1,1,XOM
2025-01-03T10:30:00.969167202Z,2025-01-03T10:30:00.969000949Z,10,2,10888,A,B,0,420.660000000,200,130,166253,4826697,420.660000000,421.250000000,200,200,1,1,420.620000000,421.310000000,15,13,1,1,420.580000000,421.490000000,10,6,1,1,420.520000000,421.570000000,1,40,1,1,420.400000000,421.600000000,858,10,1,1,420.380000000,421.700000000,100,359,1,1,420.100000000,422.100000000,100,7,1,1,420.000000000,422.400000000,534,500,7,1,419.730000000,422.500000000,3,200,1,1,418.650000000,423.500000000,1,600,1,2,MSFT
2025-01-03T10:30:00.979419532Z,2025-01-03T10:30:00.979253371Z,10,2,16727,C,B,1,314.860000000,25,130,166161,4826702,314.920000000,315.450000000,8,8,1,1,313.500000000,315.510000000,1,25,1,1,310.000000000,320.000000000,1,5,1,1,300.000000000,320.210000000,3,1,1,1,290.000000000,321.950000000,2,2,1,1,286.660000000,344.200000000,100,100,1,1,285.250000000,345.620000000,100,100,1,1,260.000000000,,2,0,1,0,,,0,0,0,0,,,0,0,0,0,V
2025-01-03T10:30:00.997100447Z,2025-01-03T10:30:00.996932833Z,10,2,16244,T,B,0,382.790000000,80,130,167614,4826704,382.710000000,382.790000000,10,80,1,1,382.680000000,382.920000000,41,50,2,1,382.230000000,382.990000000,25,1,1,1,382.110000000,383.000000000,300,31,1,2,382.100000000,383.020000000,20,20,2,1,382.010000000,383.080000000,2,1,1,1,382.000000000,383.090000000,1192,6,10,1,381.900000000,383.100000000,23,12,1,2,381.880000000,383.200000000,10,1000,1,2,381.800000000,383.300000000,12,120,1,3,TSLA
2025-01-03T10:30:00.997100447Z,2025-01-03T10:30:00.996932833Z,10,2,16244,C,A,0,382.790000000,80,130,167614,4826704,382.710000000,382.920000000,10,50,1,1,382.680000000,382.990000000,41,1,2,1,382.230000000,383.000000000,25,31,1,2,382.110000000,383.020000000,300,20,1,1,382.100000000,383.080000000,20,1,2,1,382.010000000,383.090000000,2,6,1,1,382.000000000,383.100000000,1192,12,10,2,381.900000000,383.200000000,23,1000,1,2,381.880000000,383.300000000,10,120,1,3,381.800000000,383.420000000,12,140,1,1,TSLA
2025-01-03T10:30:00.997813206Z,2025-01-03T10:30:00.997647255Z,10,2,16244,C,A,7,383.200000000,500,130,165951,4826722,382.710000000,382.920000000,10,50,1,1,382.680000000,382.990000000,41,1,2,1,382.230000000,383.000000000,25,31,1,2,382.110000000,383.020000000,300,20,1,1,382.100000000,383.080000000,20,1,2,1,382.010000000,383.090000000,2,6,1,1,382.000000000,383.100000000,1192,12,10,2,381.900000000,383.200000000,23,500,1,1,381.880000000,383.300000000,10,120,1,3,381.800000000,383.420000000,12,140,1,1,TSLA
2025-01-03T10:30:01.000922555Z,2025-01-03T10:30:01.000756632Z,10,2,16244,C,A,3,383.020000000,20,130,165923,4826735,382.710000000,382.920000000,10,50,1,1,382.680000000,382.990000000,41,1,2,1,382.230000000,383.000000000,25,31,1,2,382.110000000,383.080000000,300,1,1,1,382.100000000,383.090000000,20,6,2,1,382.010000000,383.100000000,2,12,1,2,382.000000000,383.200000000,1192,500,10,1,381.900000000,383.300000000,23,120,1,3,381.880000000,383.420000000,10,140,1,1,381.800000000,383.600000000,12,1000,1,2,TSLA
2025-01-03T10:30:01.001016501Z,2025-01-03T10:30:01.000850309Z,10,2,16244,A,A,3,383.070000000,21,130,166192,4826736,382.710000000,382.920000000,10,50,1,1,382.680000000,382.990000000,41,1,2,1,382.230000000,383.000000000,25,31,1,2,382.110000000,383.070000000,300,21,1,1,382.100000000,383.080000000,20,1,2,1,382.010000000,383.090000000,2,6,1,1,382.000000000,383.100000000,1192,12,10,2,381.900000000,383.200000000,23,500,1,1,381.880000000,383.300000000,10,120,1,3,381.800000000,383.420000000,12,140,1,1,TSLA
2025-01-03T10:30:01.001613457Z,2025-01-03T10:30:01.001447228Z,10,2,16244,C,A,3,383.070000000,21,130,166229,4826737,382.710000000,382.920000000,10,50,1,1,382.680000000,382.990000000,41,1,2,1,382.230000000,383.000000000,25,31,1,2,382.110000000,383.080000000,300,1,1,1,382.100000000,383.090000000,20,6,2,1,382.010000000,383.100000000,2,12,1,2,382.000000000,383.200000000,1192,500,10,1,381.900000000,383.300000000,23,120,1,3,381.880000000,383.420000000,10,140,1,1,381.800000000,383.600000000,12,1000,1,2,TSLA
2025-01-03T10:30:01.009117027Z,2025-01-03T10:30:01.008951262Z,10,2,17709,C,A,2,107.960000000,16,130,165765,4826743,107.640000000,107.880000000,100,400,1,2,107.600000000,107.950000000,50,10,1,1,107.000000000,108.000000000,1,150,1,2,106.240000000,108.300000000,28,50,1,1,106.000000000,108.550000000,15,50,2,1,105.870000000,108.800000000,141,50,1,1,103.180000000,108.880000000,16,28,1,1,103.000000000,109.450000000,3,137,1,1,102.000000000,109.500000000,2,100,1,1,101.000000000,111.000000000,1,10,1,1,XOM
2025-01-03T10:30:01.009205035Z,2025-01-03T10:30:01.009038910Z,10,2,17709,A,B,0,107.660000000,16,130,166125,4826744,107.660000000,107.880000000,16,400,1,2,107.640000000,107.950000000,100,10,1,1,107.600000000,108.000000000,50,150,1,2,107.000000000,108.300000000,1,50,1,1,106.240000000,108.550000000,28,50,1,1,106.000000000,108.800000000,15,50,2,1,105.870000000,108.880000000,141,28,1,1,103.180000000,109.450000000,16,137,1,1,103.000000000,109.500000000,3,100,1,1,102.000000000,111.000000000,2,10,1,1,XOM
2025-01-03T10:30:01.009259392Z,2025-01-03T10:30:01.009092878Z,10,2,17709,A,A,1,107.940000000,15,130,166514,4826745,107.660000000,107.880000000,16,400,1,2,107.640000000,107.940000000,100,15,1,1,107.600000000,107.950000000,50,10,1,1,107.000000000,108.000000000,1,150,1,2,106.240000000,108.300000000,28,50,1,1,106.000000000,108.550000000,15,50,2,1,105.870000000,108.800000000,141,50,1,1,103.180000000,108.880000000,16,28,1,1,103.000000000,109.450000000,3,137,1,1,102.000000000,109.500000000,2,100,1,1,XOM
2025-01-03T10:30:01.017374349Z,2025-01-03T10:30:01.017208582Z,10,2,17709,C,B,0,107.660000000,16,130,165767,4826757,107.640000000,107.880000000,100,400,1,2,107.600000000,107.940000000,50,15,1,1,107.000000000,107.950000000,1,10,1,1,106.240000000,108.000000000,28,150,1,2,106.000000000,108.300000000,15,50,2,1,105.870000000,108.550000000,141,50,1,1,103.180000000,108.800000000,16,50,1,1,103.000000000,108.880000000,3,28,1,1,102.000000000,109.450000000,2,137,1,1,101.000000000,109.500000000,1,100,1,1,XOM
2025-01-03T10:30:01.025224499Z,2025-01-03T10:30:01.025057247Z,10,2,9155,T,N,0,242.080000000,11,130,167252,4826762,242.020000000,242.400000000,120,485,1,1,242.000000000,242.460000000,200,8,1,1,241.670000000,242.850000000,2,300,1,2,241.000000000,242.900000000,100,100,1,1,240.000000000,243.000000000,10,92,1,2,238.000000000,243.310000000,30,10,1,1,236.000000000,243.700000000,6,100,1,1,235.500000000,246.810000000,5,100,1,1,235.000000000,262.740000000,5,100,1,1,232.880000000,263.830000000,1,100,1,1,JPM
2025-01-03T10:30:01.025248906Z,2025-01-03T10:30:01.025082524Z,10,2,9155,A,A,0,242.240000000,1,130,166382,4826763,242.020000000,242.240000000,120,1,1,1,242.000000000,242.400000000,200,485,1,1,241.670000000,242.460000000,2,8,1,1,241.000000000,242.850000000,100,300,1,2,240.000000000,242.900000000,10,100,1,1,238.000000000,243.000000000,30,92,1,2,236.000000000,243.310000000,6,10,1,1,235.500000000,243.700000000,5,100,1,1,235.000000000,246.810000000,5,100,1,1,232.880000000,262.740000000,1,100,1,1,JPM
2025-01-03T10:30:01.027152499Z,2025-01-03T10:30:01.026986621Z,10,2,9155,C,A,0,242.240000000,1,130,165878,4826764,242.020000000,242.400000000,120,485,1,1,242.000000000,242.460000000,200,8,1,1,241.670000000,242.850000000,2,300,1,2,241.000000000,242.900000000,100,100,1,1,240.000000000,243.000000000,10,92,1,2,238.000000000,243.310000000,30,10,1,1,236.000000000,243.700000000,6,100,1,1,235.500000000,246.810000000,5,100,1,1,235.000000000,262.740000000,5,100,1,1,232.880000000,263.830000000,1,100,1,1,JPM
2025-01-03T10:30:01.031226209Z,2025-01-03T10:30:01.031059483Z,10,2,17709,C,B,0,107.640000000,100,130,166726,4826770,107.600000000,107.880000000,50,400,1,2,107.000000000,107.940000000,1,15,1,1,106.240000000,107.950000000,28,10,1,1,106.000000000,108.000000000,15,150,2,2,105.870000000,108.300000000,141,50,1,1,103.180000000,108.550000000,16,50,1,1,103.000000000,108.800000000,3,50,1,1,102.000000000,108.880000000,2,28,1,1,101.000000000,109.450000000,1,137,1,1,100.880000000,109.500000000,36,100,1,1,XOM
2025-01-03T10:30:01.031237547Z,2025-01-03T10:30:01.031071265Z,10,2,17709,A,B,1,107.580000000,100,130,166282,4826771,107.600000000,107.880000000,50,400,1,2,107.580000000,107.940000000,100,15,1,1,107.000000000,107.950000000,1,10,1,1,106.240000000,108.000000000,28,150,1,2,106.000000000,108.300000000,15,50,2,1,105.870000000,108.550000000,141,50,1,1,103.180000000,108.800000000,16,50,1,1,103.000000000,108.880000000,3,28,1,1,102.000000000,109.450000000,2,137,1,1,101.000000000,109.500000000,1,100,1,1,XOM
2025-01-03T10:30:01.060504291Z,2025-01-03T10:30:01.060337835Z,10,2,16727,A,B,1,314.860000000,25,130,166456,4826799,314.920000000,315.450000000,8,8,1,1,314.860000000,315.510000000,25,25,1,1,313.500000000,320.000000000,1,5,1,1,310.000000000,320.210000000,1,1,1,1,300.000000000,321.950000000,3,2,1,1,290.000000000,344.200000000,2,100,1,1,286.660000000,345.620000000,100,100,1,1,285.250000000,,100,0,1,0,260.000000000,,2,0,1,0,,,0,0,0,0,V
2025-01-03T10:30:01.063205533Z,2025-01-03T10:30:01.063039541Z,10,2,10888,C,B,0,420.660000000,200,130,165992,4826800,420.620000000,421.250000000,15,200,1,1,420.580000000,421.310000000,10,13,1,1,420.520000000,421.490000000,1,6,1,1,420.400000000,421.570000000,858,40,1,1,420.380000000,421.600000000,100,10,1,1,420.100000000,421.700000000,100,359,1,1,420.000000000,422.100000000,534,7,7,1,419.730000000,422.400000000,3,500,1,1,418.650000000,422.500000000,1,200,1,1,418.500000000,423.500000000,1,600,1,2,MSFT
2025-01-03T10:30:01.063218996Z,2025-01-03T10:30:01.063052838Z,10,2,10888,A,B,0,420.630000000,200,130,166158,4826801,420.630000000,421.250000000,200,200,1,1,420.620000000,421.310000000,15,13,1,1,420.580000000,421.490000000,10,6,1,1,420.520000000,421.570000000,1,40,1,1,420.400000000,421.600000000,858,10,1,1,420.380000000,421.700000000,100,359,1,1,420.100000000,422.100000000,100,7,1,1,420.000000000,422.400000000,534,500,7,1,419.730000000,422.500000000,3,200,1,1,418.650000000,423.500000000,1,600,1,2,MSFT
2025-01-03T10:30:01.064837234Z,2025-01-03T10:30:01.064670955Z,10,2,16244,A,B,0,382.720000000,20,130,166279,4826802,382.720000000,382.920000000,20,50,1,1,382.710000000,382.990000000,10,1,1,1,382.680000000,383.000000000,41,31,2,2,382.230000000,383.080000000,25,1,1,1,382.110000000,383.090000000,300,6,1,1,382.100000000,383.100000000,20,12,2,2,382.010000000,383.200000000,2,500,1,1,382.000000000,383.300000000,1192,120,10,3,381.900000000,383.420000000,23,140,1,1,381.880000000,383.600000000,10,1000,1,2,TSLA
2025-01-03T10:30:01.187098715Z,2025-01-03T10:30:01.186932810Z,10,2,16727,C,B,1,314.860000000,25,130,165905,4826938,314.920000000,315.450000000,8,8,1,1,313.500000000,315.510000000,1,25,1,1,310.000000000,320.000000000,1,5,1,1,300.000000000,320.210000000,3,1,1,1,290.000000000,321.950000000,2,2,1,1,286.660000000,344.200000000,100,100,1,1,285.250000000,345.620000000,100,100,1,1,260.000000000,,2,0,1,0,,,0,0,0,0,,,0,0,0,0,V
2025-01-03T10:30:01.199204709Z,2025-01-03T10:30:01.199038225Z,10,2,10888,A,B,0,420.640000000,200,130,166484,4826942,420.640000000,421.250000000,200,200,1,1,420.620000000,421.310000000,15,13,1,1,420.580000000,421.490000000,10,6,1,1,420.520000000,421.570000000,1,40,1,1,420.400000000,421.600000000,858,10,1,1,420.380000000,421.700000000,100,359,1,1,420.100000000,422.100000000,100,7,1,1,420.000000000,422.400000000,534,500,7,1,419.730000000,422.500000000,3,200,1,1,418.650000000,423.500000000,1,600,1,2,MSFT
2025-01-03T10:30:01.212033457Z,2025-01-03T10:30:01.211866764Z,10,2,780,A,A,0,261.800000000,25,130,166693,4826949,259.930000000,261.800000000,25,25,1,1,259.010000000,270.990000000,181,203,2,2,258.100000000,294.170000000,25,100,1,1,257.700000000,295.390000000,1,100,1,1,250.000000000,,13,0,2,0,236.860000000,,100,0,1,0,235.690000000,,100,0,1,0,,,0,0,0,0,,,0,0,0,0,,,0,0,0,0,AMGN
2025-01-03T10:30:01.220422215Z,2025-01-03T10:30:01.220255099Z,10,2,9155,T,N,0,242.040000000,11,130,167116,4826967,242.020000000,242.400000000,120,485,1,1,242.000000000,242.460000000,200,8,1,1,241.670000000,242.850000000,2,300,1,2,241.000000000,242.900000000,100,100,1,1,240.000000000,243.000000000,10,92,1,2,238.000000000,243.310000000,30,10,1,1,236.000000000,243.700000000,6,100,1,1,235.500000000,246.810000000,5,100,1,1,235.000000000,262.740000000,5,100,1,1,232.880000000,263.830000000,1,100,1,1,JPM
2025-01-03T10:30:01.220444395Z,2025-01-03T10:30:01.220278337Z,10,2,9155,A,A,0,242.220000000,1,130,166058,4826968,242.020000000,242.220000000,120,1,1,1,242.000000000,242.400000000,200,485,1,1,241.670000000,242.460000000,2,8,1,1,241.000000000,242.850000000,100,300,1,2,240.000000000,242.900000000,10,100,1,1,238.000000000,243.000000000,30,92,1,2,236.000000000,243.310000000,6,10,1,1,235.500000000,243.700000000,5,100,1,1,235.000000000,246.810000000,5,100,1,1,232.880000000,262.740000000,1,100,1,1,JPM
2025-01-03T10:30:01.221159676Z,2025-01-03T10:30:01.220993467Z,10,2,9155,A,A,1,242.240000000,1,130,166209,4826969,242.020000000,242.220000000,120,1,1,1,242.000000000,242.240000000,200,1,1,1,241.670000000,242.400000000,2,485,1,1,241.000000000,242.460000000,100,8,1,1,240.000000000,242.850000000,10,300,1,2,238.000000000,242.900000000,30,100,1,1,236.000000000,243.000000000,6,92,1,2,235.500000000,243.310000000,5,10,1,1,235.000000000,243.700000000,5,100,1,1,232.880000000,246.810000000,1,100,1,1,JPM
2025-01-03T10:30:01.221173366Z,2025-01-03T10:30:01.221007139Z,10,2,9155,A,A,2,242.390000000,1,130,166227,4826970,242.020000000,242.220000000,120,1,1,1,242.000000000,242.240000000,200,1,1,1,241.670000000,242.390000000,2,1,1,1,241.000000000,242.400000000,100,485,1,1,240.000000000,242.460000000,10,8,1,1,238.000000000,242.850000000,30,300,1,2,236.000000000,242.900000000,6,100,1,1,235.500000000,243.000000000,5,92,1,2,235.000000000,243.310000000,5,10,1,1,232.880000000,243.700000000,1,100,1,1,JPM
2025-01-03T10:30:01.227152392Z,2025-01-03T10:30:01.226986614Z,10,2,9155,C,A,0,242.220000000,1,130,165778,4826978,242.020000000,242.240000000,120,1,1,1,242.000000000,242.390000000,200,1,1,1,241.670000000,242.400000000,2,485,1,1,241.000000000,242.460000000,100,8,1,1,240.000000000,242.850000000,10,300,1,2,238.000000000,242.900000000,30,100,1,1,236.000000000,243.000000000,6,92,1,2,235.500000000,243.310000000,5,10,1,1,235.000000000,243.700000000,5,100,1,1,232.880000000,246.810000000,1,100,1,1,JPM
2025-01-03T10:30:01.239733490Z,2025-01-03T10:30:01.239567766Z,10,2,9155,C,A,0,242.240000000,1,130,165724,4826986,242.020000000,242.390000000,120,1,1,1,242.000000000,242.400000000,200,485,1,1,241.670000000,242.460000000,2,8,1,1,241.000000000,242.850000000,100,300,1,2,240.000000000,242.900000000,10,100,1,1,238.000000000,243.000000000,30,92,1,2,236.000000000,243.310000000,6,10,1,1,235.500000000,243.700000000,5,100,1,1,235.000000000,246.810000000,5,100,1,1,232.880000000,262.740000000,1,100,1,1,JPM
2025-01-03T10:30:01.249528126Z,2025-01-03T10:30:01.249360785Z,10,2,16244,C,B,0,382.720000000,20,130,167341,4827021,382.710000000,382.920000000,10,50,1,1,382.680000000,382.990000000,41,1,2,1,382.230000000,383.000000000,25,31,1,2,382.110000000,383.080000000,300,1,1,1,382.100000000,383.090000000,20,6,2,1,382.010000000,383.100000000,2,12,1,2,382.000000000,383.200000000,1192,500,10,1,381.900000000,383.300000000,23,120,1,3,381.880000000,383.420000000,10,140,1,1,381.800000000,383.600000000,12,1000,1,2,TSLA
2025-01-03T10:30:01.279735190Z,2025-01-03T10:30:01.279569245Z,10,2,9155,C,A,0,242.390000000,1,130,165945,4827091,242.020000000,242.400000000,120,485,1,1,242.000000000,242.460000000,200,8,1,1,241.670000000,242.850000000,2,300,1,2,241.000000000,242.900000000,100,100,1,1,240.000000000,243.000000000,10,92,1,2,238.000000000,243.310000000,30,10,1,1,236.000000000,243.700000000,6,100,1,1,235.500000000,246.810000000,5,100,1,1,235.000000000,262.740000000,5,100,1,1,232.880000000,263.830000000,1,100,1,1,JPM
2025-01-03T10:30:01.284554278Z,2025-01-03T10:30:01.284387942Z,10,2,16727,A,B,1,314.860000000,25,130,166336,4827095,314.920000000,315.450000000,8,8,1,1,314.860000000,315.510000000,25,25,1,1,313.500000000,320.000000000,1,5,1,1,310.000000000,320.210000000,1,1,1,1,300.000000000,321.950000000,3,2,1,1,290.000000000,344.200000000,2,100,1,1,286.660000000,345.620000000,100,100,1,1,285.250000000,,100,0,1,0,260.000000000,,2,0,1,0,,,0,0,0,0,V
2025-01-03T10:30:01.460567234Z,2025-01-03T10:30:01.460399550Z,10,2,11667,T,A,0,139.160000000,72,130,167684,4827291,139.160000000,139.200000000,100,129,1,1,139.150000000,139.210000000,100,800,1,2,139.120000000,139.220000000,30,10,1,1,139.110000000,139.230000000,1,125,1,2,139.090000000,139.250000000,400,1,1,1,139.080000000,139.270000000,57,17,1,1,139.030000000,139.300000000,126,507,2,4,139.010000000,139.320000000,100,39,1,1,139.000000000,139.330000000,1420,503,6,2,138.980000000,139.360000000,300,4,1,2,NVDA
2025-01-03T10:30:01.460567234Z,2025-01-03T10:30:01.460399550Z,10,2,11667,C,B,0,139.160000000,72,130,167684,4827291,139.160000000,139.200000000,28,129,1,1,139.150000000,139.210000000,100,800,1,2,139.120000000,139.220000000,30,10,1,1,139.110000000,139.230000000,1,125,1,2,139.090000000,139.250000000,400,1,1,1,139.080000000,139.270000000,57,17,1,1,139.030000000,139.300000000,126,507,2,4,139.010000000,139.320000000,100,39,1,1,139.000000000,139.330000000,1420,503,6,2,138.980000000,139.360000000,300,4,1,2,NVDA
2025-01-03T10:30:01.460595712Z,2025-01-03T10:30:01.460430051Z,10,2,11667,C,B,4,139.090000000,400,130,165661,4827297,139.160000000,139.200000000,28,129,1,1,139.150000000,139.210000000,100,800,1,2,139.120000000,139.220000000,30,10,1,1,139.110000000,139.230000000,1,125,1,2,139.080000000,139.250000000,57,1,1,1,139.030000000,139.270000000,126,17,2,1,139.010000000,139.300000000,100,507,1,4,139.000000000,139.320000000,1420,39,6,1,138.980000000,139.330000000,300,503,1,2,138.970000000,139.360000000,800,4,2,2,NVDA
2025-01-03T10:30:01.460626146Z,2025-01-03T10:30:01.460458216Z,10,2,11667,T,A,0,139.160000000,28,128,167930,4827304,139.160000000,139.200000000,28,129,1,1,139.150000000,139.210000000,100,800,1,2,139.120000000,139.220000000,30,10,1,1,139.110000000,139.230000000,1,125,1,2,139.080000000,139.250000000,57,1,1,1,139.030000000,139.270000000,126,17,2,1,139.010000000,139.300000000,100,507,1,4,139.000000000,139.320000000,1420,39,6,1,138.980000000,139.330000000,300,503,1,2,138.970000000,139.360000000,800,4,2,2,NVDA
2025-01-03T10:30:01.460626146Z,2025-01-03T10:30:01.460458216Z,10,2,11667,C,B,0,139.160000000,28,128,167930,4827304,139.150000000,139.200000000,100,129,1,1,139.120000000,139.210000000,30,800,1,2,139.110000000,139.220000000,1,10,1,1,139.080000000,139.230000000,57,125,1,2,139.030000000,139.250000000,126,1,2,1,139.010000000,139.270000000,100,17,1,1,139.000000000,139.300000000,1420,507,6,4,138.980000000,139.320000000,300,39,1,1,138.970000000,139.330000000,800,503,2,2,138.940000000,139.360000000,400,4,1,2,NVDA
2025-01-03T10:30:01.460648679Z,2025-01-03T10:30:01.460482594Z,10,2,11667,A,A,0,139.190000000,35,130,166085,4827306,139.150000000,139.190000000,100,35,1,1,139.120000000,139.200000000,30,129,1,1,139.110000000,139.210000000,1,800,1,2,139.080000000,139.220000000,57,10,1,1,139.030000000,139.230000000,126,125,2,2,139.010000000,139.250000000,100,1,1,1,139.000000000,139.270000000,1420,17,6,1,138.980000000,139.300000000,300,507,1,4,138.970000000,139.320000000,800,39,2,1,138.940000000,139.330000000,400,503,1,2,NVDA
2025-01-03T10:30:01.460942630Z,2025-01-03T10:30:01.460776824Z,10,2,11667,C,B,6,139.000000000,1000,130,165806,4827310,139.150000000,139.190000000,100,35,1,1,139.120000000,139.200000000,30,129,1,1,139.110000000,139.210000000,1,800,1,2,139.080000000,139.220000000,57,10,1,1,139.030000000,139.230000000,126,125,2,2,139.010000000,139.250000000,100,1,1,1,139.000000000,139.270000000,420,17,5,1,138.980000000,139.300000000,300,507,1,4,138.970000000,139.320000000,800,39,2,1,138.940000000,139.330000000,400,503,1,2,NVDA
2025-01-03T10:30:01.460995357Z,2025-01-03T10:30:01.460829071Z,10,2,11667,A,A,0,139.180000000,100,130,166286,4827312,139.150000000,139.180000000,100,100,1,1,139.120000000,139.190000000,30,35,1,1,139.110000000,139.200000000,1,129,1,1,139.080000000,139.210000000,57,800,1,2,139.030000000,139.220000000,126,10,2,1,139.010000000,139.230000000,100,125,1,2,139.000000000,139.250000000,420,1,5,1,138.980000000,139.270000000,300,17,1,1,138.970000000,139.300000000,800,507,2,4,138.940000000,139.320000000,400,39,1,1,NVDA
2025-01-03T10:30:01.461491869Z,2025-01-03T10:30:01.461325134Z,10,2,11667,C,B,0,139.150000000,100,130,166735,4827332,139.120000000,139.180000000,30,100,1,1,139.110000000,139.190000000,1,35,1,1,139.080000000,139.200000000,57,129,1,1,139.030000000,139.210000000,126,800,2,2,139.010000000,139.220000000,100,10,1,1,139.000000000,139.230000000,420,125,5,2,138.980000000,139.250000000,300,1,1,1,138.970000000,139.270000000,800,17,2,1,138.940000000,139.300000000,400,507,1,4,138.920000000,139.320000000,10,39,1,1,NVDA
2025-01-03T10:30:01.461763886Z,2025-01-03T10:30:01.461597555Z,10,2,11667,A,A,5,139.230000000,100,130,166331,4827338,139.120000000,139.180000000,30,100,1,1,139.110000000,139.190000000,1,35,1,1,139.080000000,139.200000000,57,129,1,1,139.030000000,139.210000000,126,800,2,2,139.010000000,139.220000000,100,10,1,1,139.000000000,139.230000000,420,225,5,3,138.980000000,139.250000000,300,1,1,1,138.970000000,139.270000000,800,17,2,1,138.940000000,139.300000000,400,507,1,4,138.920000000,139.320000000,10,39,1,1,NVDA
2025-01-03T10:30:01.463173198Z,2025-01-03T10:30:01.463007016Z,10,2,11667,A,A,5,139.230000000,100,130,166182,4827366,139.120000000,139.180000000,30,100,1,1,139.110000000,139.190000000,1,35,1,1,139.080000000,139.200000000,57,129,1,1,139.030000000,139.210000000,126,800,2,2,139.010000000,139.220000000,100,10,1,1,139.000000000,139.230000000,420,325,5,4,138.980000000,139.250000000,300,1,1,1,138.970000000,139.270000000,800,17,2,1,138.940000000,139.300000000,400,507,1,4,138.920000000,139.320000000,10,39,1,1,NVDA
2025-01-03T10:30:01.472267418Z,2025-01-03T10:30:01.472101027Z,10,2,11667,C,A,1,139.190000000,35,130,166391,4827399,139.120000000,139.180000000,30,100,1,1,139.110000000,139.200000000,1,129,1,1,139.080000000,139.210000000,57,800,1,2,139.030000000,139.220000000,126,10,2,1,139.010000000,139.230000000,100,325,1,4,139.000000000,139.250000000,420,1,5,1,138.980000000,139.270000000,300,17,1,1,138.970000000,139.300000000,800,507,2,4,138.940000000,139.320000000,400,39,1,1,138.920000000,139.330000000,10,503,1,2,NVDA
2025-01-03T10:30:01.530680761Z,2025-01-03T10:30:01.530514884Z,10,2,11667,C,B,9,138.920000000,10,130,165877,4827483,139.120000000,139.180000000,30,100,1,1,139.110000000,139.200000000,1,129,1,1,139.080000000,139.210000000,57,800,1,2,139.030000000,139.220000000,126,10,2,1,139.010000000,139.230000000,100,325,1,4,139.000000000,139.250000000,420,1,5,1,138.980000000,139.270000000,300,17,1,1,138.970000000,139.300000000,800,507,2,4,138.940000000,139.320000000,400,39,1,1,138.900000000,139.330000000,541,503,4,2,NVDA
2025-01-03T10:30:01.531727145Z,2025-01-03T10:30:01.531560847Z,10,2,11667,A,B,4,139.020000000,400,130,166298,4827485,139.120000000,139.180000000,30,100,1,1,139.110000000,139.200000000,1,129,1,1,139.080000000,139.210000000,57,800,1,2,139.030000000,139.220000000,126,10,2,1,139.020000000,139.230000000,400,325,1,4,139.010000000,139.250000000,100,1,1,1,139.000000000,139.270000000,420,17,5,1,138.980000000,139.300000000,300,507,1,4,138.970000000,139.320000000,800,39,2,1,138.940000000,139.330000000,400,503,1,2,NVDA
2025-01-03T10:30:01.532493895Z,2025-01-03T10:30:01.532328259Z,10,2,11667,C,B,4,139.020000000,400,130,165636,4827491,139.120000000,139.180000000,30,100,1,1,139.110000000,139.200000000,1,129,1,1,139.080000000,139.210000000,57,800,1,2,139.030000000,139.220000000,126,10,2,1,139.010000000,139.230000000,100,325,1,4,139.000000000,139.250000000,420,1,5,1,138.980000000,139.270000000,300,17,1,1,138.970000000,139.300000000,800,507,2,4,138.940000000,139.320000000,400,39,1,1,138.900000000,139.330000000,541,503,4,2,NVDA
2025-01-03T10:30:01.571454102Z,2025-01-03T10:30:01.571287936Z,10,2,11667,A,B,5,139.000000000,400,130,166166,4827540,139.120000000,139.180000000,30,100,1,1,139.110000000,139.200000000,1,129,1,1,139.080000000,139.210000000,57,800,1,2,139.030000000,139.220000000,126,10,2,1,139.010000000,139.230000000,100,325,1,4,139.000000000,139.250000000,820,1,6,1,138.980000000,139.270000000,300,17,1,1,138.970000000,139.300000000,800,507,2,4,138.940000000,139.320000000,400,39,1,1,138.900000000,139.330000000,541,503,4,2,NVDA
2025-01-03T10:30:01.581459146Z,2025-01-03T10:30:01.581292140Z,10,2,11667,A,A,1,139.200000000,400,130,167006,4827546,139.120000000,139.180000000,30,100,1,1,139.110000000,139.200000000,1,529,1,2,139.080000000,139.210000000,57,400,1,1,139.030000000,139.220000000,126,10,2,1,139.010000000,139.230000000,100,325,1,4,139.000000000,139.250000000,820,1,6,1,138.980000000,139.270000000,300,17,1,1,138.970000000,139.300000000,800,507,2,4,138.940000000,139.320000000,400,39,1,1,138.900000000,139.330000000,541,503,4,2,NVDA
2025-01-03T10:30:01.591213453Z,2025-01-03T10:30:01.591047023Z,10,2,11667,A,A,0,139.180000000,400,130,166430,4827550,139.120000000,139.180000000,30,500,1,2,139.110000000,139.200000000,1,129,1,1,139.080000000,139.210000000,57,400,1,1,139.030000000,139.220000000,126,10,2,1,139.010000000,139.230000000,100,325,1,4,139.000000000,139.250000000,820,1,6,1,138.980000000,139.270000000,300,17,1,1,138.970000000,139.300000000,800,507,2,4,138.940000000,139.320000000,400,39,1,1,138.900000000,139.330000000,541,503,4,2,NVDA
2025-01-03T10:30:01.662816863Z,2025-01-03T10:30:01.662650406Z,10,2,11667,A,B,4,139.010000000,400,130,166457,4827578,139.120000000,139.180000000,30,500,1,2,139.110000000,139.200000000,1,129,1,1,139.080000000,139.210000000,57,400,1,1,139.030000000,139.220000000,126,10,2,1,139.010000000,139.230000000,500,325,2,4,139.000000000,139.250000000,420,1,5,1,138.980000000,139.270000000,300,17,1,1,138.970000000,139.300000000,800,507,2,4,138.940000000,139.320000000,400,39,1,1,138.900000000,139.330000000,541,503,4,2,NVDA
2025-01-03T10:30:01.718910590Z,2025-01-03T10:30:01.718744261Z,10,2,11667,A,B,3,139.050000000,400,130,166329,4827594,139.120000000,139.180000000,30,500,1,2,139.110000000,139.200000000,1,129,1,1,139.080000000,139.210000000,57,400,1,1,139.050000000,139.220000000,400,10,1,1,139.030000000,139.230000000,126,325,2,4,139.010000000,139.250000000,100,1,1,1,139.000000000,139.270000000,420,17,5,1,138.980000000,139.300000000,300,507,1,4,138.970000000,139.320000000,800,39,2,1,138.940000000,139.330000000,400,503,1,2,NVDA
2025-01-03T10:30:01.768429968Z,2025-01-03T10:30:01.768263666Z,10,2,9155,A,B,2,241.800000000,8,130,166302,4827606,242.020000000,242.400000000,120,485,1,1,242.000000000,242.460000000,200,8,1,1,241.800000000,242.850000000,8,300,1,2,241.670000000,242.900000000,2,100,1,1,241.000000000,243.000000000,100,92,1,2,240.000000000,243.310000000,10,10,1,1,238.000000000,243.700000000,30,100,1,1,236.000000000,246.810000000,6,100,1,1,235.500000000,262.740000000,5,100,1,1,235.000000000,263.830000000,5,100,1,1,JPM
2025-01-03T10:30:01.818011652Z,2025-01-03T10:30:01.817845346Z,10,2,17709,A,B,0,107.620000000,16,130,166306,4827611,107.620000000,107.880000000,16,400,1,2,107.600000000,107.940000000,50,15,1,1,107.580000000,107.950000000,100,10,1,1,107.000000000,108.000000000,1,150,1,2,106.240000000,108.300000000,28,50,1,1,106.000000000,108.550000000,15,50,2,1,105.870000000,108.800000000,141,50,1,1,103.180000000,108.880000000,16,28,1,1,103.000000000,109.450000000,3,137,1,1,102.000000000,109.500000000,2,100,1,1,XOM
2025-01-03T10:30:02.844549603Z,2025-01-03T10:30:02.844383855Z,10,2,11667,C,B,3,139.050000000,400,130,165748,4828110,139.120000000,139.180000000,30,500,1,2,139.110000000,139.200000000,1,129,1,1,139.080000000,139.210000000,57,400,1,1,139.030000000,139.220000000,126,10,2,1,139.010000000,139.230000000,100,325,1,4,139.000000000,139.250000000,420,1,5,1,138.980000000,139.270000000,300,17,1,1,138.970000000,139.300000000,800,507,2,4,138.940000000,139.320000000,400,39,1,1,138.900000000,139.330000000,541,503,4,2,NVDA
2025-01-03T10:30:02.919748852Z,2025-01-03T10:30:02.919582983Z,10,2,11667,A,B,3,139.040000000,400,130,165869,4828217,139.120000000,139.180000000,30,500,1,2,139.110000000,139.200000000,1,129,1,1,139.080000000,139.210000000,57,400,1,1,139.040000000,139.220000000,400,10,1,1,139.030000000,139.230000000,126,325,2,4,139.010000000,139.250000000,100,1,1,1,139.000000000,139.270000000,420,17,5,1,138.980000000,139.300000000,300,507,1,4,138.970000000,139.320000000,800,39,2,1,138.940000000,139.330000000,400,503,1,2,NVDA
2025-01-03T10:30:02.952894144Z,2025-01-03T10:30:02.952727809Z,10,2,16244,A,A,6,383.180000000,20,130,166335,4828232,382.710000000,382.920000000,10,50,1,1,382.680000000,382.990000000,41,1,2,1,382.230000000,383.000000000,25,31,1,2,382.110000000,383.080000000,300,1,1,1,382.100000000,383.090000000,20,6,2,1,382.010000000,383.100000000,2,12,1,2,382.000000000,383.180000000,1192,20,10,1,381.900000000,383.200000000,23,500,1,1,381.880000000,383.300000000,10,120,1,3,381.800000000,383.420000000,12,140,1,1,TSLA
2025-01-03T10:30:03.588570182Z,2025-01-03T10:30:03.588403834Z,10,2,10888,A,B,0,420.730000000,200,130,166348,4828671,420.730000000,421.250000000,200,200,1,1,420.620000000,421.310000000,15,13,1,1,420.580000000,421.490000000,10,6,1,1,420.520000000,421.570000000,1,40,1,1,420.400000000,421.600000000,858,10,1,1,420.380000000,421.700000000,100,359,1,1,420.100000000,422.100000000,100,7,1,1,420.000000000,422.400000000,534,500,7,1,419.730000000,422.500000000,3,200,1,1,418.650000000,423.500000000,1,600,1,2,MSFT
2025-01-03T10:30:03.755984036Z,2025-01-03T10:30:03.755818009Z,10,2,6905,C,B,2,91.430000000,7,130,166027,4828716,91.480000000,91.940000000,150,7,1,1,91.440000000,92.000000000,100,100,1,1,90.000000000,93.000000000,122,1,1,1,89.000000000,94.000000000,1,1,1,1,83.810000000,95.000000000,100,2,1,2,83.400000000,96.000000000,100,1,1,1,,97.000000000,0,2,0,2,,99.950000000,0,100,0,1,,100.360000000,0,100,0,1,,,0,0,0,0,GILD
2025-01-03T10:30:03.756076738Z,2025-01-03T10:30:03.755910191Z,10,2,6905,A,B,1,91.440000000,7,130,166547,4828717,91.480000000,91.940000000,150,7,1,1,91.440000000,92.000000000,107,100,2,1,90.000000000,93.000000000,122,1,1,1,89.000000000,94.000000000,1,1,1,1,83.810000000,95.000000000,100,2,1,2,83.400000000,96.000000000,100,1,1,1,,97.000000000,0,2,0,2,,99.950000000,0,100,0,1,,100.360000000,0,100,0,1,,,0,0,0,0,GILD
2025-01-03T10:30:03.821263468Z,2025-01-03T10:30:03.821093055Z,10,2,10888,T,N,0,420.820000000,30,0,170413,4828735,420.730000000,421.250000000,200,200,1,1,420.620000000,421.310000000,15,13,1,1,420.580000000,421.490000000,10,6,1,1,420.520000000,421.570000000,1,40,1,1,420.400000000,421.600000000,858,10,1,1,420.380000000,421.700000000,100,359,1,1,420.100000000,422.100000000,100,7,1,1,420.000000000,422.400000000,534,500,7,1,419.730000000,422.500000000,3,200,1,1,418.650000000,423.500000000,1,600,1,2,MSFT
2025-01-03T10:30:03.821263468Z,2025-01-03T10:30:03.821093055Z,10,2,10888,T,N,0,420.810000000,30,0,170413,4828736,420.730000000,421.250000000,200,200,1,1,420.620000000,421.310000000,15,13,1,1,420.580000000,421.490000000,10,6,1,1,420.520000000,421.570000000,1,40,1,1,420.400000000,421.600000000,858,10,1,1,420.380000000,421.700000000,100,359,1,1,420.100000000,422.100000000,100,7,1,1,420.000000000,422.400000000,534,500,7,1,419.730000000,422.500000000,3,200,1,1,418.650000000,423.500000000,1,600,1,2,MSFT
2025-01-03T10:30:03.821263468Z,2025-01-03T10:30:03.821093055Z,10,2,10888,T,N,0,420.800000000,15,130,170413,4828737,420.730000000,421.250000000,200,200,1,1,420.620000000,421.310000000,15,13,1,1,420.580000000,421.490000000,10,6,1,1,420.520000000,421.570000000,1,40,1,1,420.400000000,421.600000000,858,10,1,1,420.380000000,421.700000000,100,359,1,1,420.100000000,422.100000000,100,7,1,1,420.000000000,422.400000000,534,500,7,1,419.730000000,422.500000000,3,200,1,1,418.650000000,423.500000000,1,600,1,2,MSFT
2025-01-03T10:30:03.821286995Z,2025-01-03T10:30:03.821120954Z,10,2,10888,A,A,0,421.030000000,1,130,166041,4828738,420.730000000,421.030000000,200,1,1,1,420.620000000,421.250000000,15,200,1,1,420.580000000,421.310000000,10,13,1,1,420.520000000,421.490000000,1,6,1,1,420.400000000,421.570000000,858,40,1,1,420.380000000,421.600000000,100,10,1,1,420.100000000,421.700000000,100,359,1,1,420.000000000,422.100000000,534,7,7,1,419.730000000,422.400000000,3,500,1,1,418.650000000,422.500000000,1,200,1,1,MSFT
2025-01-03T10:30:03.828453958Z,2025-01-03T10:30:03.828287771Z,10,2,10888,C,A,0,421.030000000,1,130,166187,4828740,420.730000000,421.250000000,200,200,1,1,420.620000000,421.310000000,15,13,1,1,420.580000000,421.490000000,10,6,1,1,420.520000000,421.570000000,1,40,1,1,420.400000000,421.600000000,858,10,1,1,420.380000000,421.700000000,100,359,1,1,420.100000000,422.100000000,100,7,1,1,420.000000000,422.400000000,534,500,7,1,419.730000000,422.500000000,3,200,1,1,418.650000000,423.500000000,1,600,1,2,MSFT
2025-01-03T10:30:03.830419044Z,2025-01-03T10:30:03.830252432Z,10,2,6905,A,A,1,91.970000000,7,130,166612,4828750,91.480000000,91.940000000,150,7,1,1,91.440000000,91.970000000,107,7,2,1,90.000000000,92.000000000,122,100,1,1,89.000000000,93.000000000,1,1,1,1,83.810000000,94.000000000,100,1,1,1,83.400000000,95.000000000,100,2,1,2,,96.000000000,0,1,0,1,,97.000000000,0,2,0,2,,99.950000000,0,100,0,1,,100.360000000,0,100,0,1,GILD
2025-01-03T10:30:03.832047679Z,2025-01-03T10:30:03.831881694Z,10,2,6905,C,A,0,91.940000000,7,130,165985,4828752,91.480000000,91.970000000,150,7,1,1,91.440000000,92.000000000,107,100,2,1,90.000000000,93.000000000,122,1,1,1,89.000000000,94.000000000,1,1,1,1,83.810000000,95.000000000,100,2,1,2,83.400000000,96.000000000,100,1,1,1,,97.000000000,0,2,0,2,,99.950000000,0,100,0,1,,100.360000000,0,100,0,1,,,0,0,0,0,GILD
2025-01-03T10:30:03.903014268Z,2025-01-03T10:30:03.902848062Z,10,2,11667,A,B,3,139.060000000,400,130,166206,4828774,139.120000000,139.180000000,30,500,1,2,139.110000000,139.200000000,1,129,1,1,139.080000000,139.210000000,57,400,1,1,139.060000000,139.220000000,400,10,1,1,139.030000000,139.230000000,126,325,2,4,139.010000000,139.250000000,100,1,1,1,139.000000000,139.270000000,420,17,5,1,138.980000000,139.300000000,300,507,1,4,138.970000000,139.320000000,800,39,2,1,138.940000000,139.330000000,400,503,1,2,NVDA
2025-01-03T10:30:03.907049524Z,2025-01-03T10:30:03.906883352Z,10,2,10888,C,B,0,420.730000000,200,130,166172,4828775,420.620000000,421.250000000,15,200,1,1,420.580000000,421.310000000,10,13,1,1,420.520000000,421.490000000,1,6,1,1,420.400000000,421.570000000,858,40,1,1,420.380000000,421.600000000,100,10,1,1,420.100000000,421.700000000,100,359,1,1,420.000000000,422.100000000,534,7,7,1,419.730000000,422.400000000,3,500,1,1,418.650000000,422.500000000,1,200,1,1,418.500000000,423.500000000,1,600,1,2,MSFT
2025-01-03T10:30:03.907063099Z,2025-01-03T10:30:03.906896961Z,10,2,10888,A,B,0,420.640000000,200,130,166138,4828776,420.640000000,421.250000000,200,200,1,1,420.620000000,421.310000000,15,13,1,1,420.580000000,421.490000000,10,6,1,1,420.520000000,421.570000000,1,40,1,1,420.400000000,421.600000000,858,10,1,1,420.380000000,421.700000000,100,359,1,1,420.100000000,422.100000000,100,7,1,1,420.000000000,422.400000000,534,500,7,1,419.730000000,422.500000000,3,200,1,1,418.650000000,423.500000000,1,600,1,2,MSFT
2025-01-03T10:30:03.950439050Z,2025-01-03T10:30:03.950272804Z,10,2,16244,A,B,1,382.700000000,50,130,166246,4828790,382.710000000,382.920000000,10,50,1,1,382.700000000,382.990000000,50,1,1,1,382.680000000,383.000000000,41,31,2,2,382.230000000,383.080000000,25,1,1,1,382.110000000,383.090000000,300,6,1,1,382.100000000,383.100000000,20,12,2,2,382.010000000,383.180000000,2,20,1,1,382.000000000,383.200000000,1192,500,10,1,381.900000000,383.300000000,23,120,1,3,381.880000000,383.420000000,10,140,1,1,TSLA
2025-01-03T10:30:03.990380400Z,2025-01-03T10:30:03.990211902Z,10,2,16244,T,N,0,382.820000000,40,0,168498,4828800,382.710000000,382.920000000,10,50,1,1,382.700000000,382.990000000,50,1,1,1,382.680000000,383.000000000,41,31,2,2,382.230000000,383.080000000,25,1,1,1,382.110000000,383.090000000,300,6,1,1,382.100000000,383.100000000,20,12,2,2,382.010000000,383.180000000,2,20,1,1,382.000000000,383.200000000,1192,500,10,1,381.900000000,383.300000000,23,120,1,3,381.880000000,383.420000000,10,140,1,1,TSLA
2025-01-03T10:30:03.990380400Z,2025-01-03T10:30:03.990211902Z,10,2,16244,T,N,0,382.820000000,30,130,168498,4828801,382.710000000,382.920000000,10,50,1,1,382.700000000,382.990000000,50,1,1,1,382.680000000,383.000000000,41,31,2,2,382.230000000,383.080000000,25,1,1,1,382.110000000,383.090000000,300,6,1,1,382.100000000,383.100000000,20,12,2,2,382.010000000,383.180000000,2,20,1,1,382.000000000,383.200000000,1192,500,10,1,381.900000000,383.300000000,23,120,1,3,381.880000000,383.420000000,10,140,1,1,TSLA
2025-01-03T10:30:04.220061184Z,2025-01-03T10:30:04.219895061Z,10,2,38,A,B,4,243.020000000,79,130,166123,4828877,243.500000000,243.650000000,6,61,1,2,243.460000000,243.680000000,400,200,1,1,243.390000000,243.740000000,27,26,1,1,243.190000000,244.000000000,2,1,1,1,243.020000000,244.200000000,79,1000,1,1,243.000000000,244.400000000,1233,50,8,1,242.990000000,244.420000000,1,10,1,1,242.750000000,244.580000000,30,100,1,1,242.590000000,245.000000000,5,79,1,2,242.280000000,245.190000000,100,83,1,1,AAPL
2025-01-03T10:30:04.242969217Z,2025-01-03T10:30:04.242802972Z,10,2,38,A,A,4,244.140000000,79,130,166245,4828899,243.500000000,243.650000000,6,61,1,2,243.460000000,243.680000000,400,200,1,1,243.390000000,243.740000000,27,26,1,1,243.190000000,244.000000000,2,1,1,1,243.020000000,244.140000000,79,79,1,1,243.000000000,244.200000000,1233,1000,8,1,242.990000000,244.400000000,1,50,1,1,242.750000000,244.420000000,30,10,1,1,242.590000000,244.580000000,5,100,1,1,242.280000000,245.000000000,100,79,1,2,AAPL
2025-01-03T10:30:04.269475318Z,2025-01-03T10:30:04.269309211Z,10,2,9155,A,B,6,239.890000000,82,130,166107,4828916,242.020000000,242.400000000,120,485,1,1,242.000000000,242.460000000,200,8,1,1,241.800000000,242.850000000,8,300,1,2,241.670000000,242.900000000,2,100,1,1,241.000000000,243.000000000,100,92,1,2,240.000000000,243.310000000,10,10,1,1,239.890000000,243.700000000,82,100,1,1,238.000000000,246.810000000,30,100,1,1,236.000000000,262.740000000,6,100,1,1,235.500000000,263.830000000,5,100,1,1,JPM
2025-01-03T10:30:04.293150837Z,2025-01-03T10:30:04.292982710Z,10,2,9155,T,N,0,242.040000000,79,0,168127,4828931,242.020000000,242.400000000,120,485,1,1,242.000000000,242.460000000,200,8,1,1,241.800000000,242.850000000,8,300,1,2,241.670000000,242.900000000,2,100,1,1,241.000000000,243.000000000,100,92,1,2,240.000000000,243.310000000,10,10,1,1,239.890000000,243.700000000,82,100,1,1,238.000000000,246.810000000,30,100,1,1,236.000000000,262.740000000,6,100,1,1,235.500000000,263.830000000,5,100,1,1,JPM
2025-01-03T10:30:04.293150837Z,2025-01-03T10:30:04.292982710Z,10,2,9155,T,N,0,242.030000000,3,130,168127,4828932,242.020000000,242.400000000,120,485,1,1,242.000000000,242.460000000,200,8,1,1,241.800000000,242.850000000,8,300,1,2,241.670000000,242.900000000,2,100,1,1,241.000000000,243.000000000,100,92,1,2,240.000000000,243.310000000,10,10,1,1,239.890000000,243.700000000,82,100,1,1,238.000000000,246.810000000,30,100,1,1,236.000000000,262.740000000,6,100,1,1,235.500000000,263.830000000,5,100,1,1,JPM
2025-01-03T10:30:04.293174757Z,2025-01-03T10:30:04.293007906Z,10,2,9155,A,A,0,242.220000000,1,130,166851,4828933,242.020000000,242.220000000,120,1,1,1,242.000000000,242.400000000,200,485,1,1,241.800000000,242.460000000,8,8,1,1,241.670000000,242.850000000,2,300,1,2,241.000000000,242.900000000,100,100,1,1,240.000000000,243.000000000,10,92,1,2,239.890000000,243.310000000,82,10,1,1,238.000000000,243.700000000,30,100,1,1,236.000000000,246.810000000,6,100,1,1,235.500000000,262.740000000,5,100,1,1,JPM
2025-01-03T10:30:04.297152370Z,2025-01-03T10:30:04.296986599Z,10,2,9155,C,A,0,242.220000000,1,130,165771,4828934,242.020000000,242.400000000,120,485,1,1,242.000000000,242.460000000,200,8,1,1,241.800000000,242.850000000,8,300,1,2,241.670000000,242.900000000,2,100,1,1,241.000000000,243.000000000,100,92,1,2,240.000000000,243.310000000,10,10,1,1,239.890000000,243.700000000,82,100,1,1,238.000000000,246.810000000,30,100,1,1,236.000000000,262.740000000,6,100,1,1,235.500000000,263.830000000,5,100,1,1,JPM
2025-01-03T10:30:04.380770527Z,2025-01-03T10:30:04.380604344Z,10,2,16727,A,B,2,313.740000000,62,130,166183,4829025,314.920000000,315.450000000,8,8,1,1,314.860000000,315.510000000,25,25,1,1,313.740000000,320.000000000,62,5,1,1,313.500000000,320.210000000,1,1,1,1,310.000000000,321.950000000,1,2,1,1,300.000000000,344.200000000,3,100,1,1,290.000000000,345.620000000,2,100,1,1,286.660000000,,100,0,1,0,285.250000000,,100,0,1,0,260.000000000,,2,0,1,0,V
2025-01-03T10:30:04.460011858Z,2025-01-03T10:30:04.459845703Z,10,2,16727,A,A,0,315.080000000,62,130,166155,4829057,314.920000000,315.080000000,8,62,1,1,314.860000000,315.450000000,25,8,1,1,313.740000000,315.510000000,62,25,1,1,313.500000000,320.000000000,1,5,1,1,310.000000000,320.210000000,1,1,1,1,300.000000000,321.950000000,3,2,1,1,290.000000000,344.200000000,2,100,1,1,286.660000000,345.620000000,100,100,1,1,285.250000000,,100,0,1,0,260.000000000,,2,0,1,0,V
2025-01-03T10:30:04.460043825Z,2025-01-03T10:30:04.459876835Z,10,2,16727,T,B,0,315.080000000,9,130,166990,4829058,314.920000000,315.080000000,8,62,1,1,314.860000000,315.450000000,25,8,1,1,313.740000000,315.510000000,62,25,1,1,313.500000000,320.000000000,1,5,1,1,310.000000000,320.210000000,1,1,1,1,300.000000000,321.950000000,3,2,1,1,290.000000000,344.200000000,2,100,1,1,286.660000000,345.620000000,100,100,1,1,285.250000000,,100,0,1,0,260.000000000,,2,0,1,0,V
2025-01-03T10:30:04.460043825Z,2025-01-03T10:30:04.459876835Z,10,2,16727,C,A,0,315.080000000,9,130,166990,4829058,314.920000000,315.080000000,8,53,1,1,314.860000000,315.450000000,25,8,1,1,313.740000000,315.510000000,62,25,1,1,313.500000000,320.000000000,1,5,1,1,310.000000000,320.210000000,1,1,1,1,300.000000000,321.950000000,3,2,1,1,290.000000000,344.200000000,2,100,1,1,286.660000000,345.620000000,100,100,1,1,285.250000000,,100,0,1,0,260.000000000,,2,0,1,0,V
2025-01-03T10:30:04.460424371Z,2025-01-03T10:30:04.460257198Z,10,2,16727,T,B,0,315.080000000,9,130,167173,4829061,314.920000000,315.080000000,8,53,1,1,314.860000000,315.450000000,25,8,1,1,313.740000000,315.510000000,62,25,1,1,313.500000000,320.000000000,1,5,1,1,310.000000000,320.210000000,1,1,1,1,300.000000000,321.950000000,3,2,1,1,290.000000000,344.200000000,2,100,1,1,286.660000000,345.620000000,100,100,1,1,285.250000000,,100,0,1,0,260.000000000,,2,0,1,0,V
2025-01-03T10:30:04.460424371Z,2025-01-03T10:30:04.460257198Z,10,2,16727,C,A,0,315.080000000,9,130,167173,4829061,314.920000000,315.080000000,8,44,1,1,314.860000000,315.450000000,25,8,1,1,313.740000000,315.510000000,62,25,1,1,313.500000000,320.000000000,1,5,1,1,310.000000000,320.210000000,1,1,1,1,300.000000000,321.950000000,3,2,1,1,290.000000000,344.200000000,2,100,1,1,286.660000000,345.620000000,100,100,1,1,285.250000000,,100,0,1,0,260.000000000,,2,0,1,0,V
2025-01-03T10:30:04.460464160Z,2025-01-03T10:30:04.460298124Z,10,2,16727,C,A,2,315.510000000,25,130,166036,4829062,314.920000000,315.080000000,8,44,1,1,314.860000000,315.450000000,25,8,1,1,313.740000000,320.000000000,62,5,1,1,313.500000000,320.210000000,1,1,1,1,310.000000000,321.950000000,1,2,1,1,300.000000000,344.200000000,3,100,1,1,290.000000000,345.620000000,2,100,1,1,286.660000000,,100,0,1,0,285.250000000,,100,0,1,0,260.000000000,,2,0,1,0,V
2025-01-03T10:30:04.461859934Z,2025-01-03T10:30:04.461692181Z,10,2,16727,T,B,0,315.080000000,22,130,167753,4829073,314.920000000,315.080000000,8,44,1,1,314.860000000,315.450000000,25,8,1,1,313.740000000,320.000000000,62,5,1,1,313.500000000,320.210000000,1,1,1,1,310.000000000,321.950000000,1,2,1,1,300.000000000,344.200000000,3,100,1,1,290.000000000,345.620000000,2,100,1,1,286.660000000,,100,0,1,0,285.250000000,,100,0,1,0,260.000000000,,2,0,1,0,V
2025-01-03T10:30:04.461859934Z,2025-01-03T10:30:04.461692181Z,10,2,16727,C,A,0,315.080000000,22,130,167753,4829073,314.920000000,315.080000000,8,22,1,1,314.860000000,315.450000000,25,8,1,1,313.740000000,320.000000000,62,5,1,1,313.500000000,320.210000000,1,1,1,1,310.000000000,321.950000000,1,2,1,1,300.000000000,344.200000000,3,100,1,1,290.000000000,345.620000000,2,100,1,1,286.660000000,,100,0,1,0,285.250000000,,100,0,1,0,260.000000000,,2,0,1,0,V
2025-01-03T10:30:04.461929824Z,2025-01-03T10:30:04.461762588Z,10,2,16727,T,B,0,315.080000000,22,130,167236,4829074,314.920000000,315.080000000,8,22,1,1,314.860000000,315.450000000,25,8,1,1,313.740000000,320.000000000,62,5,1,1,313.500000000,320.210000000,1,1,1,1,310.000000000,321.950000000,1,2,1,1,300.000000000,344.200000000,3,100,1,1,290.000000000,345.620000000,2,100,1,1,286.660000000,,100,0,1,0,285.250000000,,100,0,1,0,260.000000000,,2,0,1,0,V
2025-01-03T10:30:04.461929824Z,2025-01-03T10:30:04.461762588Z,10,2,16727,C,A,0,315.080000000,22,130,167236,4829074,314.920000000,315.450000000,8,8,1,1,314.860000000,320.000000000,25,5,1,1,313.740000000,320.210000000,62,1,1,1,313.500000000,321.950000000,1,2,1,1,310.000000000,344.200000000,1,100,1,1,300.000000000,345.620000000,3,100,1,1,290.000000000,,2,0,1,0,286.660000000,,100,0,1,0,285.250000000,,100,0,1,0,260.000000000,,2,0,1,0,V
2025-01-03T10:30:04.461973587Z,2025-01-03T10:30:04.461807794Z,10,2,16727,C,B,1,314.860000000,25,130,165793,4829075,314.920000000,315.450000000,8,8,1,1,313.740000000,320.000000000,62,5,1,1,313.500000000,320.210000000,1,1,1,1,310.000000000,321.950000000,1,2,1,1,300.000000000,344.200000000,3,100,1,1,290.000000000,345.620000000,2,100,1,1,286.660000000,,100,0,1,0,285.250000000,,100,0,1,0,260.000000000,,2,0,1,0,,,0,0,0,0,V
2025-01-03T10:30:04.462026241Z,2025-01-03T10:30:04.461859448Z,10,2,16727,A,A,1,315.490000000,2,130,166793,4829076,314.920000000,315.450000000,8,8,1,1,313.740000000,315.490000000,62,2,1,1,313.500000000,320.000000000,1,5,1,1,310.000000000,320.210000000,1,1,1,1,300.000000000,321.950000000,3,2,1,1,290.000000000,344.200000000,2,100,1,1,286.660000000,345.620000000,100,100,1,1,285.250000000,,100,0,1,0,260.000000000,,2,0,1,0,,,0,0,0,0,V
2025-01-03T10:30:04.472348190Z,2025-01-03T10:30:04.472182007Z,10,2,16727,C,A,1,315.490000000,2,130,166183,4829095,314.920000000,315.450000000,8,8,1,1,313.740000000,320.000000000,62,5,1,1,313.500000000,320.210000000,1,1,1,1,310.000000000,321.950000000,1,2,1,1,300.000000000,344.200000000,3,100,1,1,290.000000000,345.620000000,2,100,1,1,286.660000000,,100,0,1,0,285.250000000,,100,0,1,0,260.000000000,,2,0,1,0,,,0,0,0,0,V
2025-01-03T10:30:04.522073731Z,2025-01-03T10:30:04.521907191Z,10,2,17709,A,B,3,107.050000000,247,130,166540,4829130,107.620000000,107.880000000,16,400,1,2,107.600000000,107.940000000,50,15,1,1,107.580000000,107.950000000,100,10,1,1,107.050000000,108.000000000,247,150,1,2,107.000000000,108.300000000,1,50,1,1,106.240000000,108.550000000,28,50,1,1,106.000000000,108.800000000,15,50,2,1,105.870000000,108.880000000,141,28,1,1,103.180000000,109.450000000,16,137,1,1,103.000000000,109.500000000,3,100,1,1,XOM
2025-01-03T10:30:04.559271280Z,2025-01-03T10:30:04.559104695Z,10,2,16727,A,A,1,315.640000000,25,130,166585,4829285,314.920000000,315.450000000,8,8,1,1,313.740000000,315.640000000,62,25,1,1,313.500000000,320.000000000,1,5,1,1,310.000000000,320.210000000,1,1,1,1,300.000000000,321.950000000,3,2,1,1,290.000000000,344.200000000,2,100,1,1,286.660000000,345.620000000,100,100,1,1,285.250000000,,100,0,1,0,260.000000000,,2,0,1,0,,,0,0,0,0,V
2025-01-03T10:30:04.569272656Z,2025-01-03T10:30:04.569106382Z,10,2,16727,A,B,1,314.860000000,25,130,166274,4829287,314.920000000,315.450000000,8,8,1,1,314.860000000,315.640000000,25,25,1,1,313.740000000,320.000000000,62,5,1,1,313.500000000,320.210000000,1,1,1,1,310.000000000,321.950000000,1,2,1,1,300.000000000,344.200000000,3,100,1,1,290.000000000,345.620000000,2,100,1,1,286.660000000,,100,0,1,0,285.250000000,,100,0,1,0,260.000000000,,2,0,1,0,V
2025-01-03T10:30:04.606881827Z,2025-01-03T10:30:04.606715876Z,10,2,16244,C,A,7,383.200000000,500,130,165951,4829300,382.710000000,382.920000000,10,50,1,1,382.700000000,382.990000000,50,1,1,1,382.680000000,383.000000000,41,31,2,2,382.230000000,383.080000000,25,1,1,1,382.110000000,383.090000000,300,6,1,1,382.100000000,383.100000000,20,12,2,2,382.010000000,383.180000000,2,20,1,1,382.000000000,383.300000000,1192,120,10,3,381.900000000,383.420000000,23,140,1,1,381.880000000,383.600000000,10,1000,1,2,TSLA
2025-01-03T10:30:04.737046777Z,2025-01-03T10:30:04.736880296Z,10,2,17709,A,A,0,107.870000000,242,130,166481,4829338,107.620000000,107.870000000,16,242,1,1,107.600000000,107.880000000,50,400,1,2,107.580000000,107.940000000,100,15,1,1,107.050000000,107.950000000,247,10,1,1,107.000000000,108.000000000,1,150,1,2,106.240000000,108.300000000,28,50,1,1,106.000000000,108.550000000,15,50,2,1,105.870000000,108.800000000,141,50,1,1,103.180000000,108.880000000,16,28,1,1,103.000000000,109.450000000,3,137,1,1,XOM
2025-01-03T10:30:04.737093317Z,2025-01-03T10:30:04.736926334Z,10,2,17709,A,A,0,107.870000000,200,130,166983,4829339,107.620000000,107.870000000,16,442,1,2,107.600000000,107.880000000,50,400,1,2,107.580000000,107.940000000,100,15,1,1,107.050000000,107.950000000,247,10,1,1,107.000000000,108.000000000,1,150,1,2,106.240000000,108.300000000,28,50,1,1,106.000000000,108.550000000,15,50,2,1,105.870000000,108.800000000,141,50,1,1,103.180000000,108.880000000,16,28,1,1,103.000000000,109.450000000,3,137,1,1,XOM
2025-01-03T10:30:04.737102098Z,2025-01-03T10:30:04.736935870Z,10,2,17709,A,A,0,107.870000000,200,130,166228,4829340,107.620000000,107.870000000,16,642,1,3,107.600000000,107.880000000,50,400,1,2,107.580000000,107.940000000,100,15,1,1,107.050000000,107.950000000,247,10,1,1,107.000000000,108.000000000,1,150,1,2,106.240000000,108.300000000,28,50,1,1,106.000000000,108.550000000,15,50,2,1,105.870000000,108.800000000,141,50,1,1,103.180000000,108.880000000,16,28,1,1,103.000000000,109.450000000,3,137,1,1,XOM
2025-01-03T10:30:04.737106113Z,2025-01-03T10:30:04.736939951Z,10,2,17709,C,A,1,107.880000000,200,130,166162,4829341,107.620000000,107.870000000,16,642,1,3,107.600000000,107.880000000,50,200,1,1,107.580000000,107.940000000,100,15,1,1,107.050000000,107.950000000,247,10,1,1,107.000000000,108.000000000,1,150,1,2,106.240000000,108.300000000,28,50,1,1,106.000000000,108.550000000,15,50,2,1,105.870000000,108.800000000,141,50,1,1,103.180000000,108.880000000,16,28,1,1,103.000000000,109.450000000,3,137,1,1,XOM
2025-01-03T10:30:04.737115351Z,2025-01-03T10:30:04.736949299Z,10,2,17709,C,A,1,107.880000000,200,130,166052,4829342,107.620000000,107.870000000,16,642,1,3,107.600000000,107.940000000,50,15,1,1,107.580000000,107.950000000,100,10,1,1,107.050000000,108.000000000,247,150,1,2,107.000000000,108.300000000,1,50,1,1,106.240000000,108.550000000,28,50,1,1,106.000000000,108.800000000,15,50,2,1,105.870000000,108.880000000,141,28,1,1,103.180000000,109.450000000,16,137,1,1,103.000000000,109.500000000,3,100,1,1,XOM
2025-01-03T10:30:04.755280765Z,2025-01-03T10:30:04.755114565Z,10,2,11667,A,A,0,139.180000000,350,130,166200,4829343,139.120000000,139.180000000,30,850,1,3,139.110000000,139.200000000,1,129,1,1,139.080000000,139.210000000,57,400,1,1,139.060000000,139.220000000,400,10,1,1,139.030000000,139.230000000,126,325,2,4,139.010000000,139.250000000,100,1,1,1,139.000000000,139.270000000,420,17,5,1,138.980000000,139.300000000,300,507,1,4,138.970000000,139.320000000,800,39,2,1,138.940000000,139.330000000,400,503,1,2,NVDA
2025-01-03T10:30:04.999779808Z,2025-01-03T10:30:04.999613768Z,10,2,11667,A,B,0,139.150000000,100,130,166040,4829472,139.150000000,139.180000000,100,850,1,3,139.120000000,139.200000000,30,129,1,1,139.110000000,139.210000000,1,400,1,1,139.080000000,139.220000000,57,10,1,1,139.060000000,139.230000000,400,325,1,4,139.030000000,139.250000000,126,1,2,1,139.010000000,139.270000000,100,17,1,1,139.000000000,139.300000000,420,507,5,4,138.980000000,139.320000000,300,39,1,1,138.970000000,139.330000000,800,503,2,2,NVDA
2025-01-03T10:30:05.010222706Z,2025-01-03T10:30:05.010056894Z,10,2,11667,C,A,0,139.180000000,100,130,165812,4829485,139.150000000,139.180000000,100,750,1,2,139.120000000,139.200000000,30,129,1,1,139.110000000,139.210000000,1,400,1,1,139.080000000,139.220000000,57,10,1,1,139.060000000,139.230000000,400,325,1,4,139.030000000,139.250000000,126,1,2,1,139.010000000,139.270000000,100,17,1,1,139.000000000,139.300000000,420,507,5,4,138.980000000,139.320000000,300,39,1,1,138.970000000,139.330000000,800,503,2,2,NVDA
2025-01-03T10:30:05.094852174Z,2025-01-03T10:30:05.094685317Z,10,2,11667,A,A,0,139.180000000,100,130,166857,4829678,139.150000000,139.180000000,100,850,1,3,139.120000000,139.200000000,30,129,1,1,139.110000000,139.210000000,1,400,1,1,139.080000000,139.220000000,57,10,1,1,139.060000000,139.230000000,400,325,1,4,139.030000000,139.250000000,126,1,2,1,139.010000000,139.270000000,100,17,1,1,139.000000000,139.300000000,420,507,5,4,138.980000000,139.320000000,300,39,1,1,138.970000000,139.330000000,800,503,2,2,NVDA
2025-01-03T10:30:05.162258816Z,2025-01-03T10:30:05.162092385Z,10,2,11667,A,B,3,139.090000000,400,130,166431,4829722,139.150000000,139.180000000,100,850,1,3,139.120000000,139.200000000,30,129,1,1,139.110000000,139.210000000,1,400,1,1,139.090000000,139.220000000,400,10,1,1,139.080000000,139.230000000,57,325,1,4,139.030000000,139.250000000,126,1,2,1,139.010000000,139.270000000,100,17,1,1,139.000000000,139.300000000,420,507,5,4,138.980000000,139.320000000,300,39,1,1,138.970000000,139.330000000,800,503,2,2,NVDA
2025-01-03T10:30:06.185990302Z,2025-01-03T10:30:06.185824097Z,10,2,6905,C,A,1,92.000000000,100,130,166205,4830051,91.480000000,91.970000000,150,7,1,1,91.440000000,93.000000000,107,1,2,1,90.000000000,94.000000000,122,1,1,1,89.000000000,95.000000000,1,2,1,2,83.810000000,96.000000000,100,1,1,1,83.400000000,97.000000000,100,2,1,2,,99.950000000,0,100,0,1,,100.360000000,0,100,0,1,,,0,0,0,0,,,0,0,0,0,GILD
2025-01-03T10:30:06.186003068Z,2025-01-03T10:30:06.185836829Z,10,2,6905,A,A,1,92.080000000,100,130,166239,4830052,91.480000000,91.970000000,150,7,1,1,91.440000000,92.080000000,107,100,2,1,90.000000000,93.000000000,122,1,1,1,89.000000000,94.000000000,1,1,1,1,83.810000000,95.000000000,100,2,1,2,83.400000000,96.000000000,100,1,1,1,,97.000000000,0,2,0,2,,99.950000000,0,100,0,1,,100.360000000,0,100,0,1,,,0,0,0,0,GILD
2025-01-03T10:30:06.237519608Z,2025-01-03T10:30:06.237353811Z,10,2,6905,C,B,1,91.440000000,7,130,165797,4830079,91.480000000,91.970000000,150,7,1,1,91.440000000,92.080000000,100,100,1,1,90.000000000,93.000000000,122,1,1,1,89.000000000,94.000000000,1,1,1,1,83.810000000,95.000000000,100,2,1,2,83.400000000,96.000000000,100,1,1,1,,97.000000000,0,2,0,2,,99.950000000,0,100,0,1,,100.360000000,0,100,0,1,,,0,0,0,0,GILD
2025-01-03T10:30:06.237551751Z,2025-01-03T10:30:06.237385784Z,10,2,6905,C,A,0,91.970000000,7,130,165967,4830080,91.480000000,92.080000000,150,100,1,1,91.440000000,93.000000000,100,1,1,1,90.000000000,94.000000000,122,1,1,1,89.000000000,95.000000000,1,2,1,2,83.810000000,96.000000000,100,1,1,1,83.400000000,97.000000000,100,2,1,2,,99.950000000,0,100,0,1,,100.360000000,0,100,0,1,,,0,0,0,0,,,0,0,0,0,GILD
2025-01-03T10:30:06.237621402Z,2025-01-03T10:30:06.237455299Z,10,2,6905,A,B,0,91.520000000,7,130,166103,4830081,91.520000000,92.080000000,7,100,1,1,91.480000000,93.000000000,150,1,1,1,91.440000000,94.000000000,100,1,1,1,90.000000000,95.000000000,122,2,1,2,89.000000000,96.000000000,1,1,1,1,83.810000000,97.000000000,100,2,1,2,83.400000000,99.950000000,100,100,1,1,,100.360000000,0,100,0,1,,,0,0,0,0,,,0,0,0,0,GILD
2025-01-03T10:30:06.237681018Z,2025-01-03T10:30:06.237514743Z,10,2,6905,A,A,0,91.960000000,7,130,166275,4830082,91.520000000,91.960000000,7,7,1,1,91.480000000,92.080000000,150,100,1,1,91.440000000,93.000000000,100,1,1,1,90.000000000,94.000000000,122,1,1,1,89.000000000,95.000000000,1,2,1,2,83.810000000,96.000000000,100,1,1,1,83.400000000,97.000000000,100,2,1,2,,99.950000000,0,100,0,1,,100.360000000,0,100,0,1,,,0,0,0,0,GILD
2025-01-03T10:30:06.294008395Z,2025-01-03T10:30:06.293841778Z,10,2,6905,A,A,0,91.960000000,100,130,166617,4830147,91.520000000,91.960000000,7,107,1,2,91.480000000,93.000000000,150,1,1,1,91.440000000,94.000000000,100,1,1,1,90.000000000,95.000000000,122,2,1,2,89.000000000,96.000000000,1,1,1,1,83.810000000,97.000000000,100,2,1,2,83.400000000,99.950000000,100,100,1,1,,100.360000000,0,100,0,1,,,0,0,0,0,,,0,0,0,0,GILD
2025-01-03T10:30:06.365030641Z,2025-01-03T10:30:06.364865028Z,10,2,11667,C,A,0,139.180000000,100,130,165613,4830196,139.150000000,139.180000000,100,750,1,2,139.120000000,139.200000000,30,129,1,1,139.110000000,139.210000000,1,400,1,1,139.090000000,139.220000000,400,10,1,1,139.080000000,139.230000000,57,325,1,4,139.030000000,139.250000000,126,1,2,1,139.010000000,139.270000000,100,17,1,1,139.000000000,139.300000000,420,507,5,4,138.980000000,139.320000000,300,39,1,1,138.970000000,139.330000000,800,503,2,2,NVDA
2025-01-03T10:30:06.427101461Z,2025-01-03T10:30:06.426935397Z,10,2,11667,C,B,3,139.090000000,400,130,166064,4830265,139.150000000,139.180000000,100,750,1,2,139.120000000,139.200000000,30,129,1,1,139.110000000,139.210000000,1,400,1,1,139.080000000,139.220000000,57,10,1,1,139.030000000,139.230000000,126,325,2,4,139.010000000,139.250000000,100,1,1,1,139.000000000,139.270000000,420,17,5,1,138.980000000,139.300000000,300,507,1,4,138.970000000,139.320000000,800,39,2,1,138.940000000,139.330000000,400,503,1,2,NVDA
2025-01-03T10:30:06.427115114Z,2025-01-03T10:30:06.426948837Z,10,2,11667,A,B,4,139.060000000,400,130,166277,4830266,139.150000000,139.180000000,100,750,1,2,139.120000000,139.200000000,30,129,1,1,139.110000000,139.210000000,1,400,1,1,139.080000000,139.220000000,57,10,1,1,139.060000000,139.230000000,400,325,1,4,139.030000000,139.250000000,126,1,2,1,139.010000000,139.270000000,100,17,1,1,139.000000000,139.300000000,420,507,5,4,138.980000000,139.320000000,300,39,1,1,138.970000000,139.330000000,800,503,2,2,NVDA
2025-01-03T10:30:06.427146941Z,2025-01-03T10:30:06.426981136Z,10,2,11667,C,A,4,139.230000000,100,130,165805,4830267,139.150000000,139.180000000,100,750,1,2,139.120000000,139.200000000,30,129,1,1,139.110000000,139.210000000,1,400,1,1,139.080000000,139.220000000,57,10,1,1,139.060000000,139.230000000,400,225,1,3,139.030000000,139.250000000,126,1,2,1,139.010000000,139.270000000,100,17,1,1,139.000000000,139.300000000,420,507,5,4,138.980000000,139.320000000,300,39,1,1,138.970000000,139.330000000,800,503,2,2,NVDA
2025-01-03T10:30:06.427156882Z,2025-01-03T10:30:06.426990931Z,10,2,11667,C,A,4,139.230000000,100,130,165951,4830268,139.150000000,139.180000000,100,750,1,2,139.120000000,139.200000000,30,129,1,1,139.110000000,139.210000000,1,400,1,1,139.080000000,139.220000000,57,10,1,1,139.060000000,139.230000000,400,125,1,2,139.030000000,139.250000000,126,1,2,1,139.010000000,139.270000000,100,17,1,1,139.000000000,139.300000000,420,507,5,4,138.980000000,139.320000000,300,39,1,1,138.970000000,139.330000000,800,503,2,2,NVDA
2025-01-03T10:30:06.427168537Z,2025-01-03T10:30:06.427001727Z,10,2,11667,A,A,3,139.220000000,300,130,166810,4830269,139.150000000,139.180000000,100,750,1,2,139.120000000,139.200000000,30,129,1,1,139.110000000,139.210000000,1,400,1,1,139.080000000,139.220000000,57,310,1,2,139.060000000,139.230000000,400,25,1,1,139.030000000,139.250000000,126,1,2,1,139.010000000,139.270000000,100,17,1,1,139.000000000,139.300000000,420,507,5,4,138.980000000,139.320000000,300,39,1,1,138.970000000,139.330000000,800,503,2,2,NVDA
2025-01-03T10:30:06.437532528Z,2025-01-03T10:30:06.437366704Z,10,2,11667,C,B,4,139.060000000,400,130,165824,4830273,139.150000000,139.180000000,100,750,1,2,139.120000000,139.200000000,30,129,1,1,139.110000000,139.210000000,1,400,1,1,139.080000000,139.220000000,57,310,1,2,139.030000000,139.230000000,126,25,2,1,139.010000000,139.250000000,100,1,1,1,139.000000000,139.270000000,420,17,5,1,138.980000000,139.300000000,300,507,1,4,138.970000000,139.320000000,800,39,2,1,138.940000000,139.330000000,400,503,1,2,NVDA
2025-01-03T10:30:06.437545632Z,2025-01-03T10:30:06.437379738Z,10,2,11667,A,B,4,139.050000000,400,130,165894,4830274,139.150000000,139.180000000,100,750,1,2,139.120000000,139.200000000,30,129,1,1,139.110000000,139.210000000,1,400,1,1,139.080000000,139.220000000,57,310,1,2,139.050000000,139.230000000,400,25,1,1,139.030000000,139.250000000,126,1,2,1,139.010000000,139.270000000,100,17,1,1,139.000000000,139.300000000,420,507,5,4,138.980000000,139.320000000,300,39,1,1,138.970000000,139.330000000,800,503,2,2,NVDA
2025-01-03T10:30:06.774692794Z,2025-01-03T10:30:06.774526838Z,10,2,9155,C,B,2,241.800000000,8,130,165956,4830350,242.020000000,242.400000000,120,485,1,1,242.000000000,242.460000000,200,8,1,1,241.670000000,242.850000000,2,300,1,2,241.000000000,242.900000000,100,100,1,1,240.000000000,243.000000000,10,92,1,2,239.890000000,243.310000000,82,10,1,1,238.000000000,243.700000000,30,100,1,1,236.000000000,246.810000000,6,100,1,1,235.500000000,262.740000000,5,100,1,1,235.000000000,263.830000000,5,100,1,1,JPM
2025-01-03T10:30:06.774753754Z,2025-01-03T10:30:06.774587520Z,10,2,9155,A,B,2,241.850000000,8,130,166234,4830351,242.020000000,242.400000000,120,485,1,1,242.000000000,242.460000000,200,8,1,1,241.850000000,242.850000000,8,300,1,2,241.670000000,242.900000000,2,100,1,1,241.000000000,243.000000000,100,92,1,2,240.000000000,243.310000000,10,10,1,1,239.890000000,243.700000000,82,100,1,1,238.000000000,246.810000000,30,100,1,1,236.000000000,262.740000000,6,100,1,1,235.500000000,263.830000000,5,100,1,1,JPM
2025-01-03T10:30:06.964052546Z,2025-01-03T10:30:06.963886156Z,10,2,10888,A,B,0,420.710000000,200,130,166390,4830397,420.710000000,421.250000000,200,200,1,1,420.620000000,421.310000000,15,13,1,1,420.580000000,421.490000000,10,6,1,1,420.520000000,421.570000000,1,40,1,1,420.400000000,421.600000000,858,10,1,1,420.380000000,421.700000000,100,359,1,1,420.100000000,422.100000000,100,7,1,1,420.000000000,422.400000000,534,500,7,1,419.730000000,422.500000000,3,200,1,1,418.650000000,423.500000000,1,600,1,2,MSFT
2025-01-03T10:30:06.993322051Z,2025-01-03T10:30:06.993154037Z,10,2,11667,T,A,0,139.150000000,100,130,168014,4830408,139.150000000,139.180000000,100,750,1,2,139.120000000,139.200000000,30,129,1,1,139.110000000,139.210000000,1,400,1,1,139.080000000,139.220000000,57,310,1,2,139.050000000,139.230000000,400,25,1,1,139.030000000,139.250000000,126,1,2,1,139.010000000,139.270000000,100,17,1,1,139.000000000,139.300000000,420,507,5,4,138.980000000,139.320000000,300,39,1,1,138.970000000,139.330000000,800,503,2,2,NVDA
2025-01-03T10:30:06.993322051Z,2025-01-03T10:30:06.993154037Z,10,2,11667,C,B,0,139.150000000,100,130,168014,4830408,139.120000000,139.180000000,30,750,1,2,139.110000000,139.200000000,1,129,1,1,139.080000000,139.210000000,57,400,1,1,139.050000000,139.220000000,400,310,1,2,139.030000000,139.230000000,126,25,2,1,139.010000000,139.250000000,100,1,1,1,139.000000000,139.270000000,420,17,5,1,138.980000000,139.300000000,300,507,1,4,138.970000000,139.320000000,800,39,2,1,138.940000000,139.330000000,400,503,1,2,NVDA
2025-01-03T10:30:06.993366794Z,2025-01-03T10:30:06.993200468Z,10,2,11667,A,A,0,139.160000000,100,130,166326,4830411,139.120000000,139.160000000,30,100,1,1,139.110000000,139.180000000,1,750,1,2,139.080000000,139.200000000,57,129,1,1,139.050000000,139.210000000,400,400,1,1,139.030000000,139.220000000,126,310,2,2,139.010000000,139.230000000,100,25,1,1,139.000000000,139.250000000,420,1,5,1,138.980000000,139.270000000,300,17,1,1,138.970000000,139.300000000,800,507,2,4,138.940000000,139.320000000,400,39,1,1,NVDA
2025-01-03T10:30:06.993394472Z,2025-01-03T10:30:06.993228709Z,10,2,11667,C,B,3,139.050000000,400,130,165763,4830418,139.120000000,139.160000000,30,100,1,1,139.110000000,139.180000000,1,750,1,2,139.080000000,139.200000000,57,129,1,1,139.030000000,139.210000000,126,400,2,1,139.010000000,139.220000000,100,310,1,2,139.000000000,139.230000000,420,25,5,1,138.980000000,139.250000000,300,1,1,1,138.970000000,139.270000000,800,17,2,1,138.940000000,139.300000000,400,507,1,4,138.900000000,139.320000000,541,39,4,1,NVDA
2025-01-03T10:30:07.060095010Z,2025-01-03T10:30:07.059928623Z,10,2,11667,A,B,3,139.040000000,400,130,166387,4830542,139.120000000,139.160000000,30,100,1,1,139.110000000,139.180000000,1,750,1,2,139.080000000,139.200000000,57,129,1,1,139.040000000,139.210000000,400,400,1,1,139.030000000,139.220000000,126,310,2,2,139.010000000,139.230000000,100,25,1,1,139.000000000,139.250000000,420,1,5,1,138.980000000,139.270000000,300,17,1,1,138.970000000,139.300000000,800,507,2,4,138.940000000,139.320000000,400,39,1,1,NVDA
2025-01-03T10:30:07.060713410Z,2025-01-03T10:30:07.060547611Z,10,2,11667,C,B,3,139.040000000,400,130,165799,4830543,139.120000000,139.160000000,30,100,1,1,139.110000000,139.180000000,1,750,1,2,139.080000000,139.200000000,57,129,1,1,139.030000000,139.210000000,126,400,2,1,139.010000000,139.220000000,100,310,1,2,139.000000000,139.230000000,420,25,5,1,138.980000000,139.250000000,300,1,1,1,138.970000000,139.270000000,800,17,2,1,138.940000000,139.300000000,400,507,1,4,138.900000000,139.320000000,541,39,4,1,NVDA
2025-01-03T10:30:07.060956176Z,2025-01-03T10:30:07.060789964Z,10,2,11667,A,B,3,139.030000000,400,130,166212,4830544,139.120000000,139.160000000,30,100,1,1,139.110000000,139.180000000,1,750,1,2,139.080000000,139.200000000,57,129,1,1,139.030000000,139.210000000,526,400,3,1,139.010000000,139.220000000,100,310,1,2,139.000000000,139.230000000,420,25,5,1,138.980000000,139.250000000,300,1,1,1,138.970000000,139.270000000,800,17,2,1,138.940000000,139.300000000,400,507,1,4,138.900000000,139.320000000,541,39,4,1,NVDA
2025-01-03T10:30:07.119587464Z,2025-01-03T10:30:07.119420864Z,10,2,11667,A,B,3,139.040000000,400,130,166600,4830551,139.120000000,139.160000000,30,100,1,1,139.110000000,139.180000000,1,750,1,2,139.080000000,139.200000000,57,129,1,1,139.040000000,139.210000000,400,400,1,1,139.030000000,139.220000000,126,310,2,2,139.010000000,139.230000000,100,25,1,1,139.000000000,139.250000000,420,1,5,1,138.980000000,139.270000000,300,17,1,1,138.970000000,139.300000000,800,507,2,4,138.940000000,139.320000000,400,39,1,1,NVDA
2025-01-03T10:30:07.119603822Z,2025-01-03T10:30:07.119437338Z,10,2,11667,A,A,0,139.160000000,400,130,166484,4830552,139.120000000,139.160000000,30,500,1,2,139.110000000,139.180000000,1,350,1,1,139.080000000,139.200000000,57,129,1,1,139.040000000,139.210000000,400,400,1,1,139.030000000,139.220000000,126,310,2,2,139.010000000,139.230000000,100,25,1,1,139.000000000,139.250000000,420,1,5,1,138.980000000,139.270000000,300,17,1,1,138.970000000,139.300000000,800,507,2,4,138.940000000,139.320000000,400,39,1,1,NVDA
2025-01-03T10:30:07.130789364Z,2025-01-03T10:30:07.130623527Z,10,2,11667,C,A,0,139.160000000,400,130,165837,4830558,139.120000000,139.160000000,30,100,1,1,139.110000000,139.180000000,1,350,1,1,139.080000000,139.200000000,57,129,1,1,139.040000000,139.210000000,400,400,1,1,139.030000000,139.220000000,126,310,2,2,139.010000000,139.230000000,100,25,1,1,139.000000000,139.250000000,420,1,5,1,138.980000000,139.270000000,300,17,1,1,138.970000000,139.300000000,800,507,2,4,138.940000000,139.320000000,400,39,1,1,NVDA
2025-01-03T10:30:07.130801503Z,2025-01-03T10:30:07.130635263Z,10,2,11667,A,A,1,139.180000000,400,130,166240,4830559,139.120000000,139.160000000,30,100,1,1,139.110000000,139.180000000,1,750,1,2,139.080000000,139.200000000,57,129,1,1,139.040000000,139.210000000,400,400,1,1,139.030000000,139.220000000,126,310,2,2,139.010000000,139.230000000,100,25,1,1,139.000000000,139.250000000,420,1,5,1,138.980000000,139.270000000,300,17,1,1,138.970000000,139.300000000,800,507,2,4,138.940000000,139.320000000,400,39,1,1,NVDA
2025-01-03T10:30:07.233650000Z,2025-01-03T10:30:07.233483738Z,10,2,11667,A,B,3,139.060000000,400,130,166262,4830586,139.120000000,139.160000000,30,100,1,1,139.110000000,139.180000000,1,750,1,2,139.080000000,139.200000000,57,129,1,1,139.060000000,139.210000000,400,400,1,1,139.030000000,139.220000000,126,310,2,2,139.010000000,139.230000000,100,25,1,1,139.000000000,139.250000000,420,1,5,1,138.980000000,139.270000000,300,17,1,1,138.970000000,139.300000000,800,507,2,4,138.940000000,139.320000000,400,39,1,1,NVDA
2025-01-03T10:30:07.275180647Z,2025-01-03T10:30:07.275014613Z,10,2,9155,C,B,2,241.850000000,8,130,166034,4830631,242.020000000,242.400000000,120,485,1,1,242.000000000,242.460000000,200,8,1,1,241.670000000,242.850000000,2,300,1,2,241.000000000,242.900000000,100,100,1,1,240.000000000,243.000000000,10,92,1,2,239.890000000,243.310000000,82,10,1,1,238.000000000,243.700000000,30,100,1,1,236.000000000,246.810000000,6,100,1,1,235.500000000,262.740000000,5,100,1,1,235.000000000,263.830000000,5,100,1,1,JPM
2025-01-03T10:30:07.277712082Z,2025-01-03T10:30:07.277546370Z,10,2,16244,C,A,0,382.920000000,50,130,165712,4830632,382.710000000,382.990000000,10,1,1,1,382.700000000,383.000000000,50,31,1,2,382.680000000,383.080000000,41,1,2,1,382.230000000,383.090000000,25,6,1,1,382.110000000,383.100000000,300,12,1,2,382.100000000,383.180000000,20,20,2,1,382.010000000,383.300000000,2,120,1,3,382.000000000,383.420000000,1192,140,10,1,381.900000000,383.600000000,23,1000,1,2,381.880000000,383.720000000,10,7085,1,8,TSLA
2025-01-03T10:30:07.279202886Z,2025-01-03T10:30:07.279035713Z,10,2,16244,T,N,0,382.820000000,50,130,167173,4830638,382.710000000,382.990000000,10,1,1,1,382.700000000,383.000000000,50,31,1,2,382.680000000,383.080000000,41,1,2,1,382.230000000,383.090000000,25,6,1,1,382.110000000,383.100000000,300,12,1,2,382.100000000,383.180000000,20,20,2,1,382.010000000,383.300000000,2,120,1,3,382.000000000,383.420000000,1192,140,10,1,381.900000000,383.600000000,23,1000,1,2,381.880000000,383.720000000,10,7085,1,8,TSLA
2025-01-03T10:30:07.569789230Z,2025-01-03T10:30:07.569623437Z,10,2,11667,C,A,1,139.180000000,400,130,165793,4830735,139.120000000,139.160000000,30,100,1,1,139.110000000,139.180000000,1,350,1,1,139.080000000,139.200000000,57,129,1,1,139.060000000,139.210000000,400,400,1,1,139.030000000,139.220000000,126,310,2,2,139.010000000,139.230000000,100,25,1,1,139.000000000,139.250000000,420,1,5,1,138.980000000,139.270000000,300,17,1,1,138.970000000,139.300000000,800,507,2,4,138.940000000,139.320000000,400,39,1,1,NVDA
2025-01-03T10:30:07.569802470Z,2025-01-03T10:30:07.569636310Z,10,2,11667,A,A,2,139.190000000,400,130,166160,4830736,139.120000000,139.160000000,30,100,1,1,139.110000000,139.180000000,1,350,1,1,139.080000000,139.190000000,57,400,1,1,139.060000000,139.200000000,400,129,1,1,139.030000000,139.210000000,126,400,2,1,139.010000000,139.220000000,100,310,1,2,139.000000000,139.230000000,420,25,5,1,138.980000000,139.250000000,300,1,1,1,138.970000000,139.270000000,800,17,2,1,138.940000000,139.300000000,400,507,1,4,NVDA
2025-01-03T10:30:07.670932121Z,2025-01-03T10:30:07.670766129Z,10,2,16244,C,A,5,383.180000000,20,130,165992,4830771,382.710000000,382.990000000,10,1,1,1,382.700000000,383.000000000,50,31,1,2,382.680000000,383.080000000,41,1,2,1,382.230000000,383.090000000,25,6,1,1,382.110000000,383.100000000,300,12,1,2,382.100000000,383.300000000,20,120,2,3,382.010000000,383.420000000,2,140,1,1,382.000000000,383.600000000,1192,1000,10,2,381.900000000,383.720000000,23,7085,1,8,381.880000000,383.800000000,10,10,1,1,TSLA
2025-01-03T10:30:07.670995973Z,2025-01-03T10:30:07.670829865Z,10,2,16244,A,A,5,383.170000000,23,130,166108,4830772,382.710000000,382.990000000,10,1,1,1,382.700000000,383.000000000,50,31,1,2,382.680000000,383.080000000,41,1,2,1,382.230000000,383.090000000,25,6,1,1,382.110000000,383.100000000,300,12,1,2,382.100000000,383.170000000,20,23,2,1,382.010000000,383.300000000,2,120,1,3,382.000000000,383.420000000,1192,140,10,1,381.900000000,383.600000000,23,1000,1,2,381.880000000,383.720000000,10,7085,1,8,TSLA
2025-01-03T10:30:08.216651022Z,2025-01-03T10:30:08.216484848Z,10,2,11667,A,A,4,139.210000000,300,130,166174,4831009,139.120000000,139.160000000,30,100,1,1,139.110000000,139.180000000,1,350,1,1,139.080000000,139.190000000,57,400,1,1,139.060000000,139.200000000,400,129,1,1,139.030000000,139.210000000,126,700,2,2,139.010000000,139.220000000,100,10,1,1,139.000000000,139.230000000,420,25,5,1,138.980000000,139.250000000,300,1,1,1,138.970000000,139.270000000,800,17,2,1,138.940000000,139.300000000,400,507,1,4,NVDA
2025-01-03T10:30:08.411194124Z,2025-01-03T10:30:08.411028209Z,10,2,6905,C,A,0,91.960000000,7,130,165915,4831064,91.520000000,91.960000000,7,100,1,1,91.480000000,93.000000000,150,1,1,1,91.440000000,94.000000000,100,1,1,1,90.000000000,95.000000000,122,2,1,2,89.000000000,96.000000000,1,1,1,1,83.810000000,97.000000000,100,2,1,2,83.400000000,99.950000000,100,100,1,1,,100.360000000,0,100,0,1,,,0,0,0,0,,,0,0,0,0,GILD
2025-01-03T10:30:08.411227505Z,2025-01-03T10:30:08.411060654Z,10,2,6905,A,A,0,91.950000000,7,130,166851,4831065,91.520000000,91.950000000,7,7,1,1,91.480000000,91.960000000,150,100,1,1,91.440000000,93.000000000,100,1,1,1,90.000000000,94.000000000,122,1,1,1,89.000000000,95.000000000,1,2,1,2,83.810000000,96.000000000,100,1,1,1,83.400000000,97.000000000,100,2,1,2,,99.950000000,0,100,0,1,,100.360000000,0,100,0,1,,,0,0,0,0,GILD
2025-01-03T10:30:09.304793202Z,2025-01-03T10:30:09.304626558Z,10,2,11667,A,A,3,139.200000000,300,130,166644,4831279,139.120000000,139.160000000,30,100,1,1,139.110000000,139.180000000,1,350,1,1,139.080000000,139.190000000,57,400,1,1,139.060000000,139.200000000,400,429,1,2,139.030000000,139.210000000,126,400,2,1,139.010000000,139.220000000,100,10,1,1,139.000000000,139.230000000,420,25,5,1,138.980000000,139.250000000,300,1,1,1,138.970000000,139.270000000,800,17,2,1,138.940000000,139.300000000,400,507,1,4,NVDA
2025-01-03T10:30:10.199422075Z,2025-01-03T10:30:10.199255766Z,10,2,11667,A,A,1,139.180000000,400,130,166309,4831770,139.120000000,139.160000000,30,100,1,1,139.110000000,139.180000000,1,750,1,2,139.080000000,139.200000000,57,429,1,2,139.060000000,139.210000000,400,400,1,1,139.030000000,139.220000000,126,10,2,1,139.010000000,139.230000000,100,25,1,1,139.000000000,139.250000000,420,1,5,1,138.980000000,139.270000000,300,17,1,1,138.970000000,139.300000000,800,507,2,4,138.940000000,139.320000000,400,39,1,1,NVDA
2025-01-03T10:30:10.201749640Z,2025-01-03T10:30:10.201583364Z,10,2,6905,A,A,0,91.940000000,7,130,166276,4831781,91.520000000,91.940000000,7,7,1,1,91.480000000,91.950000000,150,7,1,1,91.440000000,91.960000000,100,100,1,1,90.000000000,93.000000000,122,1,1,1,89.000000000,94.000000000,1,1,1,1,83.810000000,95.000000000,100,2,1,2,83.400000000,96.000000000,100,1,1,1,,97.000000000,0,2,0,2,,99.950000000,0,100,0,1,,100.360000000,0,100,0,1,GILD
2025-01-03T10:30:10.201782906Z,2025-01-03T10:30:10.201616730Z,10,2,6905,C,A,1,91.950000000,7,130,166176,4831782,91.520000000,91.940000000,7,7,1,1,91.480000000,91.960000000,150,100,1,1,91.440000000,93.000000000,100,1,1,1,90.000000000,94.000000000,122,1,1,1,89.000000000,95.000000000,1,2,1,2,83.810000000,96.000000000,100,1,1,1,83.400000000,97.000000000,100,2,1,2,,99.950000000,0,100,0,1,,100.360000000,0,100,0,1,,,0,0,0,0,GILD
2025-01-03T10:30:10.345508644Z,2025-01-03T10:30:10.345342247Z,10,2,10888,A,A,0,421.240000000,200,130,166397,4832087,420.710000000,421.240000000,200,200,1,1,420.620000000,421.310000000,15,13,1,1,420.580000000,421.490000000,10,6,1,1,420.520000000,421.570000000,1,40,1,1,420.400000000,421.600000000,858,10,1,1,420.380000000,421.700000000,100,359,1,1,420.100000000,422.100000000,100,7,1,1,420.000000000,422.400000000,534,500,7,1,419.730000000,422.500000000,3,200,1,1,418.650000000,423.500000000,1,600,1,2,MSFT
2025-01-03T10:30:10.369437402Z,2025-01-03T10:30:10.369271365Z,10,2,9155,C,A,1,242.460000000,8,130,166037,4832197,242.020000000,242.400000000,120,485,1,1,242.000000000,242.850000000,200,300,1,2,241.670000000,242.900000000,2,100,1,1,241.000000000,243.000000000,100,92,1,2,240.000000000,243.310000000,10,10,1,1,239.890000000,243.700000000,82,100,1,1,238.000000000,246.810000000,30,100,1,1,236.000000000,262.740000000,6,100,1,1,235.500000000,263.830000000,5,100,1,1,235.000000000,,5,0,1,0,JPM
2025-01-03T10:30:10.369631449Z,2025-01-03T10:30:10.369465285Z,10,2,9155,A,A,1,242.450000000,8,130,166164,4832198,242.020000000,242.400000000,120,485,1,1,242.000000000,242.450000000,200,8,1,1,241.670000000,242.850000000,2,300,1,2,241.000000000,242.900000000,100,100,1,1,240.000000000,243.000000000,10,92,1,2,239.890000000,243.310000000,82,10,1,1,238.000000000,243.700000000,30,100,1,1,236.000000000,246.810000000,6,100,1,1,235.500000000,262.740000000,5,100,1,1,235.000000000,263.830000000,5,100,1,1,JPM
2025-01-03T10:30:10.536469163Z,2025-01-03T10:30:10.536300043Z,10,2,11667,A,B,0,139.130000000,100,130,169120,4832316,139.130000000,139.160000000,100,100,1,1,139.120000000,139.180000000,30,750,1,2,139.110000000,139.200000000,1,429,1,2,139.080000000,139.210000000,57,400,1,1,139.060000000,139.220000000,400,10,1,1,139.030000000,139.230000000,126,25,2,1,139.010000000,139.250000000,100,1,1,1,139.000000000,139.270000000,420,17,5,1,138.980000000,139.300000000,300,507,1,4,138.970000000,139.320000000,800,39,2,1,NVDA
2025-01-03T10:30:10.660625397Z,2025-01-03T10:30:10.660458845Z,10,2,11667,A,B,4,139.070000000,400,130,166552,4832390,139.130000000,139.160000000,100,100,1,1,139.120000000,139.180000000,30,750,1,2,139.110000000,139.200000000,1,429,1,2,139.080000000,139.210000000,57,400,1,1,139.070000000,139.220000000,400,10,1,1,139.030000000,139.230000000,126,25,2,1,139.010000000,139.250000000,100,1,1,1,139.000000000,139.270000000,420,17,5,1,138.980000000,139.300000000,300,507,1,4,138.970000000,139.320000000,800,39,2,1,NVDA
2025-01-03T10:30:10.737209607Z,2025-01-03T10:30:10.737042846Z,10,2,16244,A,B,0,382.710000000,19,130,166761,4832402,382.710000000,382.990000000,29,1,2,1,382.700000000,383.000000000,50,31,1,2,382.680000000,383.080000000,41,1,2,1,382.230000000,383.090000000,25,6,1,1,382.110000000,383.100000000,300,12,1,2,382.100000000,383.170000000,20,23,2,1,382.010000000,383.300000000,2,120,1,3,382.000000000,383.420000000,1192,140,10,1,381.900000000,383.600000000,23,1000,1,2,381.880000000,383.720000000,10,7085,1,8,TSLA
2025-01-03T10:30:11.289344571Z,2025-01-03T10:30:11.289178380Z,10,2,11667,C,A,0,139.160000000,100,130,166191,4832645,139.130000000,139.180000000,100,750,1,2,139.120000000,139.200000000,30,429,1,2,139.110000000,139.210000000,1,400,1,1,139.080000000,139.220000000,57,10,1,1,139.070000000,139.230000000,400,25,1,1,139.030000000,139.250000000,126,1,2,1,139.010000000,139.270000000,100,17,1,1,139.000000000,139.300000000,420,507,5,4,138.980000000,139.320000000,300,39,1,1,138.970000000,139.330000000,800,503,2,2,NVDA
2025-01-03T10:30:11.781248577Z,2025-01-03T10:30:11.781082075Z,10,2,9155,A,B,2,241.790000000,8,130,166502,4832800,242.020000000,242.400000000,120,485,1,1,242.000000000,242.450000000,200,8,1,1,241.790000000,242.850000000,8,300,1,2,241.670000000,242.900000000,2,100,1,1,241.000000000,243.000000000,100,92,1,2,240.000000000,243.310000000,10,10,1,1,239.890000000,243.700000000,82,100,1,1,238.000000000,246.810000000,30,100,1,1,236.000000000,262.740000000,6,100,1,1,235.500000000,263.830000000,5,100,1,1,JPM
2025-01-03T10:30:11.835567694Z,2025-01-03T10:30:11.835401498Z,10,2,17709,A,A,0,107.840000000,200,130,166196,4832807,107.620000000,107.840000000,16,200,1,1,107.600000000,107.870000000,50,642,1,3,107.580000000,107.940000000,100,15,1,1,107.050000000,107.950000000,247,10,1,1,107.000000000,108.000000000,1,150,1,2,106.240000000,108.300000000,28,50,1,1,106.000000000,108.550000000,15,50,2,1,105.870000000,108.800000000,141,50,1,1,103.180000000,108.880000000,16,28,1,1,103.000000000,109.450000000,3,137,1,1,XOM
2025-01-03T10:30:11.835579323Z,2025-01-03T10:30:11.835413325Z,10,2,17709,C,A,1,107.870000000,200,130,165998,4832808,107.620000000,107.840000000,16,200,1,1,107.600000000,107.870000000,50,442,1,2,107.580000000,107.940000000,100,15,1,1,107.050000000,107.950000000,247,10,1,1,107.000000000,108.000000000,1,150,1,2,106.240000000,108.300000000,28,50,1,1,106.000000000,108.550000000,15,50,2,1,105.870000000,108.800000000,141,50,1,1,103.180000000,108.880000000,16,28,1,1,103.000000000,109.450000000,3,137,1,1,XOM
2025-01-03T10:30:11.835602471Z,2025-01-03T10:30:11.835435170Z,10,2,17709,A,A,0,107.840000000,200,130,167301,4832809,107.620000000,107.840000000,16,400,1,2,107.600000000,107.870000000,50,442,1,2,107.580000000,107.940000000,100,15,1,1,107.050000000,107.950000000,247,10,1,1,107.000000000,108.000000000,1,150,1,2,106.240000000,108.300000000,28,50,1,1,106.000000000,108.550000000,15,50,2,1,105.870000000,108.800000000,141,50,1,1,103.180000000,108.880000000,16,28,1,1,103.000000000,109.450000000,3,137,1,1,XOM
2025-01-03T10:30:11.835613707Z,2025-01-03T10:30:11.835447909Z,10,2,17709,C,A,1,107.870000000,200,130,165798,4832810,107.620000000,107.840000000,16,400,1,2,107.600000000,107.870000000,50,242,1,1,107.580000000,107.940000000,100,15,1,1,107.050000000,107.950000000,247,10,1,1,107.000000000,108.000000000,1,150,1,2,106.240000000,108.300000000,28,50,1,1,106.000000000,108.550000000,15,50,2,1,105.870000000,108.800000000,141,50,1,1,103.180000000,108.880000000,16,28,1,1,103.000000000,109.450000000,3,137,1,1,XOM
2025-01-03T10:30:11.835735638Z,2025-01-03T10:30:11.835569567Z,10,2,17709,A,A,0,107.810000000,1,130,166071,4832811,107.620000000,107.810000000,16,1,1,1,107.600000000,107.840000000,50,400,1,2,107.580000000,107.870000000,100,242,1,1,107.050000000,107.940000000,247,15,1,1,107.000000000,107.950000000,1,10,1,1,106.240000000,108.000000000,28,150,1,2,106.000000000,108.300000000,15,50,2,1,105.870000000,108.550000000,141,50,1,1,103.180000000,108.800000000,16,50,1,1,103.000000000,108.880000000,3,28,1,1,XOM
2025-01-03T10:30:11.835749301Z,2025-01-03T10:30:11.835583202Z,10,2,17709,A,A,2,107.860000000,6,130,166099,4832812,107.620000000,107.810000000,16,1,1,1,107.600000000,107.840000000,50,400,1,2,107.580000000,107.860000000,100,6,1,1,107.050000000,107.870000000,247,242,1,1,107.000000000,107.940000000,1,15,1,1,106.240000000,107.950000000,28,10,1,1,106.000000000,108.000000000,15,150,2,2,105.870000000,108.300000000,141,50,1,1,103.180000000,108.550000000,16,50,1,1,103.000000000,108.800000000,3,50,1,1,XOM
2025-01-03T10:30:11.851172384Z,2025-01-03T10:30:11.851006434Z,10,2,17709,C,A,0,107.810000000,1,130,165950,4832818,107.620000000,107.840000000,16,400,1,2,107.600000000,107.860000000,50,6,1,1,107.580000000,107.870000000,100,242,1,1,107.050000000,107.940000000,247,15,1,1,107.000000000,107.950000000,1,10,1,1,106.240000000,108.000000000,28,150,1,2,106.000000000,108.300000000,15,50,2,1,105.870000000,108.550000000,141,50,1,1,103.180000000,108.800000000,16,50,1,1,103.000000000,108.880000000,3,28,1,1,XOM
2025-01-03T10:30:11.891172018Z,2025-01-03T10:30:11.891006039Z,10,2,17709,C,A,1,107.860000000,6,130,165979,4832827,107.620000000,107.840000000,16,400,1,2,107.600000000,107.870000000,50,242,1,1,107.580000000,107.940000000,100,15,1,1,107.050000000,107.950000000,247,10,1,1,107.000000000,108.000000000,1,150,1,2,106.240000000,108.300000000,28,50,1,1,106.000000000,108.550000000,15,50,2,1,105.870000000,108.800000000,141,50,1,1,103.180000000,108.880000000,16,28,1,1,103.000000000,109.450000000,3,137,1,1,XOM
2025-01-03T10:30:11.905170952Z,2025-01-03T10:30:11.905005052Z,10,2,17709,C,B,0,107.620000000,16,130,165900,4832838,107.600000000,107.840000000,50,400,1,2,107.580000000,107.870000000,100,242,1,1,107.050000000,107.940000000,247,15,1,1,107.000000000,107.950000000,1,10,1,1,106.240000000,108.000000000,28,150,1,2,106.000000000,108.300000000,15,50,2,1,105.870000000,108.550000000,141,50,1,1,103.180000000,108.800000000,16,50,1,1,103.000000000,108.880000000,3,28,1,1,102.000000000,109.450000000,2,137,1,1,XOM
2025-01-03T10:30:11.905302270Z,2025-01-03T10:30:11.905136191Z,10,2,17709,A,B,0,107.600000000,16,130,166079,4832839,107.600000000,107.840000000,66,400,2,2,107.580000000,107.870000000,100,242,1,1,107.050000000,107.940000000,247,15,1,1,107.000000000,107.950000000,1,10,1,1,106.240000000,108.000000000,28,150,1,2,106.000000000,108.300000000,15,50,2,1,105.870000000,108.550000000,141,50,1,1,103.180000000,108.800000000,16,50,1,1,103.000000000,108.880000000,3,28,1,1,102.000000000,109.450000000,2,137,1,1,XOM
2025-01-03T10:30:11.905384193Z,2025-01-03T10:30:11.905218334Z,10,2,17709,C,A,2,107.940000000,15,130,165859,4832840,107.600000000,107.840000000,66,400,2,2,107.580000000,107.870000000,100,242,1,1,107.050000000,107.950000000,247,10,1,1,107.000000000,108.000000000,1,150,1,2,106.240000000,108.300000000,28,50,1,1,106.000000000,108.550000000,15,50,2,1,105.870000000,108.800000000,141,50,1,1,103.180000000,108.880000000,16,28,1,1,103.000000000,109.450000000,3,137,1,1,102.000000000,109.500000000,2,100,1,1,XOM
2025-01-03T10:30:11.905445791Z,2025-01-03T10:30:11.905279739Z,10,2,17709,A,A,3,107.980000000,16,130,166052,4832841,107.600000000,107.840000000,66,400,2,2,107.580000000,107.870000000,100,242,1,1,107.050000000,107.950000000,247,10,1,1,107.000000000,107.980000000,1,16,1,1,106.240000000,108.000000000,28,150,1,2,106.000000000,108.300000000,15,50,2,1,105.870000000,108.550000000,141,50,1,1,103.180000000,108.800000000,16,50,1,1,103.000000000,108.880000000,3,28,1,1,102.000000000,109.450000000,2,137,1,1,XOM
2025-01-03T10:30:11.906590702Z,2025-01-03T10:30:11.906424798Z,10,2,17709,C,B,0,107.600000000,16,130,165904,4832842,107.600000000,107.840000000,50,400,1,2,107.580000000,107.870000000,100,242,1,1,107.050000000,107.950000000,247,10,1,1,107.000000000,107.980000000,1,16,1,1,106.240000000,108.000000000,28,150,1,2,106.000000000,108.300000000,15,50,2,1,105.870000000,108.550000000,141,50,1,1,103.180000000,108.800000000,16,50,1,1,103.000000000,108.880000000,3,28,1,1,102.000000000,109.450000000,2,137,1,1,XOM
2025-01-03T10:30:11.911608000Z,2025-01-03T10:30:11.911442010Z,10,2,17709,C,B,1,107.580000000,100,130,165990,4832846,107.600000000,107.840000000,50,400,1,2,107.050000000,107.870000000,247,242,1,1,107.000000000,107.950000000,1,10,1,1,106.240000000,107.980000000,28,16,1,1,106.000000000,108.000000000,15,150,2,2,105.870000000,108.300000000,141,50,1,1,103.180000000,108.550000000,16,50,1,1,103.000000000,108.800000000,3,50,1,1,102.000000000,108.880000000,2,28,1,1,101.000000000,109.450000000,1,137,1,1,XOM
2025-01-03T10:30:11.911621333Z,2025-01-03T10:30:11.911455260Z,10,2,17709,A,B,1,107.520000000,100,130,166073,4832847,107.600000000,107.840000000,50,400,1,2,107.520000000,107.870000000,100,242,1,1,107.050000000,107.950000000,247,10,1,1,107.000000000,107.980000000,1,16,1,1,106.240000000,108.000000000,28,150,1,2,106.000000000,108.300000000,15,50,2,1,105.870000000,108.550000000,141,50,1,1,103.180000000,108.800000000,16,50,1,1,103.000000000,108.880000000,3,28,1,1,102.000000000,109.450000000,2,137,1,1,XOM
2025-01-03T10:30:11.931102762Z,2025-01-03T10:30:11.930936773Z,10,2,16727,C,B,2,313.740000000,62,130,165989,4832860,314.920000000,315.450000000,8,8,1,1,314.860000000,315.640000000,25,25,1,1,313.500000000,320.000000000,1,5,1,1,310.000000000,320.210000000,1,1,1,1,300.000000000,321.950000000,3,2,1,1,290.000000000,344.200000000,2,100,1,1,286.660000000,345.620000000,100,100,1,1,285.250000000,,100,0,1,0,260.000000000,,2,0,1,0,,,0,0,0,0,V
2025-01-03T10:30:11.932221537Z,2025-01-03T10:30:11.932055607Z,10,2,9155,C,B,6,239.890000000,82,130,165930,4832861,242.020000000,242.400000000,120,485,1,1,242.000000000,242.450000000,200,8,1,1,241.790000000,242.850000000,8,300,1,2,241.670000000,242.900000000,2,100,1,1,241.000000000,243.000000000,100,92,1,2,240.000000000,243.310000000,10,10,1,1,238.000000000,243.700000000,30,100,1,1,236.000000000,246.810000000,6,100,1,1,235.500000000,262.740000000,5,100,1,1,235.000000000,263.830000000,5,100,1,1,JPM
2025-01-03T10:30:11.934057418Z,2025-01-03T10:30:11.933891178Z,10,2,11667,C,A,0,139.180000000,350,130,166240,4832863,139.130000000,139.180000000,100,400,1,1,139.120000000,139.200000000,30,429,1,2,139.110000000,139.210000000,1,400,1,1,139.080000000,139.220000000,57,10,1,1,139.070000000,139.230000000,400,25,1,1,139.030000000,139.250000000,126,1,2,1,139.010000000,139.270000000,100,17,1,1,139.000000000,139.300000000,420,507,5,4,138.980000000,139.320000000,300,39,1,1,138.970000000,139.330000000,800,503,2,2,NVDA
2025-01-03T10:30:12.005374229Z,2025-01-03T10:30:12.005207685Z,10,2,17709,C,A,3,107.980000000,16,130,166544,4832930,107.600000000,107.840000000,50,400,1,2,107.520000000,107.870000000,100,242,1,1,107.050000000,107.950000000,247,10,1,1,107.000000000,108.000000000,1,150,1,2,106.240000000,108.300000000,28,50,1,1,106.000000000,108.550000000,15,50,2,1,105.870000000,108.800000000,141,50,1,1,103.180000000,108.880000000,16,28,1,1,103.000000000,109.450000000,3,137,1,1,102.000000000,109.500000000,2,100,1,1,XOM
2025-01-03T10:30:12.028861621Z,2025-01-03T10:30:12.028694714Z,10,2,9155,T,N,0,242.030000000,12,130,166907,4832947,242.020000000,242.400000000,120,485,1,1,242.000000000,242.450000000,200,8,1,1,241.790000000,242.850000000,8,300,1,2,241.670000000,242.900000000,2,100,1,1,241.000000000,243.000000000,100,92,1,2,240.000000000,243.310000000,10,10,1,1,238.000000000,243.700000000,30,100,1,1,236.000000000,246.810000000,6,100,1,1,235.500000000,262.740000000,5,100,1,1,235.000000000,263.830000000,5,100,1,1,JPM
2025-01-03T10:30:12.028886810Z,2025-01-03T10:30:12.028720025Z,10,2,9155,A,A,0,242.220000000,1,130,166785,4832948,242.020000000,242.220000000,120,1,1,1,242.000000000,242.400000000,200,485,1,1,241.790000000,242.450000000,8,8,1,1,241.670000000,242.850000000,2,300,1,2,241.000000000,242.900000000,100,100,1,1,240.000000000,243.000000000,10,92,1,2,238.000000000,243.310000000,30,10,1,1,236.000000000,243.700000000,6,100,1,1,235.500000000,246.810000000,5,100,1,1,235.000000000,262.740000000,5,100,1,1,JPM
2025-01-03T10:30:12.037153293Z,2025-01-03T10:30:12.036986877Z,10,2,9155,C,A,0,242.220000000,1,130,166416,4832966,242.020000000,242.400000000,120,485,1,1,242.000000000,242.450000000,200,8,1,1,241.790000000,242.850000000,8,300,1,2,241.670000000,242.900000000,2,100,1,1,241.000000000,243.000000000,100,92,1,2,240.000000000,243.310000000,10,10,1,1,238.000000000,243.700000000,30,100,1,1,236.000000000,246.810000000,6,100,1,1,235.500000000,262.740000000,5,100,1,1,235.000000000,263.830000000,5,100,1,1,JPM
2025-01-03T10:30:12.040174715Z,2025-01-03T10:30:12.040008426Z,10,2,11667,A,B,0,139.140000000,30,130,166289,4832971,139.140000000,139.180000000,30,400,1,1,139.130000000,139.200000000,100,429,1,2,139.120000000,139.210000000,30,400,1,1,139.110000000,139.220000000,1,10,1,1,139.080000000,139.230000000,57,25,1,1,139.070000000,139.250000000,400,1,1,1,139.030000000,139.270000000,126,17,2,1,139.010000000,139.300000000,100,507,1,4,139.000000000,139.320000000,420,39,5,1,138.980000000,139.330000000,300,503,1,2,NVDA
2025-01-03T10:30:12.202744358Z,2025-01-03T10:30:12.202578367Z,10,2,11667,C,A,0,139.180000000,400,130,165991,4833083,139.140000000,139.200000000,30,429,1,2,139.130000000,139.210000000,100,400,1,1,139.120000000,139.220000000,30,10,1,1,139.110000000,139.230000000,1,25,1,1,139.080000000,139.250000000,57,1,1,1,139.070000000,139.270000000,400,17,1,1,139.030000000,139.300000000,126,507,2,4,139.010000000,139.320000000,100,39,1,1,139.000000000,139.330000000,420,503,5,2,138.980000000,139.340000000,300,11,1,1,NVDA
2025-01-03T10:30:12.202758597Z,2025-01-03T10:30:12.202591718Z,10,2,11667,A,A,0,139.190000000,400,130,166879,4833084,139.140000000,139.190000000,30,400,1,1,139.130000000,139.200000000,100,429,1,2,139.120000000,139.210000000,30,400,1,1,139.110000000,139.220000000,1,10,1,1,139.080000000,139.230000000,57,25,1,1,139.070000000,139.250000000,400,1,1,1,139.030000000,139.270000000,126,17,2,1,139.010000000,139.300000000,100,507,1,4,139.000000000,139.320000000,420,39,5,1,138.980000000,139.330000000,300,503,1,2,NVDA
2025-01-03T10:30:12.202803412Z,2025-01-03T10:30:12.202637273Z,10,2,11667,C,A,0,139.190000000,400,130,166139,4833085,139.140000000,139.200000000,30,429,1,2,139.130000000,139.210000000,100,400,1,1,139.120000000,139.220000000,30,10,1,1,139.110000000,139.230000000,1,25,1,1,139.080000000,139.250000000,57,1,1,1,139.070000000,139.270000000,400,17,1,1,139.030000000,139.300000000,126,507,2,4,139.010000000,139.320000000,100,39,1,1,139.000000000,139.330000000,420,503,5,2,138.980000000,139.340000000,300,11,1,1,NVDA
2025-01-03T10:30:12.202814968Z,2025-01-03T10:30:12.202648732Z,10,2,11667,A,A,1,139.210000000,400,130,166236,4833086,139.140000000,139.200000000,30,429,1,2,139.130000000,139.210000000,100,800,1,2,139.120000000,139.220000000,30,10,1,1,139.110000000,139.230000000,1,25,1,1,139.080000000,139.250000000,57,1,1,1,139.070000000,139.270000000,400,17,1,1,139.030000000,139.300000000,126,507,2,4,139.010000000,139.320000000,100,39,1,1,139.000000000,139.330000000,420,503,5,2,138.980000000,139.340000000,300,11,1,1,NVDA
2025-01-03T10:30:12.203244515Z,2025-01-03T10:30:12.203078445Z,10,2,11667,C,A,9,139.340000000,11,130,166070,4833089,139.140000000,139.200000000,30,429,1,2,139.130000000,139.210000000,100,800,1,2,139.120000000,139.220000000,30,10,1,1,139.110000000,139.230000000,1,25,1,1,139.080000000,139.250000000,57,1,1,1,139.070000000,139.270000000,400,17,1,1,139.030000000,139.300000000,126,507,2,4,139.010000000,139.320000000,100,39,1,1,139.000000000,139.330000000,420,503,5,2,138.980000000,139.360000000,300,4,1,2,NVDA
2025-01-03T10:30:12.256933124Z,2025-01-03T10:30:12.256766244Z,10,2,11667,A,A,0,139.200000000,400,130,166880,4833119,139.140000000,139.200000000,30,829,1,3,139.130000000,139.210000000,100,400,1,1,139.120000000,139.220000000,30,10,1,1,139.110000000,139.230000000,1,25,1,1,139.080000000,139.250000000,57,1,1,1,139.070000000,139.270000000,400,17,1,1,139.030000000,139.300000000,126,507,2,4,139.010000000,139.320000000,100,39,1,1,139.000000000,139.330000000,420,503,5,2,138.980000000,139.360000000,300,4,1,2,NVDA
2025-01-03T10:30:13.352610106Z,2025-01-03T10:30:13.352444040Z,10,2,16244,C,B,0,382.710000000,10,130,166066,4833711,382.710000000,382.990000000,19,1,1,1,382.700000000,383.000000000,50,31,1,2,382.680000000,383.080000000,41,1,2,1,382.230000000,383.090000000,25,6,1,1,382.110000000,383.100000000,300,12,1,2,382.100000000,383.170000000,20,23,2,1,382.010000000,383.300000000,2,120,1,3,382.000000000,383.420000000,1192,140,10,1,381.900000000,383.600000000,23,1000,1,2,381.880000000,383.720000000,10,7085,1,8,TSLA
2025-01-03T10:30:13.415397017Z,2025-01-03T10:30:13.415230279Z,10,2,16244,C,A,5,383.170000000,23,130,166738,4833726,382.710000000,382.990000000,19,1,1,1,382.700000000,383.000000000,50,31,1,2,382.680000000,383.080000000,41,1,2,1,382.230000000,383.090000000,25,6,1,1,382.110000000,383.100000000,300,12,1,2,382.100000000,383.300000000,20,120,2,3,382.010000000,383.420000000,2,140,1,1,382.000000000,383.600000000,1192,1000,10,2,381.900000000,383.720000000,23,7085,1,8,381.880000000,383.740000000,10,37,1,1,TSLA
2025-01-03T10:30:13.415505268Z,2025-01-03T10:30:13.415339019Z,10,2,16244,A,A,5,383.150000000,19,130,166249,4833727,382.710000000,382.990000000,19,1,1,1,382.700000000,383.000000000,50,31,1,2,382.680000000,383.080000000,41,1,2,1,382.230000000,383.090000000,25,6,1,1,382.110000000,383.100000000,300,12,1,2,382.100000000,383.150000000,20,19,2,1,382.010000000,383.300000000,2,120,1,3,382.000000000,383.420000000,1192,140,10,1,381.900000000,383.600000000,23,1000,1,2,381.880000000,383.720000000,10,7085,1,8,TSLA
2025-01-03T10:30:13.818105206Z,2025-01-03T10:30:13.817938784Z,10,2,17709,A,B,0,107.600000000,17,130,166422,4833781,107.600000000,107.840000000,67,400,2,2,107.520000000,107.870000000,100,242,1,1,107.050000000,107.950000000,247,10,1,1,107.000000000,108.000000000,1,150,1,2,106.240000000,108.300000000,28,50,1,1,106.000000000,108.550000000,15,50,2,1,105.870000000,108.800000000,141,50,1,1,103.180000000,108.880000000,16,28,1,1,103.000000000,109.450000000,3,137,1,1,102.000000000,109.500000000,2,100,1,1,XOM
2025-01-03T10:30:13.818148914Z,2025-01-03T10:30:13.817982717Z,10,2,17709,A,A,2,107.900000000,15,130,166197,4833782,107.600000000,107.840000000,67,400,2,2,107.520000000,107.870000000,100,242,1,1,107.050000000,107.900000000,247,15,1,1,107.000000000,107.950000000,1,10,1,1,106.240000000,108.000000000,28,150,1,2,106.000000000,108.300000000,15,50,2,1,105.870000000,108.550000000,141,50,1,1,103.180000000,108.800000000,16,50,1,1,103.000000000,108.880000000,3,28,1,1,102.000000000,109.450000000,2,137,1,1,XOM
2025-01-03T10:30:14.036572419Z,2025-01-03T10:30:14.036405941Z,10,2,10888,A,B,9,419.650000000,39,130,166478,4833803,420.710000000,421.240000000,200,200,1,1,420.620000000,421.310000000,15,13,1,1,420.580000000,421.490000000,10,6,1,1,420.520000000,421.570000000,1,40,1,1,420.400000000,421.600000000,858,10,1,1,420.380000000,421.700000000,100,359,1,1,420.100000000,422.100000000,100,7,1,1,420.000000000,422.400000000,534,500,7,1,419.730000000,422.500000000,3,200,1,1,419.650000000,423.500000000,39,600,1,2,MSFT
2025-01-03T10:30:14.051538544Z,2025-01-03T10:30:14.051372306Z,10,2,10888,A,A,2,421.460000000,39,130,166238,4833810,420.710000000,421.240000000,200,200,1,1,420.620000000,421.310000000,15,13,1,1,420.580000000,421.460000000,10,39,1,1,420.520000000,421.490000000,1,6,1,1,420.400000000,421.570000000,858,40,1,1,420.380000000,421.600000000,100,10,1,1,420.100000000,421.700000000,100,359,1,1,420.000000000,422.100000000,534,7,7,1,419.730000000,422.400000000,3,500,1,1,419.650000000,422.500000000,39,200,1,1,MSFT
2025-01-03T10:30:14.143896645Z,2025-01-03T10:30:14.143730363Z,10,2,11667,A,A,0,139.150000000,337,130,166282,4833865,139.140000000,139.150000000,30,337,1,1,139.130000000,139.200000000,100,829,1,3,139.120000000,139.210000000,30,400,1,1,139.110000000,139.220000000,1,10,1,1,139.080000000,139.230000000,57,25,1,1,139.070000000,139.250000000,400,1,1,1,139.030000000,139.270000000,126,17,2,1,139.010000000,139.300000000,100,507,1,4,139.000000000,139.320000000,420,39,5,1,138.980000000,139.330000000,300,503,1,2,NVDA
2025-01-03T10:30:14.508879235Z,2025-01-03T10:30:14.508713186Z,10,2,16244,A,A,6,383.200000000,1000,130,166049,4834113,382.710000000,382.990000000,19,1,1,1,382.700000000,383.000000000,50,31,1,2,382.680000000,383.080000000,41,1,2,1,382.230000000,383.090000000,25,6,1,1,382.110000000,383.100000000,300,12,1,2,382.100000000,383.150000000,20,19,2,1,382.010000000,383.200000000,2,1000,1,1,382.000000000,383.300000000,1192,120,10,3,381.900000000,383.420000000,23,140,1,1,381.880000000,383.600000000,10,1000,1,2,TSLA
2025-01-03T10:30:14.608038815Z,2025-01-03T10:30:14.607872490Z,10,2,16727,A,B,2,314.420000000,61,130,166325,4834142,314.920000000,315.450000000,8,8,1,1,314.860000000,315.640000000,25,25,1,1,314.420000000,320.000000000,61,5,1,1,313.500000000,320.210000000,1,1,1,1,310.000000000,321.950000000,1,2,1,1,300.000000000,344.200000000,3,100,1,1,290.000000000,345.620000000,2,100,1,1,286.660000000,,100,0,1,0,285.250000000,,100,0,1,0,260.000000000,,2,0,1,0,V
2025-01-03T10:30:14.630192855Z,2025-01-03T10:30:14.630026201Z,10,2,16727,A,A,2,315.750000000,61,130,166654,4834152,314.920000000,315.450000000,8,8,1,1,314.860000000,315.640000000,25,25,1,1,314.420000000,315.750000000,61,61,1,1,313.500000000,320.000000000,1,5,1,1,310.000000000,320.210000000,1,1,1,1,300.000000000,321.950000000,3,2,1,1,290.000000000,344.200000000,2,100,1,1,286.660000000,345.620000000,100,100,1,1,285.250000000,,100,0,1,0,260.000000000,,2,0,1,0,V
2025-01-03T10:30:14.725149283Z,2025-01-03T10:30:14.724982325Z,10,2,9155,A,B,5,240.440000000,82,130,166958,4834194,242.020000000,242.400000000,120,485,1,1,242.000000000,242.450000000,200,8,1,1,241.790000000,242.850000000,8,300,1,2,241.670000000,242.900000000,2,100,1,1,241.000000000,243.000000000,100,92,1,2,240.440000000,243.310000000,82,10,1,1,240.000000000,243.700000000,10,100,1,1,238.000000000,246.810000000,30,100,1,1,236.000000000,262.740000000,6,100,1,1,235.500000000,263.830000000,5,100,1,1,JPM
2025-01-03T10:30:14.751789270Z,2025-01-03T10:30:14.751621886Z,10,2,9155,T,N,0,242.030000000,82,130,167384,4834204,242.020000000,242.400000000,120,485,1,1,242.000000000,242.450000000,200,8,1,1,241.790000000,242.850000000,8,300,1,2,241.670000000,242.900000000,2,100,1,1,241.000000000,243.000000000,100,92,1,2,240.440000000,243.310000000,82,10,1,1,240.000000000,243.700000000,10,100,1,1,238.000000000,246.810000000,30,100,1,1,236.000000000,262.740000000,6,100,1,1,235.500000000,263.830000000,5,100,1,1,JPM
2025-01-03T10:30:14.751818779Z,2025-01-03T10:30:14.751652478Z,10,2,9155,A,A,0,242.220000000,5,130,166301,4834205,242.020000000,242.220000000,120,5,1,1,242.000000000,242.400000000,200,485,1,1,241.790000000,242.450000000,8,8,1,1,241.670000000,242.850000000,2,300,1,2,241.000000000,242.900000000,100,100,1,1,240.440000000,243.000000000,82,92,1,2,240.000000000,243.310000000,10,10,1,1,238.000000000,243.700000000,30,100,1,1,236.000000000,246.810000000,6,100,1,1,235.500000000,262.740000000,5,100,1,1,JPM
2025-01-03T10:30:14.757153095Z,2025-01-03T10:30:14.756986960Z,10,2,9155,C,A,0,242.220000000,5,130,166135,4834206,242.020000000,242.400000000,120,485,1,1,242.000000000,242.450000000,200,8,1,1,241.790000000,242.850000000,8,300,1,2,241.670000000,242.900000000,2,100,1,1,241.000000000,243.000000000,100,92,1,2,240.440000000,243.310000000,82,10,1,1,240.000000000,243.700000000,10,100,1,1,238.000000000,246.810000000,30,100,1,1,236.000000000,262.740000000,6,100,1,1,235.500000000,263.830000000,5,100,1,1,JPM
2025-01-03T10:30:15.035567427Z,2025-01-03T10:30:15.035400701Z,10,2,16244,C,A,4,383.100000000,1,130,166726,4834384,382.710000000,382.990000000,19,1,1,1,382.700000000,383.000000000,50,31,1,2,382.680000000,383.080000000,41,1,2,1,382.230000000,383.090000000,25,6,1,1,382.110000000,383.100000000,300,11,1,1,382.100000000,383.150000000,20,19,2,1,382.010000000,383.200000000,2,1000,1,1,382.000000000,383.300000000,1192,120,10,3,381.900000000,383.420000000,23,140,1,1,381.880000000,383.600000000,10,1000,1,2,TSLA
2025-01-03T10:30:16.643062567Z,2025-01-03T10:30:16.642896346Z,10,2,9155,C,B,2,241.790000000,8,130,166221,4835041,242.020000000,242.400000000,120,485,1,1,242.000000000,242.450000000,200,8,1,1,241.670000000,242.850000000,2,300,1,2,241.000000000,242.900000000,100,100,1,1,240.440000000,243.000000000,82,92,1,2,240.000000000,243.310000000,10,10,1,1,238.000000000,243.700000000,30,100,1,1,236.000000000,246.810000000,6,100,1,1,235.500000000,262.740000000,5,100,1,1,235.000000000,263.830000000,5,100,1,1,JPM
2025-01-03T10:30:16.643136658Z,2025-01-03T10:30:16.642970260Z,10,2,9155,C,A,1,242.450000000,8,130,166398,4835042,242.020000000,242.400000000,120,485,1,1,242.000000000,242.850000000,200,300,1,2,241.670000000,242.900000000,2,100,1,1,241.000000000,243.000000000,100,92,1,2,240.440000000,243.310000000,82,10,1,1,240.000000000,243.700000000,10,100,1,1,238.000000000,246.810000000,30,100,1,1,236.000000000,262.740000000,6,100,1,1,235.500000000,263.830000000,5,100,1,1,235.000000000,,5,0,1,0,JPM
2025-01-03T10:30:16.643158437Z,2025-01-03T10:30:16.642992083Z,10,2,9155,A,B,2,241.890000000,8,130,166354,4835043,242.020000000,242.400000000,120,485,1,1,242.000000000,242.850000000,200,300,1,2,241.890000000,242.900000000,8,100,1,1,241.670000000,243.000000000,2,92,1,2,241.000000000,243.310000000,100,10,1,1,240.440000000,243.700000000,82,100,1,1,240.000000000,246.810000000,10,100,1,1,238.000000000,262.740000000,30,100,1,1,236.000000000,263.830000000,6,100,1,1,235.500000000,,5,0,1,0,JPM
2025-01-03T10:30:16.643203039Z,2025-01-03T10:30:16.643036828Z,10,2,9155,A,A,1,242.500000000,8,130,166211,4835044,242.020000000,242.400000000,120,485,1,1,242.000000000,242.500000000,200,8,1,1,241.890000000,242.850000000,8,300,1,2,241.670000000,242.900000000,2,100,1,1,241.000000000,243.000000000,100,92,1,2,240.440000000,243.310000000,82,10,1,1,240.000000000,243.700000000,10,100,1,1,238.000000000,246.810000000,30,100,1,1,236.000000000,262.740000000,6,100,1,1,235.500000000,263.830000000,5,100,1,1,JPM
2025-01-03T10:30:16.784431552Z,2025-01-03T10:30:16.784265642Z,10,2,9155,C,B,2,241.890000000,8,130,165910,4835080,242.020000000,242.400000000,120,485,1,1,242.000000000,242.500000000,200,8,1,1,241.670000000,242.850000000,2,300,1,2,241.000000000,242.900000000,100,100,1,1,240.440000000,243.000000000,82,92,1,2,240.000000000,243.310000000,10,10,1,1,238.000000000,243.700000000,30,100,1,1,236.000000000,246.810000000,6,100,1,1,235.500000000,262.740000000,5,100,1,1,235.000000000,263.830000000,5,100,1,1,JPM
2025-01-03T10:30:17.113937470Z,2025-01-03T10:30:17.113771267Z,10,2,17709,C,B,0,107.600000000,17,130,166203,4835160,107.600000000,107.840000000,50,400,1,2,107.520000000,107.870000000,100,242,1,1,107.050000000,107.900000000,247,15,1,1,107.000000000,107.950000000,1,10,1,1,106.240000000,108.000000000,28,150,1,2,106.000000000,108.300000000,15,50,2,1,105.870000000,108.550000000,141,50,1,1,103.180000000,108.800000000,16,50,1,1,103.000000000,108.880000000,3,28,1,1,102.000000000,109.450000000,2,137,1,1,XOM
2025-01-03T10:30:17.113995962Z,2025-01-03T10:30:17.113829780Z,10,2,17709,A,B,1,107.580000000,17,130,166182,4835161,107.600000000,107.840000000,50,400,1,2,107.580000000,107.870000000,17,242,1,1,107.520000000,107.900000000,100,15,1,1,107.050000000,107.950000000,247,10,1,1,107.000000000,108.000000000,1,150,1,2,106.240000000,108.300000000,28,50,1,1,106.000000000,108.550000000,15,50,2,1,105.870000000,108.800000000,141,50,1,1,103.180000000,108.880000000,16,28,1,1,103.000000000,109.450000000,3,137,1,1,XOM
2025-01-03T10:30:17.366341878Z,2025-01-03T10:30:17.366175859Z,10,2,10888,C,B,0,420.710000000,200,130,166019,4835265,420.620000000,421.240000000,15,200,1,1,420.580000000,421.310000000,10,13,1,1,420.520000000,421.460000000,1,39,1,1,420.400000000,421.490000000,858,6,1,1,420.380000000,421.570000000,100,40,1,1,420.100000000,421.600000000,100,10,1,1,420.000000000,421.700000000,534,359,7,1,419.730000000,422.100000000,3,7,1,1,419.650000000,422.400000000,39,500,1,1,418.650000000,422.500000000,1,200,1,1,MSFT
2025-01-03T10:30:17.366353930Z,2025-01-03T10:30:17.366187710Z,10,2,10888,A,B,0,420.680000000,200,130,166220,4835266,420.680000000,421.240000000,200,200,1,1,420.620000000,421.310000000,15,13,1,1,420.580000000,421.460000000,10,39,1,1,420.520000000,421.490000000,1,6,1,1,420.400000000,421.570000000,858,40,1,1,420.380000000,421.600000000,100,10,1,1,420.100000000,421.700000000,100,359,1,1,420.000000000,422.100000000,534,7,7,1,419.730000000,422.400000000,3,500,1,1,419.650000000,422.500000000,39,200,1,1,MSFT
2025-01-03T10:30:17.366483591Z,2025-01-03T10:30:17.366317498Z,10,2,38,C,B,1,243.460000000,400,130,166093,4835272,243.500000000,243.650000000,6,61,1,2,243.390000000,243.680000000,27,200,1,1,243.190000000,243.740000000,2,26,1,1,243.020000000,244.000000000,79,1,1,1,243.000000000,244.140000000,1233,79,8,1,242.990000000,244.200000000,1,1000,1,1,242.750000000,244.400000000,30,50,1,1,242.590000000,244.420000000,5,10,1,1,242.280000000,244.580000000,100,100,1,1,242.170000000,245.000000000,100,79,1,2,AAPL
2025-01-03T10:30:17.366495714Z,2025-01-03T10:30:17.366329456Z,10,2,38,A,B,1,243.440000000,400,130,166258,4835273,243.500000000,243.650000000,6,61,1,2,243.440000000,243.680000000,400,200,1,1,243.390000000,243.740000000,27,26,1,1,243.190000000,244.000000000,2,1,1,1,243.020000000,244.140000000,79,79,1,1,243.000000000,244.200000000,1233,1000,8,1,242.990000000,244.400000000,1,50,1,1,242.750000000,244.420000000,30,10,1,1,242.590000000,244.580000000,5,100,1,1,242.280000000,245.000000000,100,79,1,2,AAPL
2025-01-03T10:30:17.424456897Z,2025-01-03T10:30:17.424290810Z,10,2,10888,C,A,1,421.310000000,13,130,166087,4835317,420.680000000,421.240000000,200,200,1,1,420.620000000,421.460000000,15,39,1,1,420.580000000,421.490000000,10,6,1,1,420.520000000,421.570000000,1,40,1,1,420.400000000,421.600000000,858,10,1,1,420.380000000,421.700000000,100,359,1,1,420.100000000,422.100000000,100,7,1,1,420.000000000,422.400000000,534,500,7,1,419.730000000,422.500000000,3,200,1,1,419.650000000,423.500000000,39,600,1,2,MSFT
2025-01-03T10:30:17.424546416Z,2025-01-03T10:30:17.424380051Z,10,2,10888,A,A,1,421.300000000,14,130,166365,4835318,420.680000000,421.240000000,200,200,1,1,420.620000000,421.300000000,15,14,1,1,420.580000000,421.460000000,10,39,1,1,420.520000000,421.490000000,1,6,1,1,420.400000000,421.570000000,858,40,1,1,420.380000000,421.600000000,100,10,1,1,420.100000000,421.700000000,100,359,1,1,420.000000000,422.100000000,534,7,7,1,419.730000000,422.400000000,3,500,1,1,419.650000000,422.500000000,39,200,1,1,MSFT
2025-01-03T10:30:17.426645138Z,2025-01-03T10:30:17.426478412Z,10,2,16727,C,A,0,315.450000000,8,130,166726,4835335,314.920000000,315.640000000,8,25,1,1,314.860000000,315.750000000,25,61,1,1,314.420000000,320.000000000,61,5,1,1,313.500000000,320.210000000,1,1,1,1,310.000000000,321.950000000,1,2,1,1,300.000000000,344.200000000,3,100,1,1,290.000000000,345.620000000,2,100,1,1,286.660000000,,100,0,1,0,285.250000000,,100,0,1,0,260.000000000,,2,0,1,0,V
2025-01-03T10:30:17.426814147Z,2025-01-03T10:30:17.426647901Z,10,2,16727,A,A,0,315.440000000,8,130,166246,4835336,314.920000000,315.440000000,8,8,1,1,314.860000000,315.640000000,25,25,1,1,314.420000000,315.750000000,61,61,1,1,313.500000000,320.000000000,1,5,1,1,310.000000000,320.210000000,1,1,1,1,300.000000000,321.950000000,3,2,1,1,290.000000000,344.200000000,2,100,1,1,286.660000000,345.620000000,100,100,1,1,285.250000000,,100,0,1,0,260.000000000,,2,0,1,0,V
2025-01-03T10:30:17.427230437Z,2025-01-03T10:30:17.427064362Z,10,2,12463,C,A,0,150.810000000,9,130,166075,4835339,150.460000000,150.840000000,1,100,1,1,150.300000000,151.000000000,9,1,1,1,150.260000000,153.280000000,234,10,1,1,150.250000000,163.540000000,1,100,1,1,150.210000000,164.210000000,113,100,2,1,150.020000000,179.000000000,2,5,1,1,150.000000000,,250,0,1,0,149.950000000,,5,0,1,0,149.740000000,,10,0,1,0,149.000000000,,5,0,1,0,PEP
2025-01-03T10:30:17.427292498Z,2025-01-03T10:30:17.427126108Z,10,2,12463,A,A,0,150.800000000,9,130,166390,4835340,150.460000000,150.800000000,1,9,1,1,150.300000000,150.840000000,9,100,1,1,150.260000000,151.000000000,234,1,1,1,150.250000000,153.280000000,1,10,1,1,150.210000000,163.540000000,113,100,2,1,150.020000000,164.210000000,2,100,1,1,150.000000000,179.000000000,250,5,1,1,149.950000000,,5,0,1,0,149.740000000,,10,0,1,0,149.000000000,,5,0,1,0,PEP
2025-01-03T10:30:17.428696659Z,2025-01-03T10:30:17.428530456Z,10,2,10888,A,B,0,420.690000000,200,130,166203,4835352,420.690000000,421.240000000,200,200,1,1,420.620000000,421.300000000,15,14,1,1,420.580000000,421.460000000,10,39,1,1,420.520000000,421.490000000,1,6,1,1,420.400000000,421.570000000,858,40,1,1,420.380000000,421.600000000,100,10,1,1,420.100000000,421.700000000,100,359,1,1,420.000000000,422.100000000,534,7,7,1,419.730000000,422.400000000,3,500,1,1,419.650000000,422.500000000,39,200,1,1,MSFT
2025-01-03T10:30:17.429617112Z,2025-01-03T10:30:17.429450930Z,10,2,38,A,B,1,243.450000000,400,130,166182,4835363,243.500000000,243.650000000,6,61,1,2,243.450000000,243.680000000,400,200,1,1,243.390000000,243.740000000,27,26,1,1,243.190000000,244.000000000,2,1,1,1,243.020000000,244.140000000,79,79,1,1,243.000000000,244.200000000,1233,1000,8,1,242.990000000,244.400000000,1,50,1,1,242.750000000,244.420000000,30,10,1,1,242.590000000,244.580000000,5,100,1,1,242.280000000,245.000000000,100,79,1,2,AAPL
2025-01-03T10:30:17.435541526Z,2025-01-03T10:30:17.435375366Z,10,2,10888,C,B,1,420.620000000,15,130,166160,4835371,420.690000000,421.240000000,200,200,1,1,420.580000000,421.300000000,10,14,1,1,420.520000000,421.460000000,1,39,1,1,420.400000000,421.490000000,858,6,1,1,420.380000000,421.570000000,100,40,1,1,420.100000000,421.600000000,100,10,1,1,420.000000000,421.700000000,534,359,7,1,419.730000000,422.100000000,3,7,1,1,419.650000000,422.400000000,39,500,1,1,418.650000000,422.500000000,1,200,1,1,MSFT
2025-01-03T10:30:17.435598533Z,2025-01-03T10:30:17.435432150Z,10,2,10888,A,B,1,420.650000000,15,130,166383,4835372,420.690000000,421.240000000,200,200,1,1,420.650000000,421.300000000,15,14,1,1,420.580000000,421.460000000,10,39,1,1,420.520000000,421.490000000,1,6,1,1,420.400000000,421.570000000,858,40,1,1,420.380000000,421.600000000,100,10,1,1,420.100000000,421.700000000,100,359,1,1,420.000000000,422.100000000,534,7,7,1,419.730000000,422.400000000,3,500,1,1,419.650000000,422.500000000,39,200,1,1,MSFT
2025-01-03T10:30:17.483509156Z,2025-01-03T10:30:17.483342619Z,10,2,10888,A,B,0,420.710000000,200,130,166537,4835434,420.710000000,421.240000000,200,200,1,1,420.650000000,421.300000000,15,14,1,1,420.580000000,421.460000000,10,39,1,1,420.520000000,421.490000000,1,6,1,1,420.400000000,421.570000000,858,40,1,1,420.380000000,421.600000000,100,10,1,1,420.100000000,421.700000000,100,359,1,1,420.000000000,422.100000000,534,7,7,1,419.730000000,422.400000000,3,500,1,1,419.650000000,422.500000000,39,200,1,1,MSFT
2025-01-03T10:30:17.597160500Z,2025-01-03T10:30:17.596993941Z,10,2,11667,A,A,1,139.190000000,400,130,166559,4835678,139.140000000,139.150000000,30,337,1,1,139.130000000,139.190000000,100,400,1,1,139.120000000,139.200000000,30,429,1,2,139.110000000,139.210000000,1,400,1,1,139.080000000,139.220000000,57,10,1,1,139.070000000,139.230000000,400,25,1,1,139.030000000,139.250000000,126,1,2,1,139.010000000,139.270000000,100,17,1,1,139.000000000,139.300000000,420,507,5,4,138.980000000,139.320000000,300,39,1,1,NVDA
2025-01-03T10:30:17.600473365Z,2025-01-03T10:30:17.600306952Z,10,2,17709,A,A,3,107.940000000,100,130,166413,4835681,107.600000000,107.840000000,50,400,1,2,107.580000000,107.870000000,17,242,1,1,107.520000000,107.900000000,100,15,1,1,107.050000000,107.940000000,247,100,1,1,107.000000000,107.950000000,1,10,1,1,106.240000000,108.000000000,28,50,1,1,106.000000000,108.300000000,15,50,2,1,105.870000000,108.550000000,141,50,1,1,103.180000000,108.800000000,16,50,1,1,103.000000000,108.880000000,3,28,1,1,XOM
2025-01-03T10:30:17.600530946Z,2025-01-03T10:30:17.600364406Z,10,2,10888,A,A,0,421.230000000,200,130,166540,4835682,420.710000000,421.230000000,200,200,1,1,420.650000000,421.300000000,15,14,1,1,420.580000000,421.460000000,10,39,1,1,420.520000000,421.490000000,1,6,1,1,420.400000000,421.570000000,858,40,1,1,420.380000000,421.600000000,100,10,1,1,420.100000000,421.700000000,100,359,1,1,420.000000000,422.100000000,534,7,7,1,419.730000000,422.400000000,3,500,1,1,419.650000000,422.500000000,39,200,1,1,MSFT
2025-01-03T10:30:17.600589106Z,2025-01-03T10:30:17.600422793Z,10,2,16727,A,A,1,315.510000000,25,130,166313,4835684,314.920000000,315.440000000,8,8,1,1,314.860000000,315.510000000,25,25,1,1,314.420000000,315.750000000,61,61,1,1,313.500000000,320.000000000,1,5,1,1,310.000000000,320.210000000,1,1,1,1,300.000000000,321.950000000,3,2,1,1,290.000000000,344.200000000,2,100,1,1,286.660000000,345.620000000,100,100,1,1,285.250000000,,100,0,1,0,260.000000000,,2,0,1,0,V
2025-01-03T10:30:17.601019076Z,2025-01-03T10:30:17.600852598Z,10,2,38,A,A,1,243.670000000,200,130,166478,4835688,243.500000000,243.650000000,6,61,1,2,243.450000000,243.670000000,400,200,1,1,243.390000000,243.740000000,27,26,1,1,243.190000000,244.000000000,2,1,1,1,243.020000000,244.140000000,79,79,1,1,243.000000000,244.200000000,1233,1000,8,1,242.990000000,244.400000000,1,50,1,1,242.750000000,244.420000000,30,10,1,1,242.590000000,244.580000000,5,100,1,1,242.280000000,245.000000000,100,79,1,2,AAPL
2025-01-03T10:30:17.708175732Z,2025-01-03T10:30:17.708008699Z,10,2,11667,A,B,4,139.090000000,400,130,167033,4835842,139.140000000,139.150000000,30,337,1,1,139.130000000,139.190000000,100,400,1,1,139.120000000,139.200000000,30,429,1,2,139.110000000,139.210000000,1,400,1,1,139.090000000,139.220000000,400,10,1,1,139.080000000,139.230000000,57,25,1,1,139.030000000,139.250000000,126,1,2,1,139.010000000,139.270000000,100,17,1,1,139.000000000,139.300000000,420,507,5,4,138.980000000,139.320000000,300,39,1,1,NVDA
2025-01-03T10:30:17.782289490Z,2025-01-03T10:30:17.782117869Z,10,2,11667,T,B,0,139.150000000,70,130,171621,4835932,139.140000000,139.150000000,30,337,1,1,139.130000000,139.190000000,100,400,1,1,139.120000000,139.200000000,30,429,1,2,139.110000000,139.210000000,1,400,1,1,139.090000000,139.220000000,400,10,1,1,139.080000000,139.230000000,57,25,1,1,139.030000000,139.250000000,126,1,2,1,139.010000000,139.270000000,100,17,1,1,139.000000000,139.300000000,420,507,5,4,138.980000000,139.320000000,300,39,1,1,NVDA
2025-01-03T10:30:17.782289490Z,2025-01-03T10:30:17.782117869Z,10,2,11667,C,A,0,139.150000000,70,130,171621,4835932,139.140000000,139.150000000,30,267,1,1,139.130000000,139.190000000,100,400,1,1,139.120000000,139.200000000,30,429,1,2,139.110000000,139.210000000,1,400,1,1,139.090000000,139.220000000,400,10,1,1,139.080000000,139.230000000,57,25,1,1,139.030000000,139.250000000,126,1,2,1,139.010000000,139.270000000,100,17,1,1,139.000000000,139.300000000,420,507,5,4,138.980000000,139.320000000,300,39,1,1,NVDA
2025-01-03T10:30:17.782293573Z,2025-01-03T10:30:17.782122129Z,10,2,11667,T,B,0,139.150000000,70,130,171444,4835933,139.140000000,139.150000000,30,267,1,1,139.130000000,139.190000000,100,400,1,1,139.120000000,139.200000000,30,429,1,2,139.110000000,139.210000000,1,400,1,1,139.090000000,139.220000000,400,10,1,1,139.080000000,139.230000000,57,25,1,1,139.030000000,139.250000000,126,1,2,1,139.010000000,139.270000000,100,17,1,1,139.000000000,139.300000000,420,507,5,4,138.980000000,139.320000000,300,39,1,1,NVDA
2025-01-03T10:30:17.782293573Z,2025-01-03T10:30:17.782122129Z,10,2,11667,C,A,0,139.150000000,70,130,171444,4835933,139.140000000,139.150000000,30,197,1,1,139.130000000,139.190000000,100,400,1,1,139.120000000,139.200000000,30,429,1,2,139.110000000,139.210000000,1,400,1,1,139.090000000,139.220000000,400,10,1,1,139.080000000,139.230000000,57,25,1,1,139.030000000,139.250000000,126,1,2,1,139.010000000,139.270000000,100,17,1,1,139.000000000,139.300000000,420,507,5,4,138.980000000,139.320000000,300,39,1,1,NVDA
2025-01-03T10:30:17.782332902Z,2025-01-03T10:30:17.782166038Z,10,2,11667,T,B,0,139.150000000,70,130,166864,4835934,139.140000000,139.150000000,30,197,1,1,139.130000000,139.190000000,100,400,1,1,139.120000000,139.200000000,30,429,1,2,139.110000000,139.210000000,1,400,1,1,139.090000000,139.220000000,400,10,1,1,139.080000000,139.230000000,57,25,1,1,139.030000000,139.250000000,126,1,2,1,139.010000000,139.270000000,100,17,1,1,139.000000000,139.300000000,420,507,5,4,138.980000000,139.320000000,300,39,1,1,NVDA
2025-01-03T10:30:17.782332902Z,2025-01-03T10:30:17.782166038Z,10,2,11667,C,A,0,139.150000000,70,130,166864,4835934,139.140000000,139.150000000,30,127,1,1,139.130000000,139.190000000,100,400,1,1,139.120000000,139.200000000,30,429,1,2,139.110000000,139.210000000,1,400,1,1,139.090000000,139.220000000,400,10,1,1,139.080000000,139.230000000,57,25,1,1,139.030000000,139.250000000,126,1,2,1,139.010000000,139.270000000,100,17,1,1,139.000000000,139.300000000,420,507,5,4,138.980000000,139.320000000,300,39,1,1,NVDA
2025-01-03T10:30:17.782334888Z,2025-01-03T10:30:17.782167334Z,10,2,11667,T,B,0,139.150000000,58,130,167554,4835935,139.140000000,139.150000000,30,127,1,1,139.130000000,139.190000000,100,400,1,1,139.120000000,139.200000000,30,429,1,2,139.110000000,139.210000000,1,400,1,1,139.090000000,139.220000000,400,10,1,1,139.080000000,139.230000000,57,25,1,1,139.030000000,139.250000000,126,1,2,1,139.010000000,139.270000000,100,17,1,1,139.000000000,139.300000000,420,507,5,4,138.980000000,139.320000000,300,39,1,1,NVDA
2025-01-03T10:30:17.782334888Z,2025-01-03T10:30:17.782167334Z,10,2,11667,C,A,0,139.150000000,58,130,167554,4835935,139.140000000,139.150000000,30,69,1,1,139.130000000,139.190000000,100,400,1,1,139.120000000,139.200000000,30,429,1,2,139.110000000,139.210000000,1,400,1,1,139.090000000,139.220000000,400,10,1,1,139.080000000,139.230000000,57,25,1,1,139.030000000,139.250000000,126,1,2,1,139.010000000,139.270000000,100,17,1,1,139.000000000,139.300000000,420,507,5,4,138.980000000,139.320000000,300,39,1,1,NVDA
2025-01-03T10:30:17.782338714Z,2025-01-03T10:30:17.782169153Z,10,2,11667,T,B,0,139.150000000,54,0,169561,4835937,139.140000000,139.150000000,30,69,1,1,139.130000000,139.190000000,100,400,1,1,139.120000000,139.200000000,30,429,1,2,139.110000000,139.210000000,1,400,1,1,139.090000000,139.220000000,400,10,1,1,139.080000000,139.230000000,57,25,1,1,139.030000000,139.250000000,126,1,2,1,139.010000000,139.270000000,100,17,1,1,139.000000000,139.300000000,420,507,5,4,138.980000000,139.320000000,300,39,1,1,NVDA
2025-01-03T10:30:17.782338714Z,2025-01-03T10:30:17.782169744Z,10,2,11667,T,B,0,139.150000000,15,130,168970,4835938,139.140000000,139.150000000,30,15,1,1,139.130000000,139.190000000,100,400,1,1,139.120000000,139.200000000,30,429,1,2,139.110000000,139.210000000,1,400,1,1,139.090000000,139.220000000,400,10,1,1,139.080000000,139.230000000,57,25,1,1,139.030000000,139.250000000,126,1,2,1,139.010000000,139.270000000,100,17,1,1,139.000000000,139.300000000,420,507,5,4,138.980000000,139.320000000,300,39,1,1,NVDA
2025-01-03T10:30:17.782338714Z,2025-01-03T10:30:17.782169744Z,10,2,11667,C,A,0,139.150000000,15,130,168970,4835938,139.140000000,139.190000000,30,400,1,1,139.130000000,139.200000000,100,429,1,2,139.120000000,139.210000000,30,400,1,1,139.110000000,139.220000000,1,10,1,1,139.090000000,139.230000000,400,25,1,1,139.080000000,139.250000000,57,1,1,1,139.030000000,139.270000000,126,17,2,1,139.010000000,139.300000000,100,507,1,4,139.000000000,139.320000000,420,39,5,1,138.980000000,139.330000000,300,503,1,2,NVDA
2025-01-03T10:30:17.782375986Z,2025-01-03T10:30:17.782208012Z,10,2,11667,C,A,0,139.190000000,400,130,167974,4835945,139.140000000,139.200000000,30,429,1,2,139.130000000,139.210000000,100,400,1,1,139.120000000,139.220000000,30,10,1,1,139.110000000,139.230000000,1,25,1,1,139.090000000,139.250000000,400,1,1,1,139.080000000,139.270000000,57,17,1,1,139.030000000,139.300000000,126,507,2,4,139.010000000,139.320000000,100,39,1,1,139.000000000,139.330000000,420,503,5,2,138.980000000,139.360000000,300,4,1,2,NVDA
2025-01-03T10:30:17.866311491Z,2025-01-03T10:30:17.866145371Z,10,2,16244,C,A,5,383.150000000,19,130,166120,4836058,382.710000000,382.990000000,19,1,1,1,382.700000000,383.000000000,50,31,1,2,382.680000000,383.080000000,41,1,2,1,382.230000000,383.090000000,25,6,1,1,382.110000000,383.100000000,300,11,1,1,382.100000000,383.200000000,20,1000,2,1,382.010000000,383.300000000,2,120,1,3,382.000000000,383.420000000,1192,140,10,1,381.900000000,383.600000000,23,1000,1,2,381.880000000,383.720000000,10,7085,1,8,TSLA
2025-01-03T10:30:17.866376522Z,2025-01-03T10:30:17.866209998Z,10,2,16244,A,A,5,383.140000000,23,130,166524,4836059,382.710000000,382.990000000,19,1,1,1,382.700000000,383.000000000,50,31,1,2,382.680000000,383.080000000,41,1,2,1,382.230000000,383.090000000,25,6,1,1,382.110000000,383.100000000,300,11,1,1,382.100000000,383.140000000,20,23,2,1,382.010000000,383.200000000,2,1000,1,1,382.000000000,383.300000000,1192,120,10,3,381.900000000,383.420000000,23,140,1,1,381.880000000,383.600000000,10,1000,1,2,TSLA
2025-01-03T10:30:17.871622761Z,2025-01-03T10:30:17.871456592Z,10,2,16727,C,B,0,314.920000000,8,130,166169,4836096,314.860000000,315.440000000,25,8,1,1,314.420000000,315.510000000,61,25,1,1,313.500000000,315.750000000,1,61,1,1,310.000000000,320.000000000,1,5,1,1,300.000000000,320.210000000,3,1,1,1,290.000000000,321.950000000,2,2,1,1,286.660000000,344.200000000,100,100,1,1,285.250000000,345.620000000,100,100,1,1,260.000000000,,2,0,1,0,,,0,0,0,0,V
2025-01-03T10:30:17.871653191Z,2025-01-03T10:30:17.871486977Z,10,2,16727,A,B,0,314.890000000,8,130,166214,4836097,314.890000000,315.440000000,8,8,1,1,314.860000000,315.510000000,25,25,1,1,314.420000000,315.750000000,61,61,1,1,313.500000000,320.000000000,1,5,1,1,310.000000000,320.210000000,1,1,1,1,300.000000000,321.950000000,3,2,1,1,290.000000000,344.200000000,2,100,1,1,286.660000000,345.620000000,100,100,1,1,285.250000000,,100,0,1,0,260.000000000,,2,0,1,0,V
2025-01-03T10:30:17.871825706Z,2025-01-03T10:30:17.871659801Z,10,2,9155,C,A,1,242.500000000,8,130,165905,4836098,242.020000000,242.400000000,120,485,1,1,242.000000000,242.850000000,200,300,1,2,241.670000000,242.900000000,2,100,1,1,241.000000000,243.000000000,100,92,1,2,240.440000000,243.310000000,82,10,1,1,240.000000000,243.700000000,10,100,1,1,238.000000000,246.810000000,30,100,1,1,236.000000000,262.740000000,6,100,1,1,235.500000000,263.830000000,5,100,1,1,235.000000000,,5,0,1,0,JPM
2025-01-03T10:30:17.872430903Z,2025-01-03T10:30:17.872264725Z,10,2,9155,A,A,1,242.490000000,8,130,166178,4836104,242.020000000,242.400000000,120,485,1,1,242.000000000,242.490000000,200,8,1,1,241.670000000,242.850000000,2,300,1,2,241.000000000,242.900000000,100,100,1,1,240.440000000,243.000000000,82,92,1,2,240.000000000,243.310000000,10,10,1,1,238.000000000,243.700000000,30,100,1,1,236.000000000,246.810000000,6,100,1,1,235.500000000,262.740000000,5,100,1,1,235.000000000,263.830000000,5,100,1,1,JPM
2025-01-03T10:30:17.873544207Z,2025-01-03T10:30:17.873378364Z,10,2,17709,C,A,2,107.900000000,15,130,165843,4836118,107.600000000,107.840000000,50,400,1,2,107.580000000,107.870000000,17,242,1,1,107.520000000,107.940000000,100,100,1,1,107.050000000,107.950000000,247,10,1,1,107.000000000,108.000000000,1,50,1,1,106.240000000,108.300000000,28,50,1,1,106.000000000,108.550000000,15,50,2,1,105.870000000,108.800000000,141,50,1,1,103.180000000,108.880000000,16,28,1,1,103.000000000,109.450000000,3,137,1,1,XOM
2025-01-03T10:30:17.873663803Z,2025-01-03T10:30:17.873497572Z,10,2,17709,A,A,2,107.890000000,16,130,166231,4836119,107.600000000,107.840000000,50,400,1,2,107.580000000,107.870000000,17,242,1,1,107.520000000,107.890000000,100,16,1,1,107.050000000,107.940000000,247,100,1,1,107.000000000,107.950000000,1,10,1,1,106.240000000,108.000000000,28,50,1,1,106.000000000,108.300000000,15,50,2,1,105.870000000,108.550000000,141,50,1,1,103.180000000,108.800000000,16,50,1,1,103.000000000,108.880000000,3,28,1,1,XOM
2025-01-03T10:30:17.874500154Z,2025-01-03T10:30:17.874333762Z,10,2,38,C,B,2,243.390000000,27,130,166392,4836123,243.500000000,243.650000000,6,61,1,2,243.450000000,243.670000000,400,200,1,1,243.190000000,243.740000000,2,26,1,1,243.020000000,244.000000000,79,1,1,1,243.000000000,244.140000000,1233,79,8,1,242.990000000,244.200000000,1,1000,1,1,242.750000000,244.400000000,30,50,1,1,242.590000000,244.420000000,5,10,1,1,242.280000000,244.580000000,100,100,1,1,242.170000000,245.000000000,100,79,1,2,AAPL
2025-01-03T10:30:17.874532266Z,2025-01-03T10:30:17.874365785Z,10,2,38,A,A,2,243.730000000,26,130,166481,4836124,243.500000000,243.650000000,6,61,1,2,243.450000000,243.670000000,400,200,1,1,243.190000000,243.730000000,2,26,1,1,243.020000000,243.740000000,79,26,1,1,243.000000000,244.000000000,1233,1,8,1,242.990000000,244.140000000,1,79,1,1,242.750000000,244.200000000,30,1000,1,1,242.590000000,244.400000000,5,50,1,1,242.280000000,244.420000000,100,10,1,1,242.170000000,244.580000000,100,100,1,1,AAPL
2025-01-03T10:30:17.875028644Z,2025-01-03T10:30:17.874862357Z,10,2,38,C,A,3,243.740000000,26,130,166287,4836126,243.500000000,243.650000000,6,61,1,2,243.450000000,243.670000000,400,200,1,1,243.190000000,243.730000000,2,26,1,1,243.020000000,244.000000000,79,1,1,1,243.000000000,244.140000000,1233,79,8,1,242.990000000,244.200000000,1,1000,1,1,242.750000000,244.400000000,30,50,1,1,242.590000000,244.420000000,5,10,1,1,242.280000000,244.580000000,100,100,1,1,242.170000000,245.000000000,100,79,1,2,AAPL
2025-01-03T10:30:17.875089514Z,2025-01-03T10:30:17.874922970Z,10,2,38,A,B,2,243.370000000,27,130,166544,4836127,243.500000000,243.650000000,6,61,1,2,243.450000000,243.670000000,400,200,1,1,243.370000000,243.730000000,27,26,1,1,243.190000000,244.000000000,2,1,1,1,243.020000000,244.140000000,79,79,1,1,243.000000000,244.200000000,1233,1000,8,1,242.990000000,244.400000000,1,50,1,1,242.750000000,244.420000000,30,10,1,1,242.590000000,244.580000000,5,100,1,1,242.280000000,245.000000000,100,79,1,2,AAPL
2025-01-03T10:30:17.896229366Z,2025-01-03T10:30:17.896063196Z,10,2,11667,A,A,1,139.210000000,400,130,166170,4836138,139.140000000,139.200000000,30,429,1,2,139.130000000,139.210000000,100,800,1,2,139.120000000,139.220000000,30,10,1,1,139.110000000,139.230000000,1,25,1,1,139.090000000,139.250000000,400,1,1,1,139.080000000,139.270000000,57,17,1,1,139.030000000,139.300000000,126,507,2,4,139.010000000,139.320000000,100,39,1,1,139.000000000,139.330000000,420,503,5,2,138.980000000,139.360000000,300,4,1,2,NVDA
2025-01-03T10:30:17.934331793Z,2025-01-03T10:30:17.934165901Z,10,2,16727,C,A,0,315.440000000,8,130,165892,4836150,314.890000000,315.510000000,8,25,1,1,314.860000000,315.750000000,25,61,1,1,314.420000000,320.000000000,61,5,1,1,313.500000000,320.210000000,1,1,1,1,310.000000000,321.950000000,1,2,1,1,300.000000000,344.200000000,3,100,1,1,290.000000000,345.620000000,2,100,1,1,286.660000000,,100,0,1,0,285.250000000,,100,0,1,0,260.000000000,,2,0,1,0,V
2025-01-03T10:30:17.934391952Z,2025-01-03T10:30:17.934225575Z,10,2,16727,A,A,0,315.430000000,8,130,166377,4836151,314.890000000,315.430000000,8,8,1,1,314.860000000,315.510000000,25,25,1,1,314.420000000,315.750000000,61,61,1,1,313.500000000,320.000000000,1,5,1,1,310.000000000,320.210000000,1,1,1,1,300.000000000,321.950000000,3,2,1,1,290.000000000,344.200000000,2,100,1,1,286.660000000,345.620000000,100,100,1,1,285.250000000,,100,0,1,0,260.000000000,,2,0,1,0,V
2025-01-03T10:30:18.048922753Z,2025-01-03T10:30:18.048756660Z,10,2,10888,C,A,1,421.300000000,14,130,166093,4836213,420.710000000,421.230000000,200,200,1,1,420.650000000,421.460000000,15,39,1,1,420.580000000,421.490000000,10,6,1,1,420.520000000,421.570000000,1,40,1,1,420.400000000,421.600000000,858,10,1,1,420.380000000,421.700000000,100,359,1,1,420.100000000,422.100000000,100,7,1,1,420.000000000,422.400000000,534,500,7,1,419.730000000,422.500000000,3,200,1,1,419.650000000,423.500000000,39,600,1,2,MSFT
2025-01-03T10:30:18.048982983Z,2025-01-03T10:30:18.048816920Z,10,2,10888,A,A,1,421.290000000,13,130,166063,4836214,420.710000000,421.230000000,200,200,1,1,420.650000000,421.290000000,15,13,1,1,420.580000000,421.460000000,10,39,1,1,420.520000000,421.490000000,1,6,1,1,420.400000000,421.570000000,858,40,1,1,420.380000000,421.600000000,100,10,1,1,420.100000000,421.700000000,100,359,1,1,420.000000000,422.100000000,534,7,7,1,419.730000000,422.400000000,3,500,1,1,419.650000000,422.500000000,39,200,1,1,MSFT
2025-01-03T10:30:18.537706526Z,2025-01-03T10:30:18.537540609Z,10,2,16727,C,B,0,314.890000000,8,130,165917,4836564,314.860000000,315.430000000,25,8,1,1,314.420000000,315.510000000,61,25,1,1,313.500000000,315.750000000,1,61,1,1,310.000000000,320.000000000,1,5,1,1,300.000000000,320.210000000,3,1,1,1,290.000000000,321.950000000,2,2,1,1,286.660000000,344.200000000,100,100,1,1,285.250000000,345.620000000,100,100,1,1,260.000000000,,2,0,1,0,,,0,0,0,0,V
2025-01-03T10:30:18.537769248Z,2025-01-03T10:30:18.537603166Z,10,2,16727,A,B,0,314.900000000,8,130,166082,4836565,314.900000000,315.430000000,8,8,1,1,314.860000000,315.510000000,25,25,1,1,314.420000000,315.750000000,61,61,1,1,313.500000000,320.000000000,1,5,1,1,310.000000000,320.210000000,1,1,1,1,300.000000000,321.950000000,3,2,1,1,290.000000000,344.200000000,2,100,1,1,286.660000000,345.620000000,100,100,1,1,285.250000000,,100,0,1,0,260.000000000,,2,0,1,0,V
2025-01-03T10:30:18.540544618Z,2025-01-03T10:30:18.540378390Z,10,2,11667,A,B,4,139.100000000,400,130,166228,4836579,139.140000000,139.200000000,30,429,1,2,139.130000000,139.210000000,100,800,1,2,139.120000000,139.220000000,30,10,1,1,139.110000000,139.230000000,1,25,1,1,139.100000000,139.250000000,400,1,1,1,139.080000000,139.270000000,57,17,1,1,139.030000000,139.300000000,126,507,2,4,139.010000000,139.320000000,100,39,1,1,139.000000000,139.330000000,420,503,5,2,138.980000000,139.360000000,300,4,1,2,NVDA
2025-01-03T10:30:18.656182002Z,2025-01-03T10:30:18.656014739Z,10,2,9155,T,N,0,242.030000000,12,130,167263,4836649,242.020000000,242.400000000,120,485,1,1,242.000000000,242.490000000,200,8,1,1,241.670000000,242.850000000,2,300,1,2,241.000000000,242.900000000,100,100,1,1,240.440000000,243.000000000,82,92,1,2,240.000000000,243.310000000,10,10,1,1,238.000000000,243.700000000,30,100,1,1,236.000000000,246.810000000,6,100,1,1,235.500000000,262.740000000,5,100,1,1,235.000000000,263.830000000,5,100,1,1,JPM
2025-01-03T10:30:18.656206357Z,2025-01-03T10:30:18.656040120Z,10,2,9155,A,A,0,242.220000000,1,130,166237,4836650,242.020000000,242.220000000,120,1,1,1,242.000000000,242.400000000,200,485,1,1,241.670000000,242.490000000,2,8,1,1,241.000000000,242.850000000,100,300,1,2,240.440000000,242.900000000,82,100,1,1,240.000000000,243.000000000,10,92,1,2,238.000000000,243.310000000,30,10,1,1,236.000000000,243.700000000,6,100,1,1,235.500000000,246.810000000,5,100,1,1,235.000000000,262.740000000,5,100,1,1,JPM
2025-01-03T10:30:18.667152648Z,2025-01-03T10:30:18.666986893Z,10,2,9155,C,A,0,242.220000000,1,130,165755,4836653,242.020000000,242.400000000,120,485,1,1,242.000000000,242.490000000,200,8,1,1,241.670000000,242.850000000,2,300,1,2,241.000000000,242.900000000,100,100,1,1,240.440000000,243.000000000,82,92,1,2,240.000000000,243.310000000,10,10,1,1,238.000000000,243.700000000,30,100,1,1,236.000000000,246.810000000,6,100,1,1,235.500000000,262.740000000,5,100,1,1,235.000000000,263.830000000,5,100,1,1,JPM
2025-01-03T10:30:18.704577672Z,2025-01-03T10:30:18.704411803Z,10,2,17709,C,B,2,107.520000000,100,130,165869,4836679,107.600000000,107.840000000,50,400,1,2,107.580000000,107.870000000,17,242,1,1,107.050000000,107.890000000,247,16,1,1,107.000000000,107.940000000,1,100,1,1,106.240000000,107.950000000,28,10,1,1,106.000000000,108.000000000,15,50,2,1,105.870000000,108.300000000,141,50,1,1,103.180000000,108.550000000,16,50,1,1,103.000000000,108.800000000,3,50,1,1,102.000000000,108.880000000,2,28,1,1,XOM
2025-01-03T10:30:18.704635684Z,2025-01-03T10:30:18.704469350Z,10,2,17709,A,A,3,107.940000000,39,130,166334,4836680,107.600000000,107.840000000,50,400,1,2,107.580000000,107.870000000,17,242,1,1,107.050000000,107.890000000,247,16,1,1,107.000000000,107.940000000,1,139,1,2,106.240000000,107.950000000,28,10,1,1,106.000000000,108.000000000,15,50,2,1,105.870000000,108.300000000,141,50,1,1,103.180000000,108.550000000,16,50,1,1,103.000000000,108.800000000,3,50,1,1,102.000000000,108.880000000,2,28,1,1,XOM
2025-01-03T10:30:18.719795558Z,2025-01-03T10:30:18.719629366Z,10,2,17709,C,A,3,107.940000000,39,130,166192,4836685,107.600000000,107.840000000,50,400,1,2,107.580000000,107.870000000,17,242,1,1,107.050000000,107.890000000,247,16,1,1,107.000000000,107.940000000,1,100,1,1,106.240000000,107.950000000,28,10,1,1,106.000000000,108.000000000,15,50,2,1,105.870000000,108.300000000,141,50,1,1,103.180000000,108.550000000,16,50,1,1,103.000000000,108.800000000,3,50,1,1,102.000000000,108.880000000,2,28,1,1,XOM
2025-01-03T10:30:18.747863654Z,2025-01-03T10:30:18.747697544Z,10,2,17709,A,B,2,107.520000000,100,130,166110,4836706,107.600000000,107.840000000,50,400,1,2,107.580000000,107.870000000,17,242,1,1,107.520000000,107.890000000,100,16,1,1,107.050000000,107.940000000,247,100,1,1,107.000000000,107.950000000,1,10,1,1,106.240000000,108.000000000,28,50,1,1,106.000000000,108.300000000,15,50,2,1,105.870000000,108.550000000,141,50,1,1,103.180000000,108.800000000,16,50,1,1,103.000000000,108.880000000,3,28,1,1,XOM
2025-01-03T10:30:18.774093065Z,2025-01-03T10:30:18.773927159Z,10,2,17709,C,B,2,107.520000000,100,130,165906,4836723,107.600000000,107.840000000,50,400,1,2,107.580000000,107.870000000,17,242,1,1,107.050000000,107.890000000,247,16,1,1,107.000000000,107.940000000,1,100,1,1,106.240000000,107.950000000,28,10,1,1,106.000000000,108.000000000,15,50,2,1,105.870000000,108.300000000,141,50,1,1,103.180000000,108.550000000,16,50,1,1,103.000000000,108.800000000,3,50,1,1,102.000000000,108.880000000,2,28,1,1,XOM
2025-01-03T10:30:18.774106925Z,2025-01-03T10:30:18.773940460Z,10,2,17709,A,B,2,107.460000000,100,130,166465,4836724,107.600000000,107.840000000,50,400,1,2,107.580000000,107.870000000,17,242,1,1,107.460000000,107.890000000,100,16,1,1,107.050000000,107.940000000,247,100,1,1,107.000000000,107.950000000,1,10,1,1,106.240000000,108.000000000,28,50,1,1,106.000000000,108.300000000,15,50,2,1,105.870000000,108.550000000,141,50,1,1,103.180000000,108.800000000,16,50,1,1,103.000000000,108.880000000,3,28,1,1,XOM
2025-01-03T10:30:18.774506046Z,2025-01-03T10:30:18.774340113Z,10,2,17709,C,B,1,107.580000000,17,130,165933,4836725,107.600000000,107.840000000,50,400,1,2,107.460000000,107.870000000,100,242,1,1,107.050000000,107.890000000,247,16,1,1,107.000000000,107.940000000,1,100,1,1,106.240000000,107.950000000,28,10,1,1,106.000000000,108.000000000,15,50,2,1,105.870000000,108.300000000,141,50,1,1,103.180000000,108.550000000,16,50,1,1,103.000000000,108.800000000,3,50,1,1,102.000000000,108.880000000,2,28,1,1,XOM
2025-01-03T10:30:18.774643812Z,2025-01-03T10:30:18.774477621Z,10,2,17709,A,A,1,107.870000000,16,130,166191,4836726,107.600000000,107.840000000,50,400,1,2,107.460000000,107.870000000,100,258,1,2,107.050000000,107.890000000,247,16,1,1,107.000000000,107.940000000,1,100,1,1,106.240000000,107.950000000,28,10,1,1,106.000000000,108.000000000,15,50,2,1,105.870000000,108.300000000,141,50,1,1,103.180000000,108.550000000,16,50,1,1,103.000000000,108.800000000,3,50,1,1,102.000000000,108.880000000,2,28,1,1,XOM
2025-01-03T10:30:18.774667248Z,2025-01-03T10:30:18.774501149Z,10,2,17709,C,A,2,107.890000000,16,130,166099,4836727,107.600000000,107.840000000,50,400,1,2,107.460000000,107.870000000,100,258,1,2,107.050000000,107.940000000,247,100,1,1,107.000000000,107.950000000,1,10,1,1,106.240000000,108.000000000,28,50,1,1,106.000000000,108.300000000,15,50,2,1,105.870000000,108.550000000,141,50,1,1,103.180000000,108.800000000,16,50,1,1,103.000000000,108.880000000,3,28,1,1,102.000000000,109.450000000,2,137,1,1,XOM
2025-01-03T10:30:18.831880131Z,2025-01-03T10:30:18.831713593Z,10,2,17709,A,B,1,107.520000000,100,130,166538,4836752,107.600000000,107.840000000,50,400,1,2,107.520000000,107.870000000,100,258,1,2,107.050000000,107.940000000,247,100,1,1,107.000000000,107.950000000,1,10,1,1,106.240000000,108.000000000,28,50,1,1,106.000000000,108.300000000,15,50,2,1,105.870000000,108.550000000,141,50,1,1,103.180000000,108.800000000,16,50,1,1,103.000000000,108.880000000,3,28,1,1,102.000000000,109.450000000,2,137,1,1,XOM
2025-01-03T10:30:19.932326210Z,2025-01-03T10:30:19.932160291Z,10,2,10888,C,B,0,420.710000000,200,130,165919,4837196,420.650000000,421.230000000,15,200,1,1,420.580000000,421.290000000,10,13,1,1,420.520000000,421.460000000,1,39,1,1,420.400000000,421.490000000,858,6,1,1,420.380000000,421.570000000,100,40,1,1,420.100000000,421.600000000,100,10,1,1,420.000000000,421.700000000,534,359,7,1,419.730000000,422.100000000,3,7,1,1,419.650000000,422.400000000,39,500,1,1,418.650000000,422.500000000,1,200,1,1,MSFT
2025-01-03T10:30:19.932339530Z,2025-01-03T10:30:19.932173384Z,10,2,10888,A,B,0,420.680000000,200,130,166146,4837197,420.680000000,421.230000000,200,200,1,1,420.650000000,421.290000000,15,13,1,1,420.580000000,421.460000000,10,39,1,1,420.520000000,421.490000000,1,6,1,1,420.400000000,421.570000000,858,40,1,1,420.380000000,421.600000000,100,10,1,1,420.100000000,421.700000000,100,359,1,1,420.000000000,422.100000000,534,7,7,1,419.730000000,422.400000000,3,500,1,1,419.650000000,422.500000000,39,200,1,1,MSFT
2025-01-03T10:30:20.221105566Z,2025-01-03T10:30:20.220939537Z,10,2,10888,A,B,0,420.690000000,200,130,166029,4837437,420.690000000,421.230000000,200,200,1,1,420.650000000,421.290000000,15,13,1,1,420.580000000,421.460000000,10,39,1,1,420.520000000,421.490000000,1,6,1,1,420.400000000,421.570000000,858,40,1,1,420.380000000,421.600000000,100,10,1,1,420.100000000,421.700000000,100,359,1,1,420.000000000,422.100000000,534,7,7,1,419.730000000,422.400000000,3,500,1,1,419.650000000,422.500000000,39,200,1,1,MSFT
2025-01-03T10:30:21.045774227Z,2025-01-03T10:30:21.045608005Z,10,2,9155,C,B,4,240.440000000,82,130,166222,4838293,242.020000000,242.400000000,120,485,1,1,242.000000000,242.490000000,200,8,1,1,241.670000000,242.850000000,2,300,1,2,241.000000000,242.900000000,100,100,1,1,240.000000000,243.000000000,10,92,1,2,238.000000000,243.310000000,30,10,1,1,236.000000000,243.700000000,6,100,1,1,235.500000000,246.810000000,5,100,1,1,235.000000000,262.740000000,5,100,1,1,232.880000000,263.830000000,1,100,1,1,JPM
2025-01-03T10:30:21.559063166Z,2025-01-03T10:30:21.558895957Z,10,2,9155,T,N,0,242.030000000,12,130,167209,4838483,242.020000000,242.400000000,120,485,1,1,242.000000000,242.490000000,200,8,1,1,241.670000000,242.850000000,2,300,1,2,241.000000000,242.900000000,100,100,1,1,240.000000000,243.000000000,10,92,1,2,238.000000000,243.310000000,30,10,1,1,236.000000000,243.700000000,6,100,1,1,235.500000000,246.810000000,5,100,1,1,235.000000000,262.740000000,5,100,1,1,232.880000000,263.830000000,1,100,1,1,JPM
2025-01-03T10:30:21.559088349Z,2025-01-03T10:30:21.558921970Z,10,2,9155,A,A,0,242.220000000,1,130,166379,4838484,242.020000000,242.220000000,120,1,1,1,242.000000000,242.400000000,200,485,1,1,241.670000000,242.490000000,2,8,1,1,241.000000000,242.850000000,100,300,1,2,240.000000000,242.900000000,10,100,1,1,238.000000000,243.000000000,30,92,1,2,236.000000000,243.310000000,6,10,1,1,235.500000000,243.700000000,5,100,1,1,235.000000000,246.810000000,5,100,1,1,232.880000000,262.740000000,1,100,1,1,JPM
2025-01-03T10:30:21.559808320Z,2025-01-03T10:30:21.559642381Z,10,2,9155,A,A,0,242.220000000,1,130,165939,4838485,242.020000000,242.220000000,120,2,1,2,242.000000000,242.400000000,200,485,1,1,241.670000000,242.490000000,2,8,1,1,241.000000000,242.850000000,100,300,1,2,240.000000000,242.900000000,10,100,1,1,238.000000000,243.000000000,30,92,1,2,236.000000000,243.310000000,6,10,1,1,235.500000000,243.700000000,5,100,1,1,235.000000000,246.810000000,5,100,1,1,232.880000000,262.740000000,1,100,1,1,JPM
2025-01-03T10:30:21.559822587Z,2025-01-03T10:30:21.559656524Z,10,2,9155,A,A,1,242.390000000,1,130,166063,4838486,242.020000000,242.220000000,120,2,1,2,242.000000000,242.390000000,200,1,1,1,241.670000000,242.400000000,2,485,1,1,241.000000000,242.490000000,100,8,1,1,240.000000000,242.850000000,10,300,1,2,238.000000000,242.900000000,30,100,1,1,236.000000000,243.000000000,6,92,1,2,235.500000000,243.310000000,5,10,1,1,235.000000000,243.700000000,5,100,1,1,232.880000000,246.810000000,1,100,1,1,JPM
2025-01-03T10:30:21.567152837Z,2025-01-03T10:30:21.566986878Z,10,2,9155,C,A,0,242.220000000,1,130,165959,4838494,242.020000000,242.220000000,120,1,1,1,242.000000000,242.390000000,200,1,1,1,241.670000000,242.400000000,2,485,1,1,241.000000000,242.490000000,100,8,1,1,240.000000000,242.850000000,10,300,1,2,238.000000000,242.900000000,30,100,1,1,236.000000000,243.000000000,6,92,1,2,235.500000000,243.310000000,5,10,1,1,235.000000000,243.700000000,5,100,1,1,232.880000000,246.810000000,1,100,1,1,JPM
2025-01-03T10:30:21.579734023Z,2025-01-03T10:30:21.579567838Z,10,2,9155,C,A,0,242.220000000,1,130,166185,4838496,242.020000000,242.390000000,120,1,1,1,242.000000000,242.400000000,200,485,1,1,241.670000000,242.490000000,2,8,1,1,241.000000000,242.850000000,100,300,1,2,240.000000000,242.900000000,10,100,1,1,238.000000000,243.000000000,30,92,1,2,236.000000000,243.310000000,6,10,1,1,235.500000000,243.700000000,5,100,1,1,235.000000000,246.810000000,5,100,1,1,232.880000000,262.740000000,1,100,1,1,JPM
2025-01-03T10:30:21.603462118Z,2025-01-03T10:30:21.603296315Z,10,2,10888,C,A,0,421.230000000,200,130,165803,4838513,420.690000000,421.290000000,200,13,1,1,420.650000000,421.460000000,15,39,1,1,420.580000000,421.490000000,10,6,1,1,420.520000000,421.570000000,1,40,1,1,420.400000000,421.600000000,858,10,1,1,420.380000000,421.700000000,100,359,1,1,420.100000000,422.100000000,100,7,1,1,420.000000000,422.400000000,534,500,7,1,419.730000000,422.500000000,3,200,1,1,419.650000000,423.500000000,39,600,1,2,MSFT
2025-01-03T10:30:21.603476333Z,2025-01-03T10:30:21.603309584Z,10,2,10888,A,A,1,421.300000000,200,130,166749,4838514,420.690000000,421.290000000,200,13,1,1,420.650000000,421.300000000,15,200,1,1,420.580000000,421.460000000,10,39,1,1,420.520000000,421.490000000,1,6,1,1,420.400000000,421.570000000,858,40,1,1,420.380000000,421.600000000,100,10,1,1,420.100000000,421.700000000,100,359,1,1,420.000000000,422.100000000,534,7,7,1,419.730000000,422.400000000,3,500,1,1,419.650000000,422.500000000,39,200,1,1,MSFT
2025-01-03T10:30:21.619733907Z,2025-01-03T10:30:21.619567976Z,10,2,9155,C,A,0,242.390000000,1,130,165931,4838521,242.020000000,242.400000000,120,485,1,1,242.000000000,242.490000000,200,8,1,1,241.670000000,242.850000000,2,300,1,2,241.000000000,242.900000000,100,100,1,1,240.000000000,243.000000000,10,92,1,2,238.000000000,243.310000000,30,10,1,1,236.000000000,243.700000000,6,100,1,1,235.500000000,246.810000000,5,100,1,1,235.000000000,262.740000000,5,100,1,1,232.880000000,263.830000000,1,100,1,1,JPM
2025-01-03T10:30:21.622071997Z,2025-01-03T10:30:21.621905612Z,10,2,9155,A,B,2,241.880000000,8,130,166385,4838522,242.020000000,242.400000000,120,485,1,1,242.000000000,242.490000000,200,8,1,1,241.880000000,242.850000000,8,300,1,2,241.670000000,242.900000000,2,100,1,1,241.000000000,243.000000000,100,92,1,2,240.000000000,243.310000000,10,10,1,1,238.000000000,243.700000000,30,100,1,1,236.000000000,246.810000000,6,100,1,1,235.500000000,262.740000000,5,100,1,1,235.000000000,263.830000000,5,100,1,1,JPM
2025-01-03T10:30:21.669166451Z,2025-01-03T10:30:21.668999625Z,10,2,17709,A,B,0,107.650000000,2,130,166826,4838527,107.650000000,107.840000000,2,400,1,2,107.600000000,107.870000000,50,258,1,2,107.520000000,107.940000000,100,100,1,1,107.050000000,107.950000000,247,10,1,1,107.000000000,108.000000000,1,50,1,1,106.240000000,108.300000000,28,50,1,1,106.000000000,108.550000000,15,50,2,1,105.870000000,108.800000000,141,50,1,1,103.180000000,108.880000000,16,28,1,1,103.000000000,109.450000000,3,137,1,1,XOM
2025-01-03T10:30:21.669179641Z,2025-01-03T10:30:21.669013524Z,10,2,17709,A,B,1,107.620000000,7,130,166117,4838528,107.650000000,107.840000000,2,400,1,2,107.620000000,107.870000000,7,258,1,2,107.600000000,107.940000000,50,100,1,1,107.520000000,107.950000000,100,10,1,1,107.050000000,108.000000000,247,50,1,1,107.000000000,108.300000000,1,50,1,1,106.240000000,108.550000000,28,50,1,1,106.000000000,108.800000000,15,50,2,1,105.870000000,108.880000000,141,28,1,1,103.180000000,109.450000000,16,137,1,1,XOM
2025-01-03T10:30:21.681172031Z,2025-01-03T10:30:21.681005997Z,10,2,17709,C,B,0,107.650000000,2,130,166034,4838530,107.620000000,107.840000000,7,400,1,2,107.600000000,107.870000000,50,258,1,2,107.520000000,107.940000000,100,100,1,1,107.050000000,107.950000000,247,10,1,1,107.000000000,108.000000000,1,50,1,1,106.240000000,108.300000000,28,50,1,1,106.000000000,108.550000000,15,50,2,1,105.870000000,108.800000000,141,50,1,1,103.180000000,108.880000000,16,28,1,1,103.000000000,109.450000000,3,137,1,1,XOM
2025-01-03T10:30:21.721172242Z,2025-01-03T10:30:21.721006207Z,10,2,17709,C,B,0,107.620000000,7,130,166035,4838546,107.600000000,107.840000000,50,400,1,2,107.520000000,107.870000000,100,258,1,2,107.050000000,107.940000000,247,100,1,1,107.000000000,107.950000000,1,10,1,1,106.240000000,108.000000000,28,50,1,1,106.000000000,108.300000000,15,50,2,1,105.870000000,108.550000000,141,50,1,1,103.180000000,108.800000000,16,50,1,1,103.000000000,108.880000000,3,28,1,1,102.000000000,109.450000000,2,137,1,1,XOM
2025-01-03T10:30:21.731178074Z,2025-01-03T10:30:21.731011729Z,10,2,17709,A,B,1,107.550000000,15,130,166345,4838547,107.600000000,107.840000000,50,400,1,2,107.550000000,107.870000000,15,258,1,2,107.520000000,107.940000000,100,100,1,1,107.050000000,107.950000000,247,10,1,1,107.000000000,108.000000000,1,50,1,1,106.240000000,108.300000000,28,50,1,1,106.000000000,108.550000000,15,50,2,1,105.870000000,108.800000000,141,50,1,1,103.180000000,108.880000000,16,28,1,1,103.000000000,109.450000000,3,137,1,1,XOM
2025-01-03T10:30:21.788024711Z,2025-01-03T10:30:21.787858640Z,10,2,9155,C,B,2,241.880000000,8,130,166071,4838558,242.020000000,242.400000000,120,485,1,1,242.000000000,242.490000000,200,8,1,1,241.670000000,242.850000000,2,300,1,2,241.000000000,242.900000000,100,100,1,1,240.000000000,243.000000000,10,92,1,2,238.000000000,243.310000000,30,10,1,1,236.000000000,243.700000000,6,100,1,1,235.500000000,246.810000000,5,100,1,1,235.000000000,262.740000000,5,100,1,1,232.880000000,263.830000000,1,100,1,1,JPM
2025-01-03T10:30:22.128504971Z,2025-01-03T10:30:22.128338573Z,10,2,16244,C,A,7,383.300000000,99,130,166398,4838627,382.710000000,382.990000000,19,1,1,1,382.700000000,383.000000000,50,31,1,2,382.680000000,383.080000000,41,1,2,1,382.230000000,383.090000000,25,6,1,1,382.110000000,383.100000000,300,11,1,1,382.100000000,383.140000000,20,23,2,1,382.010000000,383.200000000,2,1000,1,1,382.000000000,383.300000000,1192,21,10,2,381.900000000,383.420000000,23,140,1,1,381.880000000,383.600000000,10,1000,1,2,TSLA
2025-01-03T10:30:22.128537884Z,2025-01-03T10:30:22.128371901Z,10,2,16244,C,A,7,383.300000000,1,130,165983,4838628,382.710000000,382.990000000,19,1,1,1,382.700000000,383.000000000,50,31,1,2,382.680000000,383.080000000,41,1,2,1,382.230000000,383.090000000,25,6,1,1,382.110000000,383.100000000,300,11,1,1,382.100000000,383.140000000,20,23,2,1,382.010000000,383.200000000,2,1000,1,1,382.000000000,383.300000000,1192,20,10,1,381.900000000,383.420000000,23,140,1,1,381.880000000,383.600000000,10,1000,1,2,TSLA
2025-01-03T10:30:22.560527267Z,2025-01-03T10:30:22.560359937Z,10,2,10888,A,B,0,420.700000000,200,130,167330,4838878,420.700000000,421.290000000,200,13,1,1,420.650000000,421.300000000,15,200,1,1,420.580000000,421.460000000,10,39,1,1,420.520000000,421.490000000,1,6,1,1,420.400000000,421.570000000,858,40,1,1,420.380000000,421.600000000,100,10,1,1,420.100000000,421.700000000,100,359,1,1,420.000000000,422.100000000,534,7,7,1,419.730000000,422.400000000,3,500,1,1,419.650000000,422.500000000,39,200,1,1,MSFT
2025-01-03T10:30:23.867264887Z,2025-01-03T10:30:23.867099081Z,10,2,11667,C,A,1,139.210000000,400,130,165806,4839562,139.140000000,139.200000000,30,429,1,2,139.130000000,139.210000000,100,400,1,1,139.120000000,139.220000000,30,10,1,1,139.110000000,139.230000000,1,25,1,1,139.100000000,139.250000000,400,1,1,1,139.080000000,139.270000000,57,17,1,1,139.030000000,139.300000000,126,507,2,4,139.010000000,139.320000000,100,39,1,1,139.000000000,139.330000000,420,503,5,2,138.980000000,139.360000000,300,4,1,2,NVDA
2025-01-03T10:30:23.984211445Z,2025-01-03T10:30:23.984044922Z,10,2,11667,A,A,1,139.210000000,400,130,166523,4839614,139.140000000,139.200000000,30,429,1,2,139.130000000,139.210000000,100,800,1,2,139.120000000,139.220000000,30,10,1,1,139.110000000,139.230000000,1,25,1,1,139.100000000,139.250000000,400,1,1,1,139.080000000,139.270000000,57,17,1,1,139.030000000,139.300000000,126,507,2,4,139.010000000,139.320000000,100,39,1,1,139.000000000,139.330000000,420,503,5,2,138.980000000,139.360000000,300,4,1,2,NVDA
2025-01-03T10:30:24.654864439Z,2025-01-03T10:30:24.654697527Z,10,2,10888,A,A,0,421.210000000,200,130,166912,4839990,420.700000000,421.210000000,200,200,1,1,420.650000000,421.290000000,15,13,1,1,420.580000000,421.460000000,10,39,1,1,420.520000000,421.490000000,1,6,1,1,420.400000000,421.570000000,858,40,1,1,420.380000000,421.600000000,100,10,1,1,420.100000000,421.700000000,100,359,1,1,420.000000000,422.100000000,534,7,7,1,419.730000000,422.400000000,3,500,1,1,419.650000000,422.500000000,39,200,1,1,MSFT
2025-01-03T10:30:25.502086156Z,2025-01-03T10:30:25.501918792Z,10,2,17709,T,N,0,107.830000000,30,130,167364,4840441,107.600000000,107.840000000,50,400,1,2,107.550000000,107.870000000,15,258,1,2,107.520000000,107.940000000,100,100,1,1,107.050000000,107.950000000,247,10,1,1,107.000000000,108.000000000,1,50,1,1,106.240000000,108.300000000,28,50,1,1,106.000000000,108.550000000,15,50,2,1,105.870000000,108.800000000,141,50,1,1,103.180000000,108.880000000,16,28,1,1,103.000000000,109.450000000,3,137,1,1,XOM
2025-01-03T10:30:25.600624614Z,2025-01-03T10:30:25.600458498Z,10,2,38,A,B,5,243.000000000,10,130,166116,4840509,243.500000000,243.650000000,6,61,1,2,243.450000000,243.670000000,400,200,1,1,243.370000000,243.730000000,27,26,1,1,243.190000000,244.000000000,2,1,1,1,243.020000000,244.140000000,79,79,1,1,243.000000000,244.200000000,1243,1000,9,1,242.990000000,244.400000000,1,50,1,1,242.750000000,244.420000000,30,10,1,1,242.590000000,244.580000000,5,100,1,1,242.280000000,245.000000000,100,79,1,2,AAPL
2025-01-03T10:30:26.475101326Z,2025-01-03T10:30:26.474934791Z,10,2,10888,A,A,0,421.200000000,200,130,166535,4841086,420.700000000,421.200000000,200,200,1,1,420.650000000,421.290000000,15,13,1,1,420.580000000,421.460000000,10,39,1,1,420.520000000,421.490000000,1,6,1,1,420.400000000,421.570000000,858,40,1,1,420.380000000,421.600000000,100,10,1,1,420.100000000,421.700000000,100,359,1,1,420.000000000,422.100000000,534,7,7,1,419.730000000,422.400000000,3,500,1,1,419.650000000,422.500000000,39,200,1,1,MSFT
2025-01-03T10:30:26.475733472Z,2025-01-03T10:30:26.475566954Z,10,2,9155,A,B,2,241.890000000,8,130,166518,4841091,242.020000000,242.400000000,120,485,1,1,242.000000000,242.490000000,200,8,1,1,241.890000000,242.850000000,8,300,1,2,241.670000000,242.900000000,2,100,1,1,241.000000000,243.000000000,100,92,1,2,240.000000000,243.310000000,10,10,1,1,238.000000000,243.700000000,30,100,1,1,236.000000000,246.810000000,6,100,1,1,235.500000000,262.740000000,5,100,1,1,235.000000000,263.830000000,5,100,1,1,JPM
2025-01-03T10:30:26.614117511Z,2025-01-03T10:30:26.613951361Z,10,2,10888,A,A,0,421.190000000,200,130,166150,4841205,420.700000000,421.190000000,200,200,1,1,420.650000000,421.290000000,15,13,1,1,420.580000000,421.460000000,10,39,1,1,420.520000000,421.490000000,1,6,1,1,420.400000000,421.570000000,858,40,1,1,420.380000000,421.600000000,100,10,1,1,420.100000000,421.700000000,100,359,1,1,420.000000000,422.100000000,534,7,7,1,419.730000000,422.400000000,3,500,1,1,419.650000000,422.500000000,39,200,1,1,MSFT
2025-01-03T10:30:26.647113736Z,2025-01-03T10:30:26.646947617Z,10,2,11667,A,B,0,139.150000000,50,130,166119,4841302,139.150000000,139.200000000,50,429,1,2,139.140000000,139.210000000,30,800,1,2,139.130000000,139.220000000,100,10,1,1,139.120000000,139.230000000,30,25,1,1,139.110000000,139.250000000,1,1,1,1,139.100000000,139.270000000,400,17,1,1,139.080000000,139.300000000,57,507,1,4,139.030000000,139.320000000,126,39,2,1,139.010000000,139.330000000,100,503,1,2,139.000000000,139.360000000,420,4,5,2,NVDA
2025-01-03T10:30:26.791606520Z,2025-01-03T10:30:26.791440695Z,10,2,9155,C,B,2,241.890000000,8,130,165825,4841378,242.020000000,242.400000000,120,485,1,1,242.000000000,242.490000000,200,8,1,1,241.670000000,242.850000000,2,300,1,2,241.000000000,242.900000000,100,100,1,1,240.000000000,243.000000000,10,92,1,2,238.000000000,243.310000000,30,10,1,1,236.000000000,243.700000000,6,100,1,1,235.500000000,246.810000000,5,100,1,1,235.000000000,262.740000000,5,100,1,1,232.880000000,263.830000000,1,100,1,1,JPM
2025-01-03T10:30:26.909173859Z,2025-01-03T10:30:26.909007849Z,10,2,10888,C,B,0,420.700000000,200,130,166010,4841439,420.650000000,421.190000000,15,200,1,1,420.580000000,421.290000000,10,13,1,1,420.520000000,421.460000000,1,39,1,1,420.400000000,421.490000000,858,6,1,1,420.380000000,421.570000000,100,40,1,1,420.100000000,421.600000000,100,10,1,1,420.000000000,421.700000000,534,359,7,1,419.730000000,422.100000000,3,7,1,1,419.650000000,422.400000000,39,500,1,1,418.650000000,422.500000000,1,200,1,1,MSFT
2025-01-03T10:30:26.909927309Z,2025-01-03T10:30:26.909761179Z,10,2,10888,A,B,1,420.580000000,14,130,166130,4841442,420.650000000,421.190000000,15,200,1,1,420.580000000,421.290000000,24,13,2,1,420.520000000,421.460000000,1,39,1,1,420.400000000,421.490000000,858,6,1,1,420.380000000,421.570000000,100,40,1,1,420.100000000,421.600000000,100,10,1,1,420.000000000,421.700000000,534,359,7,1,419.730000000,422.100000000,3,7,1,1,419.650000000,422.400000000,39,500,1,1,418.650000000,422.500000000,1,200,1,1,MSFT
2025-01-03T10:30:26.909955136Z,2025-01-03T10:30:26.909789122Z,10,2,10888,C,B,0,420.650000000,15,130,166014,4841443,420.580000000,421.190000000,24,200,2,1,420.520000000,421.290000000,1,13,1,1,420.400000000,421.460000000,858,39,1,1,420.380000000,421.490000000,100,6,1,1,420.100000000,421.570000000,100,40,1,1,420.000000000,421.600000000,534,10,7,1,419.730000000,421.700000000,3,359,1,1,419.650000000,422.100000000,39,7,1,1,418.650000000,422.400000000,1,500,1,1,418.500000000,422.500000000,1,200,1,1,MSFT
2025-01-03T10:30:26.966168918Z,2025-01-03T10:30:26.966002604Z,10,2,10888,A,B,1,420.540000000,200,130,166314,4841459,420.580000000,421.190000000,24,200,2,1,420.540000000,421.290000000,200,13,1,1,420.520000000,421.460000000,1,39,1,1,420.400000000,421.490000000,858,6,1,1,420.380000000,421.570000000,100,40,1,1,420.100000000,421.600000000,100,10,1,1,420.000000000,421.700000000,534,359,7,1,419.730000000,422.100000000,3,7,1,1,419.650000000,422.400000000,39,500,1,1,418.650000000,422.500000000,1,200,1,1,MSFT
2025-01-03T10:30:28.546495385Z,2025-01-03T10:30:28.546328644Z,10,2,16244,A,B,0,382.810000000,10,130,166741,4842301,382.810000000,382.990000000,10,1,1,1,382.710000000,383.000000000,19,31,1,2,382.700000000,383.080000000,50,1,1,1,382.680000000,383.090000000,41,6,2,1,382.230000000,383.100000000,25,11,1,1,382.110000000,383.140000000,300,23,1,1,382.100000000,383.200000000,20,1000,2,1,382.010000000,383.300000000,2,20,1,1,382.000000000,383.420000000,1192,140,10,1,381.900000000,383.600000000,23,1000,1,2,TSLA
2025-01-03T10:30:28.609270424Z,2025-01-03T10:30:28.609104528Z,10,2,16244,C,B,1,382.710000000,19,130,165896,4842306,382.810000000,382.990000000,10,1,1,1,382.700000000,383.000000000,50,31,1,2,382.680000000,383.080000000,41,1,2,1,382.230000000,383.090000000,25,6,1,1,382.110000000,383.100000000,300,11,1,1,382.100000000,383.140000000,20,23,2,1,382.010000000,383.200000000,2,1000,1,1,382.000000000,383.300000000,1192,20,10,1,381.900000000,383.420000000,23,140,1,1,381.880000000,383.600000000,10,1000,1,2,TSLA
2025-01-03T10:30:28.609303349Z,2025-01-03T10:30:28.609137445Z,10,2,16244,C,B,2,382.680000000,21,130,165904,4842307,382.810000000,382.990000000,10,1,1,1,382.700000000,383.000000000,50,31,1,2,382.680000000,383.080000000,20,1,1,1,382.230000000,383.090000000,25,6,1,1,382.110000000,383.100000000,300,11,1,1,382.100000000,383.140000000,20,23,2,1,382.010000000,383.200000000,2,1000,1,1,382.000000000,383.300000000,1192,20,10,1,381.900000000,383.420000000,23,140,1,1,381.880000000,383.600000000,10,1000,1,2,TSLA
2025-01-03T10:30:28.609373586Z,2025-01-03T10:30:28.609207519Z,10,2,16244,A,B,1,382.750000000,22,130,166067,4842308,382.810000000,382.990000000,10,1,1,1,382.750000000,383.000000000,22,31,1,2,382.700000000,383.080000000,50,1,1,1,382.680000000,383.090000000,20,6,1,1,382.230000000,383.100000000,25,11,1,1,382.110000000,383.140000000,300,23,1,1,382.100000000,383.200000000,20,1000,2,1,382.010000000,383.300000000,2,20,1,1,382.000000000,383.420000000,1192,140,10,1,381.900000000,383.600000000,23,1000,1,2,TSLA
2025-01-03T10:30:29.785819515Z,2025-01-03T10:30:29.785653070Z,10,2,6905,A,A,0,91.930000000,7,130,166445,4842825,91.520000000,91.930000000,7,7,1,1,91.480000000,91.940000000,150,7,1,1,91.440000000,91.960000000,100,100,1,1,90.000000000,93.000000000,122,1,1,1,89.000000000,94.000000000,1,1,1,1,83.810000000,95.000000000,100,2,1,2,83.400000000,96.000000000,100,1,1,1,,97.000000000,0,2,0,2,,99.950000000,0,100,0,1,,100.360000000,0,100,0,1,GILD
2025-01-03T10:30:29.785854038Z,2025-01-03T10:30:29.785687920Z,10,2,6905,C,A,1,91.940000000,7,130,166118,4842826,91.520000000,91.930000000,7,7,1,1,91.480000000,91.960000000,150,100,1,1,91.440000000,93.000000000,100,1,1,1,90.000000000,94.000000000,122,1,1,1,89.000000000,95.000000000,1,2,1,2,83.810000000,96.000000000,100,1,1,1,83.400000000,97.000000000,100,2,1,2,,99.950000000,0,100,0,1,,100.360000000,0,100,0,1,,,0,0,0,0,GILD
2025-01-03T10:30:29.910153957Z,2025-01-03T10:30:29.909988067Z,10,2,10888,C,B,0,420.580000000,14,130,165890,4842999,420.580000000,421.190000000,10,200,1,1,420.540000000,421.290000000,200,13,1,1,420.520000000,421.460000000,1,39,1,1,420.400000000,421.490000000,858,6,1,1,420.380000000,421.570000000,100,40,1,1,420.100000000,421.600000000,100,10,1,1,420.000000000,421.700000000,534,359,7,1,419.730000000,422.100000000,3,7,1,1,419.650000000,422.400000000,39,500,1,1,418.650000000,422.500000000,1,200,1,1,MSFT
2025-01-03T10:30:29.910213328Z,2025-01-03T10:30:29.910047190Z,10,2,10888,A,B,0,420.630000000,13,130,166138,4843001,420.630000000,421.190000000,13,200,1,1,420.580000000,421.290000000,10,13,1,1,420.540000000,421.460000000,200,39,1,1,420.520000000,421.490000000,1,6,1,1,420.400000000,421.570000000,858,40,1,1,420.380000000,421.600000000,100,10,1,1,420.100000000,421.700000000,100,359,1,1,420.000000000,422.100000000,534,7,7,1,419.730000000,422.400000000,3,500,1,1,419.650000000,422.500000000,39,200,1,1,MSFT
2025-01-03T10:30:29.964580446Z,2025-01-03T10:30:29.964414017Z,10,2,10888,A,B,0,420.710000000,200,130,166429,4843062,420.710000000,421.190000000,200,200,1,1,420.630000000,421.290000000,13,13,1,1,420.580000000,421.460000000,10,39,1,1,420.520000000,421.490000000,1,6,1,1,420.400000000,421.570000000,858,40,1,1,420.380000000,421.600000000,100,10,1,1,420.100000000,421.700000000,100,359,1,1,420.000000000,422.100000000,534,7,7,1,419.730000000,422.400000000,3,500,1,1,419.650000000,422.500000000,39,200,1,1,MSFT
2025-01-03T10:30:30.045194402Z,2025-01-03T10:30:30.045027660Z,10,2,11667,C,A,1,139.210000000,400,130,166742,4843104,139.150000000,139.200000000,50,429,1,2,139.140000000,139.210000000,30,400,1,1,139.130000000,139.220000000,100,10,1,1,139.120000000,139.230000000,30,25,1,1,139.110000000,139.250000000,1,1,1,1,139.100000000,139.270000000,400,17,1,1,139.080000000,139.300000000,57,507,1,4,139.030000000,139.320000000,126,39,2,1,139.010000000,139.330000000,100,503,1,2,139.000000000,139.360000000,420,4,5,2,NVDA
2025-01-03T10:30:30.046442814Z,2025-01-03T10:30:30.046273762Z,10,2,11667,T,N,0,139.160000000,100,0,169052,4843105,139.150000000,139.200000000,50,429,1,2,139.140000000,139.210000000,30,400,1,1,139.130000000,139.220000000,100,10,1,1,139.120000000,139.230000000,30,25,1,1,139.110000000,139.250000000,1,1,1,1,139.100000000,139.270000000,400,17,1,1,139.080000000,139.300000000,57,507,1,4,139.030000000,139.320000000,126,39,2,1,139.010000000,139.330000000,100,503,1,2,139.000000000,139.360000000,420,4,5,2,NVDA
2025-01-03T10:30:30.046442814Z,2025-01-03T10:30:30.046273762Z,10,2,11667,A,A,0,139.160000000,300,130,169052,4843106,139.150000000,139.160000000,50,300,1,1,139.140000000,139.200000000,30,429,1,2,139.130000000,139.210000000,100,400,1,1,139.120000000,139.220000000,30,10,1,1,139.110000000,139.230000000,1,25,1,1,139.100000000,139.250000000,400,1,1,1,139.080000000,139.270000000,57,17,1,1,139.030000000,139.300000000,126,507,2,4,139.010000000,139.320000000,100,39,1,1,139.000000000,139.330000000,420,503,5,2,NVDA
2025-01-03T10:30:30.750863316Z,2025-01-03T10:30:30.750695519Z,10,2,9155,T,A,0,242.020000000,14,130,167797,4843651,242.020000000,242.400000000,120,485,1,1,242.000000000,242.490000000,200,8,1,1,241.670000000,242.850000000,2,300,1,2,241.000000000,242.900000000,100,100,1,1,240.000000000,243.000000000,10,92,1,2,238.000000000,243.310000000,30,10,1,1,236.000000000,243.700000000,6,100,1,1,235.500000000,246.810000000,5,100,1,1,235.000000000,262.740000000,5,100,1,1,232.880000000,263.830000000,1,100,1,1,JPM
2025-01-03T10:30:30.750863316Z,2025-01-03T10:30:30.750695519Z,10,2,9155,C,B,0,242.020000000,14,130,167797,4843651,242.020000000,242.400000000,106,485,1,1,242.000000000,242.490000000,200,8,1,1,241.670000000,242.850000000,2,300,1,2,241.000000000,242.900000000,100,100,1,1,240.000000000,243.000000000,10,92,1,2,238.000000000,243.310000000,30,10,1,1,236.000000000,243.700000000,6,100,1,1,235.500000000,246.810000000,5,100,1,1,235.000000000,262.740000000,5,100,1,1,232.880000000,263.830000000,1,100,1,1,JPM
2025-01-03T10:30:30.775346244Z,2025-01-03T10:30:30.775179994Z,10,2,17709,A,B,0,107.650000000,2,130,166250,4843653,107.650000000,107.840000000,2,400,1,2,107.600000000,107.870000000,50,258,1,2,107.550000000,107.940000000,15,100,1,1,107.520000000,107.950000000,100,10,1,1,107.050000000,108.000000000,247,50,1,1,107.000000000,108.300000000,1,50,1,1,106.240000000,108.550000000,28,50,1,1,106.000000000,108.800000000,15,50,2,1,105.870000000,108.880000000,141,28,1,1,103.180000000,109.450000000,16,137,1,1,XOM
2025-01-03T10:30:30.775358109Z,2025-01-03T10:30:30.775192094Z,10,2,17709,A,B,1,107.620000000,8,130,166015,4843654,107.650000000,107.840000000,2,400,1,2,107.620000000,107.870000000,8,258,1,2,107.600000000,107.940000000,50,100,1,1,107.550000000,107.950000000,15,10,1,1,107.520000000,108.000000000,100,50,1,1,107.050000000,108.300000000,247,50,1,1,107.000000000,108.550000000,1,50,1,1,106.240000000,108.800000000,28,50,1,1,106.000000000,108.880000000,15,28,2,1,105.870000000,109.450000000,141,137,1,1,XOM
2025-01-03T10:30:30.791173244Z,2025-01-03T10:30:30.791007192Z,10,2,17709,C,B,0,107.650000000,2,130,166052,4843655,107.620000000,107.840000000,8,400,1,2,107.600000000,107.870000000,50,258,1,2,107.550000000,107.940000000,15,100,1,1,107.520000000,107.950000000,100,10,1,1,107.050000000,108.000000000,247,50,1,1,107.000000000,108.300000000,1,50,1,1,106.240000000,108.550000000,28,50,1,1,106.000000000,108.800000000,15,50,2,1,105.870000000,108.880000000,141,28,1,1,103.180000000,109.450000000,16,137,1,1,XOM
2025-01-03T10:30:30.831171807Z,2025-01-03T10:30:30.831006080Z,10,2,17709,C,B,0,107.620000000,8,130,165727,4843674,107.600000000,107.840000000,50,400,1,2,107.550000000,107.870000000,15,258,1,2,107.520000000,107.940000000,100,100,1,1,107.050000000,107.950000000,247,10,1,1,107.000000000,108.000000000,1,50,1,1,106.240000000,108.300000000,28,50,1,1,106.000000000,108.550000000,15,50,2,1,105.870000000,108.800000000,141,50,1,1,103.180000000,108.880000000,16,28,1,1,103.000000000,109.450000000,3,137,1,1,XOM
2025-01-03T10:30:31.189002545Z,2025-01-03T10:30:31.188836236Z,10,2,9155,A,B,4,240.980000000,82,130,166309,4843881,242.020000000,242.400000000,106,485,1,1,242.000000000,242.490000000,200,8,1,1,241.670000000,242.850000000,2,300,1,2,241.000000000,242.900000000,100,100,1,1,240.980000000,243.000000000,82,92,1,2,240.000000000,243.310000000,10,10,1,1,238.000000000,243.700000000,30,100,1,1,236.000000000,246.810000000,6,100,1,1,235.500000000,262.740000000,5,100,1,1,235.000000000,263.830000000,5,100,1,1,JPM
2025-01-03T10:30:31.205867556Z,2025-01-03T10:30:31.205700977Z,10,2,9155,A,A,0,242.070000000,82,130,166579,4843891,242.020000000,242.070000000,106,82,1,1,242.000000000,242.400000000,200,485,1,1,241.670000000,242.490000000,2,8,1,1,241.000000000,242.850000000,100,300,1,2,240.980000000,242.900000000,82,100,1,1,240.000000000,243.000000000,10,92,1,2,238.000000000,243.310000000,30,10,1,1,236.000000000,243.700000000,6,100,1,1,235.500000000,246.810000000,5,100,1,1,235.000000000,262.740000000,5,100,1,1,JPM
2025-01-03T10:30:31.205896761Z,2025-01-03T10:30:31.205730159Z,10,2,9155,T,B,0,242.070000000,20,130,166602,4843894,242.020000000,242.070000000,106,82,1,1,242.000000000,242.400000000,200,485,1,1,241.670000000,242.490000000,2,8,1,1,241.000000000,242.850000000,100,300,1,2,240.980000000,242.900000000,82,100,1,1,240.000000000,243.000000000,10,92,1,2,238.000000000,243.310000000,30,10,1,1,236.000000000,243.700000000,6,100,1,1,235.500000000,246.810000000,5,100,1,1,235.000000000,262.740000000,5,100,1,1,JPM
2025-01-03T10:30:31.205896761Z,2025-01-03T10:30:31.205730159Z,10,2,9155,C,A,0,242.070000000,20,130,166602,4843894,242.020000000,242.070000000,106,62,1,1,242.000000000,242.400000000,200,485,1,1,241.670000000,242.490000000,2,8,1,1,241.000000000,242.850000000,100,300,1,2,240.980000000,242.900000000,82,100,1,1,240.000000000,243.000000000,10,92,1,2,238.000000000,243.310000000,30,10,1,1,236.000000000,243.700000000,6,100,1,1,235.500000000,246.810000000,5,100,1,1,235.000000000,262.740000000,5,100,1,1,JPM
2025-01-03T10:30:31.206281904Z,2025-01-03T10:30:31.206114402Z,10,2,9155,T,N,0,242.060000000,10,130,167502,4843895,242.020000000,242.070000000,106,62,1,1,242.000000000,242.400000000,200,485,1,1,241.670000000,242.490000000,2,8,1,1,241.000000000,242.850000000,100,300,1,2,240.980000000,242.900000000,82,100,1,1,240.000000000,243.000000000,10,92,1,2,238.000000000,243.310000000,30,10,1,1,236.000000000,243.700000000,6,100,1,1,235.500000000,246.810000000,5,100,1,1,235.000000000,262.740000000,5,100,1,1,JPM
2025-01-03T10:30:31.318227728Z,2025-01-03T10:30:31.318061594Z,10,2,16244,A,A,5,383.130000000,21,130,166134,4844046,382.810000000,382.990000000,10,1,1,1,382.750000000,383.000000000,22,31,1,2,382.700000000,383.080000000,50,1,1,1,382.680000000,383.090000000,20,6,1,1,382.230000000,383.100000000,25,11,1,1,382.110000000,383.130000000,300,21,1,1,382.100000000,383.140000000,20,23,2,1,382.010000000,383.200000000,2,1000,1,1,382.000000000,383.300000000,1192,20,10,1,381.900000000,383.420000000,23,140,1,1,TSLA
2025-01-03T10:30:31.318300541Z,2025-01-03T10:30:31.318134328Z,10,2,16244,C,A,6,383.140000000,23,130,166213,4844047,382.810000000,382.990000000,10,1,1,1,382.750000000,383.000000000,22,31,1,2,382.700000000,383.080000000,50,1,1,1,382.680000000,383.090000000,20,6,1,1,382.230000000,383.100000000,25,11,1,1,382.110000000,383.130000000,300,21,1,1,382.100000000,383.200000000,20,1000,2,1,382.010000000,383.300000000,2,20,1,1,382.000000000,383.420000000,1192,140,10,1,381.900000000,383.600000000,23,1000,1,2,TSLA
2025-01-03T10:30:31.319276564Z,2025-01-03T10:30:31.319110417Z,10,2,6905,A,A,0,91.920000000,7,130,166147,4844053,91.520000000,91.920000000,7,7,1,1,91.480000000,91.930000000,150,7,1,1,91.440000000,91.960000000,100,100,1,1,90.000000000,93.000000000,122,1,1,1,89.000000000,94.000000000,1,1,1,1,83.810000000,95.000000000,100,2,1,2,83.400000000,96.000000000,100,1,1,1,,97.000000000,0,2,0,2,,99.950000000,0,100,0,1,,100.360000000,0,100,0,1,GILD
2025-01-03T10:30:31.319324531Z,2025-01-03T10:30:31.319158776Z,10,2,6905,C,A,1,91.930000000,7,130,165755,4844054,91.520000000,91.920000000,7,7,1,1,91.480000000,91.960000000,150,100,1,1,91.440000000,93.000000000,100,1,1,1,90.000000000,94.000000000,122,1,1,1,89.000000000,95.000000000,1,2,1,2,83.810000000,96.000000000,100,1,1,1,83.400000000,97.000000000,100,2,1,2,,99.950000000,0,100,0,1,,100.360000000,0,100,0,1,,,0,0,0,0,GILD
2025-01-03T10:30:31.321648193Z,2025-01-03T10:30:31.321482338Z,10,2,10888,C,A,1,421.290000000,13,130,165855,4844100,420.710000000,421.190000000,200,200,1,1,420.630000000,421.460000000,13,39,1,1,420.580000000,421.490000000,10,6,1,1,420.520000000,421.570000000,1,40,1,1,420.400000000,421.600000000,858,10,1,1,420.380000000,421.700000000,100,359,1,1,420.100000000,422.100000000,100,7,1,1,420.000000000,422.400000000,534,500,7,1,419.730000000,422.500000000,3,200,1,1,419.650000000,423.500000000,39,600,1,2,MSFT
2025-01-03T10:30:31.321809041Z,2025-01-03T10:30:31.321642644Z,10,2,10888,A,A,1,421.280000000,15,130,166397,4844103,420.710000000,421.190000000,200,200,1,1,420.630000000,421.280000000,13,15,1,1,420.580000000,421.460000000,10,39,1,1,420.520000000,421.490000000,1,6,1,1,420.400000000,421.570000000,858,40,1,1,420.380000000,421.600000000,100,10,1,1,420.100000000,421.700000000,100,359,1,1,420.000000000,422.100000000,534,7,7,1,419.730000000,422.400000000,3,500,1,1,419.650000000,422.500000000,39,200,1,1,MSFT
2025-01-03T10:30:31.445058224Z,2025-01-03T10:30:31.444891678Z,10,2,16244,C,A,6,383.200000000,500,130,166546,4844371,382.810000000,382.990000000,10,1,1,1,382.750000000,383.000000000,22,31,1,2,382.700000000,383.080000000,50,1,1,1,382.680000000,383.090000000,20,6,1,1,382.230000000,383.100000000,25,11,1,1,382.110000000,383.130000000,300,21,1,1,382.100000000,383.200000000,20,500,2,1,382.010000000,383.300000000,2,20,1,1,382.000000000,383.420000000,1192,140,10,1,381.900000000,383.600000000,23,1000,1,2,TSLA
2025-01-03T10:30:31.491785976Z,2025-01-03T10:30:31.491618488Z,10,2,9155,T,A,0,242.020000000,14,130,167488,4844416,242.020000000,242.070000000,106,62,1,1,242.000000000,242.400000000,200,485,1,1,241.670000000,242.490000000,2,8,1,1,241.000000000,242.850000000,100,300,1,2,240.980000000,242.900000000,82,100,1,1,240.000000000,243.000000000,10,92,1,2,238.000000000,243.310000000,30,10,1,1,236.000000000,243.700000000,6,100,1,1,235.500000000,246.810000000,5,100,1,1,235.000000000,262.740000000,5,100,1,1,JPM
2025-01-03T10:30:31.491785976Z,2025-01-03T10:30:31.491618488Z,10,2,9155,C,B,0,242.020000000,14,130,167488,4844416,242.020000000,242.070000000,92,62,1,1,242.000000000,242.400000000,200,485,1,1,241.670000000,242.490000000,2,8,1,1,241.000000000,242.850000000,100,300,1,2,240.980000000,242.900000000,82,100,1,1,240.000000000,243.000000000,10,92,1,2,238.000000000,243.310000000,30,10,1,1,236.000000000,243.700000000,6,100,1,1,235.500000000,246.810000000,5,100,1,1,235.000000000,262.740000000,5,100,1,1,JPM
2025-01-03T10:30:31.540927665Z,2025-01-03T10:30:31.540761814Z,10,2,17709,C,A,1,107.870000000,16,130,165851,4844466,107.600000000,107.840000000,50,400,1,2,107.550000000,107.870000000,15,242,1,1,107.520000000,107.940000000,100,100,1,1,107.050000000,107.950000000,247,10,1,1,107.000000000,108.000000000,1,50,1,1,106.240000000,108.300000000,28,50,1,1,106.000000000,108.550000000,15,50,2,1,105.870000000,108.800000000,141,50,1,1,103.180000000,108.880000000,16,28,1,1,103.000000000,109.450000000,3,137,1,1,XOM
2025-01-03T10:30:31.540986099Z,2025-01-03T10:30:31.540819889Z,10,2,17709,A,A,1,107.850000000,16,130,166210,4844467,107.600000000,107.840000000,50,400,1,2,107.550000000,107.850000000,15,16,1,1,107.520000000,107.870000000,100,242,1,1,107.050000000,107.940000000,247,100,1,1,107.000000000,107.950000000,1,10,1,1,106.240000000,108.000000000,28,50,1,1,106.000000000,108.300000000,15,50,2,1,105.870000000,108.550000000,141,50,1,1,103.180000000,108.800000000,16,50,1,1,103.000000000,108.880000000,3,28,1,1,XOM
2025-01-03T10:30:31.554556696Z,2025-01-03T10:30:31.554390157Z,10,2,9155,A,B,2,241.880000000,8,130,166539,4844477,242.020000000,242.070000000,92,62,1,1,242.000000000,242.400000000,200,485,1,1,241.880000000,242.490000000,8,8,1,1,241.670000000,242.850000000,2,300,1,2,241.000000000,242.900000000,100,100,1,1,240.980000000,243.000000000,82,92,1,2,240.000000000,243.310000000,10,10,1,1,238.000000000,243.700000000,30,100,1,1,236.000000000,246.810000000,6,100,1,1,235.500000000,262.740000000,5,100,1,1,JPM
2025-01-03T10:30:31.795234842Z,2025-01-03T10:30:31.795068788Z,10,2,9155,C,B,2,241.880000000,8,130,166054,4844543,242.020000000,242.070000000,92,62,1,1,242.000000000,242.400000000,200,485,1,1,241.670000000,242.490000000,2,8,1,1,241.000000000,242.850000000,100,300,1,2,240.980000000,242.900000000,82,100,1,1,240.000000000,243.000000000,10,92,1,2,238.000000000,243.310000000,30,10,1,1,236.000000000,243.700000000,6,100,1,1,235.500000000,246.810000000,5,100,1,1,235.000000000,262.740000000,5,100,1,1,JPM
2025-01-03T10:30:31.985621656Z,2025-01-03T10:30:31.985455506Z,10,2,16244,A,A,6,383.200000000,500,130,166150,4844605,382.810000000,382.990000000,10,1,1,1,382.750000000,383.000000000,22,31,1,2,382.700000000,383.080000000,50,1,1,1,382.680000000,383.090000000,20,6,1,1,382.230000000,383.100000000,25,11,1,1,382.110000000,383.130000000,300,21,1,1,382.100000000,383.200000000,20,1000,2,2,382.010000000,383.300000000,2,20,1,1,382.000000000,383.420000000,1192,140,10,1,381.900000000,383.600000000,23,1000,1,2,TSLA
2025-01-03T10:30:33.127332349Z,2025-01-03T10:30:33.127166691Z,10,2,16244,C,A,6,383.200000000,500,130,165658,4845242,382.810000000,382.990000000,10,1,1,1,382.750000000,383.000000000,22,31,1,2,382.700000000,383.080000000,50,1,1,1,382.680000000,383.090000000,20,6,1,1,382.230000000,383.100000000,25,11,1,1,382.110000000,383.130000000,300,21,1,1,382.100000000,383.200000000,20,500,2,1,382.010000000,383.300000000,2,20,1,1,382.000000000,383.420000000,1192,140,10,1,381.900000000,383.600000000,23,1000,1,2,TSLA
2025-01-03T10:30:33.137934094Z,2025-01-03T10:30:33.137767958Z,10,2,16244,A,B,4,382.400000000,500,130,166136,4845250,382.810000000,382.990000000,10,1,1,1,382.750000000,383.000000000,22,31,1,2,382.700000000,383.080000000,50,1,1,1,382.680000000,383.090000000,20,6,1,1,382.400000000,383.100000000,500,11,1,1,382.230000000,383.130000000,25,21,1,1,382.110000000,383.200000000,300,500,1,1,382.100000000,383.300000000,20,20,2,1,382.010000000,383.420000000,2,140,1,1,382.000000000,383.600000000,1192,1000,10,2,TSLA
2025-01-03T10:30:33.137952857Z,2025-01-03T10:30:33.137786943Z,10,2,16244,C,B,9,382.000000000,500,130,165914,4845251,382.810000000,382.990000000,10,1,1,1,382.750000000,383.000000000,22,31,1,2,382.700000000,383.080000000,50,1,1,1,382.680000000,383.090000000,20,6,1,1,382.400000000,383.100000000,500,11,1,1,382.230000000,383.130000000,25,21,1,1,382.110000000,383.200000000,300,500,1,1,382.100000000,383.300000000,20,20,2,1,382.010000000,383.420000000,2,140,1,1,382.000000000,383.600000000,692,1000,9,2,TSLA
2025-01-03T10:30:33.138600446Z,2025-01-03T10:30:33.138434529Z,10,2,16244,C,A,6,383.200000000,500,130,165917,4845253,382.810000000,382.990000000,10,1,1,1,382.750000000,383.000000000,22,31,1,2,382.700000000,383.080000000,50,1,1,1,382.680000000,383.090000000,20,6,1,1,382.400000000,383.100000000,500,11,1,1,382.230000000,383.130000000,25,21,1,1,382.110000000,383.300000000,300,20,1,1,382.100000000,383.420000000,20,140,2,1,382.010000000,383.600000000,2,1000,1,2,382.000000000,383.720000000,692,7085,9,8,TSLA
2025-01-03T10:30:33.662897695Z,2025-01-03T10:30:33.662725549Z,10,2,16244,T,N,0,382.930000000,32,0,172146,4845808,382.810000000,382.990000000,10,1,1,1,382.750000000,383.000000000,22,31,1,2,382.700000000,383.080000000,50,1,1,1,382.680000000,383.090000000,20,6,1,1,382.400000000,383.100000000,500,11,1,1,382.230000000,383.130000000,25,21,1,1,382.110000000,383.300000000,300,20,1,1,382.100000000,383.420000000,20,140,2,1,382.010000000,383.600000000,2,1000,1,2,382.000000000,383.720000000,692,7085,9,8,TSLA
2025-01-03T10:30:33.662897695Z,2025-01-03T10:30:33.662725549Z,10,2,16244,T,N,0,382.930000000,8,0,172146,4845809,382.810000000,382.990000000,10,1,1,1,382.750000000,383.000000000,22,31,1,2,382.700000000,383.080000000,50,1,1,1,382.680000000,383.090000000,20,6,1,1,382.400000000,383.100000000,500,11,1,1,382.230000000,383.130000000,25,21,1,1,382.110000000,383.300000000,300,20,1,1,382.100000000,383.420000000,20,140,2,1,382.010000000,383.600000000,2,1000,1,2,382.000000000,383.720000000,692,7085,9,8,TSLA
2025-01-03T10:30:33.662897695Z,2025-01-03T10:30:33.662728086Z,10,2,16244,T,N,0,382.930000000,12,130,169609,4845810,382.810000000,382.990000000,10,1,1,1,382.750000000,383.000000000,22,31,1,2,382.700000000,383.080000000,50,1,1,1,382.680000000,383.090000000,20,6,1,1,382.400000000,383.100000000,500,11,1,1,382.230000000,383.130000000,25,21,1,1,382.110000000,383.300000000,300,20,1,1,382.100000000,383.420000000,20,140,2,1,382.010000000,383.600000000,2,1000,1,2,382.000000000,383.720000000,692,7085,9,8,TSLA
2025-01-03T10:30:34.636803314Z,2025-01-03T10:30:34.636635735Z,10,2,16244,T,B,0,382.990000000,1,130,167579,4846507,382.810000000,382.990000000,10,1,1,1,382.750000000,383.000000000,22,31,1,2,382.700000000,383.080000000,50,1,1,1,382.680000000,383.090000000,20,6,1,1,382.400000000,383.100000000,500,11,1,1,382.230000000,383.130000000,25,21,1,1,382.110000000,383.300000000,300,20,1,1,382.100000000,383.420000000,20,140,2,1,382.010000000,383.600000000,2,1000,1,2,382.000000000,383.720000000,692,7085,9,8,TSLA
2025-01-03T10:30:34.636803314Z,2025-01-03T10:30:34.636635735Z,10,2,16244,C,A,0,382.990000000,1,130,167579,4846507,382.810000000,383.000000000,10,31,1,2,382.750000000,383.080000000,22,1,1,1,382.700000000,383.090000000,50,6,1,1,382.680000000,383.100000000,20,11,1,1,382.400000000,383.130000000,500,21,1,1,382.230000000,383.300000000,25,20,1,1,382.110000000,383.420000000,300,140,1,1,382.100000000,383.600000000,20,1000,2,2,382.010000000,383.720000000,2,7085,1,8,382.000000000,383.740000000,692,37,9,1,TSLA
2025-01-03T10:30:34.679123246Z,2025-01-03T10:30:34.678957108Z,10,2,16244,C,A,4,383.130000000,21,130,166138,4846524,382.810000000,383.000000000,10,31,1,2,382.750000000,383.080000000,22,1,1,1,382.700000000,383.090000000,50,6,1,1,382.680000000,383.100000000,20,11,1,1,382.400000000,383.300000000,500,20,1,1,382.230000000,383.420000000,25,140,1,1,382.110000000,383.600000000,300,1000,1,2,382.100000000,383.720000000,20,7085,2,8,382.010000000,383.740000000,2,37,1,1,382.000000000,383.800000000,692,10,9,1,TSLA
2025-01-03T10:30:34.679230185Z,2025-01-03T10:30:34.679063839Z,10,2,16244,A,A,4,383.240000000,19,130,166346,4846525,382.810000000,383.000000000,10,31,1,2,382.750000000,383.080000000,22,1,1,1,382.700000000,383.090000000,50,6,1,1,382.680000000,383.100000000,20,11,1,1,382.400000000,383.240000000,500,19,1,1,382.230000000,383.300000000,25,20,1,1,382.110000000,383.420000000,300,140,1,1,382.100000000,383.600000000,20,1000,2,2,382.010000000,383.720000000,2,7085,1,8,382.000000000,383.740000000,692,37,9,1,TSLA
2025-01-03T10:30:34.679267730Z,2025-01-03T10:30:34.679101759Z,10,2,16244,C,B,1,382.750000000,22,130,165971,4846526,382.810000000,383.000000000,10,31,1,2,382.700000000,383.080000000,50,1,1,1,382.680000000,383.090000000,20,6,1,1,382.400000000,383.100000000,500,11,1,1,382.230000000,383.240000000,25,19,1,1,382.110000000,383.300000000,300,20,1,1,382.100000000,383.420000000,20,140,2,1,382.010000000,383.600000000,2,1000,1,2,382.000000000,383.720000000,692,7085,9,8,381.900000000,383.740000000,23,37,1,1,TSLA
2025-01-03T10:30:34.679350720Z,2025-01-03T10:30:34.679184568Z,10,2,16244,A,B,1,382.800000000,23,130,166152,4846527,382.810000000,383.000000000,10,31,1,2,382.800000000,383.080000000,23,1,1,1,382.700000000,383.090000000,50,6,1,1,382.680000000,383.100000000,20,11,1,1,382.400000000,383.240000000,500,19,1,1,382.230000000,383.300000000,25,20,1,1,382.110000000,383.420000000,300,140,1,1,382.100000000,383.600000000,20,1000,2,2,382.010000000,383.720000000,2,7085,1,8,382.000000000,383.740000000,692,37,9,1,TSLA
2025-01-03T10:30:34.705996061Z,2025-01-03T10:30:34.705830010Z,10,2,16244,C,A,4,383.240000000,19,130,166051,4846530,382.810000000,383.000000000,10,31,1,2,382.800000000,383.080000000,23,1,1,1,382.700000000,383.090000000,50,6,1,1,382.680000000,383.100000000,20,11,1,1,382.400000000,383.300000000,500,20,1,1,382.230000000,383.420000000,25,140,1,1,382.110000000,383.600000000,300,1000,1,2,382.100000000,383.720000000,20,7085,2,8,382.010000000,383.740000000,2,37,1,1,382.000000000,383.800000000,692,10,9,1,TSLA
2025-01-03T10:30:35.220180528Z,2025-01-03T10:30:35.220011626Z,10,2,16244,T,B,0,383.000000000,1,0,168902,4846688,382.810000000,383.000000000,10,31,1,2,382.800000000,383.080000000,23,1,1,1,382.700000000,383.090000000,50,6,1,1,382.680000000,383.100000000,20,11,1,1,382.400000000,383.300000000,500,20,1,1,382.230000000,383.420000000,25,140,1,1,382.110000000,383.600000000,300,1000,1,2,382.100000000,383.720000000,20,7085,2,8,382.010000000,383.740000000,2,37,1,1,382.000000000,383.800000000,692,10,9,1,TSLA
2025-01-03T10:30:35.220180528Z,2025-01-03T10:30:35.220011626Z,10,2,16244,T,B,0,383.000000000,30,130,168902,4846689,382.810000000,383.000000000,10,30,1,1,382.800000000,383.080000000,23,1,1,1,382.700000000,383.090000000,50,6,1,1,382.680000000,383.100000000,20,11,1,1,382.400000000,383.300000000,500,20,1,1,382.230000000,383.420000000,25,140,1,1,382.110000000,383.600000000,300,1000,1,2,382.100000000,383.720000000,20,7085,2,8,382.010000000,383.740000000,2,37,1,1,382.000000000,383.800000000,692,10,9,1,TSLA
2025-01-03T10:30:35.220180528Z,2025-01-03T10:30:35.220011626Z,10,2,16244,C,A,0,383.000000000,30,130,168902,4846689,382.810000000,383.080000000,10,1,1,1,382.800000000,383.090000000,23,6,1,1,382.700000000,383.100000000,50,11,1,1,382.680000000,383.300000000,20,20,1,1,382.400000000,383.420000000,500,140,1,1,382.230000000,383.600000000,25,1000,1,2,382.110000000,383.720000000,300,7085,1,8,382.100000000,383.740000000,20,37,2,1,382.010000000,383.800000000,2,10,1,1,382.000000000,383.880000000,692,4,9,1,TSLA
2025-01-03T10:30:35.220204942Z,2025-01-03T10:30:35.220038152Z,10,2,16244,A,B,0,382.900000000,4,130,166790,4846690,382.900000000,383.080000000,4,1,1,1,382.810000000,383.090000000,10,6,1,1,382.800000000,383.100000000,23,11,1,1,382.700000000,383.300000000,50,20,1,1,382.680000000,383.420000000,20,140,1,1,382.400000000,383.600000000,500,1000,1,2,382.230000000,383.720000000,25,7085,1,8,382.110000000,383.740000000,300,37,1,1,382.100000000,383.800000000,20,10,2,1,382.010000000,383.880000000,2,4,1,1,TSLA
2025-01-03T10:30:35.220217037Z,2025-01-03T10:30:35.220050435Z,10,2,16244,A,B,1,382.840000000,4,130,166602,4846691,382.900000000,383.080000000,4,1,1,1,382.840000000,383.090000000,4,6,1,1,382.810000000,383.100000000,10,11,1,1,382.800000000,383.300000000,23,20,1,1,382.700000000,383.420000000,50,140,1,1,382.680000000,383.600000000,20,1000,1,2,382.400000000,383.720000000,500,7085,1,8,382.230000000,383.740000000,25,37,1,1,382.110000000,383.800000000,300,10,1,1,382.100000000,383.880000000,20,4,2,1,TSLA
2025-01-03T10:30:35.220846176Z,2025-01-03T10:30:35.220679648Z,10,2,16244,C,A,5,383.600000000,500,130,166528,4846703,382.900000000,383.080000000,4,1,1,1,382.840000000,383.090000000,4,6,1,1,382.810000000,383.100000000,10,11,1,1,382.800000000,383.300000000,23,20,1,1,382.700000000,383.420000000,50,140,1,1,382.680000000,383.600000000,20,500,1,1,382.400000000,383.720000000,500,7085,1,8,382.230000000,383.740000000,25,37,1,1,382.110000000,383.800000000,300,10,1,1,382.100000000,383.880000000,20,4,2,1,TSLA
2025-01-03T10:30:35.232322645Z,2025-01-03T10:30:35.232156748Z,10,2,16244,C,B,1,382.840000000,4,130,165897,4846734,382.900000000,383.080000000,4,1,1,1,382.810000000,383.090000000,10,6,1,1,382.800000000,383.100000000,23,11,1,1,382.700000000,383.300000000,50,20,1,1,382.680000000,383.420000000,20,140,1,1,382.400000000,383.600000000,500,500,1,1,382.230000000,383.720000000,25,7085,1,8,382.110000000,383.740000000,300,37,1,1,382.100000000,383.800000000,20,10,2,1,382.010000000,383.880000000,2,4,1,1,TSLA
2025-01-03T10:30:35.257529991Z,2025-01-03T10:30:35.257363529Z,10,2,16244,A,A,5,383.600000000,500,130,166462,4846756,382.900000000,383.080000000,4,1,1,1,382.810000000,383.090000000,10,6,1,1,382.800000000,383.100000000,23,11,1,1,382.700000000,383.300000000,50,20,1,1,382.680000000,383.420000000,20,140,1,1,382.400000000,383.600000000,500,1000,1,2,382.230000000,383.720000000,25,7085,1,8,382.110000000,383.740000000,300,37,1,1,382.100000000,383.800000000,20,10,2,1,382.010000000,383.880000000,2,4,1,1,TSLA
2025-01-03T10:30:35.282974771Z,2025-01-03T10:30:35.282808698Z,10,2,16244,A,A,3,383.290000000,21,130,166073,4846764,382.900000000,383.080000000,4,1,1,1,382.810000000,383.090000000,10,6,1,1,382.800000000,383.100000000,23,11,1,1,382.700000000,383.290000000,50,21,1,1,382.680000000,383.300000000,20,20,1,1,382.400000000,383.420000000,500,140,1,1,382.230000000,383.600000000,25,1000,1,2,382.110000000,383.720000000,300,7085,1,8,382.100000000,383.740000000,20,37,2,1,382.010000000,383.800000000,2,10,1,1,TSLA
2025-01-03T10:30:35.287977349Z,2025-01-03T10:30:35.287811295Z,10,2,16244,C,A,3,383.290000000,21,130,166054,4846767,382.900000000,383.080000000,4,1,1,1,382.810000000,383.090000000,10,6,1,1,382.800000000,383.100000000,23,11,1,1,382.700000000,383.300000000,50,20,1,1,382.680000000,383.420000000,20,140,1,1,382.400000000,383.600000000,500,1000,1,2,382.230000000,383.720000000,25,7085,1,8,382.110000000,383.740000000,300,37,1,1,382.100000000,383.800000000,20,10,2,1,382.010000000,383.880000000,2,4,1,1,TSLA
2025-01-03T10:30:35.374432763Z,2025-01-03T10:30:35.374261924Z,10,2,16244,T,N,0,383.050000000,100,0,170839,4846845,382.900000000,383.080000000,4,1,1,1,382.810000000,383.090000000,10,6,1,1,382.800000000,383.100000000,23,11,1,1,382.700000000,383.300000000,50,20,1,1,382.680000000,383.420000000,20,140,1,1,382.400000000,383.600000000,500,1000,1,2,382.230000000,383.720000000,25,7085,1,8,382.110000000,383.740000000,300,37,1,1,382.100000000,383.800000000,20,10,2,1,382.010000000,383.880000000,2,4,1,1,TSLA
2025-01-03T10:30:35.374432763Z,2025-01-03T10:30:35.374261924Z,10,2,16244,T,N,0,383.070000000,11,0,170839,4846846,382.900000000,383.080000000,4,1,1,1,382.810000000,383.090000000,10,6,1,1,382.800000000,383.100000000,23,11,1,1,382.700000000,383.300000000,50,20,1,1,382.680000000,383.420000000,20,140,1,1,382.400000000,383.600000000,500,1000,1,2,382.230000000,383.720000000,25,7085,1,8,382.110000000,383.740000000,300,37,1,1,382.100000000,383.800000000,20,10,2,1,382.010000000,383.880000000,2,4,1,1,TSLA
2025-01-03T10:30:35.374432763Z,2025-01-03T10:30:35.374261924Z,10,2,16244,T,B,0,383.080000000,1,130,170839,4846847,382.900000000,383.080000000,4,1,1,1,382.810000000,383.090000000,10,6,1,1,382.800000000,383.100000000,23,11,1,1,382.700000000,383.300000000,50,20,1,1,382.680000000,383.420000000,20,140,1,1,382.400000000,383.600000000,500,1000,1,2,382.230000000,383.720000000,25,7085,1,8,382.110000000,383.740000000,300,37,1,1,382.100000000,383.800000000,20,10,2,1,382.010000000,383.880000000,2,4,1,1,TSLA
2025-01-03T10:30:35.374432763Z,2025-01-03T10:30:35.374261924Z,10,2,16244,C,A,0,383.080000000,1,130,170839,4846847,382.900000000,383.090000000,4,6,1,1,382.810000000,383.100000000,10,11,1,1,382.800000000,383.300000000,23,20,1,1,382.700000000,383.420000000,50,140,1,1,382.680000000,383.600000000,20,1000,1,2,382.400000000,383.720000000,500,7085,1,8,382.230000000,383.740000000,25,37,1,1,382.110000000,383.800000000,300,10,1,1,382.100000000,383.880000000,20,4,2,1,382.010000000,384.000000000,2,1300,1,4,TSLA
2025-01-03T10:30:35.472322841Z,2025-01-03T10:30:35.472157031Z,10,2,16244,C,B,0,382.900000000,4,130,165810,4846918,382.810000000,383.090000000,10,6,1,1,382.800000000,383.100000000,23,11,1,1,382.700000000,383.300000000,50,20,1,1,382.680000000,383.420000000,20,140,1,1,382.400000000,383.600000000,500,1000,1,2,382.230000000,383.720000000,25,7085,1,8,382.110000000,383.740000000,300,37,1,1,382.100000000,383.800000000,20,10,2,1,382.010000000,383.880000000,2,4,1,1,382.000000000,384.000000000,692,1300,9,4,TSLA
