ts_recv,ts_event,rtype,publisher_id,instrument_id,action,side,depth,price,size,flags,ts_in_delta,sequence,bid_px_00,ask_px_00,bid_sz_00,ask_sz_00,bid_ct_00,ask_ct_00,bid_px_01,ask_px_01,bid_sz_01,ask_sz_01,bid_ct_01,ask_ct_01,bid_px_02,ask_px_02,bid_sz_02,ask_sz_02,bid_ct_02,ask_ct_02,bid_px_03,ask_px_03,bid_sz_03,ask_sz_03,bid_ct_03,ask_ct_03,bid_px_04,ask_px_04,bid_sz_04,ask_sz_04,bid_ct_04,ask_ct_04,bid_px_05,ask_px_05,bid_sz_05,ask_sz_05,bid_ct_05,ask_ct_05,bid_px_06,ask_px_06,bid_sz_06,ask_sz_06,bid_ct_06,ask_ct_06,bid_px_07,ask_px_07,bid_sz_07,ask_sz_07,bid_ct_07,ask_ct_07,bid_px_08,ask_px_08,bid_sz_08,ask_sz_08,bid_ct_08,ask_ct_08,bid_px_09,ask_px_09,bid_sz_09,ask_sz_09,bid_ct_09,ask_ct_09,symbol
2025-01-03T10:31:56.546951953Z,2025-01-03T10:31:56.546785725Z,10,2,9155,A,A,1,242.410000000,8,130,166228,4900906,241.670000000,242.070000000,2,62,1,1,241.120000000,242.410000000,81,8,1,1,241.000000000,242.850000000,100,300,1,2,240.000000000,242.900000000,10,100,1,1,238.000000000,243.000000000,30,92,1,2,236.000000000,243.310000000,6,10,1,1,235.500000000,243.700000000,5,100,1,1,235.000000000,246.810000000,5,100,1,1,232.880000000,262.740000000,1,100,1,1,231.110000000,263.830000000,3,100,1,1,JPM
2025-01-03T10:31:56.547025976Z,2025-01-03T10:31:56.546859840Z,10,2,9155,A,B,1,241.590000000,8,130,166136,4900907,241.670000000,242.070000000,2,62,1,1,241.590000000,242.410000000,8,8,1,1,241.120000000,242.850000000,81,300,1,2,241.000000000,242.900000000,100,100,1,1,240.000000000,243.000000000,10,92,1,2,238.000000000,243.310000000,30,10,1,1,236.000000000,243.700000000,6,100,1,1,235.500000000,246.810000000,5,100,1,1,235.000000000,262.740000000,5,100,1,1,232.880000000,263.830000000,1,100,1,1,JPM
2025-01-03T10:31:56.548804090Z,2025-01-03T10:31:56.548638233Z,10,2,38,C,A,3,243.730000000,29,130,165857,4900920,243.500000000,243.590000000,6,120,1,1,243.460000000,243.650000000,400,61,1,2,243.390000000,243.710000000,29,200,1,1,243.190000000,244.000000000,2,1001,1,2,243.020000000,244.140000000,79,79,1,1,243.000000000,244.400000000,1243,50,9,1,242.990000000,244.420000000,1,10,1,1,242.800000000,244.580000000,30,100,1,1,242.750000000,245.000000000,30,79,1,2,242.590000000,245.190000000,5,83,1,1,AAPL
2025-01-03T10:31:56.548833583Z,2025-01-03T10:31:56.548667349Z,10,2,38,A,A,3,243.760000000,28,130,166234,4900921,243.500000000,243.590000000,6,120,1,1,243.460000000,243.650000000,400,61,1,2,243.390000000,243.710000000,29,200,1,1,243.190000000,243.760000000,2,28,1,1,243.020000000,244.000000000,79,1001,1,2,243.000000000,244.140000000,1243,79,9,1,242.990000000,244.400000000,1,50,1,1,242.800000000,244.420000000,30,10,1,1,242.750000000,244.580000000,30,100,1,1,242.590000000,245.000000000,5,79,1,2,AAPL
2025-01-03T10:31:56.610498431Z,2025-01-03T10:31:56.610332564Z,10,2,10888,C,A,1,421.290000000,14,130,165867,4900969,420.690000000,421.240000000,200,200,1,1,420.580000000,421.460000000,10,39,1,1,420.570000000,421.490000000,14,6,1,1,420.520000000,421.570000000,1,40,1,1,420.400000000,421.600000000,858,510,1,2,420.380000000,421.700000000,100,359,1,1,420.100000000,421.800000000,100,7,1,1,420.000000000,422.100000000,334,7,7,1,419.730000000,422.500000000,3,200,1,1,419.650000000,423.500000000,39,600,1,2,MSFT
2025-01-03T10:31:56.610557790Z,2025-01-03T10:31:56.610391820Z,10,2,10888,A,A,1,421.280000000,14,130,165970,4900970,420.690000000,421.240000000,200,200,1,1,420.580000000,421.280000000,10,14,1,1,420.570000000,421.460000000,14,39,1,1,420.520000000,421.490000000,1,6,1,1,420.400000000,421.570000000,858,40,1,1,420.380000000,421.600000000,100,510,1,2,420.100000000,421.700000000,100,359,1,1,420.000000000,421.800000000,334,7,7,1,419.730000000,422.100000000,3,7,1,1,419.650000000,422.500000000,39,200,1,1,MSFT
2025-01-03T10:31:56.665528861Z,2025-01-03T10:31:56.665362620Z,10,2,10888,A,A,0,421.220000000,200,130,166241,4901057,420.690000000,421.220000000,200,200,1,1,420.580000000,421.280000000,10,14,1,1,420.570000000,421.460000000,14,39,1,1,420.520000000,421.490000000,1,6,1,1,420.400000000,421.570000000,858,40,1,1,420.380000000,421.600000000,100,510,1,2,420.100000000,421.700000000,100,359,1,1,420.000000000,421.800000000,334,7,7,1,419.730000000,422.100000000,3,7,1,1,419.650000000,422.500000000,39,200,1,1,MSFT
2025-01-03T10:31:57.386494913Z,2025-01-03T10:31:57.386328889Z,10,2,9155,C,B,1,241.590000000,8,130,166024,4901337,241.670000000,242.070000000,2,62,1,1,241.120000000,242.410000000,81,8,1,1,241.000000000,242.850000000,100,300,1,2,240.000000000,242.900000000,10,100,1,1,238.000000000,243.000000000,30,92,1,2,236.000000000,243.310000000,6,10,1,1,235.500000000,243.700000000,5,100,1,1,235.000000000,246.810000000,5,100,1,1,232.880000000,262.740000000,1,100,1,1,231.110000000,263.830000000,3,100,1,1,JPM
2025-01-03T10:31:57.891647079Z,2025-01-03T10:31:57.891481037Z,10,2,10888,C,A,1,421.280000000,14,130,166042,4901490,420.690000000,421.220000000,200,200,1,1,420.580000000,421.460000000,10,39,1,1,420.570000000,421.490000000,14,6,1,1,420.520000000,421.570000000,1,40,1,1,420.400000000,421.600000000,858,510,1,2,420.380000000,421.700000000,100,359,1,1,420.100000000,421.800000000,100,7,1,1,420.000000000,422.100000000,334,7,7,1,419.730000000,422.500000000,3,200,1,1,419.650000000,423.500000000,39,600,1,2,MSFT
2025-01-03T10:31:57.891753558Z,2025-01-03T10:31:57.891587170Z,10,2,10888,A,A,1,421.230000000,15,130,166388,4901491,420.690000000,421.220000000,200,200,1,1,420.580000000,421.230000000,10,15,1,1,420.570000000,421.460000000,14,39,1,1,420.520000000,421.490000000,1,6,1,1,420.400000000,421.570000000,858,40,1,1,420.380000000,421.600000000,100,510,1,2,420.100000000,421.700000000,100,359,1,1,420.000000000,421.800000000,334,7,7,1,419.730000000,422.100000000,3,7,1,1,419.650000000,422.500000000,39,200,1,1,MSFT
2025-01-03T10:31:58.003006068Z,2025-01-03T10:31:58.002839882Z,10,2,780,C,A,0,260.610000000,25,130,166186,4901499,259.010000000,294.170000000,175,100,1,1,258.740000000,295.390000000,25,100,1,1,258.100000000,,25,0,1,0,257.700000000,,1,0,1,0,255.920000000,,1,0,1,0,250.000000000,,13,0,2,0,236.860000000,,100,0,1,0,235.690000000,,100,0,1,0,,,0,0,0,0,,,0,0,0,0,AMGN
2025-01-03T10:31:58.003019832Z,2025-01-03T10:31:58.002853489Z,10,2,780,A,A,0,260.780000000,25,130,166343,4901500,259.010000000,260.780000000,175,25,1,1,258.740000000,294.170000000,25,100,1,1,258.100000000,295.390000000,25,100,1,1,257.700000000,,1,0,1,0,255.920000000,,1,0,1,0,250.000000000,,13,0,2,0,236.860000000,,100,0,1,0,235.690000000,,100,0,1,0,,,0,0,0,0,,,0,0,0,0,AMGN
2025-01-03T10:31:58.823750723Z,2025-01-03T10:31:58.823584743Z,10,2,16244,C,A,1,383.480000000,20,130,165980,4901903,383.000000000,383.420000000,13,140,2,1,382.860000000,383.480000000,23,30,1,1,382.810000000,383.500000000,20,20,2,1,382.700000000,383.600000000,50,1000,1,2,382.680000000,383.720000000,20,7085,1,8,382.400000000,383.740000000,500,37,1,1,382.230000000,383.800000000,25,10,1,1,382.110000000,383.880000000,300,4,1,1,382.100000000,384.000000000,20,1300,2,4,382.010000000,384.260000000,2,15,1,1,TSLA
2025-01-03T10:31:58.877154488Z,2025-01-03T10:31:58.876987787Z,10,2,16244,A,B,0,383.000000000,10,130,166701,4901916,383.000000000,383.420000000,23,140,3,1,382.860000000,383.480000000,23,30,1,1,382.810000000,383.500000000,20,20,2,1,382.700000000,383.600000000,50,1000,1,2,382.680000000,383.720000000,20,7085,1,8,382.400000000,383.740000000,500,37,1,1,382.230000000,383.800000000,25,10,1,1,382.110000000,383.880000000,300,4,1,1,382.100000000,384.000000000,20,1300,2,4,382.010000000,384.260000000,2,15,1,1,TSLA
2025-01-03T10:31:58.939868697Z,2025-01-03T10:31:58.939702167Z,10,2,16244,C,B,1,382.860000000,23,130,166530,4901919,383.000000000,383.420000000,23,140,3,1,382.810000000,383.480000000,20,30,2,1,382.700000000,383.500000000,50,20,1,1,382.680000000,383.600000000,20,1000,1,2,382.400000000,383.720000000,500,7085,1,8,382.230000000,383.740000000,25,37,1,1,382.110000000,383.800000000,300,10,1,1,382.100000000,383.880000000,20,4,2,1,382.010000000,384.000000000,2,1300,1,4,382.000000000,384.260000000,1242,15,11,1,TSLA
2025-01-03T10:31:58.939985158Z,2025-01-03T10:31:58.939818866Z,10,2,16244,A,B,1,382.890000000,20,130,166292,4901920,383.000000000,383.420000000,23,140,3,1,382.890000000,383.480000000,20,30,1,1,382.810000000,383.500000000,20,20,2,1,382.700000000,383.600000000,50,1000,1,2,382.680000000,383.720000000,20,7085,1,8,382.400000000,383.740000000,500,37,1,1,382.230000000,383.800000000,25,10,1,1,382.110000000,383.880000000,300,4,1,1,382.100000000,384.000000000,20,1300,2,4,382.010000000,384.260000000,2,15,1,1,TSLA
2025-01-03T10:31:59.027890449Z,2025-01-03T10:31:59.027723987Z,10,2,10888,A,A,0,421.200000000,200,130,166462,4901935,420.690000000,421.200000000,200,200,1,1,420.580000000,421.230000000,10,15,1,1,420.570000000,421.460000000,14,39,1,1,420.520000000,421.490000000,1,6,1,1,420.400000000,421.570000000,858,40,1,1,420.380000000,421.600000000,100,510,1,2,420.100000000,421.700000000,100,359,1,1,420.000000000,421.800000000,334,7,7,1,419.730000000,422.100000000,3,7,1,1,419.650000000,422.500000000,39,200,1,1,MSFT
2025-01-03T10:31:59.114431183Z,2025-01-03T10:31:59.114263764Z,10,2,16244,T,N,0,383.140000000,15,130,167419,4902010,383.000000000,383.420000000,23,140,3,1,382.890000000,383.480000000,20,30,1,1,382.810000000,383.500000000,20,20,2,1,382.700000000,383.600000000,50,1000,1,2,382.680000000,383.720000000,20,7085,1,8,382.400000000,383.740000000,500,37,1,1,382.230000000,383.800000000,25,10,1,1,382.110000000,383.880000000,300,4,1,1,382.100000000,384.000000000,20,1300,2,4,382.010000000,384.260000000,2,15,1,1,TSLA
2025-01-03T10:31:59.457799017Z,2025-01-03T10:31:59.457633103Z,10,2,16727,C,B,0,314.910000000,8,130,165914,4902277,314.860000000,315.470000000,25,8,1,1,314.420000000,315.510000000,61,25,1,1,313.500000000,315.750000000,1,61,1,1,310.000000000,320.000000000,1,5,1,1,300.000000000,320.210000000,3,1,1,1,290.000000000,321.950000000,2,2,1,1,286.660000000,344.200000000,100,100,1,1,285.250000000,345.620000000,100,100,1,1,260.000000000,,2,0,1,0,,,0,0,0,0,V
2025-01-03T10:31:59.457862581Z,2025-01-03T10:31:59.457696354Z,10,2,16727,A,B,0,314.920000000,8,130,166227,4902278,314.920000000,315.470000000,8,8,1,1,314.860000000,315.510000000,25,25,1,1,314.420000000,315.750000000,61,61,1,1,313.500000000,320.000000000,1,5,1,1,310.000000000,320.210000000,1,1,1,1,300.000000000,321.950000000,3,2,1,1,290.000000000,344.200000000,2,100,1,1,286.660000000,345.620000000,100,100,1,1,285.250000000,,100,0,1,0,260.000000000,,2,0,1,0,V
2025-01-03T10:31:59.586315541Z,2025-01-03T10:31:59.586149392Z,10,2,38,C,B,1,243.460000000,400,130,166149,4902539,243.500000000,243.590000000,6,120,1,1,243.390000000,243.650000000,29,61,1,2,243.190000000,243.710000000,2,200,1,1,243.020000000,243.760000000,79,28,1,1,243.000000000,244.000000000,1243,1001,9,2,242.990000000,244.140000000,1,79,1,1,242.800000000,244.400000000,30,50,1,1,242.750000000,244.420000000,30,10,1,1,242.590000000,244.580000000,5,100,1,1,242.280000000,245.000000000,100,79,1,2,AAPL
2025-01-03T10:31:59.586328080Z,2025-01-03T10:31:59.586161207Z,10,2,38,A,B,1,243.430000000,200,130,166873,4902540,243.500000000,243.590000000,6,120,1,1,243.430000000,243.650000000,200,61,1,2,243.390000000,243.710000000,29,200,1,1,243.190000000,243.760000000,2,28,1,1,243.020000000,244.000000000,79,1001,1,2,243.000000000,244.140000000,1243,79,9,1,242.990000000,244.400000000,1,50,1,1,242.800000000,244.420000000,30,10,1,1,242.750000000,244.580000000,30,100,1,1,242.590000000,245.000000000,5,79,1,2,AAPL
2025-01-03T10:31:59.586374341Z,2025-01-03T10:31:59.586208014Z,10,2,38,A,A,2,243.710000000,200,130,166327,4902541,243.500000000,243.590000000,6,120,1,1,243.430000000,243.650000000,200,61,1,2,243.390000000,243.710000000,29,400,1,2,243.190000000,243.760000000,2,28,1,1,243.020000000,244.000000000,79,1001,1,2,243.000000000,244.140000000,1243,79,9,1,242.990000000,244.400000000,1,50,1,1,242.800000000,244.420000000,30,10,1,1,242.750000000,244.580000000,30,100,1,1,242.590000000,245.000000000,5,79,1,2,AAPL
2025-01-03T10:31:59.587358754Z,2025-01-03T10:31:59.587192490Z,10,2,38,A,A,2,243.710000000,30,130,166264,4902542,243.500000000,243.590000000,6,120,1,1,243.430000000,243.650000000,200,61,1,2,243.390000000,243.710000000,29,430,1,3,243.190000000,243.760000000,2,28,1,1,243.020000000,244.000000000,79,1001,1,2,243.000000000,244.140000000,1243,79,9,1,242.990000000,244.400000000,1,50,1,1,242.800000000,244.420000000,30,10,1,1,242.750000000,244.580000000,30,100,1,1,242.590000000,245.000000000,5,79,1,2,AAPL
2025-01-03T10:31:59.587388960Z,2025-01-03T10:31:59.587223002Z,10,2,38,C,A,3,243.760000000,28,130,165958,4902543,243.500000000,243.590000000,6,120,1,1,243.430000000,243.650000000,200,61,1,2,243.390000000,243.710000000,29,430,1,3,243.190000000,244.000000000,2,1001,1,2,243.020000000,244.140000000,79,79,1,1,243.000000000,244.400000000,1243,50,9,1,242.990000000,244.420000000,1,10,1,1,242.800000000,244.580000000,30,100,1,1,242.750000000,245.000000000,30,79,1,2,242.590000000,245.190000000,5,83,1,1,AAPL
2025-01-03T10:31:59.642399293Z,2025-01-03T10:31:59.642232690Z,10,2,38,C,A,2,243.710000000,200,130,166603,4902589,243.500000000,243.590000000,6,120,1,1,243.430000000,243.650000000,200,61,1,2,243.390000000,243.710000000,29,230,1,2,243.190000000,244.000000000,2,1001,1,2,243.020000000,244.140000000,79,79,1,1,243.000000000,244.400000000,1243,50,9,1,242.990000000,244.420000000,1,10,1,1,242.800000000,244.580000000,30,100,1,1,242.750000000,245.000000000,30,79,1,2,242.590000000,245.190000000,5,83,1,1,AAPL
2025-01-03T10:31:59.642412648Z,2025-01-03T10:31:59.642245717Z,10,2,38,A,A,2,243.660000000,200,130,166931,4902590,243.500000000,243.590000000,6,120,1,1,243.430000000,243.650000000,200,61,1,2,243.390000000,243.660000000,29,200,1,1,243.190000000,243.710000000,2,30,1,1,243.020000000,244.000000000,79,1001,1,2,243.000000000,244.140000000,1243,79,9,1,242.990000000,244.400000000,1,50,1,1,242.800000000,244.420000000,30,10,1,1,242.750000000,244.580000000,30,100,1,1,242.590000000,245.000000000,5,79,1,2,AAPL
2025-01-03T10:31:59.983279056Z,2025-01-03T10:31:59.983112969Z,10,2,16244,C,A,1,383.480000000,30,130,166087,4902849,383.000000000,383.420000000,23,140,3,1,382.890000000,383.500000000,20,20,1,1,382.810000000,383.600000000,20,1000,2,2,382.700000000,383.720000000,50,7085,1,8,382.680000000,383.740000000,20,37,1,1,382.400000000,383.800000000,500,10,1,1,382.230000000,383.880000000,25,4,1,1,382.110000000,384.000000000,300,1300,1,4,382.100000000,384.260000000,20,15,2,1,382.010000000,384.400000000,2,1000,1,2,TSLA
2025-01-03T10:31:59.984319445Z,2025-01-03T10:31:59.984153160Z,10,2,16244,A,A,0,383.310000000,30,130,166285,4902850,383.000000000,383.310000000,23,30,3,1,382.890000000,383.420000000,20,140,1,1,382.810000000,383.500000000,20,20,2,1,382.700000000,383.600000000,50,1000,1,2,382.680000000,383.720000000,20,7085,1,8,382.400000000,383.740000000,500,37,1,1,382.230000000,383.800000000,25,10,1,1,382.110000000,383.880000000,300,4,1,1,382.100000000,384.000000000,20,1300,2,4,382.010000000,384.260000000,2,15,1,1,TSLA
2025-01-03T10:32:00.047304351Z,2025-01-03T10:32:00.047138092Z,10,2,6905,A,A,1,91.950000000,7,130,166259,4902949,91.520000000,91.930000000,7,7,1,1,91.480000000,91.950000000,150,7,1,1,91.440000000,91.960000000,100,100,1,1,90.000000000,93.000000000,122,1,1,1,89.000000000,94.000000000,1,1,1,1,83.810000000,95.000000000,100,2,1,2,83.400000000,96.000000000,100,1,1,1,,97.000000000,0,2,0,2,,99.950000000,0,100,0,1,,100.360000000,0,100,0,1,GILD
2025-01-03T10:32:00.047338741Z,2025-01-03T10:32:00.047171465Z,10,2,6905,C,A,0,91.930000000,7,130,167276,4902950,91.520000000,91.950000000,7,7,1,1,91.480000000,91.960000000,150,100,1,1,91.440000000,93.000000000,100,1,1,1,90.000000000,94.000000000,122,1,1,1,89.000000000,95.000000000,1,2,1,2,83.810000000,96.000000000,100,1,1,1,83.400000000,97.000000000,100,2,1,2,,99.950000000,0,100,0,1,,100.360000000,0,100,0,1,,,0,0,0,0,GILD
2025-01-03T10:32:00.116880455Z,2025-01-03T10:32:00.116714097Z,10,2,11667,A,A,0,139.200000000,100,130,166358,4903236,139.160000000,139.200000000,100,160,1,2,139.150000000,139.220000000,9860,410,2,2,139.130000000,139.230000000,2200,1977,2,2,139.120000000,139.240000000,30,300,1,2,139.110000000,139.250000000,1,1,1,1,139.090000000,139.270000000,400,37,1,2,139.080000000,139.300000000,57,507,1,4,139.070000000,139.320000000,100,39,1,1,139.030000000,139.330000000,126,503,2,2,139.010000000,139.360000000,100,4,1,2,NVDA
2025-01-03T10:32:00.377680159Z,2025-01-03T10:32:00.377513868Z,10,2,11667,A,B,5,139.100000000,10,130,166291,4903528,139.160000000,139.200000000,100,160,1,2,139.150000000,139.220000000,9860,410,2,2,139.130000000,139.230000000,2200,1977,2,2,139.120000000,139.240000000,30,300,1,2,139.110000000,139.250000000,1,1,1,1,139.100000000,139.270000000,10,37,1,2,139.090000000,139.300000000,400,507,1,4,139.080000000,139.320000000,57,39,1,1,139.070000000,139.330000000,100,503,1,2,139.030000000,139.360000000,126,4,2,2,NVDA
2025-01-03T10:32:00.537452353Z,2025-01-03T10:32:00.537285990Z,10,2,10888,A,B,7,420.000000000,500,130,166363,4903623,420.690000000,421.200000000,200,200,1,1,420.580000000,421.230000000,10,15,1,1,420.570000000,421.460000000,14,39,1,1,420.520000000,421.490000000,1,6,1,1,420.400000000,421.570000000,858,40,1,1,420.380000000,421.600000000,100,510,1,2,420.100000000,421.700000000,100,359,1,1,420.000000000,421.800000000,834,7,8,1,419.730000000,422.100000000,3,7,1,1,419.650000000,422.500000000,39,200,1,1,MSFT
2025-01-03T10:32:01.082211726Z,2025-01-03T10:32:01.082045964Z,10,2,11667,C,A,0,139.200000000,100,130,165762,4903808,139.160000000,139.200000000,100,60,1,1,139.150000000,139.220000000,9860,410,2,2,139.130000000,139.230000000,2200,1977,2,2,139.120000000,139.240000000,30,300,1,2,139.110000000,139.250000000,1,1,1,1,139.100000000,139.270000000,10,37,1,2,139.090000000,139.300000000,400,507,1,4,139.080000000,139.320000000,57,39,1,1,139.070000000,139.330000000,100,503,1,2,139.030000000,139.360000000,126,4,2,2,NVDA
2025-01-03T10:32:01.878019153Z,2025-01-03T10:32:01.877852935Z,10,2,9155,A,B,1,241.590000000,8,130,166218,4904137,241.670000000,242.070000000,2,62,1,1,241.590000000,242.410000000,8,8,1,1,241.120000000,242.850000000,81,300,1,2,241.000000000,242.900000000,100,100,1,1,240.000000000,243.000000000,10,92,1,2,238.000000000,243.310000000,30,10,1,1,236.000000000,243.700000000,6,100,1,1,235.500000000,246.810000000,5,100,1,1,235.000000000,262.740000000,5,100,1,1,232.880000000,263.830000000,1,100,1,1,JPM
2025-01-03T10:32:01.952609590Z,2025-01-03T10:32:01.952443154Z,10,2,16244,A,A,2,383.490000000,19,130,166436,4904169,383.000000000,383.310000000,23,30,3,1,382.890000000,383.420000000,20,140,1,1,382.810000000,383.490000000,20,19,2,1,382.700000000,383.500000000,50,20,1,1,382.680000000,383.600000000,20,1000,1,2,382.400000000,383.720000000,500,7085,1,8,382.230000000,383.740000000,25,37,1,1,382.110000000,383.800000000,300,10,1,1,382.100000000,383.880000000,20,4,2,1,382.010000000,384.000000000,2,1300,1,4,TSLA
2025-01-03T10:32:02.024887273Z,2025-01-03T10:32:02.024720695Z,10,2,11667,A,A,1,139.210000000,400,130,166578,4904201,139.160000000,139.200000000,100,60,1,1,139.150000000,139.210000000,9860,400,2,1,139.130000000,139.220000000,2200,10,2,1,139.120000000,139.230000000,30,1977,1,2,139.110000000,139.240000000,1,300,1,2,139.100000000,139.250000000,10,1,1,1,139.090000000,139.270000000,400,37,1,2,139.080000000,139.300000000,57,507,1,4,139.070000000,139.320000000,100,39,1,1,139.030000000,139.330000000,126,503,2,2,NVDA
2025-01-03T10:32:02.401475172Z,2025-01-03T10:32:02.401309076Z,10,2,17709,C,A,1,107.870000000,16,130,166096,4904292,107.600000000,107.840000000,50,400,1,2,107.540000000,107.870000000,15,242,1,1,107.520000000,107.940000000,100,100,1,1,107.050000000,107.950000000,247,10,1,1,107.000000000,108.000000000,1,50,1,1,106.240000000,108.300000000,28,50,1,1,106.000000000,108.550000000,15,50,2,1,105.870000000,108.800000000,141,50,1,1,103.180000000,108.880000000,16,28,1,1,103.000000000,109.000000000,3,100,1,1,XOM
2025-01-03T10:32:02.401565715Z,2025-01-03T10:32:02.401399346Z,10,2,17709,A,A,1,107.860000000,16,130,166369,4904293,107.600000000,107.840000000,50,400,1,2,107.540000000,107.860000000,15,16,1,1,107.520000000,107.870000000,100,242,1,1,107.050000000,107.940000000,247,100,1,1,107.000000000,107.950000000,1,10,1,1,106.240000000,108.000000000,28,50,1,1,106.000000000,108.300000000,15,50,2,1,105.870000000,108.550000000,141,50,1,1,103.180000000,108.800000000,16,50,1,1,103.000000000,108.880000000,3,28,1,1,XOM
2025-01-03T10:32:02.410771946Z,2025-01-03T10:32:02.410604760Z,10,2,10888,C,B,2,420.570000000,14,130,167186,4904302,420.690000000,421.200000000,200,200,1,1,420.580000000,421.230000000,10,15,1,1,420.520000000,421.460000000,1,39,1,1,420.400000000,421.490000000,858,6,1,1,420.380000000,421.570000000,100,40,1,1,420.100000000,421.600000000,100,510,1,2,420.000000000,421.700000000,834,359,8,1,419.730000000,421.800000000,3,7,1,1,419.650000000,422.100000000,39,7,1,1,418.650000000,422.500000000,1,200,1,1,MSFT
2025-01-03T10:32:02.410803313Z,2025-01-03T10:32:02.410637331Z,10,2,10888,A,B,1,420.580000000,14,130,165982,4904303,420.690000000,421.200000000,200,200,1,1,420.580000000,421.230000000,24,15,2,1,420.520000000,421.460000000,1,39,1,1,420.400000000,421.490000000,858,6,1,1,420.380000000,421.570000000,100,40,1,1,420.100000000,421.600000000,100,510,1,2,420.000000000,421.700000000,834,359,8,1,419.730000000,421.800000000,3,7,1,1,419.650000000,422.100000000,39,7,1,1,418.650000000,422.500000000,1,200,1,1,MSFT
2025-01-03T10:32:02.588569292Z,2025-01-03T10:32:02.588402979Z,10,2,38,A,B,1,243.430000000,200,130,166313,4904449,243.500000000,243.590000000,6,120,1,1,243.430000000,243.650000000,400,61,2,2,243.390000000,243.660000000,29,200,1,1,243.190000000,243.710000000,2,30,1,1,243.020000000,244.000000000,79,1001,1,2,243.000000000,244.140000000,1243,79,9,1,242.990000000,244.400000000,1,50,1,1,242.800000000,244.420000000,30,10,1,1,242.750000000,244.580000000,30,100,1,1,242.590000000,245.000000000,5,79,1,2,AAPL
2025-01-03T10:32:02.606129283Z,2025-01-03T10:32:02.605963022Z,10,2,16244,A,A,0,383.250000000,47,130,166261,4904453,383.000000000,383.250000000,23,47,3,1,382.890000000,383.310000000,20,30,1,1,382.810000000,383.420000000,20,140,2,1,382.700000000,383.490000000,50,19,1,1,382.680000000,383.500000000,20,20,1,1,382.400000000,383.600000000,500,1000,1,2,382.230000000,383.720000000,25,7085,1,8,382.110000000,383.740000000,300,37,1,1,382.100000000,383.800000000,20,10,2,1,382.010000000,383.880000000,2,4,1,1,TSLA
2025-01-03T10:32:02.643154693Z,2025-01-03T10:32:02.642988729Z,10,2,38,C,B,1,243.430000000,200,130,165964,4904475,243.500000000,243.590000000,6,120,1,1,243.430000000,243.650000000,200,61,1,2,243.390000000,243.660000000,29,200,1,1,243.190000000,243.710000000,2,30,1,1,243.020000000,244.000000000,79,1001,1,2,243.000000000,244.140000000,1243,79,9,1,242.990000000,244.400000000,1,50,1,1,242.800000000,244.420000000,30,10,1,1,242.750000000,244.580000000,30,100,1,1,242.590000000,245.000000000,5,79,1,2,AAPL
2025-01-03T10:32:02.643168345Z,2025-01-03T10:32:02.643001836Z,10,2,38,A,B,1,243.460000000,200,130,166509,4904476,243.500000000,243.590000000,6,120,1,1,243.460000000,243.650000000,200,61,1,2,243.390000000,243.660000000,29,200,1,1,243.190000000,243.710000000,2,30,1,1,243.020000000,244.000000000,79,1001,1,2,243.000000000,244.140000000,1243,79,9,1,242.990000000,244.400000000,1,50,1,1,242.800000000,244.420000000,30,10,1,1,242.750000000,244.580000000,30,100,1,1,242.590000000,245.000000000,5,79,1,2,AAPL
2025-01-03T10:32:02.828979812Z,2025-01-03T10:32:02.828813821Z,10,2,38,C,B,1,243.460000000,200,130,165991,4904705,243.500000000,243.590000000,6,120,1,1,243.390000000,243.650000000,29,61,1,2,243.190000000,243.660000000,2,200,1,1,243.020000000,243.710000000,79,30,1,1,243.000000000,244.000000000,1243,1001,9,2,242.990000000,244.140000000,1,79,1,1,242.800000000,244.400000000,30,50,1,1,242.750000000,244.420000000,30,10,1,1,242.590000000,244.580000000,5,100,1,1,242.280000000,245.000000000,100,79,1,2,AAPL
2025-01-03T10:32:02.828992677Z,2025-01-03T10:32:02.828826365Z,10,2,38,A,B,1,243.430000000,200,130,166312,4904706,243.500000000,243.590000000,6,120,1,1,243.430000000,243.650000000,200,61,1,2,243.390000000,243.660000000,29,200,1,1,243.190000000,243.710000000,2,30,1,1,243.020000000,244.000000000,79,1001,1,2,243.000000000,244.140000000,1243,79,9,1,242.990000000,244.400000000,1,50,1,1,242.800000000,244.420000000,30,10,1,1,242.750000000,244.580000000,30,100,1,1,242.590000000,245.000000000,5,79,1,2,AAPL
2025-01-03T10:32:02.829325299Z,2025-01-03T10:32:02.829155836Z,10,2,38,T,N,0,243.560000000,20,0,169463,4904721,243.500000000,243.590000000,6,120,1,1,243.430000000,243.650000000,200,61,1,2,243.390000000,243.660000000,29,200,1,1,243.190000000,243.710000000,2,30,1,1,243.020000000,244.000000000,79,1001,1,2,243.000000000,244.140000000,1243,79,9,1,242.990000000,244.400000000,1,50,1,1,242.800000000,244.420000000,30,10,1,1,242.750000000,244.580000000,30,100,1,1,242.590000000,245.000000000,5,79,1,2,AAPL
2025-01-03T10:32:02.829325299Z,2025-01-03T10:32:02.829155836Z,10,2,38,T,N,0,243.570000000,20,0,169463,4904722,243.500000000,243.590000000,6,120,1,1,243.430000000,243.650000000,200,61,1,2,243.390000000,243.660000000,29,200,1,1,243.190000000,243.710000000,2,30,1,1,243.020000000,244.000000000,79,1001,1,2,243.000000000,244.140000000,1243,79,9,1,242.990000000,244.400000000,1,50,1,1,242.800000000,244.420000000,30,10,1,1,242.750000000,244.580000000,30,100,1,1,242.590000000,245.000000000,5,79,1,2,AAPL
2025-01-03T10:32:02.829325299Z,2025-01-03T10:32:02.829155836Z,10,2,38,T,N,0,243.580000000,20,0,169463,4904723,243.500000000,243.590000000,6,120,1,1,243.430000000,243.650000000,200,61,1,2,243.390000000,243.660000000,29,200,1,1,243.190000000,243.710000000,2,30,1,1,243.020000000,244.000000000,79,1001,1,2,243.000000000,244.140000000,1243,79,9,1,242.990000000,244.400000000,1,50,1,1,242.800000000,244.420000000,30,10,1,1,242.750000000,244.580000000,30,100,1,1,242.590000000,245.000000000,5,79,1,2,AAPL
2025-01-03T10:32:02.829325299Z,2025-01-03T10:32:02.829155836Z,10,2,38,T,N,0,243.580000000,26,130,169463,4904724,243.500000000,243.590000000,6,120,1,1,243.430000000,243.650000000,200,61,1,2,243.390000000,243.660000000,29,200,1,1,243.190000000,243.710000000,2,30,1,1,243.020000000,244.000000000,79,1001,1,2,243.000000000,244.140000000,1243,79,9,1,242.990000000,244.400000000,1,50,1,1,242.800000000,244.420000000,30,10,1,1,242.750000000,244.580000000,30,100,1,1,242.590000000,245.000000000,5,79,1,2,AAPL
2025-01-03T10:32:02.829579344Z,2025-01-03T10:32:02.829411603Z,10,2,38,T,N,0,243.580000000,34,130,167741,4904729,243.500000000,243.590000000,6,120,1,1,243.430000000,243.650000000,200,61,1,2,243.390000000,243.660000000,29,200,1,1,243.190000000,243.710000000,2,30,1,1,243.020000000,244.000000000,79,1001,1,2,243.000000000,244.140000000,1243,79,9,1,242.990000000,244.400000000,1,50,1,1,242.800000000,244.420000000,30,10,1,1,242.750000000,244.580000000,30,100,1,1,242.590000000,245.000000000,5,79,1,2,AAPL
2025-01-03T10:32:02.829618326Z,2025-01-03T10:32:02.829451821Z,10,2,38,C,A,4,244.000000000,1000,130,166505,4904730,243.500000000,243.590000000,6,120,1,1,243.430000000,243.650000000,200,61,1,2,243.390000000,243.660000000,29,200,1,1,243.190000000,243.710000000,2,30,1,1,243.020000000,244.000000000,79,1,1,1,243.000000000,244.140000000,1243,79,9,1,242.990000000,244.400000000,1,50,1,1,242.800000000,244.420000000,30,10,1,1,242.750000000,244.580000000,30,100,1,1,242.590000000,245.000000000,5,79,1,2,AAPL
2025-01-03T10:32:02.829656212Z,2025-01-03T10:32:02.829489261Z,10,2,38,T,N,0,243.580000000,16,130,166951,4904731,243.500000000,243.590000000,6,120,1,1,243.430000000,243.650000000,200,61,1,2,243.390000000,243.660000000,29,200,1,1,243.190000000,243.710000000,2,30,1,1,243.020000000,244.000000000,79,1,1,1,243.000000000,244.140000000,1243,79,9,1,242.990000000,244.400000000,1,50,1,1,242.800000000,244.420000000,30,10,1,1,242.750000000,244.580000000,30,100,1,1,242.590000000,245.000000000,5,79,1,2,AAPL
2025-01-03T10:32:02.830356634Z,2025-01-03T10:32:02.830190458Z,10,2,38,C,A,2,243.660000000,200,130,166176,4904734,243.500000000,243.590000000,6,120,1,1,243.430000000,243.650000000,200,61,1,2,243.390000000,243.710000000,29,30,1,1,243.190000000,244.000000000,2,1,1,1,243.020000000,244.140000000,79,79,1,1,243.000000000,244.400000000,1243,50,9,1,242.990000000,244.420000000,1,10,1,1,242.800000000,244.580000000,30,100,1,1,242.750000000,245.000000000,30,79,1,2,242.590000000,245.190000000,5,83,1,1,AAPL
2025-01-03T10:32:02.830695332Z,2025-01-03T10:32:02.830528287Z,10,2,38,T,B,0,243.590000000,120,130,167045,4904740,243.500000000,243.590000000,6,120,1,1,243.430000000,243.650000000,200,61,1,2,243.390000000,243.710000000,29,30,1,1,243.190000000,244.000000000,2,1,1,1,243.020000000,244.140000000,79,79,1,1,243.000000000,244.400000000,1243,50,9,1,242.990000000,244.420000000,1,10,1,1,242.800000000,244.580000000,30,100,1,1,242.750000000,245.000000000,30,79,1,2,242.590000000,245.190000000,5,83,1,1,AAPL
2025-01-03T10:32:02.830695332Z,2025-01-03T10:32:02.830528287Z,10,2,38,C,A,0,243.590000000,120,130,167045,4904740,243.500000000,243.650000000,6,61,1,2,243.430000000,243.710000000,200,30,1,1,243.390000000,244.000000000,29,1,1,1,243.190000000,244.140000000,2,79,1,1,243.020000000,244.400000000,79,50,1,1,243.000000000,244.420000000,1243,10,9,1,242.990000000,244.580000000,1,100,1,1,242.800000000,245.000000000,30,79,1,2,242.750000000,245.190000000,30,83,1,1,242.590000000,245.540000000,5,10,1,1,AAPL
2025-01-03T10:32:02.830718476Z,2025-01-03T10:32:02.830551759Z,10,2,38,A,B,0,243.520000000,100,130,166717,4904742,243.520000000,243.650000000,200,61,2,2,243.500000000,243.710000000,6,30,1,1,243.430000000,244.000000000,200,1,1,1,243.390000000,244.140000000,29,79,1,1,243.190000000,244.400000000,2,50,1,1,243.020000000,244.420000000,79,10,1,1,243.000000000,244.580000000,1243,100,9,1,242.990000000,245.000000000,1,79,1,2,242.800000000,245.190000000,30,83,1,1,242.750000000,245.540000000,30,10,1,1,AAPL
2025-01-03T10:32:02.830719690Z,2025-01-03T10:32:02.830552834Z,10,2,38,A,B,0,243.520000000,100,130,166856,4904743,243.520000000,243.650000000,300,61,3,2,243.500000000,243.710000000,6,30,1,1,243.430000000,244.000000000,200,1,1,1,243.390000000,244.140000000,29,79,1,1,243.190000000,244.400000000,2,50,1,1,243.020000000,244.420000000,79,10,1,1,243.000000000,244.580000000,1243,100,9,1,242.990000000,245.000000000,1,79,1,2,242.800000000,245.190000000,30,83,1,1,242.750000000,245.540000000,30,10,1,1,AAPL
2025-01-03T10:32:02.830778291Z,2025-01-03T10:32:02.830612529Z,10,2,38,C,B,0,243.520000000,100,130,165762,4904746,243.520000000,243.650000000,200,61,2,2,243.500000000,243.710000000,6,30,1,1,243.430000000,244.000000000,200,1,1,1,243.390000000,244.140000000,29,79,1,1,243.190000000,244.400000000,2,50,1,1,243.020000000,244.420000000,79,10,1,1,243.000000000,244.580000000,1243,100,9,1,242.990000000,245.000000000,1,79,1,2,242.800000000,245.190000000,30,83,1,1,242.750000000,245.540000000,30,10,1,1,AAPL
2025-01-03T10:32:02.830784612Z,2025-01-03T10:32:02.830618853Z,10,2,38,C,B,0,243.520000000,100,130,165759,4904748,243.520000000,243.650000000,100,61,1,2,243.500000000,243.710000000,6,30,1,1,243.430000000,244.000000000,200,1,1,1,243.390000000,244.140000000,29,79,1,1,243.190000000,244.400000000,2,50,1,1,243.020000000,244.420000000,79,10,1,1,243.000000000,244.580000000,1243,100,9,1,242.990000000,245.000000000,1,79,1,2,242.800000000,245.190000000,30,83,1,1,242.750000000,245.540000000,30,10,1,1,AAPL
2025-01-03T10:32:02.835713266Z,2025-01-03T10:32:02.835547329Z,10,2,38,C,B,0,243.520000000,100,130,165937,4904752,243.500000000,243.650000000,6,61,1,2,243.430000000,243.710000000,200,30,1,1,243.390000000,244.000000000,29,1,1,1,243.190000000,244.140000000,2,79,1,1,243.020000000,244.400000000,79,50,1,1,243.000000000,244.420000000,1243,10,9,1,242.990000000,244.580000000,1,100,1,1,242.800000000,245.000000000,30,79,1,2,242.750000000,245.190000000,30,83,1,1,242.590000000,245.540000000,5,10,1,1,AAPL
2025-01-03T10:32:02.876972494Z,2025-01-03T10:32:02.876806266Z,10,2,38,A,A,4,244.400000000,1000,130,166228,4904793,243.500000000,243.650000000,6,61,1,2,243.430000000,243.710000000,200,30,1,1,243.390000000,244.000000000,29,1,1,1,243.190000000,244.140000000,2,79,1,1,243.020000000,244.400000000,79,1050,1,2,243.000000000,244.420000000,1243,10,9,1,242.990000000,244.580000000,1,100,1,1,242.800000000,245.000000000,30,79,1,2,242.750000000,245.190000000,30,83,1,1,242.590000000,245.540000000,5,10,1,1,AAPL
2025-01-03T10:32:02.886637303Z,2025-01-03T10:32:02.886470655Z,10,2,11667,A,B,4,139.110000000,400,130,166648,4904797,139.160000000,139.200000000,100,60,1,1,139.150000000,139.210000000,9860,400,2,1,139.130000000,139.220000000,2200,10,2,1,139.120000000,139.230000000,30,1977,1,2,139.110000000,139.240000000,401,300,2,2,139.100000000,139.250000000,10,1,1,1,139.080000000,139.270000000,57,37,1,2,139.070000000,139.300000000,100,507,1,4,139.030000000,139.320000000,126,39,2,1,139.010000000,139.330000000,100,503,1,2,NVDA
2025-01-03T10:32:02.934249233Z,2025-01-03T10:32:02.934082979Z,10,2,38,A,A,1,243.660000000,200,130,166254,4904804,243.500000000,243.650000000,6,61,1,2,243.430000000,243.660000000,200,200,1,1,243.390000000,243.710000000,29,30,1,1,243.190000000,244.000000000,2,1,1,1,243.020000000,244.140000000,79,79,1,1,243.000000000,244.400000000,1243,1050,9,2,242.990000000,244.420000000,1,10,1,1,242.800000000,244.580000000,30,100,1,1,242.750000000,245.000000000,30,79,1,2,242.590000000,245.190000000,5,83,1,1,AAPL
2025-01-03T10:32:02.972979441Z,2025-01-03T10:32:02.972813031Z,10,2,38,A,A,5,244.200000000,1000,130,166410,4904807,243.500000000,243.650000000,6,61,1,2,243.430000000,243.660000000,200,200,1,1,243.390000000,243.710000000,29,30,1,1,243.190000000,244.000000000,2,1,1,1,243.020000000,244.140000000,79,79,1,1,243.000000000,244.200000000,1243,1000,9,1,242.990000000,244.400000000,1,1050,1,2,242.800000000,244.420000000,30,10,1,1,242.750000000,244.580000000,30,100,1,1,242.590000000,245.000000000,5,79,1,2,AAPL
2025-01-03T10:32:02.973007349Z,2025-01-03T10:32:02.972841310Z,10,2,38,C,A,6,244.400000000,1000,130,166039,4904808,243.500000000,243.650000000,6,61,1,2,243.430000000,243.660000000,200,200,1,1,243.390000000,243.710000000,29,30,1,1,243.190000000,244.000000000,2,1,1,1,243.020000000,244.140000000,79,79,1,1,243.000000000,244.200000000,1243,1000,9,1,242.990000000,244.400000000,1,50,1,1,242.800000000,244.420000000,30,10,1,1,242.750000000,244.580000000,30,100,1,1,242.590000000,245.000000000,5,79,1,2,AAPL
2025-01-03T10:32:03.390819024Z,2025-01-03T10:32:03.390652839Z,10,2,9155,C,B,1,241.590000000,8,130,166185,4905005,241.670000000,242.070000000,2,62,1,1,241.120000000,242.410000000,81,8,1,1,241.000000000,242.850000000,100,300,1,2,240.000000000,242.900000000,10,100,1,1,238.000000000,243.000000000,30,92,1,2,236.000000000,243.310000000,6,10,1,1,235.500000000,243.700000000,5,100,1,1,235.000000000,246.810000000,5,100,1,1,232.880000000,262.740000000,1,100,1,1,231.110000000,263.830000000,3,100,1,1,JPM
2025-01-03T10:32:03.832567103Z,2025-01-03T10:32:03.832400549Z,10,2,11667,C,B,4,139.110000000,400,130,166554,4905302,139.160000000,139.200000000,100,60,1,1,139.150000000,139.210000000,9860,400,2,1,139.130000000,139.220000000,2200,10,2,1,139.120000000,139.230000000,30,1977,1,2,139.110000000,139.240000000,1,300,1,2,139.100000000,139.250000000,10,1,1,1,139.080000000,139.270000000,57,37,1,2,139.070000000,139.300000000,100,507,1,4,139.030000000,139.320000000,126,39,2,1,139.010000000,139.330000000,100,503,1,2,NVDA
2025-01-03T10:32:03.832578996Z,2025-01-03T10:32:03.832412527Z,10,2,11667,A,B,6,139.090000000,400,130,166469,4905303,139.160000000,139.200000000,100,60,1,1,139.150000000,139.210000000,9860,400,2,1,139.130000000,139.220000000,2200,10,2,1,139.120000000,139.230000000,30,1977,1,2,139.110000000,139.240000000,1,300,1,2,139.100000000,139.250000000,10,1,1,1,139.090000000,139.270000000,400,37,1,2,139.080000000,139.300000000,57,507,1,4,139.070000000,139.320000000,100,39,1,1,139.030000000,139.330000000,126,503,2,2,NVDA
2025-01-03T10:32:03.838920608Z,2025-01-03T10:32:03.838754503Z,10,2,6905,C,B,0,91.520000000,7,130,166105,4905305,91.480000000,91.950000000,150,7,1,1,91.440000000,91.960000000,100,100,1,1,90.000000000,93.000000000,122,1,1,1,89.000000000,94.000000000,1,1,1,1,83.810000000,95.000000000,100,2,1,2,83.400000000,96.000000000,100,1,1,1,,97.000000000,0,2,0,2,,99.950000000,0,100,0,1,,100.360000000,0,100,0,1,,,0,0,0,0,GILD
2025-01-03T10:32:03.839057648Z,2025-01-03T10:32:03.838890477Z,10,2,6905,A,B,2,91.430000000,7,130,167171,4905306,91.480000000,91.950000000,150,7,1,1,91.440000000,91.960000000,100,100,1,1,91.430000000,93.000000000,7,1,1,1,90.000000000,94.000000000,122,1,1,1,89.000000000,95.000000000,1,2,1,2,83.810000000,96.000000000,100,1,1,1,83.400000000,97.000000000,100,2,1,2,,99.950000000,0,100,0,1,,100.360000000,0,100,0,1,,,0,0,0,0,GILD
2025-01-03T10:32:03.839138963Z,2025-01-03T10:32:03.838972348Z,10,2,6905,A,A,0,91.940000000,7,130,166615,4905307,91.480000000,91.940000000,150,7,1,1,91.440000000,91.950000000,100,7,1,1,91.430000000,91.960000000,7,100,1,1,90.000000000,93.000000000,122,1,1,1,89.000000000,94.000000000,1,1,1,1,83.810000000,95.000000000,100,2,1,2,83.400000000,96.000000000,100,1,1,1,,97.000000000,0,2,0,2,,99.950000000,0,100,0,1,,100.360000000,0,100,0,1,GILD
2025-01-03T10:32:03.839169632Z,2025-01-03T10:32:03.839003766Z,10,2,6905,C,A,1,91.950000000,7,130,165866,4905308,91.480000000,91.940000000,150,7,1,1,91.440000000,91.960000000,100,100,1,1,91.430000000,93.000000000,7,1,1,1,90.000000000,94.000000000,122,1,1,1,89.000000000,95.000000000,1,2,1,2,83.810000000,96.000000000,100,1,1,1,83.400000000,97.000000000,100,2,1,2,,99.950000000,0,100,0,1,,100.360000000,0,100,0,1,,,0,0,0,0,GILD
2025-01-03T10:32:03.893600049Z,2025-01-03T10:32:03.893432704Z,10,2,6905,A,B,0,91.480000000,100,130,167345,4905315,91.480000000,91.940000000,250,7,2,1,91.430000000,91.960000000,7,100,1,1,90.000000000,93.000000000,122,1,1,1,89.000000000,94.000000000,1,1,1,1,83.810000000,95.000000000,100,2,1,2,83.400000000,96.000000000,100,1,1,1,,97.000000000,0,2,0,2,,99.950000000,0,100,0,1,,100.360000000,0,100,0,1,,,0,0,0,0,GILD
2025-01-03T10:32:03.991685089Z,2025-01-03T10:32:03.991519081Z,10,2,16244,C,B,1,382.890000000,20,130,166008,4905360,383.000000000,383.250000000,23,47,3,1,382.810000000,383.310000000,20,30,2,1,382.700000000,383.420000000,50,140,1,1,382.680000000,383.490000000,20,19,1,1,382.400000000,383.500000000,500,20,1,1,382.230000000,383.600000000,25,1000,1,2,382.110000000,383.720000000,300,7085,1,8,382.100000000,383.740000000,20,37,2,1,382.010000000,383.800000000,2,10,1,1,382.000000000,383.880000000,1242,4,11,1,TSLA
2025-01-03T10:32:03.991754833Z,2025-01-03T10:32:03.991588598Z,10,2,16244,A,B,1,382.840000000,23,130,166235,4905361,383.000000000,383.250000000,23,47,3,1,382.840000000,383.310000000,23,30,1,1,382.810000000,383.420000000,20,140,2,1,382.700000000,383.490000000,50,19,1,1,382.680000000,383.500000000,20,20,1,1,382.400000000,383.600000000,500,1000,1,2,382.230000000,383.720000000,25,7085,1,8,382.110000000,383.740000000,300,37,1,1,382.100000000,383.800000000,20,10,2,1,382.010000000,383.880000000,2,4,1,1,TSLA
2025-01-03T10:32:04.638491834Z,2025-01-03T10:32:04.638326045Z,10,2,38,C,A,1,243.660000000,200,130,165789,4905790,243.500000000,243.650000000,6,61,1,2,243.430000000,243.710000000,200,30,1,1,243.390000000,244.000000000,29,1,1,1,243.190000000,244.140000000,2,79,1,1,243.020000000,244.200000000,79,1000,1,1,243.000000000,244.400000000,1243,50,9,1,242.990000000,244.420000000,1,10,1,1,242.800000000,244.580000000,30,100,1,1,242.750000000,245.000000000,30,79,1,2,242.590000000,245.190000000,5,83,1,1,AAPL
2025-01-03T10:32:04.638505620Z,2025-01-03T10:32:04.638339346Z,10,2,38,A,A,1,243.680000000,400,130,166274,4905791,243.500000000,243.650000000,6,61,1,2,243.430000000,243.680000000,200,400,1,1,243.390000000,243.710000000,29,30,1,1,243.190000000,244.000000000,2,1,1,1,243.020000000,244.140000000,79,79,1,1,243.000000000,244.200000000,1243,1000,9,1,242.990000000,244.400000000,1,50,1,1,242.800000000,244.420000000,30,10,1,1,242.750000000,244.580000000,30,100,1,1,242.590000000,245.000000000,5,79,1,2,AAPL
2025-01-03T10:32:04.638804262Z,2025-01-03T10:32:04.638637338Z,10,2,38,T,N,0,243.640000000,61,130,166924,4905808,243.500000000,243.650000000,6,61,1,2,243.430000000,243.680000000,200,400,1,1,243.390000000,243.710000000,29,30,1,1,243.190000000,244.000000000,2,1,1,1,243.020000000,244.140000000,79,79,1,1,243.000000000,244.200000000,1243,1000,9,1,242.990000000,244.400000000,1,50,1,1,242.800000000,244.420000000,30,10,1,1,242.750000000,244.580000000,30,100,1,1,242.590000000,245.000000000,5,79,1,2,AAPL
2025-01-03T10:32:04.639165316Z,2025-01-03T10:32:04.638998360Z,10,2,38,T,N,0,243.640000000,30,130,166956,4905811,243.500000000,243.650000000,6,61,1,2,243.430000000,243.680000000,200,400,1,1,243.390000000,243.710000000,29,30,1,1,243.190000000,244.000000000,2,1,1,1,243.020000000,244.140000000,79,79,1,1,243.000000000,244.200000000,1243,1000,9,1,242.990000000,244.400000000,1,50,1,1,242.800000000,244.420000000,30,10,1,1,242.750000000,244.580000000,30,100,1,1,242.590000000,245.000000000,5,79,1,2,AAPL
2025-01-03T10:32:04.639235039Z,2025-01-03T10:32:04.639069054Z,10,2,38,C,A,5,244.200000000,1000,130,165985,4905812,243.500000000,243.650000000,6,61,1,2,243.430000000,243.680000000,200,400,1,1,243.390000000,243.710000000,29,30,1,1,243.190000000,244.000000000,2,1,1,1,243.020000000,244.140000000,79,79,1,1,243.000000000,244.400000000,1243,50,9,1,242.990000000,244.420000000,1,10,1,1,242.800000000,244.580000000,30,100,1,1,242.750000000,245.000000000,30,79,1,2,242.590000000,245.190000000,5,83,1,1,AAPL
2025-01-03T10:32:04.639281973Z,2025-01-03T10:32:04.639115902Z,10,2,38,C,A,2,243.710000000,30,130,166071,4905813,243.500000000,243.650000000,6,61,1,2,243.430000000,243.680000000,200,400,1,1,243.390000000,244.000000000,29,1,1,1,243.190000000,244.140000000,2,79,1,1,243.020000000,244.400000000,79,50,1,1,243.000000000,244.420000000,1243,10,9,1,242.990000000,244.580000000,1,100,1,1,242.800000000,245.000000000,30,79,1,2,242.750000000,245.190000000,30,83,1,1,242.590000000,245.540000000,5,10,1,1,AAPL
2025-01-03T10:32:04.639344320Z,2025-01-03T10:32:04.639177678Z,10,2,38,A,A,2,243.760000000,29,130,166642,4905814,243.500000000,243.650000000,6,61,1,2,243.430000000,243.680000000,200,400,1,1,243.390000000,243.760000000,29,29,1,1,243.190000000,244.000000000,2,1,1,1,243.020000000,244.140000000,79,79,1,1,243.000000000,244.400000000,1243,50,9,1,242.990000000,244.420000000,1,10,1,1,242.800000000,244.580000000,30,100,1,1,242.750000000,245.000000000,30,79,1,2,242.590000000,245.190000000,5,83,1,1,AAPL
2025-01-03T10:32:04.639647856Z,2025-01-03T10:32:04.639481843Z,10,2,38,C,A,1,243.680000000,400,130,166013,4905817,243.500000000,243.650000000,6,61,1,2,243.430000000,243.760000000,200,29,1,1,243.390000000,244.000000000,29,1,1,1,243.190000000,244.140000000,2,79,1,1,243.020000000,244.400000000,79,50,1,1,243.000000000,244.420000000,1243,10,9,1,242.990000000,244.580000000,1,100,1,1,242.800000000,245.000000000,30,79,1,2,242.750000000,245.190000000,30,83,1,1,242.590000000,245.540000000,5,10,1,1,AAPL
2025-01-03T10:32:04.639819779Z,2025-01-03T10:32:04.639651323Z,10,2,38,T,B,0,243.650000000,31,0,168456,4905818,243.500000000,243.650000000,6,61,1,2,243.430000000,243.760000000,200,29,1,1,243.390000000,244.000000000,29,1,1,1,243.190000000,244.140000000,2,79,1,1,243.020000000,244.400000000,79,50,1,1,243.000000000,244.420000000,1243,10,9,1,242.990000000,244.580000000,1,100,1,1,242.800000000,245.000000000,30,79,1,2,242.750000000,245.190000000,30,83,1,1,242.590000000,245.540000000,5,10,1,1,AAPL
2025-01-03T10:32:04.639819779Z,2025-01-03T10:32:04.639651323Z,10,2,38,T,B,0,243.650000000,30,130,168456,4905819,243.500000000,243.650000000,6,30,1,1,243.430000000,243.760000000,200,29,1,1,243.390000000,244.000000000,29,1,1,1,243.190000000,244.140000000,2,79,1,1,243.020000000,244.400000000,79,50,1,1,243.000000000,244.420000000,1243,10,9,1,242.990000000,244.580000000,1,100,1,1,242.800000000,245.000000000,30,79,1,2,242.750000000,245.190000000,30,83,1,1,242.590000000,245.540000000,5,10,1,1,AAPL
2025-01-03T10:32:04.639819779Z,2025-01-03T10:32:04.639651323Z,10,2,38,C,A,0,243.650000000,30,130,168456,4905819,243.500000000,243.760000000,6,29,1,1,243.430000000,244.000000000,200,1,1,1,243.390000000,244.140000000,29,79,1,1,243.190000000,244.400000000,2,50,1,1,243.020000000,244.420000000,79,10,1,1,243.000000000,244.580000000,1243,100,9,1,242.990000000,245.000000000,1,79,1,2,242.800000000,245.190000000,30,83,1,1,242.750000000,245.540000000,30,10,1,1,242.590000000,245.550000000,5,6,1,1,AAPL
2025-01-03T10:32:04.639840593Z,2025-01-03T10:32:04.639673736Z,10,2,38,A,B,0,243.530000000,100,130,166857,4905820,243.530000000,243.760000000,100,29,1,1,243.500000000,244.000000000,6,1,1,1,243.430000000,244.140000000,200,79,1,1,243.390000000,244.400000000,29,50,1,1,243.190000000,244.420000000,2,10,1,1,243.020000000,244.580000000,79,100,1,1,243.000000000,245.000000000,1243,79,9,2,242.990000000,245.190000000,1,83,1,1,242.800000000,245.540000000,30,10,1,1,242.750000000,245.550000000,30,6,1,1,AAPL
2025-01-03T10:32:04.639842923Z,2025-01-03T10:32:04.639675013Z,10,2,38,A,B,0,243.530000000,100,130,167910,4905821,243.530000000,243.760000000,200,29,2,1,243.500000000,244.000000000,6,1,1,1,243.430000000,244.140000000,200,79,1,1,243.390000000,244.400000000,29,50,1,1,243.190000000,244.420000000,2,10,1,1,243.020000000,244.580000000,79,100,1,1,243.000000000,245.000000000,1243,79,9,2,242.990000000,245.190000000,1,83,1,1,242.800000000,245.540000000,30,10,1,1,242.750000000,245.550000000,30,6,1,1,AAPL
2025-01-03T10:32:04.639856430Z,2025-01-03T10:32:04.639689548Z,10,2,38,C,B,0,243.530000000,100,130,166882,4905822,243.530000000,243.760000000,100,29,1,1,243.500000000,244.000000000,6,1,1,1,243.430000000,244.140000000,200,79,1,1,243.390000000,244.400000000,29,50,1,1,243.190000000,244.420000000,2,10,1,1,243.020000000,244.580000000,79,100,1,1,243.000000000,245.000000000,1243,79,9,2,242.990000000,245.190000000,1,83,1,1,242.800000000,245.540000000,30,10,1,1,242.750000000,245.550000000,30,6,1,1,AAPL
2025-01-03T10:32:04.644838888Z,2025-01-03T10:32:04.644672728Z,10,2,38,C,B,0,243.530000000,100,130,166160,4905828,243.500000000,243.760000000,6,29,1,1,243.430000000,244.000000000,200,1,1,1,243.390000000,244.140000000,29,79,1,1,243.190000000,244.400000000,2,50,1,1,243.020000000,244.420000000,79,10,1,1,243.000000000,244.580000000,1243,100,9,1,242.990000000,245.000000000,1,79,1,2,242.800000000,245.190000000,30,83,1,1,242.750000000,245.540000000,30,10,1,1,242.590000000,245.550000000,5,6,1,1,AAPL
2025-01-03T10:32:04.675562569Z,2025-01-03T10:32:04.675396216Z,10,2,38,A,A,3,244.200000000,1000,130,166353,4905896,243.500000000,243.760000000,6,29,1,1,243.430000000,244.000000000,200,1,1,1,243.390000000,244.140000000,29,79,1,1,243.190000000,244.200000000,2,1000,1,1,243.020000000,244.400000000,79,50,1,1,243.000000000,244.420000000,1243,10,9,1,242.990000000,244.580000000,1,100,1,1,242.800000000,245.000000000,30,79,1,2,242.750000000,245.190000000,30,83,1,1,242.590000000,245.540000000,5,10,1,1,AAPL
2025-01-03T10:32:04.693660572Z,2025-01-03T10:32:04.693494126Z,10,2,38,A,B,1,243.450000000,200,130,166446,4905916,243.500000000,243.760000000,6,29,1,1,243.450000000,244.000000000,200,1,1,1,243.390000000,244.140000000,29,79,1,1,243.190000000,244.200000000,2,1000,1,1,243.020000000,244.400000000,79,50,1,1,243.000000000,244.420000000,1243,10,9,1,242.990000000,244.580000000,1,100,1,1,242.800000000,245.000000000,30,79,1,2,242.750000000,245.190000000,30,83,1,1,242.590000000,245.540000000,5,10,1,1,AAPL
2025-01-03T10:32:04.765770749Z,2025-01-03T10:32:04.765604525Z,10,2,38,A,A,0,243.710000000,200,130,166224,4906087,243.500000000,243.710000000,6,200,1,1,243.450000000,243.760000000,200,29,1,1,243.390000000,244.000000000,29,1,1,1,243.190000000,244.140000000,2,79,1,1,243.020000000,244.200000000,79,1000,1,1,243.000000000,244.400000000,1243,50,9,1,242.990000000,244.420000000,1,10,1,1,242.800000000,244.580000000,30,100,1,1,242.750000000,245.000000000,30,79,1,2,242.590000000,245.190000000,5,83,1,1,AAPL
2025-01-03T10:32:04.788777150Z,2025-01-03T10:32:04.788610832Z,10,2,38,A,B,1,243.460000000,200,130,166318,4906098,243.500000000,243.710000000,6,200,1,1,243.460000000,243.760000000,200,29,1,1,243.390000000,244.000000000,29,1,1,1,243.190000000,244.140000000,2,79,1,1,243.020000000,244.200000000,79,1000,1,1,243.000000000,244.400000000,1243,50,9,1,242.990000000,244.420000000,1,10,1,1,242.800000000,244.580000000,30,100,1,1,242.750000000,245.000000000,30,79,1,2,242.590000000,245.190000000,5,83,1,1,AAPL
2025-01-03T10:32:04.840898464Z,2025-01-03T10:32:04.840732333Z,10,2,6905,C,B,1,91.430000000,7,130,166131,4906149,91.480000000,91.940000000,250,7,2,1,90.000000000,91.960000000,122,100,1,1,89.000000000,93.000000000,1,1,1,1,83.810000000,94.000000000,100,1,1,1,83.400000000,95.000000000,100,2,1,2,,96.000000000,0,1,0,1,,97.000000000,0,2,0,2,,99.950000000,0,100,0,1,,100.360000000,0,100,0,1,,,0,0,0,0,GILD
2025-01-03T10:32:04.840960277Z,2025-01-03T10:32:04.840794355Z,10,2,6905,A,B,0,91.510000000,7,130,165922,4906150,91.510000000,91.940000000,7,7,1,1,91.480000000,91.960000000,250,100,2,1,90.000000000,93.000000000,122,1,1,1,89.000000000,94.000000000,1,1,1,1,83.810000000,95.000000000,100,2,1,2,83.400000000,96.000000000,100,1,1,1,,97.000000000,0,2,0,2,,99.950000000,0,100,0,1,,100.360000000,0,100,0,1,,,0,0,0,0,GILD
2025-01-03T10:32:05.020041266Z,2025-01-03T10:32:05.019875087Z,10,2,11667,C,A,1,139.210000000,400,130,166179,4906241,139.160000000,139.200000000,100,60,1,1,139.150000000,139.220000000,9860,10,2,1,139.130000000,139.230000000,2200,1977,2,2,139.120000000,139.240000000,30,300,1,2,139.110000000,139.250000000,1,1,1,1,139.100000000,139.270000000,10,37,1,2,139.090000000,139.300000000,400,507,1,4,139.080000000,139.320000000,57,39,1,1,139.070000000,139.330000000,100,503,1,2,139.030000000,139.360000000,126,4,2,2,NVDA
2025-01-03T10:32:05.020168988Z,2025-01-03T10:32:05.020001846Z,10,2,11667,T,B,0,139.200000000,30,130,167142,4906247,139.160000000,139.200000000,100,60,1,1,139.150000000,139.220000000,9860,10,2,1,139.130000000,139.230000000,2200,1977,2,2,139.120000000,139.240000000,30,300,1,2,139.110000000,139.250000000,1,1,1,1,139.100000000,139.270000000,10,37,1,2,139.090000000,139.300000000,400,507,1,4,139.080000000,139.320000000,57,39,1,1,139.070000000,139.330000000,100,503,1,2,139.030000000,139.360000000,126,4,2,2,NVDA
2025-01-03T10:32:05.020168988Z,2025-01-03T10:32:05.020001846Z,10,2,11667,C,A,0,139.200000000,30,130,167142,4906247,139.160000000,139.200000000,100,30,1,1,139.150000000,139.220000000,9860,10,2,1,139.130000000,139.230000000,2200,1977,2,2,139.120000000,139.240000000,30,300,1,2,139.110000000,139.250000000,1,1,1,1,139.100000000,139.270000000,10,37,1,2,139.090000000,139.300000000,400,507,1,4,139.080000000,139.320000000,57,39,1,1,139.070000000,139.330000000,100,503,1,2,139.030000000,139.360000000,126,4,2,2,NVDA
2025-01-03T10:32:05.136535409Z,2025-01-03T10:32:05.136369123Z,10,2,11667,A,A,1,139.210000000,400,130,166286,4906324,139.160000000,139.200000000,100,30,1,1,139.150000000,139.210000000,9860,400,2,1,139.130000000,139.220000000,2200,10,2,1,139.120000000,139.230000000,30,1977,1,2,139.110000000,139.240000000,1,300,1,2,139.100000000,139.250000000,10,1,1,1,139.090000000,139.270000000,400,37,1,2,139.080000000,139.300000000,57,507,1,4,139.070000000,139.320000000,100,39,1,1,139.030000000,139.330000000,126,503,2,2,NVDA
2025-01-03T10:32:06.789462677Z,2025-01-03T10:32:06.789296531Z,10,2,11667,A,A,0,139.200000000,100,130,166146,4907349,139.160000000,139.200000000,100,130,1,2,139.150000000,139.210000000,9860,400,2,1,139.130000000,139.220000000,2200,10,2,1,139.120000000,139.230000000,30,1977,1,2,139.110000000,139.240000000,1,300,1,2,139.100000000,139.250000000,10,1,1,1,139.090000000,139.270000000,400,37,1,2,139.080000000,139.300000000,57,507,1,4,139.070000000,139.320000000,100,39,1,1,139.030000000,139.330000000,126,503,2,2,NVDA
2025-01-03T10:32:06.968721055Z,2025-01-03T10:32:06.968554788Z,10,2,16244,C,A,3,383.490000000,19,130,166267,4907430,383.000000000,383.250000000,23,47,3,1,382.840000000,383.310000000,23,30,1,1,382.810000000,383.420000000,20,140,2,1,382.700000000,383.500000000,50,20,1,1,382.680000000,383.600000000,20,1000,1,2,382.400000000,383.720000000,500,7085,1,8,382.230000000,383.740000000,25,37,1,1,382.110000000,383.800000000,300,10,1,1,382.100000000,383.880000000,20,4,2,1,382.010000000,384.000000000,2,1300,1,4,TSLA
2025-01-03T10:32:06.968813627Z,2025-01-03T10:32:06.968647504Z,10,2,16244,A,A,3,383.440000000,22,130,166123,4907432,383.000000000,383.250000000,23,47,3,1,382.840000000,383.310000000,23,30,1,1,382.810000000,383.420000000,20,140,2,1,382.700000000,383.440000000,50,22,1,1,382.680000000,383.500000000,20,20,1,1,382.400000000,383.600000000,500,1000,1,2,382.230000000,383.720000000,25,7085,1,8,382.110000000,383.740000000,300,37,1,1,382.100000000,383.800000000,20,10,2,1,382.010000000,383.880000000,2,4,1,1,TSLA
2025-01-03T10:32:07.393812346Z,2025-01-03T10:32:07.393646046Z,10,2,9155,A,B,1,241.490000000,8,130,166300,4907662,241.670000000,242.070000000,2,62,1,1,241.490000000,242.410000000,8,8,1,1,241.120000000,242.850000000,81,300,1,2,241.000000000,242.900000000,100,100,1,1,240.000000000,243.000000000,10,92,1,2,238.000000000,243.310000000,30,10,1,1,236.000000000,243.700000000,6,100,1,1,235.500000000,246.810000000,5,100,1,1,235.000000000,262.740000000,5,100,1,1,232.880000000,263.830000000,1,100,1,1,JPM
2025-01-03T10:32:07.401386113Z,2025-01-03T10:32:07.401219978Z,10,2,17709,C,A,1,107.860000000,16,130,166135,4907663,107.600000000,107.840000000,50,400,1,2,107.540000000,107.870000000,15,242,1,1,107.520000000,107.940000000,100,100,1,1,107.050000000,107.950000000,247,10,1,1,107.000000000,108.000000000,1,50,1,1,106.240000000,108.300000000,28,50,1,1,106.000000000,108.550000000,15,50,2,1,105.870000000,108.800000000,141,50,1,1,103.180000000,108.880000000,16,28,1,1,103.000000000,109.000000000,3,100,1,1,XOM
2025-01-03T10:32:07.401445192Z,2025-01-03T10:32:07.401279029Z,10,2,17709,A,A,2,107.900000000,17,130,166163,4907664,107.600000000,107.840000000,50,400,1,2,107.540000000,107.870000000,15,242,1,1,107.520000000,107.900000000,100,17,1,1,107.050000000,107.940000000,247,100,1,1,107.000000000,107.950000000,1,10,1,1,106.240000000,108.000000000,28,50,1,1,106.000000000,108.300000000,15,50,2,1,105.870000000,108.550000000,141,50,1,1,103.180000000,108.800000000,16,50,1,1,103.000000000,108.880000000,3,28,1,1,XOM
2025-01-03T10:32:07.530606834Z,2025-01-03T10:32:07.530440527Z,10,2,16244,C,B,8,382.100000000,10,130,166307,4907694,383.000000000,383.250000000,23,47,3,1,382.840000000,383.310000000,23,30,1,1,382.810000000,383.420000000,20,140,2,1,382.700000000,383.440000000,50,22,1,1,382.680000000,383.500000000,20,20,1,1,382.400000000,383.600000000,500,1000,1,2,382.230000000,383.720000000,25,7085,1,8,382.110000000,383.740000000,300,37,1,1,382.100000000,383.800000000,10,10,1,1,382.010000000,383.880000000,2,4,1,1,TSLA
2025-01-03T10:32:07.674704454Z,2025-01-03T10:32:07.674538347Z,10,2,6905,C,B,0,91.510000000,7,130,166107,4907776,91.480000000,91.940000000,250,7,2,1,90.000000000,91.960000000,122,100,1,1,89.000000000,93.000000000,1,1,1,1,83.810000000,94.000000000,100,1,1,1,83.400000000,95.000000000,100,2,1,2,,96.000000000,0,1,0,1,,97.000000000,0,2,0,2,,99.950000000,0,100,0,1,,100.360000000,0,100,0,1,,,0,0,0,0,GILD
2025-01-03T10:32:07.674763109Z,2025-01-03T10:32:07.674596704Z,10,2,6905,A,B,0,91.520000000,7,130,166405,4907777,91.520000000,91.940000000,7,7,1,1,91.480000000,91.960000000,250,100,2,1,90.000000000,93.000000000,122,1,1,1,89.000000000,94.000000000,1,1,1,1,83.810000000,95.000000000,100,2,1,2,83.400000000,96.000000000,100,1,1,1,,97.000000000,0,2,0,2,,99.950000000,0,100,0,1,,100.360000000,0,100,0,1,,,0,0,0,0,GILD
2025-01-03T10:32:07.761363876Z,2025-01-03T10:32:07.761197975Z,10,2,11667,C,A,0,139.200000000,100,130,165901,4907820,139.160000000,139.200000000,100,30,1,1,139.150000000,139.210000000,9860,400,2,1,139.130000000,139.220000000,2200,10,2,1,139.120000000,139.230000000,30,1977,1,2,139.110000000,139.240000000,1,300,1,2,139.100000000,139.250000000,10,1,1,1,139.090000000,139.270000000,400,37,1,2,139.080000000,139.300000000,57,507,1,4,139.070000000,139.320000000,100,39,1,1,139.030000000,139.330000000,126,503,2,2,NVDA
2025-01-03T10:32:08.512465047Z,2025-01-03T10:32:08.512298987Z,10,2,6905,C,B,1,91.480000000,100,130,166060,4908087,91.520000000,91.940000000,7,7,1,1,91.480000000,91.960000000,150,100,1,1,90.000000000,93.000000000,122,1,1,1,89.000000000,94.000000000,1,1,1,1,83.810000000,95.000000000,100,2,1,2,83.400000000,96.000000000,100,1,1,1,,97.000000000,0,2,0,2,,99.950000000,0,100,0,1,,100.360000000,0,100,0,1,,,0,0,0,0,GILD
2025-01-03T10:32:08.512478272Z,2025-01-03T10:32:08.512312109Z,10,2,6905,A,B,2,91.440000000,100,130,166163,4908088,91.520000000,91.940000000,7,7,1,1,91.480000000,91.960000000,150,100,1,1,91.440000000,93.000000000,100,1,1,1,90.000000000,94.000000000,122,1,1,1,89.000000000,95.000000000,1,2,1,2,83.810000000,96.000000000,100,1,1,1,83.400000000,97.000000000,100,2,1,2,,99.950000000,0,100,0,1,,100.360000000,0,100,0,1,,,0,0,0,0,GILD
2025-01-03T10:32:08.738383513Z,2025-01-03T10:32:08.738217567Z,10,2,16244,A,B,0,383.000000000,28,130,165946,4908207,383.000000000,383.250000000,51,47,4,1,382.840000000,383.310000000,23,30,1,1,382.810000000,383.420000000,20,140,2,1,382.700000000,383.440000000,50,22,1,1,382.680000000,383.500000000,20,20,1,1,382.400000000,383.600000000,500,1000,1,2,382.230000000,383.720000000,25,7085,1,8,382.110000000,383.740000000,300,37,1,1,382.100000000,383.800000000,10,10,1,1,382.010000000,383.880000000,2,4,1,1,TSLA
2025-01-03T10:32:09.030366759Z,2025-01-03T10:32:09.030200280Z,10,2,10888,A,A,0,421.140000000,200,130,166479,4908318,420.690000000,421.140000000,200,200,1,1,420.580000000,421.230000000,24,15,2,1,420.520000000,421.460000000,1,39,1,1,420.400000000,421.490000000,858,6,1,1,420.380000000,421.570000000,100,40,1,1,420.100000000,421.600000000,100,510,1,2,420.000000000,421.700000000,834,359,8,1,419.730000000,421.800000000,3,7,1,1,419.650000000,422.100000000,39,7,1,1,418.650000000,422.500000000,1,200,1,1,MSFT
2025-01-03T10:32:09.600978721Z,2025-01-03T10:32:09.600812465Z,10,2,16244,C,B,4,382.680000000,20,130,166256,4909149,383.000000000,383.250000000,51,47,4,1,382.840000000,383.310000000,23,30,1,1,382.810000000,383.420000000,20,140,2,1,382.700000000,383.440000000,50,22,1,1,382.400000000,383.500000000,500,20,1,1,382.230000000,383.600000000,25,1000,1,2,382.110000000,383.720000000,300,7085,1,8,382.100000000,383.740000000,10,37,1,1,382.010000000,383.800000000,2,10,1,1,382.000000000,383.880000000,1242,4,11,1,TSLA
2025-01-03T10:32:09.698460652Z,2025-01-03T10:32:09.698294356Z,10,2,10888,A,B,0,420.700000000,200,130,166296,4909370,420.700000000,421.140000000,200,200,1,1,420.580000000,421.230000000,24,15,2,1,420.520000000,421.460000000,1,39,1,1,420.400000000,421.490000000,858,6,1,1,420.380000000,421.570000000,100,40,1,1,420.100000000,421.600000000,100,510,1,2,420.000000000,421.700000000,834,359,8,1,419.730000000,421.800000000,3,7,1,1,419.650000000,422.100000000,39,7,1,1,418.650000000,422.500000000,1,200,1,1,MSFT
2025-01-03T10:32:09.918517609Z,2025-01-03T10:32:09.918351550Z,10,2,17709,C,A,2,107.900000000,17,130,166059,4909712,107.600000000,107.840000000,50,400,1,2,107.540000000,107.870000000,15,242,1,1,107.520000000,107.940000000,100,100,1,1,107.050000000,107.950000000,247,10,1,1,107.000000000,108.000000000,1,50,1,1,106.240000000,108.300000000,28,50,1,1,106.000000000,108.550000000,15,50,2,1,105.870000000,108.800000000,141,50,1,1,103.180000000,108.880000000,16,28,1,1,103.000000000,109.000000000,3,100,1,1,XOM
2025-01-03T10:32:09.918608971Z,2025-01-03T10:32:09.918442348Z,10,2,17709,A,A,2,107.890000000,15,130,166623,4909713,107.600000000,107.840000000,50,400,1,2,107.540000000,107.870000000,15,242,1,1,107.520000000,107.890000000,100,15,1,1,107.050000000,107.940000000,247,100,1,1,107.000000000,107.950000000,1,10,1,1,106.240000000,108.000000000,28,50,1,1,106.000000000,108.300000000,15,50,2,1,105.870000000,108.550000000,141,50,1,1,103.180000000,108.800000000,16,50,1,1,103.000000000,108.880000000,3,28,1,1,XOM
2025-01-03T10:32:09.952485932Z,2025-01-03T10:32:09.952320009Z,10,2,16244,C,B,1,382.840000000,23,130,165923,4909730,383.000000000,383.250000000,51,47,4,1,382.810000000,383.310000000,20,30,2,1,382.700000000,383.420000000,50,140,1,1,382.400000000,383.440000000,500,22,1,1,382.230000000,383.500000000,25,20,1,1,382.110000000,383.600000000,300,1000,1,2,382.100000000,383.720000000,10,7085,1,8,382.010000000,383.740000000,2,37,1,1,382.000000000,383.800000000,1242,10,11,1,381.900000000,383.880000000,23,4,1,1,TSLA
2025-01-03T10:32:09.952567439Z,2025-01-03T10:32:09.952401011Z,10,2,16244,A,B,1,382.890000000,20,130,166428,4909731,383.000000000,383.250000000,51,47,4,1,382.890000000,383.310000000,20,30,1,1,382.810000000,383.420000000,20,140,2,1,382.700000000,383.440000000,50,22,1,1,382.400000000,383.500000000,500,20,1,1,382.230000000,383.600000000,25,1000,1,2,382.110000000,383.720000000,300,7085,1,8,382.100000000,383.740000000,10,37,1,1,382.010000000,383.800000000,2,10,1,1,382.000000000,383.880000000,1242,4,11,1,TSLA
2025-01-03T10:32:10.010654902Z,2025-01-03T10:32:10.010488368Z,10,2,16244,A,A,0,383.100000000,370,130,166534,4909766,383.000000000,383.100000000,51,370,4,1,382.890000000,383.250000000,20,47,1,1,382.810000000,383.310000000,20,30,2,1,382.700000000,383.420000000,50,140,1,1,382.400000000,383.440000000,500,22,1,1,382.230000000,383.500000000,25,20,1,1,382.110000000,383.600000000,300,1000,1,2,382.100000000,383.720000000,10,7085,1,8,382.010000000,383.740000000,2,37,1,1,382.000000000,383.800000000,1242,10,11,1,TSLA
2025-01-03T10:32:10.042719801Z,2025-01-03T10:32:10.042553486Z,10,2,11667,A,A,0,139.180000000,55,130,166315,4909803,139.160000000,139.180000000,100,55,1,1,139.150000000,139.200000000,9860,30,2,1,139.130000000,139.210000000,2200,400,2,1,139.120000000,139.220000000,30,10,1,1,139.110000000,139.230000000,1,1977,1,2,139.100000000,139.240000000,10,300,1,2,139.090000000,139.250000000,400,1,1,1,139.080000000,139.270000000,57,37,1,2,139.070000000,139.300000000,100,507,1,4,139.030000000,139.320000000,126,39,2,1,NVDA
2025-01-03T10:32:10.134550169Z,2025-01-03T10:32:10.134384140Z,10,2,16244,C,B,1,382.890000000,20,130,166029,4909887,383.000000000,383.100000000,51,370,4,1,382.810000000,383.250000000,20,47,2,1,382.700000000,383.310000000,50,30,1,1,382.400000000,383.420000000,500,140,1,1,382.230000000,383.440000000,25,22,1,1,382.110000000,383.500000000,300,20,1,1,382.100000000,383.600000000,10,1000,1,2,382.010000000,383.720000000,2,7085,1,8,382.000000000,383.740000000,1242,37,11,1,381.900000000,383.800000000,23,10,1,1,TSLA
2025-01-03T10:32:11.804910718Z,2025-01-03T10:32:11.804744682Z,10,2,16244,A,A,3,383.390000000,21,130,166036,4910631,383.000000000,383.100000000,51,370,4,1,382.810000000,383.250000000,20,47,2,1,382.700000000,383.310000000,50,30,1,1,382.400000000,383.390000000,500,21,1,1,382.230000000,383.420000000,25,140,1,1,382.110000000,383.440000000,300,22,1,1,382.100000000,383.500000000,10,20,1,1,382.010000000,383.600000000,2,1000,1,2,382.000000000,383.720000000,1242,7085,11,8,381.900000000,383.740000000,23,37,1,1,TSLA
2025-01-03T10:32:11.804942777Z,2025-01-03T10:32:11.804777146Z,10,2,16244,C,A,5,383.440000000,22,130,165631,4910633,383.000000000,383.100000000,51,370,4,1,382.810000000,383.250000000,20,47,2,1,382.700000000,383.310000000,50,30,1,1,382.400000000,383.390000000,500,21,1,1,382.230000000,383.420000000,25,140,1,1,382.110000000,383.500000000,300,20,1,1,382.100000000,383.600000000,10,1000,1,2,382.010000000,383.720000000,2,7085,1,8,382.000000000,383.740000000,1242,37,11,1,381.900000000,383.800000000,23,10,1,1,TSLA
2025-01-03T10:32:11.805860586Z,2025-01-03T10:32:11.805694668Z,10,2,9155,C,B,1,241.490000000,8,130,165918,4910637,241.670000000,242.070000000,2,62,1,1,241.120000000,242.410000000,81,8,1,1,241.000000000,242.850000000,100,300,1,2,240.000000000,242.900000000,10,100,1,1,238.000000000,243.000000000,30,92,1,2,236.000000000,243.310000000,6,10,1,1,235.500000000,243.700000000,5,100,1,1,235.000000000,246.810000000,5,100,1,1,232.880000000,262.740000000,1,100,1,1,231.110000000,263.830000000,3,100,1,1,JPM
2025-01-03T10:32:11.805924646Z,2025-01-03T10:32:11.805758374Z,10,2,9155,A,B,1,241.600000000,8,130,166272,4910638,241.670000000,242.070000000,2,62,1,1,241.600000000,242.410000000,8,8,1,1,241.120000000,242.850000000,81,300,1,2,241.000000000,242.900000000,100,100,1,1,240.000000000,243.000000000,10,92,1,2,238.000000000,243.310000000,30,10,1,1,236.000000000,243.700000000,6,100,1,1,235.500000000,246.810000000,5,100,1,1,235.000000000,262.740000000,5,100,1,1,232.880000000,263.830000000,1,100,1,1,JPM
2025-01-03T10:32:11.815769437Z,2025-01-03T10:32:11.815603037Z,10,2,10888,A,B,0,420.710000000,200,130,166400,4910642,420.710000000,421.140000000,200,200,1,1,420.580000000,421.230000000,24,15,2,1,420.520000000,421.460000000,1,39,1,1,420.400000000,421.490000000,858,6,1,1,420.380000000,421.570000000,100,40,1,1,420.100000000,421.600000000,100,510,1,2,420.000000000,421.700000000,834,359,8,1,419.730000000,421.800000000,3,7,1,1,419.650000000,422.100000000,39,7,1,1,418.650000000,422.500000000,1,200,1,1,MSFT
2025-01-03T10:32:11.816248969Z,2025-01-03T10:32:11.816082553Z,10,2,11667,A,B,5,139.100000000,400,130,166416,4910646,139.160000000,139.180000000,100,55,1,1,139.150000000,139.200000000,9860,30,2,1,139.130000000,139.210000000,2200,400,2,1,139.120000000,139.220000000,30,10,1,1,139.110000000,139.230000000,1,1977,1,2,139.100000000,139.240000000,410,300,2,2,139.080000000,139.250000000,57,1,1,1,139.070000000,139.270000000,100,37,1,2,139.030000000,139.300000000,126,507,2,4,139.010000000,139.320000000,100,39,1,1,NVDA
2025-01-03T10:32:12.148250827Z,2025-01-03T10:32:12.148084864Z,10,2,11667,C,B,5,139.100000000,400,130,165963,4910878,139.160000000,139.180000000,100,55,1,1,139.150000000,139.200000000,9860,30,2,1,139.130000000,139.210000000,2200,400,2,1,139.120000000,139.220000000,30,10,1,1,139.110000000,139.230000000,1,1977,1,2,139.100000000,139.240000000,10,300,1,2,139.080000000,139.250000000,57,1,1,1,139.070000000,139.270000000,100,37,1,2,139.030000000,139.300000000,126,507,2,4,139.010000000,139.320000000,100,39,1,1,NVDA
2025-01-03T10:32:12.148261765Z,2025-01-03T10:32:12.148095538Z,10,2,11667,A,B,6,139.090000000,400,130,166227,4910879,139.160000000,139.180000000,100,55,1,1,139.150000000,139.200000000,9860,30,2,1,139.130000000,139.210000000,2200,400,2,1,139.120000000,139.220000000,30,10,1,1,139.110000000,139.230000000,1,1977,1,2,139.100000000,139.240000000,10,300,1,2,139.090000000,139.250000000,400,1,1,1,139.080000000,139.270000000,57,37,1,2,139.070000000,139.300000000,100,507,1,4,139.030000000,139.320000000,126,39,2,1,NVDA
2025-01-03T10:32:12.226057423Z,2025-01-03T10:32:12.225891063Z,10,2,17709,C,A,2,107.890000000,15,130,166360,4911044,107.600000000,107.840000000,50,400,1,2,107.540000000,107.870000000,15,242,1,1,107.520000000,107.940000000,100,100,1,1,107.050000000,107.950000000,247,10,1,1,107.000000000,108.000000000,1,50,1,1,106.240000000,108.300000000,28,50,1,1,106.000000000,108.550000000,15,50,2,1,105.870000000,108.800000000,141,50,1,1,103.180000000,108.880000000,16,28,1,1,103.000000000,109.000000000,3,100,1,1,XOM
2025-01-03T10:32:12.226120539Z,2025-01-03T10:32:12.225954243Z,10,2,17709,A,A,2,107.880000000,16,130,166296,4911045,107.600000000,107.840000000,50,400,1,2,107.540000000,107.870000000,15,242,1,1,107.520000000,107.880000000,100,16,1,1,107.050000000,107.940000000,247,100,1,1,107.000000000,107.950000000,1,10,1,1,106.240000000,108.000000000,28,50,1,1,106.000000000,108.300000000,15,50,2,1,105.870000000,108.550000000,141,50,1,1,103.180000000,108.800000000,16,50,1,1,103.000000000,108.880000000,3,28,1,1,XOM
2025-01-03T10:32:12.397585897Z,2025-01-03T10:32:12.397420045Z,10,2,9155,C,B,1,241.600000000,8,130,165852,4911179,241.670000000,242.070000000,2,62,1,1,241.120000000,242.410000000,81,8,1,1,241.000000000,242.850000000,100,300,1,2,240.000000000,242.900000000,10,100,1,1,238.000000000,243.000000000,30,92,1,2,236.000000000,243.310000000,6,10,1,1,235.500000000,243.700000000,5,100,1,1,235.000000000,246.810000000,5,100,1,1,232.880000000,262.740000000,1,100,1,1,231.110000000,263.830000000,3,100,1,1,JPM
2025-01-03T10:32:13.952463057Z,2025-01-03T10:32:13.952296730Z,10,2,16244,A,B,2,382.780000000,20,130,166327,4911902,383.000000000,383.100000000,51,370,4,1,382.810000000,383.250000000,20,47,2,1,382.780000000,383.310000000,20,30,1,1,382.700000000,383.390000000,50,21,1,1,382.400000000,383.420000000,500,140,1,1,382.230000000,383.500000000,25,20,1,1,382.110000000,383.600000000,300,1000,1,2,382.100000000,383.720000000,10,7085,1,8,382.010000000,383.740000000,2,37,1,1,382.000000000,383.800000000,1242,10,11,1,TSLA
2025-01-03T10:32:14.124251334Z,2025-01-03T10:32:14.124085409Z,10,2,10888,C,B,0,420.710000000,200,130,165925,4912156,420.580000000,421.140000000,24,200,2,1,420.520000000,421.230000000,1,15,1,1,420.400000000,421.460000000,858,39,1,1,420.380000000,421.490000000,100,6,1,1,420.100000000,421.570000000,100,40,1,1,420.000000000,421.600000000,834,510,8,2,419.730000000,421.700000000,3,359,1,1,419.650000000,421.800000000,39,7,1,1,418.650000000,422.100000000,1,7,1,1,418.500000000,422.500000000,1,200,1,1,MSFT
2025-01-03T10:32:14.124981690Z,2025-01-03T10:32:14.124815813Z,10,2,10888,C,B,0,420.580000000,14,130,165877,4912161,420.580000000,421.140000000,10,200,1,1,420.520000000,421.230000000,1,15,1,1,420.400000000,421.460000000,858,39,1,1,420.380000000,421.490000000,100,6,1,1,420.100000000,421.570000000,100,40,1,1,420.000000000,421.600000000,834,510,8,2,419.730000000,421.700000000,3,359,1,1,419.650000000,421.800000000,39,7,1,1,418.650000000,422.100000000,1,7,1,1,418.500000000,422.500000000,1,200,1,1,MSFT
2025-01-03T10:32:14.125089888Z,2025-01-03T10:32:14.124923781Z,10,2,10888,A,B,2,420.510000000,15,130,166107,4912162,420.580000000,421.140000000,10,200,1,1,420.520000000,421.230000000,1,15,1,1,420.510000000,421.460000000,15,39,1,1,420.400000000,421.490000000,858,6,1,1,420.380000000,421.570000000,100,40,1,1,420.100000000,421.600000000,100,510,1,2,420.000000000,421.700000000,834,359,8,1,419.730000000,421.800000000,3,7,1,1,419.650000000,422.100000000,39,7,1,1,418.650000000,422.500000000,1,200,1,1,MSFT
2025-01-03T10:32:14.181216531Z,2025-01-03T10:32:14.181049802Z,10,2,10888,A,B,2,420.510000000,200,130,166729,4912216,420.580000000,421.140000000,10,200,1,1,420.520000000,421.230000000,1,15,1,1,420.510000000,421.460000000,215,39,2,1,420.400000000,421.490000000,858,6,1,1,420.380000000,421.570000000,100,40,1,1,420.100000000,421.600000000,100,510,1,2,420.000000000,421.700000000,834,359,8,1,419.730000000,421.800000000,3,7,1,1,419.650000000,422.100000000,39,7,1,1,418.650000000,422.500000000,1,200,1,1,MSFT
2025-01-03T10:32:14.191216922Z,2025-01-03T10:32:14.191050582Z,10,2,10888,A,A,0,421.130000000,200,130,166340,4912228,420.580000000,421.130000000,10,200,1,1,420.520000000,421.230000000,1,15,1,1,420.510000000,421.460000000,215,39,2,1,420.400000000,421.490000000,858,6,1,1,420.380000000,421.570000000,100,40,1,1,420.100000000,421.600000000,100,510,1,2,420.000000000,421.700000000,834,359,8,1,419.730000000,421.800000000,3,7,1,1,419.650000000,422.100000000,39,7,1,1,418.650000000,422.500000000,1,200,1,1,MSFT
2025-01-03T10:32:14.372632953Z,2025-01-03T10:32:14.372466384Z,10,2,6905,A,A,0,91.930000000,7,130,166569,4912333,91.520000000,91.930000000,7,7,1,1,91.480000000,91.940000000,150,7,1,1,91.440000000,91.960000000,100,100,1,1,90.000000000,93.000000000,122,1,1,1,89.000000000,94.000000000,1,1,1,1,83.810000000,95.000000000,100,2,1,2,83.400000000,96.000000000,100,1,1,1,,97.000000000,0,2,0,2,,99.950000000,0,100,0,1,,100.360000000,0,100,0,1,GILD
2025-01-03T10:32:14.372663141Z,2025-01-03T10:32:14.372497324Z,10,2,6905,C,A,1,91.940000000,7,130,165817,4912334,91.520000000,91.930000000,7,7,1,1,91.480000000,91.960000000,150,100,1,1,91.440000000,93.000000000,100,1,1,1,90.000000000,94.000000000,122,1,1,1,89.000000000,95.000000000,1,2,1,2,83.810000000,96.000000000,100,1,1,1,83.400000000,97.000000000,100,2,1,2,,99.950000000,0,100,0,1,,100.360000000,0,100,0,1,,,0,0,0,0,GILD
2025-01-03T10:32:14.375913417Z,2025-01-03T10:32:14.375747091Z,10,2,16727,C,A,0,315.470000000,8,130,166326,4912357,314.920000000,315.510000000,8,25,1,1,314.860000000,315.750000000,25,61,1,1,314.420000000,320.000000000,61,5,1,1,313.500000000,320.210000000,1,1,1,1,310.000000000,321.950000000,1,2,1,1,300.000000000,344.200000000,3,100,1,1,290.000000000,345.620000000,2,100,1,1,286.660000000,,100,0,1,0,285.250000000,,100,0,1,0,260.000000000,,2,0,1,0,V
2025-01-03T10:32:14.376041964Z,2025-01-03T10:32:14.375876017Z,10,2,16727,A,A,0,315.460000000,8,130,165947,4912359,314.920000000,315.460000000,8,8,1,1,314.860000000,315.510000000,25,25,1,1,314.420000000,315.750000000,61,61,1,1,313.500000000,320.000000000,1,5,1,1,310.000000000,320.210000000,1,1,1,1,300.000000000,321.950000000,3,2,1,1,290.000000000,344.200000000,2,100,1,1,286.660000000,345.620000000,100,100,1,1,285.250000000,,100,0,1,0,260.000000000,,2,0,1,0,V
2025-01-03T10:32:14.378304042Z,2025-01-03T10:32:14.378137968Z,10,2,38,C,A,1,243.760000000,29,130,166074,4912373,243.500000000,243.710000000,6,200,1,1,243.460000000,244.000000000,200,1,1,1,243.390000000,244.140000000,29,79,1,1,243.190000000,244.200000000,2,1000,1,1,243.020000000,244.400000000,79,50,1,1,243.000000000,244.420000000,1243,10,9,1,242.990000000,244.580000000,1,100,1,1,242.800000000,245.000000000,30,79,1,2,242.750000000,245.190000000,30,83,1,1,242.590000000,245.540000000,5,10,1,1,AAPL
2025-01-03T10:32:14.378393291Z,2025-01-03T10:32:14.378226948Z,10,2,38,A,A,1,243.750000000,27,130,166343,4912374,243.500000000,243.710000000,6,200,1,1,243.460000000,243.750000000,200,27,1,1,243.390000000,244.000000000,29,1,1,1,243.190000000,244.140000000,2,79,1,1,243.020000000,244.200000000,79,1000,1,1,243.000000000,244.400000000,1243,50,9,1,242.990000000,244.420000000,1,10,1,1,242.800000000,244.580000000,30,100,1,1,242.750000000,245.000000000,30,79,1,2,242.590000000,245.190000000,5,83,1,1,AAPL
2025-01-03T10:32:14.668769455Z,2025-01-03T10:32:14.668602788Z,10,2,16244,A,B,0,383.040000000,5,130,166667,4912532,383.040000000,383.100000000,5,370,1,1,383.000000000,383.250000000,51,47,4,1,382.810000000,383.310000000,20,30,2,1,382.780000000,383.390000000,20,21,1,1,382.700000000,383.420000000,50,140,1,1,382.400000000,383.500000000,500,20,1,1,382.230000000,383.600000000,25,1000,1,2,382.110000000,383.720000000,300,7085,1,8,382.100000000,383.740000000,10,37,1,1,382.010000000,383.800000000,2,10,1,1,TSLA
2025-01-03T10:32:15.241692127Z,2025-01-03T10:32:15.241525945Z,10,2,10888,C,A,1,421.230000000,15,130,166182,4912700,420.580000000,421.130000000,10,200,1,1,420.520000000,421.460000000,1,39,1,1,420.510000000,421.490000000,215,6,2,1,420.400000000,421.570000000,858,40,1,1,420.380000000,421.600000000,100,510,1,2,420.100000000,421.700000000,100,359,1,1,420.000000000,421.800000000,834,7,8,1,419.730000000,422.100000000,3,7,1,1,419.650000000,422.500000000,39,200,1,1,418.650000000,423.500000000,1,600,1,2,MSFT
2025-01-03T10:32:15.241754632Z,2025-01-03T10:32:15.241588265Z,10,2,10888,A,A,1,421.220000000,13,130,166367,4912701,420.580000000,421.130000000,10,200,1,1,420.520000000,421.220000000,1,13,1,1,420.510000000,421.460000000,215,39,2,1,420.400000000,421.490000000,858,6,1,1,420.380000000,421.570000000,100,40,1,1,420.100000000,421.600000000,100,510,1,2,420.000000000,421.700000000,834,359,8,1,419.730000000,421.800000000,3,7,1,1,419.650000000,422.100000000,39,7,1,1,418.650000000,422.500000000,1,200,1,1,MSFT
2025-01-03T10:32:15.601480282Z,2025-01-03T10:32:15.601311775Z,10,2,16244,T,N,0,383.070000000,40,0,168507,4912916,383.040000000,383.100000000,5,370,1,1,383.000000000,383.250000000,51,47,4,1,382.810000000,383.310000000,20,30,2,1,382.780000000,383.390000000,20,21,1,1,382.700000000,383.420000000,50,140,1,1,382.400000000,383.500000000,500,20,1,1,382.230000000,383.600000000,25,1000,1,2,382.110000000,383.720000000,300,7085,1,8,382.100000000,383.740000000,10,37,1,1,382.010000000,383.800000000,2,10,1,1,TSLA
2025-01-03T10:32:15.601480282Z,2025-01-03T10:32:15.601311775Z,10,2,16244,T,N,0,383.080000000,10,130,168507,4912917,383.040000000,383.100000000,5,370,1,1,383.000000000,383.250000000,51,47,4,1,382.810000000,383.310000000,20,30,2,1,382.780000000,383.390000000,20,21,1,1,382.700000000,383.420000000,50,140,1,1,382.400000000,383.500000000,500,20,1,1,382.230000000,383.600000000,25,1000,1,2,382.110000000,383.720000000,300,7085,1,8,382.100000000,383.740000000,10,37,1,1,382.010000000,383.800000000,2,10,1,1,TSLA
2025-01-03T10:32:17.070143931Z,2025-01-03T10:32:17.069977761Z,10,2,16244,C,A,5,383.500000000,20,130,166170,4913701,383.040000000,383.100000000,5,370,1,1,383.000000000,383.250000000,51,47,4,1,382.810000000,383.310000000,20,30,2,1,382.780000000,383.390000000,20,21,1,1,382.700000000,383.420000000,50,140,1,1,382.400000000,383.600000000,500,1000,1,2,382.230000000,383.720000000,25,7085,1,8,382.110000000,383.740000000,300,37,1,1,382.100000000,383.800000000,10,10,1,1,382.010000000,383.880000000,2,4,1,1,TSLA
2025-01-03T10:32:17.071669183Z,2025-01-03T10:32:17.071503225Z,10,2,16244,A,A,1,383.200000000,10,130,165958,4913704,383.040000000,383.100000000,5,370,1,1,383.000000000,383.200000000,51,10,4,1,382.810000000,383.250000000,20,47,2,1,382.780000000,383.310000000,20,30,1,1,382.700000000,383.390000000,50,21,1,1,382.400000000,383.420000000,500,140,1,1,382.230000000,383.600000000,25,1000,1,2,382.110000000,383.720000000,300,7085,1,8,382.100000000,383.740000000,10,37,1,1,382.010000000,383.800000000,2,10,1,1,TSLA
2025-01-03T10:32:17.125895880Z,2025-01-03T10:32:17.125729710Z,10,2,10888,A,B,1,420.570000000,13,130,166170,4913735,420.580000000,421.130000000,10,200,1,1,420.570000000,421.220000000,13,13,1,1,420.520000000,421.460000000,1,39,1,1,420.510000000,421.490000000,215,6,2,1,420.400000000,421.570000000,858,40,1,1,420.380000000,421.600000000,100,510,1,2,420.100000000,421.700000000,100,359,1,1,420.000000000,421.800000000,834,7,8,1,419.730000000,422.100000000,3,7,1,1,419.650000000,422.500000000,39,200,1,1,MSFT
2025-01-03T10:32:17.125921690Z,2025-01-03T10:32:17.125755647Z,10,2,10888,C,B,3,420.510000000,15,130,166043,4913736,420.580000000,421.130000000,10,200,1,1,420.570000000,421.220000000,13,13,1,1,420.520000000,421.460000000,1,39,1,1,420.510000000,421.490000000,200,6,1,1,420.400000000,421.570000000,858,40,1,1,420.380000000,421.600000000,100,510,1,2,420.100000000,421.700000000,100,359,1,1,420.000000000,421.800000000,834,7,8,1,419.730000000,422.100000000,3,7,1,1,419.650000000,422.500000000,39,200,1,1,MSFT
2025-01-03T10:32:17.180666191Z,2025-01-03T10:32:17.180499784Z,10,2,10888,A,B,0,420.680000000,200,130,166407,4913813,420.680000000,421.130000000,200,200,1,1,420.580000000,421.220000000,10,13,1,1,420.570000000,421.460000000,13,39,1,1,420.520000000,421.490000000,1,6,1,1,420.400000000,421.570000000,858,40,1,1,420.380000000,421.600000000,100,510,1,2,420.100000000,421.700000000,100,359,1,1,420.000000000,421.800000000,834,7,8,1,419.730000000,422.100000000,3,7,1,1,419.650000000,422.500000000,39,200,1,1,MSFT
2025-01-03T10:32:17.395185962Z,2025-01-03T10:32:17.395018929Z,10,2,16244,T,N,0,383.090000000,5,130,167033,4913900,383.040000000,383.100000000,5,370,1,1,383.000000000,383.200000000,51,10,4,1,382.810000000,383.250000000,20,47,2,1,382.780000000,383.310000000,20,30,1,1,382.700000000,383.390000000,50,21,1,1,382.400000000,383.420000000,500,140,1,1,382.230000000,383.600000000,25,1000,1,2,382.110000000,383.720000000,300,7085,1,8,382.100000000,383.740000000,10,37,1,1,382.010000000,383.800000000,2,10,1,1,TSLA
2025-01-03T10:32:17.401277421Z,2025-01-03T10:32:17.401111113Z,10,2,9155,A,B,1,241.490000000,8,130,166308,4913902,241.670000000,242.070000000,2,62,1,1,241.490000000,242.410000000,8,8,1,1,241.120000000,242.850000000,81,300,1,2,241.000000000,242.900000000,100,100,1,1,240.000000000,243.000000000,10,92,1,2,238.000000000,243.310000000,30,10,1,1,236.000000000,243.700000000,6,100,1,1,235.500000000,246.810000000,5,100,1,1,235.000000000,262.740000000,5,100,1,1,232.880000000,263.830000000,1,100,1,1,JPM
2025-01-03T10:32:17.457932524Z,2025-01-03T10:32:17.457766722Z,10,2,16244,C,A,4,383.390000000,21,130,165802,4913926,383.040000000,383.100000000,5,370,1,1,383.000000000,383.200000000,51,10,4,1,382.810000000,383.250000000,20,47,2,1,382.780000000,383.310000000,20,30,1,1,382.700000000,383.420000000,50,140,1,1,382.400000000,383.600000000,500,1000,1,2,382.230000000,383.720000000,25,7085,1,8,382.110000000,383.740000000,300,37,1,1,382.100000000,383.800000000,10,10,1,1,382.010000000,383.880000000,2,4,1,1,TSLA
2025-01-03T10:32:17.458022301Z,2025-01-03T10:32:17.457856100Z,10,2,16244,A,A,4,383.330000000,22,130,166201,4913927,383.040000000,383.100000000,5,370,1,1,383.000000000,383.200000000,51,10,4,1,382.810000000,383.250000000,20,47,2,1,382.780000000,383.310000000,20,30,1,1,382.700000000,383.330000000,50,22,1,1,382.400000000,383.420000000,500,140,1,1,382.230000000,383.600000000,25,1000,1,2,382.110000000,383.720000000,300,7085,1,8,382.100000000,383.740000000,10,37,1,1,382.010000000,383.800000000,2,10,1,1,TSLA
2025-01-03T10:32:17.659698335Z,2025-01-03T10:32:17.659530954Z,10,2,16244,T,A,0,383.040000000,5,130,167381,4914051,383.040000000,383.100000000,5,370,1,1,383.000000000,383.200000000,51,10,4,1,382.810000000,383.250000000,20,47,2,1,382.780000000,383.310000000,20,30,1,1,382.700000000,383.330000000,50,22,1,1,382.400000000,383.420000000,500,140,1,1,382.230000000,383.600000000,25,1000,1,2,382.110000000,383.720000000,300,7085,1,8,382.100000000,383.740000000,10,37,1,1,382.010000000,383.800000000,2,10,1,1,TSLA
2025-01-03T10:32:17.659698335Z,2025-01-03T10:32:17.659530954Z,10,2,16244,C,B,0,383.040000000,5,130,167381,4914051,383.000000000,383.100000000,51,370,4,1,382.810000000,383.200000000,20,10,2,1,382.780000000,383.250000000,20,47,1,1,382.700000000,383.310000000,50,30,1,1,382.400000000,383.330000000,500,22,1,1,382.230000000,383.420000000,25,140,1,1,382.110000000,383.600000000,300,1000,1,2,382.100000000,383.720000000,10,7085,1,8,382.010000000,383.740000000,2,37,1,1,382.000000000,383.800000000,1242,10,11,1,TSLA
2025-01-03T10:32:17.659750095Z,2025-01-03T10:32:17.659579941Z,10,2,16244,T,A,0,383.000000000,3,0,170154,4914054,383.000000000,383.100000000,51,370,4,1,382.810000000,383.200000000,20,10,2,1,382.780000000,383.250000000,20,47,1,1,382.700000000,383.310000000,50,30,1,1,382.400000000,383.330000000,500,22,1,1,382.230000000,383.420000000,25,140,1,1,382.110000000,383.600000000,300,1000,1,2,382.100000000,383.720000000,10,7085,1,8,382.010000000,383.740000000,2,37,1,1,382.000000000,383.800000000,1242,10,11,1,TSLA
2025-01-03T10:32:17.659750095Z,2025-01-03T10:32:17.659579941Z,10,2,16244,T,A,0,383.000000000,10,0,170154,4914055,383.000000000,383.100000000,48,370,3,1,382.810000000,383.200000000,20,10,2,1,382.780000000,383.250000000,20,47,1,1,382.700000000,383.310000000,50,30,1,1,382.400000000,383.330000000,500,22,1,1,382.230000000,383.420000000,25,140,1,1,382.110000000,383.600000000,300,1000,1,2,382.100000000,383.720000000,10,7085,1,8,382.010000000,383.740000000,2,37,1,1,382.000000000,383.800000000,1242,10,11,1,TSLA
2025-01-03T10:32:17.659750095Z,2025-01-03T10:32:17.659579941Z,10,2,16244,T,A,0,383.000000000,10,0,170154,4914056,383.000000000,383.100000000,38,370,2,1,382.810000000,383.200000000,20,10,2,1,382.780000000,383.250000000,20,47,1,1,382.700000000,383.310000000,50,30,1,1,382.400000000,383.330000000,500,22,1,1,382.230000000,383.420000000,25,140,1,1,382.110000000,383.600000000,300,1000,1,2,382.100000000,383.720000000,10,7085,1,8,382.010000000,383.740000000,2,37,1,1,382.000000000,383.800000000,1242,10,11,1,TSLA
2025-01-03T10:32:17.659750095Z,2025-01-03T10:32:17.659579941Z,10,2,16244,T,A,0,383.000000000,28,130,170154,4914057,383.000000000,383.100000000,28,370,1,1,382.810000000,383.200000000,20,10,2,1,382.780000000,383.250000000,20,47,1,1,382.700000000,383.310000000,50,30,1,1,382.400000000,383.330000000,500,22,1,1,382.230000000,383.420000000,25,140,1,1,382.110000000,383.600000000,300,1000,1,2,382.100000000,383.720000000,10,7085,1,8,382.010000000,383.740000000,2,37,1,1,382.000000000,383.800000000,1242,10,11,1,TSLA
2025-01-03T10:32:17.659750095Z,2025-01-03T10:32:17.659579941Z,10,2,16244,C,B,0,383.000000000,28,130,170154,4914057,382.810000000,383.100000000,20,370,2,1,382.780000000,383.200000000,20,10,1,1,382.700000000,383.250000000,50,47,1,1,382.400000000,383.310000000,500,30,1,1,382.230000000,383.330000000,25,22,1,1,382.110000000,383.420000000,300,140,1,1,382.100000000,383.600000000,10,1000,1,2,382.010000000,383.720000000,2,7085,1,8,382.000000000,383.740000000,1242,37,11,1,381.900000000,383.800000000,23,10,1,1,TSLA
2025-01-03T10:32:17.659820903Z,2025-01-03T10:32:17.659652350Z,10,2,16244,T,N,0,383.000000000,3,130,168553,4914064,382.810000000,383.100000000,20,370,2,1,382.780000000,383.200000000,20,10,1,1,382.700000000,383.250000000,50,47,1,1,382.400000000,383.310000000,500,30,1,1,382.230000000,383.330000000,25,22,1,1,382.110000000,383.420000000,300,140,1,1,382.100000000,383.600000000,10,1000,1,2,382.010000000,383.720000000,2,7085,1,8,382.000000000,383.740000000,1242,37,11,1,381.900000000,383.800000000,23,10,1,1,TSLA
2025-01-03T10:32:17.659935860Z,2025-01-03T10:32:17.659768102Z,10,2,16244,T,N,0,383.000000000,1,130,167758,4914071,382.810000000,383.100000000,20,370,2,1,382.780000000,383.200000000,20,10,1,1,382.700000000,383.250000000,50,47,1,1,382.400000000,383.310000000,500,30,1,1,382.230000000,383.330000000,25,22,1,1,382.110000000,383.420000000,300,140,1,1,382.100000000,383.600000000,10,1000,1,2,382.010000000,383.720000000,2,7085,1,8,382.000000000,383.740000000,1242,37,11,1,381.900000000,383.800000000,23,10,1,1,TSLA
2025-01-03T10:32:17.660137067Z,2025-01-03T10:32:17.659969710Z,10,2,16244,T,N,0,383.000000000,1,130,167357,4914075,382.810000000,383.100000000,20,370,2,1,382.780000000,383.200000000,20,10,1,1,382.700000000,383.250000000,50,47,1,1,382.400000000,383.310000000,500,30,1,1,382.230000000,383.330000000,25,22,1,1,382.110000000,383.420000000,300,140,1,1,382.100000000,383.600000000,10,1000,1,2,382.010000000,383.720000000,2,7085,1,8,382.000000000,383.740000000,1242,37,11,1,381.900000000,383.800000000,23,10,1,1,TSLA
2025-01-03T10:32:17.660270617Z,2025-01-03T10:32:17.660104896Z,10,2,16244,C,B,3,382.400000000,500,130,165721,4914082,382.810000000,383.100000000,20,370,2,1,382.780000000,383.200000000,20,10,1,1,382.700000000,383.250000000,50,47,1,1,382.230000000,383.310000000,25,30,1,1,382.110000000,383.330000000,300,22,1,1,382.100000000,383.420000000,10,140,1,1,382.010000000,383.600000000,2,1000,1,2,382.000000000,383.720000000,1242,7085,11,8,381.900000000,383.740000000,23,37,1,1,381.880000000,383.800000000,10,10,1,1,TSLA
2025-01-03T10:32:17.722559373Z,2025-01-03T10:32:17.722392920Z,10,2,16244,A,B,0,382.820000000,21,130,166453,4914270,382.820000000,383.100000000,21,370,1,1,382.810000000,383.200000000,20,10,2,1,382.780000000,383.250000000,20,47,1,1,382.700000000,383.310000000,50,30,1,1,382.230000000,383.330000000,25,22,1,1,382.110000000,383.420000000,300,140,1,1,382.100000000,383.600000000,10,1000,1,2,382.010000000,383.720000000,2,7085,1,8,382.000000000,383.740000000,1242,37,11,1,381.900000000,383.800000000,23,10,1,1,TSLA
2025-01-03T10:32:17.727601292Z,2025-01-03T10:32:17.727435258Z,10,2,16244,C,B,0,382.820000000,21,130,166034,4914285,382.810000000,383.100000000,20,370,2,1,382.780000000,383.200000000,20,10,1,1,382.700000000,383.250000000,50,47,1,1,382.230000000,383.310000000,25,30,1,1,382.110000000,383.330000000,300,22,1,1,382.100000000,383.420000000,10,140,1,1,382.010000000,383.600000000,2,1000,1,2,382.000000000,383.720000000,1242,7085,11,8,381.900000000,383.740000000,23,37,1,1,381.880000000,383.800000000,10,10,1,1,TSLA
2025-01-03T10:32:17.732021584Z,2025-01-03T10:32:17.731855600Z,10,2,16244,C,B,1,382.780000000,20,130,165984,4914303,382.810000000,383.100000000,20,370,2,1,382.700000000,383.200000000,50,10,1,1,382.230000000,383.250000000,25,47,1,1,382.110000000,383.310000000,300,30,1,1,382.100000000,383.330000000,10,22,1,1,382.010000000,383.420000000,2,140,1,1,382.000000000,383.600000000,1242,1000,11,2,381.900000000,383.720000000,23,7085,1,8,381.880000000,383.740000000,10,37,1,1,381.870000000,383.800000000,37,10,1,1,TSLA
2025-01-03T10:32:17.766796682Z,2025-01-03T10:32:17.766630416Z,10,2,10888,A,B,0,420.690000000,200,130,166266,4914327,420.690000000,421.130000000,200,200,1,1,420.580000000,421.220000000,10,13,1,1,420.570000000,421.460000000,13,39,1,1,420.520000000,421.490000000,1,6,1,1,420.400000000,421.570000000,858,40,1,1,420.380000000,421.600000000,100,510,1,2,420.100000000,421.700000000,100,359,1,1,420.000000000,421.800000000,834,7,8,1,419.730000000,422.100000000,3,7,1,1,419.650000000,422.500000000,39,200,1,1,MSFT
2025-01-03T10:32:17.776178665Z,2025-01-03T10:32:17.776011057Z,10,2,16244,T,N,0,382.960000000,4,130,167608,4914334,382.810000000,383.100000000,20,370,2,1,382.700000000,383.200000000,50,10,1,1,382.230000000,383.250000000,25,47,1,1,382.110000000,383.310000000,300,30,1,1,382.100000000,383.330000000,10,22,1,1,382.010000000,383.420000000,2,140,1,1,382.000000000,383.600000000,1242,1000,11,2,381.900000000,383.720000000,23,7085,1,8,381.880000000,383.740000000,10,37,1,1,381.870000000,383.800000000,37,10,1,1,TSLA
2025-01-03T10:32:18.602367358Z,2025-01-03T10:32:18.602199851Z,10,2,16244,T,N,0,382.950000000,20,130,167507,4914643,382.810000000,383.100000000,20,370,2,1,382.700000000,383.200000000,50,10,1,1,382.230000000,383.250000000,25,47,1,1,382.110000000,383.310000000,300,30,1,1,382.100000000,383.330000000,10,22,1,1,382.010000000,383.420000000,2,140,1,1,382.000000000,383.600000000,1242,1000,11,2,381.900000000,383.720000000,23,7085,1,8,381.880000000,383.740000000,10,37,1,1,381.870000000,383.800000000,37,10,1,1,TSLA
2025-01-03T10:32:18.844120507Z,2025-01-03T10:32:18.843954387Z,10,2,10888,C,B,0,420.690000000,200,130,166120,4914687,420.580000000,421.130000000,10,200,1,1,420.570000000,421.220000000,13,13,1,1,420.520000000,421.460000000,1,39,1,1,420.400000000,421.490000000,858,6,1,1,420.380000000,421.570000000,100,40,1,1,420.100000000,421.600000000,100,510,1,2,420.000000000,421.700000000,834,359,8,1,419.730000000,421.800000000,3,7,1,1,419.650000000,422.100000000,39,7,1,1,418.650000000,422.500000000,1,200,1,1,MSFT
2025-01-03T10:32:18.844134132Z,2025-01-03T10:32:18.843967726Z,10,2,10888,A,B,3,420.510000000,200,130,166406,4914688,420.580000000,421.130000000,10,200,1,1,420.570000000,421.220000000,13,13,1,1,420.520000000,421.460000000,1,39,1,1,420.510000000,421.490000000,200,6,1,1,420.400000000,421.570000000,858,40,1,1,420.380000000,421.600000000,100,510,1,2,420.100000000,421.700000000,100,359,1,1,420.000000000,421.800000000,834,7,8,1,419.730000000,422.100000000,3,7,1,1,419.650000000,422.500000000,39,200,1,1,MSFT
2025-01-03T10:32:18.844708089Z,2025-01-03T10:32:18.844541905Z,10,2,10888,A,B,2,420.520000000,14,130,166184,4914690,420.580000000,421.130000000,10,200,1,1,420.570000000,421.220000000,13,13,1,1,420.520000000,421.460000000,15,39,2,1,420.510000000,421.490000000,200,6,1,1,420.400000000,421.570000000,858,40,1,1,420.380000000,421.600000000,100,510,1,2,420.100000000,421.700000000,100,359,1,1,420.000000000,421.800000000,834,7,8,1,419.730000000,422.100000000,3,7,1,1,419.650000000,422.500000000,39,200,1,1,MSFT
2025-01-03T10:32:18.844735599Z,2025-01-03T10:32:18.844569383Z,10,2,10888,C,B,1,420.570000000,13,130,166216,4914691,420.580000000,421.130000000,10,200,1,1,420.520000000,421.220000000,15,13,2,1,420.510000000,421.460000000,200,39,1,1,420.400000000,421.490000000,858,6,1,1,420.380000000,421.570000000,100,40,1,1,420.100000000,421.600000000,100,510,1,2,420.000000000,421.700000000,834,359,8,1,419.730000000,421.800000000,3,7,1,1,419.650000000,422.100000000,39,7,1,1,418.650000000,422.500000000,1,200,1,1,MSFT
2025-01-03T10:32:18.845323352Z,2025-01-03T10:32:18.845157472Z,10,2,10888,C,B,1,420.520000000,14,130,165880,4914692,420.580000000,421.130000000,10,200,1,1,420.520000000,421.220000000,1,13,1,1,420.510000000,421.460000000,200,39,1,1,420.400000000,421.490000000,858,6,1,1,420.380000000,421.570000000,100,40,1,1,420.100000000,421.600000000,100,510,1,2,420.000000000,421.700000000,834,359,8,1,419.730000000,421.800000000,3,7,1,1,419.650000000,422.100000000,39,7,1,1,418.650000000,422.500000000,1,200,1,1,MSFT
2025-01-03T10:32:18.874553773Z,2025-01-03T10:32:18.874387848Z,10,2,17709,C,A,2,107.880000000,16,130,165925,4914708,107.600000000,107.840000000,50,400,1,2,107.540000000,107.870000000,15,242,1,1,107.520000000,107.940000000,100,100,1,1,107.050000000,107.950000000,247,10,1,1,107.000000000,108.000000000,1,50,1,1,106.240000000,108.300000000,28,50,1,1,106.000000000,108.550000000,15,50,2,1,105.870000000,108.800000000,141,50,1,1,103.180000000,108.880000000,16,28,1,1,103.000000000,109.000000000,3,100,1,1,XOM
2025-01-03T10:32:18.874613156Z,2025-01-03T10:32:18.874446407Z,10,2,17709,A,A,1,107.860000000,17,130,166749,4914709,107.600000000,107.840000000,50,400,1,2,107.540000000,107.860000000,15,17,1,1,107.520000000,107.870000000,100,242,1,1,107.050000000,107.940000000,247,100,1,1,107.000000000,107.950000000,1,10,1,1,106.240000000,108.000000000,28,50,1,1,106.000000000,108.300000000,15,50,2,1,105.870000000,108.550000000,141,50,1,1,103.180000000,108.800000000,16,50,1,1,103.000000000,108.880000000,3,28,1,1,XOM
2025-01-03T10:32:18.884501611Z,2025-01-03T10:32:18.884335576Z,10,2,17709,C,B,1,107.540000000,15,130,166035,4914713,107.600000000,107.840000000,50,400,1,2,107.520000000,107.860000000,100,17,1,1,107.050000000,107.870000000,247,242,1,1,107.000000000,107.940000000,1,100,1,1,106.240000000,107.950000000,28,10,1,1,106.000000000,108.000000000,15,50,2,1,105.870000000,108.300000000,141,50,1,1,103.180000000,108.550000000,16,50,1,1,103.000000000,108.800000000,3,50,1,1,102.000000000,108.880000000,2,28,1,1,XOM
2025-01-03T10:32:18.884585287Z,2025-01-03T10:32:18.884419081Z,10,2,17709,A,B,1,107.560000000,15,130,166206,4914714,107.600000000,107.840000000,50,400,1,2,107.560000000,107.860000000,15,17,1,1,107.520000000,107.870000000,100,242,1,1,107.050000000,107.940000000,247,100,1,1,107.000000000,107.950000000,1,10,1,1,106.240000000,108.000000000,28,50,1,1,106.000000000,108.300000000,15,50,2,1,105.870000000,108.550000000,141,50,1,1,103.180000000,108.800000000,16,50,1,1,103.000000000,108.880000000,3,28,1,1,XOM
2025-01-03T10:32:18.924974449Z,2025-01-03T10:32:18.924808063Z,10,2,10888,A,B,1,420.530000000,200,130,166386,4914725,420.580000000,421.130000000,10,200,1,1,420.530000000,421.220000000,200,13,1,1,420.520000000,421.460000000,1,39,1,1,420.400000000,421.490000000,858,6,1,1,420.380000000,421.570000000,100,40,1,1,420.100000000,421.600000000,100,510,1,2,420.000000000,421.700000000,834,359,8,1,419.730000000,421.800000000,3,7,1,1,419.650000000,422.100000000,39,7,1,1,418.650000000,422.500000000,1,200,1,1,MSFT
2025-01-03T10:32:18.965315139Z,2025-01-03T10:32:18.965148843Z,10,2,16244,C,B,6,382.000000000,3,130,166296,4914743,382.810000000,383.100000000,20,370,2,1,382.700000000,383.200000000,50,10,1,1,382.230000000,383.250000000,25,47,1,1,382.110000000,383.310000000,300,30,1,1,382.100000000,383.330000000,10,22,1,1,382.010000000,383.420000000,2,140,1,1,382.000000000,383.600000000,1239,1000,10,2,381.900000000,383.720000000,23,7085,1,8,381.880000000,383.740000000,10,37,1,1,381.870000000,383.800000000,37,10,1,1,TSLA
2025-01-03T10:32:18.966448544Z,2025-01-03T10:32:18.966282242Z,10,2,16244,A,B,2,382.500000000,3,130,166302,4914744,382.810000000,383.100000000,20,370,2,1,382.700000000,383.200000000,50,10,1,1,382.500000000,383.250000000,3,47,1,1,382.230000000,383.310000000,25,30,1,1,382.110000000,383.330000000,300,22,1,1,382.100000000,383.420000000,10,140,1,1,382.010000000,383.600000000,2,1000,1,2,382.000000000,383.720000000,1239,7085,10,8,381.900000000,383.740000000,23,37,1,1,381.880000000,383.800000000,10,10,1,1,TSLA
2025-01-03T10:32:19.350210886Z,2025-01-03T10:32:19.350044794Z,10,2,16244,A,A,0,383.000000000,2,130,166092,4914968,382.810000000,383.000000000,20,2,2,1,382.700000000,383.100000000,50,370,1,1,382.500000000,383.200000000,3,10,1,1,382.230000000,383.250000000,25,47,1,1,382.110000000,383.310000000,300,30,1,1,382.100000000,383.330000000,10,22,1,1,382.010000000,383.420000000,2,140,1,1,382.000000000,383.600000000,1239,1000,10,2,381.900000000,383.720000000,23,7085,1,8,381.880000000,383.740000000,10,37,1,1,TSLA
2025-01-03T10:32:19.360543417Z,2025-01-03T10:32:19.360377469Z,10,2,16244,C,A,0,383.000000000,2,130,165948,4914981,382.810000000,383.100000000,20,370,2,1,382.700000000,383.200000000,50,10,1,1,382.500000000,383.250000000,3,47,1,1,382.230000000,383.310000000,25,30,1,1,382.110000000,383.330000000,300,22,1,1,382.100000000,383.420000000,10,140,1,1,382.010000000,383.600000000,2,1000,1,2,382.000000000,383.720000000,1239,7085,10,8,381.900000000,383.740000000,23,37,1,1,381.880000000,383.800000000,10,10,1,1,TSLA
2025-01-03T10:32:19.412548994Z,2025-01-03T10:32:19.412382568Z,10,2,16244,A,B,2,382.690000000,22,130,166426,4915080,382.810000000,383.100000000,20,370,2,1,382.700000000,383.200000000,50,10,1,1,382.690000000,383.250000000,22,47,1,1,382.500000000,383.310000000,3,30,1,1,382.230000000,383.330000000,25,22,1,1,382.110000000,383.420000000,300,140,1,1,382.100000000,383.600000000,10,1000,1,2,382.010000000,383.720000000,2,7085,1,8,382.000000000,383.740000000,1239,37,10,1,381.900000000,383.800000000,23,10,1,1,TSLA
2025-01-03T10:32:21.847113605Z,2025-01-03T10:32:21.846947451Z,10,2,10888,A,B,1,420.530000000,14,130,166154,4916145,420.580000000,421.130000000,10,200,1,1,420.530000000,421.220000000,214,13,2,1,420.520000000,421.460000000,1,39,1,1,420.400000000,421.490000000,858,6,1,1,420.380000000,421.570000000,100,40,1,1,420.100000000,421.600000000,100,510,1,2,420.000000000,421.700000000,834,359,8,1,419.730000000,421.800000000,3,7,1,1,419.650000000,422.100000000,39,7,1,1,418.650000000,422.500000000,1,200,1,1,MSFT
2025-01-03T10:32:21.877927927Z,2025-01-03T10:32:21.877761946Z,10,2,9155,C,B,1,241.490000000,8,130,165981,4916149,241.670000000,242.070000000,2,62,1,1,241.120000000,242.410000000,81,8,1,1,241.000000000,242.850000000,100,300,1,2,240.000000000,242.900000000,10,100,1,1,238.000000000,243.000000000,30,92,1,2,236.000000000,243.310000000,6,10,1,1,235.500000000,243.700000000,5,100,1,1,235.000000000,246.810000000,5,100,1,1,232.880000000,262.740000000,1,100,1,1,231.110000000,263.830000000,3,100,1,1,JPM
2025-01-03T10:32:21.878017585Z,2025-01-03T10:32:21.877851126Z,10,2,9155,A,B,1,241.600000000,8,130,166459,4916150,241.670000000,242.070000000,2,62,1,1,241.600000000,242.410000000,8,8,1,1,241.120000000,242.850000000,81,300,1,2,241.000000000,242.900000000,100,100,1,1,240.000000000,243.000000000,10,92,1,2,238.000000000,243.310000000,30,10,1,1,236.000000000,243.700000000,6,100,1,1,235.500000000,246.810000000,5,100,1,1,235.000000000,262.740000000,5,100,1,1,232.880000000,263.830000000,1,100,1,1,JPM
2025-01-03T10:32:21.901395443Z,2025-01-03T10:32:21.901228975Z,10,2,10888,A,B,0,420.660000000,200,130,166468,4916156,420.660000000,421.130000000,200,200,1,1,420.580000000,421.220000000,10,13,1,1,420.530000000,421.460000000,14,39,1,1,420.520000000,421.490000000,1,6,1,1,420.400000000,421.570000000,858,40,1,1,420.380000000,421.600000000,100,510,1,2,420.100000000,421.700000000,100,359,1,1,420.000000000,421.800000000,834,7,8,1,419.730000000,422.100000000,3,7,1,1,419.650000000,422.500000000,39,200,1,1,MSFT
2025-01-03T10:32:21.952374481Z,2025-01-03T10:32:21.952208082Z,10,2,16244,C,A,4,383.330000000,22,130,166399,4916169,382.810000000,383.100000000,20,370,2,1,382.700000000,383.200000000,50,10,1,1,382.690000000,383.250000000,22,47,1,1,382.500000000,383.310000000,3,30,1,1,382.230000000,383.420000000,25,140,1,1,382.110000000,383.600000000,300,1000,1,2,382.100000000,383.720000000,10,7085,1,8,382.010000000,383.740000000,2,37,1,1,382.000000000,383.800000000,1239,10,10,1,381.900000000,383.880000000,23,4,1,1,TSLA
2025-01-03T10:32:21.952435171Z,2025-01-03T10:32:21.952268886Z,10,2,16244,A,A,2,383.240000000,19,130,166285,4916170,382.810000000,383.100000000,20,370,2,1,382.700000000,383.200000000,50,10,1,1,382.690000000,383.240000000,22,19,1,1,382.500000000,383.250000000,3,47,1,1,382.230000000,383.310000000,25,30,1,1,382.110000000,383.420000000,300,140,1,1,382.100000000,383.600000000,10,1000,1,2,382.010000000,383.720000000,2,7085,1,8,382.000000000,383.740000000,1239,37,10,1,381.900000000,383.800000000,23,10,1,1,TSLA
2025-01-03T10:32:22.404779400Z,2025-01-03T10:32:22.404613363Z,10,2,9155,C,B,1,241.600000000,8,130,166037,4916323,241.670000000,242.070000000,2,62,1,1,241.120000000,242.410000000,81,8,1,1,241.000000000,242.850000000,100,300,1,2,240.000000000,242.900000000,10,100,1,1,238.000000000,243.000000000,30,92,1,2,236.000000000,243.310000000,6,10,1,1,235.500000000,243.700000000,5,100,1,1,235.000000000,246.810000000,5,100,1,1,232.880000000,262.740000000,1,100,1,1,231.110000000,263.830000000,3,100,1,1,JPM
2025-01-03T10:32:22.913810258Z,2025-01-03T10:32:22.913643912Z,10,2,10888,C,A,0,421.130000000,200,130,166346,4916778,420.660000000,421.220000000,200,13,1,1,420.580000000,421.460000000,10,39,1,1,420.530000000,421.490000000,14,6,1,1,420.520000000,421.570000000,1,40,1,1,420.400000000,421.600000000,858,510,1,2,420.380000000,421.700000000,100,359,1,1,420.100000000,421.800000000,100,7,1,1,420.000000000,422.100000000,834,7,8,1,419.730000000,422.500000000,3,200,1,1,419.650000000,423.500000000,39,600,1,2,MSFT
2025-01-03T10:32:22.913822958Z,2025-01-03T10:32:22.913656186Z,10,2,10888,A,A,0,421.160000000,200,128,166772,4916779,420.660000000,421.160000000,200,200,1,1,420.580000000,421.220000000,10,13,1,1,420.530000000,421.460000000,14,39,1,1,420.520000000,421.490000000,1,6,1,1,420.400000000,421.570000000,858,40,1,1,420.380000000,421.600000000,100,510,1,2,420.100000000,421.700000000,100,359,1,1,420.000000000,421.800000000,834,7,8,1,419.730000000,422.100000000,3,7,1,1,419.650000000,422.500000000,39,200,1,1,MSFT
2025-01-03T10:32:22.943939614Z,2025-01-03T10:32:22.943771441Z,10,2,11667,T,N,0,139.170000000,35,130,168173,4917268,139.160000000,139.180000000,100,55,1,1,139.150000000,139.200000000,9860,30,2,1,139.130000000,139.210000000,2200,400,2,1,139.120000000,139.220000000,30,10,1,1,139.110000000,139.230000000,1,1977,1,2,139.100000000,139.240000000,10,300,1,2,139.090000000,139.250000000,400,1,1,1,139.080000000,139.270000000,57,37,1,2,139.070000000,139.300000000,100,507,1,4,139.030000000,139.320000000,126,39,2,1,NVDA
2025-01-03T10:32:22.951820389Z,2025-01-03T10:32:22.951654504Z,10,2,16727,C,B,0,314.920000000,8,130,165885,4917314,314.860000000,315.460000000,25,8,1,1,314.420000000,315.510000000,61,25,1,1,313.500000000,315.750000000,1,61,1,1,310.000000000,320.000000000,1,5,1,1,300.000000000,320.210000000,3,1,1,1,290.000000000,321.950000000,2,2,1,1,286.660000000,344.200000000,100,100,1,1,285.250000000,345.620000000,100,100,1,1,260.000000000,,2,0,1,0,,,0,0,0,0,V
2025-01-03T10:32:22.952094518Z,2025-01-03T10:32:22.951928129Z,10,2,16727,A,B,0,314.930000000,8,130,166389,4917317,314.930000000,315.460000000,8,8,1,1,314.860000000,315.510000000,25,25,1,1,314.420000000,315.750000000,61,61,1,1,313.500000000,320.000000000,1,5,1,1,310.000000000,320.210000000,1,1,1,1,300.000000000,321.950000000,3,2,1,1,290.000000000,344.200000000,2,100,1,1,286.660000000,345.620000000,100,100,1,1,285.250000000,,100,0,1,0,260.000000000,,2,0,1,0,V
2025-01-03T10:32:22.954422458Z,2025-01-03T10:32:22.954256592Z,10,2,38,C,B,2,243.390000000,29,130,165866,4917345,243.500000000,243.710000000,6,200,1,1,243.460000000,243.750000000,200,27,1,1,243.190000000,244.000000000,2,1,1,1,243.020000000,244.140000000,79,79,1,1,243.000000000,244.200000000,1243,1000,9,1,242.990000000,244.400000000,1,50,1,1,242.800000000,244.420000000,30,10,1,1,242.750000000,244.580000000,30,100,1,1,242.590000000,245.000000000,5,79,1,2,242.280000000,245.190000000,100,83,1,1,AAPL
2025-01-03T10:32:22.954483371Z,2025-01-03T10:32:22.954317237Z,10,2,38,A,B,2,243.400000000,30,130,166134,4917346,243.500000000,243.710000000,6,200,1,1,243.460000000,243.750000000,200,27,1,1,243.400000000,244.000000000,30,1,1,1,243.190000000,244.140000000,2,79,1,1,243.020000000,244.200000000,79,1000,1,1,243.000000000,244.400000000,1243,50,9,1,242.990000000,244.420000000,1,10,1,1,242.800000000,244.580000000,30,100,1,1,242.750000000,245.000000000,30,79,1,2,242.590000000,245.190000000,5,83,1,1,AAPL
2025-01-03T10:32:22.968551240Z,2025-01-03T10:32:22.968384633Z,10,2,10888,A,B,0,420.670000000,200,130,166607,4917400,420.670000000,421.160000000,200,200,1,1,420.580000000,421.220000000,10,13,1,1,420.530000000,421.460000000,14,39,1,1,420.520000000,421.490000000,1,6,1,1,420.400000000,421.570000000,858,40,1,1,420.380000000,421.600000000,100,510,1,2,420.100000000,421.700000000,100,359,1,1,420.000000000,421.800000000,834,7,8,1,419.730000000,422.100000000,3,7,1,1,419.650000000,422.500000000,39,200,1,1,MSFT
2025-01-03T10:32:22.970029431Z,2025-01-03T10:32:22.969862973Z,10,2,11667,A,B,5,139.100000000,400,130,166458,4917403,139.160000000,139.180000000,100,55,1,1,139.150000000,139.200000000,9860,30,2,1,139.130000000,139.210000000,2200,400,2,1,139.120000000,139.220000000,30,10,1,1,139.110000000,139.230000000,1,1977,1,2,139.100000000,139.240000000,410,300,2,2,139.080000000,139.250000000,57,1,1,1,139.070000000,139.270000000,100,37,1,2,139.030000000,139.300000000,126,507,2,4,139.010000000,139.320000000,100,39,1,1,NVDA
2025-01-03T10:32:22.972074749Z,2025-01-03T10:32:22.971908725Z,10,2,17709,C,B,1,107.560000000,15,130,166024,4917411,107.600000000,107.840000000,50,400,1,2,107.520000000,107.860000000,100,17,1,1,107.050000000,107.870000000,247,242,1,1,107.000000000,107.940000000,1,100,1,1,106.240000000,107.950000000,28,10,1,1,106.000000000,108.000000000,15,50,2,1,105.870000000,108.300000000,141,50,1,1,103.180000000,108.550000000,16,50,1,1,103.000000000,108.800000000,3,50,1,1,102.000000000,108.880000000,2,28,1,1,XOM
2025-01-03T10:32:22.972180270Z,2025-01-03T10:32:22.972014225Z,10,2,17709,A,B,1,107.570000000,15,130,166045,4917412,107.600000000,107.840000000,50,400,1,2,107.570000000,107.860000000,15,17,1,1,107.520000000,107.870000000,100,242,1,1,107.050000000,107.940000000,247,100,1,1,107.000000000,107.950000000,1,10,1,1,106.240000000,108.000000000,28,50,1,1,106.000000000,108.300000000,15,50,2,1,105.870000000,108.550000000,141,50,1,1,103.180000000,108.800000000,16,50,1,1,103.000000000,108.880000000,3,28,1,1,XOM
2025-01-03T10:32:22.993114356Z,2025-01-03T10:32:22.992948374Z,10,2,10888,C,A,0,421.160000000,200,130,165982,4917497,420.670000000,421.220000000,200,13,1,1,420.580000000,421.460000000,10,39,1,1,420.530000000,421.490000000,14,6,1,1,420.520000000,421.570000000,1,40,1,1,420.400000000,421.600000000,858,510,1,2,420.380000000,421.700000000,100,359,1,1,420.100000000,421.800000000,100,7,1,1,420.000000000,422.100000000,834,7,8,1,419.730000000,422.500000000,3,200,1,1,419.650000000,423.500000000,39,600,1,2,MSFT
2025-01-03T10:32:22.993128691Z,2025-01-03T10:32:22.992961851Z,10,2,10888,A,A,0,421.220000000,200,130,166840,4917498,420.670000000,421.220000000,200,213,1,2,420.580000000,421.460000000,10,39,1,1,420.530000000,421.490000000,14,6,1,1,420.520000000,421.570000000,1,40,1,1,420.400000000,421.600000000,858,510,1,2,420.380000000,421.700000000,100,359,1,1,420.100000000,421.800000000,100,7,1,1,420.000000000,422.100000000,834,7,8,1,419.730000000,422.500000000,3,200,1,1,419.650000000,423.500000000,39,600,1,2,MSFT
2025-01-03T10:32:23.003276652Z,2025-01-03T10:32:23.003110698Z,10,2,16244,C,A,2,383.240000000,19,130,165954,4917520,382.810000000,383.100000000,20,370,2,1,382.700000000,383.200000000,50,10,1,1,382.690000000,383.250000000,22,47,1,1,382.500000000,383.310000000,3,30,1,1,382.230000000,383.420000000,25,140,1,1,382.110000000,383.600000000,300,1000,1,2,382.100000000,383.720000000,10,7085,1,8,382.010000000,383.740000000,2,37,1,1,382.000000000,383.800000000,1239,10,10,1,381.900000000,383.880000000,23,4,1,1,TSLA
2025-01-03T10:32:23.029919956Z,2025-01-03T10:32:23.029753825Z,10,2,16244,A,A,1,383.140000000,3,130,166131,4917575,382.810000000,383.100000000,20,370,2,1,382.700000000,383.140000000,50,3,1,1,382.690000000,383.200000000,22,10,1,1,382.500000000,383.250000000,3,47,1,1,382.230000000,383.310000000,25,30,1,1,382.110000000,383.420000000,300,140,1,1,382.100000000,383.600000000,10,1000,1,2,382.010000000,383.720000000,2,7085,1,8,382.000000000,383.740000000,1239,37,10,1,381.900000000,383.800000000,23,10,1,1,TSLA
2025-01-03T10:32:23.309269809Z,2025-01-03T10:32:23.309102741Z,10,2,11667,T,B,0,139.180000000,55,130,167068,4918012,139.160000000,139.180000000,100,55,1,1,139.150000000,139.200000000,9860,30,2,1,139.130000000,139.210000000,2200,400,2,1,139.120000000,139.220000000,30,10,1,1,139.110000000,139.230000000,1,1977,1,2,139.100000000,139.240000000,410,300,2,2,139.080000000,139.250000000,57,1,1,1,139.070000000,139.270000000,100,37,1,2,139.030000000,139.300000000,126,507,2,4,139.010000000,139.320000000,100,39,1,1,NVDA
2025-01-03T10:32:23.309269809Z,2025-01-03T10:32:23.309102741Z,10,2,11667,C,A,0,139.180000000,55,130,167068,4918012,139.160000000,139.200000000,100,30,1,1,139.150000000,139.210000000,9860,400,2,1,139.130000000,139.220000000,2200,10,2,1,139.120000000,139.230000000,30,1977,1,2,139.110000000,139.240000000,1,300,1,2,139.100000000,139.250000000,410,1,2,1,139.080000000,139.270000000,57,37,1,2,139.070000000,139.300000000,100,507,1,4,139.030000000,139.320000000,126,39,2,1,139.010000000,139.330000000,100,503,1,2,NVDA
2025-01-03T10:32:23.309343460Z,2025-01-03T10:32:23.309177301Z,10,2,11667,C,A,1,139.210000000,400,130,166159,4918019,139.160000000,139.200000000,100,30,1,1,139.150000000,139.220000000,9860,10,2,1,139.130000000,139.230000000,2200,1977,2,2,139.120000000,139.240000000,30,300,1,2,139.110000000,139.250000000,1,1,1,1,139.100000000,139.270000000,410,37,2,2,139.080000000,139.300000000,57,507,1,4,139.070000000,139.320000000,100,39,1,1,139.030000000,139.330000000,126,503,2,2,139.010000000,139.360000000,100,4,1,2,NVDA
2025-01-03T10:32:23.366713519Z,2025-01-03T10:32:23.366547445Z,10,2,11667,A,A,1,139.220000000,400,130,166074,4918605,139.160000000,139.200000000,100,30,1,1,139.150000000,139.220000000,9860,410,2,2,139.130000000,139.230000000,2200,1977,2,2,139.120000000,139.240000000,30,300,1,2,139.110000000,139.250000000,1,1,1,1,139.100000000,139.270000000,410,37,2,2,139.080000000,139.300000000,57,507,1,4,139.070000000,139.320000000,100,39,1,1,139.030000000,139.330000000,126,503,2,2,139.010000000,139.360000000,100,4,1,2,NVDA
2025-01-03T10:32:23.792124230Z,2025-01-03T10:32:23.791958014Z,10,2,11667,C,A,1,139.220000000,400,130,166216,4919040,139.160000000,139.200000000,100,30,1,1,139.150000000,139.220000000,9860,10,2,1,139.130000000,139.230000000,2200,1977,2,2,139.120000000,139.240000000,30,300,1,2,139.110000000,139.250000000,1,1,1,1,139.100000000,139.270000000,410,37,2,2,139.080000000,139.300000000,57,507,1,4,139.070000000,139.320000000,100,39,1,1,139.030000000,139.330000000,126,503,2,2,139.010000000,139.360000000,100,4,1,2,NVDA
2025-01-03T10:32:23.851939586Z,2025-01-03T10:32:23.851772975Z,10,2,11667,A,A,1,139.220000000,400,130,166611,4919189,139.160000000,139.200000000,100,30,1,1,139.150000000,139.220000000,9860,410,2,2,139.130000000,139.230000000,2200,1977,2,2,139.120000000,139.240000000,30,300,1,2,139.110000000,139.250000000,1,1,1,1,139.100000000,139.270000000,410,37,2,2,139.080000000,139.300000000,57,507,1,4,139.070000000,139.320000000,100,39,1,1,139.030000000,139.330000000,126,503,2,2,139.010000000,139.360000000,100,4,1,2,NVDA
2025-01-03T10:32:23.851969628Z,2025-01-03T10:32:23.851802400Z,10,2,11667,A,A,0,139.200000000,100,130,167228,4919190,139.160000000,139.200000000,100,130,1,2,139.150000000,139.220000000,9860,410,2,2,139.130000000,139.230000000,2200,1977,2,2,139.120000000,139.240000000,30,300,1,2,139.110000000,139.250000000,1,1,1,1,139.100000000,139.270000000,410,37,2,2,139.080000000,139.300000000,57,507,1,4,139.070000000,139.320000000,100,39,1,1,139.030000000,139.330000000,126,503,2,2,139.010000000,139.360000000,100,4,1,2,NVDA
2025-01-03T10:32:23.874857845Z,2025-01-03T10:32:23.874691737Z,10,2,17709,C,A,1,107.860000000,17,130,166108,4919250,107.600000000,107.840000000,50,400,1,2,107.570000000,107.870000000,15,242,1,1,107.520000000,107.940000000,100,100,1,1,107.050000000,107.950000000,247,10,1,1,107.000000000,108.000000000,1,50,1,1,106.240000000,108.300000000,28,50,1,1,106.000000000,108.550000000,15,50,2,1,105.870000000,108.800000000,141,50,1,1,103.180000000,108.880000000,16,28,1,1,103.000000000,109.000000000,3,100,1,1,XOM
2025-01-03T10:32:23.874946079Z,2025-01-03T10:32:23.874779879Z,10,2,17709,A,A,2,107.910000000,17,130,166200,4919251,107.600000000,107.840000000,50,400,1,2,107.570000000,107.870000000,15,242,1,1,107.520000000,107.910000000,100,17,1,1,107.050000000,107.940000000,247,100,1,1,107.000000000,107.950000000,1,10,1,1,106.240000000,108.000000000,28,50,1,1,106.000000000,108.300000000,15,50,2,1,105.870000000,108.550000000,141,50,1,1,103.180000000,108.800000000,16,50,1,1,103.000000000,108.880000000,3,28,1,1,XOM
2025-01-03T10:32:24.103782024Z,2025-01-03T10:32:24.103616228Z,10,2,16244,C,B,2,382.690000000,22,130,165796,4919521,382.810000000,383.100000000,20,370,2,1,382.700000000,383.140000000,50,3,1,1,382.500000000,383.200000000,3,10,1,1,382.230000000,383.250000000,25,47,1,1,382.110000000,383.310000000,300,30,1,1,382.100000000,383.420000000,10,140,1,1,382.010000000,383.600000000,2,1000,1,2,382.000000000,383.720000000,1239,7085,10,8,381.900000000,383.740000000,23,37,1,1,381.880000000,383.800000000,10,10,1,1,TSLA
2025-01-03T10:32:24.103867906Z,2025-01-03T10:32:24.103701363Z,10,2,16244,A,B,1,382.800000000,23,130,166543,4919522,382.810000000,383.100000000,20,370,2,1,382.800000000,383.140000000,23,3,1,1,382.700000000,383.200000000,50,10,1,1,382.500000000,383.250000000,3,47,1,1,382.230000000,383.310000000,25,30,1,1,382.110000000,383.420000000,300,140,1,1,382.100000000,383.600000000,10,1000,1,2,382.010000000,383.720000000,2,7085,1,8,382.000000000,383.740000000,1239,37,10,1,381.900000000,383.800000000,23,10,1,1,TSLA
2025-01-03T10:32:25.952521869Z,2025-01-03T10:32:25.952355530Z,10,2,16244,A,A,5,383.350000000,20,130,166339,4920728,382.810000000,383.100000000,20,370,2,1,382.800000000,383.140000000,23,3,1,1,382.700000000,383.200000000,50,10,1,1,382.500000000,383.250000000,3,47,1,1,382.230000000,383.310000000,25,30,1,1,382.110000000,383.350000000,300,20,1,1,382.100000000,383.420000000,10,140,1,1,382.010000000,383.600000000,2,1000,1,2,382.000000000,383.720000000,1239,7085,10,8,381.900000000,383.740000000,23,37,1,1,TSLA
2025-01-03T10:32:26.050999313Z,2025-01-03T10:32:26.050832891Z,10,2,10888,A,A,0,421.200000000,200,130,166422,4920957,420.670000000,421.200000000,200,200,1,1,420.580000000,421.220000000,10,13,1,1,420.530000000,421.460000000,14,39,1,1,420.520000000,421.490000000,1,6,1,1,420.400000000,421.570000000,858,40,1,1,420.380000000,421.600000000,100,510,1,2,420.100000000,421.700000000,100,359,1,1,420.000000000,421.800000000,834,7,8,1,419.730000000,422.100000000,3,7,1,1,419.650000000,422.500000000,39,200,1,1,MSFT
2025-01-03T10:32:26.085150792Z,2025-01-03T10:32:26.084985057Z,10,2,16244,C,B,1,382.800000000,23,130,165735,4920984,382.810000000,383.100000000,20,370,2,1,382.700000000,383.140000000,50,3,1,1,382.500000000,383.200000000,3,10,1,1,382.230000000,383.250000000,25,47,1,1,382.110000000,383.310000000,300,30,1,1,382.100000000,383.350000000,10,20,1,1,382.010000000,383.420000000,2,140,1,1,382.000000000,383.600000000,1239,1000,10,2,381.900000000,383.720000000,23,7085,1,8,381.880000000,383.740000000,10,37,1,1,TSLA
2025-01-03T10:32:26.240630823Z,2025-01-03T10:32:26.240464805Z,10,2,16244,C,A,4,383.310000000,30,130,166018,4921126,382.810000000,383.100000000,20,370,2,1,382.700000000,383.140000000,50,3,1,1,382.500000000,383.200000000,3,10,1,1,382.230000000,383.250000000,25,47,1,1,382.110000000,383.350000000,300,20,1,1,382.100000000,383.420000000,10,140,1,1,382.010000000,383.600000000,2,1000,1,2,382.000000000,383.720000000,1239,7085,10,8,381.900000000,383.740000000,23,37,1,1,381.880000000,383.800000000,10,10,1,1,TSLA
2025-01-03T10:32:26.241832975Z,2025-01-03T10:32:26.241666837Z,10,2,16244,A,A,0,383.090000000,30,130,166138,4921133,382.810000000,383.090000000,20,30,2,1,382.700000000,383.100000000,50,370,1,1,382.500000000,383.140000000,3,3,1,1,382.230000000,383.200000000,25,10,1,1,382.110000000,383.250000000,300,47,1,1,382.100000000,383.350000000,10,20,1,1,382.010000000,383.420000000,2,140,1,1,382.000000000,383.600000000,1239,1000,10,2,381.900000000,383.720000000,23,7085,1,8,381.880000000,383.740000000,10,37,1,1,TSLA
2025-01-03T10:32:26.391637713Z,2025-01-03T10:32:26.391471841Z,10,2,17709,C,A,2,107.910000000,17,130,165872,4921253,107.600000000,107.840000000,50,400,1,2,107.570000000,107.870000000,15,242,1,1,107.520000000,107.940000000,100,100,1,1,107.050000000,107.950000000,247,10,1,1,107.000000000,108.000000000,1,50,1,1,106.240000000,108.300000000,28,50,1,1,106.000000000,108.550000000,15,50,2,1,105.870000000,108.800000000,141,50,1,1,103.180000000,108.880000000,16,28,1,1,103.000000000,109.000000000,3,100,1,1,XOM
2025-01-03T10:32:26.391732333Z,2025-01-03T10:32:26.391566049Z,10,2,17709,A,A,2,107.890000000,15,130,166284,4921255,107.600000000,107.840000000,50,400,1,2,107.570000000,107.870000000,15,242,1,1,107.520000000,107.890000000,100,15,1,1,107.050000000,107.940000000,247,100,1,1,107.000000000,107.950000000,1,10,1,1,106.240000000,108.000000000,28,50,1,1,106.000000000,108.300000000,15,50,2,1,105.870000000,108.550000000,141,50,1,1,103.180000000,108.800000000,16,50,1,1,103.000000000,108.880000000,3,28,1,1,XOM
2025-01-03T10:32:26.397468230Z,2025-01-03T10:32:26.397302238Z,10,2,17709,C,B,1,107.570000000,15,130,165992,4921266,107.600000000,107.840000000,50,400,1,2,107.520000000,107.870000000,100,242,1,1,107.050000000,107.890000000,247,15,1,1,107.000000000,107.940000000,1,100,1,1,106.240000000,107.950000000,28,10,1,1,106.000000000,108.000000000,15,50,2,1,105.870000000,108.300000000,141,50,1,1,103.180000000,108.550000000,16,50,1,1,103.000000000,108.800000000,3,50,1,1,102.000000000,108.880000000,2,28,1,1,XOM
2025-01-03T10:32:26.397527229Z,2025-01-03T10:32:26.397360691Z,10,2,17709,A,B,1,107.540000000,15,130,166538,4921267,107.600000000,107.840000000,50,400,1,2,107.540000000,107.870000000,15,242,1,1,107.520000000,107.890000000,100,15,1,1,107.050000000,107.940000000,247,100,1,1,107.000000000,107.950000000,1,10,1,1,106.240000000,108.000000000,28,50,1,1,106.000000000,108.300000000,15,50,2,1,105.870000000,108.550000000,141,50,1,1,103.180000000,108.800000000,16,50,1,1,103.000000000,108.880000000,3,28,1,1,XOM
2025-01-03T10:32:26.398197726Z,2025-01-03T10:32:26.398031820Z,10,2,17709,C,B,1,107.540000000,15,130,165906,4921274,107.600000000,107.840000000,50,400,1,2,107.520000000,107.870000000,100,242,1,1,107.050000000,107.890000000,247,15,1,1,107.000000000,107.940000000,1,100,1,1,106.240000000,107.950000000,28,10,1,1,106.000000000,108.000000000,15,50,2,1,105.870000000,108.300000000,141,50,1,1,103.180000000,108.550000000,16,50,1,1,103.000000000,108.800000000,3,50,1,1,102.000000000,108.880000000,2,28,1,1,XOM
2025-01-03T10:32:26.455471001Z,2025-01-03T10:32:26.455304144Z,10,2,17709,A,A,2,107.880000000,100,130,166857,4921296,107.600000000,107.840000000,50,400,1,2,107.520000000,107.870000000,100,242,1,1,107.050000000,107.880000000,247,100,1,1,107.000000000,107.890000000,1,15,1,1,106.240000000,107.950000000,28,10,1,1,106.000000000,108.000000000,15,50,2,1,105.870000000,108.300000000,141,50,1,1,103.180000000,108.550000000,16,50,1,1,103.000000000,108.800000000,3,50,1,1,102.000000000,108.880000000,2,28,1,1,XOM
2025-01-03T10:32:27.391647540Z,2025-01-03T10:32:27.391481365Z,10,2,17709,C,A,2,107.880000000,100,130,166175,4921854,107.600000000,107.840000000,50,400,1,2,107.520000000,107.870000000,100,242,1,1,107.050000000,107.890000000,247,15,1,1,107.000000000,107.950000000,1,10,1,1,106.240000000,108.000000000,28,50,1,1,106.000000000,108.300000000,15,50,2,1,105.870000000,108.550000000,141,50,1,1,103.180000000,108.800000000,16,50,1,1,103.000000000,108.880000000,3,28,1,1,102.000000000,109.000000000,2,100,1,1,XOM
2025-01-03T10:32:27.391660706Z,2025-01-03T10:32:27.391494443Z,10,2,17709,A,A,3,107.940000000,100,130,166263,4921855,107.600000000,107.840000000,50,400,1,2,107.520000000,107.870000000,100,242,1,1,107.050000000,107.890000000,247,15,1,1,107.000000000,107.940000000,1,100,1,1,106.240000000,107.950000000,28,10,1,1,106.000000000,108.000000000,15,50,2,1,105.870000000,108.300000000,141,50,1,1,103.180000000,108.550000000,16,50,1,1,103.000000000,108.800000000,3,50,1,1,102.000000000,108.880000000,2,28,1,1,XOM
2025-01-03T10:32:27.392208872Z,2025-01-03T10:32:27.392042049Z,10,2,17709,A,B,1,107.540000000,15,130,166823,4921856,107.600000000,107.840000000,50,400,1,2,107.540000000,107.870000000,15,242,1,1,107.520000000,107.890000000,100,15,1,1,107.050000000,107.940000000,247,100,1,1,107.000000000,107.950000000,1,10,1,1,106.240000000,108.000000000,28,50,1,1,106.000000000,108.300000000,15,50,2,1,105.870000000,108.550000000,141,50,1,1,103.180000000,108.800000000,16,50,1,1,103.000000000,108.880000000,3,28,1,1,XOM
2025-01-03T10:32:27.392234918Z,2025-01-03T10:32:27.392068992Z,10,2,17709,C,A,2,107.890000000,15,130,165926,4921857,107.600000000,107.840000000,50,400,1,2,107.540000000,107.870000000,15,242,1,1,107.520000000,107.940000000,100,100,1,1,107.050000000,107.950000000,247,10,1,1,107.000000000,108.000000000,1,50,1,1,106.240000000,108.300000000,28,50,1,1,106.000000000,108.550000000,15,50,2,1,105.870000000,108.800000000,141,50,1,1,103.180000000,108.880000000,16,28,1,1,103.000000000,109.000000000,3,100,1,1,XOM
2025-01-03T10:32:27.408413532Z,2025-01-03T10:32:27.408247177Z,10,2,9155,A,B,1,241.500000000,8,130,166355,4921860,241.670000000,242.070000000,2,62,1,1,241.500000000,242.410000000,8,8,1,1,241.120000000,242.850000000,81,300,1,2,241.000000000,242.900000000,100,100,1,1,240.000000000,243.000000000,10,92,1,2,238.000000000,243.310000000,30,10,1,1,236.000000000,243.700000000,6,100,1,1,235.500000000,246.810000000,5,100,1,1,235.000000000,262.740000000,5,100,1,1,232.880000000,263.830000000,1,100,1,1,JPM
2025-01-03T10:32:27.455286377Z,2025-01-03T10:32:27.455120104Z,10,2,17709,A,A,2,107.910000000,16,130,166273,4921870,107.600000000,107.840000000,50,400,1,2,107.540000000,107.870000000,15,242,1,1,107.520000000,107.910000000,100,16,1,1,107.050000000,107.940000000,247,100,1,1,107.000000000,107.950000000,1,10,1,1,106.240000000,108.000000000,28,50,1,1,106.000000000,108.300000000,15,50,2,1,105.870000000,108.550000000,141,50,1,1,103.180000000,108.800000000,16,50,1,1,103.000000000,108.880000000,3,28,1,1,XOM
2025-01-03T10:32:27.477001092Z,2025-01-03T10:32:27.476835173Z,10,2,17709,C,B,1,107.540000000,15,130,165919,4921875,107.600000000,107.840000000,50,400,1,2,107.520000000,107.870000000,100,242,1,1,107.050000000,107.910000000,247,16,1,1,107.000000000,107.940000000,1,100,1,1,106.240000000,107.950000000,28,10,1,1,106.000000000,108.000000000,15,50,2,1,105.870000000,108.300000000,141,50,1,1,103.180000000,108.550000000,16,50,1,1,103.000000000,108.800000000,3,50,1,1,102.000000000,108.880000000,2,28,1,1,XOM
2025-01-03T10:32:28.830311007Z,2025-01-03T10:32:28.830144677Z,10,2,38,A,B,1,243.460000000,200,130,166330,4922357,243.500000000,243.710000000,6,200,1,1,243.460000000,243.750000000,400,27,2,1,243.400000000,244.000000000,30,1,1,1,243.190000000,244.140000000,2,79,1,1,243.020000000,244.200000000,79,1000,1,1,243.000000000,244.400000000,1243,50,9,1,242.990000000,244.420000000,1,10,1,1,242.800000000,244.580000000,30,100,1,1,242.750000000,245.000000000,30,79,1,2,242.590000000,245.190000000,5,83,1,1,AAPL
2025-01-03T10:32:28.884706071Z,2025-01-03T10:32:28.884539967Z,10,2,38,C,B,1,243.460000000,200,130,166104,4922390,243.500000000,243.710000000,6,200,1,1,243.460000000,243.750000000,200,27,1,1,243.400000000,244.000000000,30,1,1,1,243.190000000,244.140000000,2,79,1,1,243.020000000,244.200000000,79,1000,1,1,243.000000000,244.400000000,1243,50,9,1,242.990000000,244.420000000,1,10,1,1,242.800000000,244.580000000,30,100,1,1,242.750000000,245.000000000,30,79,1,2,242.590000000,245.190000000,5,83,1,1,AAPL
2025-01-03T10:32:28.884720376Z,2025-01-03T10:32:28.884553838Z,10,2,38,A,B,1,243.470000000,400,130,166538,4922391,243.500000000,243.710000000,6,200,1,1,243.470000000,243.750000000,400,27,1,1,243.400000000,244.000000000,30,1,1,1,243.190000000,244.140000000,2,79,1,1,243.020000000,244.200000000,79,1000,1,1,243.000000000,244.400000000,1243,50,9,1,242.990000000,244.420000000,1,10,1,1,242.800000000,244.580000000,30,100,1,1,242.750000000,245.000000000,30,79,1,2,242.590000000,245.190000000,5,83,1,1,AAPL
2025-01-03T10:32:29.322492059Z,2025-01-03T10:32:29.322325810Z,10,2,11667,C,B,6,139.080000000,57,130,166249,4922546,139.160000000,139.200000000,100,130,1,2,139.150000000,139.220000000,9860,410,2,2,139.130000000,139.230000000,2200,1977,2,2,139.120000000,139.240000000,30,300,1,2,139.110000000,139.250000000,1,1,1,1,139.100000000,139.270000000,410,37,2,2,139.070000000,139.300000000,100,507,1,4,139.030000000,139.320000000,126,39,2,1,139.010000000,139.330000000,100,503,1,2,139.000000000,139.360000000,410,4,4,2,NVDA
2025-01-03T10:32:29.323498984Z,2025-01-03T10:32:29.323332913Z,10,2,11667,A,B,6,139.090000000,57,130,166071,4922547,139.160000000,139.200000000,100,130,1,2,139.150000000,139.220000000,9860,410,2,2,139.130000000,139.230000000,2200,1977,2,2,139.120000000,139.240000000,30,300,1,2,139.110000000,139.250000000,1,1,1,1,139.100000000,139.270000000,410,37,2,2,139.090000000,139.300000000,57,507,1,4,139.070000000,139.320000000,100,39,1,1,139.030000000,139.330000000,126,503,2,2,139.010000000,139.360000000,100,4,1,2,NVDA
2025-01-03T10:32:29.817995052Z,2025-01-03T10:32:29.817828704Z,10,2,17709,A,B,1,107.520000000,15,130,166348,4922680,107.600000000,107.840000000,50,400,1,2,107.520000000,107.870000000,115,242,2,1,107.050000000,107.910000000,247,16,1,1,107.000000000,107.940000000,1,100,1,1,106.240000000,107.950000000,28,10,1,1,106.000000000,108.000000000,15,50,2,1,105.870000000,108.300000000,141,50,1,1,103.180000000,108.550000000,16,50,1,1,103.000000000,108.800000000,3,50,1,1,102.000000000,108.880000000,2,28,1,1,XOM
2025-01-03T10:32:29.891682152Z,2025-01-03T10:32:29.891516265Z,10,2,10888,C,B,2,420.530000000,14,130,165887,4922692,420.670000000,421.200000000,200,200,1,1,420.580000000,421.220000000,10,13,1,1,420.520000000,421.460000000,1,39,1,1,420.400000000,421.490000000,858,6,1,1,420.380000000,421.570000000,100,40,1,1,420.100000000,421.600000000,100,510,1,2,420.000000000,421.700000000,834,359,8,1,419.730000000,421.800000000,3,7,1,1,419.650000000,422.100000000,39,7,1,1,418.650000000,422.500000000,1,200,1,1,MSFT
2025-01-03T10:32:29.891760193Z,2025-01-03T10:32:29.891593929Z,10,2,10888,A,B,1,420.590000000,14,130,166264,4922693,420.670000000,421.200000000,200,200,1,1,420.590000000,421.220000000,14,13,1,1,420.580000000,421.460000000,10,39,1,1,420.520000000,421.490000000,1,6,1,1,420.400000000,421.570000000,858,40,1,1,420.380000000,421.600000000,100,510,1,2,420.100000000,421.700000000,100,359,1,1,420.000000000,421.800000000,834,7,8,1,419.730000000,422.100000000,3,7,1,1,419.650000000,422.500000000,39,200,1,1,MSFT
2025-01-03T10:32:29.952517045Z,2025-01-03T10:32:29.952350808Z,10,2,16244,A,B,1,382.750000000,21,130,166237,4922717,382.810000000,383.090000000,20,30,2,1,382.750000000,383.100000000,21,370,1,1,382.700000000,383.140000000,50,3,1,1,382.500000000,383.200000000,3,10,1,1,382.230000000,383.250000000,25,47,1,1,382.110000000,383.350000000,300,20,1,1,382.100000000,383.420000000,10,140,1,1,382.010000000,383.600000000,2,1000,1,2,382.000000000,383.720000000,1239,7085,10,8,381.900000000,383.740000000,23,37,1,1,TSLA
2025-01-03T10:32:30.282737349Z,2025-01-03T10:32:30.282569610Z,10,2,16244,T,N,0,382.900000000,38,130,167739,4922883,382.810000000,383.090000000,20,30,2,1,382.750000000,383.100000000,21,370,1,1,382.700000000,383.140000000,50,3,1,1,382.500000000,383.200000000,3,10,1,1,382.230000000,383.250000000,25,47,1,1,382.110000000,383.350000000,300,20,1,1,382.100000000,383.420000000,10,140,1,1,382.010000000,383.600000000,2,1000,1,2,382.000000000,383.720000000,1239,7085,10,8,381.900000000,383.740000000,23,37,1,1,TSLA
2025-01-03T10:32:31.425177884Z,2025-01-03T10:32:31.425012131Z,10,2,16244,C,A,5,383.350000000,20,130,165753,4923376,382.810000000,383.090000000,20,30,2,1,382.750000000,383.100000000,21,370,1,1,382.700000000,383.140000000,50,3,1,1,382.500000000,383.200000000,3,10,1,1,382.230000000,383.250000000,25,47,1,1,382.110000000,383.420000000,300,140,1,1,382.100000000,383.600000000,10,1000,1,2,382.010000000,383.720000000,2,7085,1,8,382.000000000,383.740000000,1239,37,10,1,381.900000000,383.800000000,23,10,1,1,TSLA
2025-01-03T10:32:31.425331289Z,2025-01-03T10:32:31.425165057Z,10,2,16244,A,A,5,383.290000000,20,130,166232,4923377,382.810000000,383.090000000,20,30,2,1,382.750000000,383.100000000,21,370,1,1,382.700000000,383.140000000,50,3,1,1,382.500000000,383.200000000,3,10,1,1,382.230000000,383.250000000,25,47,1,1,382.110000000,383.290000000,300,20,1,1,382.100000000,383.420000000,10,140,1,1,382.010000000,383.600000000,2,1000,1,2,382.000000000,383.720000000,1239,7085,10,8,381.900000000,383.740000000,23,37,1,1,TSLA
2025-01-03T10:32:32.412720152Z,2025-01-03T10:32:32.412554286Z,10,2,9155,C,B,1,241.500000000,8,130,165866,4923969,241.670000000,242.070000000,2,62,1,1,241.120000000,242.410000000,81,8,1,1,241.000000000,242.850000000,100,300,1,2,240.000000000,242.900000000,10,100,1,1,238.000000000,243.000000000,30,92,1,2,236.000000000,243.310000000,6,10,1,1,235.500000000,243.700000000,5,100,1,1,235.000000000,246.810000000,5,100,1,1,232.880000000,262.740000000,1,100,1,1,231.110000000,263.830000000,3,100,1,1,JPM
2025-01-03T10:32:32.412786396Z,2025-01-03T10:32:32.412619816Z,10,2,9155,A,B,1,241.550000000,8,130,166580,4923970,241.670000000,242.070000000,2,62,1,1,241.550000000,242.410000000,8,8,1,1,241.120000000,242.850000000,81,300,1,2,241.000000000,242.900000000,100,100,1,1,240.000000000,243.000000000,10,92,1,2,238.000000000,243.310000000,30,10,1,1,236.000000000,243.700000000,6,100,1,1,235.500000000,246.810000000,5,100,1,1,235.000000000,262.740000000,5,100,1,1,232.880000000,263.830000000,1,100,1,1,JPM
2025-01-03T10:32:32.736127458Z,2025-01-03T10:32:32.735961233Z,10,2,11667,A,A,0,139.200000000,400,130,166225,4924089,139.160000000,139.200000000,100,530,1,3,139.150000000,139.220000000,9860,10,2,1,139.130000000,139.230000000,2200,1977,2,2,139.120000000,139.240000000,30,300,1,2,139.110000000,139.250000000,1,1,1,1,139.100000000,139.270000000,410,37,2,2,139.090000000,139.300000000,57,507,1,4,139.070000000,139.320000000,100,39,1,1,139.030000000,139.330000000,126,503,2,2,139.010000000,139.360000000,100,4,1,2,NVDA
2025-01-03T10:32:33.413342165Z,2025-01-03T10:32:33.413175880Z,10,2,9155,C,B,1,241.550000000,8,130,166285,4924413,241.670000000,242.070000000,2,62,1,1,241.120000000,242.410000000,81,8,1,1,241.000000000,242.850000000,100,300,1,2,240.000000000,242.900000000,10,100,1,1,238.000000000,243.000000000,30,92,1,2,236.000000000,243.310000000,6,10,1,1,235.500000000,243.700000000,5,100,1,1,235.000000000,246.810000000,5,100,1,1,232.880000000,262.740000000,1,100,1,1,231.110000000,263.830000000,3,100,1,1,JPM
2025-01-03T10:32:33.776779934Z,2025-01-03T10:32:33.776613674Z,10,2,16244,C,B,5,382.110000000,300,130,166260,4924526,382.810000000,383.090000000,20,30,2,1,382.750000000,383.100000000,21,370,1,1,382.700000000,383.140000000,50,3,1,1,382.500000000,383.200000000,3,10,1,1,382.230000000,383.250000000,25,47,1,1,382.100000000,383.290000000,10,20,1,1,382.010000000,383.420000000,2,140,1,1,382.000000000,383.600000000,1239,1000,10,2,381.900000000,383.720000000,23,7085,1,8,381.880000000,383.740000000,10,37,1,1,TSLA
2025-01-03T10:32:33.778351324Z,2025-01-03T10:32:33.778184865Z,10,2,16244,A,B,0,382.840000000,300,130,166459,4924527,382.840000000,383.090000000,300,30,1,1,382.810000000,383.100000000,20,370,2,1,382.750000000,383.140000000,21,3,1,1,382.700000000,383.200000000,50,10,1,1,382.500000000,383.250000000,3,47,1,1,382.230000000,383.290000000,25,20,1,1,382.100000000,383.420000000,10,140,1,1,382.010000000,383.600000000,2,1000,1,2,382.000000000,383.720000000,1239,7085,10,8,381.900000000,383.740000000,23,37,1,1,TSLA
2025-01-03T10:32:33.918417679Z,2025-01-03T10:32:33.918251421Z,10,2,17709,A,A,2,107.890000000,16,130,166258,4924571,107.600000000,107.840000000,50,400,1,2,107.520000000,107.870000000,115,242,2,1,107.050000000,107.890000000,247,16,1,1,107.000000000,107.910000000,1,16,1,1,106.240000000,107.940000000,28,100,1,1,106.000000000,107.950000000,15,10,2,1,105.870000000,108.000000000,141,50,1,1,103.180000000,108.300000000,16,50,1,1,103.000000000,108.550000000,3,50,1,1,102.000000000,108.800000000,2,50,1,1,XOM
2025-01-03T10:32:33.918447640Z,2025-01-03T10:32:33.918281791Z,10,2,17709,C,A,3,107.910000000,16,130,165849,4924572,107.600000000,107.840000000,50,400,1,2,107.520000000,107.870000000,115,242,2,1,107.050000000,107.890000000,247,16,1,1,107.000000000,107.940000000,1,100,1,1,106.240000000,107.950000000,28,10,1,1,106.000000000,108.000000000,15,50,2,1,105.870000000,108.300000000,141,50,1,1,103.180000000,108.550000000,16,50,1,1,103.000000000,108.800000000,3,50,1,1,102.000000000,108.880000000,2,28,1,1,XOM
2025-01-03T10:32:33.922264479Z,2025-01-03T10:32:33.922098185Z,10,2,17709,C,B,1,107.520000000,15,130,166294,4924573,107.600000000,107.840000000,50,400,1,2,107.520000000,107.870000000,100,242,1,1,107.050000000,107.890000000,247,16,1,1,107.000000000,107.940000000,1,100,1,1,106.240000000,107.950000000,28,10,1,1,106.000000000,108.000000000,15,50,2,1,105.870000000,108.300000000,141,50,1,1,103.180000000,108.550000000,16,50,1,1,103.000000000,108.800000000,3,50,1,1,102.000000000,108.880000000,2,28,1,1,XOM
2025-01-03T10:32:33.922320968Z,2025-01-03T10:32:33.922154768Z,10,2,17709,A,B,1,107.540000000,15,130,166200,4924574,107.600000000,107.840000000,50,400,1,2,107.540000000,107.870000000,15,242,1,1,107.520000000,107.890000000,100,16,1,1,107.050000000,107.940000000,247,100,1,1,107.000000000,107.950000000,1,10,1,1,106.240000000,108.000000000,28,50,1,1,106.000000000,108.300000000,15,50,2,1,105.870000000,108.550000000,141,50,1,1,103.180000000,108.800000000,16,50,1,1,103.000000000,108.880000000,3,28,1,1,XOM
2025-01-03T10:32:33.976596482Z,2025-01-03T10:32:33.976429935Z,10,2,17709,A,A,2,107.880000000,100,130,166547,4924595,107.600000000,107.840000000,50,400,1,2,107.540000000,107.870000000,15,242,1,1,107.520000000,107.880000000,100,100,1,1,107.050000000,107.890000000,247,16,1,1,107.000000000,107.950000000,1,10,1,1,106.240000000,108.000000000,28,50,1,1,106.000000000,108.300000000,15,50,2,1,105.870000000,108.550000000,141,50,1,1,103.180000000,108.800000000,16,50,1,1,103.000000000,108.880000000,3,28,1,1,XOM
2025-01-03T10:32:34.421394075Z,2025-01-03T10:32:34.421227934Z,10,2,16244,A,B,1,382.820000000,1,130,166141,4924716,382.840000000,383.090000000,300,30,1,1,382.820000000,383.100000000,1,370,1,1,382.810000000,383.140000000,20,3,2,1,382.750000000,383.200000000,21,10,1,1,382.700000000,383.250000000,50,47,1,1,382.500000000,383.290000000,3,20,1,1,382.230000000,383.420000000,25,140,1,1,382.100000000,383.600000000,10,1000,1,2,382.010000000,383.720000000,2,7085,1,8,382.000000000,383.740000000,1239,37,10,1,TSLA
2025-01-03T10:32:34.535524631Z,2025-01-03T10:32:34.535358766Z,10,2,10888,C,B,0,420.670000000,200,130,165865,4924745,420.590000000,421.200000000,14,200,1,1,420.580000000,421.220000000,10,13,1,1,420.520000000,421.460000000,1,39,1,1,420.400000000,421.490000000,858,6,1,1,420.380000000,421.570000000,100,40,1,1,420.100000000,421.600000000,100,510,1,2,420.000000000,421.700000000,834,359,8,1,419.730000000,421.800000000,3,7,1,1,419.650000000,422.100000000,39,7,1,1,418.650000000,422.500000000,1,200,1,1,MSFT
2025-01-03T10:32:34.535535153Z,2025-01-03T10:32:34.535369289Z,10,2,10888,A,B,0,420.640000000,200,130,165864,4924747,420.640000000,421.200000000,200,200,1,1,420.590000000,421.220000000,14,13,1,1,420.580000000,421.460000000,10,39,1,1,420.520000000,421.490000000,1,6,1,1,420.400000000,421.570000000,858,40,1,1,420.380000000,421.600000000,100,510,1,2,420.100000000,421.700000000,100,359,1,1,420.000000000,421.800000000,834,7,8,1,419.730000000,422.100000000,3,7,1,1,419.650000000,422.500000000,39,200,1,1,MSFT
2025-01-03T10:32:34.535647031Z,2025-01-03T10:32:34.535481357Z,10,2,11667,C,B,5,139.100000000,400,130,165674,4924753,139.160000000,139.200000000,100,530,1,3,139.150000000,139.220000000,9860,10,2,1,139.130000000,139.230000000,2200,1977,2,2,139.120000000,139.240000000,30,300,1,2,139.110000000,139.250000000,1,1,1,1,139.100000000,139.270000000,10,37,1,2,139.090000000,139.300000000,57,507,1,4,139.070000000,139.320000000,100,39,1,1,139.030000000,139.330000000,126,503,2,2,139.010000000,139.360000000,100,4,1,2,NVDA
2025-01-03T10:32:34.535658084Z,2025-01-03T10:32:34.535492162Z,10,2,11667,A,B,6,139.090000000,400,130,165922,4924754,139.160000000,139.200000000,100,530,1,3,139.150000000,139.220000000,9860,10,2,1,139.130000000,139.230000000,2200,1977,2,2,139.120000000,139.240000000,30,300,1,2,139.110000000,139.250000000,1,1,1,1,139.100000000,139.270000000,10,37,1,2,139.090000000,139.300000000,457,507,2,4,139.070000000,139.320000000,100,39,1,1,139.030000000,139.330000000,126,503,2,2,139.010000000,139.360000000,100,4,1,2,NVDA
2025-01-03T10:32:34.590238277Z,2025-01-03T10:32:34.590071987Z,10,2,10888,A,A,0,421.170000000,200,130,166290,4924818,420.640000000,421.170000000,200,200,1,1,420.590000000,421.220000000,14,13,1,1,420.580000000,421.460000000,10,39,1,1,420.520000000,421.490000000,1,6,1,1,420.400000000,421.570000000,858,40,1,1,420.380000000,421.600000000,100,510,1,2,420.100000000,421.700000000,100,359,1,1,420.000000000,421.800000000,834,7,8,1,419.730000000,422.100000000,3,7,1,1,419.650000000,422.500000000,39,200,1,1,MSFT
2025-01-03T10:32:34.590507997Z,2025-01-03T10:32:34.590341761Z,10,2,38,A,A,0,243.700000000,200,130,166236,4924821,243.500000000,243.700000000,6,200,1,1,243.470000000,243.750000000,400,27,1,1,243.400000000,244.000000000,30,1,1,1,243.190000000,244.140000000,2,79,1,1,243.020000000,244.200000000,79,1000,1,1,243.000000000,244.400000000,1243,50,9,1,242.990000000,244.420000000,1,10,1,1,242.800000000,244.580000000,30,100,1,1,242.750000000,245.000000000,30,79,1,2,242.590000000,245.190000000,5,83,1,1,AAPL
2025-01-03T10:32:34.651246420Z,2025-01-03T10:32:34.651079976Z,10,2,10888,A,B,0,420.650000000,200,130,166444,4924895,420.650000000,421.170000000,200,200,1,1,420.590000000,421.220000000,14,13,1,1,420.580000000,421.460000000,10,39,1,1,420.520000000,421.490000000,1,6,1,1,420.400000000,421.570000000,858,40,1,1,420.380000000,421.600000000,100,510,1,2,420.100000000,421.700000000,100,359,1,1,420.000000000,421.800000000,834,7,8,1,419.730000000,422.100000000,3,7,1,1,419.650000000,422.500000000,39,200,1,1,MSFT
2025-01-03T10:32:34.660932072Z,2025-01-03T10:32:34.660765535Z,10,2,11667,C,A,0,139.200000000,400,130,166537,4924906,139.160000000,139.200000000,100,130,1,2,139.150000000,139.220000000,9860,10,2,1,139.130000000,139.230000000,2200,1977,2,2,139.120000000,139.240000000,30,300,1,2,139.110000000,139.250000000,1,1,1,1,139.100000000,139.270000000,10,37,1,2,139.090000000,139.300000000,457,507,2,4,139.070000000,139.320000000,100,39,1,1,139.030000000,139.330000000,126,503,2,2,139.010000000,139.360000000,100,4,1,2,NVDA
2025-01-03T10:32:34.660943364Z,2025-01-03T10:32:34.660777195Z,10,2,11667,A,A,1,139.220000000,400,130,166169,4924907,139.160000000,139.200000000,100,130,1,2,139.150000000,139.220000000,9860,410,2,2,139.130000000,139.230000000,2200,1977,2,2,139.120000000,139.240000000,30,300,1,2,139.110000000,139.250000000,1,1,1,1,139.100000000,139.270000000,10,37,1,2,139.090000000,139.300000000,457,507,2,4,139.070000000,139.320000000,100,39,1,1,139.030000000,139.330000000,126,503,2,2,139.010000000,139.360000000,100,4,1,2,NVDA
2025-01-03T10:32:35.126246982Z,2025-01-03T10:32:35.126081028Z,10,2,17709,C,A,2,107.880000000,100,130,165954,4925076,107.600000000,107.840000000,50,400,1,2,107.540000000,107.870000000,15,242,1,1,107.520000000,107.890000000,100,16,1,1,107.050000000,107.950000000,247,10,1,1,107.000000000,108.000000000,1,50,1,1,106.240000000,108.300000000,28,50,1,1,106.000000000,108.550000000,15,50,2,1,105.870000000,108.800000000,141,50,1,1,103.180000000,108.880000000,16,28,1,1,103.000000000,109.000000000,3,100,1,1,XOM
2025-01-03T10:32:35.126260492Z,2025-01-03T10:32:35.126094300Z,10,2,17709,A,A,3,107.940000000,100,130,166192,4925077,107.600000000,107.840000000,50,400,1,2,107.540000000,107.870000000,15,242,1,1,107.520000000,107.890000000,100,16,1,1,107.050000000,107.940000000,247,100,1,1,107.000000000,107.950000000,1,10,1,1,106.240000000,108.000000000,28,50,1,1,106.000000000,108.300000000,15,50,2,1,105.870000000,108.550000000,141,50,1,1,103.180000000,108.800000000,16,50,1,1,103.000000000,108.880000000,3,28,1,1,XOM
2025-01-03T10:32:35.126665253Z,2025-01-03T10:32:35.126499508Z,10,2,17709,C,A,2,107.890000000,16,130,165745,4925078,107.600000000,107.840000000,50,400,1,2,107.540000000,107.870000000,15,242,1,1,107.520000000,107.940000000,100,100,1,1,107.050000000,107.950000000,247,10,1,1,107.000000000,108.000000000,1,50,1,1,106.240000000,108.300000000,28,50,1,1,106.000000000,108.550000000,15,50,2,1,105.870000000,108.800000000,141,50,1,1,103.180000000,108.880000000,16,28,1,1,103.000000000,109.000000000,3,100,1,1,XOM
2025-01-03T10:32:35.428185895Z,2025-01-03T10:32:35.428020010Z,10,2,17709,C,B,1,107.540000000,15,130,165885,4925203,107.600000000,107.840000000,50,400,1,2,107.520000000,107.870000000,100,242,1,1,107.050000000,107.940000000,247,100,1,1,107.000000000,107.950000000,1,10,1,1,106.240000000,108.000000000,28,50,1,1,106.000000000,108.300000000,15,50,2,1,105.870000000,108.550000000,141,50,1,1,103.180000000,108.800000000,16,50,1,1,103.000000000,108.880000000,3,28,1,1,102.000000000,109.000000000,2,100,1,1,XOM
2025-01-03T10:32:35.558304241Z,2025-01-03T10:32:35.558138395Z,10,2,38,C,A,0,243.700000000,200,130,165846,4925214,243.500000000,243.750000000,6,27,1,1,243.470000000,244.000000000,400,1,1,1,243.400000000,244.140000000,30,79,1,1,243.190000000,244.200000000,2,1000,1,1,243.020000000,244.400000000,79,50,1,1,243.000000000,244.420000000,1243,10,9,1,242.990000000,244.580000000,1,100,1,1,242.800000000,245.000000000,30,79,1,2,242.750000000,245.190000000,30,83,1,1,242.590000000,245.540000000,5,10,1,1,AAPL
2025-01-03T10:32:35.558316321Z,2025-01-03T10:32:35.558150232Z,10,2,38,A,A,0,243.710000000,200,130,166089,4925215,243.500000000,243.710000000,6,200,1,1,243.470000000,243.750000000,400,27,1,1,243.400000000,244.000000000,30,1,1,1,243.190000000,244.140000000,2,79,1,1,243.020000000,244.200000000,79,1000,1,1,243.000000000,244.400000000,1243,50,9,1,242.990000000,244.420000000,1,10,1,1,242.800000000,244.580000000,30,100,1,1,242.750000000,245.000000000,30,79,1,2,242.590000000,245.190000000,5,83,1,1,AAPL
2025-01-03T10:32:35.612391367Z,2025-01-03T10:32:35.612225154Z,10,2,10888,A,B,0,420.660000000,200,130,166213,4925218,420.660000000,421.170000000,200,200,1,1,420.590000000,421.220000000,14,13,1,1,420.580000000,421.460000000,10,39,1,1,420.520000000,421.490000000,1,6,1,1,420.400000000,421.570000000,858,40,1,1,420.380000000,421.600000000,100,510,1,2,420.100000000,421.700000000,100,359,1,1,420.000000000,421.800000000,834,7,8,1,419.730000000,422.100000000,3,7,1,1,419.650000000,422.500000000,39,200,1,1,MSFT
2025-01-03T10:32:36.969985696Z,2025-01-03T10:32:36.969819892Z,10,2,16244,C,B,3,382.750000000,21,130,165804,4925932,382.840000000,383.090000000,300,30,1,1,382.820000000,383.100000000,1,370,1,1,382.810000000,383.140000000,20,3,2,1,382.700000000,383.200000000,50,10,1,1,382.500000000,383.250000000,3,47,1,1,382.230000000,383.290000000,25,20,1,1,382.100000000,383.420000000,10,140,1,1,382.010000000,383.600000000,2,1000,1,2,382.000000000,383.720000000,1239,7085,10,8,381.900000000,383.740000000,23,37,1,1,TSLA
2025-01-03T10:32:36.970051574Z,2025-01-03T10:32:36.969882935Z,10,2,16244,A,B,3,382.790000000,19,130,168639,4925933,382.840000000,383.090000000,300,30,1,1,382.820000000,383.100000000,1,370,1,1,382.810000000,383.140000000,20,3,2,1,382.790000000,383.200000000,19,10,1,1,382.700000000,383.250000000,50,47,1,1,382.500000000,383.290000000,3,20,1,1,382.230000000,383.420000000,25,140,1,1,382.100000000,383.600000000,10,1000,1,2,382.010000000,383.720000000,2,7085,1,8,382.000000000,383.740000000,1239,37,10,1,TSLA
2025-01-03T10:32:36.980410486Z,2025-01-03T10:32:36.980244625Z,10,2,16244,C,A,5,383.290000000,20,130,165861,4925941,382.840000000,383.090000000,300,30,1,1,382.820000000,383.100000000,1,370,1,1,382.810000000,383.140000000,20,3,2,1,382.790000000,383.200000000,19,10,1,1,382.700000000,383.250000000,50,47,1,1,382.500000000,383.420000000,3,140,1,1,382.230000000,383.600000000,25,1000,1,2,382.100000000,383.720000000,10,7085,1,8,382.010000000,383.740000000,2,37,1,1,382.000000000,383.800000000,1239,10,10,1,TSLA
2025-01-03T10:32:36.980472063Z,2025-01-03T10:32:36.980305306Z,10,2,16244,A,A,5,383.340000000,21,130,166757,4925942,382.840000000,383.090000000,300,30,1,1,382.820000000,383.100000000,1,370,1,1,382.810000000,383.140000000,20,3,2,1,382.790000000,383.200000000,19,10,1,1,382.700000000,383.250000000,50,47,1,1,382.500000000,383.340000000,3,21,1,1,382.230000000,383.420000000,25,140,1,1,382.100000000,383.600000000,10,1000,1,2,382.010000000,383.720000000,2,7085,1,8,382.000000000,383.740000000,1239,37,10,1,TSLA
2025-01-03T10:32:37.190183275Z,2025-01-03T10:32:37.190017464Z,10,2,11667,C,A,3,139.240000000,100,130,165811,4926094,139.160000000,139.200000000,100,130,1,2,139.150000000,139.220000000,9860,410,2,2,139.130000000,139.230000000,2200,1977,2,2,139.120000000,139.240000000,30,200,1,1,139.110000000,139.250000000,1,1,1,1,139.100000000,139.270000000,10,37,1,2,139.090000000,139.300000000,457,507,2,4,139.070000000,139.320000000,100,39,1,1,139.030000000,139.330000000,126,503,2,2,139.010000000,139.360000000,100,4,1,2,NVDA
2025-01-03T10:32:37.190196962Z,2025-01-03T10:32:37.190030363Z,10,2,11667,A,A,2,139.230000000,200,130,166599,4926095,139.160000000,139.200000000,100,130,1,2,139.150000000,139.220000000,9860,410,2,2,139.130000000,139.230000000,2200,2177,2,3,139.120000000,139.250000000,30,1,1,1,139.110000000,139.270000000,1,37,1,2,139.100000000,139.300000000,10,507,1,4,139.090000000,139.320000000,457,39,2,1,139.070000000,139.330000000,100,503,1,2,139.030000000,139.360000000,126,4,2,2,139.010000000,139.370000000,100,75,1,1,NVDA
2025-01-03T10:32:37.416272516Z,2025-01-03T10:32:37.416105510Z,10,2,9155,A,B,1,241.500000000,8,130,167006,4926249,241.670000000,242.070000000,2,62,1,1,241.500000000,242.410000000,8,8,1,1,241.120000000,242.850000000,81,300,1,2,241.000000000,242.900000000,100,100,1,1,240.000000000,243.000000000,10,92,1,2,238.000000000,243.310000000,30,10,1,1,236.000000000,243.700000000,6,100,1,1,235.500000000,246.810000000,5,100,1,1,235.000000000,262.740000000,5,100,1,1,232.880000000,263.830000000,1,100,1,1,JPM
2025-01-03T10:32:37.419016065Z,2025-01-03T10:32:37.418850158Z,10,2,38,C,A,0,243.710000000,200,130,165907,4926251,243.500000000,243.750000000,6,27,1,1,243.470000000,244.000000000,400,1,1,1,243.400000000,244.140000000,30,79,1,1,243.190000000,244.200000000,2,1000,1,1,243.020000000,244.400000000,79,50,1,1,243.000000000,244.420000000,1243,10,9,1,242.990000000,244.580000000,1,100,1,1,242.800000000,245.000000000,30,79,1,2,242.750000000,245.190000000,30,83,1,1,242.590000000,245.540000000,5,10,1,1,AAPL
2025-01-03T10:32:37.419215241Z,2025-01-03T10:32:37.419049133Z,10,2,38,C,A,3,244.200000000,1000,130,166108,4926255,243.500000000,243.750000000,6,27,1,1,243.470000000,244.000000000,400,1,1,1,243.400000000,244.140000000,30,79,1,1,243.190000000,244.400000000,2,50,1,1,243.020000000,244.420000000,79,10,1,1,243.000000000,244.580000000,1243,100,9,1,242.990000000,245.000000000,1,79,1,2,242.800000000,245.190000000,30,83,1,1,242.750000000,245.540000000,30,10,1,1,242.590000000,245.550000000,5,6,1,1,AAPL
2025-01-03T10:32:37.453018864Z,2025-01-03T10:32:37.452852510Z,10,2,10888,C,A,0,421.170000000,200,130,166354,4926558,420.660000000,421.220000000,200,13,1,1,420.590000000,421.460000000,14,39,1,1,420.580000000,421.490000000,10,6,1,1,420.520000000,421.570000000,1,40,1,1,420.400000000,421.600000000,858,510,1,2,420.380000000,421.700000000,100,359,1,1,420.100000000,421.800000000,100,7,1,1,420.000000000,422.100000000,834,7,8,1,419.730000000,422.500000000,3,200,1,1,419.650000000,423.500000000,39,600,1,2,MSFT
2025-01-03T10:32:37.453032473Z,2025-01-03T10:32:37.452864632Z,10,2,10888,A,A,0,421.190000000,200,130,167841,4926560,420.660000000,421.190000000,200,200,1,1,420.590000000,421.220000000,14,13,1,1,420.580000000,421.460000000,10,39,1,1,420.520000000,421.490000000,1,6,1,1,420.400000000,421.570000000,858,40,1,1,420.380000000,421.600000000,100,510,1,2,420.100000000,421.700000000,100,359,1,1,420.000000000,421.800000000,834,7,8,1,419.730000000,422.100000000,3,7,1,1,419.650000000,422.500000000,39,200,1,1,MSFT
2025-01-03T10:32:37.456793196Z,2025-01-03T10:32:37.456626869Z,10,2,38,A,A,3,244.400000000,1000,130,166327,4926570,243.500000000,243.750000000,6,27,1,1,243.470000000,244.000000000,400,1,1,1,243.400000000,244.140000000,30,79,1,1,243.190000000,244.400000000,2,1050,1,2,243.020000000,244.420000000,79,10,1,1,243.000000000,244.580000000,1243,100,9,1,242.990000000,245.000000000,1,79,1,2,242.800000000,245.190000000,30,83,1,1,242.750000000,245.540000000,30,10,1,1,242.590000000,245.550000000,5,6,1,1,AAPL
2025-01-03T10:32:37.495403776Z,2025-01-03T10:32:37.495237636Z,10,2,38,A,A,0,243.750000000,200,130,166140,4926625,243.500000000,243.750000000,6,227,1,2,243.470000000,244.000000000,400,1,1,1,243.400000000,244.140000000,30,79,1,1,243.190000000,244.400000000,2,1050,1,2,243.020000000,244.420000000,79,10,1,1,243.000000000,244.580000000,1243,100,9,1,242.990000000,245.000000000,1,79,1,2,242.800000000,245.190000000,30,83,1,1,242.750000000,245.540000000,30,10,1,1,242.590000000,245.550000000,5,6,1,1,AAPL
2025-01-03T10:32:37.500294283Z,2025-01-03T10:32:37.500128440Z,10,2,11667,C,A,1,139.220000000,400,130,165843,4926636,139.160000000,139.200000000,100,130,1,2,139.150000000,139.220000000,9860,10,2,1,139.130000000,139.230000000,2200,2177,2,3,139.120000000,139.250000000,30,1,1,1,139.110000000,139.270000000,1,37,1,2,139.100000000,139.300000000,10,507,1,4,139.090000000,139.320000000,457,39,2,1,139.070000000,139.330000000,100,503,1,2,139.030000000,139.360000000,126,4,2,2,139.010000000,139.370000000,100,75,1,1,NVDA
2025-01-03T10:32:37.500305856Z,2025-01-03T10:32:37.500139588Z,10,2,11667,A,A,2,139.230000000,400,130,166268,4926637,139.160000000,139.200000000,100,130,1,2,139.150000000,139.220000000,9860,10,2,1,139.130000000,139.230000000,2200,2577,2,4,139.120000000,139.250000000,30,1,1,1,139.110000000,139.270000000,1,37,1,2,139.100000000,139.300000000,10,507,1,4,139.090000000,139.320000000,457,39,2,1,139.070000000,139.330000000,100,503,1,2,139.030000000,139.360000000,126,4,2,2,139.010000000,139.370000000,100,75,1,1,NVDA
2025-01-03T10:32:37.505575088Z,2025-01-03T10:32:37.505408717Z,10,2,10888,A,B,0,420.670000000,200,130,166371,4926642,420.670000000,421.190000000,200,200,1,1,420.590000000,421.220000000,14,13,1,1,420.580000000,421.460000000,10,39,1,1,420.520000000,421.490000000,1,6,1,1,420.400000000,421.570000000,858,40,1,1,420.380000000,421.600000000,100,510,1,2,420.100000000,421.700000000,100,359,1,1,420.000000000,421.800000000,834,7,8,1,419.730000000,422.100000000,3,7,1,1,419.650000000,422.500000000,39,200,1,1,MSFT
2025-01-03T10:32:37.506443856Z,2025-01-03T10:32:37.506277447Z,10,2,11667,A,B,5,139.100000000,400,130,166409,4926646,139.160000000,139.200000000,100,130,1,2,139.150000000,139.220000000,9860,10,2,1,139.130000000,139.230000000,2200,2577,2,4,139.120000000,139.250000000,30,1,1,1,139.110000000,139.270000000,1,37,1,2,139.100000000,139.300000000,410,507,2,4,139.090000000,139.320000000,57,39,1,1,139.070000000,139.330000000,100,503,1,2,139.030000000,139.360000000,126,4,2,2,139.010000000,139.370000000,100,75,1,1,NVDA
2025-01-03T10:32:37.510765258Z,2025-01-03T10:32:37.510599549Z,10,2,38,C,B,2,243.400000000,30,130,165709,4926697,243.500000000,243.750000000,6,227,1,2,243.470000000,244.000000000,400,1,1,1,243.190000000,244.140000000,2,79,1,1,243.020000000,244.400000000,79,1050,1,2,243.000000000,244.420000000,1243,10,9,1,242.990000000,244.580000000,1,100,1,1,242.800000000,245.000000000,30,79,1,2,242.750000000,245.190000000,30,83,1,1,242.590000000,245.540000000,5,10,1,1,242.280000000,245.550000000,100,6,1,1,AAPL
2025-01-03T10:32:37.510852909Z,2025-01-03T10:32:37.510686534Z,10,2,38,A,B,2,243.450000000,26,130,166375,4926698,243.500000000,243.750000000,6,227,1,2,243.470000000,244.000000000,400,1,1,1,243.450000000,244.140000000,26,79,1,1,243.190000000,244.400000000,2,1050,1,2,243.020000000,244.420000000,79,10,1,1,243.000000000,244.580000000,1243,100,9,1,242.990000000,245.000000000,1,79,1,2,242.800000000,245.190000000,30,83,1,1,242.750000000,245.540000000,30,10,1,1,242.590000000,245.550000000,5,6,1,1,AAPL
2025-01-03T10:32:37.519957309Z,2025-01-03T10:32:37.519790860Z,10,2,38,A,A,0,243.750000000,200,130,166449,4926704,243.500000000,243.750000000,6,427,1,3,243.470000000,244.000000000,400,1,1,1,243.450000000,244.140000000,26,79,1,1,243.190000000,244.400000000,2,1050,1,2,243.020000000,244.420000000,79,10,1,1,243.000000000,244.580000000,1243,100,9,1,242.990000000,245.000000000,1,79,1,2,242.800000000,245.190000000,30,83,1,1,242.750000000,245.540000000,30,10,1,1,242.590000000,245.550000000,5,6,1,1,AAPL
2025-01-03T10:32:37.522878862Z,2025-01-03T10:32:37.522712317Z,10,2,17709,A,A,2,107.910000000,16,130,166545,4926711,107.600000000,107.840000000,50,400,1,2,107.520000000,107.870000000,100,242,1,1,107.050000000,107.910000000,247,16,1,1,107.000000000,107.940000000,1,100,1,1,106.240000000,107.950000000,28,10,1,1,106.000000000,108.000000000,15,50,2,1,105.870000000,108.300000000,141,50,1,1,103.180000000,108.550000000,16,50,1,1,103.000000000,108.800000000,3,50,1,1,102.000000000,108.880000000,2,28,1,1,XOM
2025-01-03T10:32:37.562001266Z,2025-01-03T10:32:37.561834886Z,10,2,38,A,B,0,243.500000000,200,130,166380,4926804,243.500000000,243.750000000,206,427,2,3,243.450000000,244.000000000,26,1,1,1,243.190000000,244.140000000,2,79,1,1,243.020000000,244.400000000,79,1050,1,2,243.000000000,244.420000000,1243,10,9,1,242.990000000,244.580000000,1,100,1,1,242.800000000,245.000000000,30,79,1,2,242.750000000,245.190000000,30,83,1,1,242.590000000,245.540000000,5,10,1,1,242.280000000,245.550000000,100,6,1,1,AAPL
2025-01-03T10:32:37.591429570Z,2025-01-03T10:32:37.591263542Z,10,2,38,C,B,0,243.500000000,200,130,166028,4926828,243.500000000,243.750000000,6,427,1,3,243.450000000,244.000000000,26,1,1,1,243.190000000,244.140000000,2,79,1,1,243.020000000,244.400000000,79,1050,1,2,243.000000000,244.420000000,1243,10,9,1,242.990000000,244.580000000,1,100,1,1,242.800000000,245.000000000,30,79,1,2,242.750000000,245.190000000,30,83,1,1,242.590000000,245.540000000,5,10,1,1,242.280000000,245.550000000,100,6,1,1,AAPL
2025-01-03T10:32:37.591443695Z,2025-01-03T10:32:37.591276913Z,10,2,38,A,B,1,243.480000000,200,130,166782,4926829,243.500000000,243.750000000,6,427,1,3,243.480000000,244.000000000,200,1,1,1,243.450000000,244.140000000,26,79,1,1,243.190000000,244.400000000,2,1050,1,2,243.020000000,244.420000000,79,10,1,1,243.000000000,244.580000000,1243,100,9,1,242.990000000,245.000000000,1,79,1,2,242.800000000,245.190000000,30,83,1,1,242.750000000,245.540000000,30,10,1,1,242.590000000,245.550000000,5,6,1,1,AAPL
2025-01-03T10:32:37.591901131Z,2025-01-03T10:32:37.591735222Z,10,2,38,C,B,2,243.450000000,26,130,165909,4926832,243.500000000,243.750000000,6,427,1,3,243.480000000,244.000000000,200,1,1,1,243.190000000,244.140000000,2,79,1,1,243.020000000,244.400000000,79,1050,1,2,243.000000000,244.420000000,1243,10,9,1,242.990000000,244.580000000,1,100,1,1,242.800000000,245.000000000,30,79,1,2,242.750000000,245.190000000,30,83,1,1,242.590000000,245.540000000,5,10,1,1,242.280000000,245.550000000,100,6,1,1,AAPL
2025-01-03T10:32:37.647014470Z,2025-01-03T10:32:37.646848634Z,10,2,38,C,A,0,243.750000000,200,130,165836,4926862,243.500000000,243.750000000,6,227,1,2,243.480000000,244.000000000,200,1,1,1,243.190000000,244.140000000,2,79,1,1,243.020000000,244.400000000,79,1050,1,2,243.000000000,244.420000000,1243,10,9,1,242.990000000,244.580000000,1,100,1,1,242.800000000,245.000000000,30,79,1,2,242.750000000,245.190000000,30,83,1,1,242.590000000,245.540000000,5,10,1,1,242.280000000,245.550000000,100,6,1,1,AAPL
2025-01-03T10:32:37.647027654Z,2025-01-03T10:32:37.646861122Z,10,2,38,A,A,0,243.730000000,200,130,166532,4926863,243.500000000,243.730000000,6,200,1,1,243.480000000,243.750000000,200,27,1,1,243.190000000,244.000000000,2,1,1,1,243.020000000,244.140000000,79,79,1,1,243.000000000,244.400000000,1243,1050,9,2,242.990000000,244.420000000,1,10,1,1,242.800000000,244.580000000,30,100,1,1,242.750000000,245.000000000,30,79,1,2,242.590000000,245.190000000,5,83,1,1,242.280000000,245.540000000,100,10,1,1,AAPL
2025-01-03T10:32:39.087491564Z,2025-01-03T10:32:39.087325339Z,10,2,16244,C,B,3,382.790000000,19,130,166225,4927359,382.840000000,383.090000000,300,30,1,1,382.820000000,383.100000000,1,370,1,1,382.810000000,383.140000000,20,3,2,1,382.700000000,383.200000000,50,10,1,1,382.500000000,383.250000000,3,47,1,1,382.230000000,383.340000000,25,21,1,1,382.100000000,383.420000000,10,140,1,1,382.010000000,383.600000000,2,1000,1,2,382.000000000,383.720000000,1239,7085,10,8,381.900000000,383.740000000,23,37,1,1,TSLA
2025-01-03T10:32:39.087610229Z,2025-01-03T10:32:39.087444068Z,10,2,16244,A,B,3,382.800000000,23,130,166161,4927360,382.840000000,383.090000000,300,30,1,1,382.820000000,383.100000000,1,370,1,1,382.810000000,383.140000000,20,3,2,1,382.800000000,383.200000000,23,10,1,1,382.700000000,383.250000000,50,47,1,1,382.500000000,383.340000000,3,21,1,1,382.230000000,383.420000000,25,140,1,1,382.100000000,383.600000000,10,1000,1,2,382.010000000,383.720000000,2,7085,1,8,382.000000000,383.740000000,1239,37,10,1,TSLA
2025-01-03T10:32:39.095817951Z,2025-01-03T10:32:39.095651553Z,10,2,16244,A,B,0,382.850000000,23,130,166398,4927361,382.850000000,383.090000000,23,30,1,1,382.840000000,383.100000000,300,370,1,1,382.820000000,383.140000000,1,3,1,1,382.810000000,383.200000000,20,10,2,1,382.800000000,383.250000000,23,47,1,1,382.700000000,383.340000000,50,21,1,1,382.500000000,383.420000000,3,140,1,1,382.230000000,383.600000000,25,1000,1,2,382.100000000,383.720000000,10,7085,1,8,382.010000000,383.740000000,2,37,1,1,TSLA
2025-01-03T10:32:39.096161834Z,2025-01-03T10:32:39.095995915Z,10,2,16244,C,A,5,383.340000000,21,130,165919,4927362,382.850000000,383.090000000,23,30,1,1,382.840000000,383.100000000,300,370,1,1,382.820000000,383.140000000,1,3,1,1,382.810000000,383.200000000,20,10,2,1,382.800000000,383.250000000,23,47,1,1,382.700000000,383.420000000,50,140,1,1,382.500000000,383.600000000,3,1000,1,2,382.230000000,383.720000000,25,7085,1,8,382.100000000,383.740000000,10,37,1,1,382.010000000,383.800000000,2,10,1,1,TSLA
2025-01-03T10:32:39.104955311Z,2025-01-03T10:32:39.104789209Z,10,2,16244,C,B,0,382.850000000,23,130,166102,4927364,382.840000000,383.090000000,300,30,1,1,382.820000000,383.100000000,1,370,1,1,382.810000000,383.140000000,20,3,2,1,382.800000000,383.200000000,23,10,1,1,382.700000000,383.250000000,50,47,1,1,382.500000000,383.420000000,3,140,1,1,382.230000000,383.600000000,25,1000,1,2,382.100000000,383.720000000,10,7085,1,8,382.010000000,383.740000000,2,37,1,1,382.000000000,383.800000000,1239,10,10,1,TSLA
2025-01-03T10:32:39.105589247Z,2025-01-03T10:32:39.105422975Z,10,2,16244,A,B,0,382.850000000,23,130,166272,4927365,382.850000000,383.090000000,23,30,1,1,382.840000000,383.100000000,300,370,1,1,382.820000000,383.140000000,1,3,1,1,382.810000000,383.200000000,20,10,2,1,382.800000000,383.250000000,23,47,1,1,382.700000000,383.420000000,50,140,1,1,382.500000000,383.600000000,3,1000,1,2,382.230000000,383.720000000,25,7085,1,8,382.100000000,383.740000000,10,37,1,1,382.010000000,383.800000000,2,10,1,1,TSLA
2025-01-03T10:32:39.124407734Z,2025-01-03T10:32:39.124241780Z,10,2,16244,C,B,0,382.850000000,23,130,165954,4927370,382.840000000,383.090000000,300,30,1,1,382.820000000,383.100000000,1,370,1,1,382.810000000,383.140000000,20,3,2,1,382.800000000,383.200000000,23,10,1,1,382.700000000,383.250000000,50,47,1,1,382.500000000,383.420000000,3,140,1,1,382.230000000,383.600000000,25,1000,1,2,382.100000000,383.720000000,10,7085,1,8,382.010000000,383.740000000,2,37,1,1,382.000000000,383.800000000,1239,10,10,1,TSLA
2025-01-03T10:32:39.124490988Z,2025-01-03T10:32:39.124324702Z,10,2,16244,C,B,3,382.800000000,23,130,166286,4927371,382.840000000,383.090000000,300,30,1,1,382.820000000,383.100000000,1,370,1,1,382.810000000,383.140000000,20,3,2,1,382.700000000,383.200000000,50,10,1,1,382.500000000,383.250000000,3,47,1,1,382.230000000,383.420000000,25,140,1,1,382.100000000,383.600000000,10,1000,1,2,382.010000000,383.720000000,2,7085,1,8,382.000000000,383.740000000,1239,37,10,1,381.900000000,383.800000000,23,10,1,1,TSLA
2025-01-03T10:32:39.168109037Z,2025-01-03T10:32:39.167942711Z,10,2,16244,A,B,0,382.850000000,22,130,166326,4927391,382.850000000,383.090000000,22,30,1,1,382.840000000,383.100000000,300,370,1,1,382.820000000,383.140000000,1,3,1,1,382.810000000,383.200000000,20,10,2,1,382.700000000,383.250000000,50,47,1,1,382.500000000,383.420000000,3,140,1,1,382.230000000,383.600000000,25,1000,1,2,382.100000000,383.720000000,10,7085,1,8,382.010000000,383.740000000,2,37,1,1,382.000000000,383.800000000,1239,10,10,1,TSLA
2025-01-03T10:32:40.021038839Z,2025-01-03T10:32:40.020872395Z,10,2,38,A,B,2,243.400000000,30,130,166444,4927702,243.500000000,243.730000000,6,200,1,1,243.480000000,243.750000000,200,27,1,1,243.400000000,244.000000000,30,1,1,1,243.190000000,244.140000000,2,79,1,1,243.020000000,244.400000000,79,1050,1,2,243.000000000,244.420000000,1243,10,9,1,242.990000000,244.580000000,1,100,1,1,242.800000000,245.000000000,30,79,1,2,242.750000000,245.190000000,30,83,1,1,242.590000000,245.540000000,5,10,1,1,AAPL
2025-01-03T10:32:40.185896455Z,2025-01-03T10:32:40.185730610Z,10,2,16244,C,B,0,382.850000000,22,130,165845,4927794,382.840000000,383.090000000,300,30,1,1,382.820000000,383.100000000,1,370,1,1,382.810000000,383.140000000,20,3,2,1,382.700000000,383.200000000,50,10,1,1,382.500000000,383.250000000,3,47,1,1,382.230000000,383.420000000,25,140,1,1,382.100000000,383.600000000,10,1000,1,2,382.010000000,383.720000000,2,7085,1,8,382.000000000,383.740000000,1239,37,10,1,381.900000000,383.800000000,23,10,1,1,TSLA
2025-01-03T10:32:40.469277563Z,2025-01-03T10:32:40.469111342Z,10,2,11667,A,A,2,139.230000000,100,130,166221,4928170,139.160000000,139.200000000,100,130,1,2,139.150000000,139.220000000,9860,10,2,1,139.130000000,139.230000000,2200,2677,2,5,139.120000000,139.250000000,30,1,1,1,139.110000000,139.270000000,1,37,1,2,139.100000000,139.300000000,410,507,2,4,139.090000000,139.320000000,57,39,1,1,139.070000000,139.330000000,100,503,1,2,139.030000000,139.360000000,126,4,2,2,139.010000000,139.370000000,100,75,1,1,NVDA
2025-01-03T10:32:40.511997581Z,2025-01-03T10:32:40.511831253Z,10,2,38,A,B,1,243.480000000,200,130,166328,4928339,243.500000000,243.730000000,6,200,1,1,243.480000000,243.750000000,400,27,2,1,243.400000000,244.000000000,30,1,1,1,243.190000000,244.140000000,2,79,1,1,243.020000000,244.400000000,79,1050,1,2,243.000000000,244.420000000,1243,10,9,1,242.990000000,244.580000000,1,100,1,1,242.800000000,245.000000000,30,79,1,2,242.750000000,245.190000000,30,83,1,1,242.590000000,245.540000000,5,10,1,1,AAPL
2025-01-03T10:32:40.512055922Z,2025-01-03T10:32:40.511889054Z,10,2,38,C,A,0,243.730000000,200,130,166868,4928340,243.500000000,243.750000000,6,27,1,1,243.480000000,244.000000000,400,1,2,1,243.400000000,244.140000000,30,79,1,1,243.190000000,244.400000000,2,1050,1,2,243.020000000,244.420000000,79,10,1,1,243.000000000,244.580000000,1243,100,9,1,242.990000000,245.000000000,1,79,1,2,242.800000000,245.190000000,30,83,1,1,242.750000000,245.540000000,30,10,1,1,242.590000000,245.550000000,5,6,1,1,AAPL
2025-01-03T10:32:40.512066779Z,2025-01-03T10:32:40.511900770Z,10,2,38,A,A,0,243.750000000,400,130,166009,4928341,243.500000000,243.750000000,6,427,1,2,243.480000000,244.000000000,400,1,2,1,243.400000000,244.140000000,30,79,1,1,243.190000000,244.400000000,2,1050,1,2,243.020000000,244.420000000,79,10,1,1,243.000000000,244.580000000,1243,100,9,1,242.990000000,245.000000000,1,79,1,2,242.800000000,245.190000000,30,83,1,1,242.750000000,245.540000000,30,10,1,1,242.590000000,245.550000000,5,6,1,1,AAPL
2025-01-03T10:32:40.566461437Z,2025-01-03T10:32:40.566295768Z,10,2,38,C,B,1,243.480000000,200,130,165669,4928484,243.500000000,243.750000000,6,427,1,2,243.480000000,244.000000000,200,1,1,1,243.400000000,244.140000000,30,79,1,1,243.190000000,244.400000000,2,1050,1,2,243.020000000,244.420000000,79,10,1,1,243.000000000,244.580000000,1243,100,9,1,242.990000000,245.000000000,1,79,1,2,242.800000000,245.190000000,30,83,1,1,242.750000000,245.540000000,30,10,1,1,242.590000000,245.550000000,5,6,1,1,AAPL
2025-01-03T10:32:40.566474081Z,2025-01-03T10:32:40.566307462Z,10,2,38,A,B,0,243.520000000,200,130,166619,4928486,243.520000000,243.750000000,200,427,1,2,243.500000000,244.000000000,6,1,1,1,243.400000000,244.140000000,30,79,1,1,243.190000000,244.400000000,2,1050,1,2,243.020000000,244.420000000,79,10,1,1,243.000000000,244.580000000,1243,100,9,1,242.990000000,245.000000000,1,79,1,2,242.800000000,245.190000000,30,83,1,1,242.750000000,245.540000000,30,10,1,1,242.590000000,245.550000000,5,6,1,1,AAPL
2025-01-03T10:32:40.566922916Z,2025-01-03T10:32:40.566756908Z,10,2,38,C,B,2,243.400000000,30,130,166008,4928502,243.520000000,243.750000000,200,427,1,2,243.500000000,244.000000000,6,1,1,1,243.190000000,244.140000000,2,79,1,1,243.020000000,244.400000000,79,1050,1,2,243.000000000,244.420000000,1243,10,9,1,242.990000000,244.580000000,1,100,1,1,242.800000000,245.000000000,30,79,1,2,242.750000000,245.190000000,30,83,1,1,242.590000000,245.540000000,5,10,1,1,242.280000000,245.550000000,100,6,1,1,AAPL
2025-01-03T10:32:40.567030221Z,2025-01-03T10:32:40.566864229Z,10,2,38,A,B,2,243.450000000,29,130,165992,4928505,243.520000000,243.750000000,200,427,1,2,243.500000000,244.000000000,6,1,1,1,243.450000000,244.140000000,29,79,1,1,243.190000000,244.400000000,2,1050,1,2,243.020000000,244.420000000,79,10,1,1,243.000000000,244.580000000,1243,100,9,1,242.990000000,245.000000000,1,79,1,2,242.800000000,245.190000000,30,83,1,1,242.750000000,245.540000000,30,10,1,1,242.590000000,245.550000000,5,6,1,1,AAPL
2025-01-03T10:32:40.613046253Z,2025-01-03T10:32:40.612879471Z,10,2,17709,A,B,1,107.520000000,17,130,166782,4928612,107.600000000,107.840000000,50,400,1,2,107.520000000,107.870000000,117,242,2,1,107.050000000,107.910000000,247,16,1,1,107.000000000,107.940000000,1,100,1,1,106.240000000,107.950000000,28,10,1,1,106.000000000,108.000000000,15,50,2,1,105.870000000,108.300000000,141,50,1,1,103.180000000,108.550000000,16,50,1,1,103.000000000,108.800000000,3,50,1,1,102.000000000,108.880000000,2,28,1,1,XOM
2025-01-03T10:32:40.915631313Z,2025-01-03T10:32:40.915465179Z,10,2,11667,C,A,0,139.200000000,100,130,166134,4928906,139.160000000,139.200000000,100,30,1,1,139.150000000,139.220000000,9860,10,2,1,139.130000000,139.230000000,2200,2677,2,5,139.120000000,139.250000000,30,1,1,1,139.110000000,139.270000000,1,37,1,2,139.100000000,139.300000000,410,507,2,4,139.090000000,139.320000000,57,39,1,1,139.070000000,139.330000000,100,503,1,2,139.030000000,139.360000000,126,4,2,2,139.010000000,139.370000000,100,75,1,1,NVDA
2025-01-03T10:32:40.925600142Z,2025-01-03T10:32:40.925433847Z,10,2,11667,A,A,1,139.210000000,400,130,166295,4928915,139.160000000,139.200000000,100,30,1,1,139.150000000,139.210000000,9860,400,2,1,139.130000000,139.220000000,2200,10,2,1,139.120000000,139.230000000,30,2277,1,4,139.110000000,139.250000000,1,1,1,1,139.100000000,139.270000000,410,37,2,2,139.090000000,139.300000000,57,507,1,4,139.070000000,139.320000000,100,39,1,1,139.030000000,139.330000000,126,503,2,2,139.010000000,139.360000000,100,4,1,2,NVDA
2025-01-03T10:32:40.990484303Z,2025-01-03T10:32:40.990318424Z,10,2,11667,C,A,1,139.210000000,400,130,165879,4928945,139.160000000,139.200000000,100,30,1,1,139.150000000,139.220000000,9860,10,2,1,139.130000000,139.230000000,2200,2277,2,4,139.120000000,139.250000000,30,1,1,1,139.110000000,139.270000000,1,37,1,2,139.100000000,139.300000000,410,507,2,4,139.090000000,139.320000000,57,39,1,1,139.070000000,139.330000000,100,503,1,2,139.030000000,139.360000000,126,4,2,2,139.010000000,139.370000000,100,75,1,1,NVDA
2025-01-03T10:32:40.990497863Z,2025-01-03T10:32:40.990331505Z,10,2,11667,A,A,2,139.230000000,400,130,166358,4928946,139.160000000,139.200000000,100,30,1,1,139.150000000,139.220000000,9860,10,2,1,139.130000000,139.230000000,2200,2677,2,5,139.120000000,139.250000000,30,1,1,1,139.110000000,139.270000000,1,37,1,2,139.100000000,139.300000000,410,507,2,4,139.090000000,139.320000000,57,39,1,1,139.070000000,139.330000000,100,503,1,2,139.030000000,139.360000000,126,4,2,2,139.010000000,139.370000000,100,75,1,1,NVDA
2025-01-03T10:32:41.042684791Z,2025-01-03T10:32:41.042518412Z,10,2,11667,A,B,4,139.110000000,400,130,166379,4928983,139.160000000,139.200000000,100,30,1,1,139.150000000,139.220000000,9860,10,2,1,139.130000000,139.230000000,2200,2677,2,5,139.120000000,139.250000000,30,1,1,1,139.110000000,139.270000000,401,37,2,2,139.100000000,139.300000000,10,507,1,4,139.090000000,139.320000000,57,39,1,1,139.070000000,139.330000000,100,503,1,2,139.030000000,139.360000000,126,4,2,2,139.010000000,139.370000000,100,75,1,1,NVDA
2025-01-03T10:32:41.528795139Z,2025-01-03T10:32:41.528628839Z,10,2,17709,A,A,2,107.880000000,100,130,166300,4929295,107.600000000,107.840000000,50,400,1,2,107.520000000,107.870000000,117,242,2,1,107.050000000,107.880000000,247,100,1,1,107.000000000,107.910000000,1,16,1,1,106.240000000,107.950000000,28,10,1,1,106.000000000,108.000000000,15,50,2,1,105.870000000,108.300000000,141,50,1,1,103.180000000,108.550000000,16,50,1,1,103.000000000,108.800000000,3,50,1,1,102.000000000,108.880000000,2,28,1,1,XOM
2025-01-03T10:32:41.877949730Z,2025-01-03T10:32:41.877783940Z,10,2,9155,C,B,1,241.500000000,8,130,165790,4929423,241.670000000,242.070000000,2,62,1,1,241.120000000,242.410000000,81,8,1,1,241.000000000,242.850000000,100,300,1,2,240.000000000,242.900000000,10,100,1,1,238.000000000,243.000000000,30,92,1,2,236.000000000,243.310000000,6,10,1,1,235.500000000,243.700000000,5,100,1,1,235.000000000,246.810000000,5,100,1,1,232.880000000,262.740000000,1,100,1,1,231.110000000,263.830000000,3,100,1,1,JPM
2025-01-03T10:32:41.878027482Z,2025-01-03T10:32:41.877860947Z,10,2,9155,A,B,1,241.600000000,8,130,166535,4929424,241.670000000,242.070000000,2,62,1,1,241.600000000,242.410000000,8,8,1,1,241.120000000,242.850000000,81,300,1,2,241.000000000,242.900000000,100,100,1,1,240.000000000,243.000000000,10,92,1,2,238.000000000,243.310000000,30,10,1,1,236.000000000,243.700000000,6,100,1,1,235.500000000,246.810000000,5,100,1,1,235.000000000,262.740000000,5,100,1,1,232.880000000,263.830000000,1,100,1,1,JPM
2025-01-03T10:32:41.952505378Z,2025-01-03T10:32:41.952337211Z,10,2,16244,A,A,5,383.350000000,19,130,168167,4929445,382.840000000,383.090000000,300,30,1,1,382.820000000,383.100000000,1,370,1,1,382.810000000,383.140000000,20,3,2,1,382.700000000,383.200000000,50,10,1,1,382.500000000,383.250000000,3,47,1,1,382.230000000,383.350000000,25,19,1,1,382.100000000,383.420000000,10,140,1,1,382.010000000,383.600000000,2,1000,1,2,382.000000000,383.720000000,1239,7085,10,8,381.900000000,383.740000000,23,37,1,1,TSLA
2025-01-03T10:32:41.986830596Z,2025-01-03T10:32:41.986664311Z,10,2,11667,C,B,4,139.110000000,400,130,166285,4929456,139.160000000,139.200000000,100,30,1,1,139.150000000,139.220000000,9860,10,2,1,139.130000000,139.230000000,2200,2677,2,5,139.120000000,139.250000000,30,1,1,1,139.110000000,139.270000000,1,37,1,2,139.100000000,139.300000000,10,507,1,4,139.090000000,139.320000000,57,39,1,1,139.070000000,139.330000000,100,503,1,2,139.030000000,139.360000000,126,4,2,2,139.010000000,139.370000000,100,75,1,1,NVDA
2025-01-03T10:32:41.986843339Z,2025-01-03T10:32:41.986677138Z,10,2,11667,A,B,5,139.100000000,400,130,166201,4929457,139.160000000,139.200000000,100,30,1,1,139.150000000,139.220000000,9860,10,2,1,139.130000000,139.230000000,2200,2677,2,5,139.120000000,139.250000000,30,1,1,1,139.110000000,139.270000000,1,37,1,2,139.100000000,139.300000000,410,507,2,4,139.090000000,139.320000000,57,39,1,1,139.070000000,139.330000000,100,503,1,2,139.030000000,139.360000000,126,4,2,2,139.010000000,139.370000000,100,75,1,1,NVDA
2025-01-03T10:32:42.046872463Z,2025-01-03T10:32:42.046705720Z,10,2,11667,A,A,1,139.210000000,400,130,166743,4929473,139.160000000,139.200000000,100,30,1,1,139.150000000,139.210000000,9860,400,2,1,139.130000000,139.220000000,2200,10,2,1,139.120000000,139.230000000,30,2277,1,4,139.110000000,139.250000000,1,1,1,1,139.100000000,139.270000000,410,37,2,2,139.090000000,139.300000000,57,507,1,4,139.070000000,139.320000000,100,39,1,1,139.030000000,139.330000000,126,503,2,2,139.010000000,139.360000000,100,4,1,2,NVDA
2025-01-03T10:32:42.055276234Z,2025-01-03T10:32:42.055110004Z,10,2,11667,A,B,4,139.110000000,400,130,166230,4929480,139.160000000,139.200000000,100,30,1,1,139.150000000,139.210000000,9860,400,2,1,139.130000000,139.220000000,2200,10,2,1,139.120000000,139.230000000,30,2277,1,4,139.110000000,139.250000000,401,1,2,1,139.100000000,139.270000000,10,37,1,2,139.090000000,139.300000000,57,507,1,4,139.070000000,139.320000000,100,39,1,1,139.030000000,139.330000000,126,503,2,2,139.010000000,139.360000000,100,4,1,2,NVDA
2025-01-03T10:32:42.420080676Z,2025-01-03T10:32:42.419914601Z,10,2,9155,C,B,1,241.600000000,8,130,166075,4929657,241.670000000,242.070000000,2,62,1,1,241.120000000,242.410000000,81,8,1,1,241.000000000,242.850000000,100,300,1,2,240.000000000,242.900000000,10,100,1,1,238.000000000,243.000000000,30,92,1,2,236.000000000,243.310000000,6,10,1,1,235.500000000,243.700000000,5,100,1,1,235.000000000,246.810000000,5,100,1,1,232.880000000,262.740000000,1,100,1,1,231.110000000,263.830000000,3,100,1,1,JPM
2025-01-03T10:32:43.319234765Z,2025-01-03T10:32:43.319068659Z,10,2,10888,C,B,0,420.670000000,200,130,166106,4930130,420.590000000,421.190000000,14,200,1,1,420.580000000,421.220000000,10,13,1,1,420.520000000,421.460000000,1,39,1,1,420.400000000,421.490000000,858,6,1,1,420.380000000,421.570000000,100,40,1,1,420.100000000,421.600000000,100,510,1,2,420.000000000,421.700000000,834,359,8,1,419.730000000,421.800000000,3,7,1,1,419.650000000,422.100000000,39,7,1,1,418.650000000,422.500000000,1,200,1,1,MSFT
2025-01-03T10:32:43.319992662Z,2025-01-03T10:32:43.319826808Z,10,2,10888,C,B,0,420.590000000,14,130,165854,4930131,420.580000000,421.190000000,10,200,1,1,420.520000000,421.220000000,1,13,1,1,420.400000000,421.460000000,858,39,1,1,420.380000000,421.490000000,100,6,1,1,420.100000000,421.570000000,100,40,1,1,420.000000000,421.600000000,834,510,8,2,419.730000000,421.700000000,3,359,1,1,419.650000000,421.800000000,39,7,1,1,418.650000000,422.100000000,1,7,1,1,418.500000000,422.500000000,1,200,1,1,MSFT
2025-01-03T10:32:43.320102821Z,2025-01-03T10:32:43.319936805Z,10,2,10888,A,B,1,420.530000000,14,130,166016,4930133,420.580000000,421.190000000,10,200,1,1,420.530000000,421.220000000,14,13,1,1,420.520000000,421.460000000,1,39,1,1,420.400000000,421.490000000,858,6,1,1,420.380000000,421.570000000,100,40,1,1,420.100000000,421.600000000,100,510,1,2,420.000000000,421.700000000,834,359,8,1,419.730000000,421.800000000,3,7,1,1,419.650000000,422.100000000,39,7,1,1,418.650000000,422.500000000,1,200,1,1,MSFT
2025-01-03T10:32:43.375531399Z,2025-01-03T10:32:43.375365158Z,10,2,10888,A,B,1,420.540000000,200,130,166241,4930135,420.580000000,421.190000000,10,200,1,1,420.540000000,421.220000000,200,13,1,1,420.530000000,421.460000000,14,39,1,1,420.520000000,421.490000000,1,6,1,1,420.400000000,421.570000000,858,40,1,1,420.380000000,421.600000000,100,510,1,2,420.100000000,421.700000000,100,359,1,1,420.000000000,421.800000000,834,7,8,1,419.730000000,422.100000000,3,7,1,1,419.650000000,422.500000000,39,200,1,1,MSFT
2025-01-03T10:32:44.045159823Z,2025-01-03T10:32:44.044993402Z,10,2,16244,A,B,3,382.800000000,21,130,166421,4930367,382.840000000,383.090000000,300,30,1,1,382.820000000,383.100000000,1,370,1,1,382.810000000,383.140000000,20,3,2,1,382.800000000,383.200000000,21,10,1,1,382.700000000,383.250000000,50,47,1,1,382.500000000,383.350000000,3,19,1,1,382.230000000,383.420000000,25,140,1,1,382.100000000,383.600000000,10,1000,1,2,382.010000000,383.720000000,2,7085,1,8,382.000000000,383.740000000,1239,37,10,1,TSLA
2025-01-03T10:32:44.045597423Z,2025-01-03T10:32:44.045431547Z,10,2,17709,C,B,1,107.520000000,17,130,165876,4930373,107.600000000,107.840000000,50,400,1,2,107.520000000,107.870000000,100,242,1,1,107.050000000,107.880000000,247,100,1,1,107.000000000,107.910000000,1,16,1,1,106.240000000,107.950000000,28,10,1,1,106.000000000,108.000000000,15,50,2,1,105.870000000,108.300000000,141,50,1,1,103.180000000,108.550000000,16,50,1,1,103.000000000,108.800000000,3,50,1,1,102.000000000,108.880000000,2,28,1,1,XOM
2025-01-03T10:32:44.045690789Z,2025-01-03T10:32:44.045524513Z,10,2,17709,A,B,1,107.550000000,15,130,166276,4930374,107.600000000,107.840000000,50,400,1,2,107.550000000,107.870000000,15,242,1,1,107.520000000,107.880000000,100,100,1,1,107.050000000,107.910000000,247,16,1,1,107.000000000,107.950000000,1,10,1,1,106.240000000,108.000000000,28,50,1,1,106.000000000,108.300000000,15,50,2,1,105.870000000,108.550000000,141,50,1,1,103.180000000,108.800000000,16,50,1,1,103.000000000,108.880000000,3,28,1,1,XOM
2025-01-03T10:32:44.045710757Z,2025-01-03T10:32:44.045544738Z,10,2,17709,C,A,3,107.910000000,16,130,166019,4930375,107.600000000,107.840000000,50,400,1,2,107.550000000,107.870000000,15,242,1,1,107.520000000,107.880000000,100,100,1,1,107.050000000,107.950000000,247,10,1,1,107.000000000,108.000000000,1,50,1,1,106.240000000,108.300000000,28,50,1,1,106.000000000,108.550000000,15,50,2,1,105.870000000,108.800000000,141,50,1,1,103.180000000,108.880000000,16,28,1,1,103.000000000,109.000000000,3,100,1,1,XOM
2025-01-03T10:32:44.045775542Z,2025-01-03T10:32:44.045609478Z,10,2,17709,A,A,1,107.850000000,17,130,166064,4930376,107.600000000,107.840000000,50,400,1,2,107.550000000,107.850000000,15,17,1,1,107.520000000,107.870000000,100,242,1,1,107.050000000,107.880000000,247,100,1,1,107.000000000,107.950000000,1,10,1,1,106.240000000,108.000000000,28,50,1,1,106.000000000,108.300000000,15,50,2,1,105.870000000,108.550000000,141,50,1,1,103.180000000,108.800000000,16,50,1,1,103.000000000,108.880000000,3,28,1,1,XOM
2025-01-03T10:32:44.393710311Z,2025-01-03T10:32:44.393543076Z,10,2,11667,T,N,0,139.170000000,207,130,167235,4930517,139.160000000,139.200000000,100,30,1,1,139.150000000,139.210000000,9860,400,2,1,139.130000000,139.220000000,2200,10,2,1,139.120000000,139.230000000,30,2277,1,4,139.110000000,139.250000000,401,1,2,1,139.100000000,139.270000000,10,37,1,2,139.090000000,139.300000000,57,507,1,4,139.070000000,139.320000000,100,39,1,1,139.030000000,139.330000000,126,503,2,2,139.010000000,139.360000000,100,4,1,2,NVDA
2025-01-03T10:32:44.393717234Z,2025-01-03T10:32:44.393551367Z,10,2,11667,C,B,4,139.110000000,400,130,165867,4930518,139.160000000,139.200000000,100,30,1,1,139.150000000,139.210000000,9860,400,2,1,139.130000000,139.220000000,2200,10,2,1,139.120000000,139.230000000,30,2277,1,4,139.110000000,139.250000000,1,1,1,1,139.100000000,139.270000000,10,37,1,2,139.090000000,139.300000000,57,507,1,4,139.070000000,139.320000000,100,39,1,1,139.030000000,139.330000000,126,503,2,2,139.010000000,139.360000000,100,4,1,2,NVDA
2025-01-03T10:32:44.393729893Z,2025-01-03T10:32:44.393563874Z,10,2,11667,A,B,5,139.100000000,400,130,166019,4930519,139.160000000,139.200000000,100,30,1,1,139.150000000,139.210000000,9860,400,2,1,139.130000000,139.220000000,2200,10,2,1,139.120000000,139.230000000,30,2277,1,4,139.110000000,139.250000000,1,1,1,1,139.100000000,139.270000000,410,37,2,2,139.090000000,139.300000000,57,507,1,4,139.070000000,139.320000000,100,39,1,1,139.030000000,139.330000000,126,503,2,2,139.010000000,139.360000000,100,4,1,2,NVDA
2025-01-03T10:32:44.393934198Z,2025-01-03T10:32:44.393768309Z,10,2,11667,C,B,5,139.100000000,400,130,165889,4930524,139.160000000,139.200000000,100,30,1,1,139.150000000,139.210000000,9860,400,2,1,139.130000000,139.220000000,2200,10,2,1,139.120000000,139.230000000,30,2277,1,4,139.110000000,139.250000000,1,1,1,1,139.100000000,139.270000000,10,37,1,2,139.090000000,139.300000000,57,507,1,4,139.070000000,139.320000000,100,39,1,1,139.030000000,139.330000000,126,503,2,2,139.010000000,139.360000000,100,4,1,2,NVDA
2025-01-03T10:32:44.394114589Z,2025-01-03T10:32:44.393948452Z,10,2,11667,A,A,0,139.190000000,100,130,166137,4930528,139.160000000,139.190000000,100,100,1,1,139.150000000,139.200000000,9860,30,2,1,139.130000000,139.210000000,2200,400,2,1,139.120000000,139.220000000,30,10,1,1,139.110000000,139.230000000,1,2277,1,4,139.100000000,139.250000000,10,1,1,1,139.090000000,139.270000000,57,37,1,2,139.070000000,139.300000000,100,507,1,4,139.030000000,139.320000000,126,39,2,1,139.010000000,139.330000000,100,503,1,2,NVDA
2025-01-03T10:32:44.394850567Z,2025-01-03T10:32:44.394684437Z,10,2,11667,A,B,6,139.090000000,400,130,166130,4930535,139.160000000,139.190000000,100,100,1,1,139.150000000,139.200000000,9860,30,2,1,139.130000000,139.210000000,2200,400,2,1,139.120000000,139.220000000,30,10,1,1,139.110000000,139.230000000,1,2277,1,4,139.100000000,139.250000000,10,1,1,1,139.090000000,139.270000000,457,37,2,2,139.070000000,139.300000000,100,507,1,4,139.030000000,139.320000000,126,39,2,1,139.010000000,139.330000000,100,503,1,2,NVDA
2025-01-03T10:32:44.449347140Z,2025-01-03T10:32:44.449180842Z,10,2,11667,A,B,5,139.100000000,400,130,166298,4930570,139.160000000,139.190000000,100,100,1,1,139.150000000,139.200000000,9860,30,2,1,139.130000000,139.210000000,2200,400,2,1,139.120000000,139.220000000,30,10,1,1,139.110000000,139.230000000,1,2277,1,4,139.100000000,139.250000000,410,1,2,1,139.090000000,139.270000000,57,37,1,2,139.070000000,139.300000000,100,507,1,4,139.030000000,139.320000000,126,39,2,1,139.010000000,139.330000000,100,503,1,2,NVDA
2025-01-03T10:32:44.459346872Z,2025-01-03T10:32:44.459180595Z,10,2,11667,A,A,1,139.200000000,400,130,166277,4930572,139.160000000,139.190000000,100,100,1,1,139.150000000,139.200000000,9860,430,2,2,139.130000000,139.220000000,2200,10,2,1,139.120000000,139.230000000,30,2277,1,4,139.110000000,139.250000000,1,1,1,1,139.100000000,139.270000000,410,37,2,2,139.090000000,139.300000000,57,507,1,4,139.070000000,139.320000000,100,39,1,1,139.030000000,139.330000000,126,503,2,2,139.010000000,139.360000000,100,4,1,2,NVDA
2025-01-03T10:32:44.461483006Z,2025-01-03T10:32:44.461317037Z,10,2,11667,C,B,5,139.100000000,400,130,165969,4930573,139.160000000,139.190000000,100,100,1,1,139.150000000,139.200000000,9860,430,2,2,139.130000000,139.220000000,2200,10,2,1,139.120000000,139.230000000,30,2277,1,4,139.110000000,139.250000000,1,1,1,1,139.100000000,139.270000000,10,37,1,2,139.090000000,139.300000000,57,507,1,4,139.070000000,139.320000000,100,39,1,1,139.030000000,139.330000000,126,503,2,2,139.010000000,139.360000000,100,4,1,2,NVDA
2025-01-03T10:32:44.461496199Z,2025-01-03T10:32:44.461329867Z,10,2,11667,A,B,6,139.090000000,400,130,166332,4930574,139.160000000,139.190000000,100,100,1,1,139.150000000,139.200000000,9860,430,2,2,139.130000000,139.220000000,2200,10,2,1,139.120000000,139.230000000,30,2277,1,4,139.110000000,139.250000000,1,1,1,1,139.100000000,139.270000000,10,37,1,2,139.090000000,139.300000000,457,507,2,4,139.070000000,139.320000000,100,39,1,1,139.030000000,139.330000000,126,503,2,2,139.010000000,139.360000000,100,4,1,2,NVDA
2025-01-03T10:32:44.899446295Z,2025-01-03T10:32:44.899280071Z,10,2,16244,C,B,5,382.500000000,3,130,166224,4930892,382.840000000,383.090000000,300,30,1,1,382.820000000,383.100000000,1,370,1,1,382.810000000,383.140000000,20,3,2,1,382.800000000,383.200000000,21,10,1,1,382.700000000,383.250000000,50,47,1,1,382.230000000,383.350000000,25,19,1,1,382.100000000,383.420000000,10,140,1,1,382.010000000,383.600000000,2,1000,1,2,382.000000000,383.720000000,1239,7085,10,8,381.900000000,383.740000000,23,37,1,1,TSLA
2025-01-03T10:32:44.900618232Z,2025-01-03T10:32:44.900451722Z,10,2,16244,A,B,8,382.000000000,3,130,166510,4930893,382.840000000,383.090000000,300,30,1,1,382.820000000,383.100000000,1,370,1,1,382.810000000,383.140000000,20,3,2,1,382.800000000,383.200000000,21,10,1,1,382.700000000,383.250000000,50,47,1,1,382.230000000,383.350000000,25,19,1,1,382.100000000,383.420000000,10,140,1,1,382.010000000,383.600000000,2,1000,1,2,382.000000000,383.720000000,1242,7085,11,8,381.900000000,383.740000000,23,37,1,1,TSLA
2025-01-03T10:32:45.412436274Z,2025-01-03T10:32:45.412269989Z,10,2,16244,C,B,3,382.800000000,21,130,166285,4931212,382.840000000,383.090000000,300,30,1,1,382.820000000,383.100000000,1,370,1,1,382.810000000,383.140000000,20,3,2,1,382.700000000,383.200000000,50,10,1,1,382.230000000,383.250000000,25,47,1,1,382.100000000,383.350000000,10,19,1,1,382.010000000,383.420000000,2,140,1,1,382.000000000,383.600000000,1242,1000,11,2,381.900000000,383.720000000,23,7085,1,8,381.880000000,383.740000000,10,37,1,1,TSLA
2025-01-03T10:32:45.433340098Z,2025-01-03T10:32:45.433173779Z,10,2,38,C,A,5,244.580000000,100,130,166319,4931228,243.520000000,243.750000000,200,427,1,2,243.500000000,244.000000000,6,1,1,1,243.450000000,244.140000000,29,79,1,1,243.190000000,244.400000000,2,1050,1,2,243.020000000,244.420000000,79,10,1,1,243.000000000,245.000000000,1243,79,9,2,242.990000000,245.190000000,1,83,1,1,242.800000000,245.540000000,30,10,1,1,242.750000000,245.550000000,30,6,1,1,242.590000000,245.780000000,5,100,1,1,AAPL
2025-01-03T10:32:45.434341353Z,2025-01-03T10:32:45.434175392Z,10,2,38,A,A,0,243.730000000,100,130,165961,4931229,243.520000000,243.730000000,200,100,1,1,243.500000000,243.750000000,6,427,1,2,243.450000000,244.000000000,29,1,1,1,243.190000000,244.140000000,2,79,1,1,243.020000000,244.400000000,79,1050,1,2,243.000000000,244.420000000,1243,10,9,1,242.990000000,245.000000000,1,79,1,2,242.800000000,245.190000000,30,83,1,1,242.750000000,245.540000000,30,10,1,1,242.590000000,245.550000000,5,6,1,1,AAPL
2025-01-03T10:32:46.320059624Z,2025-01-03T10:32:46.319893339Z,10,2,10888,A,B,0,420.580000000,15,130,166285,4931747,420.580000000,421.190000000,25,200,2,1,420.540000000,421.220000000,200,13,1,1,420.530000000,421.460000000,14,39,1,1,420.520000000,421.490000000,1,6,1,1,420.400000000,421.570000000,858,40,1,1,420.380000000,421.600000000,100,510,1,2,420.100000000,421.700000000,100,359,1,1,420.000000000,421.800000000,834,7,8,1,419.730000000,422.100000000,3,7,1,1,419.650000000,422.500000000,39,200,1,1,MSFT
2025-01-03T10:32:46.320084609Z,2025-01-03T10:32:46.319918801Z,10,2,10888,C,B,2,420.530000000,14,130,165808,4931748,420.580000000,421.190000000,25,200,2,1,420.540000000,421.220000000,200,13,1,1,420.520000000,421.460000000,1,39,1,1,420.400000000,421.490000000,858,6,1,1,420.380000000,421.570000000,100,40,1,1,420.100000000,421.600000000,100,510,1,2,420.000000000,421.700000000,834,359,8,1,419.730000000,421.800000000,3,7,1,1,419.650000000,422.100000000,39,7,1,1,418.650000000,422.500000000,1,200,1,1,MSFT
2025-01-03T10:32:46.374981533Z,2025-01-03T10:32:46.374815009Z,10,2,10888,A,B,0,420.700000000,200,130,166524,4931772,420.700000000,421.190000000,200,200,1,1,420.580000000,421.220000000,25,13,2,1,420.520000000,421.460000000,1,39,1,1,420.400000000,421.490000000,858,6,1,1,420.380000000,421.570000000,100,40,1,1,420.100000000,421.600000000,100,510,1,2,420.000000000,421.700000000,834,359,8,1,419.730000000,421.800000000,3,7,1,1,419.650000000,422.100000000,39,7,1,1,418.650000000,422.500000000,1,200,1,1,MSFT
2025-01-03T10:32:46.849125789Z,2025-01-03T10:32:46.848959441Z,10,2,11667,C,A,0,139.190000000,100,130,166348,4931945,139.160000000,139.200000000,100,430,1,2,139.150000000,139.220000000,9860,10,2,1,139.130000000,139.230000000,2200,2277,2,4,139.120000000,139.250000000,30,1,1,1,139.110000000,139.270000000,1,37,1,2,139.100000000,139.300000000,10,507,1,4,139.090000000,139.320000000,457,39,2,1,139.070000000,139.330000000,100,503,1,2,139.030000000,139.360000000,126,4,2,2,139.010000000,139.370000000,100,75,1,1,NVDA
2025-01-03T10:32:47.004276034Z,2025-01-03T10:32:47.004109870Z,10,2,17709,C,A,3,107.880000000,100,130,166164,4931994,107.600000000,107.840000000,50,400,1,2,107.550000000,107.850000000,15,17,1,1,107.520000000,107.870000000,100,242,1,1,107.050000000,107.950000000,247,10,1,1,107.000000000,108.000000000,1,50,1,1,106.240000000,108.300000000,28,50,1,1,106.000000000,108.550000000,15,50,2,1,105.870000000,108.800000000,141,50,1,1,103.180000000,108.880000000,16,28,1,1,103.000000000,109.000000000,3,100,1,1,XOM
2025-01-03T10:32:47.004288641Z,2025-01-03T10:32:47.004122403Z,10,2,17709,A,A,3,107.940000000,100,130,166238,4931995,107.600000000,107.840000000,50,400,1,2,107.550000000,107.850000000,15,17,1,1,107.520000000,107.870000000,100,242,1,1,107.050000000,107.940000000,247,100,1,1,107.000000000,107.950000000,1,10,1,1,106.240000000,108.000000000,28,50,1,1,106.000000000,108.300000000,15,50,2,1,105.870000000,108.550000000,141,50,1,1,103.180000000,108.800000000,16,50,1,1,103.000000000,108.880000000,3,28,1,1,XOM
2025-01-03T10:32:47.004728981Z,2025-01-03T10:32:47.004563202Z,10,2,17709,C,A,1,107.850000000,17,130,165779,4931996,107.600000000,107.840000000,50,400,1,2,107.550000000,107.870000000,15,242,1,1,107.520000000,107.940000000,100,100,1,1,107.050000000,107.950000000,247,10,1,1,107.000000000,108.000000000,1,50,1,1,106.240000000,108.300000000,28,50,1,1,106.000000000,108.550000000,15,50,2,1,105.870000000,108.800000000,141,50,1,1,103.180000000,108.880000000,16,28,1,1,103.000000000,109.000000000,3,100,1,1,XOM
2025-01-03T10:32:47.423623911Z,2025-01-03T10:32:47.423457646Z,10,2,9155,A,B,1,241.500000000,8,130,166265,4932171,241.670000000,242.070000000,2,62,1,1,241.500000000,242.410000000,8,8,1,1,241.120000000,242.850000000,81,300,1,2,241.000000000,242.900000000,100,100,1,1,240.000000000,243.000000000,10,92,1,2,238.000000000,243.310000000,30,10,1,1,236.000000000,243.700000000,6,100,1,1,235.500000000,246.810000000,5,100,1,1,235.000000000,262.740000000,5,100,1,1,232.880000000,263.830000000,1,100,1,1,JPM
2025-01-03T10:32:49.017986814Z,2025-01-03T10:32:49.017820675Z,10,2,17709,A,A,2,107.890000000,16,130,166139,4932997,107.600000000,107.840000000,50,400,1,2,107.550000000,107.870000000,15,242,1,1,107.520000000,107.890000000,100,16,1,1,107.050000000,107.940000000,247,100,1,1,107.000000000,107.950000000,1,10,1,1,106.240000000,108.000000000,28,50,1,1,106.000000000,108.300000000,15,50,2,1,105.870000000,108.550000000,141,50,1,1,103.180000000,108.800000000,16,50,1,1,103.000000000,108.880000000,3,28,1,1,XOM
2025-01-03T10:32:49.411971522Z,2025-01-03T10:32:49.411805141Z,10,2,16244,A,B,2,382.810000000,19,130,166381,4933118,382.840000000,383.090000000,300,30,1,1,382.820000000,383.100000000,1,370,1,1,382.810000000,383.140000000,39,3,3,1,382.700000000,383.200000000,50,10,1,1,382.230000000,383.250000000,25,47,1,1,382.100000000,383.350000000,10,19,1,1,382.010000000,383.420000000,2,140,1,1,382.000000000,383.600000000,1242,1000,11,2,381.900000000,383.720000000,23,7085,1,8,381.880000000,383.740000000,10,37,1,1,TSLA
2025-01-03T10:32:49.412027350Z,2025-01-03T10:32:49.411860884Z,10,2,16244,A,B,0,382.850000000,23,130,166466,4933119,382.850000000,383.090000000,23,30,1,1,382.840000000,383.100000000,300,370,1,1,382.820000000,383.140000000,1,3,1,1,382.810000000,383.200000000,39,10,3,1,382.700000000,383.250000000,50,47,1,1,382.230000000,383.350000000,25,19,1,1,382.100000000,383.420000000,10,140,1,1,382.010000000,383.600000000,2,1000,1,2,382.000000000,383.720000000,1242,7085,11,8,381.900000000,383.740000000,23,37,1,1,TSLA
2025-01-03T10:32:50.143877321Z,2025-01-03T10:32:50.143711328Z,10,2,11667,C,A,0,139.200000000,400,130,165993,4933482,139.160000000,139.200000000,100,30,1,1,139.150000000,139.220000000,9860,10,2,1,139.130000000,139.230000000,2200,2277,2,4,139.120000000,139.250000000,30,1,1,1,139.110000000,139.270000000,1,37,1,2,139.100000000,139.300000000,10,507,1,4,139.090000000,139.320000000,457,39,2,1,139.070000000,139.330000000,100,503,1,2,139.030000000,139.360000000,126,4,2,2,139.010000000,139.370000000,100,75,1,1,NVDA
2025-01-03T10:32:50.143967988Z,2025-01-03T10:32:50.143797245Z,10,2,11667,T,N,0,139.190000000,70,0,170743,4933483,139.160000000,139.200000000,100,30,1,1,139.150000000,139.220000000,9860,10,2,1,139.130000000,139.230000000,2200,2277,2,4,139.120000000,139.250000000,30,1,1,1,139.110000000,139.270000000,1,37,1,2,139.100000000,139.300000000,10,507,1,4,139.090000000,139.320000000,457,39,2,1,139.070000000,139.330000000,100,503,1,2,139.030000000,139.360000000,126,4,2,2,139.010000000,139.370000000,100,75,1,1,NVDA
2025-01-03T10:32:50.143967988Z,2025-01-03T10:32:50.143797245Z,10,2,11667,T,N,0,139.190000000,70,0,170743,4933484,139.160000000,139.200000000,100,30,1,1,139.150000000,139.220000000,9860,10,2,1,139.130000000,139.230000000,2200,2277,2,4,139.120000000,139.250000000,30,1,1,1,139.110000000,139.270000000,1,37,1,2,139.100000000,139.300000000,10,507,1,4,139.090000000,139.320000000,457,39,2,1,139.070000000,139.330000000,100,503,1,2,139.030000000,139.360000000,126,4,2,2,139.010000000,139.370000000,100,75,1,1,NVDA
2025-01-03T10:32:50.143967988Z,2025-01-03T10:32:50.143797245Z,10,2,11667,T,N,0,139.190000000,10,0,170743,4933485,139.160000000,139.200000000,100,30,1,1,139.150000000,139.220000000,9860,10,2,1,139.130000000,139.230000000,2200,2277,2,4,139.120000000,139.250000000,30,1,1,1,139.110000000,139.270000000,1,37,1,2,139.100000000,139.300000000,10,507,1,4,139.090000000,139.320000000,457,39,2,1,139.070000000,139.330000000,100,503,1,2,139.030000000,139.360000000,126,4,2,2,139.010000000,139.370000000,100,75,1,1,NVDA
2025-01-03T10:32:50.143967988Z,2025-01-03T10:32:50.143798093Z,10,2,11667,T,N,0,139.190000000,88,130,169895,4933486,139.160000000,139.200000000,100,30,1,1,139.150000000,139.220000000,9860,10,2,1,139.130000000,139.230000000,2200,2277,2,4,139.120000000,139.250000000,30,1,1,1,139.110000000,139.270000000,1,37,1,2,139.100000000,139.300000000,10,507,1,4,139.090000000,139.320000000,457,39,2,1,139.070000000,139.330000000,100,503,1,2,139.030000000,139.360000000,126,4,2,2,139.010000000,139.370000000,100,75,1,1,NVDA
2025-01-03T10:32:50.143987583Z,2025-01-03T10:32:50.143819712Z,10,2,11667,T,N,0,139.190000000,2,0,167871,4933487,139.160000000,139.200000000,100,30,1,1,139.150000000,139.220000000,9860,10,2,1,139.130000000,139.230000000,2200,2277,2,4,139.120000000,139.250000000,30,1,1,1,139.110000000,139.270000000,1,37,1,2,139.100000000,139.300000000,10,507,1,4,139.090000000,139.320000000,457,39,2,1,139.070000000,139.330000000,100,503,1,2,139.030000000,139.360000000,126,4,2,2,139.010000000,139.370000000,100,75,1,1,NVDA
2025-01-03T10:32:50.143987583Z,2025-01-03T10:32:50.143819712Z,10,2,11667,T,B,0,139.200000000,28,130,167871,4933488,139.160000000,139.200000000,100,30,1,1,139.150000000,139.220000000,9860,10,2,1,139.130000000,139.230000000,2200,2277,2,4,139.120000000,139.250000000,30,1,1,1,139.110000000,139.270000000,1,37,1,2,139.100000000,139.300000000,10,507,1,4,139.090000000,139.320000000,457,39,2,1,139.070000000,139.330000000,100,503,1,2,139.030000000,139.360000000,126,4,2,2,139.010000000,139.370000000,100,75,1,1,NVDA
2025-01-03T10:32:50.143987583Z,2025-01-03T10:32:50.143819712Z,10,2,11667,C,A,0,139.200000000,28,130,167871,4933488,139.160000000,139.200000000,100,2,1,1,139.150000000,139.220000000,9860,10,2,1,139.130000000,139.230000000,2200,2277,2,4,139.120000000,139.250000000,30,1,1,1,139.110000000,139.270000000,1,37,1,2,139.100000000,139.300000000,10,507,1,4,139.090000000,139.320000000,457,39,2,1,139.070000000,139.330000000,100,503,1,2,139.030000000,139.360000000,126,4,2,2,139.010000000,139.370000000,100,75,1,1,NVDA
2025-01-03T10:32:50.200369018Z,2025-01-03T10:32:50.200202427Z,10,2,11667,A,B,5,139.100000000,400,130,166591,4933507,139.160000000,139.200000000,100,2,1,1,139.150000000,139.220000000,9860,10,2,1,139.130000000,139.230000000,2200,2277,2,4,139.120000000,139.250000000,30,1,1,1,139.110000000,139.270000000,1,37,1,2,139.100000000,139.300000000,410,507,2,4,139.090000000,139.320000000,57,39,1,1,139.070000000,139.330000000,100,503,1,2,139.030000000,139.360000000,126,4,2,2,139.010000000,139.370000000,100,75,1,1,NVDA
2025-01-03T10:32:50.217855695Z,2025-01-03T10:32:50.217689363Z,10,2,11667,A,A,3,139.250000000,400,130,166332,4933511,139.160000000,139.200000000,100,2,1,1,139.150000000,139.220000000,9860,10,2,1,139.130000000,139.230000000,2200,2277,2,4,139.120000000,139.250000000,30,401,1,2,139.110000000,139.270000000,1,37,1,2,139.100000000,139.300000000,410,507,2,4,139.090000000,139.320000000,57,39,1,1,139.070000000,139.330000000,100,503,1,2,139.030000000,139.360000000,126,4,2,2,139.010000000,139.370000000,100,75,1,1,NVDA
2025-01-03T10:32:50.222932451Z,2025-01-03T10:32:50.222766030Z,10,2,11667,A,B,0,139.160000000,400,130,166421,4933515,139.160000000,139.200000000,500,2,2,1,139.150000000,139.220000000,9860,10,2,1,139.130000000,139.230000000,2200,2277,2,4,139.120000000,139.250000000,30,401,1,2,139.110000000,139.270000000,1,37,1,2,139.100000000,139.300000000,10,507,1,4,139.090000000,139.320000000,57,39,1,1,139.070000000,139.330000000,100,503,1,2,139.030000000,139.360000000,126,4,2,2,139.010000000,139.370000000,100,75,1,1,NVDA
2025-01-03T10:32:50.222961944Z,2025-01-03T10:32:50.222795453Z,10,2,11667,A,B,0,139.170000000,100,130,166491,4933516,139.170000000,139.200000000,100,2,1,1,139.160000000,139.220000000,500,10,2,1,139.150000000,139.230000000,9860,2277,2,4,139.130000000,139.250000000,2200,401,2,2,139.120000000,139.270000000,30,37,1,2,139.110000000,139.300000000,1,507,1,4,139.100000000,139.320000000,10,39,1,1,139.090000000,139.330000000,57,503,1,2,139.070000000,139.360000000,100,4,1,2,139.030000000,139.370000000,126,75,2,1,NVDA
2025-01-03T10:32:50.222973645Z,2025-01-03T10:32:50.222807619Z,10,2,11667,C,B,3,139.130000000,100,130,166026,4933517,139.170000000,139.200000000,100,2,1,1,139.160000000,139.220000000,500,10,2,1,139.150000000,139.230000000,9860,2277,2,4,139.130000000,139.250000000,2100,401,1,2,139.120000000,139.270000000,30,37,1,2,139.110000000,139.300000000,1,507,1,4,139.100000000,139.320000000,10,39,1,1,139.090000000,139.330000000,57,503,1,2,139.070000000,139.360000000,100,4,1,2,139.030000000,139.370000000,126,75,2,1,NVDA
2025-01-03T10:32:50.244534696Z,2025-01-03T10:32:50.244368662Z,10,2,11667,C,A,3,139.250000000,400,130,166034,4933580,139.170000000,139.200000000,100,2,1,1,139.160000000,139.220000000,500,10,2,1,139.150000000,139.230000000,9860,2277,2,4,139.130000000,139.250000000,2100,1,1,1,139.120000000,139.270000000,30,37,1,2,139.110000000,139.300000000,1,507,1,4,139.100000000,139.320000000,10,39,1,1,139.090000000,139.330000000,57,503,1,2,139.070000000,139.360000000,100,4,1,2,139.030000000,139.370000000,126,75,2,1,NVDA
2025-01-03T10:32:50.247635455Z,2025-01-03T10:32:50.247468839Z,10,2,11667,A,A,5,139.300000000,400,130,166616,4933581,139.170000000,139.200000000,100,2,1,1,139.160000000,139.220000000,500,10,2,1,139.150000000,139.230000000,9860,2277,2,4,139.130000000,139.250000000,2100,1,1,1,139.120000000,139.270000000,30,37,1,2,139.110000000,139.300000000,1,907,1,5,139.100000000,139.320000000,10,39,1,1,139.090000000,139.330000000,57,503,1,2,139.070000000,139.360000000,100,4,1,2,139.030000000,139.370000000,126,75,2,1,NVDA
2025-01-03T10:32:50.247699549Z,2025-01-03T10:32:50.247533750Z,10,2,11667,C,B,1,139.160000000,400,130,165799,4933582,139.170000000,139.200000000,100,2,1,1,139.160000000,139.220000000,100,10,1,1,139.150000000,139.230000000,9860,2277,2,4,139.130000000,139.250000000,2100,1,1,1,139.120000000,139.270000000,30,37,1,2,139.110000000,139.300000000,1,907,1,5,139.100000000,139.320000000,10,39,1,1,139.090000000,139.330000000,57,503,1,2,139.070000000,139.360000000,100,4,1,2,139.030000000,139.370000000,126,75,2,1,NVDA
2025-01-03T10:32:50.247711833Z,2025-01-03T10:32:50.247545684Z,10,2,11667,A,B,2,139.150000000,400,130,166149,4933583,139.170000000,139.200000000,100,2,1,1,139.160000000,139.220000000,100,10,1,1,139.150000000,139.230000000,10260,2277,3,4,139.130000000,139.250000000,2100,1,1,1,139.120000000,139.270000000,30,37,1,2,139.110000000,139.300000000,1,907,1,5,139.100000000,139.320000000,10,39,1,1,139.090000000,139.330000000,57,503,1,2,139.070000000,139.360000000,100,4,1,2,139.030000000,139.370000000,126,75,2,1,NVDA
