ts_recv,ts_event,rtype,publisher_id,instrument_id,action,side,depth,price,size,flags,ts_in_delta,sequence,bid_px_00,ask_px_00,bid_sz_00,ask_sz_00,bid_ct_00,ask_ct_00,bid_px_01,ask_px_01,bid_sz_01,ask_sz_01,bid_ct_01,ask_ct_01,bid_px_02,ask_px_02,bid_sz_02,ask_sz_02,bid_ct_02,ask_ct_02,bid_px_03,ask_px_03,bid_sz_03,ask_sz_03,bid_ct_03,ask_ct_03,bid_px_04,ask_px_04,bid_sz_04,ask_sz_04,bid_ct_04,ask_ct_04,bid_px_05,ask_px_05,bid_sz_05,ask_sz_05,bid_ct_05,ask_ct_05,bid_px_06,ask_px_06,bid_sz_06,ask_sz_06,bid_ct_06,ask_ct_06,bid_px_07,ask_px_07,bid_sz_07,ask_sz_07,bid_ct_07,ask_ct_07,bid_px_08,ask_px_08,bid_sz_08,ask_sz_08,bid_ct_08,ask_ct_08,bid_px_09,ask_px_09,bid_sz_09,ask_sz_09,bid_ct_09,ask_ct_09,symbol
2025-01-03T10:30:35.496614004Z,2025-01-03T10:30:35.496448107Z,10,2,16244,C,B,1,382.800000000,23,130,165897,4846926,382.810000000,383.090000000,10,6,1,1,382.700000000,383.100000000,50,11,1,1,382.680000000,383.300000000,20,20,1,1,382.400000000,383.420000000,500,140,1,1,382.230000000,383.600000000,25,1000,1,2,382.110000000,383.720000000,300,7085,1,8,382.100000000,383.740000000,20,37,2,1,382.010000000,383.800000000,2,10,1,1,382.000000000,383.880000000,692,4,9,1,381.900000000,384.000000000,23,1300,1,4,TSLA
2025-01-03T10:30:35.496677350Z,2025-01-03T10:30:35.496511328Z,10,2,16244,A,B,0,382.850000000,23,130,166022,4846927,382.850000000,383.090000000,23,6,1,1,382.810000000,383.100000000,10,11,1,1,382.700000000,383.300000000,50,20,1,1,382.680000000,383.420000000,20,140,1,1,382.400000000,383.600000000,500,1000,1,2,382.230000000,383.720000000,25,7085,1,8,382.110000000,383.740000000,300,37,1,1,382.100000000,383.800000000,20,10,2,1,382.010000000,383.880000000,2,4,1,1,382.000000000,384.000000000,692,1300,9,4,TSLA
2025-01-03T10:30:36.798869180Z,2025-01-03T10:30:36.798702725Z,10,2,9155,A,B,2,241.780000000,8,130,166455,4847386,242.020000000,242.070000000,92,62,1,1,242.000000000,242.400000000,200,485,1,1,241.780000000,242.490000000,8,8,1,1,241.670000000,242.850000000,2,300,1,2,241.000000000,242.900000000,100,100,1,1,240.980000000,243.000000000,82,92,1,2,240.000000000,243.310000000,10,10,1,1,238.000000000,243.700000000,30,100,1,1,236.000000000,246.810000000,6,100,1,1,235.500000000,262.740000000,5,100,1,1,JPM
2025-01-03T10:30:37.731518615Z,2025-01-03T10:30:37.731351119Z,10,2,38,T,N,0,243.550000000,1,130,167496,4847646,243.500000000,243.650000000,6,61,1,2,243.450000000,243.670000000,400,200,1,1,243.370000000,243.730000000,27,26,1,1,243.190000000,244.000000000,2,1,1,1,243.020000000,244.140000000,79,79,1,1,243.000000000,244.200000000,1243,1000,9,1,242.990000000,244.400000000,1,50,1,1,242.750000000,244.420000000,30,10,1,1,242.590000000,244.580000000,5,100,1,1,242.280000000,245.000000000,100,79,1,2,AAPL
2025-01-03T10:30:37.952487985Z,2025-01-03T10:30:37.952321610Z,10,2,16244,A,A,3,383.340000000,23,130,166375,4847711,382.850000000,383.090000000,23,6,1,1,382.810000000,383.100000000,10,11,1,1,382.700000000,383.300000000,50,20,1,1,382.680000000,383.340000000,20,23,1,1,382.400000000,383.420000000,500,140,1,1,382.230000000,383.600000000,25,1000,1,2,382.110000000,383.720000000,300,7085,1,8,382.100000000,383.740000000,20,37,2,1,382.010000000,383.800000000,2,10,1,1,382.000000000,383.880000000,692,4,9,1,TSLA
2025-01-03T10:30:38.605577003Z,2025-01-03T10:30:38.605411080Z,10,2,11667,C,B,5,139.100000000,400,130,165923,4848135,139.150000000,139.160000000,50,300,1,1,139.140000000,139.200000000,30,429,1,2,139.130000000,139.210000000,100,400,1,1,139.120000000,139.220000000,30,10,1,1,139.110000000,139.230000000,1,25,1,1,139.080000000,139.250000000,57,1,1,1,139.030000000,139.270000000,126,17,2,1,139.010000000,139.300000000,100,507,1,4,139.000000000,139.320000000,420,39,5,1,138.980000000,139.330000000,300,503,1,2,NVDA
2025-01-03T10:30:38.605588366Z,2025-01-03T10:30:38.605422426Z,10,2,11667,A,B,5,139.080000000,400,130,165940,4848136,139.150000000,139.160000000,50,300,1,1,139.140000000,139.200000000,30,429,1,2,139.130000000,139.210000000,100,400,1,1,139.120000000,139.220000000,30,10,1,1,139.110000000,139.230000000,1,25,1,1,139.080000000,139.250000000,457,1,2,1,139.030000000,139.270000000,126,17,2,1,139.010000000,139.300000000,100,507,1,4,139.000000000,139.320000000,420,39,5,1,138.980000000,139.330000000,300,503,1,2,NVDA
2025-01-03T10:30:38.605693607Z,2025-01-03T10:30:38.605527722Z,10,2,38,C,B,1,243.450000000,400,130,165885,4848139,243.500000000,243.650000000,6,61,1,2,243.370000000,243.670000000,27,200,1,1,243.190000000,243.730000000,2,26,1,1,243.020000000,244.000000000,79,1,1,1,243.000000000,244.140000000,1243,79,9,1,242.990000000,244.200000000,1,1000,1,1,242.750000000,244.400000000,30,50,1,1,242.590000000,244.420000000,5,10,1,1,242.280000000,244.580000000,100,100,1,1,242.170000000,245.000000000,100,79,1,2,AAPL
2025-01-03T10:30:38.605706180Z,2025-01-03T10:30:38.605540078Z,10,2,38,A,B,1,243.420000000,400,130,166102,4848140,243.500000000,243.650000000,6,61,1,2,243.420000000,243.670000000,400,200,1,1,243.370000000,243.730000000,27,26,1,1,243.190000000,244.000000000,2,1,1,1,243.020000000,244.140000000,79,79,1,1,243.000000000,244.200000000,1243,1000,9,1,242.990000000,244.400000000,1,50,1,1,242.750000000,244.420000000,30,10,1,1,242.590000000,244.580000000,5,100,1,1,242.280000000,245.000000000,100,79,1,2,AAPL
2025-01-03T10:30:38.657020890Z,2025-01-03T10:30:38.656854510Z,10,2,11667,A,A,1,139.200000000,400,130,166380,4848352,139.150000000,139.160000000,50,300,1,1,139.140000000,139.200000000,30,829,1,3,139.130000000,139.220000000,100,10,1,1,139.120000000,139.230000000,30,25,1,1,139.110000000,139.250000000,1,1,1,1,139.080000000,139.270000000,457,17,2,1,139.030000000,139.300000000,126,507,2,4,139.010000000,139.320000000,100,39,1,1,139.000000000,139.330000000,420,503,5,2,138.980000000,139.360000000,300,4,1,2,NVDA
2025-01-03T10:30:38.661844769Z,2025-01-03T10:30:38.661678667Z,10,2,10888,A,A,1,421.270000000,13,130,166102,4848396,420.710000000,421.190000000,200,200,1,1,420.630000000,421.270000000,13,13,1,1,420.580000000,421.280000000,10,15,1,1,420.520000000,421.460000000,1,39,1,1,420.400000000,421.490000000,858,6,1,1,420.380000000,421.570000000,100,40,1,1,420.100000000,421.600000000,100,10,1,1,420.000000000,421.700000000,534,359,7,1,419.730000000,422.100000000,3,7,1,1,419.650000000,422.400000000,39,500,1,1,MSFT
2025-01-03T10:30:38.661853950Z,2025-01-03T10:30:38.661687866Z,10,2,10888,A,A,0,421.180000000,200,130,166084,4848398,420.710000000,421.180000000,200,200,1,1,420.630000000,421.270000000,13,13,1,1,420.580000000,421.280000000,10,15,1,1,420.520000000,421.460000000,1,39,1,1,420.400000000,421.490000000,858,6,1,1,420.380000000,421.570000000,100,40,1,1,420.100000000,421.600000000,100,10,1,1,420.000000000,421.700000000,534,359,7,1,419.730000000,422.100000000,3,7,1,1,419.650000000,422.400000000,39,500,1,1,MSFT
2025-01-03T10:30:38.661955906Z,2025-01-03T10:30:38.661790031Z,10,2,10888,C,A,2,421.280000000,15,130,165875,4848399,420.710000000,421.180000000,200,200,1,1,420.630000000,421.270000000,13,13,1,1,420.580000000,421.460000000,10,39,1,1,420.520000000,421.490000000,1,6,1,1,420.400000000,421.570000000,858,40,1,1,420.380000000,421.600000000,100,10,1,1,420.100000000,421.700000000,100,359,1,1,420.000000000,422.100000000,534,7,7,1,419.730000000,422.400000000,3,500,1,1,419.650000000,422.500000000,39,200,1,1,MSFT
2025-01-03T10:30:38.666067084Z,2025-01-03T10:30:38.665901058Z,10,2,16727,C,A,0,315.430000000,8,130,166026,4848445,314.900000000,315.510000000,8,25,1,1,314.860000000,315.750000000,25,61,1,1,314.420000000,320.000000000,61,5,1,1,313.500000000,320.210000000,1,1,1,1,310.000000000,321.950000000,1,2,1,1,300.000000000,344.200000000,3,100,1,1,290.000000000,345.620000000,2,100,1,1,286.660000000,,100,0,1,0,285.250000000,,100,0,1,0,260.000000000,,2,0,1,0,V
2025-01-03T10:30:38.666127957Z,2025-01-03T10:30:38.665961687Z,10,2,16727,A,A,0,315.420000000,8,130,166270,4848446,314.900000000,315.420000000,8,8,1,1,314.860000000,315.510000000,25,25,1,1,314.420000000,315.750000000,61,61,1,1,313.500000000,320.000000000,1,5,1,1,310.000000000,320.210000000,1,1,1,1,300.000000000,321.950000000,3,2,1,1,290.000000000,344.200000000,2,100,1,1,286.660000000,345.620000000,100,100,1,1,285.250000000,,100,0,1,0,260.000000000,,2,0,1,0,V
2025-01-03T10:30:38.666832174Z,2025-01-03T10:30:38.666666267Z,10,2,9155,C,A,2,242.490000000,8,130,165907,4848453,242.020000000,242.070000000,92,62,1,1,242.000000000,242.400000000,200,485,1,1,241.780000000,242.850000000,8,300,1,2,241.670000000,242.900000000,2,100,1,1,241.000000000,243.000000000,100,92,1,2,240.980000000,243.310000000,82,10,1,1,240.000000000,243.700000000,10,100,1,1,238.000000000,246.810000000,30,100,1,1,236.000000000,262.740000000,6,100,1,1,235.500000000,263.830000000,5,100,1,1,JPM
2025-01-03T10:30:38.666893915Z,2025-01-03T10:30:38.666727610Z,10,2,9155,A,A,2,242.480000000,8,130,166305,4848454,242.020000000,242.070000000,92,62,1,1,242.000000000,242.400000000,200,485,1,1,241.780000000,242.480000000,8,8,1,1,241.670000000,242.850000000,2,300,1,2,241.000000000,242.900000000,100,100,1,1,240.980000000,243.000000000,82,92,1,2,240.000000000,243.310000000,10,10,1,1,238.000000000,243.700000000,30,100,1,1,236.000000000,246.810000000,6,100,1,1,235.500000000,262.740000000,5,100,1,1,JPM
2025-01-03T10:30:38.667147742Z,2025-01-03T10:30:38.666981723Z,10,2,12463,C,A,0,150.800000000,9,130,166019,4848456,150.460000000,150.840000000,1,100,1,1,150.300000000,151.000000000,9,1,1,1,150.260000000,153.280000000,234,10,1,1,150.250000000,163.540000000,1,100,1,1,150.210000000,164.210000000,113,100,2,1,150.020000000,179.000000000,2,5,1,1,150.000000000,,250,0,1,0,149.950000000,,5,0,1,0,149.740000000,,10,0,1,0,149.000000000,,5,0,1,0,PEP
2025-01-03T10:30:38.667214389Z,2025-01-03T10:30:38.667048139Z,10,2,12463,A,A,0,150.790000000,9,130,166250,4848457,150.460000000,150.790000000,1,9,1,1,150.300000000,150.840000000,9,100,1,1,150.260000000,151.000000000,234,1,1,1,150.250000000,153.280000000,1,10,1,1,150.210000000,163.540000000,113,100,2,1,150.020000000,164.210000000,2,100,1,1,150.000000000,179.000000000,250,5,1,1,149.950000000,,5,0,1,0,149.740000000,,10,0,1,0,149.000000000,,5,0,1,0,PEP
2025-01-03T10:30:38.670544370Z,2025-01-03T10:30:38.670378491Z,10,2,38,C,A,2,243.730000000,26,130,165879,4848494,243.500000000,243.650000000,6,61,1,2,243.420000000,243.670000000,400,200,1,1,243.370000000,244.000000000,27,1,1,1,243.190000000,244.140000000,2,79,1,1,243.020000000,244.200000000,79,1000,1,1,243.000000000,244.400000000,1243,50,9,1,242.990000000,244.420000000,1,10,1,1,242.750000000,244.580000000,30,100,1,1,242.590000000,245.000000000,5,79,1,2,242.280000000,245.190000000,100,83,1,1,AAPL
2025-01-03T10:30:38.670608784Z,2025-01-03T10:30:38.670442633Z,10,2,38,A,A,2,243.720000000,29,130,166151,4848495,243.500000000,243.650000000,6,61,1,2,243.420000000,243.670000000,400,200,1,1,243.370000000,243.720000000,27,29,1,1,243.190000000,244.000000000,2,1,1,1,243.020000000,244.140000000,79,79,1,1,243.000000000,244.200000000,1243,1000,9,1,242.990000000,244.400000000,1,50,1,1,242.750000000,244.420000000,30,10,1,1,242.590000000,244.580000000,5,100,1,1,242.280000000,245.000000000,100,79,1,2,AAPL
2025-01-03T10:30:38.678875204Z,2025-01-03T10:30:38.678709273Z,10,2,6905,C,B,0,91.520000000,7,130,165931,4848542,91.480000000,91.920000000,150,7,1,1,91.440000000,91.960000000,100,100,1,1,90.000000000,93.000000000,122,1,1,1,89.000000000,94.000000000,1,1,1,1,83.810000000,95.000000000,100,2,1,2,83.400000000,96.000000000,100,1,1,1,,97.000000000,0,2,0,2,,99.950000000,0,100,0,1,,100.360000000,0,100,0,1,,,0,0,0,0,GILD
2025-01-03T10:30:38.678967307Z,2025-01-03T10:30:38.678800080Z,10,2,6905,A,B,0,91.510000000,7,130,167227,4848543,91.510000000,91.920000000,7,7,1,1,91.480000000,91.960000000,150,100,1,1,91.440000000,93.000000000,100,1,1,1,90.000000000,94.000000000,122,1,1,1,89.000000000,95.000000000,1,2,1,2,83.810000000,96.000000000,100,1,1,1,83.400000000,97.000000000,100,2,1,2,,99.950000000,0,100,0,1,,100.360000000,0,100,0,1,,,0,0,0,0,GILD
2025-01-03T10:30:38.694737347Z,2025-01-03T10:30:38.694570788Z,10,2,11667,A,B,5,139.090000000,400,130,166559,4848573,139.150000000,139.160000000,50,300,1,1,139.140000000,139.200000000,30,829,1,3,139.130000000,139.220000000,100,10,1,1,139.120000000,139.230000000,30,25,1,1,139.110000000,139.250000000,1,1,1,1,139.090000000,139.270000000,400,17,1,1,139.080000000,139.300000000,57,507,1,4,139.030000000,139.320000000,126,39,2,1,139.010000000,139.330000000,100,503,1,2,139.000000000,139.360000000,420,4,5,2,NVDA
2025-01-03T10:30:38.698435227Z,2025-01-03T10:30:38.698268426Z,10,2,38,A,B,1,243.430000000,400,130,166801,4848580,243.500000000,243.650000000,6,61,1,2,243.430000000,243.670000000,400,200,1,1,243.370000000,243.720000000,27,29,1,1,243.190000000,244.000000000,2,1,1,1,243.020000000,244.140000000,79,79,1,1,243.000000000,244.200000000,1243,1000,9,1,242.990000000,244.400000000,1,50,1,1,242.750000000,244.420000000,30,10,1,1,242.590000000,244.580000000,5,100,1,1,242.280000000,245.000000000,100,79,1,2,AAPL
2025-01-03T10:30:38.896041577Z,2025-01-03T10:30:38.895874878Z,10,2,38,A,B,1,243.440000000,400,130,166699,4848855,243.500000000,243.650000000,6,61,1,2,243.440000000,243.670000000,400,200,1,1,243.370000000,243.720000000,27,29,1,1,243.190000000,244.000000000,2,1,1,1,243.020000000,244.140000000,79,79,1,1,243.000000000,244.200000000,1243,1000,9,1,242.990000000,244.400000000,1,50,1,1,242.750000000,244.420000000,30,10,1,1,242.590000000,244.580000000,5,100,1,1,242.280000000,245.000000000,100,79,1,2,AAPL
2025-01-03T10:30:39.069283600Z,2025-01-03T10:30:39.069117142Z,10,2,16244,A,A,0,383.020000000,3,130,166458,4849018,382.850000000,383.020000000,23,3,1,1,382.810000000,383.090000000,10,6,1,1,382.700000000,383.100000000,50,11,1,1,382.680000000,383.300000000,20,20,1,1,382.400000000,383.340000000,500,23,1,1,382.230000000,383.420000000,25,140,1,1,382.110000000,383.600000000,300,1000,1,2,382.100000000,383.720000000,20,7085,2,8,382.010000000,383.740000000,2,37,1,1,382.000000000,383.800000000,692,10,9,1,TSLA
2025-01-03T10:30:39.079298114Z,2025-01-03T10:30:39.079132306Z,10,2,16244,C,A,0,383.020000000,3,130,165808,4849036,382.850000000,383.090000000,23,6,1,1,382.810000000,383.100000000,10,11,1,1,382.700000000,383.300000000,50,20,1,1,382.680000000,383.340000000,20,23,1,1,382.400000000,383.420000000,500,140,1,1,382.230000000,383.600000000,25,1000,1,2,382.110000000,383.720000000,300,7085,1,8,382.100000000,383.740000000,20,37,2,1,382.010000000,383.800000000,2,10,1,1,382.000000000,383.880000000,692,4,9,1,TSLA
2025-01-03T10:30:39.353066572Z,2025-01-03T10:30:39.352900168Z,10,2,9155,C,A,1,242.400000000,485,130,166404,4849183,242.020000000,242.070000000,92,62,1,1,242.000000000,242.480000000,200,8,1,1,241.780000000,242.850000000,8,300,1,2,241.670000000,242.900000000,2,100,1,1,241.000000000,243.000000000,100,92,1,2,240.980000000,243.310000000,82,10,1,1,240.000000000,243.700000000,10,100,1,1,238.000000000,246.810000000,30,100,1,1,236.000000000,262.740000000,6,100,1,1,235.500000000,263.830000000,5,100,1,1,JPM
2025-01-03T10:30:40.831719054Z,2025-01-03T10:30:40.831552636Z,10,2,10888,C,B,1,420.630000000,13,130,166418,4850078,420.710000000,421.180000000,200,200,1,1,420.580000000,421.270000000,10,13,1,1,420.520000000,421.460000000,1,39,1,1,420.400000000,421.490000000,858,6,1,1,420.380000000,421.570000000,100,40,1,1,420.100000000,421.600000000,100,10,1,1,420.000000000,421.700000000,534,359,7,1,419.730000000,422.100000000,3,7,1,1,419.650000000,422.400000000,39,500,1,1,418.650000000,422.500000000,1,200,1,1,MSFT
2025-01-03T10:30:40.831798017Z,2025-01-03T10:30:40.831631920Z,10,2,10888,A,B,1,420.640000000,13,130,166097,4850079,420.710000000,421.180000000,200,200,1,1,420.640000000,421.270000000,13,13,1,1,420.580000000,421.460000000,10,39,1,1,420.520000000,421.490000000,1,6,1,1,420.400000000,421.570000000,858,40,1,1,420.380000000,421.600000000,100,10,1,1,420.100000000,421.700000000,100,359,1,1,420.000000000,422.100000000,534,7,7,1,419.730000000,422.400000000,3,500,1,1,419.650000000,422.500000000,39,200,1,1,MSFT
2025-01-03T10:30:40.842028518Z,2025-01-03T10:30:40.841862686Z,10,2,10888,C,A,0,421.180000000,200,130,165832,4850131,420.710000000,421.270000000,200,13,1,1,420.640000000,421.460000000,13,39,1,1,420.580000000,421.490000000,10,6,1,1,420.520000000,421.570000000,1,40,1,1,420.400000000,421.600000000,858,10,1,1,420.380000000,421.700000000,100,359,1,1,420.100000000,422.100000000,100,7,1,1,420.000000000,422.400000000,534,500,7,1,419.730000000,422.500000000,3,200,1,1,419.650000000,423.500000000,39,600,1,2,MSFT
2025-01-03T10:30:40.842040558Z,2025-01-03T10:30:40.841874605Z,10,2,10888,A,A,0,421.210000000,200,130,165953,4850132,420.710000000,421.210000000,200,200,1,1,420.640000000,421.270000000,13,13,1,1,420.580000000,421.460000000,10,39,1,1,420.520000000,421.490000000,1,6,1,1,420.400000000,421.570000000,858,40,1,1,420.380000000,421.600000000,100,10,1,1,420.100000000,421.700000000,100,359,1,1,420.000000000,422.100000000,534,7,7,1,419.730000000,422.400000000,3,500,1,1,419.650000000,422.500000000,39,200,1,1,MSFT
2025-01-03T10:30:40.842097949Z,2025-01-03T10:30:40.841930385Z,10,2,11667,C,A,1,139.200000000,400,130,167564,4850133,139.150000000,139.160000000,50,300,1,1,139.140000000,139.200000000,30,429,1,2,139.130000000,139.220000000,100,10,1,1,139.120000000,139.230000000,30,25,1,1,139.110000000,139.250000000,1,1,1,1,139.090000000,139.270000000,400,17,1,1,139.080000000,139.300000000,57,507,1,4,139.030000000,139.320000000,126,39,2,1,139.010000000,139.330000000,100,503,1,2,139.000000000,139.360000000,420,4,5,2,NVDA
2025-01-03T10:30:40.842108561Z,2025-01-03T10:30:40.841942284Z,10,2,11667,A,A,2,139.210000000,400,130,166277,4850134,139.150000000,139.160000000,50,300,1,1,139.140000000,139.200000000,30,429,1,2,139.130000000,139.210000000,100,400,1,1,139.120000000,139.220000000,30,10,1,1,139.110000000,139.230000000,1,25,1,1,139.090000000,139.250000000,400,1,1,1,139.080000000,139.270000000,57,17,1,1,139.030000000,139.300000000,126,507,2,4,139.010000000,139.320000000,100,39,1,1,139.000000000,139.330000000,420,503,5,2,NVDA
2025-01-03T10:30:40.842172558Z,2025-01-03T10:30:40.842006646Z,10,2,38,C,A,1,243.670000000,200,130,165912,4850137,243.500000000,243.650000000,6,61,1,2,243.440000000,243.720000000,400,29,1,1,243.370000000,244.000000000,27,1,1,1,243.190000000,244.140000000,2,79,1,1,243.020000000,244.200000000,79,1000,1,1,243.000000000,244.400000000,1243,50,9,1,242.990000000,244.420000000,1,10,1,1,242.750000000,244.580000000,30,100,1,1,242.590000000,245.000000000,5,79,1,2,242.280000000,245.190000000,100,83,1,1,AAPL
2025-01-03T10:30:40.842184359Z,2025-01-03T10:30:40.842018338Z,10,2,38,A,A,1,243.700000000,200,130,166021,4850140,243.500000000,243.650000000,6,61,1,2,243.440000000,243.700000000,400,200,1,1,243.370000000,243.720000000,27,29,1,1,243.190000000,244.000000000,2,1,1,1,243.020000000,244.140000000,79,79,1,1,243.000000000,244.200000000,1243,1000,9,1,242.990000000,244.400000000,1,50,1,1,242.750000000,244.420000000,30,10,1,1,242.590000000,244.580000000,5,100,1,1,242.280000000,245.000000000,100,79,1,2,AAPL
2025-01-03T10:30:40.877370959Z,2025-01-03T10:30:40.877205079Z,10,2,16244,C,B,0,382.850000000,23,130,165880,4850214,382.810000000,383.090000000,10,6,1,1,382.700000000,383.100000000,50,11,1,1,382.680000000,383.300000000,20,20,1,1,382.400000000,383.340000000,500,23,1,1,382.230000000,383.420000000,25,140,1,1,382.110000000,383.600000000,300,1000,1,2,382.100000000,383.720000000,20,7085,2,8,382.010000000,383.740000000,2,37,1,1,382.000000000,383.800000000,692,10,9,1,381.900000000,383.880000000,23,4,1,1,TSLA
2025-01-03T10:30:40.877475936Z,2025-01-03T10:30:40.877309370Z,10,2,16244,A,B,0,382.860000000,19,130,166566,4850215,382.860000000,383.090000000,19,6,1,1,382.810000000,383.100000000,10,11,1,1,382.700000000,383.300000000,50,20,1,1,382.680000000,383.340000000,20,23,1,1,382.400000000,383.420000000,500,140,1,1,382.230000000,383.600000000,25,1000,1,2,382.110000000,383.720000000,300,7085,1,8,382.100000000,383.740000000,20,37,2,1,382.010000000,383.800000000,2,10,1,1,382.000000000,383.880000000,692,4,9,1,TSLA
2025-01-03T10:30:40.888029102Z,2025-01-03T10:30:40.887863076Z,10,2,9155,C,B,5,240.980000000,82,130,166026,4850249,242.020000000,242.070000000,92,62,1,1,242.000000000,242.480000000,200,8,1,1,241.780000000,242.850000000,8,300,1,2,241.670000000,242.900000000,2,100,1,1,241.000000000,243.000000000,100,92,1,2,240.000000000,243.310000000,10,10,1,1,238.000000000,243.700000000,30,100,1,1,236.000000000,246.810000000,6,100,1,1,235.500000000,262.740000000,5,100,1,1,235.000000000,263.830000000,5,100,1,1,JPM
2025-01-03T10:30:40.896941584Z,2025-01-03T10:30:40.896775278Z,10,2,38,A,B,1,243.450000000,400,130,166306,4850301,243.500000000,243.650000000,6,61,1,2,243.450000000,243.700000000,400,200,1,1,243.370000000,243.720000000,27,29,1,1,243.190000000,244.000000000,2,1,1,1,243.020000000,244.140000000,79,79,1,1,243.000000000,244.200000000,1243,1000,9,1,242.990000000,244.400000000,1,50,1,1,242.750000000,244.420000000,30,10,1,1,242.590000000,244.580000000,5,100,1,1,242.280000000,245.000000000,100,79,1,2,AAPL
2025-01-03T10:30:40.899634346Z,2025-01-03T10:30:40.899467748Z,10,2,11667,A,B,5,139.100000000,400,130,166598,4850313,139.150000000,139.160000000,50,300,1,1,139.140000000,139.200000000,30,429,1,2,139.130000000,139.210000000,100,400,1,1,139.120000000,139.220000000,30,10,1,1,139.110000000,139.230000000,1,25,1,1,139.100000000,139.250000000,400,1,1,1,139.080000000,139.270000000,57,17,1,1,139.030000000,139.300000000,126,507,2,4,139.010000000,139.320000000,100,39,1,1,139.000000000,139.330000000,420,503,5,2,NVDA
2025-01-03T10:30:40.905094407Z,2025-01-03T10:30:40.904928376Z,10,2,17709,C,B,1,107.550000000,15,130,166031,4850355,107.600000000,107.840000000,50,400,1,2,107.520000000,107.850000000,100,16,1,1,107.050000000,107.870000000,247,242,1,1,107.000000000,107.940000000,1,100,1,1,106.240000000,107.950000000,28,10,1,1,106.000000000,108.000000000,15,50,2,1,105.870000000,108.300000000,141,50,1,1,103.180000000,108.550000000,16,50,1,1,103.000000000,108.800000000,3,50,1,1,102.000000000,108.880000000,2,28,1,1,XOM
2025-01-03T10:30:40.905152279Z,2025-01-03T10:30:40.904986184Z,10,2,17709,A,B,1,107.560000000,16,130,166095,4850356,107.600000000,107.840000000,50,400,1,2,107.560000000,107.850000000,16,16,1,1,107.520000000,107.870000000,100,242,1,1,107.050000000,107.940000000,247,100,1,1,107.000000000,107.950000000,1,10,1,1,106.240000000,108.000000000,28,50,1,1,106.000000000,108.300000000,15,50,2,1,105.870000000,108.550000000,141,50,1,1,103.180000000,108.800000000,16,50,1,1,103.000000000,108.880000000,3,28,1,1,XOM
2025-01-03T10:30:40.906208031Z,2025-01-03T10:30:40.906041854Z,10,2,38,C,B,2,243.370000000,27,130,166177,4850362,243.500000000,243.650000000,6,61,1,2,243.450000000,243.700000000,400,200,1,1,243.190000000,243.720000000,2,29,1,1,243.020000000,244.000000000,79,1,1,1,243.000000000,244.140000000,1243,79,9,1,242.990000000,244.200000000,1,1000,1,1,242.750000000,244.400000000,30,50,1,1,242.590000000,244.420000000,5,10,1,1,242.280000000,244.580000000,100,100,1,1,242.170000000,245.000000000,100,79,1,2,AAPL
2025-01-03T10:30:40.906876285Z,2025-01-03T10:30:40.906709977Z,10,2,38,A,B,2,243.380000000,28,130,166308,4850369,243.500000000,243.650000000,6,61,1,2,243.450000000,243.700000000,400,200,1,1,243.380000000,243.720000000,28,29,1,1,243.190000000,244.000000000,2,1,1,1,243.020000000,244.140000000,79,79,1,1,243.000000000,244.200000000,1243,1000,9,1,242.990000000,244.400000000,1,50,1,1,242.750000000,244.420000000,30,10,1,1,242.590000000,244.580000000,5,100,1,1,242.280000000,245.000000000,100,79,1,2,AAPL
2025-01-03T10:30:40.922802569Z,2025-01-03T10:30:40.922636502Z,10,2,6905,C,B,0,91.510000000,7,130,166067,4850412,91.480000000,91.920000000,150,7,1,1,91.440000000,91.960000000,100,100,1,1,90.000000000,93.000000000,122,1,1,1,89.000000000,94.000000000,1,1,1,1,83.810000000,95.000000000,100,2,1,2,83.400000000,96.000000000,100,1,1,1,,97.000000000,0,2,0,2,,99.950000000,0,100,0,1,,100.360000000,0,100,0,1,,,0,0,0,0,GILD
2025-01-03T10:30:40.922863197Z,2025-01-03T10:30:40.922696949Z,10,2,6905,A,B,0,91.520000000,7,130,166248,4850413,91.520000000,91.920000000,7,7,1,1,91.480000000,91.960000000,150,100,1,1,91.440000000,93.000000000,100,1,1,1,90.000000000,94.000000000,122,1,1,1,89.000000000,95.000000000,1,2,1,2,83.810000000,96.000000000,100,1,1,1,83.400000000,97.000000000,100,2,1,2,,99.950000000,0,100,0,1,,100.360000000,0,100,0,1,,,0,0,0,0,GILD
2025-01-03T10:30:40.924924628Z,2025-01-03T10:30:40.924758431Z,10,2,16727,C,B,0,314.900000000,8,130,166197,4850431,314.860000000,315.420000000,25,8,1,1,314.420000000,315.510000000,61,25,1,1,313.500000000,315.750000000,1,61,1,1,310.000000000,320.000000000,1,5,1,1,300.000000000,320.210000000,3,1,1,1,290.000000000,321.950000000,2,2,1,1,286.660000000,344.200000000,100,100,1,1,285.250000000,345.620000000,100,100,1,1,260.000000000,,2,0,1,0,,,0,0,0,0,V
2025-01-03T10:30:40.925033522Z,2025-01-03T10:30:40.924867237Z,10,2,16727,A,B,0,314.910000000,8,130,166285,4850432,314.910000000,315.420000000,8,8,1,1,314.860000000,315.510000000,25,25,1,1,314.420000000,315.750000000,61,61,1,1,313.500000000,320.000000000,1,5,1,1,310.000000000,320.210000000,1,1,1,1,300.000000000,321.950000000,3,2,1,1,290.000000000,344.200000000,2,100,1,1,286.660000000,345.620000000,100,100,1,1,285.250000000,,100,0,1,0,260.000000000,,2,0,1,0,V
2025-01-03T10:30:40.925109984Z,2025-01-03T10:30:40.924943834Z,10,2,9155,C,A,1,242.480000000,8,130,166150,4850433,242.020000000,242.070000000,92,62,1,1,242.000000000,242.850000000,200,300,1,2,241.780000000,242.900000000,8,100,1,1,241.670000000,243.000000000,2,92,1,2,241.000000000,243.310000000,100,10,1,1,240.000000000,243.700000000,10,100,1,1,238.000000000,246.810000000,30,100,1,1,236.000000000,262.740000000,6,100,1,1,235.500000000,263.830000000,5,100,1,1,235.000000000,,5,0,1,0,JPM
2025-01-03T10:30:40.925192831Z,2025-01-03T10:30:40.925026349Z,10,2,9155,A,A,1,242.510000000,8,130,166482,4850434,242.020000000,242.070000000,92,62,1,1,242.000000000,242.510000000,200,8,1,1,241.780000000,242.850000000,8,300,1,2,241.670000000,242.900000000,2,100,1,1,241.000000000,243.000000000,100,92,1,2,240.000000000,243.310000000,10,10,1,1,238.000000000,243.700000000,30,100,1,1,236.000000000,246.810000000,6,100,1,1,235.500000000,262.740000000,5,100,1,1,235.000000000,263.830000000,5,100,1,1,JPM
2025-01-03T10:30:40.927133532Z,2025-01-03T10:30:40.926966635Z,10,2,38,C,A,2,243.720000000,29,130,166897,4850459,243.500000000,243.650000000,6,61,1,2,243.450000000,243.700000000,400,200,1,1,243.380000000,244.000000000,28,1,1,1,243.190000000,244.140000000,2,79,1,1,243.020000000,244.200000000,79,1000,1,1,243.000000000,244.400000000,1243,50,9,1,242.990000000,244.420000000,1,10,1,1,242.750000000,244.580000000,30,100,1,1,242.590000000,245.000000000,5,79,1,2,242.280000000,245.190000000,100,83,1,1,AAPL
2025-01-03T10:30:40.927156490Z,2025-01-03T10:30:40.926990133Z,10,2,38,A,A,2,243.740000000,28,130,166357,4850460,243.500000000,243.650000000,6,61,1,2,243.450000000,243.700000000,400,200,1,1,243.380000000,243.740000000,28,28,1,1,243.190000000,244.000000000,2,1,1,1,243.020000000,244.140000000,79,79,1,1,243.000000000,244.200000000,1243,1000,9,1,242.990000000,244.400000000,1,50,1,1,242.750000000,244.420000000,30,10,1,1,242.590000000,244.580000000,5,100,1,1,242.280000000,245.000000000,100,79,1,2,AAPL
2025-01-03T10:30:40.946659401Z,2025-01-03T10:30:40.946492556Z,10,2,11667,A,A,1,139.200000000,400,130,166845,4850468,139.150000000,139.160000000,50,300,1,1,139.140000000,139.200000000,30,829,1,3,139.130000000,139.220000000,100,10,1,1,139.120000000,139.230000000,30,25,1,1,139.110000000,139.250000000,1,1,1,1,139.100000000,139.270000000,400,17,1,1,139.080000000,139.300000000,57,507,1,4,139.030000000,139.320000000,126,39,2,1,139.010000000,139.330000000,100,503,1,2,139.000000000,139.360000000,420,4,5,2,NVDA
2025-01-03T10:30:40.970070142Z,2025-01-03T10:30:40.969903791Z,10,2,38,A,A,1,243.680000000,200,130,166351,4850518,243.500000000,243.650000000,6,61,1,2,243.450000000,243.680000000,400,200,1,1,243.380000000,243.740000000,28,28,1,1,243.190000000,244.000000000,2,1,1,1,243.020000000,244.140000000,79,79,1,1,243.000000000,244.200000000,1243,1000,9,1,242.990000000,244.400000000,1,50,1,1,242.750000000,244.420000000,30,10,1,1,242.590000000,244.580000000,5,100,1,1,242.280000000,245.000000000,100,79,1,2,AAPL
2025-01-03T10:30:41.346182005Z,2025-01-03T10:30:41.346014852Z,10,2,9155,T,A,0,242.020000000,14,130,167153,4850866,242.020000000,242.070000000,92,62,1,1,242.000000000,242.510000000,200,8,1,1,241.780000000,242.850000000,8,300,1,2,241.670000000,242.900000000,2,100,1,1,241.000000000,243.000000000,100,92,1,2,240.000000000,243.310000000,10,10,1,1,238.000000000,243.700000000,30,100,1,1,236.000000000,246.810000000,6,100,1,1,235.500000000,262.740000000,5,100,1,1,235.000000000,263.830000000,5,100,1,1,JPM
2025-01-03T10:30:41.346182005Z,2025-01-03T10:30:41.346014852Z,10,2,9155,C,B,0,242.020000000,14,130,167153,4850866,242.020000000,242.070000000,78,62,1,1,242.000000000,242.510000000,200,8,1,1,241.780000000,242.850000000,8,300,1,2,241.670000000,242.900000000,2,100,1,1,241.000000000,243.000000000,100,92,1,2,240.000000000,243.310000000,10,10,1,1,238.000000000,243.700000000,30,100,1,1,236.000000000,246.810000000,6,100,1,1,235.500000000,262.740000000,5,100,1,1,235.000000000,263.830000000,5,100,1,1,JPM
2025-01-03T10:30:41.422620142Z,2025-01-03T10:30:41.422453310Z,10,2,9155,T,A,0,242.020000000,14,130,166832,4850903,242.020000000,242.070000000,78,62,1,1,242.000000000,242.510000000,200,8,1,1,241.780000000,242.850000000,8,300,1,2,241.670000000,242.900000000,2,100,1,1,241.000000000,243.000000000,100,92,1,2,240.000000000,243.310000000,10,10,1,1,238.000000000,243.700000000,30,100,1,1,236.000000000,246.810000000,6,100,1,1,235.500000000,262.740000000,5,100,1,1,235.000000000,263.830000000,5,100,1,1,JPM
2025-01-03T10:30:41.422620142Z,2025-01-03T10:30:41.422453310Z,10,2,9155,C,B,0,242.020000000,14,130,166832,4850903,242.020000000,242.070000000,64,62,1,1,242.000000000,242.510000000,200,8,1,1,241.780000000,242.850000000,8,300,1,2,241.670000000,242.900000000,2,100,1,1,241.000000000,243.000000000,100,92,1,2,240.000000000,243.310000000,10,10,1,1,238.000000000,243.700000000,30,100,1,1,236.000000000,246.810000000,6,100,1,1,235.500000000,262.740000000,5,100,1,1,235.000000000,263.830000000,5,100,1,1,JPM
2025-01-03T10:30:41.422827084Z,2025-01-03T10:30:41.422660393Z,10,2,9155,T,A,0,242.020000000,5,130,166691,4850906,242.020000000,242.070000000,64,62,1,1,242.000000000,242.510000000,200,8,1,1,241.780000000,242.850000000,8,300,1,2,241.670000000,242.900000000,2,100,1,1,241.000000000,243.000000000,100,92,1,2,240.000000000,243.310000000,10,10,1,1,238.000000000,243.700000000,30,100,1,1,236.000000000,246.810000000,6,100,1,1,235.500000000,262.740000000,5,100,1,1,235.000000000,263.830000000,5,100,1,1,JPM
2025-01-03T10:30:41.422827084Z,2025-01-03T10:30:41.422660393Z,10,2,9155,C,B,0,242.020000000,5,130,166691,4850906,242.020000000,242.070000000,59,62,1,1,242.000000000,242.510000000,200,8,1,1,241.780000000,242.850000000,8,300,1,2,241.670000000,242.900000000,2,100,1,1,241.000000000,243.000000000,100,92,1,2,240.000000000,243.310000000,10,10,1,1,238.000000000,243.700000000,30,100,1,1,236.000000000,246.810000000,6,100,1,1,235.500000000,262.740000000,5,100,1,1,235.000000000,263.830000000,5,100,1,1,JPM
2025-01-03T10:30:41.422836005Z,2025-01-03T10:30:41.422669253Z,10,2,9155,T,A,0,242.020000000,5,130,166752,4850907,242.020000000,242.070000000,59,62,1,1,242.000000000,242.510000000,200,8,1,1,241.780000000,242.850000000,8,300,1,2,241.670000000,242.900000000,2,100,1,1,241.000000000,243.000000000,100,92,1,2,240.000000000,243.310000000,10,10,1,1,238.000000000,243.700000000,30,100,1,1,236.000000000,246.810000000,6,100,1,1,235.500000000,262.740000000,5,100,1,1,235.000000000,263.830000000,5,100,1,1,JPM
2025-01-03T10:30:41.422836005Z,2025-01-03T10:30:41.422669253Z,10,2,9155,C,B,0,242.020000000,5,130,166752,4850907,242.020000000,242.070000000,54,62,1,1,242.000000000,242.510000000,200,8,1,1,241.780000000,242.850000000,8,300,1,2,241.670000000,242.900000000,2,100,1,1,241.000000000,243.000000000,100,92,1,2,240.000000000,243.310000000,10,10,1,1,238.000000000,243.700000000,30,100,1,1,236.000000000,246.810000000,6,100,1,1,235.500000000,262.740000000,5,100,1,1,235.000000000,263.830000000,5,100,1,1,JPM
2025-01-03T10:30:41.423061936Z,2025-01-03T10:30:41.422894971Z,10,2,9155,T,A,0,242.020000000,15,130,166965,4850908,242.020000000,242.070000000,54,62,1,1,242.000000000,242.510000000,200,8,1,1,241.780000000,242.850000000,8,300,1,2,241.670000000,242.900000000,2,100,1,1,241.000000000,243.000000000,100,92,1,2,240.000000000,243.310000000,10,10,1,1,238.000000000,243.700000000,30,100,1,1,236.000000000,246.810000000,6,100,1,1,235.500000000,262.740000000,5,100,1,1,235.000000000,263.830000000,5,100,1,1,JPM
2025-01-03T10:30:41.423061936Z,2025-01-03T10:30:41.422894971Z,10,2,9155,C,B,0,242.020000000,15,130,166965,4850908,242.020000000,242.070000000,39,62,1,1,242.000000000,242.510000000,200,8,1,1,241.780000000,242.850000000,8,300,1,2,241.670000000,242.900000000,2,100,1,1,241.000000000,243.000000000,100,92,1,2,240.000000000,243.310000000,10,10,1,1,238.000000000,243.700000000,30,100,1,1,236.000000000,246.810000000,6,100,1,1,235.500000000,262.740000000,5,100,1,1,235.000000000,263.830000000,5,100,1,1,JPM
2025-01-03T10:30:41.423094445Z,2025-01-03T10:30:41.422927559Z,10,2,9155,T,A,0,242.020000000,5,130,166886,4850909,242.020000000,242.070000000,39,62,1,1,242.000000000,242.510000000,200,8,1,1,241.780000000,242.850000000,8,300,1,2,241.670000000,242.900000000,2,100,1,1,241.000000000,243.000000000,100,92,1,2,240.000000000,243.310000000,10,10,1,1,238.000000000,243.700000000,30,100,1,1,236.000000000,246.810000000,6,100,1,1,235.500000000,262.740000000,5,100,1,1,235.000000000,263.830000000,5,100,1,1,JPM
2025-01-03T10:30:41.423094445Z,2025-01-03T10:30:41.422927559Z,10,2,9155,C,B,0,242.020000000,5,130,166886,4850909,242.020000000,242.070000000,34,62,1,1,242.000000000,242.510000000,200,8,1,1,241.780000000,242.850000000,8,300,1,2,241.670000000,242.900000000,2,100,1,1,241.000000000,243.000000000,100,92,1,2,240.000000000,243.310000000,10,10,1,1,238.000000000,243.700000000,30,100,1,1,236.000000000,246.810000000,6,100,1,1,235.500000000,262.740000000,5,100,1,1,235.000000000,263.830000000,5,100,1,1,JPM
2025-01-03T10:30:41.425324539Z,2025-01-03T10:30:41.425158509Z,10,2,10888,C,B,1,420.640000000,13,130,166030,4850917,420.710000000,421.210000000,200,200,1,1,420.580000000,421.270000000,10,13,1,1,420.520000000,421.460000000,1,39,1,1,420.400000000,421.490000000,858,6,1,1,420.380000000,421.570000000,100,40,1,1,420.100000000,421.600000000,100,10,1,1,420.000000000,421.700000000,534,359,7,1,419.730000000,422.100000000,3,7,1,1,419.650000000,422.400000000,39,500,1,1,418.650000000,422.500000000,1,200,1,1,MSFT
2025-01-03T10:30:41.425356955Z,2025-01-03T10:30:41.425190565Z,10,2,10888,A,B,1,420.650000000,15,130,166390,4850918,420.710000000,421.210000000,200,200,1,1,420.650000000,421.270000000,15,13,1,1,420.580000000,421.460000000,10,39,1,1,420.520000000,421.490000000,1,6,1,1,420.400000000,421.570000000,858,40,1,1,420.380000000,421.600000000,100,10,1,1,420.100000000,421.700000000,100,359,1,1,420.000000000,422.100000000,534,7,7,1,419.730000000,422.400000000,3,500,1,1,419.650000000,422.500000000,39,200,1,1,MSFT
2025-01-03T10:30:41.485551051Z,2025-01-03T10:30:41.485384955Z,10,2,9155,C,B,2,241.780000000,8,130,166096,4850937,242.020000000,242.070000000,34,62,1,1,242.000000000,242.510000000,200,8,1,1,241.670000000,242.850000000,2,300,1,2,241.000000000,242.900000000,100,100,1,1,240.000000000,243.000000000,10,92,1,2,238.000000000,243.310000000,30,10,1,1,236.000000000,243.700000000,6,100,1,1,235.500000000,246.810000000,5,100,1,1,235.000000000,262.740000000,5,100,1,1,232.880000000,263.830000000,1,100,1,1,JPM
2025-01-03T10:30:41.485585155Z,2025-01-03T10:30:41.485418891Z,10,2,9155,A,B,2,241.890000000,8,130,166264,4850938,242.020000000,242.070000000,34,62,1,1,242.000000000,242.510000000,200,8,1,1,241.890000000,242.850000000,8,300,1,2,241.670000000,242.900000000,2,100,1,1,241.000000000,243.000000000,100,92,1,2,240.000000000,243.310000000,10,10,1,1,238.000000000,243.700000000,30,100,1,1,236.000000000,246.810000000,6,100,1,1,235.500000000,262.740000000,5,100,1,1,235.000000000,263.830000000,5,100,1,1,JPM
2025-01-03T10:30:41.635549813Z,2025-01-03T10:30:41.635383253Z,10,2,17709,C,B,1,107.560000000,16,130,166560,4850981,107.600000000,107.840000000,50,400,1,2,107.520000000,107.850000000,100,16,1,1,107.050000000,107.870000000,247,242,1,1,107.000000000,107.940000000,1,100,1,1,106.240000000,107.950000000,28,10,1,1,106.000000000,108.000000000,15,50,2,1,105.870000000,108.300000000,141,50,1,1,103.180000000,108.550000000,16,50,1,1,103.000000000,108.800000000,3,50,1,1,102.000000000,108.880000000,2,28,1,1,XOM
2025-01-03T10:30:41.635634268Z,2025-01-03T10:30:41.635467984Z,10,2,17709,A,B,1,107.540000000,15,130,166284,4850982,107.600000000,107.840000000,50,400,1,2,107.540000000,107.850000000,15,16,1,1,107.520000000,107.870000000,100,242,1,1,107.050000000,107.940000000,247,100,1,1,107.000000000,107.950000000,1,10,1,1,106.240000000,108.000000000,28,50,1,1,106.000000000,108.300000000,15,50,2,1,105.870000000,108.550000000,141,50,1,1,103.180000000,108.800000000,16,50,1,1,103.000000000,108.880000000,3,28,1,1,XOM
2025-01-03T10:30:41.635691250Z,2025-01-03T10:30:41.635525194Z,10,2,17709,A,A,0,107.840000000,17,130,166056,4850983,107.600000000,107.840000000,50,417,1,3,107.540000000,107.850000000,15,16,1,1,107.520000000,107.870000000,100,242,1,1,107.050000000,107.940000000,247,100,1,1,107.000000000,107.950000000,1,10,1,1,106.240000000,108.000000000,28,50,1,1,106.000000000,108.300000000,15,50,2,1,105.870000000,108.550000000,141,50,1,1,103.180000000,108.800000000,16,50,1,1,103.000000000,108.880000000,3,28,1,1,XOM
2025-01-03T10:30:41.635758114Z,2025-01-03T10:30:41.635591987Z,10,2,17709,C,A,1,107.850000000,16,130,166127,4850984,107.600000000,107.840000000,50,417,1,3,107.540000000,107.870000000,15,242,1,1,107.520000000,107.940000000,100,100,1,1,107.050000000,107.950000000,247,10,1,1,107.000000000,108.000000000,1,50,1,1,106.240000000,108.300000000,28,50,1,1,106.000000000,108.550000000,15,50,2,1,105.870000000,108.800000000,141,50,1,1,103.180000000,108.880000000,16,28,1,1,103.000000000,109.450000000,3,137,1,1,XOM
2025-01-03T10:30:41.679372175Z,2025-01-03T10:30:41.679205707Z,10,2,38,C,A,1,243.680000000,200,130,166468,4850999,243.500000000,243.650000000,6,61,1,2,243.450000000,243.740000000,400,28,1,1,243.380000000,244.000000000,28,1,1,1,243.190000000,244.140000000,2,79,1,1,243.020000000,244.200000000,79,1000,1,1,243.000000000,244.400000000,1243,50,9,1,242.990000000,244.420000000,1,10,1,1,242.750000000,244.580000000,30,100,1,1,242.590000000,245.000000000,5,79,1,2,242.280000000,245.190000000,100,83,1,1,AAPL
2025-01-03T10:30:41.679384493Z,2025-01-03T10:30:41.679218158Z,10,2,38,A,A,1,243.700000000,200,130,166335,4851000,243.500000000,243.650000000,6,61,1,2,243.450000000,243.700000000,400,200,1,1,243.380000000,243.740000000,28,28,1,1,243.190000000,244.000000000,2,1,1,1,243.020000000,244.140000000,79,79,1,1,243.000000000,244.200000000,1243,1000,9,1,242.990000000,244.400000000,1,50,1,1,242.750000000,244.420000000,30,10,1,1,242.590000000,244.580000000,5,100,1,1,242.280000000,245.000000000,100,79,1,2,AAPL
2025-01-03T10:30:41.694299241Z,2025-01-03T10:30:41.694132859Z,10,2,17709,A,A,2,107.880000000,100,130,166382,4851008,107.600000000,107.840000000,50,417,1,3,107.540000000,107.870000000,15,242,1,1,107.520000000,107.880000000,100,100,1,1,107.050000000,107.950000000,247,10,1,1,107.000000000,108.000000000,1,50,1,1,106.240000000,108.300000000,28,50,1,1,106.000000000,108.550000000,15,50,2,1,105.870000000,108.800000000,141,50,1,1,103.180000000,108.880000000,16,28,1,1,103.000000000,109.450000000,3,137,1,1,XOM
2025-01-03T10:30:42.112379381Z,2025-01-03T10:30:42.112212916Z,10,2,9155,A,B,4,241.120000000,81,130,166465,4851411,242.020000000,242.070000000,34,62,1,1,242.000000000,242.510000000,200,8,1,1,241.890000000,242.850000000,8,300,1,2,241.670000000,242.900000000,2,100,1,1,241.120000000,243.000000000,81,92,1,2,241.000000000,243.310000000,100,10,1,1,240.000000000,243.700000000,10,100,1,1,238.000000000,246.810000000,30,100,1,1,236.000000000,262.740000000,6,100,1,1,235.500000000,263.830000000,5,100,1,1,JPM
2025-01-03T10:30:42.454579916Z,2025-01-03T10:30:42.454413975Z,10,2,9155,C,A,1,242.510000000,8,130,165941,4851550,242.020000000,242.070000000,34,62,1,1,242.000000000,242.850000000,200,300,1,2,241.890000000,242.900000000,8,100,1,1,241.670000000,243.000000000,2,92,1,2,241.120000000,243.310000000,81,10,1,1,241.000000000,243.700000000,100,100,1,1,240.000000000,246.810000000,10,100,1,1,238.000000000,262.740000000,30,100,1,1,236.000000000,263.830000000,6,100,1,1,235.500000000,,5,0,1,0,JPM
2025-01-03T10:30:42.454639182Z,2025-01-03T10:30:42.454473263Z,10,2,9155,A,A,1,242.500000000,8,130,165919,4851552,242.020000000,242.070000000,34,62,1,1,242.000000000,242.500000000,200,8,1,1,241.890000000,242.850000000,8,300,1,2,241.670000000,242.900000000,2,100,1,1,241.120000000,243.000000000,81,92,1,2,241.000000000,243.310000000,100,10,1,1,240.000000000,243.700000000,10,100,1,1,238.000000000,246.810000000,30,100,1,1,236.000000000,262.740000000,6,100,1,1,235.500000000,263.830000000,5,100,1,1,JPM
2025-01-03T10:30:42.455860781Z,2025-01-03T10:30:42.455694862Z,10,2,17709,C,A,0,107.840000000,17,130,165919,4851557,107.600000000,107.840000000,50,400,1,2,107.540000000,107.870000000,15,242,1,1,107.520000000,107.880000000,100,100,1,1,107.050000000,107.950000000,247,10,1,1,107.000000000,108.000000000,1,50,1,1,106.240000000,108.300000000,28,50,1,1,106.000000000,108.550000000,15,50,2,1,105.870000000,108.800000000,141,50,1,1,103.180000000,108.880000000,16,28,1,1,103.000000000,109.450000000,3,137,1,1,XOM
2025-01-03T10:30:42.455929200Z,2025-01-03T10:30:42.455762925Z,10,2,17709,A,A,0,107.830000000,17,130,166275,4851558,107.600000000,107.830000000,50,17,1,1,107.540000000,107.840000000,15,400,1,2,107.520000000,107.870000000,100,242,1,1,107.050000000,107.880000000,247,100,1,1,107.000000000,107.950000000,1,10,1,1,106.240000000,108.000000000,28,50,1,1,106.000000000,108.300000000,15,50,2,1,105.870000000,108.550000000,141,50,1,1,103.180000000,108.800000000,16,50,1,1,103.000000000,108.880000000,3,28,1,1,XOM
2025-01-03T10:30:42.758624983Z,2025-01-03T10:30:42.758457827Z,10,2,16244,T,N,0,382.930000000,8,130,167156,4851645,382.860000000,383.090000000,19,6,1,1,382.810000000,383.100000000,10,11,1,1,382.700000000,383.300000000,50,20,1,1,382.680000000,383.340000000,20,23,1,1,382.400000000,383.420000000,500,140,1,1,382.230000000,383.600000000,25,1000,1,2,382.110000000,383.720000000,300,7085,1,8,382.100000000,383.740000000,20,37,2,1,382.010000000,383.800000000,2,10,1,1,382.000000000,383.880000000,692,4,9,1,TSLA
2025-01-03T10:30:43.223335900Z,2025-01-03T10:30:43.223169662Z,10,2,16244,A,B,2,382.720000000,10,130,166238,4851732,382.860000000,383.090000000,19,6,1,1,382.810000000,383.100000000,10,11,1,1,382.720000000,383.300000000,10,20,1,1,382.700000000,383.340000000,50,23,1,1,382.680000000,383.420000000,20,140,1,1,382.400000000,383.600000000,500,1000,1,2,382.230000000,383.720000000,25,7085,1,8,382.110000000,383.740000000,300,37,1,1,382.100000000,383.800000000,20,10,2,1,382.010000000,383.880000000,2,4,1,1,TSLA
2025-01-03T10:30:43.247533229Z,2025-01-03T10:30:43.247365765Z,10,2,16244,T,N,0,383.050000000,21,130,167464,4851733,382.860000000,383.090000000,19,6,1,1,382.810000000,383.100000000,10,11,1,1,382.720000000,383.300000000,10,20,1,1,382.700000000,383.340000000,50,23,1,1,382.680000000,383.420000000,20,140,1,1,382.400000000,383.600000000,500,1000,1,2,382.230000000,383.720000000,25,7085,1,8,382.110000000,383.740000000,300,37,1,1,382.100000000,383.800000000,20,10,2,1,382.010000000,383.880000000,2,4,1,1,TSLA
2025-01-03T10:30:43.741228839Z,2025-01-03T10:30:43.741062665Z,10,2,16244,A,B,0,382.990000000,30,130,166174,4851853,382.990000000,383.090000000,30,6,1,1,382.860000000,383.100000000,19,11,1,1,382.810000000,383.300000000,10,20,1,1,382.720000000,383.340000000,10,23,1,1,382.700000000,383.420000000,50,140,1,1,382.680000000,383.600000000,20,1000,1,2,382.400000000,383.720000000,500,7085,1,8,382.230000000,383.740000000,25,37,1,1,382.110000000,383.800000000,300,10,1,1,382.100000000,383.880000000,20,4,2,1,TSLA
2025-01-03T10:30:43.755716783Z,2025-01-03T10:30:43.755550863Z,10,2,16244,C,B,6,382.400000000,500,130,165920,4851869,382.990000000,383.090000000,30,6,1,1,382.860000000,383.100000000,19,11,1,1,382.810000000,383.300000000,10,20,1,1,382.720000000,383.340000000,10,23,1,1,382.700000000,383.420000000,50,140,1,1,382.680000000,383.600000000,20,1000,1,2,382.230000000,383.720000000,25,7085,1,8,382.110000000,383.740000000,300,37,1,1,382.100000000,383.800000000,20,10,2,1,382.010000000,383.880000000,2,4,1,1,TSLA
2025-01-03T10:30:43.961461820Z,2025-01-03T10:30:43.961295129Z,10,2,38,A,A,0,243.640000000,54,130,166691,4851930,243.500000000,243.640000000,6,54,1,1,243.450000000,243.650000000,400,61,1,2,243.380000000,243.700000000,28,200,1,1,243.190000000,243.740000000,2,28,1,1,243.020000000,244.000000000,79,1,1,1,243.000000000,244.140000000,1243,79,9,1,242.990000000,244.200000000,1,1000,1,1,242.750000000,244.400000000,30,50,1,1,242.590000000,244.420000000,5,10,1,1,242.280000000,244.580000000,100,100,1,1,AAPL
2025-01-03T10:30:44.663098737Z,2025-01-03T10:30:44.662932465Z,10,2,11667,C,B,0,139.150000000,50,130,166272,4852108,139.140000000,139.160000000,30,300,1,1,139.130000000,139.200000000,100,829,1,3,139.120000000,139.220000000,30,10,1,1,139.110000000,139.230000000,1,25,1,1,139.100000000,139.250000000,400,1,1,1,139.080000000,139.270000000,57,17,1,1,139.030000000,139.300000000,126,507,2,4,139.010000000,139.320000000,100,39,1,1,139.000000000,139.330000000,420,503,5,2,138.980000000,139.360000000,300,4,1,2,NVDA
2025-01-03T10:30:44.664362306Z,2025-01-03T10:30:44.664195225Z,10,2,11667,T,B,0,139.160000000,50,130,167081,4852111,139.140000000,139.160000000,30,300,1,1,139.130000000,139.200000000,100,829,1,3,139.120000000,139.220000000,30,10,1,1,139.110000000,139.230000000,1,25,1,1,139.100000000,139.250000000,400,1,1,1,139.080000000,139.270000000,57,17,1,1,139.030000000,139.300000000,126,507,2,4,139.010000000,139.320000000,100,39,1,1,139.000000000,139.330000000,420,503,5,2,138.980000000,139.360000000,300,4,1,2,NVDA
2025-01-03T10:30:44.664362306Z,2025-01-03T10:30:44.664195225Z,10,2,11667,C,A,0,139.160000000,50,130,167081,4852111,139.140000000,139.160000000,30,250,1,1,139.130000000,139.200000000,100,829,1,3,139.120000000,139.220000000,30,10,1,1,139.110000000,139.230000000,1,25,1,1,139.100000000,139.250000000,400,1,1,1,139.080000000,139.270000000,57,17,1,1,139.030000000,139.300000000,126,507,2,4,139.010000000,139.320000000,100,39,1,1,139.000000000,139.330000000,420,503,5,2,138.980000000,139.360000000,300,4,1,2,NVDA
2025-01-03T10:30:44.712768056Z,2025-01-03T10:30:44.712601100Z,10,2,10888,A,A,0,421.200000000,200,130,166956,4852126,420.710000000,421.200000000,200,200,1,1,420.650000000,421.270000000,15,13,1,1,420.580000000,421.460000000,10,39,1,1,420.520000000,421.490000000,1,6,1,1,420.400000000,421.570000000,858,40,1,1,420.380000000,421.600000000,100,10,1,1,420.100000000,421.700000000,100,359,1,1,420.000000000,422.100000000,534,7,7,1,419.730000000,422.400000000,3,500,1,1,419.650000000,422.500000000,39,200,1,1,MSFT
2025-01-03T10:30:44.787776125Z,2025-01-03T10:30:44.787609476Z,10,2,10888,A,A,0,421.180000000,200,130,166649,4852200,420.710000000,421.180000000,200,200,1,1,420.650000000,421.270000000,15,13,1,1,420.580000000,421.460000000,10,39,1,1,420.520000000,421.490000000,1,6,1,1,420.400000000,421.570000000,858,40,1,1,420.380000000,421.600000000,100,10,1,1,420.100000000,421.700000000,100,359,1,1,420.000000000,422.100000000,534,7,7,1,419.730000000,422.400000000,3,500,1,1,419.650000000,422.500000000,39,200,1,1,MSFT
2025-01-03T10:30:44.788175507Z,2025-01-03T10:30:44.788008420Z,10,2,38,A,A,2,243.680000000,200,130,167087,4852205,243.500000000,243.640000000,6,54,1,1,243.450000000,243.650000000,400,61,1,2,243.380000000,243.680000000,28,200,1,1,243.190000000,243.740000000,2,28,1,1,243.020000000,244.000000000,79,1,1,1,243.000000000,244.140000000,1243,79,9,1,242.990000000,244.200000000,1,1000,1,1,242.750000000,244.400000000,30,50,1,1,242.590000000,244.420000000,5,10,1,1,242.280000000,244.580000000,100,100,1,1,AAPL
2025-01-03T10:30:44.788516075Z,2025-01-03T10:30:44.788349669Z,10,2,11667,A,A,1,139.190000000,400,130,166406,4852207,139.140000000,139.160000000,30,250,1,1,139.130000000,139.190000000,100,400,1,1,139.120000000,139.200000000,30,429,1,2,139.110000000,139.220000000,1,10,1,1,139.100000000,139.230000000,400,25,1,1,139.080000000,139.250000000,57,1,1,1,139.030000000,139.270000000,126,17,2,1,139.010000000,139.300000000,100,507,1,4,139.000000000,139.320000000,420,39,5,1,138.980000000,139.330000000,300,503,1,2,NVDA
2025-01-03T10:30:44.803731021Z,2025-01-03T10:30:44.803565115Z,10,2,38,C,A,3,243.740000000,28,130,165906,4852289,243.500000000,243.640000000,6,54,1,1,243.450000000,243.650000000,400,61,1,2,243.380000000,243.680000000,28,200,1,1,243.190000000,244.000000000,2,1,1,1,243.020000000,244.140000000,79,79,1,1,243.000000000,244.200000000,1243,1000,9,1,242.990000000,244.400000000,1,50,1,1,242.750000000,244.420000000,30,10,1,1,242.590000000,244.580000000,5,100,1,1,242.280000000,245.000000000,100,79,1,2,AAPL
2025-01-03T10:30:44.803789303Z,2025-01-03T10:30:44.803623221Z,10,2,38,A,A,3,243.730000000,30,130,166082,4852291,243.500000000,243.640000000,6,54,1,1,243.450000000,243.650000000,400,61,1,2,243.380000000,243.680000000,28,200,1,1,243.190000000,243.730000000,2,30,1,1,243.020000000,244.000000000,79,1,1,1,243.000000000,244.140000000,1243,79,9,1,242.990000000,244.200000000,1,1000,1,1,242.750000000,244.400000000,30,50,1,1,242.590000000,244.420000000,5,10,1,1,242.280000000,244.580000000,100,100,1,1,AAPL
2025-01-03T10:30:44.865984486Z,2025-01-03T10:30:44.865818192Z,10,2,17709,C,B,2,107.520000000,100,130,166294,4852327,107.600000000,107.830000000,50,17,1,1,107.540000000,107.840000000,15,400,1,2,107.050000000,107.870000000,247,242,1,1,107.000000000,107.880000000,1,100,1,1,106.240000000,107.950000000,28,10,1,1,106.000000000,108.000000000,15,50,2,1,105.870000000,108.300000000,141,50,1,1,103.180000000,108.550000000,16,50,1,1,103.000000000,108.800000000,3,50,1,1,102.000000000,108.880000000,2,28,1,1,XOM
2025-01-03T10:30:44.865998152Z,2025-01-03T10:30:44.865831240Z,10,2,17709,A,B,2,107.460000000,100,130,166912,4852328,107.600000000,107.830000000,50,17,1,1,107.540000000,107.840000000,15,400,1,2,107.460000000,107.870000000,100,242,1,1,107.050000000,107.880000000,247,100,1,1,107.000000000,107.950000000,1,10,1,1,106.240000000,108.000000000,28,50,1,1,106.000000000,108.300000000,15,50,2,1,105.870000000,108.550000000,141,50,1,1,103.180000000,108.800000000,16,50,1,1,103.000000000,108.880000000,3,28,1,1,XOM
2025-01-03T10:30:44.875158730Z,2025-01-03T10:30:44.874991961Z,10,2,17709,A,B,2,107.510000000,15,130,166769,4852334,107.600000000,107.830000000,50,17,1,1,107.540000000,107.840000000,15,400,1,2,107.510000000,107.870000000,15,242,1,1,107.460000000,107.880000000,100,100,1,1,107.050000000,107.950000000,247,10,1,1,107.000000000,108.000000000,1,50,1,1,106.240000000,108.300000000,28,50,1,1,106.000000000,108.550000000,15,50,2,1,105.870000000,108.800000000,141,50,1,1,103.180000000,108.880000000,16,28,1,1,XOM
2025-01-03T10:30:44.875184512Z,2025-01-03T10:30:44.875018510Z,10,2,17709,C,B,1,107.540000000,15,130,166002,4852335,107.600000000,107.830000000,50,17,1,1,107.510000000,107.840000000,15,400,1,2,107.460000000,107.870000000,100,242,1,1,107.050000000,107.880000000,247,100,1,1,107.000000000,107.950000000,1,10,1,1,106.240000000,108.000000000,28,50,1,1,106.000000000,108.300000000,15,50,2,1,105.870000000,108.550000000,141,50,1,1,103.180000000,108.800000000,16,50,1,1,103.000000000,108.880000000,3,28,1,1,XOM
2025-01-03T10:30:44.875217862Z,2025-01-03T10:30:44.875051814Z,10,2,17709,C,A,0,107.830000000,17,130,166048,4852336,107.600000000,107.840000000,50,400,1,2,107.510000000,107.870000000,15,242,1,1,107.460000000,107.880000000,100,100,1,1,107.050000000,107.950000000,247,10,1,1,107.000000000,108.000000000,1,50,1,1,106.240000000,108.300000000,28,50,1,1,106.000000000,108.550000000,15,50,2,1,105.870000000,108.800000000,141,50,1,1,103.180000000,108.880000000,16,28,1,1,103.000000000,109.450000000,3,137,1,1,XOM
2025-01-03T10:30:44.875275557Z,2025-01-03T10:30:44.875109563Z,10,2,17709,A,A,0,107.810000000,15,130,165994,4852337,107.600000000,107.810000000,50,15,1,1,107.510000000,107.840000000,15,400,1,2,107.460000000,107.870000000,100,242,1,1,107.050000000,107.880000000,247,100,1,1,107.000000000,107.950000000,1,10,1,1,106.240000000,108.000000000,28,50,1,1,106.000000000,108.300000000,15,50,2,1,105.870000000,108.550000000,141,50,1,1,103.180000000,108.800000000,16,50,1,1,103.000000000,108.880000000,3,28,1,1,XOM
2025-01-03T10:30:44.883278141Z,2025-01-03T10:30:44.883112081Z,10,2,17709,C,B,1,107.510000000,15,130,166060,4852338,107.600000000,107.810000000,50,15,1,1,107.460000000,107.840000000,100,400,1,2,107.050000000,107.870000000,247,242,1,1,107.000000000,107.880000000,1,100,1,1,106.240000000,107.950000000,28,10,1,1,106.000000000,108.000000000,15,50,2,1,105.870000000,108.300000000,141,50,1,1,103.180000000,108.550000000,16,50,1,1,103.000000000,108.800000000,3,50,1,1,102.000000000,108.880000000,2,28,1,1,XOM
2025-01-03T10:30:45.088347115Z,2025-01-03T10:30:45.088180812Z,10,2,17709,C,A,3,107.880000000,100,130,166303,4852431,107.600000000,107.810000000,50,15,1,1,107.460000000,107.840000000,100,400,1,2,107.050000000,107.870000000,247,242,1,1,107.000000000,107.950000000,1,10,1,1,106.240000000,108.000000000,28,50,1,1,106.000000000,108.300000000,15,50,2,1,105.870000000,108.550000000,141,50,1,1,103.180000000,108.800000000,16,50,1,1,103.000000000,108.880000000,3,28,1,1,102.000000000,109.450000000,2,137,1,1,XOM
2025-01-03T10:30:45.088360721Z,2025-01-03T10:30:45.088194374Z,10,2,17709,A,A,3,107.940000000,100,130,166347,4852432,107.600000000,107.810000000,50,15,1,1,107.460000000,107.840000000,100,400,1,2,107.050000000,107.870000000,247,242,1,1,107.000000000,107.940000000,1,100,1,1,106.240000000,107.950000000,28,10,1,1,106.000000000,108.000000000,15,50,2,1,105.870000000,108.300000000,141,50,1,1,103.180000000,108.550000000,16,50,1,1,103.000000000,108.800000000,3,50,1,1,102.000000000,108.880000000,2,28,1,1,XOM
2025-01-03T10:30:45.088798600Z,2025-01-03T10:30:45.088632720Z,10,2,17709,C,A,0,107.810000000,15,130,165880,4852433,107.600000000,107.840000000,50,400,1,2,107.460000000,107.870000000,100,242,1,1,107.050000000,107.940000000,247,100,1,1,107.000000000,107.950000000,1,10,1,1,106.240000000,108.000000000,28,50,1,1,106.000000000,108.300000000,15,50,2,1,105.870000000,108.550000000,141,50,1,1,103.180000000,108.800000000,16,50,1,1,103.000000000,108.880000000,3,28,1,1,102.000000000,109.450000000,2,137,1,1,XOM
2025-01-03T10:30:47.253371811Z,2025-01-03T10:30:47.253205748Z,10,2,16244,A,B,3,382.750000000,10,130,166063,4853128,382.990000000,383.090000000,30,6,1,1,382.860000000,383.100000000,19,11,1,1,382.810000000,383.300000000,10,20,1,1,382.750000000,383.340000000,10,23,1,1,382.720000000,383.420000000,10,140,1,1,382.700000000,383.600000000,50,1000,1,2,382.680000000,383.720000000,20,7085,1,8,382.230000000,383.740000000,25,37,1,1,382.110000000,383.800000000,300,10,1,1,382.100000000,383.880000000,20,4,2,1,TSLA
2025-01-03T10:30:47.529528564Z,2025-01-03T10:30:47.529362735Z,10,2,10888,C,A,0,421.180000000,200,130,165829,4853330,420.710000000,421.270000000,200,13,1,1,420.650000000,421.460000000,15,39,1,1,420.580000000,421.490000000,10,6,1,1,420.520000000,421.570000000,1,40,1,1,420.400000000,421.600000000,858,10,1,1,420.380000000,421.700000000,100,359,1,1,420.100000000,422.100000000,100,7,1,1,420.000000000,422.400000000,534,500,7,1,419.730000000,422.500000000,3,200,1,1,419.650000000,423.500000000,39,600,1,2,MSFT
2025-01-03T10:30:47.529540113Z,2025-01-03T10:30:47.529373666Z,10,2,10888,A,A,0,421.220000000,200,130,166447,4853331,420.710000000,421.220000000,200,200,1,1,420.650000000,421.270000000,15,13,1,1,420.580000000,421.460000000,10,39,1,1,420.520000000,421.490000000,1,6,1,1,420.400000000,421.570000000,858,40,1,1,420.380000000,421.600000000,100,10,1,1,420.100000000,421.700000000,100,359,1,1,420.000000000,422.100000000,534,7,7,1,419.730000000,422.400000000,3,500,1,1,419.650000000,422.500000000,39,200,1,1,MSFT
2025-01-03T10:30:47.529650391Z,2025-01-03T10:30:47.529484604Z,10,2,11667,C,A,1,139.190000000,400,130,165787,4853334,139.140000000,139.160000000,30,250,1,1,139.130000000,139.200000000,100,429,1,2,139.120000000,139.220000000,30,10,1,1,139.110000000,139.230000000,1,25,1,1,139.100000000,139.250000000,400,1,1,1,139.080000000,139.270000000,57,17,1,1,139.030000000,139.300000000,126,507,2,4,139.010000000,139.320000000,100,39,1,1,139.000000000,139.330000000,420,503,5,2,138.980000000,139.360000000,300,4,1,2,NVDA
2025-01-03T10:30:47.529661043Z,2025-01-03T10:30:47.529494906Z,10,2,11667,A,A,2,139.210000000,400,130,166137,4853335,139.140000000,139.160000000,30,250,1,1,139.130000000,139.200000000,100,429,1,2,139.120000000,139.210000000,30,400,1,1,139.110000000,139.220000000,1,10,1,1,139.100000000,139.230000000,400,25,1,1,139.080000000,139.250000000,57,1,1,1,139.030000000,139.270000000,126,17,2,1,139.010000000,139.300000000,100,507,1,4,139.000000000,139.320000000,420,39,5,1,138.980000000,139.330000000,300,503,1,2,NVDA
2025-01-03T10:30:47.529989675Z,2025-01-03T10:30:47.529823881Z,10,2,38,C,A,2,243.680000000,200,130,165794,4853343,243.500000000,243.640000000,6,54,1,1,243.450000000,243.650000000,400,61,1,2,243.380000000,243.730000000,28,30,1,1,243.190000000,244.000000000,2,1,1,1,243.020000000,244.140000000,79,79,1,1,243.000000000,244.200000000,1243,1000,9,1,242.990000000,244.400000000,1,50,1,1,242.750000000,244.420000000,30,10,1,1,242.590000000,244.580000000,5,100,1,1,242.280000000,245.000000000,100,79,1,2,AAPL
2025-01-03T10:30:47.530001280Z,2025-01-03T10:30:47.529835226Z,10,2,38,A,A,2,243.710000000,200,130,166054,4853344,243.500000000,243.640000000,6,54,1,1,243.450000000,243.650000000,400,61,1,2,243.380000000,243.710000000,28,200,1,1,243.190000000,243.730000000,2,30,1,1,243.020000000,244.000000000,79,1,1,1,243.000000000,244.140000000,1243,79,9,1,242.990000000,244.200000000,1,1000,1,1,242.750000000,244.400000000,30,50,1,1,242.590000000,244.420000000,5,10,1,1,242.280000000,244.580000000,100,100,1,1,AAPL
2025-01-03T10:30:47.582076566Z,2025-01-03T10:30:47.581910443Z,10,2,11667,A,A,1,139.200000000,400,130,166123,4853435,139.140000000,139.160000000,30,250,1,1,139.130000000,139.200000000,100,829,1,3,139.120000000,139.220000000,30,10,1,1,139.110000000,139.230000000,1,25,1,1,139.100000000,139.250000000,400,1,1,1,139.080000000,139.270000000,57,17,1,1,139.030000000,139.300000000,126,507,2,4,139.010000000,139.320000000,100,39,1,1,139.000000000,139.330000000,420,503,5,2,138.980000000,139.360000000,300,4,1,2,NVDA
2025-01-03T10:30:47.586170713Z,2025-01-03T10:30:47.586004397Z,10,2,10888,A,A,0,421.200000000,200,130,166316,4853447,420.710000000,421.200000000,200,200,1,1,420.650000000,421.270000000,15,13,1,1,420.580000000,421.460000000,10,39,1,1,420.520000000,421.490000000,1,6,1,1,420.400000000,421.570000000,858,40,1,1,420.380000000,421.600000000,100,10,1,1,420.100000000,421.700000000,100,359,1,1,420.000000000,422.100000000,534,7,7,1,419.730000000,422.400000000,3,500,1,1,419.650000000,422.500000000,39,200,1,1,MSFT
2025-01-03T10:30:47.586685044Z,2025-01-03T10:30:47.586518718Z,10,2,38,A,A,2,243.700000000,200,130,166326,4853452,243.500000000,243.640000000,6,54,1,1,243.450000000,243.650000000,400,61,1,2,243.380000000,243.700000000,28,200,1,1,243.190000000,243.730000000,2,30,1,1,243.020000000,244.000000000,79,1,1,1,243.000000000,244.140000000,1243,79,9,1,242.990000000,244.200000000,1,1000,1,1,242.750000000,244.400000000,30,50,1,1,242.590000000,244.420000000,5,10,1,1,242.280000000,244.580000000,100,100,1,1,AAPL
2025-01-03T10:30:47.587321612Z,2025-01-03T10:30:47.587155293Z,10,2,17709,A,A,1,107.870000000,17,130,166319,4853455,107.600000000,107.840000000,50,400,1,2,107.460000000,107.870000000,100,259,1,2,107.050000000,107.940000000,247,100,1,1,107.000000000,107.950000000,1,10,1,1,106.240000000,108.000000000,28,50,1,1,106.000000000,108.300000000,15,50,2,1,105.870000000,108.550000000,141,50,1,1,103.180000000,108.800000000,16,50,1,1,103.000000000,108.880000000,3,28,1,1,102.000000000,109.450000000,2,137,1,1,XOM
2025-01-03T10:30:47.587364546Z,2025-01-03T10:30:47.587198430Z,10,2,17709,A,B,1,107.530000000,16,130,166116,4853456,107.600000000,107.840000000,50,400,1,2,107.530000000,107.870000000,16,259,1,2,107.460000000,107.940000000,100,100,1,1,107.050000000,107.950000000,247,10,1,1,107.000000000,108.000000000,1,50,1,1,106.240000000,108.300000000,28,50,1,1,106.000000000,108.550000000,15,50,2,1,105.870000000,108.800000000,141,50,1,1,103.180000000,108.880000000,16,28,1,1,103.000000000,109.450000000,3,137,1,1,XOM
2025-01-03T10:30:47.594234844Z,2025-01-03T10:30:47.594068900Z,10,2,16244,C,B,1,382.860000000,19,130,165944,4853469,382.990000000,383.090000000,30,6,1,1,382.810000000,383.100000000,10,11,1,1,382.750000000,383.300000000,10,20,1,1,382.720000000,383.340000000,10,23,1,1,382.700000000,383.420000000,50,140,1,1,382.680000000,383.600000000,20,1000,1,2,382.230000000,383.720000000,25,7085,1,8,382.110000000,383.740000000,300,37,1,1,382.100000000,383.800000000,20,10,2,1,382.010000000,383.880000000,2,4,1,1,TSLA
2025-01-03T10:30:47.594293784Z,2025-01-03T10:30:47.594127651Z,10,2,16244,A,B,1,382.870000000,22,130,166133,4853471,382.990000000,383.090000000,30,6,1,1,382.870000000,383.100000000,22,11,1,1,382.810000000,383.300000000,10,20,1,1,382.750000000,383.340000000,10,23,1,1,382.720000000,383.420000000,10,140,1,1,382.700000000,383.600000000,50,1000,1,2,382.680000000,383.720000000,20,7085,1,8,382.230000000,383.740000000,25,37,1,1,382.110000000,383.800000000,300,10,1,1,382.100000000,383.880000000,20,4,2,1,TSLA
2025-01-03T10:30:47.597428065Z,2025-01-03T10:30:47.597262119Z,10,2,10888,C,A,1,421.270000000,13,130,165946,4853485,420.710000000,421.200000000,200,200,1,1,420.650000000,421.460000000,15,39,1,1,420.580000000,421.490000000,10,6,1,1,420.520000000,421.570000000,1,40,1,1,420.400000000,421.600000000,858,10,1,1,420.380000000,421.700000000,100,359,1,1,420.100000000,422.100000000,100,7,1,1,420.000000000,422.400000000,534,500,7,1,419.730000000,422.500000000,3,200,1,1,419.650000000,423.500000000,39,600,1,2,MSFT
2025-01-03T10:30:47.597590716Z,2025-01-03T10:30:47.597424254Z,10,2,10888,A,A,1,421.310000000,15,130,166462,4853486,420.710000000,421.200000000,200,200,1,1,420.650000000,421.310000000,15,15,1,1,420.580000000,421.460000000,10,39,1,1,420.520000000,421.490000000,1,6,1,1,420.400000000,421.570000000,858,40,1,1,420.380000000,421.600000000,100,10,1,1,420.100000000,421.700000000,100,359,1,1,420.000000000,422.100000000,534,7,7,1,419.730000000,422.400000000,3,500,1,1,419.650000000,422.500000000,39,200,1,1,MSFT
2025-01-03T10:30:47.599395211Z,2025-01-03T10:30:47.599229044Z,10,2,16727,C,A,0,315.420000000,8,130,166167,4853544,314.910000000,315.510000000,8,25,1,1,314.860000000,315.750000000,25,61,1,1,314.420000000,320.000000000,61,5,1,1,313.500000000,320.210000000,1,1,1,1,310.000000000,321.950000000,1,2,1,1,300.000000000,344.200000000,3,100,1,1,290.000000000,345.620000000,2,100,1,1,286.660000000,,100,0,1,0,285.250000000,,100,0,1,0,260.000000000,,2,0,1,0,V
2025-01-03T10:30:47.599426489Z,2025-01-03T10:30:47.599260210Z,10,2,16727,A,A,0,315.450000000,8,130,166279,4853545,314.910000000,315.450000000,8,8,1,1,314.860000000,315.510000000,25,25,1,1,314.420000000,315.750000000,61,61,1,1,313.500000000,320.000000000,1,5,1,1,310.000000000,320.210000000,1,1,1,1,300.000000000,321.950000000,3,2,1,1,290.000000000,344.200000000,2,100,1,1,286.660000000,345.620000000,100,100,1,1,285.250000000,,100,0,1,0,260.000000000,,2,0,1,0,V
2025-01-03T10:30:48.369355591Z,2025-01-03T10:30:48.369189452Z,10,2,9155,C,B,2,241.890000000,8,130,166139,4853935,242.020000000,242.070000000,34,62,1,1,242.000000000,242.500000000,200,8,1,1,241.670000000,242.850000000,2,300,1,2,241.120000000,242.900000000,81,100,1,1,241.000000000,243.000000000,100,92,1,2,240.000000000,243.310000000,10,10,1,1,238.000000000,243.700000000,30,100,1,1,236.000000000,246.810000000,6,100,1,1,235.500000000,262.740000000,5,100,1,1,235.000000000,263.830000000,5,100,1,1,JPM
2025-01-03T10:30:48.369443922Z,2025-01-03T10:30:48.369277427Z,10,2,9155,A,B,2,241.790000000,8,130,166495,4853936,242.020000000,242.070000000,34,62,1,1,242.000000000,242.500000000,200,8,1,1,241.790000000,242.850000000,8,300,1,2,241.670000000,242.900000000,2,100,1,1,241.120000000,243.000000000,81,92,1,2,241.000000000,243.310000000,100,10,1,1,240.000000000,243.700000000,10,100,1,1,238.000000000,246.810000000,30,100,1,1,236.000000000,262.740000000,6,100,1,1,235.500000000,263.830000000,5,100,1,1,JPM
2025-01-03T10:30:49.099760760Z,2025-01-03T10:30:49.099594622Z,10,2,16244,A,B,1,382.880000000,20,130,166138,4854289,382.990000000,383.090000000,30,6,1,1,382.880000000,383.100000000,20,11,1,1,382.870000000,383.300000000,22,20,1,1,382.810000000,383.340000000,10,23,1,1,382.750000000,383.420000000,10,140,1,1,382.720000000,383.600000000,10,1000,1,2,382.700000000,383.720000000,50,7085,1,8,382.680000000,383.740000000,20,37,1,1,382.230000000,383.800000000,25,10,1,1,382.110000000,383.880000000,300,4,1,1,TSLA
2025-01-03T10:30:49.099852985Z,2025-01-03T10:30:49.099686903Z,10,2,16244,C,B,2,382.870000000,22,130,166082,4854290,382.990000000,383.090000000,30,6,1,1,382.880000000,383.100000000,20,11,1,1,382.810000000,383.300000000,10,20,1,1,382.750000000,383.340000000,10,23,1,1,382.720000000,383.420000000,10,140,1,1,382.700000000,383.600000000,50,1000,1,2,382.680000000,383.720000000,20,7085,1,8,382.230000000,383.740000000,25,37,1,1,382.110000000,383.800000000,300,10,1,1,382.100000000,383.880000000,20,4,2,1,TSLA
2025-01-03T10:30:49.102923842Z,2025-01-03T10:30:49.102757753Z,10,2,10888,C,B,1,420.650000000,15,130,166089,4854312,420.710000000,421.200000000,200,200,1,1,420.580000000,421.310000000,10,15,1,1,420.520000000,421.460000000,1,39,1,1,420.400000000,421.490000000,858,6,1,1,420.380000000,421.570000000,100,40,1,1,420.100000000,421.600000000,100,10,1,1,420.000000000,421.700000000,534,359,7,1,419.730000000,422.100000000,3,7,1,1,419.650000000,422.400000000,39,500,1,1,418.650000000,422.500000000,1,200,1,1,MSFT
2025-01-03T10:30:49.103045448Z,2025-01-03T10:30:49.102878813Z,10,2,10888,A,B,1,420.660000000,15,130,166635,4854313,420.710000000,421.200000000,200,200,1,1,420.660000000,421.310000000,15,15,1,1,420.580000000,421.460000000,10,39,1,1,420.520000000,421.490000000,1,6,1,1,420.400000000,421.570000000,858,40,1,1,420.380000000,421.600000000,100,10,1,1,420.100000000,421.700000000,100,359,1,1,420.000000000,422.100000000,534,7,7,1,419.730000000,422.400000000,3,500,1,1,419.650000000,422.500000000,39,200,1,1,MSFT
2025-01-03T10:30:49.196386184Z,2025-01-03T10:30:49.196218758Z,10,2,17709,A,A,2,107.880000000,100,130,167426,4854397,107.600000000,107.840000000,50,400,1,2,107.530000000,107.870000000,16,259,1,2,107.460000000,107.880000000,100,100,1,1,107.050000000,107.950000000,247,10,1,1,107.000000000,108.000000000,1,50,1,1,106.240000000,108.300000000,28,50,1,1,106.000000000,108.550000000,15,50,2,1,105.870000000,108.800000000,141,50,1,1,103.180000000,108.880000000,16,28,1,1,103.000000000,109.450000000,3,137,1,1,XOM
2025-01-03T10:30:50.440073243Z,2025-01-03T10:30:50.439907032Z,10,2,10888,C,A,0,421.200000000,200,130,166211,4855036,420.710000000,421.310000000,200,15,1,1,420.660000000,421.460000000,15,39,1,1,420.580000000,421.490000000,10,6,1,1,420.520000000,421.570000000,1,40,1,1,420.400000000,421.600000000,858,10,1,1,420.380000000,421.700000000,100,359,1,1,420.100000000,422.100000000,100,7,1,1,420.000000000,422.400000000,534,500,7,1,419.730000000,422.500000000,3,200,1,1,419.650000000,423.500000000,39,600,1,2,MSFT
2025-01-03T10:30:50.440086855Z,2025-01-03T10:30:50.439920235Z,10,2,10888,A,A,0,421.220000000,200,130,166620,4855037,420.710000000,421.220000000,200,200,1,1,420.660000000,421.310000000,15,15,1,1,420.580000000,421.460000000,10,39,1,1,420.520000000,421.490000000,1,6,1,1,420.400000000,421.570000000,858,40,1,1,420.380000000,421.600000000,100,10,1,1,420.100000000,421.700000000,100,359,1,1,420.000000000,422.100000000,534,7,7,1,419.730000000,422.400000000,3,500,1,1,419.650000000,422.500000000,39,200,1,1,MSFT
2025-01-03T10:30:50.481584929Z,2025-01-03T10:30:50.481418669Z,10,2,17709,A,B,2,107.520000000,100,130,166260,4855067,107.600000000,107.840000000,50,400,1,2,107.530000000,107.870000000,16,259,1,2,107.520000000,107.880000000,100,100,1,1,107.050000000,107.950000000,247,10,1,1,107.000000000,108.000000000,1,50,1,1,106.240000000,108.300000000,28,50,1,1,106.000000000,108.550000000,15,50,2,1,105.870000000,108.800000000,141,50,1,1,103.180000000,108.880000000,16,28,1,1,103.000000000,109.450000000,3,137,1,1,XOM
2025-01-03T10:30:50.498043993Z,2025-01-03T10:30:50.497877882Z,10,2,10888,A,A,0,421.210000000,200,130,166111,4855100,420.710000000,421.210000000,200,200,1,1,420.660000000,421.310000000,15,15,1,1,420.580000000,421.460000000,10,39,1,1,420.520000000,421.490000000,1,6,1,1,420.400000000,421.570000000,858,40,1,1,420.380000000,421.600000000,100,10,1,1,420.100000000,421.700000000,100,359,1,1,420.000000000,422.100000000,534,7,7,1,419.730000000,422.400000000,3,500,1,1,419.650000000,422.500000000,39,200,1,1,MSFT
2025-01-03T10:30:50.513942915Z,2025-01-03T10:30:50.513777041Z,10,2,6905,C,A,0,91.920000000,7,130,165874,4855151,91.520000000,91.960000000,7,100,1,1,91.480000000,93.000000000,150,1,1,1,91.440000000,94.000000000,100,1,1,1,90.000000000,95.000000000,122,2,1,2,89.000000000,96.000000000,1,1,1,1,83.810000000,97.000000000,100,2,1,2,83.400000000,99.950000000,100,100,1,1,,100.360000000,0,100,0,1,,,0,0,0,0,,,0,0,0,0,GILD
2025-01-03T10:30:50.514007033Z,2025-01-03T10:30:50.513840873Z,10,2,6905,A,A,0,91.930000000,7,130,166160,4855152,91.520000000,91.930000000,7,7,1,1,91.480000000,91.960000000,150,100,1,1,91.440000000,93.000000000,100,1,1,1,90.000000000,94.000000000,122,1,1,1,89.000000000,95.000000000,1,2,1,2,83.810000000,96.000000000,100,1,1,1,83.400000000,97.000000000,100,2,1,2,,99.950000000,0,100,0,1,,100.360000000,0,100,0,1,,,0,0,0,0,GILD
2025-01-03T10:30:50.518448028Z,2025-01-03T10:30:50.518282085Z,10,2,12463,C,A,0,150.790000000,9,130,165943,4855180,150.460000000,150.840000000,1,100,1,1,150.300000000,151.000000000,9,1,1,1,150.260000000,153.280000000,234,10,1,1,150.250000000,163.540000000,1,100,1,1,150.210000000,164.210000000,113,100,2,1,150.020000000,179.000000000,2,5,1,1,150.000000000,,250,0,1,0,149.950000000,,5,0,1,0,149.740000000,,10,0,1,0,149.000000000,,5,0,1,0,PEP
2025-01-03T10:30:50.518508525Z,2025-01-03T10:30:50.518342073Z,10,2,12463,A,A,0,150.810000000,9,130,166452,4855181,150.460000000,150.810000000,1,9,1,1,150.300000000,150.840000000,9,100,1,1,150.260000000,151.000000000,234,1,1,1,150.250000000,153.280000000,1,10,1,1,150.210000000,163.540000000,113,100,2,1,150.020000000,164.210000000,2,100,1,1,150.000000000,179.000000000,250,5,1,1,149.950000000,,5,0,1,0,149.740000000,,10,0,1,0,149.000000000,,5,0,1,0,PEP
2025-01-03T10:30:50.525243921Z,2025-01-03T10:30:50.525077294Z,10,2,16244,C,A,3,383.340000000,23,130,166627,4855216,382.990000000,383.090000000,30,6,1,1,382.880000000,383.100000000,20,11,1,1,382.810000000,383.300000000,10,20,1,1,382.750000000,383.420000000,10,140,1,1,382.720000000,383.600000000,10,1000,1,2,382.700000000,383.720000000,50,7085,1,8,382.680000000,383.740000000,20,37,1,1,382.230000000,383.800000000,25,10,1,1,382.110000000,383.880000000,300,4,1,1,382.100000000,384.000000000,20,1300,2,4,TSLA
2025-01-03T10:30:50.525304589Z,2025-01-03T10:30:50.525138368Z,10,2,16244,A,A,3,383.380000000,22,130,166221,4855217,382.990000000,383.090000000,30,6,1,1,382.880000000,383.100000000,20,11,1,1,382.810000000,383.300000000,10,20,1,1,382.750000000,383.380000000,10,22,1,1,382.720000000,383.420000000,10,140,1,1,382.700000000,383.600000000,50,1000,1,2,382.680000000,383.720000000,20,7085,1,8,382.230000000,383.740000000,25,37,1,1,382.110000000,383.800000000,300,10,1,1,382.100000000,383.880000000,20,4,2,1,TSLA
2025-01-03T10:30:51.178182483Z,2025-01-03T10:30:51.178016237Z,10,2,11667,A,B,3,139.110000000,400,130,166246,4855533,139.140000000,139.160000000,30,250,1,1,139.130000000,139.200000000,100,829,1,3,139.120000000,139.220000000,30,10,1,1,139.110000000,139.230000000,401,25,2,1,139.080000000,139.250000000,57,1,1,1,139.030000000,139.270000000,126,17,2,1,139.010000000,139.300000000,100,507,1,4,139.000000000,139.320000000,420,39,5,1,138.980000000,139.330000000,300,503,1,2,138.970000000,139.360000000,800,4,2,2,NVDA
2025-01-03T10:30:51.178333840Z,2025-01-03T10:30:51.178167447Z,10,2,38,A,B,1,243.460000000,400,130,166393,4855534,243.500000000,243.640000000,6,54,1,1,243.460000000,243.650000000,400,61,1,2,243.380000000,243.700000000,28,200,1,1,243.190000000,243.730000000,2,30,1,1,243.020000000,244.000000000,79,1,1,1,243.000000000,244.140000000,1243,79,9,1,242.990000000,244.200000000,1,1000,1,1,242.750000000,244.400000000,30,50,1,1,242.590000000,244.420000000,5,10,1,1,242.280000000,244.580000000,100,100,1,1,AAPL
2025-01-03T10:30:51.321902374Z,2025-01-03T10:30:51.321734867Z,10,2,9155,T,A,0,242.020000000,14,130,167507,4855582,242.020000000,242.070000000,34,62,1,1,242.000000000,242.500000000,200,8,1,1,241.790000000,242.850000000,8,300,1,2,241.670000000,242.900000000,2,100,1,1,241.120000000,243.000000000,81,92,1,2,241.000000000,243.310000000,100,10,1,1,240.000000000,243.700000000,10,100,1,1,238.000000000,246.810000000,30,100,1,1,236.000000000,262.740000000,6,100,1,1,235.500000000,263.830000000,5,100,1,1,JPM
2025-01-03T10:30:51.321902374Z,2025-01-03T10:30:51.321734867Z,10,2,9155,C,B,0,242.020000000,14,130,167507,4855582,242.020000000,242.070000000,20,62,1,1,242.000000000,242.500000000,200,8,1,1,241.790000000,242.850000000,8,300,1,2,241.670000000,242.900000000,2,100,1,1,241.120000000,243.000000000,81,92,1,2,241.000000000,243.310000000,100,10,1,1,240.000000000,243.700000000,10,100,1,1,238.000000000,246.810000000,30,100,1,1,236.000000000,262.740000000,6,100,1,1,235.500000000,263.830000000,5,100,1,1,JPM
2025-01-03T10:30:51.323622225Z,2025-01-03T10:30:51.323455027Z,10,2,9155,T,A,0,242.020000000,14,130,167198,4855584,242.020000000,242.070000000,20,62,1,1,242.000000000,242.500000000,200,8,1,1,241.790000000,242.850000000,8,300,1,2,241.670000000,242.900000000,2,100,1,1,241.120000000,243.000000000,81,92,1,2,241.000000000,243.310000000,100,10,1,1,240.000000000,243.700000000,10,100,1,1,238.000000000,246.810000000,30,100,1,1,236.000000000,262.740000000,6,100,1,1,235.500000000,263.830000000,5,100,1,1,JPM
2025-01-03T10:30:51.323622225Z,2025-01-03T10:30:51.323455027Z,10,2,9155,C,B,0,242.020000000,14,130,167198,4855584,242.020000000,242.070000000,6,62,1,1,242.000000000,242.500000000,200,8,1,1,241.790000000,242.850000000,8,300,1,2,241.670000000,242.900000000,2,100,1,1,241.120000000,243.000000000,81,92,1,2,241.000000000,243.310000000,100,10,1,1,240.000000000,243.700000000,10,100,1,1,238.000000000,246.810000000,30,100,1,1,236.000000000,262.740000000,6,100,1,1,235.500000000,263.830000000,5,100,1,1,JPM
2025-01-03T10:30:51.577538246Z,2025-01-03T10:30:51.577372061Z,10,2,10888,C,A,0,421.210000000,200,130,166185,4855637,420.710000000,421.310000000,200,15,1,1,420.660000000,421.460000000,15,39,1,1,420.580000000,421.490000000,10,6,1,1,420.520000000,421.570000000,1,40,1,1,420.400000000,421.600000000,858,10,1,1,420.380000000,421.700000000,100,359,1,1,420.100000000,422.100000000,100,7,1,1,420.000000000,422.400000000,534,500,7,1,419.730000000,422.500000000,3,200,1,1,419.650000000,423.500000000,39,600,1,2,MSFT
2025-01-03T10:30:51.613757074Z,2025-01-03T10:30:51.613590768Z,10,2,10888,A,A,0,421.290000000,200,130,166306,4855656,420.710000000,421.290000000,200,200,1,1,420.660000000,421.310000000,15,15,1,1,420.580000000,421.460000000,10,39,1,1,420.520000000,421.490000000,1,6,1,1,420.400000000,421.570000000,858,40,1,1,420.380000000,421.600000000,100,10,1,1,420.100000000,421.700000000,100,359,1,1,420.000000000,422.100000000,534,7,7,1,419.730000000,422.400000000,3,500,1,1,419.650000000,422.500000000,39,200,1,1,MSFT
2025-01-03T10:30:51.758419833Z,2025-01-03T10:30:51.758253465Z,10,2,16244,A,B,7,382.400000000,500,130,166368,4855688,382.990000000,383.090000000,30,6,1,1,382.880000000,383.100000000,20,11,1,1,382.810000000,383.300000000,10,20,1,1,382.750000000,383.380000000,10,22,1,1,382.720000000,383.420000000,10,140,1,1,382.700000000,383.600000000,50,1000,1,2,382.680000000,383.720000000,20,7085,1,8,382.400000000,383.740000000,500,37,1,1,382.230000000,383.800000000,25,10,1,1,382.110000000,383.880000000,300,4,1,1,TSLA
2025-01-03T10:30:51.785915070Z,2025-01-03T10:30:51.785748732Z,10,2,10888,C,B,0,420.710000000,200,130,166338,4855694,420.660000000,421.290000000,15,200,1,1,420.580000000,421.310000000,10,15,1,1,420.520000000,421.460000000,1,39,1,1,420.400000000,421.490000000,858,6,1,1,420.380000000,421.570000000,100,40,1,1,420.100000000,421.600000000,100,10,1,1,420.000000000,421.700000000,534,359,7,1,419.730000000,422.100000000,3,7,1,1,419.650000000,422.400000000,39,500,1,1,418.650000000,422.500000000,1,200,1,1,MSFT
2025-01-03T10:30:51.786754921Z,2025-01-03T10:30:51.786588954Z,10,2,10888,C,B,0,420.660000000,15,130,165967,4855695,420.580000000,421.290000000,10,200,1,1,420.520000000,421.310000000,1,15,1,1,420.400000000,421.460000000,858,39,1,1,420.380000000,421.490000000,100,6,1,1,420.100000000,421.570000000,100,40,1,1,420.000000000,421.600000000,534,10,7,1,419.730000000,421.700000000,3,359,1,1,419.650000000,422.100000000,39,7,1,1,418.650000000,422.400000000,1,500,1,1,418.500000000,422.500000000,1,200,1,1,MSFT
2025-01-03T10:30:51.786814741Z,2025-01-03T10:30:51.786648124Z,10,2,10888,A,B,0,420.610000000,13,130,166617,4855696,420.610000000,421.290000000,13,200,1,1,420.580000000,421.310000000,10,15,1,1,420.520000000,421.460000000,1,39,1,1,420.400000000,421.490000000,858,6,1,1,420.380000000,421.570000000,100,40,1,1,420.100000000,421.600000000,100,10,1,1,420.000000000,421.700000000,534,359,7,1,419.730000000,422.100000000,3,7,1,1,419.650000000,422.400000000,39,500,1,1,418.650000000,422.500000000,1,200,1,1,MSFT
2025-01-03T10:30:51.787407393Z,2025-01-03T10:30:51.787241515Z,10,2,10888,C,B,0,420.610000000,13,130,165878,4855697,420.580000000,421.290000000,10,200,1,1,420.520000000,421.310000000,1,15,1,1,420.400000000,421.460000000,858,39,1,1,420.380000000,421.490000000,100,6,1,1,420.100000000,421.570000000,100,40,1,1,420.000000000,421.600000000,534,10,7,1,419.730000000,421.700000000,3,359,1,1,419.650000000,422.100000000,39,7,1,1,418.650000000,422.400000000,1,500,1,1,418.500000000,422.500000000,1,200,1,1,MSFT
2025-01-03T10:30:51.833668617Z,2025-01-03T10:30:51.833502665Z,10,2,16244,C,A,3,383.380000000,22,130,165952,4855702,382.990000000,383.090000000,30,6,1,1,382.880000000,383.100000000,20,11,1,1,382.810000000,383.300000000,10,20,1,1,382.750000000,383.420000000,10,140,1,1,382.720000000,383.600000000,10,1000,1,2,382.700000000,383.720000000,50,7085,1,8,382.680000000,383.740000000,20,37,1,1,382.400000000,383.800000000,500,10,1,1,382.230000000,383.880000000,25,4,1,1,382.110000000,384.000000000,300,1300,1,4,TSLA
2025-01-03T10:30:51.833796770Z,2025-01-03T10:30:51.833630116Z,10,2,16244,A,A,2,383.270000000,19,130,166654,4855703,382.990000000,383.090000000,30,6,1,1,382.880000000,383.100000000,20,11,1,1,382.810000000,383.270000000,10,19,1,1,382.750000000,383.300000000,10,20,1,1,382.720000000,383.420000000,10,140,1,1,382.700000000,383.600000000,50,1000,1,2,382.680000000,383.720000000,20,7085,1,8,382.400000000,383.740000000,500,37,1,1,382.230000000,383.800000000,25,10,1,1,382.110000000,383.880000000,300,4,1,1,TSLA
2025-01-03T10:30:51.842720875Z,2025-01-03T10:30:51.842554578Z,10,2,16244,C,A,2,383.270000000,19,130,166297,4855704,382.990000000,383.090000000,30,6,1,1,382.880000000,383.100000000,20,11,1,1,382.810000000,383.300000000,10,20,1,1,382.750000000,383.420000000,10,140,1,1,382.720000000,383.600000000,10,1000,1,2,382.700000000,383.720000000,50,7085,1,8,382.680000000,383.740000000,20,37,1,1,382.400000000,383.800000000,500,10,1,1,382.230000000,383.880000000,25,4,1,1,382.110000000,384.000000000,300,1300,1,4,TSLA
2025-01-03T10:30:51.842791193Z,2025-01-03T10:30:51.842624848Z,10,2,10888,A,B,0,420.580000000,200,130,166345,4855705,420.580000000,421.290000000,210,200,2,1,420.520000000,421.310000000,1,15,1,1,420.400000000,421.460000000,858,39,1,1,420.380000000,421.490000000,100,6,1,1,420.100000000,421.570000000,100,40,1,1,420.000000000,421.600000000,534,10,7,1,419.730000000,421.700000000,3,359,1,1,419.650000000,422.100000000,39,7,1,1,418.650000000,422.400000000,1,500,1,1,418.500000000,422.500000000,1,200,1,1,MSFT
2025-01-03T10:30:51.858146530Z,2025-01-03T10:30:51.857980241Z,10,2,10888,C,B,0,420.580000000,200,130,166289,4855708,420.580000000,421.290000000,10,200,1,1,420.520000000,421.310000000,1,15,1,1,420.400000000,421.460000000,858,39,1,1,420.380000000,421.490000000,100,6,1,1,420.100000000,421.570000000,100,40,1,1,420.000000000,421.600000000,534,10,7,1,419.730000000,421.700000000,3,359,1,1,419.650000000,422.100000000,39,7,1,1,418.650000000,422.400000000,1,500,1,1,418.500000000,422.500000000,1,200,1,1,MSFT
2025-01-03T10:30:51.858159817Z,2025-01-03T10:30:51.857993223Z,10,2,10888,A,B,1,420.550000000,200,130,166594,4855709,420.580000000,421.290000000,10,200,1,1,420.550000000,421.310000000,200,15,1,1,420.520000000,421.460000000,1,39,1,1,420.400000000,421.490000000,858,6,1,1,420.380000000,421.570000000,100,40,1,1,420.100000000,421.600000000,100,10,1,1,420.000000000,421.700000000,534,359,7,1,419.730000000,422.100000000,3,7,1,1,419.650000000,422.400000000,39,500,1,1,418.650000000,422.500000000,1,200,1,1,MSFT
2025-01-03T10:30:52.340123835Z,2025-01-03T10:30:52.339957092Z,10,2,16244,A,A,3,383.330000000,21,130,166743,4855866,382.990000000,383.090000000,30,6,1,1,382.880000000,383.100000000,20,11,1,1,382.810000000,383.300000000,10,20,1,1,382.750000000,383.330000000,10,21,1,1,382.720000000,383.420000000,10,140,1,1,382.700000000,383.600000000,50,1000,1,2,382.680000000,383.720000000,20,7085,1,8,382.400000000,383.740000000,500,37,1,1,382.230000000,383.800000000,25,10,1,1,382.110000000,383.880000000,300,4,1,1,TSLA
2025-01-03T10:30:53.245799612Z,2025-01-03T10:30:53.245630826Z,10,2,11667,T,A,0,139.140000000,30,0,168786,4856152,139.140000000,139.160000000,30,250,1,1,139.130000000,139.200000000,100,829,1,3,139.120000000,139.220000000,30,10,1,1,139.110000000,139.230000000,401,25,2,1,139.080000000,139.250000000,57,1,1,1,139.030000000,139.270000000,126,17,2,1,139.010000000,139.300000000,100,507,1,4,139.000000000,139.320000000,420,39,5,1,138.980000000,139.330000000,300,503,1,2,138.970000000,139.360000000,800,4,2,2,NVDA
2025-01-03T10:30:53.245799612Z,2025-01-03T10:30:53.245630826Z,10,2,11667,T,N,0,139.140000000,70,130,168786,4856153,139.130000000,139.160000000,100,250,1,1,139.120000000,139.200000000,30,829,1,3,139.110000000,139.220000000,401,10,2,1,139.080000000,139.230000000,57,25,1,1,139.030000000,139.250000000,126,1,2,1,139.010000000,139.270000000,100,17,1,1,139.000000000,139.300000000,420,507,5,4,138.980000000,139.320000000,300,39,1,1,138.970000000,139.330000000,800,503,2,2,138.940000000,139.360000000,400,4,1,2,NVDA
2025-01-03T10:30:53.245861452Z,2025-01-03T10:30:53.245695164Z,10,2,11667,C,B,2,139.110000000,400,130,166288,4856161,139.130000000,139.160000000,100,250,1,1,139.120000000,139.200000000,30,829,1,3,139.110000000,139.220000000,1,10,1,1,139.080000000,139.230000000,57,25,1,1,139.030000000,139.250000000,126,1,2,1,139.010000000,139.270000000,100,17,1,1,139.000000000,139.300000000,420,507,5,4,138.980000000,139.320000000,300,39,1,1,138.970000000,139.330000000,800,503,2,2,138.940000000,139.360000000,400,4,1,2,NVDA
2025-01-03T10:30:53.305313627Z,2025-01-03T10:30:53.305147274Z,10,2,11667,A,B,3,139.080000000,400,130,166353,4856202,139.130000000,139.160000000,100,250,1,1,139.120000000,139.200000000,30,829,1,3,139.110000000,139.220000000,1,10,1,1,139.080000000,139.230000000,457,25,2,1,139.030000000,139.250000000,126,1,2,1,139.010000000,139.270000000,100,17,1,1,139.000000000,139.300000000,420,507,5,4,138.980000000,139.320000000,300,39,1,1,138.970000000,139.330000000,800,503,2,2,138.940000000,139.360000000,400,4,1,2,NVDA
2025-01-03T10:30:53.313452207Z,2025-01-03T10:30:53.313286245Z,10,2,11667,C,B,3,139.080000000,400,130,165962,4856205,139.130000000,139.160000000,100,250,1,1,139.120000000,139.200000000,30,829,1,3,139.110000000,139.220000000,1,10,1,1,139.080000000,139.230000000,57,25,1,1,139.030000000,139.250000000,126,1,2,1,139.010000000,139.270000000,100,17,1,1,139.000000000,139.300000000,420,507,5,4,138.980000000,139.320000000,300,39,1,1,138.970000000,139.330000000,800,503,2,2,138.940000000,139.360000000,400,4,1,2,NVDA
2025-01-03T10:30:53.313465751Z,2025-01-03T10:30:53.313299325Z,10,2,11667,A,B,4,139.060000000,400,130,166426,4856206,139.130000000,139.160000000,100,250,1,1,139.120000000,139.200000000,30,829,1,3,139.110000000,139.220000000,1,10,1,1,139.080000000,139.230000000,57,25,1,1,139.060000000,139.250000000,400,1,1,1,139.030000000,139.270000000,126,17,2,1,139.010000000,139.300000000,100,507,1,4,139.000000000,139.320000000,420,39,5,1,138.980000000,139.330000000,300,503,1,2,138.970000000,139.360000000,800,4,2,2,NVDA
2025-01-03T10:30:53.317182621Z,2025-01-03T10:30:53.317016412Z,10,2,11667,A,A,9,139.360000000,10,130,166209,4856207,139.130000000,139.160000000,100,250,1,1,139.120000000,139.200000000,30,829,1,3,139.110000000,139.220000000,1,10,1,1,139.080000000,139.230000000,57,25,1,1,139.060000000,139.250000000,400,1,1,1,139.030000000,139.270000000,126,17,2,1,139.010000000,139.300000000,100,507,1,4,139.000000000,139.320000000,420,39,5,1,138.980000000,139.330000000,300,503,1,2,138.970000000,139.360000000,800,14,2,3,NVDA
2025-01-03T10:30:53.379381356Z,2025-01-03T10:30:53.379214414Z,10,2,16244,T,A,0,382.990000000,30,130,166942,4856257,382.990000000,383.090000000,30,6,1,1,382.880000000,383.100000000,20,11,1,1,382.810000000,383.300000000,10,20,1,1,382.750000000,383.330000000,10,21,1,1,382.720000000,383.420000000,10,140,1,1,382.700000000,383.600000000,50,1000,1,2,382.680000000,383.720000000,20,7085,1,8,382.400000000,383.740000000,500,37,1,1,382.230000000,383.800000000,25,10,1,1,382.110000000,383.880000000,300,4,1,1,TSLA
2025-01-03T10:30:53.379381356Z,2025-01-03T10:30:53.379214414Z,10,2,16244,C,B,0,382.990000000,30,130,166942,4856257,382.880000000,383.090000000,20,6,1,1,382.810000000,383.100000000,10,11,1,1,382.750000000,383.300000000,10,20,1,1,382.720000000,383.330000000,10,21,1,1,382.700000000,383.420000000,50,140,1,1,382.680000000,383.600000000,20,1000,1,2,382.400000000,383.720000000,500,7085,1,8,382.230000000,383.740000000,25,37,1,1,382.110000000,383.800000000,300,10,1,1,382.100000000,383.880000000,20,4,2,1,TSLA
2025-01-03T10:30:53.379696335Z,2025-01-03T10:30:53.379530536Z,10,2,16244,C,B,6,382.400000000,500,130,165799,4856261,382.880000000,383.090000000,20,6,1,1,382.810000000,383.100000000,10,11,1,1,382.750000000,383.300000000,10,20,1,1,382.720000000,383.330000000,10,21,1,1,382.700000000,383.420000000,50,140,1,1,382.680000000,383.600000000,20,1000,1,2,382.230000000,383.720000000,25,7085,1,8,382.110000000,383.740000000,300,37,1,1,382.100000000,383.800000000,20,10,2,1,382.010000000,383.880000000,2,4,1,1,TSLA
2025-01-03T10:30:53.380544533Z,2025-01-03T10:30:53.380378362Z,10,2,11667,A,A,0,139.160000000,400,130,166171,4856266,139.130000000,139.160000000,100,650,1,2,139.120000000,139.200000000,30,429,1,2,139.110000000,139.220000000,1,10,1,1,139.080000000,139.230000000,57,25,1,1,139.060000000,139.250000000,400,1,1,1,139.030000000,139.270000000,126,17,2,1,139.010000000,139.300000000,100,507,1,4,139.000000000,139.320000000,420,39,5,1,138.980000000,139.330000000,300,503,1,2,138.970000000,139.360000000,800,14,2,3,NVDA
2025-01-03T10:30:53.818828383Z,2025-01-03T10:30:53.818662436Z,10,2,17709,C,B,1,107.530000000,16,130,165947,4856374,107.600000000,107.840000000,50,400,1,2,107.520000000,107.870000000,100,259,1,2,107.050000000,107.880000000,247,100,1,1,107.000000000,107.950000000,1,10,1,1,106.240000000,108.000000000,28,50,1,1,106.000000000,108.300000000,15,50,2,1,105.870000000,108.550000000,141,50,1,1,103.180000000,108.800000000,16,50,1,1,103.000000000,108.880000000,3,28,1,1,102.000000000,109.450000000,2,137,1,1,XOM
2025-01-03T10:30:53.818858503Z,2025-01-03T10:30:53.818692751Z,10,2,17709,C,A,1,107.870000000,17,130,165752,4856375,107.600000000,107.840000000,50,400,1,2,107.520000000,107.870000000,100,242,1,1,107.050000000,107.880000000,247,100,1,1,107.000000000,107.950000000,1,10,1,1,106.240000000,108.000000000,28,50,1,1,106.000000000,108.300000000,15,50,2,1,105.870000000,108.550000000,141,50,1,1,103.180000000,108.800000000,16,50,1,1,103.000000000,108.880000000,3,28,1,1,102.000000000,109.450000000,2,137,1,1,XOM
2025-01-03T10:30:53.818920682Z,2025-01-03T10:30:53.818754149Z,10,2,17709,A,A,0,107.840000000,16,130,166533,4856376,107.600000000,107.840000000,50,416,1,3,107.520000000,107.870000000,100,242,1,1,107.050000000,107.880000000,247,100,1,1,107.000000000,107.950000000,1,10,1,1,106.240000000,108.000000000,28,50,1,1,106.000000000,108.300000000,15,50,2,1,105.870000000,108.550000000,141,50,1,1,103.180000000,108.800000000,16,50,1,1,103.000000000,108.880000000,3,28,1,1,102.000000000,109.450000000,2,137,1,1,XOM
2025-01-03T10:30:53.818976639Z,2025-01-03T10:30:53.818810618Z,10,2,17709,A,B,1,107.540000000,17,130,166021,4856377,107.600000000,107.840000000,50,416,1,3,107.540000000,107.870000000,17,242,1,1,107.520000000,107.880000000,100,100,1,1,107.050000000,107.950000000,247,10,1,1,107.000000000,108.000000000,1,50,1,1,106.240000000,108.300000000,28,50,1,1,106.000000000,108.550000000,15,50,2,1,105.870000000,108.800000000,141,50,1,1,103.180000000,108.880000000,16,28,1,1,103.000000000,109.450000000,3,137,1,1,XOM
2025-01-03T10:30:53.877878927Z,2025-01-03T10:30:53.877712964Z,10,2,9155,C,B,2,241.790000000,8,130,165963,4856393,242.020000000,242.070000000,6,62,1,1,242.000000000,242.500000000,200,8,1,1,241.670000000,242.850000000,2,300,1,2,241.120000000,242.900000000,81,100,1,1,241.000000000,243.000000000,100,92,1,2,240.000000000,243.310000000,10,10,1,1,238.000000000,243.700000000,30,100,1,1,236.000000000,246.810000000,6,100,1,1,235.500000000,262.740000000,5,100,1,1,235.000000000,263.830000000,5,100,1,1,JPM
2025-01-03T10:30:53.877938826Z,2025-01-03T10:30:53.877772542Z,10,2,9155,A,B,2,241.800000000,8,130,166284,4856394,242.020000000,242.070000000,6,62,1,1,242.000000000,242.500000000,200,8,1,1,241.800000000,242.850000000,8,300,1,2,241.670000000,242.900000000,2,100,1,1,241.120000000,243.000000000,81,92,1,2,241.000000000,243.310000000,100,10,1,1,240.000000000,243.700000000,10,100,1,1,238.000000000,246.810000000,30,100,1,1,236.000000000,262.740000000,6,100,1,1,235.500000000,263.830000000,5,100,1,1,JPM
2025-01-03T10:30:53.891680864Z,2025-01-03T10:30:53.891514581Z,10,2,10888,A,B,1,420.560000000,13,130,166283,4856395,420.580000000,421.290000000,10,200,1,1,420.560000000,421.310000000,13,15,1,1,420.550000000,421.460000000,200,39,1,1,420.520000000,421.490000000,1,6,1,1,420.400000000,421.570000000,858,40,1,1,420.380000000,421.600000000,100,10,1,1,420.100000000,421.700000000,100,359,1,1,420.000000000,422.100000000,534,7,7,1,419.730000000,422.400000000,3,500,1,1,419.650000000,422.500000000,39,200,1,1,MSFT
2025-01-03T10:30:54.155130241Z,2025-01-03T10:30:54.154962466Z,10,2,16244,T,N,0,383.030000000,5,130,167775,4856583,382.880000000,383.090000000,20,6,1,1,382.810000000,383.100000000,10,11,1,1,382.750000000,383.300000000,10,20,1,1,382.720000000,383.330000000,10,21,1,1,382.700000000,383.420000000,50,140,1,1,382.680000000,383.600000000,20,1000,1,2,382.230000000,383.720000000,25,7085,1,8,382.110000000,383.740000000,300,37,1,1,382.100000000,383.800000000,20,10,2,1,382.010000000,383.880000000,2,4,1,1,TSLA
2025-01-03T10:30:54.272117869Z,2025-01-03T10:30:54.271951244Z,10,2,10888,A,A,0,421.280000000,200,130,166625,4856628,420.580000000,421.280000000,10,200,1,1,420.560000000,421.310000000,13,15,1,1,420.550000000,421.460000000,200,39,1,1,420.520000000,421.490000000,1,6,1,1,420.400000000,421.570000000,858,40,1,1,420.380000000,421.600000000,100,10,1,1,420.100000000,421.700000000,100,359,1,1,420.000000000,422.100000000,534,7,7,1,419.730000000,422.400000000,3,500,1,1,419.650000000,422.500000000,39,200,1,1,MSFT
2025-01-03T10:30:54.356125682Z,2025-01-03T10:30:54.355959362Z,10,2,10888,A,A,0,421.270000000,200,130,166320,4856642,420.580000000,421.270000000,10,200,1,1,420.560000000,421.310000000,13,15,1,1,420.550000000,421.460000000,200,39,1,1,420.520000000,421.490000000,1,6,1,1,420.400000000,421.570000000,858,40,1,1,420.380000000,421.600000000,100,10,1,1,420.100000000,421.700000000,100,359,1,1,420.000000000,422.100000000,534,7,7,1,419.730000000,422.400000000,3,500,1,1,419.650000000,422.500000000,39,200,1,1,MSFT
2025-01-03T10:30:54.561779701Z,2025-01-03T10:30:54.561613871Z,10,2,16244,C,B,2,382.750000000,10,130,165830,4856766,382.880000000,383.090000000,20,6,1,1,382.810000000,383.100000000,10,11,1,1,382.720000000,383.300000000,10,20,1,1,382.700000000,383.330000000,50,21,1,1,382.680000000,383.420000000,20,140,1,1,382.230000000,383.600000000,25,1000,1,2,382.110000000,383.720000000,300,7085,1,8,382.100000000,383.740000000,20,37,2,1,382.010000000,383.800000000,2,10,1,1,382.000000000,383.880000000,1192,4,10,1,TSLA
2025-01-03T10:30:54.562796263Z,2025-01-03T10:30:54.562629697Z,10,2,16244,A,B,1,382.810000000,10,130,166566,4856775,382.880000000,383.090000000,20,6,1,1,382.810000000,383.100000000,20,11,2,1,382.720000000,383.300000000,10,20,1,1,382.700000000,383.330000000,50,21,1,1,382.680000000,383.420000000,20,140,1,1,382.230000000,383.600000000,25,1000,1,2,382.110000000,383.720000000,300,7085,1,8,382.100000000,383.740000000,20,37,2,1,382.010000000,383.800000000,2,10,1,1,382.000000000,383.880000000,1192,4,10,1,TSLA
2025-01-03T10:30:54.618929918Z,2025-01-03T10:30:54.618763770Z,10,2,16244,C,B,0,382.880000000,20,130,166148,4856824,382.810000000,383.090000000,20,6,2,1,382.720000000,383.100000000,10,11,1,1,382.700000000,383.300000000,50,20,1,1,382.680000000,383.330000000,20,21,1,1,382.230000000,383.420000000,25,140,1,1,382.110000000,383.600000000,300,1000,1,2,382.100000000,383.720000000,20,7085,2,8,382.010000000,383.740000000,2,37,1,1,382.000000000,383.800000000,1192,10,10,1,381.900000000,383.880000000,23,4,1,1,TSLA
2025-01-03T10:30:54.619021469Z,2025-01-03T10:30:54.618855026Z,10,2,16244,A,B,0,382.890000000,22,130,166443,4856825,382.890000000,383.090000000,22,6,1,1,382.810000000,383.100000000,20,11,2,1,382.720000000,383.300000000,10,20,1,1,382.700000000,383.330000000,50,21,1,1,382.680000000,383.420000000,20,140,1,1,382.230000000,383.600000000,25,1000,1,2,382.110000000,383.720000000,300,7085,1,8,382.100000000,383.740000000,20,37,2,1,382.010000000,383.800000000,2,10,1,1,382.000000000,383.880000000,1192,4,10,1,TSLA
2025-01-03T10:30:54.622947779Z,2025-01-03T10:30:54.622781851Z,10,2,16727,C,B,0,314.910000000,8,130,165928,4856852,314.860000000,315.450000000,25,8,1,1,314.420000000,315.510000000,61,25,1,1,313.500000000,315.750000000,1,61,1,1,310.000000000,320.000000000,1,5,1,1,300.000000000,320.210000000,3,1,1,1,290.000000000,321.950000000,2,2,1,1,286.660000000,344.200000000,100,100,1,1,285.250000000,345.620000000,100,100,1,1,260.000000000,,2,0,1,0,,,0,0,0,0,V
2025-01-03T10:30:54.623009521Z,2025-01-03T10:30:54.622843241Z,10,2,16727,A,B,0,314.920000000,8,130,166280,4856853,314.920000000,315.450000000,8,8,1,1,314.860000000,315.510000000,25,25,1,1,314.420000000,315.750000000,61,61,1,1,313.500000000,320.000000000,1,5,1,1,310.000000000,320.210000000,1,1,1,1,300.000000000,321.950000000,3,2,1,1,290.000000000,344.200000000,2,100,1,1,286.660000000,345.620000000,100,100,1,1,285.250000000,,100,0,1,0,260.000000000,,2,0,1,0,V
2025-01-03T10:30:54.623200867Z,2025-01-03T10:30:54.623034673Z,10,2,12463,C,B,1,150.300000000,9,130,166194,4856856,150.460000000,150.810000000,1,9,1,1,150.260000000,150.840000000,234,100,1,1,150.250000000,151.000000000,1,1,1,1,150.210000000,153.280000000,113,10,2,1,150.020000000,163.540000000,2,100,1,1,150.000000000,164.210000000,250,100,1,1,149.950000000,179.000000000,5,5,1,1,149.740000000,,10,0,1,0,149.000000000,,5,0,1,0,140.000000000,,10,0,1,0,PEP
2025-01-03T10:30:54.623367258Z,2025-01-03T10:30:54.623201188Z,10,2,12463,A,B,1,150.310000000,9,130,166070,4856857,150.460000000,150.810000000,1,9,1,1,150.310000000,150.840000000,9,100,1,1,150.260000000,151.000000000,234,1,1,1,150.250000000,153.280000000,1,10,1,1,150.210000000,163.540000000,113,100,2,1,150.020000000,164.210000000,2,100,1,1,150.000000000,179.000000000,250,5,1,1,149.950000000,,5,0,1,0,149.740000000,,10,0,1,0,149.000000000,,5,0,1,0,PEP
2025-01-03T10:30:54.625935133Z,2025-01-03T10:30:54.625769089Z,10,2,38,C,B,2,243.380000000,28,130,166044,4856884,243.500000000,243.640000000,6,54,1,1,243.460000000,243.650000000,400,61,1,2,243.190000000,243.700000000,2,200,1,1,243.020000000,243.730000000,79,30,1,1,243.000000000,244.000000000,1243,1,9,1,242.990000000,244.140000000,1,79,1,1,242.750000000,244.200000000,30,1000,1,1,242.590000000,244.400000000,5,50,1,1,242.280000000,244.420000000,100,10,1,1,242.170000000,244.580000000,100,100,1,1,AAPL
2025-01-03T10:30:54.626118297Z,2025-01-03T10:30:54.625951782Z,10,2,38,A,B,2,243.390000000,28,130,166515,4856885,243.500000000,243.640000000,6,54,1,1,243.460000000,243.650000000,400,61,1,2,243.390000000,243.700000000,28,200,1,1,243.190000000,243.730000000,2,30,1,1,243.020000000,244.000000000,79,1,1,1,243.000000000,244.140000000,1243,79,9,1,242.990000000,244.200000000,1,1000,1,1,242.750000000,244.400000000,30,50,1,1,242.590000000,244.420000000,5,10,1,1,242.280000000,244.580000000,100,100,1,1,AAPL
2025-01-03T10:30:54.632172525Z,2025-01-03T10:30:54.632005926Z,10,2,10888,A,A,0,421.250000000,200,130,166599,4856889,420.580000000,421.250000000,10,200,1,1,420.560000000,421.310000000,13,15,1,1,420.550000000,421.460000000,200,39,1,1,420.520000000,421.490000000,1,6,1,1,420.400000000,421.570000000,858,40,1,1,420.380000000,421.600000000,100,10,1,1,420.100000000,421.700000000,100,359,1,1,420.000000000,422.100000000,534,7,7,1,419.730000000,422.400000000,3,500,1,1,419.650000000,422.500000000,39,200,1,1,MSFT
2025-01-03T10:30:54.705536903Z,2025-01-03T10:30:54.705370389Z,10,2,38,A,A,4,243.760000000,27,130,166514,4856934,243.500000000,243.640000000,6,54,1,1,243.460000000,243.650000000,400,61,1,2,243.390000000,243.700000000,28,200,1,1,243.190000000,243.730000000,2,30,1,1,243.020000000,243.760000000,79,27,1,1,243.000000000,244.000000000,1243,1,9,1,242.990000000,244.140000000,1,79,1,1,242.750000000,244.200000000,30,1000,1,1,242.590000000,244.400000000,5,50,1,1,242.280000000,244.420000000,100,10,1,1,AAPL
2025-01-03T10:30:54.705559260Z,2025-01-03T10:30:54.705393344Z,10,2,38,C,A,3,243.730000000,30,130,165916,4856935,243.500000000,243.640000000,6,54,1,1,243.460000000,243.650000000,400,61,1,2,243.390000000,243.700000000,28,200,1,1,243.190000000,243.760000000,2,27,1,1,243.020000000,244.000000000,79,1,1,1,243.000000000,244.140000000,1243,79,9,1,242.990000000,244.200000000,1,1000,1,1,242.750000000,244.400000000,30,50,1,1,242.590000000,244.420000000,5,10,1,1,242.280000000,244.580000000,100,100,1,1,AAPL
2025-01-03T10:30:54.846199992Z,2025-01-03T10:30:54.846033343Z,10,2,10888,A,B,0,420.700000000,200,130,166649,4857106,420.700000000,421.250000000,200,200,1,1,420.580000000,421.310000000,10,15,1,1,420.560000000,421.460000000,13,39,1,1,420.520000000,421.490000000,1,6,1,1,420.400000000,421.570000000,858,40,1,1,420.380000000,421.600000000,100,10,1,1,420.100000000,421.700000000,100,359,1,1,420.000000000,422.100000000,534,7,7,1,419.730000000,422.400000000,3,500,1,1,419.650000000,422.500000000,39,200,1,1,MSFT
2025-01-03T10:30:55.337038598Z,2025-01-03T10:30:55.336871391Z,10,2,11667,T,B,0,139.160000000,20,130,167207,4857559,139.130000000,139.160000000,100,650,1,2,139.120000000,139.200000000,30,429,1,2,139.110000000,139.220000000,1,10,1,1,139.080000000,139.230000000,57,25,1,1,139.060000000,139.250000000,400,1,1,1,139.030000000,139.270000000,126,17,2,1,139.010000000,139.300000000,100,507,1,4,139.000000000,139.320000000,420,39,5,1,138.980000000,139.330000000,300,503,1,2,138.970000000,139.360000000,800,14,2,3,NVDA
2025-01-03T10:30:55.337038598Z,2025-01-03T10:30:55.336871391Z,10,2,11667,C,A,0,139.160000000,20,130,167207,4857559,139.130000000,139.160000000,100,630,1,2,139.120000000,139.200000000,30,429,1,2,139.110000000,139.220000000,1,10,1,1,139.080000000,139.230000000,57,25,1,1,139.060000000,139.250000000,400,1,1,1,139.030000000,139.270000000,126,17,2,1,139.010000000,139.300000000,100,507,1,4,139.000000000,139.320000000,420,39,5,1,138.980000000,139.330000000,300,503,1,2,138.970000000,139.360000000,800,14,2,3,NVDA
2025-01-03T10:30:55.337092371Z,2025-01-03T10:30:55.336926359Z,10,2,11667,C,A,0,139.160000000,400,130,166012,4857560,139.130000000,139.160000000,100,230,1,1,139.120000000,139.200000000,30,429,1,2,139.110000000,139.220000000,1,10,1,1,139.080000000,139.230000000,57,25,1,1,139.060000000,139.250000000,400,1,1,1,139.030000000,139.270000000,126,17,2,1,139.010000000,139.300000000,100,507,1,4,139.000000000,139.320000000,420,39,5,1,138.980000000,139.330000000,300,503,1,2,138.970000000,139.360000000,800,14,2,3,NVDA
2025-01-03T10:30:55.446021916Z,2025-01-03T10:30:55.445855595Z,10,2,11667,A,A,0,139.160000000,400,130,166321,4857640,139.130000000,139.160000000,100,630,1,2,139.120000000,139.200000000,30,429,1,2,139.110000000,139.220000000,1,10,1,1,139.080000000,139.230000000,57,25,1,1,139.060000000,139.250000000,400,1,1,1,139.030000000,139.270000000,126,17,2,1,139.010000000,139.300000000,100,507,1,4,139.000000000,139.320000000,420,39,5,1,138.980000000,139.330000000,300,503,1,2,138.970000000,139.360000000,800,14,2,3,NVDA
2025-01-03T10:30:55.733980687Z,2025-01-03T10:30:55.733811850Z,10,2,9155,T,A,0,242.020000000,6,0,168837,4857712,242.020000000,242.070000000,6,62,1,1,242.000000000,242.500000000,200,8,1,1,241.800000000,242.850000000,8,300,1,2,241.670000000,242.900000000,2,100,1,1,241.120000000,243.000000000,81,92,1,2,241.000000000,243.310000000,100,10,1,1,240.000000000,243.700000000,10,100,1,1,238.000000000,246.810000000,30,100,1,1,236.000000000,262.740000000,6,100,1,1,235.500000000,263.830000000,5,100,1,1,JPM
2025-01-03T10:30:55.733980687Z,2025-01-03T10:30:55.733811850Z,10,2,9155,T,A,0,242.000000000,194,130,168837,4857713,242.000000000,242.070000000,200,62,1,1,241.800000000,242.500000000,8,8,1,1,241.670000000,242.850000000,2,300,1,2,241.120000000,242.900000000,81,100,1,1,241.000000000,243.000000000,100,92,1,2,240.000000000,243.310000000,10,10,1,1,238.000000000,243.700000000,30,100,1,1,236.000000000,246.810000000,6,100,1,1,235.500000000,262.740000000,5,100,1,1,235.000000000,263.830000000,5,100,1,1,JPM
2025-01-03T10:30:55.733980687Z,2025-01-03T10:30:55.733811850Z,10,2,9155,C,B,0,242.000000000,194,130,168837,4857713,242.000000000,242.070000000,6,62,1,1,241.800000000,242.500000000,8,8,1,1,241.670000000,242.850000000,2,300,1,2,241.120000000,242.900000000,81,100,1,1,241.000000000,243.000000000,100,92,1,2,240.000000000,243.310000000,10,10,1,1,238.000000000,243.700000000,30,100,1,1,236.000000000,246.810000000,6,100,1,1,235.500000000,262.740000000,5,100,1,1,235.000000000,263.830000000,5,100,1,1,JPM
2025-01-03T10:30:55.734029741Z,2025-01-03T10:30:55.733862015Z,10,2,9155,T,A,0,242.000000000,6,130,167726,4857714,242.000000000,242.070000000,6,62,1,1,241.800000000,242.500000000,8,8,1,1,241.670000000,242.850000000,2,300,1,2,241.120000000,242.900000000,81,100,1,1,241.000000000,243.000000000,100,92,1,2,240.000000000,243.310000000,10,10,1,1,238.000000000,243.700000000,30,100,1,1,236.000000000,246.810000000,6,100,1,1,235.500000000,262.740000000,5,100,1,1,235.000000000,263.830000000,5,100,1,1,JPM
2025-01-03T10:30:55.734029741Z,2025-01-03T10:30:55.733862015Z,10,2,9155,C,B,0,242.000000000,6,130,167726,4857714,241.800000000,242.070000000,8,62,1,1,241.670000000,242.500000000,2,8,1,1,241.120000000,242.850000000,81,300,1,2,241.000000000,242.900000000,100,100,1,1,240.000000000,243.000000000,10,92,1,2,238.000000000,243.310000000,30,10,1,1,236.000000000,243.700000000,6,100,1,1,235.500000000,246.810000000,5,100,1,1,235.000000000,262.740000000,5,100,1,1,232.880000000,263.830000000,1,100,1,1,JPM
2025-01-03T10:30:55.734818711Z,2025-01-03T10:30:55.734652679Z,10,2,9155,A,A,1,242.200000000,1,130,166032,4857715,241.800000000,242.070000000,8,62,1,1,241.670000000,242.200000000,2,1,1,1,241.120000000,242.500000000,81,8,1,1,241.000000000,242.850000000,100,300,1,2,240.000000000,242.900000000,10,100,1,1,238.000000000,243.000000000,30,92,1,2,236.000000000,243.310000000,6,10,1,1,235.500000000,243.700000000,5,100,1,1,235.000000000,246.810000000,5,100,1,1,232.880000000,262.740000000,1,100,1,1,JPM
2025-01-03T10:30:55.734831917Z,2025-01-03T10:30:55.734665918Z,10,2,9155,A,A,2,242.390000000,1,130,165999,4857716,241.800000000,242.070000000,8,62,1,1,241.670000000,242.200000000,2,1,1,1,241.120000000,242.390000000,81,1,1,1,241.000000000,242.500000000,100,8,1,1,240.000000000,242.850000000,10,300,1,2,238.000000000,242.900000000,30,100,1,1,236.000000000,243.000000000,6,92,1,2,235.500000000,243.310000000,5,10,1,1,235.000000000,243.700000000,5,100,1,1,232.880000000,246.810000000,1,100,1,1,JPM
2025-01-03T10:30:55.749734191Z,2025-01-03T10:30:55.749568039Z,10,2,9155,C,A,1,242.200000000,1,130,166152,4857718,241.800000000,242.070000000,8,62,1,1,241.670000000,242.390000000,2,1,1,1,241.120000000,242.500000000,81,8,1,1,241.000000000,242.850000000,100,300,1,2,240.000000000,242.900000000,10,100,1,1,238.000000000,243.000000000,30,92,1,2,236.000000000,243.310000000,6,10,1,1,235.500000000,243.700000000,5,100,1,1,235.000000000,246.810000000,5,100,1,1,232.880000000,262.740000000,1,100,1,1,JPM
2025-01-03T10:30:55.789734089Z,2025-01-03T10:30:55.789568091Z,10,2,9155,C,A,1,242.390000000,1,130,165998,4857727,241.800000000,242.070000000,8,62,1,1,241.670000000,242.500000000,2,8,1,1,241.120000000,242.850000000,81,300,1,2,241.000000000,242.900000000,100,100,1,1,240.000000000,243.000000000,10,92,1,2,238.000000000,243.310000000,30,10,1,1,236.000000000,243.700000000,6,100,1,1,235.500000000,246.810000000,5,100,1,1,235.000000000,262.740000000,5,100,1,1,232.880000000,263.830000000,1,100,1,1,JPM
2025-01-03T10:30:55.806043523Z,2025-01-03T10:30:55.805877494Z,10,2,9155,C,B,0,241.800000000,8,130,166029,4857731,241.670000000,242.070000000,2,62,1,1,241.120000000,242.500000000,81,8,1,1,241.000000000,242.850000000,100,300,1,2,240.000000000,242.900000000,10,100,1,1,238.000000000,243.000000000,30,92,1,2,236.000000000,243.310000000,6,10,1,1,235.500000000,243.700000000,5,100,1,1,235.000000000,246.810000000,5,100,1,1,232.880000000,262.740000000,1,100,1,1,231.110000000,263.830000000,3,100,1,1,JPM
2025-01-03T10:30:55.806797318Z,2025-01-03T10:30:55.806631209Z,10,2,9155,C,A,1,242.500000000,8,130,166109,4857732,241.670000000,242.070000000,2,62,1,1,241.120000000,242.850000000,81,300,1,2,241.000000000,242.900000000,100,100,1,1,240.000000000,243.000000000,10,92,1,2,238.000000000,243.310000000,30,10,1,1,236.000000000,243.700000000,6,100,1,1,235.500000000,246.810000000,5,100,1,1,235.000000000,262.740000000,5,100,1,1,232.880000000,263.830000000,1,100,1,1,231.110000000,,3,0,1,0,JPM
2025-01-03T10:30:55.806895618Z,2025-01-03T10:30:55.806729317Z,10,2,9155,A,A,1,242.470000000,8,130,166301,4857733,241.670000000,242.070000000,2,62,1,1,241.120000000,242.470000000,81,8,1,1,241.000000000,242.850000000,100,300,1,2,240.000000000,242.900000000,10,100,1,1,238.000000000,243.000000000,30,92,1,2,236.000000000,243.310000000,6,10,1,1,235.500000000,243.700000000,5,100,1,1,235.000000000,246.810000000,5,100,1,1,232.880000000,262.740000000,1,100,1,1,231.110000000,263.830000000,3,100,1,1,JPM
2025-01-03T10:30:55.816366788Z,2025-01-03T10:30:55.816200732Z,10,2,9155,C,A,1,242.470000000,8,130,166056,4857736,241.670000000,242.070000000,2,62,1,1,241.120000000,242.850000000,81,300,1,2,241.000000000,242.900000000,100,100,1,1,240.000000000,243.000000000,10,92,1,2,238.000000000,243.310000000,30,10,1,1,236.000000000,243.700000000,6,100,1,1,235.500000000,246.810000000,5,100,1,1,235.000000000,262.740000000,5,100,1,1,232.880000000,263.830000000,1,100,1,1,231.110000000,,3,0,1,0,JPM
2025-01-03T10:30:56.223382735Z,2025-01-03T10:30:56.223216046Z,10,2,16244,A,B,5,382.400000000,500,130,166689,4857843,382.890000000,383.090000000,22,6,1,1,382.810000000,383.100000000,20,11,2,1,382.720000000,383.300000000,10,20,1,1,382.700000000,383.330000000,50,21,1,1,382.680000000,383.420000000,20,140,1,1,382.400000000,383.600000000,500,1000,1,2,382.230000000,383.720000000,25,7085,1,8,382.110000000,383.740000000,300,37,1,1,382.100000000,383.800000000,20,10,2,1,382.010000000,383.880000000,2,4,1,1,TSLA
2025-01-03T10:30:56.362236913Z,2025-01-03T10:30:56.362070328Z,10,2,9155,A,A,1,242.520000000,8,130,166585,4857930,241.670000000,242.070000000,2,62,1,1,241.120000000,242.520000000,81,8,1,1,241.000000000,242.850000000,100,300,1,2,240.000000000,242.900000000,10,100,1,1,238.000000000,243.000000000,30,92,1,2,236.000000000,243.310000000,6,10,1,1,235.500000000,243.700000000,5,100,1,1,235.000000000,246.810000000,5,100,1,1,232.880000000,262.740000000,1,100,1,1,231.110000000,263.830000000,3,100,1,1,JPM
2025-01-03T10:30:56.390202402Z,2025-01-03T10:30:56.390034538Z,10,2,38,T,N,0,243.550000000,20,130,167864,4857935,243.500000000,243.640000000,6,54,1,1,243.460000000,243.650000000,400,61,1,2,243.390000000,243.700000000,28,200,1,1,243.190000000,243.760000000,2,27,1,1,243.020000000,244.000000000,79,1,1,1,243.000000000,244.140000000,1243,79,9,1,242.990000000,244.200000000,1,1000,1,1,242.750000000,244.400000000,30,50,1,1,242.590000000,244.420000000,5,10,1,1,242.280000000,244.580000000,100,100,1,1,AAPL
2025-01-03T10:30:56.508645645Z,2025-01-03T10:30:56.508479485Z,10,2,10888,C,B,2,420.560000000,13,130,166160,4857984,420.700000000,421.250000000,200,200,1,1,420.580000000,421.310000000,10,15,1,1,420.520000000,421.460000000,1,39,1,1,420.400000000,421.490000000,858,6,1,1,420.380000000,421.570000000,100,40,1,1,420.100000000,421.600000000,100,10,1,1,420.000000000,421.700000000,534,359,7,1,419.730000000,422.100000000,3,7,1,1,419.650000000,422.400000000,39,500,1,1,418.650000000,422.500000000,1,200,1,1,MSFT
2025-01-03T10:30:56.508712422Z,2025-01-03T10:30:56.508545848Z,10,2,10888,A,B,1,420.620000000,13,130,166574,4857985,420.700000000,421.250000000,200,200,1,1,420.620000000,421.310000000,13,15,1,1,420.580000000,421.460000000,10,39,1,1,420.520000000,421.490000000,1,6,1,1,420.400000000,421.570000000,858,40,1,1,420.380000000,421.600000000,100,10,1,1,420.100000000,421.700000000,100,359,1,1,420.000000000,422.100000000,534,7,7,1,419.730000000,422.400000000,3,500,1,1,419.650000000,422.500000000,39,200,1,1,MSFT
2025-01-03T10:30:56.860065907Z,2025-01-03T10:30:56.859899748Z,10,2,9155,A,B,1,241.540000000,8,130,166159,4858375,241.670000000,242.070000000,2,62,1,1,241.540000000,242.520000000,8,8,1,1,241.120000000,242.850000000,81,300,1,2,241.000000000,242.900000000,100,100,1,1,240.000000000,243.000000000,10,92,1,2,238.000000000,243.310000000,30,10,1,1,236.000000000,243.700000000,6,100,1,1,235.500000000,246.810000000,5,100,1,1,235.000000000,262.740000000,5,100,1,1,232.880000000,263.830000000,1,100,1,1,JPM
2025-01-03T10:30:57.390506867Z,2025-01-03T10:30:57.390338720Z,10,2,38,T,N,0,243.550000000,20,130,168147,4858533,243.500000000,243.640000000,6,54,1,1,243.460000000,243.650000000,400,61,1,2,243.390000000,243.700000000,28,200,1,1,243.190000000,243.760000000,2,27,1,1,243.020000000,244.000000000,79,1,1,1,243.000000000,244.140000000,1243,79,9,1,242.990000000,244.200000000,1,1000,1,1,242.750000000,244.400000000,30,50,1,1,242.590000000,244.420000000,5,10,1,1,242.280000000,244.580000000,100,100,1,1,AAPL
2025-01-03T10:30:57.429525348Z,2025-01-03T10:30:57.429359050Z,10,2,780,C,B,0,259.930000000,25,130,166298,4858557,259.010000000,261.800000000,181,25,2,1,258.100000000,270.990000000,25,203,1,2,257.700000000,294.170000000,1,100,1,1,250.000000000,295.390000000,13,100,2,1,236.860000000,,100,0,1,0,235.690000000,,100,0,1,0,,,0,0,0,0,,,0,0,0,0,,,0,0,0,0,,,0,0,0,0,AMGN
2025-01-03T10:30:57.429539556Z,2025-01-03T10:30:57.429373223Z,10,2,780,A,B,0,259.420000000,25,130,166333,4858558,259.420000000,261.800000000,25,25,1,1,259.010000000,270.990000000,181,203,2,2,258.100000000,294.170000000,25,100,1,1,257.700000000,295.390000000,1,100,1,1,250.000000000,,13,0,2,0,236.860000000,,100,0,1,0,235.690000000,,100,0,1,0,,,0,0,0,0,,,0,0,0,0,,,0,0,0,0,AMGN
2025-01-03T10:30:57.478048422Z,2025-01-03T10:30:57.477881843Z,10,2,780,A,A,0,261.630000000,25,130,166579,4858599,259.420000000,261.630000000,25,25,1,1,259.010000000,270.990000000,181,203,2,2,258.100000000,294.170000000,25,100,1,1,257.700000000,295.390000000,1,100,1,1,250.000000000,,13,0,2,0,236.860000000,,100,0,1,0,235.690000000,,100,0,1,0,,,0,0,0,0,,,0,0,0,0,,,0,0,0,0,AMGN
2025-01-03T10:30:57.488050657Z,2025-01-03T10:30:57.487884286Z,10,2,780,A,A,0,261.460000000,25,130,166371,4858634,259.420000000,261.460000000,25,25,1,1,259.010000000,270.990000000,181,203,2,2,258.100000000,294.170000000,25,100,1,1,257.700000000,295.390000000,1,100,1,1,250.000000000,,13,0,2,0,236.860000000,,100,0,1,0,235.690000000,,100,0,1,0,,,0,0,0,0,,,0,0,0,0,,,0,0,0,0,AMGN
2025-01-03T10:30:57.595090270Z,2025-01-03T10:30:57.594924584Z,10,2,16244,C,B,5,382.400000000,500,130,165686,4858763,382.890000000,383.090000000,22,6,1,1,382.810000000,383.100000000,20,11,2,1,382.720000000,383.300000000,10,20,1,1,382.700000000,383.330000000,50,21,1,1,382.680000000,383.420000000,20,140,1,1,382.230000000,383.600000000,25,1000,1,2,382.110000000,383.720000000,300,7085,1,8,382.100000000,383.740000000,20,37,2,1,382.010000000,383.800000000,2,10,1,1,382.000000000,383.880000000,1192,4,10,1,TSLA
2025-01-03T10:30:57.606161810Z,2025-01-03T10:30:57.605995417Z,10,2,16244,A,B,5,382.400000000,500,130,166393,4858783,382.890000000,383.090000000,22,6,1,1,382.810000000,383.100000000,20,11,2,1,382.720000000,383.300000000,10,20,1,1,382.700000000,383.330000000,50,21,1,1,382.680000000,383.420000000,20,140,1,1,382.400000000,383.600000000,500,1000,1,2,382.230000000,383.720000000,25,7085,1,8,382.110000000,383.740000000,300,37,1,1,382.100000000,383.800000000,20,10,2,1,382.010000000,383.880000000,2,4,1,1,TSLA
2025-01-03T10:30:57.617093143Z,2025-01-03T10:30:57.616926744Z,10,2,780,A,A,0,261.120000000,25,130,166399,4858800,259.420000000,261.120000000,25,25,1,1,259.010000000,270.990000000,181,203,2,2,258.100000000,294.170000000,25,100,1,1,257.700000000,295.390000000,1,100,1,1,250.000000000,,13,0,2,0,236.860000000,,100,0,1,0,235.690000000,,100,0,1,0,,,0,0,0,0,,,0,0,0,0,,,0,0,0,0,AMGN
2025-01-03T10:30:57.684109395Z,2025-01-03T10:30:57.683943230Z,10,2,780,A,A,0,260.950000000,25,130,166165,4858997,259.420000000,260.950000000,25,25,1,1,259.010000000,270.990000000,181,203,2,2,258.100000000,294.170000000,25,100,1,1,257.700000000,295.390000000,1,100,1,1,250.000000000,,13,0,2,0,236.860000000,,100,0,1,0,235.690000000,,100,0,1,0,,,0,0,0,0,,,0,0,0,0,,,0,0,0,0,AMGN
2025-01-03T10:30:57.776195877Z,2025-01-03T10:30:57.776029724Z,10,2,16244,C,A,3,383.330000000,21,130,166153,4859070,382.890000000,383.090000000,22,6,1,1,382.810000000,383.100000000,20,11,2,1,382.720000000,383.300000000,10,20,1,1,382.700000000,383.420000000,50,140,1,1,382.680000000,383.600000000,20,1000,1,2,382.400000000,383.720000000,500,7085,1,8,382.230000000,383.740000000,25,37,1,1,382.110000000,383.800000000,300,10,1,1,382.100000000,383.880000000,20,4,2,1,382.010000000,384.000000000,2,1300,1,4,TSLA
2025-01-03T10:30:57.776255953Z,2025-01-03T10:30:57.776089186Z,10,2,16244,A,A,2,383.280000000,23,130,166767,4859071,382.890000000,383.090000000,22,6,1,1,382.810000000,383.100000000,20,11,2,1,382.720000000,383.280000000,10,23,1,1,382.700000000,383.300000000,50,20,1,1,382.680000000,383.420000000,20,140,1,1,382.400000000,383.600000000,500,1000,1,2,382.230000000,383.720000000,25,7085,1,8,382.110000000,383.740000000,300,37,1,1,382.100000000,383.800000000,20,10,2,1,382.010000000,383.880000000,2,4,1,1,TSLA
2025-01-03T10:30:57.996679239Z,2025-01-03T10:30:57.996513280Z,10,2,780,C,B,0,259.420000000,25,130,165959,4859246,259.010000000,260.950000000,181,25,2,1,258.100000000,270.990000000,25,203,1,2,257.700000000,294.170000000,1,100,1,1,250.000000000,295.390000000,13,100,2,1,236.860000000,,100,0,1,0,235.690000000,,100,0,1,0,,,0,0,0,0,,,0,0,0,0,,,0,0,0,0,,,0,0,0,0,AMGN
2025-01-03T10:30:57.996692445Z,2025-01-03T10:30:57.996526288Z,10,2,780,A,B,0,259.250000000,25,130,166157,4859247,259.250000000,260.950000000,25,25,1,1,259.010000000,270.990000000,181,203,2,2,258.100000000,294.170000000,25,100,1,1,257.700000000,295.390000000,1,100,1,1,250.000000000,,13,0,2,0,236.860000000,,100,0,1,0,235.690000000,,100,0,1,0,,,0,0,0,0,,,0,0,0,0,,,0,0,0,0,AMGN
2025-01-03T10:30:58.390952176Z,2025-01-03T10:30:58.390784996Z,10,2,38,T,N,0,243.550000000,20,130,167180,4859362,243.500000000,243.640000000,6,54,1,1,243.460000000,243.650000000,400,61,1,2,243.390000000,243.700000000,28,200,1,1,243.190000000,243.760000000,2,27,1,1,243.020000000,244.000000000,79,1,1,1,243.000000000,244.140000000,1243,79,9,1,242.990000000,244.200000000,1,1000,1,1,242.750000000,244.400000000,30,50,1,1,242.590000000,244.420000000,5,10,1,1,242.280000000,244.580000000,100,100,1,1,AAPL
2025-01-03T10:30:58.486279697Z,2025-01-03T10:30:58.486114078Z,10,2,11667,C,A,0,139.160000000,400,130,165619,4859422,139.130000000,139.160000000,100,230,1,1,139.120000000,139.200000000,30,429,1,2,139.110000000,139.220000000,1,10,1,1,139.080000000,139.230000000,57,25,1,1,139.060000000,139.250000000,400,1,1,1,139.030000000,139.270000000,126,17,2,1,139.010000000,139.300000000,100,507,1,4,139.000000000,139.320000000,420,39,5,1,138.980000000,139.330000000,300,503,1,2,138.970000000,139.360000000,800,14,2,3,NVDA
2025-01-03T10:30:58.486291603Z,2025-01-03T10:30:58.486125461Z,10,2,11667,A,A,1,139.170000000,400,130,166142,4859424,139.130000000,139.160000000,100,230,1,1,139.120000000,139.170000000,30,400,1,1,139.110000000,139.200000000,1,429,1,2,139.080000000,139.220000000,57,10,1,1,139.060000000,139.230000000,400,25,1,1,139.030000000,139.250000000,126,1,2,1,139.010000000,139.270000000,100,17,1,1,139.000000000,139.300000000,420,507,5,4,138.980000000,139.320000000,300,39,1,1,138.970000000,139.330000000,800,503,2,2,NVDA
2025-01-03T10:30:58.486547003Z,2025-01-03T10:30:58.486380765Z,10,2,38,C,A,2,243.700000000,200,130,166238,4859432,243.500000000,243.640000000,6,54,1,1,243.460000000,243.650000000,400,61,1,2,243.390000000,243.760000000,28,27,1,1,243.190000000,244.000000000,2,1,1,1,243.020000000,244.140000000,79,79,1,1,243.000000000,244.200000000,1243,1000,9,1,242.990000000,244.400000000,1,50,1,1,242.750000000,244.420000000,30,10,1,1,242.590000000,244.580000000,5,100,1,1,242.280000000,245.000000000,100,79,1,2,AAPL
2025-01-03T10:30:58.486558546Z,2025-01-03T10:30:58.486392503Z,10,2,38,A,A,2,243.720000000,200,130,166043,4859433,243.500000000,243.640000000,6,54,1,1,243.460000000,243.650000000,400,61,1,2,243.390000000,243.720000000,28,200,1,1,243.190000000,243.760000000,2,27,1,1,243.020000000,244.000000000,79,1,1,1,243.000000000,244.140000000,1243,79,9,1,242.990000000,244.200000000,1,1000,1,1,242.750000000,244.400000000,30,50,1,1,242.590000000,244.420000000,5,10,1,1,242.280000000,244.580000000,100,100,1,1,AAPL
2025-01-03T10:30:58.486577846Z,2025-01-03T10:30:58.486410591Z,10,2,38,T,N,0,243.550000000,20,130,167255,4859434,243.500000000,243.640000000,6,54,1,1,243.460000000,243.650000000,400,61,1,2,243.390000000,243.720000000,28,200,1,1,243.190000000,243.760000000,2,27,1,1,243.020000000,244.000000000,79,1,1,1,243.000000000,244.140000000,1243,79,9,1,242.990000000,244.200000000,1,1000,1,1,242.750000000,244.400000000,30,50,1,1,242.590000000,244.420000000,5,10,1,1,242.280000000,244.580000000,100,100,1,1,AAPL
2025-01-03T10:30:58.540696099Z,2025-01-03T10:30:58.540529310Z,10,2,10888,A,B,0,420.710000000,200,130,166789,4859483,420.710000000,421.250000000,200,200,1,1,420.620000000,421.310000000,13,15,1,1,420.580000000,421.460000000,10,39,1,1,420.520000000,421.490000000,1,6,1,1,420.400000000,421.570000000,858,40,1,1,420.380000000,421.600000000,100,10,1,1,420.100000000,421.700000000,100,359,1,1,420.000000000,422.100000000,534,7,7,1,419.730000000,422.400000000,3,500,1,1,419.650000000,422.500000000,39,200,1,1,MSFT
2025-01-03T10:30:58.540710115Z,2025-01-03T10:30:58.540544074Z,10,2,11667,A,B,4,139.070000000,400,130,166041,4859484,139.130000000,139.160000000,100,230,1,1,139.120000000,139.170000000,30,400,1,1,139.110000000,139.200000000,1,429,1,2,139.080000000,139.220000000,57,10,1,1,139.070000000,139.230000000,400,25,1,1,139.030000000,139.250000000,126,1,2,1,139.010000000,139.270000000,100,17,1,1,139.000000000,139.300000000,420,507,5,4,138.980000000,139.320000000,300,39,1,1,138.970000000,139.330000000,800,503,2,2,NVDA
2025-01-03T10:30:58.541138459Z,2025-01-03T10:30:58.540971813Z,10,2,38,A,B,1,243.470000000,400,130,166646,4859495,243.500000000,243.640000000,6,54,1,1,243.470000000,243.650000000,400,61,1,2,243.390000000,243.720000000,28,200,1,1,243.190000000,243.760000000,2,27,1,1,243.020000000,244.000000000,79,1,1,1,243.000000000,244.140000000,1243,79,9,1,242.990000000,244.200000000,1,1000,1,1,242.750000000,244.400000000,30,50,1,1,242.590000000,244.420000000,5,10,1,1,242.280000000,244.580000000,100,100,1,1,AAPL
2025-01-03T10:30:58.554725644Z,2025-01-03T10:30:58.554559330Z,10,2,16244,C,B,0,382.890000000,22,130,166314,4859518,382.810000000,383.090000000,20,6,2,1,382.720000000,383.100000000,10,11,1,1,382.700000000,383.280000000,50,23,1,1,382.680000000,383.300000000,20,20,1,1,382.400000000,383.420000000,500,140,1,1,382.230000000,383.600000000,25,1000,1,2,382.110000000,383.720000000,300,7085,1,8,382.100000000,383.740000000,20,37,2,1,382.010000000,383.800000000,2,10,1,1,382.000000000,383.880000000,1192,4,10,1,TSLA
2025-01-03T10:30:58.554785201Z,2025-01-03T10:30:58.554618490Z,10,2,16244,A,B,0,382.900000000,23,130,166711,4859519,382.900000000,383.090000000,23,6,1,1,382.810000000,383.100000000,20,11,2,1,382.720000000,383.280000000,10,23,1,1,382.700000000,383.300000000,50,20,1,1,382.680000000,383.420000000,20,140,1,1,382.400000000,383.600000000,500,1000,1,2,382.230000000,383.720000000,25,7085,1,8,382.110000000,383.740000000,300,37,1,1,382.100000000,383.800000000,20,10,2,1,382.010000000,383.880000000,2,4,1,1,TSLA
2025-01-03T10:30:58.559119971Z,2025-01-03T10:30:58.558954200Z,10,2,16727,C,B,0,314.920000000,8,130,165771,4859546,314.860000000,315.450000000,25,8,1,1,314.420000000,315.510000000,61,25,1,1,313.500000000,315.750000000,1,61,1,1,310.000000000,320.000000000,1,5,1,1,300.000000000,320.210000000,3,1,1,1,290.000000000,321.950000000,2,2,1,1,286.660000000,344.200000000,100,100,1,1,285.250000000,345.620000000,100,100,1,1,260.000000000,,2,0,1,0,,,0,0,0,0,V
2025-01-03T10:30:58.559180124Z,2025-01-03T10:30:58.559013620Z,10,2,16727,A,B,0,314.930000000,8,130,166504,4859548,314.930000000,315.450000000,8,8,1,1,314.860000000,315.510000000,25,25,1,1,314.420000000,315.750000000,61,61,1,1,313.500000000,320.000000000,1,5,1,1,310.000000000,320.210000000,1,1,1,1,300.000000000,321.950000000,3,2,1,1,290.000000000,344.200000000,2,100,1,1,286.660000000,345.620000000,100,100,1,1,285.250000000,,100,0,1,0,260.000000000,,2,0,1,0,V
2025-01-03T10:30:58.566112563Z,2025-01-03T10:30:58.565946462Z,10,2,38,A,B,2,243.400000000,29,130,166101,4859595,243.500000000,243.640000000,6,54,1,1,243.470000000,243.650000000,400,61,1,2,243.400000000,243.720000000,29,200,1,1,243.390000000,243.760000000,28,27,1,1,243.190000000,244.000000000,2,1,1,1,243.020000000,244.140000000,79,79,1,1,243.000000000,244.200000000,1243,1000,9,1,242.990000000,244.400000000,1,50,1,1,242.750000000,244.420000000,30,10,1,1,242.590000000,244.580000000,5,100,1,1,AAPL
2025-01-03T10:30:58.566163438Z,2025-01-03T10:30:58.565997532Z,10,2,38,C,B,3,243.390000000,28,130,165906,4859597,243.500000000,243.640000000,6,54,1,1,243.470000000,243.650000000,400,61,1,2,243.400000000,243.720000000,29,200,1,1,243.190000000,243.760000000,2,27,1,1,243.020000000,244.000000000,79,1,1,1,243.000000000,244.140000000,1243,79,9,1,242.990000000,244.200000000,1,1000,1,1,242.750000000,244.400000000,30,50,1,1,242.590000000,244.420000000,5,10,1,1,242.280000000,244.580000000,100,100,1,1,AAPL
2025-01-03T10:30:58.641106120Z,2025-01-03T10:30:58.640940291Z,10,2,11667,C,A,1,139.170000000,400,130,165829,4860140,139.130000000,139.160000000,100,230,1,1,139.120000000,139.200000000,30,429,1,2,139.110000000,139.220000000,1,10,1,1,139.080000000,139.230000000,57,25,1,1,139.070000000,139.250000000,400,1,1,1,139.030000000,139.270000000,126,17,2,1,139.010000000,139.300000000,100,507,1,4,139.000000000,139.320000000,420,39,5,1,138.980000000,139.330000000,300,503,1,2,138.970000000,139.360000000,800,14,2,3,NVDA
2025-01-03T10:30:58.641119711Z,2025-01-03T10:30:58.640953552Z,10,2,11667,A,A,1,139.180000000,400,130,166159,4860141,139.130000000,139.160000000,100,230,1,1,139.120000000,139.180000000,30,400,1,1,139.110000000,139.200000000,1,429,1,2,139.080000000,139.220000000,57,10,1,1,139.070000000,139.230000000,400,25,1,1,139.030000000,139.250000000,126,1,2,1,139.010000000,139.270000000,100,17,1,1,139.000000000,139.300000000,420,507,5,4,138.980000000,139.320000000,300,39,1,1,138.970000000,139.330000000,800,503,2,2,NVDA
2025-01-03T10:30:58.671455346Z,2025-01-03T10:30:58.671289263Z,10,2,11667,C,A,1,139.180000000,400,130,166083,4860221,139.130000000,139.160000000,100,230,1,1,139.120000000,139.200000000,30,429,1,2,139.110000000,139.220000000,1,10,1,1,139.080000000,139.230000000,57,25,1,1,139.070000000,139.250000000,400,1,1,1,139.030000000,139.270000000,126,17,2,1,139.010000000,139.300000000,100,507,1,4,139.000000000,139.320000000,420,39,5,1,138.980000000,139.330000000,300,503,1,2,138.970000000,139.360000000,800,14,2,3,NVDA
2025-01-03T10:30:58.671470361Z,2025-01-03T10:30:58.671302986Z,10,2,11667,A,A,1,139.200000000,400,130,167375,4860222,139.130000000,139.160000000,100,230,1,1,139.120000000,139.200000000,30,829,1,3,139.110000000,139.220000000,1,10,1,1,139.080000000,139.230000000,57,25,1,1,139.070000000,139.250000000,400,1,1,1,139.030000000,139.270000000,126,17,2,1,139.010000000,139.300000000,100,507,1,4,139.000000000,139.320000000,420,39,5,1,138.980000000,139.330000000,300,503,1,2,138.970000000,139.360000000,800,14,2,3,NVDA
2025-01-03T10:30:58.733759024Z,2025-01-03T10:30:58.733592115Z,10,2,11667,A,A,1,139.190000000,400,130,166909,4860374,139.130000000,139.160000000,100,230,1,1,139.120000000,139.190000000,30,400,1,1,139.110000000,139.200000000,1,429,1,2,139.080000000,139.220000000,57,10,1,1,139.070000000,139.230000000,400,25,1,1,139.030000000,139.250000000,126,1,2,1,139.010000000,139.270000000,100,17,1,1,139.000000000,139.300000000,420,507,5,4,138.980000000,139.320000000,300,39,1,1,138.970000000,139.330000000,800,503,2,2,NVDA
2025-01-03T10:30:59.394581996Z,2025-01-03T10:30:59.394414798Z,10,2,38,T,N,0,243.550000000,20,130,167198,4860739,243.500000000,243.640000000,6,54,1,1,243.470000000,243.650000000,400,61,1,2,243.400000000,243.720000000,29,200,1,1,243.190000000,243.760000000,2,27,1,1,243.020000000,244.000000000,79,1,1,1,243.000000000,244.140000000,1243,79,9,1,242.990000000,244.200000000,1,1000,1,1,242.750000000,244.400000000,30,50,1,1,242.590000000,244.420000000,5,10,1,1,242.280000000,244.580000000,100,100,1,1,AAPL
2025-01-03T10:30:59.507408388Z,2025-01-03T10:30:59.507242089Z,10,2,10888,A,A,7,421.800000000,7,130,166299,4860799,420.710000000,421.250000000,200,200,1,1,420.620000000,421.310000000,13,15,1,1,420.580000000,421.460000000,10,39,1,1,420.520000000,421.490000000,1,6,1,1,420.400000000,421.570000000,858,40,1,1,420.380000000,421.600000000,100,10,1,1,420.100000000,421.700000000,100,359,1,1,420.000000000,421.800000000,534,7,7,1,419.730000000,422.100000000,3,7,1,1,419.650000000,422.400000000,39,500,1,1,MSFT
2025-01-03T10:31:00.114324740Z,2025-01-03T10:31:00.114158754Z,10,2,17709,C,A,2,107.880000000,100,130,165986,4861218,107.600000000,107.840000000,50,416,1,3,107.540000000,107.870000000,17,242,1,1,107.520000000,107.950000000,100,10,1,1,107.050000000,108.000000000,247,50,1,1,107.000000000,108.300000000,1,50,1,1,106.240000000,108.550000000,28,50,1,1,106.000000000,108.800000000,15,50,2,1,105.870000000,108.880000000,141,28,1,1,103.180000000,109.450000000,16,137,1,1,103.000000000,109.500000000,3,100,1,1,XOM
2025-01-03T10:31:00.114337180Z,2025-01-03T10:31:00.114170960Z,10,2,17709,A,A,2,107.940000000,100,130,166220,4861219,107.600000000,107.840000000,50,416,1,3,107.540000000,107.870000000,17,242,1,1,107.520000000,107.940000000,100,100,1,1,107.050000000,107.950000000,247,10,1,1,107.000000000,108.000000000,1,50,1,1,106.240000000,108.300000000,28,50,1,1,106.000000000,108.550000000,15,50,2,1,105.870000000,108.800000000,141,50,1,1,103.180000000,108.880000000,16,28,1,1,103.000000000,109.450000000,3,137,1,1,XOM
2025-01-03T10:31:00.114799450Z,2025-01-03T10:31:00.114633594Z,10,2,17709,C,A,0,107.840000000,16,130,165856,4861220,107.600000000,107.840000000,50,400,1,2,107.540000000,107.870000000,17,242,1,1,107.520000000,107.940000000,100,100,1,1,107.050000000,107.950000000,247,10,1,1,107.000000000,108.000000000,1,50,1,1,106.240000000,108.300000000,28,50,1,1,106.000000000,108.550000000,15,50,2,1,105.870000000,108.800000000,141,50,1,1,103.180000000,108.880000000,16,28,1,1,103.000000000,109.450000000,3,137,1,1,XOM
2025-01-03T10:31:00.114883120Z,2025-01-03T10:31:00.114716610Z,10,2,17709,A,A,2,107.910000000,17,130,166510,4861221,107.600000000,107.840000000,50,400,1,2,107.540000000,107.870000000,17,242,1,1,107.520000000,107.910000000,100,17,1,1,107.050000000,107.940000000,247,100,1,1,107.000000000,107.950000000,1,10,1,1,106.240000000,108.000000000,28,50,1,1,106.000000000,108.300000000,15,50,2,1,105.870000000,108.550000000,141,50,1,1,103.180000000,108.800000000,16,50,1,1,103.000000000,108.880000000,3,28,1,1,XOM
2025-01-03T10:31:00.116996066Z,2025-01-03T10:31:00.116829968Z,10,2,17709,C,B,1,107.540000000,17,130,166098,4861222,107.600000000,107.840000000,50,400,1,2,107.520000000,107.870000000,100,242,1,1,107.050000000,107.910000000,247,17,1,1,107.000000000,107.940000000,1,100,1,1,106.240000000,107.950000000,28,10,1,1,106.000000000,108.000000000,15,50,2,1,105.870000000,108.300000000,141,50,1,1,103.180000000,108.550000000,16,50,1,1,103.000000000,108.800000000,3,50,1,1,102.000000000,108.880000000,2,28,1,1,XOM
2025-01-03T10:31:00.117077887Z,2025-01-03T10:31:00.116911368Z,10,2,17709,A,B,1,107.560000000,16,130,166519,4861223,107.600000000,107.840000000,50,400,1,2,107.560000000,107.870000000,16,242,1,1,107.520000000,107.910000000,100,17,1,1,107.050000000,107.940000000,247,100,1,1,107.000000000,107.950000000,1,10,1,1,106.240000000,108.000000000,28,50,1,1,106.000000000,108.300000000,15,50,2,1,105.870000000,108.550000000,141,50,1,1,103.180000000,108.800000000,16,50,1,1,103.000000000,108.880000000,3,28,1,1,XOM
2025-01-03T10:31:00.118593126Z,2025-01-03T10:31:00.118427190Z,10,2,17709,C,A,2,107.910000000,17,130,165936,4861224,107.600000000,107.840000000,50,400,1,2,107.560000000,107.870000000,16,242,1,1,107.520000000,107.940000000,100,100,1,1,107.050000000,107.950000000,247,10,1,1,107.000000000,108.000000000,1,50,1,1,106.240000000,108.300000000,28,50,1,1,106.000000000,108.550000000,15,50,2,1,105.870000000,108.800000000,141,50,1,1,103.180000000,108.880000000,16,28,1,1,103.000000000,109.450000000,3,137,1,1,XOM
2025-01-03T10:31:00.122591873Z,2025-01-03T10:31:00.122425965Z,10,2,17709,C,B,1,107.560000000,16,130,165908,4861225,107.600000000,107.840000000,50,400,1,2,107.520000000,107.870000000,100,242,1,1,107.050000000,107.940000000,247,100,1,1,107.000000000,107.950000000,1,10,1,1,106.240000000,108.000000000,28,50,1,1,106.000000000,108.300000000,15,50,2,1,105.870000000,108.550000000,141,50,1,1,103.180000000,108.800000000,16,50,1,1,103.000000000,108.880000000,3,28,1,1,102.000000000,109.450000000,2,137,1,1,XOM
2025-01-03T10:31:00.394848358Z,2025-01-03T10:31:00.394680361Z,10,2,38,T,N,0,243.550000000,20,130,167997,4861384,243.500000000,243.640000000,6,54,1,1,243.470000000,243.650000000,400,61,1,2,243.400000000,243.720000000,29,200,1,1,243.190000000,243.760000000,2,27,1,1,243.020000000,244.000000000,79,1,1,1,243.000000000,244.140000000,1243,79,9,1,242.990000000,244.200000000,1,1000,1,1,242.750000000,244.400000000,30,50,1,1,242.590000000,244.420000000,5,10,1,1,242.280000000,244.580000000,100,100,1,1,AAPL
2025-01-03T10:31:00.821249071Z,2025-01-03T10:31:00.821082933Z,10,2,11667,A,A,1,139.180000000,400,130,166138,4861892,139.130000000,139.160000000,100,230,1,1,139.120000000,139.180000000,30,400,1,1,139.110000000,139.200000000,1,429,1,2,139.080000000,139.220000000,57,10,1,1,139.070000000,139.230000000,400,25,1,1,139.030000000,139.250000000,126,1,2,1,139.010000000,139.270000000,100,17,1,1,139.000000000,139.300000000,420,507,5,4,138.980000000,139.320000000,300,39,1,1,138.970000000,139.330000000,800,503,2,2,NVDA
2025-01-03T10:31:00.961948600Z,2025-01-03T10:31:00.961782198Z,10,2,16244,A,B,5,382.500000000,3,130,166402,4862132,382.900000000,383.090000000,23,6,1,1,382.810000000,383.100000000,20,11,2,1,382.720000000,383.280000000,10,23,1,1,382.700000000,383.300000000,50,20,1,1,382.680000000,383.420000000,20,140,1,1,382.500000000,383.600000000,3,1000,1,2,382.400000000,383.720000000,500,7085,1,8,382.230000000,383.740000000,25,37,1,1,382.110000000,383.800000000,300,10,1,1,382.100000000,383.880000000,20,4,2,1,TSLA
2025-01-03T10:31:01.050048863Z,2025-01-03T10:31:01.049882419Z,10,2,38,A,A,2,243.700000000,200,130,166444,4862210,243.500000000,243.640000000,6,54,1,1,243.470000000,243.650000000,400,61,1,2,243.400000000,243.700000000,29,200,1,1,243.190000000,243.760000000,2,27,1,1,243.020000000,244.000000000,79,1,1,1,243.000000000,244.140000000,1243,79,9,1,242.990000000,244.200000000,1,1000,1,1,242.750000000,244.400000000,30,50,1,1,242.590000000,244.420000000,5,10,1,1,242.280000000,244.580000000,100,100,1,1,AAPL
2025-01-03T10:31:01.235917359Z,2025-01-03T10:31:01.235751449Z,10,2,10888,C,B,1,420.620000000,13,130,165910,4862418,420.710000000,421.250000000,200,200,1,1,420.580000000,421.310000000,10,15,1,1,420.520000000,421.460000000,1,39,1,1,420.400000000,421.490000000,858,6,1,1,420.380000000,421.570000000,100,40,1,1,420.100000000,421.600000000,100,10,1,1,420.000000000,421.700000000,534,359,7,1,419.730000000,421.800000000,3,7,1,1,419.650000000,422.100000000,39,7,1,1,418.650000000,422.400000000,1,500,1,1,MSFT
2025-01-03T10:31:01.235982477Z,2025-01-03T10:31:01.235816288Z,10,2,10888,A,B,1,420.640000000,13,130,166189,4862419,420.710000000,421.250000000,200,200,1,1,420.640000000,421.310000000,13,15,1,1,420.580000000,421.460000000,10,39,1,1,420.520000000,421.490000000,1,6,1,1,420.400000000,421.570000000,858,40,1,1,420.380000000,421.600000000,100,10,1,1,420.100000000,421.700000000,100,359,1,1,420.000000000,421.800000000,534,7,7,1,419.730000000,422.100000000,3,7,1,1,419.650000000,422.400000000,39,500,1,1,MSFT
2025-01-03T10:31:01.236467883Z,2025-01-03T10:31:01.236301482Z,10,2,10888,C,B,7,420.000000000,500,130,166401,4862421,420.710000000,421.250000000,200,200,1,1,420.640000000,421.310000000,13,15,1,1,420.580000000,421.460000000,10,39,1,1,420.520000000,421.490000000,1,6,1,1,420.400000000,421.570000000,858,40,1,1,420.380000000,421.600000000,100,10,1,1,420.100000000,421.700000000,100,359,1,1,420.000000000,421.800000000,34,7,6,1,419.730000000,422.100000000,3,7,1,1,419.650000000,422.400000000,39,500,1,1,MSFT
2025-01-03T10:31:01.281221548Z,2025-01-03T10:31:01.281055025Z,10,2,10888,A,B,0,420.720000000,200,130,166523,4862477,420.720000000,421.250000000,200,200,1,1,420.640000000,421.310000000,13,15,1,1,420.580000000,421.460000000,10,39,1,1,420.520000000,421.490000000,1,6,1,1,420.400000000,421.570000000,858,40,1,1,420.380000000,421.600000000,100,10,1,1,420.100000000,421.700000000,100,359,1,1,420.000000000,421.800000000,34,7,6,1,419.730000000,422.100000000,3,7,1,1,419.650000000,422.400000000,39,500,1,1,MSFT
2025-01-03T10:31:01.386266747Z,2025-01-03T10:31:01.386099546Z,10,2,16244,T,N,0,383.050000000,26,130,167201,4862525,382.900000000,383.090000000,23,6,1,1,382.810000000,383.100000000,20,11,2,1,382.720000000,383.280000000,10,23,1,1,382.700000000,383.300000000,50,20,1,1,382.680000000,383.420000000,20,140,1,1,382.500000000,383.600000000,3,1000,1,2,382.400000000,383.720000000,500,7085,1,8,382.230000000,383.740000000,25,37,1,1,382.110000000,383.800000000,300,10,1,1,382.100000000,383.880000000,20,4,2,1,TSLA
2025-01-03T10:31:01.386325904Z,2025-01-03T10:31:01.386158799Z,10,2,16244,T,N,0,383.050000000,13,130,167105,4862527,382.900000000,383.090000000,23,6,1,1,382.810000000,383.100000000,20,11,2,1,382.720000000,383.280000000,10,23,1,1,382.700000000,383.300000000,50,20,1,1,382.680000000,383.420000000,20,140,1,1,382.500000000,383.600000000,3,1000,1,2,382.400000000,383.720000000,500,7085,1,8,382.230000000,383.740000000,25,37,1,1,382.110000000,383.800000000,300,10,1,1,382.100000000,383.880000000,20,4,2,1,TSLA
2025-01-03T10:31:01.386363490Z,2025-01-03T10:31:01.386195997Z,10,2,16244,T,N,0,383.050000000,13,130,167493,4862528,382.900000000,383.090000000,23,6,1,1,382.810000000,383.100000000,20,11,2,1,382.720000000,383.280000000,10,23,1,1,382.700000000,383.300000000,50,20,1,1,382.680000000,383.420000000,20,140,1,1,382.500000000,383.600000000,3,1000,1,2,382.400000000,383.720000000,500,7085,1,8,382.230000000,383.740000000,25,37,1,1,382.110000000,383.800000000,300,10,1,1,382.100000000,383.880000000,20,4,2,1,TSLA
2025-01-03T10:31:01.386398478Z,2025-01-03T10:31:01.386231283Z,10,2,16244,T,N,0,383.050000000,6,130,167195,4862529,382.900000000,383.090000000,23,6,1,1,382.810000000,383.100000000,20,11,2,1,382.720000000,383.280000000,10,23,1,1,382.700000000,383.300000000,50,20,1,1,382.680000000,383.420000000,20,140,1,1,382.500000000,383.600000000,3,1000,1,2,382.400000000,383.720000000,500,7085,1,8,382.230000000,383.740000000,25,37,1,1,382.110000000,383.800000000,300,10,1,1,382.100000000,383.880000000,20,4,2,1,TSLA
2025-01-03T10:31:01.386899805Z,2025-01-03T10:31:01.386733412Z,10,2,16244,C,A,5,383.600000000,500,130,166393,4862542,382.900000000,383.090000000,23,6,1,1,382.810000000,383.100000000,20,11,2,1,382.720000000,383.280000000,10,23,1,1,382.700000000,383.300000000,50,20,1,1,382.680000000,383.420000000,20,140,1,1,382.500000000,383.600000000,3,500,1,1,382.400000000,383.720000000,500,7085,1,8,382.230000000,383.740000000,25,37,1,1,382.110000000,383.800000000,300,10,1,1,382.100000000,383.880000000,20,4,2,1,TSLA
2025-01-03T10:31:01.386934263Z,2025-01-03T10:31:01.386768093Z,10,2,16244,A,B,0,382.970000000,8,130,166170,4862544,382.970000000,383.090000000,8,6,1,1,382.900000000,383.100000000,23,11,1,1,382.810000000,383.280000000,20,23,2,1,382.720000000,383.300000000,10,20,1,1,382.700000000,383.420000000,50,140,1,1,382.680000000,383.600000000,20,500,1,1,382.500000000,383.720000000,3,7085,1,8,382.400000000,383.740000000,500,37,1,1,382.230000000,383.800000000,25,10,1,1,382.110000000,383.880000000,300,4,1,1,TSLA
2025-01-03T10:31:01.397430531Z,2025-01-03T10:31:01.397264428Z,10,2,16244,C,B,0,382.970000000,8,130,166103,4862559,382.900000000,383.090000000,23,6,1,1,382.810000000,383.100000000,20,11,2,1,382.720000000,383.280000000,10,23,1,1,382.700000000,383.300000000,50,20,1,1,382.680000000,383.420000000,20,140,1,1,382.500000000,383.600000000,3,500,1,1,382.400000000,383.720000000,500,7085,1,8,382.230000000,383.740000000,25,37,1,1,382.110000000,383.800000000,300,10,1,1,382.100000000,383.880000000,20,4,2,1,TSLA
2025-01-03T10:31:01.398524135Z,2025-01-03T10:31:01.398355862Z,10,2,38,T,N,0,243.550000000,8,130,168273,4862562,243.500000000,243.640000000,6,54,1,1,243.470000000,243.650000000,400,61,1,2,243.400000000,243.700000000,29,200,1,1,243.190000000,243.760000000,2,27,1,1,243.020000000,244.000000000,79,1,1,1,243.000000000,244.140000000,1243,79,9,1,242.990000000,244.200000000,1,1000,1,1,242.750000000,244.400000000,30,50,1,1,242.590000000,244.420000000,5,10,1,1,242.280000000,244.580000000,100,100,1,1,AAPL
2025-01-03T10:31:01.458149736Z,2025-01-03T10:31:01.457983755Z,10,2,16244,C,A,2,383.280000000,23,130,165981,4862701,382.900000000,383.090000000,23,6,1,1,382.810000000,383.100000000,20,11,2,1,382.720000000,383.300000000,10,20,1,1,382.700000000,383.420000000,50,140,1,1,382.680000000,383.600000000,20,500,1,1,382.500000000,383.720000000,3,7085,1,8,382.400000000,383.740000000,500,37,1,1,382.230000000,383.800000000,25,10,1,1,382.110000000,383.880000000,300,4,1,1,382.100000000,384.000000000,20,1300,2,4,TSLA
2025-01-03T10:31:01.458359970Z,2025-01-03T10:31:01.458191135Z,10,2,16244,T,B,0,383.090000000,6,130,168835,4862704,382.900000000,383.090000000,23,6,1,1,382.810000000,383.100000000,20,11,2,1,382.720000000,383.300000000,10,20,1,1,382.700000000,383.420000000,50,140,1,1,382.680000000,383.600000000,20,500,1,1,382.500000000,383.720000000,3,7085,1,8,382.400000000,383.740000000,500,37,1,1,382.230000000,383.800000000,25,10,1,1,382.110000000,383.880000000,300,4,1,1,382.100000000,384.000000000,20,1300,2,4,TSLA
2025-01-03T10:31:01.458359970Z,2025-01-03T10:31:01.458191135Z,10,2,16244,C,A,0,383.090000000,6,130,168835,4862704,382.900000000,383.100000000,23,11,1,1,382.810000000,383.300000000,20,20,2,1,382.720000000,383.420000000,10,140,1,1,382.700000000,383.600000000,50,500,1,1,382.680000000,383.720000000,20,7085,1,8,382.500000000,383.740000000,3,37,1,1,382.400000000,383.800000000,500,10,1,1,382.230000000,383.880000000,25,4,1,1,382.110000000,384.000000000,300,1300,1,4,382.100000000,384.260000000,20,15,2,1,TSLA
2025-01-03T10:31:01.458382404Z,2025-01-03T10:31:01.458215618Z,10,2,16244,A,B,0,382.990000000,4,130,166786,4862706,382.990000000,383.100000000,4,11,1,1,382.900000000,383.300000000,23,20,1,1,382.810000000,383.420000000,20,140,2,1,382.720000000,383.600000000,10,500,1,1,382.700000000,383.720000000,50,7085,1,8,382.680000000,383.740000000,20,37,1,1,382.500000000,383.800000000,3,10,1,1,382.400000000,383.880000000,500,4,1,1,382.230000000,384.000000000,25,1300,1,4,382.110000000,384.260000000,300,15,1,1,TSLA
2025-01-03T10:31:01.458396634Z,2025-01-03T10:31:01.458229014Z,10,2,16244,A,B,1,382.930000000,4,130,167620,4862711,382.990000000,383.100000000,4,11,1,1,382.930000000,383.300000000,4,20,1,1,382.900000000,383.420000000,23,140,1,1,382.810000000,383.600000000,20,500,2,1,382.720000000,383.720000000,10,7085,1,8,382.700000000,383.740000000,50,37,1,1,382.680000000,383.800000000,20,10,1,1,382.500000000,383.880000000,3,4,1,1,382.400000000,384.000000000,500,1300,1,4,382.230000000,384.260000000,25,15,1,1,TSLA
2025-01-03T10:31:01.458400351Z,2025-01-03T10:31:01.458231211Z,10,2,16244,T,B,0,383.100000000,11,130,169140,4862712,382.990000000,383.100000000,4,11,1,1,382.930000000,383.300000000,4,20,1,1,382.900000000,383.420000000,23,140,1,1,382.810000000,383.600000000,20,500,2,1,382.720000000,383.720000000,10,7085,1,8,382.700000000,383.740000000,50,37,1,1,382.680000000,383.800000000,20,10,1,1,382.500000000,383.880000000,3,4,1,1,382.400000000,384.000000000,500,1300,1,4,382.230000000,384.260000000,25,15,1,1,TSLA
2025-01-03T10:31:01.458400351Z,2025-01-03T10:31:01.458231211Z,10,2,16244,C,A,0,383.100000000,11,130,169140,4862712,382.990000000,383.300000000,4,20,1,1,382.930000000,383.420000000,4,140,1,1,382.900000000,383.600000000,23,500,1,1,382.810000000,383.720000000,20,7085,2,8,382.720000000,383.740000000,10,37,1,1,382.700000000,383.800000000,50,10,1,1,382.680000000,383.880000000,20,4,1,1,382.500000000,384.000000000,3,1300,1,4,382.400000000,384.260000000,500,15,1,1,382.230000000,384.400000000,25,1000,1,2,TSLA
2025-01-03T10:31:01.459184918Z,2025-01-03T10:31:01.459018975Z,10,2,16244,A,B,0,382.990000000,8,130,165943,4862748,382.990000000,383.300000000,12,20,2,1,382.930000000,383.420000000,4,140,1,1,382.900000000,383.600000000,23,500,1,1,382.810000000,383.720000000,20,7085,2,8,382.720000000,383.740000000,10,37,1,1,382.700000000,383.800000000,50,10,1,1,382.680000000,383.880000000,20,4,1,1,382.500000000,384.000000000,3,1300,1,4,382.400000000,384.260000000,500,15,1,1,382.230000000,384.400000000,25,1000,1,2,TSLA
2025-01-03T10:31:01.459255667Z,2025-01-03T10:31:01.459089549Z,10,2,16244,A,B,0,383.000000000,8,130,166118,4862751,383.000000000,383.300000000,8,20,1,1,382.990000000,383.420000000,12,140,2,1,382.930000000,383.600000000,4,500,1,1,382.900000000,383.720000000,23,7085,1,8,382.810000000,383.740000000,20,37,2,1,382.720000000,383.800000000,10,10,1,1,382.700000000,383.880000000,50,4,1,1,382.680000000,384.000000000,20,1300,1,4,382.500000000,384.260000000,3,15,1,1,382.400000000,384.400000000,500,1000,1,2,TSLA
2025-01-03T10:31:01.459923084Z,2025-01-03T10:31:01.459756519Z,10,2,16244,A,B,0,383.060000000,8,130,166565,4862785,383.060000000,383.300000000,8,20,1,1,383.000000000,383.420000000,8,140,1,1,382.990000000,383.600000000,12,500,2,1,382.930000000,383.720000000,4,7085,1,8,382.900000000,383.740000000,23,37,1,1,382.810000000,383.800000000,20,10,2,1,382.720000000,383.880000000,10,4,1,1,382.700000000,384.000000000,50,1300,1,4,382.680000000,384.260000000,20,15,1,1,382.500000000,384.400000000,3,1000,1,2,TSLA
2025-01-03T10:31:01.464577783Z,2025-01-03T10:31:01.464411927Z,10,2,16244,C,B,0,383.060000000,8,130,165856,4862806,383.000000000,383.300000000,8,20,1,1,382.990000000,383.420000000,12,140,2,1,382.930000000,383.600000000,4,500,1,1,382.900000000,383.720000000,23,7085,1,8,382.810000000,383.740000000,20,37,2,1,382.720000000,383.800000000,10,10,1,1,382.700000000,383.880000000,50,4,1,1,382.680000000,384.000000000,20,1300,1,4,382.500000000,384.260000000,3,15,1,1,382.400000000,384.400000000,500,1000,1,2,TSLA
2025-01-03T10:31:01.468765695Z,2025-01-03T10:31:01.468599534Z,10,2,16244,C,B,2,382.930000000,4,130,166161,4862816,383.000000000,383.300000000,8,20,1,1,382.990000000,383.420000000,12,140,2,1,382.900000000,383.600000000,23,500,1,1,382.810000000,383.720000000,20,7085,2,8,382.720000000,383.740000000,10,37,1,1,382.700000000,383.800000000,50,10,1,1,382.680000000,383.880000000,20,4,1,1,382.500000000,384.000000000,3,1300,1,4,382.400000000,384.260000000,500,15,1,1,382.230000000,384.400000000,25,1000,1,2,TSLA
2025-01-03T10:31:01.469583314Z,2025-01-03T10:31:01.469417618Z,10,2,16244,C,B,1,382.990000000,8,130,165696,4862825,383.000000000,383.300000000,8,20,1,1,382.990000000,383.420000000,4,140,1,1,382.900000000,383.600000000,23,500,1,1,382.810000000,383.720000000,20,7085,2,8,382.720000000,383.740000000,10,37,1,1,382.700000000,383.800000000,50,10,1,1,382.680000000,383.880000000,20,4,1,1,382.500000000,384.000000000,3,1300,1,4,382.400000000,384.260000000,500,15,1,1,382.230000000,384.400000000,25,1000,1,2,TSLA
2025-01-03T10:31:01.469594438Z,2025-01-03T10:31:01.469428586Z,10,2,16244,C,B,0,383.000000000,8,130,165852,4862826,382.990000000,383.300000000,4,20,1,1,382.900000000,383.420000000,23,140,1,1,382.810000000,383.600000000,20,500,2,1,382.720000000,383.720000000,10,7085,1,8,382.700000000,383.740000000,50,37,1,1,382.680000000,383.800000000,20,10,1,1,382.500000000,383.880000000,3,4,1,1,382.400000000,384.000000000,500,1300,1,4,382.230000000,384.260000000,25,15,1,1,382.110000000,384.400000000,300,1000,1,2,TSLA
2025-01-03T10:31:01.495411732Z,2025-01-03T10:31:01.495245203Z,10,2,16244,A,A,2,383.600000000,500,130,166529,4862885,382.990000000,383.300000000,4,20,1,1,382.900000000,383.420000000,23,140,1,1,382.810000000,383.600000000,20,1000,2,2,382.720000000,383.720000000,10,7085,1,8,382.700000000,383.740000000,50,37,1,1,382.680000000,383.800000000,20,10,1,1,382.500000000,383.880000000,3,4,1,1,382.400000000,384.000000000,500,1300,1,4,382.230000000,384.260000000,25,15,1,1,382.110000000,384.400000000,300,1000,1,2,TSLA
2025-01-03T10:31:01.495579630Z,2025-01-03T10:31:01.495413792Z,10,2,9155,C,B,1,241.540000000,8,130,165838,4862886,241.670000000,242.070000000,2,62,1,1,241.120000000,242.520000000,81,8,1,1,241.000000000,242.850000000,100,300,1,2,240.000000000,242.900000000,10,100,1,1,238.000000000,243.000000000,30,92,1,2,236.000000000,243.310000000,6,10,1,1,235.500000000,243.700000000,5,100,1,1,235.000000000,246.810000000,5,100,1,1,232.880000000,262.740000000,1,100,1,1,231.110000000,263.830000000,3,100,1,1,JPM
2025-01-03T10:31:01.495641179Z,2025-01-03T10:31:01.495475208Z,10,2,9155,A,B,1,241.550000000,8,130,165971,4862887,241.670000000,242.070000000,2,62,1,1,241.550000000,242.520000000,8,8,1,1,241.120000000,242.850000000,81,300,1,2,241.000000000,242.900000000,100,100,1,1,240.000000000,243.000000000,10,92,1,2,238.000000000,243.310000000,30,10,1,1,236.000000000,243.700000000,6,100,1,1,235.500000000,246.810000000,5,100,1,1,235.000000000,262.740000000,5,100,1,1,232.880000000,263.830000000,1,100,1,1,JPM
2025-01-03T10:31:01.504666701Z,2025-01-03T10:31:01.504500634Z,10,2,9155,C,A,1,242.520000000,8,130,166067,4862892,241.670000000,242.070000000,2,62,1,1,241.550000000,242.850000000,8,300,1,2,241.120000000,242.900000000,81,100,1,1,241.000000000,243.000000000,100,92,1,2,240.000000000,243.310000000,10,10,1,1,238.000000000,243.700000000,30,100,1,1,236.000000000,246.810000000,6,100,1,1,235.500000000,262.740000000,5,100,1,1,235.000000000,263.830000000,5,100,1,1,232.880000000,,1,0,1,0,JPM
2025-01-03T10:31:01.504912715Z,2025-01-03T10:31:01.504746399Z,10,2,9155,A,A,1,242.480000000,8,130,166316,4862893,241.670000000,242.070000000,2,62,1,1,241.550000000,242.480000000,8,8,1,1,241.120000000,242.850000000,81,300,1,2,241.000000000,242.900000000,100,100,1,1,240.000000000,243.000000000,10,92,1,2,238.000000000,243.310000000,30,10,1,1,236.000000000,243.700000000,6,100,1,1,235.500000000,246.810000000,5,100,1,1,235.000000000,262.740000000,5,100,1,1,232.880000000,263.830000000,1,100,1,1,JPM
2025-01-03T10:31:01.505472448Z,2025-01-03T10:31:01.505306407Z,10,2,9155,C,A,1,242.480000000,8,130,166041,4862894,241.670000000,242.070000000,2,62,1,1,241.550000000,242.850000000,8,300,1,2,241.120000000,242.900000000,81,100,1,1,241.000000000,243.000000000,100,92,1,2,240.000000000,243.310000000,10,10,1,1,238.000000000,243.700000000,30,100,1,1,236.000000000,246.810000000,6,100,1,1,235.500000000,262.740000000,5,100,1,1,235.000000000,263.830000000,5,100,1,1,232.880000000,,1,0,1,0,JPM
2025-01-03T10:31:01.512755514Z,2025-01-03T10:31:01.512589360Z,10,2,16244,C,B,1,382.900000000,23,130,166154,4862906,382.990000000,383.300000000,4,20,1,1,382.810000000,383.420000000,20,140,2,1,382.720000000,383.600000000,10,1000,1,2,382.700000000,383.720000000,50,7085,1,8,382.680000000,383.740000000,20,37,1,1,382.500000000,383.800000000,3,10,1,1,382.400000000,383.880000000,500,4,1,1,382.230000000,384.000000000,25,1300,1,4,382.110000000,384.260000000,300,15,1,1,382.100000000,384.400000000,20,1000,2,2,TSLA
2025-01-03T10:31:01.512775404Z,2025-01-03T10:31:01.512609535Z,10,2,16244,C,B,0,382.990000000,4,130,165869,4862907,382.810000000,383.300000000,20,20,2,1,382.720000000,383.420000000,10,140,1,1,382.700000000,383.600000000,50,1000,1,2,382.680000000,383.720000000,20,7085,1,8,382.500000000,383.740000000,3,37,1,1,382.400000000,383.800000000,500,10,1,1,382.230000000,383.880000000,25,4,1,1,382.110000000,384.000000000,300,1300,1,4,382.100000000,384.260000000,20,15,2,1,382.010000000,384.400000000,2,1000,1,2,TSLA
2025-01-03T10:31:01.512830009Z,2025-01-03T10:31:01.512663388Z,10,2,16244,A,B,0,382.950000000,21,130,166621,4862908,382.950000000,383.300000000,21,20,1,1,382.810000000,383.420000000,20,140,2,1,382.720000000,383.600000000,10,1000,1,2,382.700000000,383.720000000,50,7085,1,8,382.680000000,383.740000000,20,37,1,1,382.500000000,383.800000000,3,10,1,1,382.400000000,383.880000000,500,4,1,1,382.230000000,384.000000000,25,1300,1,4,382.110000000,384.260000000,300,15,1,1,382.100000000,384.400000000,20,1000,2,2,TSLA
2025-01-03T10:31:01.523275082Z,2025-01-03T10:31:01.523108613Z,10,2,17709,A,B,1,107.570000000,15,130,166469,4862917,107.600000000,107.840000000,50,400,1,2,107.570000000,107.870000000,15,242,1,1,107.520000000,107.940000000,100,100,1,1,107.050000000,107.950000000,247,10,1,1,107.000000000,108.000000000,1,50,1,1,106.240000000,108.300000000,28,50,1,1,106.000000000,108.550000000,15,50,2,1,105.870000000,108.800000000,141,50,1,1,103.180000000,108.880000000,16,28,1,1,103.000000000,109.450000000,3,137,1,1,XOM
2025-01-03T10:31:01.523390691Z,2025-01-03T10:31:01.523224805Z,10,2,38,C,B,1,243.470000000,400,130,165886,4862922,243.500000000,243.640000000,6,54,1,1,243.400000000,243.650000000,29,61,1,2,243.190000000,243.700000000,2,200,1,1,243.020000000,243.760000000,79,27,1,1,243.000000000,244.000000000,1243,1,9,1,242.990000000,244.140000000,1,79,1,1,242.750000000,244.200000000,30,1000,1,1,242.590000000,244.400000000,5,50,1,1,242.280000000,244.420000000,100,10,1,1,242.170000000,244.580000000,100,100,1,1,AAPL
2025-01-03T10:31:01.523403664Z,2025-01-03T10:31:01.523237680Z,10,2,38,A,B,1,243.440000000,200,130,165984,4862923,243.500000000,243.640000000,6,54,1,1,243.440000000,243.650000000,200,61,1,2,243.400000000,243.700000000,29,200,1,1,243.190000000,243.760000000,2,27,1,1,243.020000000,244.000000000,79,1,1,1,243.000000000,244.140000000,1243,79,9,1,242.990000000,244.200000000,1,1000,1,1,242.750000000,244.400000000,30,50,1,1,242.590000000,244.420000000,5,10,1,1,242.280000000,244.580000000,100,100,1,1,AAPL
2025-01-03T10:31:01.531258881Z,2025-01-03T10:31:01.531093012Z,10,2,16244,C,B,0,382.950000000,21,130,165869,4862930,382.810000000,383.300000000,20,20,2,1,382.720000000,383.420000000,10,140,1,1,382.700000000,383.600000000,50,1000,1,2,382.680000000,383.720000000,20,7085,1,8,382.500000000,383.740000000,3,37,1,1,382.400000000,383.800000000,500,10,1,1,382.230000000,383.880000000,25,4,1,1,382.110000000,384.000000000,300,1300,1,4,382.100000000,384.260000000,20,15,2,1,382.010000000,384.400000000,2,1000,1,2,TSLA
2025-01-03T10:31:01.531630742Z,2025-01-03T10:31:01.531464659Z,10,2,38,C,A,3,243.760000000,27,130,166083,4862935,243.500000000,243.640000000,6,54,1,1,243.440000000,243.650000000,200,61,1,2,243.400000000,243.700000000,29,200,1,1,243.190000000,244.000000000,2,1,1,1,243.020000000,244.140000000,79,79,1,1,243.000000000,244.200000000,1243,1000,9,1,242.990000000,244.400000000,1,50,1,1,242.750000000,244.420000000,30,10,1,1,242.590000000,244.580000000,5,100,1,1,242.280000000,245.000000000,100,79,1,2,AAPL
2025-01-03T10:31:01.531694311Z,2025-01-03T10:31:01.531528172Z,10,2,38,A,A,3,243.720000000,29,130,166139,4862936,243.500000000,243.640000000,6,54,1,1,243.440000000,243.650000000,200,61,1,2,243.400000000,243.700000000,29,200,1,1,243.190000000,243.720000000,2,29,1,1,243.020000000,244.000000000,79,1,1,1,243.000000000,244.140000000,1243,79,9,1,242.990000000,244.200000000,1,1000,1,1,242.750000000,244.400000000,30,50,1,1,242.590000000,244.420000000,5,10,1,1,242.280000000,244.580000000,100,100,1,1,AAPL
2025-01-03T10:31:01.575630564Z,2025-01-03T10:31:01.575464221Z,10,2,16244,A,B,0,382.960000000,21,130,166343,4862953,382.960000000,383.300000000,21,20,1,1,382.810000000,383.420000000,20,140,2,1,382.720000000,383.600000000,10,1000,1,2,382.700000000,383.720000000,50,7085,1,8,382.680000000,383.740000000,20,37,1,1,382.500000000,383.800000000,3,10,1,1,382.400000000,383.880000000,500,4,1,1,382.230000000,384.000000000,25,1300,1,4,382.110000000,384.260000000,300,15,1,1,382.100000000,384.400000000,20,1000,2,2,TSLA
2025-01-03T10:31:01.577275928Z,2025-01-03T10:31:01.577109794Z,10,2,38,A,A,2,243.670000000,200,130,166134,4862955,243.500000000,243.640000000,6,54,1,1,243.440000000,243.650000000,200,61,1,2,243.400000000,243.670000000,29,200,1,1,243.190000000,243.720000000,2,29,1,1,243.020000000,244.000000000,79,1,1,1,243.000000000,244.140000000,1243,79,9,1,242.990000000,244.200000000,1,1000,1,1,242.750000000,244.400000000,30,50,1,1,242.590000000,244.420000000,5,10,1,1,242.280000000,244.580000000,100,100,1,1,AAPL
2025-01-03T10:31:01.818096879Z,2025-01-03T10:31:01.817930501Z,10,2,17709,A,A,2,107.910000000,17,130,166378,4863004,107.600000000,107.840000000,50,400,1,2,107.570000000,107.870000000,15,242,1,1,107.520000000,107.910000000,100,17,1,1,107.050000000,107.940000000,247,100,1,1,107.000000000,107.950000000,1,10,1,1,106.240000000,108.000000000,28,50,1,1,106.000000000,108.300000000,15,50,2,1,105.870000000,108.550000000,141,50,1,1,103.180000000,108.800000000,16,50,1,1,103.000000000,108.880000000,3,28,1,1,XOM
2025-01-03T10:31:02.033819849Z,2025-01-03T10:31:02.033653606Z,10,2,9155,A,A,1,242.430000000,8,130,166243,4863047,241.670000000,242.070000000,2,62,1,1,241.550000000,242.430000000,8,8,1,1,241.120000000,242.850000000,81,300,1,2,241.000000000,242.900000000,100,100,1,1,240.000000000,243.000000000,10,92,1,2,238.000000000,243.310000000,30,10,1,1,236.000000000,243.700000000,6,100,1,1,235.500000000,246.810000000,5,100,1,1,235.000000000,262.740000000,5,100,1,1,232.880000000,263.830000000,1,100,1,1,JPM
2025-01-03T10:31:02.036858947Z,2025-01-03T10:31:02.036692759Z,10,2,780,A,B,4,255.920000000,1,130,166188,4863049,259.250000000,260.950000000,25,25,1,1,259.010000000,270.990000000,181,203,2,2,258.100000000,294.170000000,25,100,1,1,257.700000000,295.390000000,1,100,1,1,255.920000000,,1,0,1,0,250.000000000,,13,0,2,0,236.860000000,,100,0,1,0,235.690000000,,100,0,1,0,,,0,0,0,0,,,0,0,0,0,AMGN
2025-01-03T10:31:02.324631396Z,2025-01-03T10:31:02.324465004Z,10,2,16244,A,A,2,383.500000000,22,130,166392,4863404,382.960000000,383.300000000,21,20,1,1,382.810000000,383.420000000,20,140,2,1,382.720000000,383.500000000,10,22,1,1,382.700000000,383.600000000,50,1000,1,2,382.680000000,383.720000000,20,7085,1,8,382.500000000,383.740000000,3,37,1,1,382.400000000,383.800000000,500,10,1,1,382.230000000,383.880000000,25,4,1,1,382.110000000,384.000000000,300,1300,1,4,382.100000000,384.260000000,20,15,2,1,TSLA
2025-01-03T10:31:03.995599498Z,2025-01-03T10:31:03.995433384Z,10,2,38,A,B,1,243.440000000,200,130,166114,4864175,243.500000000,243.640000000,6,54,1,1,243.440000000,243.650000000,400,61,2,2,243.400000000,243.670000000,29,200,1,1,243.190000000,243.720000000,2,29,1,1,243.020000000,244.000000000,79,1,1,1,243.000000000,244.140000000,1243,79,9,1,242.990000000,244.200000000,1,1000,1,1,242.750000000,244.400000000,30,50,1,1,242.590000000,244.420000000,5,10,1,1,242.280000000,244.580000000,100,100,1,1,AAPL
2025-01-03T10:31:03.995636385Z,2025-01-03T10:31:03.995470351Z,10,2,38,C,A,2,243.670000000,200,130,166034,4864176,243.500000000,243.640000000,6,54,1,1,243.440000000,243.650000000,400,61,2,2,243.400000000,243.720000000,29,29,1,1,243.190000000,244.000000000,2,1,1,1,243.020000000,244.140000000,79,79,1,1,243.000000000,244.200000000,1243,1000,9,1,242.990000000,244.400000000,1,50,1,1,242.750000000,244.420000000,30,10,1,1,242.590000000,244.580000000,5,100,1,1,242.280000000,245.000000000,100,79,1,2,AAPL
2025-01-03T10:31:03.995648068Z,2025-01-03T10:31:03.995481992Z,10,2,38,A,A,2,243.700000000,200,130,166076,4864177,243.500000000,243.640000000,6,54,1,1,243.440000000,243.650000000,400,61,2,2,243.400000000,243.700000000,29,200,1,1,243.190000000,243.720000000,2,29,1,1,243.020000000,244.000000000,79,1,1,1,243.000000000,244.140000000,1243,79,9,1,242.990000000,244.200000000,1,1000,1,1,242.750000000,244.400000000,30,50,1,1,242.590000000,244.420000000,5,10,1,1,242.280000000,244.580000000,100,100,1,1,AAPL
2025-01-03T10:31:03.996191508Z,2025-01-03T10:31:03.996024967Z,10,2,38,A,A,4,243.770000000,28,130,166541,4864178,243.500000000,243.640000000,6,54,1,1,243.440000000,243.650000000,400,61,2,2,243.400000000,243.700000000,29,200,1,1,243.190000000,243.720000000,2,29,1,1,243.020000000,243.770000000,79,28,1,1,243.000000000,244.000000000,1243,1,9,1,242.990000000,244.140000000,1,79,1,1,242.750000000,244.200000000,30,1000,1,1,242.590000000,244.400000000,5,50,1,1,242.280000000,244.420000000,100,10,1,1,AAPL
2025-01-03T10:31:03.996233124Z,2025-01-03T10:31:03.996067129Z,10,2,38,C,A,3,243.720000000,29,130,165995,4864179,243.500000000,243.640000000,6,54,1,1,243.440000000,243.650000000,400,61,2,2,243.400000000,243.700000000,29,200,1,1,243.190000000,243.770000000,2,28,1,1,243.020000000,244.000000000,79,1,1,1,243.000000000,244.140000000,1243,79,9,1,242.990000000,244.200000000,1,1000,1,1,242.750000000,244.400000000,30,50,1,1,242.590000000,244.420000000,5,10,1,1,242.280000000,244.580000000,100,100,1,1,AAPL
2025-01-03T10:31:04.001422525Z,2025-01-03T10:31:04.001256542Z,10,2,38,C,A,2,243.700000000,200,130,165983,4864180,243.500000000,243.640000000,6,54,1,1,243.440000000,243.650000000,400,61,2,2,243.400000000,243.770000000,29,28,1,1,243.190000000,244.000000000,2,1,1,1,243.020000000,244.140000000,79,79,1,1,243.000000000,244.200000000,1243,1000,9,1,242.990000000,244.400000000,1,50,1,1,242.750000000,244.420000000,30,10,1,1,242.590000000,244.580000000,5,100,1,1,242.280000000,245.000000000,100,79,1,2,AAPL
2025-01-03T10:31:04.001435868Z,2025-01-03T10:31:04.001269519Z,10,2,38,A,A,2,243.720000000,200,130,166349,4864181,243.500000000,243.640000000,6,54,1,1,243.440000000,243.650000000,400,61,2,2,243.400000000,243.720000000,29,200,1,1,243.190000000,243.770000000,2,28,1,1,243.020000000,244.000000000,79,1,1,1,243.000000000,244.140000000,1243,79,9,1,242.990000000,244.200000000,1,1000,1,1,242.750000000,244.400000000,30,50,1,1,242.590000000,244.420000000,5,10,1,1,242.280000000,244.580000000,100,100,1,1,AAPL
2025-01-03T10:31:04.046802083Z,2025-01-03T10:31:04.046636133Z,10,2,38,C,B,1,243.440000000,200,130,165950,4864196,243.500000000,243.640000000,6,54,1,1,243.440000000,243.650000000,200,61,1,2,243.400000000,243.720000000,29,200,1,1,243.190000000,243.770000000,2,28,1,1,243.020000000,244.000000000,79,1,1,1,243.000000000,244.140000000,1243,79,9,1,242.990000000,244.200000000,1,1000,1,1,242.750000000,244.400000000,30,50,1,1,242.590000000,244.420000000,5,10,1,1,242.280000000,244.580000000,100,100,1,1,AAPL
2025-01-03T10:31:04.046816263Z,2025-01-03T10:31:04.046649818Z,10,2,38,A,B,1,243.470000000,200,130,166445,4864197,243.500000000,243.640000000,6,54,1,1,243.470000000,243.650000000,200,61,1,2,243.400000000,243.720000000,29,200,1,1,243.190000000,243.770000000,2,28,1,1,243.020000000,244.000000000,79,1,1,1,243.000000000,244.140000000,1243,79,9,1,242.990000000,244.200000000,1,1000,1,1,242.750000000,244.400000000,30,50,1,1,242.590000000,244.420000000,5,10,1,1,242.280000000,244.580000000,100,100,1,1,AAPL
2025-01-03T10:31:04.274629006Z,2025-01-03T10:31:04.274463063Z,10,2,16244,C,A,3,383.600000000,500,130,165943,4864262,382.960000000,383.300000000,21,20,1,1,382.810000000,383.420000000,20,140,2,1,382.720000000,383.500000000,10,22,1,1,382.700000000,383.600000000,50,500,1,1,382.680000000,383.720000000,20,7085,1,8,382.500000000,383.740000000,3,37,1,1,382.400000000,383.800000000,500,10,1,1,382.230000000,383.880000000,25,4,1,1,382.110000000,384.000000000,300,1300,1,4,382.100000000,384.260000000,20,15,2,1,TSLA
2025-01-03T10:31:04.471304303Z,2025-01-03T10:31:04.471137902Z,10,2,11667,A,A,6,139.270000000,20,130,166401,4864336,139.130000000,139.160000000,100,230,1,1,139.120000000,139.180000000,30,400,1,1,139.110000000,139.200000000,1,429,1,2,139.080000000,139.220000000,57,10,1,1,139.070000000,139.230000000,400,25,1,1,139.030000000,139.250000000,126,1,2,1,139.010000000,139.270000000,100,37,1,2,139.000000000,139.300000000,420,507,5,4,138.980000000,139.320000000,300,39,1,1,138.970000000,139.330000000,800,503,2,2,NVDA
2025-01-03T10:31:04.804420322Z,2025-01-03T10:31:04.804253855Z,10,2,10888,A,B,7,420.000000000,500,130,166467,4864469,420.720000000,421.250000000,200,200,1,1,420.640000000,421.310000000,13,15,1,1,420.580000000,421.460000000,10,39,1,1,420.520000000,421.490000000,1,6,1,1,420.400000000,421.570000000,858,40,1,1,420.380000000,421.600000000,100,10,1,1,420.100000000,421.700000000,100,359,1,1,420.000000000,421.800000000,534,7,7,1,419.730000000,422.100000000,3,7,1,1,419.650000000,422.400000000,39,500,1,1,MSFT
2025-01-03T10:31:04.812936458Z,2025-01-03T10:31:04.812770357Z,10,2,10888,C,B,7,420.000000000,500,130,166101,4864474,420.720000000,421.250000000,200,200,1,1,420.640000000,421.310000000,13,15,1,1,420.580000000,421.460000000,10,39,1,1,420.520000000,421.490000000,1,6,1,1,420.400000000,421.570000000,858,40,1,1,420.380000000,421.600000000,100,10,1,1,420.100000000,421.700000000,100,359,1,1,420.000000000,421.800000000,34,7,6,1,419.730000000,422.100000000,3,7,1,1,419.650000000,422.400000000,39,500,1,1,MSFT
2025-01-03T10:31:04.896128751Z,2025-01-03T10:31:04.895962418Z,10,2,11667,C,B,4,139.070000000,400,130,166333,4864517,139.130000000,139.160000000,100,230,1,1,139.120000000,139.180000000,30,400,1,1,139.110000000,139.200000000,1,429,1,2,139.080000000,139.220000000,57,10,1,1,139.030000000,139.230000000,126,25,2,1,139.010000000,139.250000000,100,1,1,1,139.000000000,139.270000000,420,37,5,2,138.980000000,139.300000000,300,507,1,4,138.970000000,139.320000000,800,39,2,1,138.940000000,139.330000000,400,503,1,2,NVDA
2025-01-03T10:31:04.896142894Z,2025-01-03T10:31:04.895976483Z,10,2,11667,A,B,4,139.060000000,400,130,166411,4864518,139.130000000,139.160000000,100,230,1,1,139.120000000,139.180000000,30,400,1,1,139.110000000,139.200000000,1,429,1,2,139.080000000,139.220000000,57,10,1,1,139.060000000,139.230000000,400,25,1,1,139.030000000,139.250000000,126,1,2,1,139.010000000,139.270000000,100,37,1,2,139.000000000,139.300000000,420,507,5,4,138.980000000,139.320000000,300,39,1,1,138.970000000,139.330000000,800,503,2,2,NVDA
2025-01-03T10:31:05.481029538Z,2025-01-03T10:31:05.480862671Z,10,2,16244,A,A,3,383.600000000,500,130,166867,4864845,382.960000000,383.300000000,21,20,1,1,382.810000000,383.420000000,20,140,2,1,382.720000000,383.500000000,10,22,1,1,382.700000000,383.600000000,50,1000,1,2,382.680000000,383.720000000,20,7085,1,8,382.500000000,383.740000000,3,37,1,1,382.400000000,383.800000000,500,10,1,1,382.230000000,383.880000000,25,4,1,1,382.110000000,384.000000000,300,1300,1,4,382.100000000,384.260000000,20,15,2,1,TSLA
2025-01-03T10:31:05.952448297Z,2025-01-03T10:31:05.952281981Z,10,2,16244,A,B,1,382.920000000,21,130,166316,4865010,382.960000000,383.300000000,21,20,1,1,382.920000000,383.420000000,21,140,1,1,382.810000000,383.500000000,20,22,2,1,382.720000000,383.600000000,10,1000,1,2,382.700000000,383.720000000,50,7085,1,8,382.680000000,383.740000000,20,37,1,1,382.500000000,383.800000000,3,10,1,1,382.400000000,383.880000000,500,4,1,1,382.230000000,384.000000000,25,1300,1,4,382.110000000,384.260000000,300,15,1,1,TSLA
2025-01-03T10:31:06.037579878Z,2025-01-03T10:31:06.037413847Z,10,2,780,C,A,0,260.950000000,25,130,166031,4865019,259.250000000,270.990000000,25,203,1,2,259.010000000,294.170000000,181,100,2,1,258.100000000,295.390000000,25,100,1,1,257.700000000,,1,0,1,0,255.920000000,,1,0,1,0,250.000000000,,13,0,2,0,236.860000000,,100,0,1,0,235.690000000,,100,0,1,0,,,0,0,0,0,,,0,0,0,0,AMGN
2025-01-03T10:31:06.037593786Z,2025-01-03T10:31:06.037427624Z,10,2,780,A,A,0,261.460000000,25,130,166162,4865020,259.250000000,261.460000000,25,25,1,1,259.010000000,270.990000000,181,203,2,2,258.100000000,294.170000000,25,100,1,1,257.700000000,295.390000000,1,100,1,1,255.920000000,,1,0,1,0,250.000000000,,13,0,2,0,236.860000000,,100,0,1,0,235.690000000,,100,0,1,0,,,0,0,0,0,,,0,0,0,0,AMGN
2025-01-03T10:31:06.093659518Z,2025-01-03T10:31:06.093493023Z,10,2,780,A,B,0,259.420000000,25,130,166495,4865040,259.420000000,261.460000000,25,25,1,1,259.010000000,270.990000000,181,203,2,2,258.100000000,294.170000000,25,100,1,1,257.700000000,295.390000000,1,100,1,1,255.920000000,,1,0,1,0,250.000000000,,13,0,2,0,236.860000000,,100,0,1,0,235.690000000,,100,0,1,0,,,0,0,0,0,,,0,0,0,0,AMGN
2025-01-03T10:31:06.106660018Z,2025-01-03T10:31:06.106493518Z,10,2,780,A,A,0,261.290000000,25,130,166500,4865046,259.420000000,261.290000000,25,25,1,1,259.010000000,270.990000000,181,203,2,2,258.100000000,294.170000000,25,100,1,1,257.700000000,295.390000000,1,100,1,1,255.920000000,,1,0,1,0,250.000000000,,13,0,2,0,236.860000000,,100,0,1,0,235.690000000,,100,0,1,0,,,0,0,0,0,,,0,0,0,0,AMGN
2025-01-03T10:31:07.528474879Z,2025-01-03T10:31:07.528308904Z,10,2,38,C,B,1,243.470000000,200,130,165975,4865625,243.500000000,243.640000000,6,54,1,1,243.400000000,243.650000000,29,61,1,2,243.190000000,243.720000000,2,200,1,1,243.020000000,243.770000000,79,28,1,1,243.000000000,244.000000000,1243,1,9,1,242.990000000,244.140000000,1,79,1,1,242.750000000,244.200000000,30,1000,1,1,242.590000000,244.400000000,5,50,1,1,242.280000000,244.420000000,100,10,1,1,242.170000000,244.580000000,100,100,1,1,AAPL
2025-01-03T10:31:07.528488184Z,2025-01-03T10:31:07.528321993Z,10,2,38,A,B,1,243.440000000,200,130,166191,4865626,243.500000000,243.640000000,6,54,1,1,243.440000000,243.650000000,200,61,1,2,243.400000000,243.720000000,29,200,1,1,243.190000000,243.770000000,2,28,1,1,243.020000000,244.000000000,79,1,1,1,243.000000000,244.140000000,1243,79,9,1,242.990000000,244.200000000,1,1000,1,1,242.750000000,244.400000000,30,50,1,1,242.590000000,244.420000000,5,10,1,1,242.280000000,244.580000000,100,100,1,1,AAPL
2025-01-03T10:31:07.585678339Z,2025-01-03T10:31:07.585511557Z,10,2,38,A,A,2,243.700000000,200,130,166782,4865708,243.500000000,243.640000000,6,54,1,1,243.440000000,243.650000000,200,61,1,2,243.400000000,243.700000000,29,200,1,1,243.190000000,243.770000000,2,28,1,1,243.020000000,244.000000000,79,1,1,1,243.000000000,244.140000000,1243,79,9,1,242.990000000,244.200000000,1,1000,1,1,242.750000000,244.400000000,30,50,1,1,242.590000000,244.420000000,5,10,1,1,242.280000000,244.580000000,100,100,1,1,AAPL
2025-01-03T10:31:07.635406328Z,2025-01-03T10:31:07.635239776Z,10,2,17709,A,A,2,107.890000000,16,130,166552,4865763,107.600000000,107.840000000,50,400,1,2,107.570000000,107.870000000,15,242,1,1,107.520000000,107.890000000,100,16,1,1,107.050000000,107.910000000,247,17,1,1,107.000000000,107.940000000,1,100,1,1,106.240000000,107.950000000,28,10,1,1,106.000000000,108.000000000,15,50,2,1,105.870000000,108.300000000,141,50,1,1,103.180000000,108.550000000,16,50,1,1,103.000000000,108.800000000,3,50,1,1,XOM
2025-01-03T10:31:07.635431387Z,2025-01-03T10:31:07.635265479Z,10,2,17709,C,A,3,107.910000000,17,130,165908,4865764,107.600000000,107.840000000,50,400,1,2,107.570000000,107.870000000,15,242,1,1,107.520000000,107.890000000,100,16,1,1,107.050000000,107.940000000,247,100,1,1,107.000000000,107.950000000,1,10,1,1,106.240000000,108.000000000,28,50,1,1,106.000000000,108.300000000,15,50,2,1,105.870000000,108.550000000,141,50,1,1,103.180000000,108.800000000,16,50,1,1,103.000000000,108.880000000,3,28,1,1,XOM
2025-01-03T10:31:07.639488644Z,2025-01-03T10:31:07.639322316Z,10,2,17709,A,B,2,107.540000000,17,130,166328,4865778,107.600000000,107.840000000,50,400,1,2,107.570000000,107.870000000,15,242,1,1,107.540000000,107.890000000,17,16,1,1,107.520000000,107.940000000,100,100,1,1,107.050000000,107.950000000,247,10,1,1,107.000000000,108.000000000,1,50,1,1,106.240000000,108.300000000,28,50,1,1,106.000000000,108.550000000,15,50,2,1,105.870000000,108.800000000,141,50,1,1,103.180000000,108.880000000,16,28,1,1,XOM
2025-01-03T10:31:07.639506098Z,2025-01-03T10:31:07.639340152Z,10,2,17709,C,B,1,107.570000000,15,130,165946,4865779,107.600000000,107.840000000,50,400,1,2,107.540000000,107.870000000,17,242,1,1,107.520000000,107.890000000,100,16,1,1,107.050000000,107.940000000,247,100,1,1,107.000000000,107.950000000,1,10,1,1,106.240000000,108.000000000,28,50,1,1,106.000000000,108.300000000,15,50,2,1,105.870000000,108.550000000,141,50,1,1,103.180000000,108.800000000,16,50,1,1,103.000000000,108.880000000,3,28,1,1,XOM
2025-01-03T10:31:08.733630723Z,2025-01-03T10:31:08.733464115Z,10,2,38,C,A,2,243.700000000,200,130,166608,4866360,243.500000000,243.640000000,6,54,1,1,243.440000000,243.650000000,200,61,1,2,243.400000000,243.770000000,29,28,1,1,243.190000000,244.000000000,2,1,1,1,243.020000000,244.140000000,79,79,1,1,243.000000000,244.200000000,1243,1000,9,1,242.990000000,244.400000000,1,50,1,1,242.750000000,244.420000000,30,10,1,1,242.590000000,244.580000000,5,100,1,1,242.280000000,245.000000000,100,79,1,2,AAPL
2025-01-03T10:31:08.816900293Z,2025-01-03T10:31:08.816733519Z,10,2,38,A,A,2,243.700000000,200,130,166774,4867023,243.500000000,243.640000000,6,54,1,1,243.440000000,243.650000000,200,61,1,2,243.400000000,243.700000000,29,200,1,1,243.190000000,243.770000000,2,28,1,1,243.020000000,244.000000000,79,1,1,1,243.000000000,244.140000000,1243,79,9,1,242.990000000,244.200000000,1,1000,1,1,242.750000000,244.400000000,30,50,1,1,242.590000000,244.420000000,5,10,1,1,242.280000000,244.580000000,100,100,1,1,AAPL
2025-01-03T10:31:08.823540598Z,2025-01-03T10:31:08.823374818Z,10,2,11667,C,A,1,139.180000000,400,130,165780,4867047,139.130000000,139.160000000,100,230,1,1,139.120000000,139.200000000,30,429,1,2,139.110000000,139.220000000,1,10,1,1,139.080000000,139.230000000,57,25,1,1,139.060000000,139.250000000,400,1,1,1,139.030000000,139.270000000,126,37,2,2,139.010000000,139.300000000,100,507,1,4,139.000000000,139.320000000,420,39,5,1,138.980000000,139.330000000,300,503,1,2,138.970000000,139.360000000,800,14,2,3,NVDA
2025-01-03T10:31:08.823553956Z,2025-01-03T10:31:08.823387835Z,10,2,11667,A,A,1,139.190000000,400,130,166121,4867048,139.130000000,139.160000000,100,230,1,1,139.120000000,139.190000000,30,400,1,1,139.110000000,139.200000000,1,429,1,2,139.080000000,139.220000000,57,10,1,1,139.060000000,139.230000000,400,25,1,1,139.030000000,139.250000000,126,1,2,1,139.010000000,139.270000000,100,37,1,2,139.000000000,139.300000000,420,507,5,4,138.980000000,139.320000000,300,39,1,1,138.970000000,139.330000000,800,503,2,2,NVDA
2025-01-03T10:31:08.871718660Z,2025-01-03T10:31:08.871552712Z,10,2,38,C,A,3,243.770000000,28,130,165948,4867153,243.500000000,243.640000000,6,54,1,1,243.440000000,243.650000000,200,61,1,2,243.400000000,243.700000000,29,200,1,1,243.190000000,244.000000000,2,1,1,1,243.020000000,244.140000000,79,79,1,1,243.000000000,244.200000000,1243,1000,9,1,242.990000000,244.400000000,1,50,1,1,242.750000000,244.420000000,30,10,1,1,242.590000000,244.580000000,5,100,1,1,242.280000000,245.000000000,100,79,1,2,AAPL
2025-01-03T10:31:08.871866854Z,2025-01-03T10:31:08.871700378Z,10,2,38,A,A,3,243.720000000,26,130,166476,4867154,243.500000000,243.640000000,6,54,1,1,243.440000000,243.650000000,200,61,1,2,243.400000000,243.700000000,29,200,1,1,243.190000000,243.720000000,2,26,1,1,243.020000000,244.000000000,79,1,1,1,243.000000000,244.140000000,1243,79,9,1,242.990000000,244.200000000,1,1000,1,1,242.750000000,244.400000000,30,50,1,1,242.590000000,244.420000000,5,10,1,1,242.280000000,244.580000000,100,100,1,1,AAPL
2025-01-03T10:31:08.873435287Z,2025-01-03T10:31:08.873269102Z,10,2,16244,C,A,2,383.500000000,22,130,166185,4867156,382.960000000,383.300000000,21,20,1,1,382.920000000,383.420000000,21,140,1,1,382.810000000,383.600000000,20,1000,2,2,382.720000000,383.720000000,10,7085,1,8,382.700000000,383.740000000,50,37,1,1,382.680000000,383.800000000,20,10,1,1,382.500000000,383.880000000,3,4,1,1,382.400000000,384.000000000,500,1300,1,4,382.230000000,384.260000000,25,15,1,1,382.110000000,384.400000000,300,1000,1,2,TSLA
2025-01-03T10:31:08.873540851Z,2025-01-03T10:31:08.873374414Z,10,2,16244,A,A,2,383.450000000,23,130,166437,4867158,382.960000000,383.300000000,21,20,1,1,382.920000000,383.420000000,21,140,1,1,382.810000000,383.450000000,20,23,2,1,382.720000000,383.600000000,10,1000,1,2,382.700000000,383.720000000,50,7085,1,8,382.680000000,383.740000000,20,37,1,1,382.500000000,383.800000000,3,10,1,1,382.400000000,383.880000000,500,4,1,1,382.230000000,384.000000000,25,1300,1,4,382.110000000,384.260000000,300,15,1,1,TSLA
2025-01-03T10:31:08.874158599Z,2025-01-03T10:31:08.873992840Z,10,2,16244,C,A,2,383.450000000,23,130,165759,4867159,382.960000000,383.300000000,21,20,1,1,382.920000000,383.420000000,21,140,1,1,382.810000000,383.600000000,20,1000,2,2,382.720000000,383.720000000,10,7085,1,8,382.700000000,383.740000000,50,37,1,1,382.680000000,383.800000000,20,10,1,1,382.500000000,383.880000000,3,4,1,1,382.400000000,384.000000000,500,1300,1,4,382.230000000,384.260000000,25,15,1,1,382.110000000,384.400000000,300,1000,1,2,TSLA
2025-01-03T10:31:08.923946183Z,2025-01-03T10:31:08.923779698Z,10,2,38,A,A,2,243.670000000,200,130,166485,4867237,243.500000000,243.640000000,6,54,1,1,243.440000000,243.650000000,200,61,1,2,243.400000000,243.670000000,29,200,1,1,243.190000000,243.720000000,2,26,1,1,243.020000000,244.000000000,79,1,1,1,243.000000000,244.140000000,1243,79,9,1,242.990000000,244.200000000,1,1000,1,1,242.750000000,244.400000000,30,50,1,1,242.590000000,244.420000000,5,10,1,1,242.280000000,244.580000000,100,100,1,1,AAPL
2025-01-03T10:31:09.226060826Z,2025-01-03T10:31:09.225894838Z,10,2,10888,C,B,0,420.720000000,200,130,165988,4867565,420.640000000,421.250000000,13,200,1,1,420.580000000,421.310000000,10,15,1,1,420.520000000,421.460000000,1,39,1,1,420.400000000,421.490000000,858,6,1,1,420.380000000,421.570000000,100,40,1,1,420.100000000,421.600000000,100,10,1,1,420.000000000,421.700000000,34,359,6,1,419.730000000,421.800000000,3,7,1,1,419.650000000,422.100000000,39,7,1,1,419.600000000,422.400000000,500,500,1,1,MSFT
2025-01-03T10:31:09.226072480Z,2025-01-03T10:31:09.225905913Z,10,2,10888,A,B,0,420.690000000,200,130,166567,4867566,420.690000000,421.250000000,200,200,1,1,420.640000000,421.310000000,13,15,1,1,420.580000000,421.460000000,10,39,1,1,420.520000000,421.490000000,1,6,1,1,420.400000000,421.570000000,858,40,1,1,420.380000000,421.600000000,100,10,1,1,420.100000000,421.700000000,100,359,1,1,420.000000000,421.800000000,34,7,6,1,419.730000000,422.100000000,3,7,1,1,419.650000000,422.400000000,39,500,1,1,MSFT
2025-01-03T10:31:09.238199344Z,2025-01-03T10:31:09.238032647Z,10,2,10888,A,B,7,420.000000000,500,130,166697,4867594,420.690000000,421.250000000,200,200,1,1,420.640000000,421.310000000,13,15,1,1,420.580000000,421.460000000,10,39,1,1,420.520000000,421.490000000,1,6,1,1,420.400000000,421.570000000,858,40,1,1,420.380000000,421.600000000,100,10,1,1,420.100000000,421.700000000,100,359,1,1,420.000000000,421.800000000,534,7,7,1,419.730000000,422.100000000,3,7,1,1,419.650000000,422.400000000,39,500,1,1,MSFT
2025-01-03T10:31:09.280724270Z,2025-01-03T10:31:09.280557932Z,10,2,38,A,A,2,243.660000000,200,130,166338,4867671,243.500000000,243.640000000,6,54,1,1,243.440000000,243.650000000,200,61,1,2,243.400000000,243.660000000,29,200,1,1,243.190000000,243.720000000,2,26,1,1,243.020000000,244.000000000,79,1,1,1,243.000000000,244.140000000,1243,79,9,1,242.990000000,244.200000000,1,1000,1,1,242.750000000,244.400000000,30,50,1,1,242.590000000,244.420000000,5,10,1,1,242.280000000,244.580000000,100,100,1,1,AAPL
2025-01-03T10:31:09.285743364Z,2025-01-03T10:31:09.285576914Z,10,2,9155,A,A,1,242.420000000,8,130,166450,4867703,241.670000000,242.070000000,2,62,1,1,241.550000000,242.420000000,8,8,1,1,241.120000000,242.430000000,81,8,1,1,241.000000000,242.850000000,100,300,1,2,240.000000000,242.900000000,10,100,1,1,238.000000000,243.000000000,30,92,1,2,236.000000000,243.310000000,6,10,1,1,235.500000000,243.700000000,5,100,1,1,235.000000000,246.810000000,5,100,1,1,232.880000000,262.740000000,1,100,1,1,JPM
2025-01-03T10:31:09.285939738Z,2025-01-03T10:31:09.285773568Z,10,2,9155,C,A,2,242.430000000,8,130,166170,4867704,241.670000000,242.070000000,2,62,1,1,241.550000000,242.420000000,8,8,1,1,241.120000000,242.850000000,81,300,1,2,241.000000000,242.900000000,100,100,1,1,240.000000000,243.000000000,10,92,1,2,238.000000000,243.310000000,30,10,1,1,236.000000000,243.700000000,6,100,1,1,235.500000000,246.810000000,5,100,1,1,235.000000000,262.740000000,5,100,1,1,232.880000000,263.830000000,1,100,1,1,JPM
2025-01-03T10:31:09.288317865Z,2025-01-03T10:31:09.288151868Z,10,2,38,C,A,2,243.660000000,200,130,165997,4867705,243.500000000,243.640000000,6,54,1,1,243.440000000,243.650000000,200,61,1,2,243.400000000,243.720000000,29,26,1,1,243.190000000,244.000000000,2,1,1,1,243.020000000,244.140000000,79,79,1,1,243.000000000,244.200000000,1243,1000,9,1,242.990000000,244.400000000,1,50,1,1,242.750000000,244.420000000,30,10,1,1,242.590000000,244.580000000,5,100,1,1,242.280000000,245.000000000,100,79,1,2,AAPL
2025-01-03T10:31:09.288331425Z,2025-01-03T10:31:09.288165136Z,10,2,38,A,A,2,243.690000000,200,130,166289,4867706,243.500000000,243.640000000,6,54,1,1,243.440000000,243.650000000,200,61,1,2,243.400000000,243.690000000,29,200,1,1,243.190000000,243.720000000,2,26,1,1,243.020000000,244.000000000,79,1,1,1,243.000000000,244.140000000,1243,79,9,1,242.990000000,244.200000000,1,1000,1,1,242.750000000,244.400000000,30,50,1,1,242.590000000,244.420000000,5,10,1,1,242.280000000,244.580000000,100,100,1,1,AAPL
2025-01-03T10:31:09.307603734Z,2025-01-03T10:31:09.307437153Z,10,2,38,C,A,3,243.720000000,26,130,166581,4867764,243.500000000,243.640000000,6,54,1,1,243.440000000,243.650000000,200,61,1,2,243.400000000,243.690000000,29,200,1,1,243.190000000,244.000000000,2,1,1,1,243.020000000,244.140000000,79,79,1,1,243.000000000,244.200000000,1243,1000,9,1,242.990000000,244.400000000,1,50,1,1,242.750000000,244.420000000,30,10,1,1,242.590000000,244.580000000,5,100,1,1,242.280000000,245.000000000,100,79,1,2,AAPL
2025-01-03T10:31:09.338984362Z,2025-01-03T10:31:09.338818419Z,10,2,16244,C,A,2,383.600000000,500,130,165943,4867933,382.960000000,383.300000000,21,20,1,1,382.920000000,383.420000000,21,140,1,1,382.810000000,383.600000000,20,500,2,1,382.720000000,383.720000000,10,7085,1,8,382.700000000,383.740000000,50,37,1,1,382.680000000,383.800000000,20,10,1,1,382.500000000,383.880000000,3,4,1,1,382.400000000,384.000000000,500,1300,1,4,382.230000000,384.260000000,25,15,1,1,382.110000000,384.400000000,300,1000,1,2,TSLA
2025-01-03T10:31:09.353329827Z,2025-01-03T10:31:09.353163244Z,10,2,10888,A,B,0,420.700000000,200,130,166583,4867962,420.700000000,421.250000000,200,200,1,1,420.640000000,421.310000000,13,15,1,1,420.580000000,421.460000000,10,39,1,1,420.520000000,421.490000000,1,6,1,1,420.400000000,421.570000000,858,40,1,1,420.380000000,421.600000000,100,10,1,1,420.100000000,421.700000000,100,359,1,1,420.000000000,421.800000000,534,7,7,1,419.730000000,422.100000000,3,7,1,1,419.650000000,422.400000000,39,500,1,1,MSFT
2025-01-03T10:31:09.365337816Z,2025-01-03T10:31:09.365171484Z,10,2,10888,A,B,0,420.710000000,200,130,166332,4867996,420.710000000,421.250000000,200,200,1,1,420.640000000,421.310000000,13,15,1,1,420.580000000,421.460000000,10,39,1,1,420.520000000,421.490000000,1,6,1,1,420.400000000,421.570000000,858,40,1,1,420.380000000,421.600000000,100,10,1,1,420.100000000,421.700000000,100,359,1,1,420.000000000,421.800000000,534,7,7,1,419.730000000,422.100000000,3,7,1,1,419.650000000,422.400000000,39,500,1,1,MSFT
2025-01-03T10:31:09.381127553Z,2025-01-03T10:31:09.380961267Z,10,2,38,A,A,3,243.760000000,26,130,166286,4868027,243.500000000,243.640000000,6,54,1,1,243.440000000,243.650000000,200,61,1,2,243.400000000,243.690000000,29,200,1,1,243.190000000,243.760000000,2,26,1,1,243.020000000,244.000000000,79,1,1,1,243.000000000,244.140000000,1243,79,9,1,242.990000000,244.200000000,1,1000,1,1,242.750000000,244.400000000,30,50,1,1,242.590000000,244.420000000,5,10,1,1,242.280000000,244.580000000,100,100,1,1,AAPL
2025-01-03T10:31:09.468015639Z,2025-01-03T10:31:09.467849108Z,10,2,16244,A,B,0,383.090000000,3,130,166531,4868109,383.090000000,383.300000000,3,20,1,1,382.960000000,383.420000000,21,140,1,1,382.920000000,383.600000000,21,500,1,1,382.810000000,383.720000000,20,7085,2,8,382.720000000,383.740000000,10,37,1,1,382.700000000,383.800000000,50,10,1,1,382.680000000,383.880000000,20,4,1,1,382.500000000,384.000000000,3,1300,1,4,382.400000000,384.260000000,500,15,1,1,382.230000000,384.400000000,25,1000,1,2,TSLA
2025-01-03T10:31:09.530776578Z,2025-01-03T10:31:09.530610495Z,10,2,16244,C,B,1,382.960000000,21,130,166083,4868155,383.090000000,383.300000000,3,20,1,1,382.920000000,383.420000000,21,140,1,1,382.810000000,383.600000000,20,500,2,1,382.720000000,383.720000000,10,7085,1,8,382.700000000,383.740000000,50,37,1,1,382.680000000,383.800000000,20,10,1,1,382.500000000,383.880000000,3,4,1,1,382.400000000,384.000000000,500,1300,1,4,382.230000000,384.260000000,25,15,1,1,382.110000000,384.400000000,300,1000,1,2,TSLA
2025-01-03T10:31:09.530879924Z,2025-01-03T10:31:09.530713768Z,10,2,16244,A,B,0,383.100000000,20,130,166156,4868156,383.100000000,383.300000000,20,20,1,1,383.090000000,383.420000000,3,140,1,1,382.920000000,383.600000000,21,500,1,1,382.810000000,383.720000000,20,7085,2,8,382.720000000,383.740000000,10,37,1,1,382.700000000,383.800000000,50,10,1,1,382.680000000,383.880000000,20,4,1,1,382.500000000,384.000000000,3,1300,1,4,382.400000000,384.260000000,500,15,1,1,382.230000000,384.400000000,25,1000,1,2,TSLA
2025-01-03T10:31:09.952396184Z,2025-01-03T10:31:09.952230347Z,10,2,16244,C,B,2,382.920000000,21,130,165837,4868530,383.100000000,383.300000000,20,20,1,1,383.090000000,383.420000000,3,140,1,1,382.810000000,383.600000000,20,500,2,1,382.720000000,383.720000000,10,7085,1,8,382.700000000,383.740000000,50,37,1,1,382.680000000,383.800000000,20,10,1,1,382.500000000,383.880000000,3,4,1,1,382.400000000,384.000000000,500,1300,1,4,382.230000000,384.260000000,25,15,1,1,382.110000000,384.400000000,300,1000,1,2,TSLA
2025-01-03T10:31:09.952481492Z,2025-01-03T10:31:09.952315107Z,10,2,16244,A,B,2,383.060000000,23,130,166385,4868531,383.100000000,383.300000000,20,20,1,1,383.090000000,383.420000000,3,140,1,1,383.060000000,383.600000000,23,500,1,1,382.810000000,383.720000000,20,7085,2,8,382.720000000,383.740000000,10,37,1,1,382.700000000,383.800000000,50,10,1,1,382.680000000,383.880000000,20,4,1,1,382.500000000,384.000000000,3,1300,1,4,382.400000000,384.260000000,500,15,1,1,382.230000000,384.400000000,25,1000,1,2,TSLA
2025-01-03T10:31:10.198364195Z,2025-01-03T10:31:10.198197704Z,10,2,11667,A,A,1,139.180000000,400,130,166491,4868929,139.130000000,139.160000000,100,230,1,1,139.120000000,139.180000000,30,400,1,1,139.110000000,139.200000000,1,429,1,2,139.080000000,139.220000000,57,10,1,1,139.060000000,139.230000000,400,25,1,1,139.030000000,139.250000000,126,1,2,1,139.010000000,139.270000000,100,37,1,2,139.000000000,139.300000000,420,507,5,4,138.980000000,139.320000000,300,39,1,1,138.970000000,139.330000000,800,503,2,2,NVDA
2025-01-03T10:31:10.529556725Z,2025-01-03T10:31:10.529390390Z,10,2,38,A,B,1,243.440000000,200,130,166335,4869292,243.500000000,243.640000000,6,54,1,1,243.440000000,243.650000000,400,61,2,2,243.400000000,243.690000000,29,200,1,1,243.190000000,243.760000000,2,26,1,1,243.020000000,244.000000000,79,1,1,1,243.000000000,244.140000000,1243,79,9,1,242.990000000,244.200000000,1,1000,1,1,242.750000000,244.400000000,30,50,1,1,242.590000000,244.420000000,5,10,1,1,242.280000000,244.580000000,100,100,1,1,AAPL
2025-01-03T10:31:10.531741699Z,2025-01-03T10:31:10.531575411Z,10,2,38,C,A,2,243.690000000,200,130,166288,4869293,243.500000000,243.640000000,6,54,1,1,243.440000000,243.650000000,400,61,2,2,243.400000000,243.760000000,29,26,1,1,243.190000000,244.000000000,2,1,1,1,243.020000000,244.140000000,79,79,1,1,243.000000000,244.200000000,1243,1000,9,1,242.990000000,244.400000000,1,50,1,1,242.750000000,244.420000000,30,10,1,1,242.590000000,244.580000000,5,100,1,1,242.280000000,245.000000000,100,79,1,2,AAPL
2025-01-03T10:31:10.531755193Z,2025-01-03T10:31:10.531588091Z,10,2,38,A,A,2,243.710000000,200,130,167102,4869294,243.500000000,243.640000000,6,54,1,1,243.440000000,243.650000000,400,61,2,2,243.400000000,243.710000000,29,200,1,1,243.190000000,243.760000000,2,26,1,1,243.020000000,244.000000000,79,1,1,1,243.000000000,244.140000000,1243,79,9,1,242.990000000,244.200000000,1,1000,1,1,242.750000000,244.400000000,30,50,1,1,242.590000000,244.420000000,5,10,1,1,242.280000000,244.580000000,100,100,1,1,AAPL
2025-01-03T10:31:10.586717118Z,2025-01-03T10:31:10.586550988Z,10,2,38,C,B,1,243.440000000,200,130,166130,4869323,243.500000000,243.640000000,6,54,1,1,243.440000000,243.650000000,200,61,1,2,243.400000000,243.710000000,29,200,1,1,243.190000000,243.760000000,2,26,1,1,243.020000000,244.000000000,79,1,1,1,243.000000000,244.140000000,1243,79,9,1,242.990000000,244.200000000,1,1000,1,1,242.750000000,244.400000000,30,50,1,1,242.590000000,244.420000000,5,10,1,1,242.280000000,244.580000000,100,100,1,1,AAPL
2025-01-03T10:31:10.586730792Z,2025-01-03T10:31:10.586564218Z,10,2,38,A,B,1,243.470000000,200,130,166574,4869324,243.500000000,243.640000000,6,54,1,1,243.470000000,243.650000000,200,61,1,2,243.400000000,243.710000000,29,200,1,1,243.190000000,243.760000000,2,26,1,1,243.020000000,244.000000000,79,1,1,1,243.000000000,244.140000000,1243,79,9,1,242.990000000,244.200000000,1,1000,1,1,242.750000000,244.400000000,30,50,1,1,242.590000000,244.420000000,5,10,1,1,242.280000000,244.580000000,100,100,1,1,AAPL
2025-01-03T10:31:12.369793077Z,2025-01-03T10:31:12.369627100Z,10,2,9155,C,A,1,242.420000000,8,130,165977,4870452,241.670000000,242.070000000,2,62,1,1,241.550000000,242.850000000,8,300,1,2,241.120000000,242.900000000,81,100,1,1,241.000000000,243.000000000,100,92,1,2,240.000000000,243.310000000,10,10,1,1,238.000000000,243.700000000,30,100,1,1,236.000000000,246.810000000,6,100,1,1,235.500000000,262.740000000,5,100,1,1,235.000000000,263.830000000,5,100,1,1,232.880000000,,1,0,1,0,JPM
2025-01-03T10:31:12.369885853Z,2025-01-03T10:31:12.369719645Z,10,2,9155,A,A,1,242.370000000,8,130,166208,4870453,241.670000000,242.070000000,2,62,1,1,241.550000000,242.370000000,8,8,1,1,241.120000000,242.850000000,81,300,1,2,241.000000000,242.900000000,100,100,1,1,240.000000000,243.000000000,10,92,1,2,238.000000000,243.310000000,30,10,1,1,236.000000000,243.700000000,6,100,1,1,235.500000000,246.810000000,5,100,1,1,235.000000000,262.740000000,5,100,1,1,232.880000000,263.830000000,1,100,1,1,JPM
2025-01-03T10:31:12.449842207Z,2025-01-03T10:31:12.449675955Z,10,2,10888,A,B,0,420.720000000,200,130,166252,4870489,420.720000000,421.250000000,200,200,1,1,420.640000000,421.310000000,13,15,1,1,420.580000000,421.460000000,10,39,1,1,420.520000000,421.490000000,1,6,1,1,420.400000000,421.570000000,858,40,1,1,420.380000000,421.600000000,100,10,1,1,420.100000000,421.700000000,100,359,1,1,420.000000000,421.800000000,534,7,7,1,419.730000000,422.100000000,3,7,1,1,419.650000000,422.400000000,39,500,1,1,MSFT
2025-01-03T10:31:12.456710546Z,2025-01-03T10:31:12.456544217Z,10,2,16244,A,A,2,383.500000000,19,130,166329,4870502,383.100000000,383.300000000,20,20,1,1,383.090000000,383.420000000,3,140,1,1,383.060000000,383.500000000,23,19,1,1,382.810000000,383.600000000,20,500,2,1,382.720000000,383.720000000,10,7085,1,8,382.700000000,383.740000000,50,37,1,1,382.680000000,383.800000000,20,10,1,1,382.500000000,383.880000000,3,4,1,1,382.400000000,384.000000000,500,1300,1,4,382.230000000,384.260000000,25,15,1,1,TSLA
2025-01-03T10:31:12.462674572Z,2025-01-03T10:31:12.462508636Z,10,2,17709,C,A,2,107.890000000,16,130,165936,4870507,107.600000000,107.840000000,50,400,1,2,107.540000000,107.870000000,17,242,1,1,107.520000000,107.940000000,100,100,1,1,107.050000000,107.950000000,247,10,1,1,107.000000000,108.000000000,1,50,1,1,106.240000000,108.300000000,28,50,1,1,106.000000000,108.550000000,15,50,2,1,105.870000000,108.800000000,141,50,1,1,103.180000000,108.880000000,16,28,1,1,103.000000000,109.450000000,3,137,1,1,XOM
2025-01-03T10:31:12.462732894Z,2025-01-03T10:31:12.462566568Z,10,2,17709,A,A,1,107.850000000,15,130,166326,4870508,107.600000000,107.840000000,50,400,1,2,107.540000000,107.850000000,17,15,1,1,107.520000000,107.870000000,100,242,1,1,107.050000000,107.940000000,247,100,1,1,107.000000000,107.950000000,1,10,1,1,106.240000000,108.000000000,28,50,1,1,106.000000000,108.300000000,15,50,2,1,105.870000000,108.550000000,141,50,1,1,103.180000000,108.800000000,16,50,1,1,103.000000000,108.880000000,3,28,1,1,XOM
2025-01-03T10:31:12.463192335Z,2025-01-03T10:31:12.463025871Z,10,2,38,C,B,1,243.470000000,200,130,166464,4870509,243.500000000,243.640000000,6,54,1,1,243.400000000,243.650000000,29,61,1,2,243.190000000,243.710000000,2,200,1,1,243.020000000,243.760000000,79,26,1,1,243.000000000,244.000000000,1243,1,9,1,242.990000000,244.140000000,1,79,1,1,242.750000000,244.200000000,30,1000,1,1,242.590000000,244.400000000,5,50,1,1,242.280000000,244.420000000,100,10,1,1,242.170000000,244.580000000,100,100,1,1,AAPL
2025-01-03T10:31:12.463204827Z,2025-01-03T10:31:12.463038621Z,10,2,38,A,B,1,243.440000000,200,130,166206,4870510,243.500000000,243.640000000,6,54,1,1,243.440000000,243.650000000,200,61,1,2,243.400000000,243.710000000,29,200,1,1,243.190000000,243.760000000,2,26,1,1,243.020000000,244.000000000,79,1,1,1,243.000000000,244.140000000,1243,79,9,1,242.990000000,244.200000000,1,1000,1,1,242.750000000,244.400000000,30,50,1,1,242.590000000,244.420000000,5,10,1,1,242.280000000,244.580000000,100,100,1,1,AAPL
2025-01-03T10:31:12.520423029Z,2025-01-03T10:31:12.520256546Z,10,2,38,A,A,2,243.700000000,200,130,166483,4870600,243.500000000,243.640000000,6,54,1,1,243.440000000,243.650000000,200,61,1,2,243.400000000,243.700000000,29,200,1,1,243.190000000,243.760000000,2,26,1,1,243.020000000,244.000000000,79,1,1,1,243.000000000,244.140000000,1243,79,9,1,242.990000000,244.200000000,1,1000,1,1,242.750000000,244.400000000,30,50,1,1,242.590000000,244.420000000,5,10,1,1,242.280000000,244.580000000,100,100,1,1,AAPL
2025-01-03T10:31:12.527491925Z,2025-01-03T10:31:12.527325907Z,10,2,16244,A,A,3,383.600000000,500,130,166018,4870614,383.100000000,383.300000000,20,20,1,1,383.090000000,383.420000000,3,140,1,1,383.060000000,383.500000000,23,19,1,1,382.810000000,383.600000000,20,1000,2,2,382.720000000,383.720000000,10,7085,1,8,382.700000000,383.740000000,50,37,1,1,382.680000000,383.800000000,20,10,1,1,382.500000000,383.880000000,3,4,1,1,382.400000000,384.000000000,500,1300,1,4,382.230000000,384.260000000,25,15,1,1,TSLA
2025-01-03T10:31:12.538440884Z,2025-01-03T10:31:12.538275174Z,10,2,16244,C,A,3,383.600000000,500,130,165710,4870634,383.100000000,383.300000000,20,20,1,1,383.090000000,383.420000000,3,140,1,1,383.060000000,383.500000000,23,19,1,1,382.810000000,383.600000000,20,500,2,1,382.720000000,383.720000000,10,7085,1,8,382.700000000,383.740000000,50,37,1,1,382.680000000,383.800000000,20,10,1,1,382.500000000,383.880000000,3,4,1,1,382.400000000,384.000000000,500,1300,1,4,382.230000000,384.260000000,25,15,1,1,TSLA
2025-01-03T10:31:12.573773780Z,2025-01-03T10:31:12.573607450Z,10,2,16244,A,A,3,383.600000000,500,130,166330,4870650,383.100000000,383.300000000,20,20,1,1,383.090000000,383.420000000,3,140,1,1,383.060000000,383.500000000,23,19,1,1,382.810000000,383.600000000,20,1000,2,2,382.720000000,383.720000000,10,7085,1,8,382.700000000,383.740000000,50,37,1,1,382.680000000,383.800000000,20,10,1,1,382.500000000,383.880000000,3,4,1,1,382.400000000,384.000000000,500,1300,1,4,382.230000000,384.260000000,25,15,1,1,TSLA
2025-01-03T10:31:12.582180088Z,2025-01-03T10:31:12.582013950Z,10,2,16244,C,A,2,383.500000000,19,130,166138,4870653,383.100000000,383.300000000,20,20,1,1,383.090000000,383.420000000,3,140,1,1,383.060000000,383.600000000,23,1000,1,2,382.810000000,383.720000000,20,7085,2,8,382.720000000,383.740000000,10,37,1,1,382.700000000,383.800000000,50,10,1,1,382.680000000,383.880000000,20,4,1,1,382.500000000,384.000000000,3,1300,1,4,382.400000000,384.260000000,500,15,1,1,382.230000000,384.400000000,25,1000,1,2,TSLA
2025-01-03T10:31:13.642279683Z,2025-01-03T10:31:13.642113497Z,10,2,38,A,A,2,243.690000000,200,130,166186,4871329,243.500000000,243.640000000,6,54,1,1,243.440000000,243.650000000,200,61,1,2,243.400000000,243.690000000,29,200,1,1,243.190000000,243.760000000,2,26,1,1,243.020000000,244.000000000,79,1,1,1,243.000000000,244.140000000,1243,79,9,1,242.990000000,244.200000000,1,1000,1,1,242.750000000,244.400000000,30,50,1,1,242.590000000,244.420000000,5,10,1,1,242.280000000,244.580000000,100,100,1,1,AAPL
2025-01-03T10:31:15.465259273Z,2025-01-03T10:31:15.465093121Z,10,2,38,A,B,1,243.440000000,200,130,166152,4872331,243.500000000,243.640000000,6,54,1,1,243.440000000,243.650000000,400,61,2,2,243.400000000,243.690000000,29,200,1,1,243.190000000,243.760000000,2,26,1,1,243.020000000,244.000000000,79,1,1,1,243.000000000,244.140000000,1243,79,9,1,242.990000000,244.200000000,1,1000,1,1,242.750000000,244.400000000,30,50,1,1,242.590000000,244.420000000,5,10,1,1,242.280000000,244.580000000,100,100,1,1,AAPL
2025-01-03T10:31:15.468052770Z,2025-01-03T10:31:15.467886983Z,10,2,38,C,A,2,243.690000000,200,130,165787,4872334,243.500000000,243.640000000,6,54,1,1,243.440000000,243.650000000,400,61,2,2,243.400000000,243.760000000,29,26,1,1,243.190000000,244.000000000,2,1,1,1,243.020000000,244.140000000,79,79,1,1,243.000000000,244.200000000,1243,1000,9,1,242.990000000,244.400000000,1,50,1,1,242.750000000,244.420000000,30,10,1,1,242.590000000,244.580000000,5,100,1,1,242.280000000,245.000000000,100,79,1,2,AAPL
2025-01-03T10:31:15.468066004Z,2025-01-03T10:31:15.467899528Z,10,2,38,A,A,2,243.710000000,200,130,166476,4872335,243.500000000,243.640000000,6,54,1,1,243.440000000,243.650000000,400,61,2,2,243.400000000,243.710000000,29,200,1,1,243.190000000,243.760000000,2,26,1,1,243.020000000,244.000000000,79,1,1,1,243.000000000,244.140000000,1243,79,9,1,242.990000000,244.200000000,1,1000,1,1,242.750000000,244.400000000,30,50,1,1,242.590000000,244.420000000,5,10,1,1,242.280000000,244.580000000,100,100,1,1,AAPL
2025-01-03T10:31:15.522877420Z,2025-01-03T10:31:15.522711323Z,10,2,38,C,B,1,243.440000000,200,130,166097,4872348,243.500000000,243.640000000,6,54,1,1,243.440000000,243.650000000,200,61,1,2,243.400000000,243.710000000,29,200,1,1,243.190000000,243.760000000,2,26,1,1,243.020000000,244.000000000,79,1,1,1,243.000000000,244.140000000,1243,79,9,1,242.990000000,244.200000000,1,1000,1,1,242.750000000,244.400000000,30,50,1,1,242.590000000,244.420000000,5,10,1,1,242.280000000,244.580000000,100,100,1,1,AAPL
2025-01-03T10:31:15.522890996Z,2025-01-03T10:31:15.522724549Z,10,2,38,A,B,1,243.470000000,200,130,166447,4872349,243.500000000,243.640000000,6,54,1,1,243.470000000,243.650000000,200,61,1,2,243.400000000,243.710000000,29,200,1,1,243.190000000,243.760000000,2,26,1,1,243.020000000,244.000000000,79,1,1,1,243.000000000,244.140000000,1243,79,9,1,242.990000000,244.200000000,1,1000,1,1,242.750000000,244.400000000,30,50,1,1,242.590000000,244.420000000,5,10,1,1,242.280000000,244.580000000,100,100,1,1,AAPL
2025-01-03T10:31:16.370859698Z,2025-01-03T10:31:16.370693908Z,10,2,9155,C,A,1,242.370000000,8,130,165790,4872617,241.670000000,242.070000000,2,62,1,1,241.550000000,242.850000000,8,300,1,2,241.120000000,242.900000000,81,100,1,1,241.000000000,243.000000000,100,92,1,2,240.000000000,243.310000000,10,10,1,1,238.000000000,243.700000000,30,100,1,1,236.000000000,246.810000000,6,100,1,1,235.500000000,262.740000000,5,100,1,1,235.000000000,263.830000000,5,100,1,1,232.880000000,,1,0,1,0,JPM
2025-01-03T10:31:16.370890007Z,2025-01-03T10:31:16.370724212Z,10,2,9155,C,B,1,241.550000000,8,130,165795,4872618,241.670000000,242.070000000,2,62,1,1,241.120000000,242.850000000,81,300,1,2,241.000000000,242.900000000,100,100,1,1,240.000000000,243.000000000,10,92,1,2,238.000000000,243.310000000,30,10,1,1,236.000000000,243.700000000,6,100,1,1,235.500000000,246.810000000,5,100,1,1,235.000000000,262.740000000,5,100,1,1,232.880000000,263.830000000,1,100,1,1,231.110000000,,3,0,1,0,JPM
2025-01-03T10:31:16.370958336Z,2025-01-03T10:31:16.370792092Z,10,2,9155,A,B,1,241.500000000,8,130,166244,4872619,241.670000000,242.070000000,2,62,1,1,241.500000000,242.850000000,8,300,1,2,241.120000000,242.900000000,81,100,1,1,241.000000000,243.000000000,100,92,1,2,240.000000000,243.310000000,10,10,1,1,238.000000000,243.700000000,30,100,1,1,236.000000000,246.810000000,6,100,1,1,235.500000000,262.740000000,5,100,1,1,235.000000000,263.830000000,5,100,1,1,232.880000000,,1,0,1,0,JPM
2025-01-03T10:31:16.371005596Z,2025-01-03T10:31:16.370838847Z,10,2,9155,A,A,1,242.270000000,8,130,166749,4872620,241.670000000,242.070000000,2,62,1,1,241.500000000,242.270000000,8,8,1,1,241.120000000,242.850000000,81,300,1,2,241.000000000,242.900000000,100,100,1,1,240.000000000,243.000000000,10,92,1,2,238.000000000,243.310000000,30,10,1,1,236.000000000,243.700000000,6,100,1,1,235.500000000,246.810000000,5,100,1,1,235.000000000,262.740000000,5,100,1,1,232.880000000,263.830000000,1,100,1,1,JPM
2025-01-03T10:31:16.397295489Z,2025-01-03T10:31:16.397129321Z,10,2,17709,C,A,1,107.850000000,15,130,166168,4872646,107.600000000,107.840000000,50,400,1,2,107.540000000,107.870000000,17,242,1,1,107.520000000,107.940000000,100,100,1,1,107.050000000,107.950000000,247,10,1,1,107.000000000,108.000000000,1,50,1,1,106.240000000,108.300000000,28,50,1,1,106.000000000,108.550000000,15,50,2,1,105.870000000,108.800000000,141,50,1,1,103.180000000,108.880000000,16,28,1,1,103.000000000,109.450000000,3,137,1,1,XOM
2025-01-03T10:31:16.483437744Z,2025-01-03T10:31:16.483271693Z,10,2,38,C,B,1,243.470000000,200,130,166051,4872677,243.500000000,243.640000000,6,54,1,1,243.400000000,243.650000000,29,61,1,2,243.190000000,243.710000000,2,200,1,1,243.020000000,243.760000000,79,26,1,1,243.000000000,244.000000000,1243,1,9,1,242.990000000,244.140000000,1,79,1,1,242.750000000,244.200000000,30,1000,1,1,242.590000000,244.400000000,5,50,1,1,242.280000000,244.420000000,100,10,1,1,242.170000000,244.580000000,100,100,1,1,AAPL
