ts_recv,ts_event,rtype,publisher_id,instrument_id,action,side,depth,price,size,flags,ts_in_delta,sequence,bid_px_00,ask_px_00,bid_sz_00,ask_sz_00,bid_ct_00,ask_ct_00,bid_px_01,ask_px_01,bid_sz_01,ask_sz_01,bid_ct_01,ask_ct_01,bid_px_02,ask_px_02,bid_sz_02,ask_sz_02,bid_ct_02,ask_ct_02,bid_px_03,ask_px_03,bid_sz_03,ask_sz_03,bid_ct_03,ask_ct_03,bid_px_04,ask_px_04,bid_sz_04,ask_sz_04,bid_ct_04,ask_ct_04,bid_px_05,ask_px_05,bid_sz_05,ask_sz_05,bid_ct_05,ask_ct_05,bid_px_06,ask_px_06,bid_sz_06,ask_sz_06,bid_ct_06,ask_ct_06,bid_px_07,ask_px_07,bid_sz_07,ask_sz_07,bid_ct_07,ask_ct_07,bid_px_08,ask_px_08,bid_sz_08,ask_sz_08,bid_ct_08,ask_ct_08,bid_px_09,ask_px_09,bid_sz_09,ask_sz_09,bid_ct_09,ask_ct_09,symbol
2025-01-03T10:31:16.483450832Z,2025-01-03T10:31:16.483284533Z,10,2,38,A,B,1,243.440000000,200,130,166299,4872678,243.500000000,243.640000000,6,54,1,1,243.440000000,243.650000000,200,61,1,2,243.400000000,243.710000000,29,200,1,1,243.190000000,243.760000000,2,26,1,1,243.020000000,244.000000000,79,1,1,1,243.000000000,244.140000000,1243,79,9,1,242.990000000,244.200000000,1,1000,1,1,242.750000000,244.400000000,30,50,1,1,242.590000000,244.420000000,5,10,1,1,242.280000000,244.580000000,100,100,1,1,AAPL
2025-01-03T10:31:16.499011946Z,2025-01-03T10:31:16.498846104Z,10,2,17709,C,B,1,107.540000000,17,130,165842,4872690,107.600000000,107.840000000,50,400,1,2,107.520000000,107.870000000,100,242,1,1,107.050000000,107.940000000,247,100,1,1,107.000000000,107.950000000,1,10,1,1,106.240000000,108.000000000,28,50,1,1,106.000000000,108.300000000,15,50,2,1,105.870000000,108.550000000,141,50,1,1,103.180000000,108.800000000,16,50,1,1,103.000000000,108.880000000,3,28,1,1,102.000000000,109.450000000,2,137,1,1,XOM
2025-01-03T10:31:16.499101937Z,2025-01-03T10:31:16.498935734Z,10,2,17709,A,B,1,107.560000000,17,130,166203,4872691,107.600000000,107.840000000,50,400,1,2,107.560000000,107.870000000,17,242,1,1,107.520000000,107.940000000,100,100,1,1,107.050000000,107.950000000,247,10,1,1,107.000000000,108.000000000,1,50,1,1,106.240000000,108.300000000,28,50,1,1,106.000000000,108.550000000,15,50,2,1,105.870000000,108.800000000,141,50,1,1,103.180000000,108.880000000,16,28,1,1,103.000000000,109.450000000,3,137,1,1,XOM
2025-01-03T10:31:17.108035465Z,2025-01-03T10:31:17.107869267Z,10,2,17709,A,A,9,109.000000000,100,130,166198,4873046,107.600000000,107.840000000,50,400,1,2,107.560000000,107.870000000,17,242,1,1,107.520000000,107.940000000,100,100,1,1,107.050000000,107.950000000,247,10,1,1,107.000000000,108.000000000,1,50,1,1,106.240000000,108.300000000,28,50,1,1,106.000000000,108.550000000,15,50,2,1,105.870000000,108.800000000,141,50,1,1,103.180000000,108.880000000,16,28,1,1,103.000000000,109.000000000,3,100,1,1,XOM
2025-01-03T10:31:17.370539471Z,2025-01-03T10:31:17.370373487Z,10,2,9155,C,B,1,241.500000000,8,130,165984,4873305,241.670000000,242.070000000,2,62,1,1,241.120000000,242.270000000,81,8,1,1,241.000000000,242.850000000,100,300,1,2,240.000000000,242.900000000,10,100,1,1,238.000000000,243.000000000,30,92,1,2,236.000000000,243.310000000,6,10,1,1,235.500000000,243.700000000,5,100,1,1,235.000000000,246.810000000,5,100,1,1,232.880000000,262.740000000,1,100,1,1,231.110000000,263.830000000,3,100,1,1,JPM
2025-01-03T10:31:17.370569939Z,2025-01-03T10:31:17.370404022Z,10,2,9155,C,A,1,242.270000000,8,130,165917,4873306,241.670000000,242.070000000,2,62,1,1,241.120000000,242.850000000,81,300,1,2,241.000000000,242.900000000,100,100,1,1,240.000000000,243.000000000,10,92,1,2,238.000000000,243.310000000,30,10,1,1,236.000000000,243.700000000,6,100,1,1,235.500000000,246.810000000,5,100,1,1,235.000000000,262.740000000,5,100,1,1,232.880000000,263.830000000,1,100,1,1,231.110000000,,3,0,1,0,JPM
2025-01-03T10:31:17.370656119Z,2025-01-03T10:31:17.370489628Z,10,2,9155,A,B,1,241.550000000,8,130,166491,4873307,241.670000000,242.070000000,2,62,1,1,241.550000000,242.850000000,8,300,1,2,241.120000000,242.900000000,81,100,1,1,241.000000000,243.000000000,100,92,1,2,240.000000000,243.310000000,10,10,1,1,238.000000000,243.700000000,30,100,1,1,236.000000000,246.810000000,6,100,1,1,235.500000000,262.740000000,5,100,1,1,235.000000000,263.830000000,5,100,1,1,232.880000000,,1,0,1,0,JPM
2025-01-03T10:31:17.397764007Z,2025-01-03T10:31:17.397597874Z,10,2,17709,A,A,2,107.890000000,15,130,166133,4873318,107.600000000,107.840000000,50,400,1,2,107.560000000,107.870000000,17,242,1,1,107.520000000,107.890000000,100,15,1,1,107.050000000,107.940000000,247,100,1,1,107.000000000,107.950000000,1,10,1,1,106.240000000,108.000000000,28,50,1,1,106.000000000,108.300000000,15,50,2,1,105.870000000,108.550000000,141,50,1,1,103.180000000,108.800000000,16,50,1,1,103.000000000,108.880000000,3,28,1,1,XOM
2025-01-03T10:31:17.404115568Z,2025-01-03T10:31:17.403949732Z,10,2,17709,C,B,1,107.560000000,17,130,165836,4873319,107.600000000,107.840000000,50,400,1,2,107.520000000,107.870000000,100,242,1,1,107.050000000,107.890000000,247,15,1,1,107.000000000,107.940000000,1,100,1,1,106.240000000,107.950000000,28,10,1,1,106.000000000,108.000000000,15,50,2,1,105.870000000,108.300000000,141,50,1,1,103.180000000,108.550000000,16,50,1,1,103.000000000,108.800000000,3,50,1,1,102.000000000,108.880000000,2,28,1,1,XOM
2025-01-03T10:31:17.404212499Z,2025-01-03T10:31:17.404046333Z,10,2,17709,A,B,1,107.540000000,16,130,166166,4873320,107.600000000,107.840000000,50,400,1,2,107.540000000,107.870000000,16,242,1,1,107.520000000,107.890000000,100,15,1,1,107.050000000,107.940000000,247,100,1,1,107.000000000,107.950000000,1,10,1,1,106.240000000,108.000000000,28,50,1,1,106.000000000,108.300000000,15,50,2,1,105.870000000,108.550000000,141,50,1,1,103.180000000,108.800000000,16,50,1,1,103.000000000,108.880000000,3,28,1,1,XOM
2025-01-03T10:31:17.858288580Z,2025-01-03T10:31:17.858122115Z,10,2,10888,A,B,0,420.900000000,20,130,166465,4873514,420.900000000,421.250000000,20,200,1,1,420.720000000,421.310000000,200,15,1,1,420.640000000,421.460000000,13,39,1,1,420.580000000,421.490000000,10,6,1,1,420.520000000,421.570000000,1,40,1,1,420.400000000,421.600000000,858,10,1,1,420.380000000,421.700000000,100,359,1,1,420.100000000,421.800000000,100,7,1,1,420.000000000,422.100000000,534,7,7,1,419.730000000,422.400000000,3,500,1,1,MSFT
2025-01-03T10:31:17.877984029Z,2025-01-03T10:31:17.877818142Z,10,2,9155,C,B,1,241.550000000,8,130,165887,4873530,241.670000000,242.070000000,2,62,1,1,241.120000000,242.850000000,81,300,1,2,241.000000000,242.900000000,100,100,1,1,240.000000000,243.000000000,10,92,1,2,238.000000000,243.310000000,30,10,1,1,236.000000000,243.700000000,6,100,1,1,235.500000000,246.810000000,5,100,1,1,235.000000000,262.740000000,5,100,1,1,232.880000000,263.830000000,1,100,1,1,231.110000000,,3,0,1,0,JPM
2025-01-03T10:31:17.878065480Z,2025-01-03T10:31:17.877899117Z,10,2,9155,A,B,1,241.600000000,8,130,166363,4873531,241.670000000,242.070000000,2,62,1,1,241.600000000,242.850000000,8,300,1,2,241.120000000,242.900000000,81,100,1,1,241.000000000,243.000000000,100,92,1,2,240.000000000,243.310000000,10,10,1,1,238.000000000,243.700000000,30,100,1,1,236.000000000,246.810000000,6,100,1,1,235.500000000,262.740000000,5,100,1,1,235.000000000,263.830000000,5,100,1,1,232.880000000,,1,0,1,0,JPM
2025-01-03T10:31:17.952457363Z,2025-01-03T10:31:17.952291063Z,10,2,16244,A,A,2,383.540000000,19,130,166300,4873558,383.100000000,383.300000000,20,20,1,1,383.090000000,383.420000000,3,140,1,1,383.060000000,383.540000000,23,19,1,1,382.810000000,383.600000000,20,1000,2,2,382.720000000,383.720000000,10,7085,1,8,382.700000000,383.740000000,50,37,1,1,382.680000000,383.800000000,20,10,1,1,382.500000000,383.880000000,3,4,1,1,382.400000000,384.000000000,500,1300,1,4,382.230000000,384.260000000,25,15,1,1,TSLA
2025-01-03T10:31:18.370693107Z,2025-01-03T10:31:18.370527122Z,10,2,9155,C,B,1,241.600000000,8,130,165985,4873728,241.670000000,242.070000000,2,62,1,1,241.120000000,242.850000000,81,300,1,2,241.000000000,242.900000000,100,100,1,1,240.000000000,243.000000000,10,92,1,2,238.000000000,243.310000000,30,10,1,1,236.000000000,243.700000000,6,100,1,1,235.500000000,246.810000000,5,100,1,1,235.000000000,262.740000000,5,100,1,1,232.880000000,263.830000000,1,100,1,1,231.110000000,,3,0,1,0,JPM
2025-01-03T10:31:19.400121169Z,2025-01-03T10:31:19.399955029Z,10,2,17709,C,A,2,107.890000000,15,130,166140,4873959,107.600000000,107.840000000,50,400,1,2,107.540000000,107.870000000,16,242,1,1,107.520000000,107.940000000,100,100,1,1,107.050000000,107.950000000,247,10,1,1,107.000000000,108.000000000,1,50,1,1,106.240000000,108.300000000,28,50,1,1,106.000000000,108.550000000,15,50,2,1,105.870000000,108.800000000,141,50,1,1,103.180000000,108.880000000,16,28,1,1,103.000000000,109.000000000,3,100,1,1,XOM
2025-01-03T10:31:19.484087830Z,2025-01-03T10:31:19.483921461Z,10,2,38,A,B,1,243.440000000,200,130,166369,4874011,243.500000000,243.640000000,6,54,1,1,243.440000000,243.650000000,400,61,2,2,243.400000000,243.710000000,29,200,1,1,243.190000000,243.760000000,2,26,1,1,243.020000000,244.000000000,79,1,1,1,243.000000000,244.140000000,1243,79,9,1,242.990000000,244.200000000,1,1000,1,1,242.750000000,244.400000000,30,50,1,1,242.590000000,244.420000000,5,10,1,1,242.280000000,244.580000000,100,100,1,1,AAPL
2025-01-03T10:31:19.511646559Z,2025-01-03T10:31:19.511479868Z,10,2,38,A,A,2,243.690000000,200,130,166691,4874029,243.500000000,243.640000000,6,54,1,1,243.440000000,243.650000000,400,61,2,2,243.400000000,243.690000000,29,200,1,1,243.190000000,243.760000000,2,26,1,1,243.020000000,244.000000000,79,1,1,1,243.000000000,244.140000000,1243,79,9,1,242.990000000,244.200000000,1,1000,1,1,242.750000000,244.400000000,30,50,1,1,242.590000000,244.420000000,5,10,1,1,242.280000000,244.580000000,100,100,1,1,AAPL
2025-01-03T10:31:19.539668119Z,2025-01-03T10:31:19.539501890Z,10,2,38,C,B,1,243.440000000,200,130,166229,4874043,243.500000000,243.640000000,6,54,1,1,243.440000000,243.650000000,200,61,1,2,243.400000000,243.690000000,29,200,1,1,243.190000000,243.760000000,2,26,1,1,243.020000000,244.000000000,79,1,1,1,243.000000000,244.140000000,1243,79,9,1,242.990000000,244.200000000,1,1000,1,1,242.750000000,244.400000000,30,50,1,1,242.590000000,244.420000000,5,10,1,1,242.280000000,244.580000000,100,100,1,1,AAPL
2025-01-03T10:31:19.539681335Z,2025-01-03T10:31:19.539514635Z,10,2,38,A,B,1,243.470000000,200,130,166700,4874044,243.500000000,243.640000000,6,54,1,1,243.470000000,243.650000000,200,61,1,2,243.400000000,243.690000000,29,200,1,1,243.190000000,243.760000000,2,26,1,1,243.020000000,244.000000000,79,1,1,1,243.000000000,244.140000000,1243,79,9,1,242.990000000,244.200000000,1,1000,1,1,242.750000000,244.400000000,30,50,1,1,242.590000000,244.420000000,5,10,1,1,242.280000000,244.580000000,100,100,1,1,AAPL
2025-01-03T10:31:19.684624727Z,2025-01-03T10:31:19.684458825Z,10,2,38,C,B,1,243.470000000,200,130,165902,4874105,243.500000000,243.640000000,6,54,1,1,243.400000000,243.650000000,29,61,1,2,243.190000000,243.690000000,2,200,1,1,243.020000000,243.760000000,79,26,1,1,243.000000000,244.000000000,1243,1,9,1,242.990000000,244.140000000,1,79,1,1,242.750000000,244.200000000,30,1000,1,1,242.590000000,244.400000000,5,50,1,1,242.280000000,244.420000000,100,10,1,1,242.170000000,244.580000000,100,100,1,1,AAPL
2025-01-03T10:31:19.684638193Z,2025-01-03T10:31:19.684471811Z,10,2,38,A,B,1,243.440000000,200,130,166382,4874106,243.500000000,243.640000000,6,54,1,1,243.440000000,243.650000000,200,61,1,2,243.400000000,243.690000000,29,200,1,1,243.190000000,243.760000000,2,26,1,1,243.020000000,244.000000000,79,1,1,1,243.000000000,244.140000000,1243,79,9,1,242.990000000,244.200000000,1,1000,1,1,242.750000000,244.400000000,30,50,1,1,242.590000000,244.420000000,5,10,1,1,242.280000000,244.580000000,100,100,1,1,AAPL
2025-01-03T10:31:20.280097227Z,2025-01-03T10:31:20.279930936Z,10,2,38,A,A,2,243.690000000,200,130,166291,4874501,243.500000000,243.640000000,6,54,1,1,243.440000000,243.650000000,200,61,1,2,243.400000000,243.690000000,29,400,1,2,243.190000000,243.760000000,2,26,1,1,243.020000000,244.000000000,79,1,1,1,243.000000000,244.140000000,1243,79,9,1,242.990000000,244.200000000,1,1000,1,1,242.750000000,244.400000000,30,50,1,1,242.590000000,244.420000000,5,10,1,1,242.280000000,244.580000000,100,100,1,1,AAPL
2025-01-03T10:31:20.280719964Z,2025-01-03T10:31:20.280554024Z,10,2,38,C,A,3,243.760000000,26,130,165940,4874503,243.500000000,243.640000000,6,54,1,1,243.440000000,243.650000000,200,61,1,2,243.400000000,243.690000000,29,400,1,2,243.190000000,244.000000000,2,1,1,1,243.020000000,244.140000000,79,79,1,1,243.000000000,244.200000000,1243,1000,9,1,242.990000000,244.400000000,1,50,1,1,242.750000000,244.420000000,30,10,1,1,242.590000000,244.580000000,5,100,1,1,242.280000000,245.000000000,100,79,1,2,AAPL
2025-01-03T10:31:20.280782376Z,2025-01-03T10:31:20.280615571Z,10,2,38,A,A,3,243.710000000,29,130,166805,4874504,243.500000000,243.640000000,6,54,1,1,243.440000000,243.650000000,200,61,1,2,243.400000000,243.690000000,29,400,1,2,243.190000000,243.710000000,2,29,1,1,243.020000000,244.000000000,79,1,1,1,243.000000000,244.140000000,1243,79,9,1,242.990000000,244.200000000,1,1000,1,1,242.750000000,244.400000000,30,50,1,1,242.590000000,244.420000000,5,10,1,1,242.280000000,244.580000000,100,100,1,1,AAPL
2025-01-03T10:31:20.335057883Z,2025-01-03T10:31:20.334892031Z,10,2,38,C,A,2,243.690000000,200,130,165852,4874680,243.500000000,243.640000000,6,54,1,1,243.440000000,243.650000000,200,61,1,2,243.400000000,243.690000000,29,200,1,1,243.190000000,243.710000000,2,29,1,1,243.020000000,244.000000000,79,1,1,1,243.000000000,244.140000000,1243,79,9,1,242.990000000,244.200000000,1,1000,1,1,242.750000000,244.400000000,30,50,1,1,242.590000000,244.420000000,5,10,1,1,242.280000000,244.580000000,100,100,1,1,AAPL
2025-01-03T10:31:20.335071983Z,2025-01-03T10:31:20.334905359Z,10,2,38,A,A,2,243.660000000,200,130,166624,4874681,243.500000000,243.640000000,6,54,1,1,243.440000000,243.650000000,200,61,1,2,243.400000000,243.660000000,29,200,1,1,243.190000000,243.710000000,2,29,1,1,243.020000000,244.000000000,79,1,1,1,243.000000000,244.140000000,1243,79,9,1,242.990000000,244.200000000,1,1000,1,1,242.750000000,244.400000000,30,50,1,1,242.590000000,244.420000000,5,10,1,1,242.280000000,244.580000000,100,100,1,1,AAPL
2025-01-03T10:31:20.631938463Z,2025-01-03T10:31:20.631772283Z,10,2,780,C,B,0,259.420000000,25,130,166180,4875039,259.010000000,261.290000000,181,25,2,1,258.100000000,270.990000000,25,203,1,2,257.700000000,294.170000000,1,100,1,1,255.920000000,295.390000000,1,100,1,1,250.000000000,,13,0,2,0,236.860000000,,100,0,1,0,235.690000000,,100,0,1,0,,,0,0,0,0,,,0,0,0,0,,,0,0,0,0,AMGN
2025-01-03T10:31:20.631952413Z,2025-01-03T10:31:20.631785969Z,10,2,780,A,B,0,259.080000000,25,130,166444,4875041,259.080000000,261.290000000,25,25,1,1,259.010000000,270.990000000,181,203,2,2,258.100000000,294.170000000,25,100,1,1,257.700000000,295.390000000,1,100,1,1,255.920000000,,1,0,1,0,250.000000000,,13,0,2,0,236.860000000,,100,0,1,0,235.690000000,,100,0,1,0,,,0,0,0,0,,,0,0,0,0,AMGN
2025-01-03T10:31:20.690283225Z,2025-01-03T10:31:20.690116609Z,10,2,780,A,B,0,259.250000000,25,130,166616,4875101,259.250000000,261.290000000,25,25,1,1,259.010000000,270.990000000,181,203,2,2,258.100000000,294.170000000,25,100,1,1,257.700000000,295.390000000,1,100,1,1,255.920000000,,1,0,1,0,250.000000000,,13,0,2,0,236.860000000,,100,0,1,0,235.690000000,,100,0,1,0,,,0,0,0,0,,,0,0,0,0,AMGN
2025-01-03T10:31:20.713283618Z,2025-01-03T10:31:20.713117417Z,10,2,780,A,B,0,259.590000000,25,130,166201,4875125,259.590000000,261.290000000,25,25,1,1,259.010000000,270.990000000,181,203,2,2,258.100000000,294.170000000,25,100,1,1,257.700000000,295.390000000,1,100,1,1,255.920000000,,1,0,1,0,250.000000000,,13,0,2,0,236.860000000,,100,0,1,0,235.690000000,,100,0,1,0,,,0,0,0,0,,,0,0,0,0,AMGN
2025-01-03T10:31:20.723746325Z,2025-01-03T10:31:20.723580056Z,10,2,16244,C,A,0,383.300000000,20,130,166269,4875148,383.100000000,383.420000000,20,140,1,1,383.090000000,383.540000000,3,19,1,1,383.060000000,383.600000000,23,1000,1,2,382.810000000,383.720000000,20,7085,2,8,382.720000000,383.740000000,10,37,1,1,382.700000000,383.800000000,50,10,1,1,382.680000000,383.880000000,20,4,1,1,382.500000000,384.000000000,3,1300,1,4,382.400000000,384.260000000,500,15,1,1,382.230000000,384.400000000,25,1000,1,2,TSLA
2025-01-03T10:31:20.725217010Z,2025-01-03T10:31:20.725050800Z,10,2,16244,A,A,1,383.500000000,20,130,166210,4875151,383.100000000,383.420000000,20,140,1,1,383.090000000,383.500000000,3,20,1,1,383.060000000,383.540000000,23,19,1,1,382.810000000,383.600000000,20,1000,2,2,382.720000000,383.720000000,10,7085,1,8,382.700000000,383.740000000,50,37,1,1,382.680000000,383.800000000,20,10,1,1,382.500000000,383.880000000,3,4,1,1,382.400000000,384.000000000,500,1300,1,4,382.230000000,384.260000000,25,15,1,1,TSLA
2025-01-03T10:31:20.984264309Z,2025-01-03T10:31:20.984098279Z,10,2,780,C,B,0,259.590000000,25,130,166030,4875339,259.010000000,261.290000000,181,25,2,1,258.100000000,270.990000000,25,203,1,2,257.700000000,294.170000000,1,100,1,1,255.920000000,295.390000000,1,100,1,1,250.000000000,,13,0,2,0,236.860000000,,100,0,1,0,235.690000000,,100,0,1,0,,,0,0,0,0,,,0,0,0,0,,,0,0,0,0,AMGN
2025-01-03T10:31:20.984278685Z,2025-01-03T10:31:20.984111634Z,10,2,780,A,B,0,259.250000000,25,130,167051,4875340,259.250000000,261.290000000,25,25,1,1,259.010000000,270.990000000,181,203,2,2,258.100000000,294.170000000,25,100,1,1,257.700000000,295.390000000,1,100,1,1,255.920000000,,1,0,1,0,250.000000000,,13,0,2,0,236.860000000,,100,0,1,0,235.690000000,,100,0,1,0,,,0,0,0,0,,,0,0,0,0,AMGN
2025-01-03T10:31:21.050349257Z,2025-01-03T10:31:21.050181950Z,10,2,780,A,B,0,259.420000000,25,130,167307,4875357,259.420000000,261.290000000,25,25,1,1,259.010000000,270.990000000,181,203,2,2,258.100000000,294.170000000,25,100,1,1,257.700000000,295.390000000,1,100,1,1,255.920000000,,1,0,1,0,250.000000000,,13,0,2,0,236.860000000,,100,0,1,0,235.690000000,,100,0,1,0,,,0,0,0,0,,,0,0,0,0,AMGN
2025-01-03T10:31:21.174619912Z,2025-01-03T10:31:21.174453710Z,10,2,10888,C,B,0,420.900000000,20,130,166202,4875419,420.720000000,421.250000000,200,200,1,1,420.640000000,421.310000000,13,15,1,1,420.580000000,421.460000000,10,39,1,1,420.520000000,421.490000000,1,6,1,1,420.400000000,421.570000000,858,40,1,1,420.380000000,421.600000000,100,10,1,1,420.100000000,421.700000000,100,359,1,1,420.000000000,421.800000000,534,7,7,1,419.730000000,422.100000000,3,7,1,1,419.650000000,422.400000000,39,500,1,1,MSFT
2025-01-03T10:31:21.175630652Z,2025-01-03T10:31:21.175464421Z,10,2,10888,A,B,0,420.960000000,20,130,166231,4875422,420.960000000,421.250000000,20,200,1,1,420.720000000,421.310000000,200,15,1,1,420.640000000,421.460000000,13,39,1,1,420.580000000,421.490000000,10,6,1,1,420.520000000,421.570000000,1,40,1,1,420.400000000,421.600000000,858,10,1,1,420.380000000,421.700000000,100,359,1,1,420.100000000,421.800000000,100,7,1,1,420.000000000,422.100000000,534,7,7,1,419.730000000,422.400000000,3,500,1,1,MSFT
2025-01-03T10:31:21.237783262Z,2025-01-03T10:31:21.237616718Z,10,2,780,A,B,0,259.590000000,25,130,166544,4875560,259.590000000,261.290000000,25,25,1,1,259.010000000,270.990000000,181,203,2,2,258.100000000,294.170000000,25,100,1,1,257.700000000,295.390000000,1,100,1,1,255.920000000,,1,0,1,0,250.000000000,,13,0,2,0,236.860000000,,100,0,1,0,235.690000000,,100,0,1,0,,,0,0,0,0,,,0,0,0,0,AMGN
2025-01-03T10:31:21.372967360Z,2025-01-03T10:31:21.372801054Z,10,2,9155,A,A,1,242.420000000,8,130,166306,4875632,241.670000000,242.070000000,2,62,1,1,241.120000000,242.420000000,81,8,1,1,241.000000000,242.850000000,100,300,1,2,240.000000000,242.900000000,10,100,1,1,238.000000000,243.000000000,30,92,1,2,236.000000000,243.310000000,6,10,1,1,235.500000000,243.700000000,5,100,1,1,235.000000000,246.810000000,5,100,1,1,232.880000000,262.740000000,1,100,1,1,231.110000000,263.830000000,3,100,1,1,JPM
2025-01-03T10:31:21.484981540Z,2025-01-03T10:31:21.484815284Z,10,2,780,C,A,0,261.290000000,25,130,166256,4875701,259.590000000,270.990000000,25,203,1,2,259.010000000,294.170000000,181,100,2,1,258.100000000,295.390000000,25,100,1,1,257.700000000,,1,0,1,0,255.920000000,,1,0,1,0,250.000000000,,13,0,2,0,236.860000000,,100,0,1,0,235.690000000,,100,0,1,0,,,0,0,0,0,,,0,0,0,0,AMGN
2025-01-03T10:31:21.484995025Z,2025-01-03T10:31:21.484828657Z,10,2,780,A,A,0,261.460000000,25,130,166368,4875702,259.590000000,261.460000000,25,25,1,1,259.010000000,270.990000000,181,203,2,2,258.100000000,294.170000000,25,100,1,1,257.700000000,295.390000000,1,100,1,1,255.920000000,,1,0,1,0,250.000000000,,13,0,2,0,236.860000000,,100,0,1,0,235.690000000,,100,0,1,0,,,0,0,0,0,,,0,0,0,0,AMGN
2025-01-03T10:31:21.583373391Z,2025-01-03T10:31:21.583207421Z,10,2,38,C,A,2,243.660000000,200,130,165970,4875778,243.500000000,243.640000000,6,54,1,1,243.440000000,243.650000000,200,61,1,2,243.400000000,243.710000000,29,29,1,1,243.190000000,244.000000000,2,1,1,1,243.020000000,244.140000000,79,79,1,1,243.000000000,244.200000000,1243,1000,9,1,242.990000000,244.400000000,1,50,1,1,242.750000000,244.420000000,30,10,1,1,242.590000000,244.580000000,5,100,1,1,242.280000000,245.000000000,100,79,1,2,AAPL
2025-01-03T10:31:21.583385632Z,2025-01-03T10:31:21.583219283Z,10,2,38,A,A,2,243.690000000,200,130,166349,4875779,243.500000000,243.640000000,6,54,1,1,243.440000000,243.650000000,200,61,1,2,243.400000000,243.690000000,29,200,1,1,243.190000000,243.710000000,2,29,1,1,243.020000000,244.000000000,79,1,1,1,243.000000000,244.140000000,1243,79,9,1,242.990000000,244.200000000,1,1000,1,1,242.750000000,244.400000000,30,50,1,1,242.590000000,244.420000000,5,10,1,1,242.280000000,244.580000000,100,100,1,1,AAPL
2025-01-03T10:31:21.583921252Z,2025-01-03T10:31:21.583755321Z,10,2,38,C,A,3,243.710000000,29,130,165931,4875780,243.500000000,243.640000000,6,54,1,1,243.440000000,243.650000000,200,61,1,2,243.400000000,243.690000000,29,200,1,1,243.190000000,244.000000000,2,1,1,1,243.020000000,244.140000000,79,79,1,1,243.000000000,244.200000000,1243,1000,9,1,242.990000000,244.400000000,1,50,1,1,242.750000000,244.420000000,30,10,1,1,242.590000000,244.580000000,5,100,1,1,242.280000000,245.000000000,100,79,1,2,AAPL
2025-01-03T10:31:21.584030863Z,2025-01-03T10:31:21.583864662Z,10,2,38,A,A,3,243.760000000,26,130,166201,4875781,243.500000000,243.640000000,6,54,1,1,243.440000000,243.650000000,200,61,1,2,243.400000000,243.690000000,29,200,1,1,243.190000000,243.760000000,2,26,1,1,243.020000000,244.000000000,79,1,1,1,243.000000000,244.140000000,1243,79,9,1,242.990000000,244.200000000,1,1000,1,1,242.750000000,244.400000000,30,50,1,1,242.590000000,244.420000000,5,10,1,1,242.280000000,244.580000000,100,100,1,1,AAPL
2025-01-03T10:31:21.731572971Z,2025-01-03T10:31:21.731406414Z,10,2,780,A,A,0,261.290000000,25,130,166557,4875858,259.590000000,261.290000000,25,25,1,1,259.010000000,270.990000000,181,203,2,2,258.100000000,294.170000000,25,100,1,1,257.700000000,295.390000000,1,100,1,1,255.920000000,,1,0,1,0,250.000000000,,13,0,2,0,236.860000000,,100,0,1,0,235.690000000,,100,0,1,0,,,0,0,0,0,,,0,0,0,0,AMGN
2025-01-03T10:31:21.741291216Z,2025-01-03T10:31:21.741125068Z,10,2,11667,A,B,4,139.070000000,100,130,166148,4875859,139.130000000,139.160000000,100,230,1,1,139.120000000,139.180000000,30,400,1,1,139.110000000,139.200000000,1,429,1,2,139.080000000,139.220000000,57,10,1,1,139.070000000,139.230000000,100,25,1,1,139.060000000,139.250000000,400,1,1,1,139.030000000,139.270000000,126,37,2,2,139.010000000,139.300000000,100,507,1,4,139.000000000,139.320000000,420,39,5,1,138.980000000,139.330000000,300,503,1,2,NVDA
2025-01-03T10:31:21.817952141Z,2025-01-03T10:31:21.817785480Z,10,2,17709,A,A,2,107.910000000,15,130,166661,4875948,107.600000000,107.840000000,50,400,1,2,107.540000000,107.870000000,16,242,1,1,107.520000000,107.910000000,100,15,1,1,107.050000000,107.940000000,247,100,1,1,107.000000000,107.950000000,1,10,1,1,106.240000000,108.000000000,28,50,1,1,106.000000000,108.300000000,15,50,2,1,105.870000000,108.550000000,141,50,1,1,103.180000000,108.800000000,16,50,1,1,103.000000000,108.880000000,3,28,1,1,XOM
2025-01-03T10:31:21.818598597Z,2025-01-03T10:31:21.818432403Z,10,2,11667,A,B,0,139.130000000,2100,130,166194,4875949,139.130000000,139.160000000,2200,230,2,1,139.120000000,139.180000000,30,400,1,1,139.110000000,139.200000000,1,429,1,2,139.080000000,139.220000000,57,10,1,1,139.070000000,139.230000000,100,25,1,1,139.060000000,139.250000000,400,1,1,1,139.030000000,139.270000000,126,37,2,2,139.010000000,139.300000000,100,507,1,4,139.000000000,139.320000000,420,39,5,1,138.980000000,139.330000000,300,503,1,2,NVDA
2025-01-03T10:31:21.818640189Z,2025-01-03T10:31:21.818470599Z,10,2,11667,T,B,0,139.160000000,13,0,169590,4875950,139.130000000,139.160000000,2200,230,2,1,139.120000000,139.180000000,30,400,1,1,139.110000000,139.200000000,1,429,1,2,139.080000000,139.220000000,57,10,1,1,139.070000000,139.230000000,100,25,1,1,139.060000000,139.250000000,400,1,1,1,139.030000000,139.270000000,126,37,2,2,139.010000000,139.300000000,100,507,1,4,139.000000000,139.320000000,420,39,5,1,138.980000000,139.330000000,300,503,1,2,NVDA
2025-01-03T10:31:21.818640189Z,2025-01-03T10:31:21.818470994Z,10,2,11667,T,B,0,139.160000000,36,130,169195,4875951,139.130000000,139.160000000,2200,217,2,1,139.120000000,139.180000000,30,400,1,1,139.110000000,139.200000000,1,429,1,2,139.080000000,139.220000000,57,10,1,1,139.070000000,139.230000000,100,25,1,1,139.060000000,139.250000000,400,1,1,1,139.030000000,139.270000000,126,37,2,2,139.010000000,139.300000000,100,507,1,4,139.000000000,139.320000000,420,39,5,1,138.980000000,139.330000000,300,503,1,2,NVDA
2025-01-03T10:31:21.818640189Z,2025-01-03T10:31:21.818470994Z,10,2,11667,C,A,0,139.160000000,36,130,169195,4875951,139.130000000,139.160000000,2200,181,2,1,139.120000000,139.180000000,30,400,1,1,139.110000000,139.200000000,1,429,1,2,139.080000000,139.220000000,57,10,1,1,139.070000000,139.230000000,100,25,1,1,139.060000000,139.250000000,400,1,1,1,139.030000000,139.270000000,126,37,2,2,139.010000000,139.300000000,100,507,1,4,139.000000000,139.320000000,420,39,5,1,138.980000000,139.330000000,300,503,1,2,NVDA
2025-01-03T10:31:21.818642305Z,2025-01-03T10:31:21.818473669Z,10,2,11667,T,B,0,139.160000000,74,130,168636,4875952,139.130000000,139.160000000,2200,181,2,1,139.120000000,139.180000000,30,400,1,1,139.110000000,139.200000000,1,429,1,2,139.080000000,139.220000000,57,10,1,1,139.070000000,139.230000000,100,25,1,1,139.060000000,139.250000000,400,1,1,1,139.030000000,139.270000000,126,37,2,2,139.010000000,139.300000000,100,507,1,4,139.000000000,139.320000000,420,39,5,1,138.980000000,139.330000000,300,503,1,2,NVDA
2025-01-03T10:31:21.818642305Z,2025-01-03T10:31:21.818473669Z,10,2,11667,C,A,0,139.160000000,74,130,168636,4875952,139.130000000,139.160000000,2200,107,2,1,139.120000000,139.180000000,30,400,1,1,139.110000000,139.200000000,1,429,1,2,139.080000000,139.220000000,57,10,1,1,139.070000000,139.230000000,100,25,1,1,139.060000000,139.250000000,400,1,1,1,139.030000000,139.270000000,126,37,2,2,139.010000000,139.300000000,100,507,1,4,139.000000000,139.320000000,420,39,5,1,138.980000000,139.330000000,300,503,1,2,NVDA
2025-01-03T10:31:21.818672319Z,2025-01-03T10:31:21.818505045Z,10,2,11667,T,B,0,139.160000000,100,130,167274,4875953,139.130000000,139.160000000,2200,107,2,1,139.120000000,139.180000000,30,400,1,1,139.110000000,139.200000000,1,429,1,2,139.080000000,139.220000000,57,10,1,1,139.070000000,139.230000000,100,25,1,1,139.060000000,139.250000000,400,1,1,1,139.030000000,139.270000000,126,37,2,2,139.010000000,139.300000000,100,507,1,4,139.000000000,139.320000000,420,39,5,1,138.980000000,139.330000000,300,503,1,2,NVDA
2025-01-03T10:31:21.818672319Z,2025-01-03T10:31:21.818505045Z,10,2,11667,C,A,0,139.160000000,100,130,167274,4875953,139.130000000,139.160000000,2200,7,2,1,139.120000000,139.180000000,30,400,1,1,139.110000000,139.200000000,1,429,1,2,139.080000000,139.220000000,57,10,1,1,139.070000000,139.230000000,100,25,1,1,139.060000000,139.250000000,400,1,1,1,139.030000000,139.270000000,126,37,2,2,139.010000000,139.300000000,100,507,1,4,139.000000000,139.320000000,420,39,5,1,138.980000000,139.330000000,300,503,1,2,NVDA
2025-01-03T10:31:21.818729298Z,2025-01-03T10:31:21.818563171Z,10,2,11667,C,A,1,139.180000000,400,130,166127,4875959,139.130000000,139.160000000,2200,7,2,1,139.120000000,139.200000000,30,429,1,2,139.110000000,139.220000000,1,10,1,1,139.080000000,139.230000000,57,25,1,1,139.070000000,139.250000000,100,1,1,1,139.060000000,139.270000000,400,37,1,2,139.030000000,139.300000000,126,507,2,4,139.010000000,139.320000000,100,39,1,1,139.000000000,139.330000000,420,503,5,2,138.980000000,139.360000000,300,14,1,3,NVDA
2025-01-03T10:31:21.818748198Z,2025-01-03T10:31:21.818580630Z,10,2,11667,T,B,0,139.160000000,7,130,167568,4875961,139.130000000,139.160000000,2200,7,2,1,139.120000000,139.200000000,30,429,1,2,139.110000000,139.220000000,1,10,1,1,139.080000000,139.230000000,57,25,1,1,139.070000000,139.250000000,100,1,1,1,139.060000000,139.270000000,400,37,1,2,139.030000000,139.300000000,126,507,2,4,139.010000000,139.320000000,100,39,1,1,139.000000000,139.330000000,420,503,5,2,138.980000000,139.360000000,300,14,1,3,NVDA
2025-01-03T10:31:21.818748198Z,2025-01-03T10:31:21.818580630Z,10,2,11667,C,A,0,139.160000000,7,130,167568,4875961,139.130000000,139.200000000,2200,429,2,2,139.120000000,139.220000000,30,10,1,1,139.110000000,139.230000000,1,25,1,1,139.080000000,139.250000000,57,1,1,1,139.070000000,139.270000000,100,37,1,2,139.060000000,139.300000000,400,507,1,4,139.030000000,139.320000000,126,39,2,1,139.010000000,139.330000000,100,503,1,2,139.000000000,139.360000000,420,14,5,3,138.980000000,139.370000000,300,75,1,1,NVDA
2025-01-03T10:31:21.819459179Z,2025-01-03T10:31:21.819293262Z,10,2,11667,C,A,0,139.200000000,300,130,165917,4875972,139.130000000,139.200000000,2200,129,2,1,139.120000000,139.220000000,30,10,1,1,139.110000000,139.230000000,1,25,1,1,139.080000000,139.250000000,57,1,1,1,139.070000000,139.270000000,100,37,1,2,139.060000000,139.300000000,400,507,1,4,139.030000000,139.320000000,126,39,2,1,139.010000000,139.330000000,100,503,1,2,139.000000000,139.360000000,420,14,5,3,138.980000000,139.370000000,300,75,1,1,NVDA
2025-01-03T10:31:21.819470775Z,2025-01-03T10:31:21.819304782Z,10,2,11667,A,A,1,139.220000000,100,130,165993,4875974,139.130000000,139.200000000,2200,129,2,1,139.120000000,139.220000000,30,110,1,2,139.110000000,139.230000000,1,25,1,1,139.080000000,139.250000000,57,1,1,1,139.070000000,139.270000000,100,37,1,2,139.060000000,139.300000000,400,507,1,4,139.030000000,139.320000000,126,39,2,1,139.010000000,139.330000000,100,503,1,2,139.000000000,139.360000000,420,14,5,3,138.980000000,139.370000000,300,75,1,1,NVDA
2025-01-03T10:31:21.869706317Z,2025-01-03T10:31:21.869539838Z,10,2,780,A,A,0,261.120000000,25,130,166479,4876075,259.590000000,261.120000000,25,25,1,1,259.010000000,270.990000000,181,203,2,2,258.100000000,294.170000000,25,100,1,1,257.700000000,295.390000000,1,100,1,1,255.920000000,,1,0,1,0,250.000000000,,13,0,2,0,236.860000000,,100,0,1,0,235.690000000,,100,0,1,0,,,0,0,0,0,,,0,0,0,0,AMGN
2025-01-03T10:31:21.877978690Z,2025-01-03T10:31:21.877812330Z,10,2,9155,A,B,1,241.600000000,8,130,166360,4876076,241.670000000,242.070000000,2,62,1,1,241.600000000,242.420000000,8,8,1,1,241.120000000,242.850000000,81,300,1,2,241.000000000,242.900000000,100,100,1,1,240.000000000,243.000000000,10,92,1,2,238.000000000,243.310000000,30,10,1,1,236.000000000,243.700000000,6,100,1,1,235.500000000,246.810000000,5,100,1,1,235.000000000,262.740000000,5,100,1,1,232.880000000,263.830000000,1,100,1,1,JPM
2025-01-03T10:31:21.926911175Z,2025-01-03T10:31:21.926744388Z,10,2,11667,A,A,1,139.220000000,400,130,166787,4876120,139.130000000,139.200000000,2200,129,2,1,139.120000000,139.220000000,30,510,1,3,139.110000000,139.230000000,1,25,1,1,139.080000000,139.250000000,57,1,1,1,139.070000000,139.270000000,100,37,1,2,139.060000000,139.300000000,400,507,1,4,139.030000000,139.320000000,126,39,2,1,139.010000000,139.330000000,100,503,1,2,139.000000000,139.360000000,420,14,5,3,138.980000000,139.370000000,300,75,1,1,NVDA
2025-01-03T10:31:21.936367340Z,2025-01-03T10:31:21.936200689Z,10,2,11667,A,B,3,139.090000000,400,130,166651,4876142,139.130000000,139.200000000,2200,129,2,1,139.120000000,139.220000000,30,510,1,3,139.110000000,139.230000000,1,25,1,1,139.090000000,139.250000000,400,1,1,1,139.080000000,139.270000000,57,37,1,2,139.070000000,139.300000000,100,507,1,4,139.030000000,139.320000000,126,39,2,1,139.010000000,139.330000000,100,503,1,2,139.000000000,139.360000000,420,14,5,3,138.980000000,139.370000000,300,75,1,1,NVDA
2025-01-03T10:31:22.373779157Z,2025-01-03T10:31:22.373612901Z,10,2,9155,C,B,1,241.600000000,8,130,166256,4876357,241.670000000,242.070000000,2,62,1,1,241.120000000,242.420000000,81,8,1,1,241.000000000,242.850000000,100,300,1,2,240.000000000,242.900000000,10,100,1,1,238.000000000,243.000000000,30,92,1,2,236.000000000,243.310000000,6,10,1,1,235.500000000,243.700000000,5,100,1,1,235.000000000,246.810000000,5,100,1,1,232.880000000,262.740000000,1,100,1,1,231.110000000,263.830000000,3,100,1,1,JPM
2025-01-03T10:31:22.485276578Z,2025-01-03T10:31:22.485110576Z,10,2,780,C,A,0,261.120000000,25,130,166002,4876412,259.590000000,270.990000000,25,203,1,2,259.010000000,294.170000000,181,100,2,1,258.100000000,295.390000000,25,100,1,1,257.700000000,,1,0,1,0,255.920000000,,1,0,1,0,250.000000000,,13,0,2,0,236.860000000,,100,0,1,0,235.690000000,,100,0,1,0,,,0,0,0,0,,,0,0,0,0,AMGN
2025-01-03T10:31:22.485290305Z,2025-01-03T10:31:22.485123459Z,10,2,780,A,A,0,261.460000000,25,130,166846,4876413,259.590000000,261.460000000,25,25,1,1,259.010000000,270.990000000,181,203,2,2,258.100000000,294.170000000,25,100,1,1,257.700000000,295.390000000,1,100,1,1,255.920000000,,1,0,1,0,250.000000000,,13,0,2,0,236.860000000,,100,0,1,0,235.690000000,,100,0,1,0,,,0,0,0,0,,,0,0,0,0,AMGN
2025-01-03T10:31:22.684972243Z,2025-01-03T10:31:22.684805925Z,10,2,38,A,B,1,243.440000000,200,130,166318,4876489,243.500000000,243.640000000,6,54,1,1,243.440000000,243.650000000,400,61,2,2,243.400000000,243.690000000,29,200,1,1,243.190000000,243.760000000,2,26,1,1,243.020000000,244.000000000,79,1,1,1,243.000000000,244.140000000,1243,79,9,1,242.990000000,244.200000000,1,1000,1,1,242.750000000,244.400000000,30,50,1,1,242.590000000,244.420000000,5,10,1,1,242.280000000,244.580000000,100,100,1,1,AAPL
2025-01-03T10:31:22.689650352Z,2025-01-03T10:31:22.689484511Z,10,2,38,C,A,2,243.690000000,200,130,165841,4876490,243.500000000,243.640000000,6,54,1,1,243.440000000,243.650000000,400,61,2,2,243.400000000,243.760000000,29,26,1,1,243.190000000,244.000000000,2,1,1,1,243.020000000,244.140000000,79,79,1,1,243.000000000,244.200000000,1243,1000,9,1,242.990000000,244.400000000,1,50,1,1,242.750000000,244.420000000,30,10,1,1,242.590000000,244.580000000,5,100,1,1,242.280000000,245.000000000,100,79,1,2,AAPL
2025-01-03T10:31:22.689663943Z,2025-01-03T10:31:22.689497593Z,10,2,38,A,A,2,243.710000000,200,130,166350,4876491,243.500000000,243.640000000,6,54,1,1,243.440000000,243.650000000,400,61,2,2,243.400000000,243.710000000,29,200,1,1,243.190000000,243.760000000,2,26,1,1,243.020000000,244.000000000,79,1,1,1,243.000000000,244.140000000,1243,79,9,1,242.990000000,244.200000000,1,1000,1,1,242.750000000,244.400000000,30,50,1,1,242.590000000,244.420000000,5,10,1,1,242.280000000,244.580000000,100,100,1,1,AAPL
2025-01-03T10:31:22.732999106Z,2025-01-03T10:31:22.732832458Z,10,2,780,A,A,0,261.290000000,25,130,166648,4876498,259.590000000,261.290000000,25,25,1,1,259.010000000,270.990000000,181,203,2,2,258.100000000,294.170000000,25,100,1,1,257.700000000,295.390000000,1,100,1,1,255.920000000,,1,0,1,0,250.000000000,,13,0,2,0,236.860000000,,100,0,1,0,235.690000000,,100,0,1,0,,,0,0,0,0,,,0,0,0,0,AMGN
2025-01-03T10:31:22.743878445Z,2025-01-03T10:31:22.743712392Z,10,2,38,C,B,1,243.440000000,200,130,166053,4876500,243.500000000,243.640000000,6,54,1,1,243.440000000,243.650000000,200,61,1,2,243.400000000,243.710000000,29,200,1,1,243.190000000,243.760000000,2,26,1,1,243.020000000,244.000000000,79,1,1,1,243.000000000,244.140000000,1243,79,9,1,242.990000000,244.200000000,1,1000,1,1,242.750000000,244.400000000,30,50,1,1,242.590000000,244.420000000,5,10,1,1,242.280000000,244.580000000,100,100,1,1,AAPL
2025-01-03T10:31:22.743891698Z,2025-01-03T10:31:22.743724921Z,10,2,38,A,B,1,243.470000000,200,130,166777,4876501,243.500000000,243.640000000,6,54,1,1,243.470000000,243.650000000,200,61,1,2,243.400000000,243.710000000,29,200,1,1,243.190000000,243.760000000,2,26,1,1,243.020000000,244.000000000,79,1,1,1,243.000000000,244.140000000,1243,79,9,1,242.990000000,244.200000000,1,1000,1,1,242.750000000,244.400000000,30,50,1,1,242.590000000,244.420000000,5,10,1,1,242.280000000,244.580000000,100,100,1,1,AAPL
2025-01-03T10:31:23.083509983Z,2025-01-03T10:31:23.083343617Z,10,2,11667,A,A,1,139.210000000,400,130,166366,4876632,139.130000000,139.200000000,2200,129,2,1,139.120000000,139.210000000,30,400,1,1,139.110000000,139.220000000,1,110,1,2,139.090000000,139.230000000,400,25,1,1,139.080000000,139.250000000,57,1,1,1,139.070000000,139.270000000,100,37,1,2,139.030000000,139.300000000,126,507,2,4,139.010000000,139.320000000,100,39,1,1,139.000000000,139.330000000,420,503,5,2,138.980000000,139.360000000,300,14,1,3,NVDA
2025-01-03T10:31:23.084274806Z,2025-01-03T10:31:23.084108896Z,10,2,38,C,A,2,243.710000000,200,130,165910,4876656,243.500000000,243.640000000,6,54,1,1,243.470000000,243.650000000,200,61,1,2,243.400000000,243.760000000,29,26,1,1,243.190000000,244.000000000,2,1,1,1,243.020000000,244.140000000,79,79,1,1,243.000000000,244.200000000,1243,1000,9,1,242.990000000,244.400000000,1,50,1,1,242.750000000,244.420000000,30,10,1,1,242.590000000,244.580000000,5,100,1,1,242.280000000,245.000000000,100,79,1,2,AAPL
2025-01-03T10:31:23.130287421Z,2025-01-03T10:31:23.130121063Z,10,2,38,A,A,2,243.700000000,200,130,166358,4876752,243.500000000,243.640000000,6,54,1,1,243.470000000,243.650000000,200,61,1,2,243.400000000,243.700000000,29,200,1,1,243.190000000,243.760000000,2,26,1,1,243.020000000,244.000000000,79,1,1,1,243.000000000,244.140000000,1243,79,9,1,242.990000000,244.200000000,1,1000,1,1,242.750000000,244.400000000,30,50,1,1,242.590000000,244.420000000,5,10,1,1,242.280000000,244.580000000,100,100,1,1,AAPL
2025-01-03T10:31:24.014814532Z,2025-01-03T10:31:24.014648449Z,10,2,10888,C,B,0,420.960000000,20,130,166083,4877088,420.720000000,421.250000000,200,200,1,1,420.640000000,421.310000000,13,15,1,1,420.580000000,421.460000000,10,39,1,1,420.520000000,421.490000000,1,6,1,1,420.400000000,421.570000000,858,40,1,1,420.380000000,421.600000000,100,10,1,1,420.100000000,421.700000000,100,359,1,1,420.000000000,421.800000000,534,7,7,1,419.730000000,422.100000000,3,7,1,1,419.650000000,422.400000000,39,500,1,1,MSFT
2025-01-03T10:31:24.015816122Z,2025-01-03T10:31:24.015649889Z,10,2,10888,A,B,0,421.000000000,20,130,166233,4877094,421.000000000,421.250000000,20,200,1,1,420.720000000,421.310000000,200,15,1,1,420.640000000,421.460000000,13,39,1,1,420.580000000,421.490000000,10,6,1,1,420.520000000,421.570000000,1,40,1,1,420.400000000,421.600000000,858,10,1,1,420.380000000,421.700000000,100,359,1,1,420.100000000,421.800000000,100,7,1,1,420.000000000,422.100000000,534,7,7,1,419.730000000,422.400000000,3,500,1,1,MSFT
2025-01-03T10:31:24.018731899Z,2025-01-03T10:31:24.018565568Z,10,2,10888,C,B,8,420.000000000,500,130,166331,4877097,421.000000000,421.250000000,20,200,1,1,420.720000000,421.310000000,200,15,1,1,420.640000000,421.460000000,13,39,1,1,420.580000000,421.490000000,10,6,1,1,420.520000000,421.570000000,1,40,1,1,420.400000000,421.600000000,858,10,1,1,420.380000000,421.700000000,100,359,1,1,420.100000000,421.800000000,100,7,1,1,420.000000000,422.100000000,34,7,6,1,419.730000000,422.400000000,3,500,1,1,MSFT
2025-01-03T10:31:24.034999840Z,2025-01-03T10:31:24.034833411Z,10,2,10888,A,B,8,420.000000000,500,130,166429,4877106,421.000000000,421.250000000,20,200,1,1,420.720000000,421.310000000,200,15,1,1,420.640000000,421.460000000,13,39,1,1,420.580000000,421.490000000,10,6,1,1,420.520000000,421.570000000,1,40,1,1,420.400000000,421.600000000,858,10,1,1,420.380000000,421.700000000,100,359,1,1,420.100000000,421.800000000,100,7,1,1,420.000000000,422.100000000,534,7,7,1,419.730000000,422.400000000,3,500,1,1,MSFT
2025-01-03T10:31:24.085477716Z,2025-01-03T10:31:24.085311837Z,10,2,10888,C,B,1,420.720000000,200,130,165879,4877109,421.000000000,421.250000000,20,200,1,1,420.640000000,421.310000000,13,15,1,1,420.580000000,421.460000000,10,39,1,1,420.520000000,421.490000000,1,6,1,1,420.400000000,421.570000000,858,40,1,1,420.380000000,421.600000000,100,10,1,1,420.100000000,421.700000000,100,359,1,1,420.000000000,421.800000000,534,7,7,1,419.730000000,422.100000000,3,7,1,1,419.650000000,422.400000000,39,500,1,1,MSFT
2025-01-03T10:31:24.085489920Z,2025-01-03T10:31:24.085323744Z,10,2,10888,A,B,1,420.690000000,200,130,166176,4877110,421.000000000,421.250000000,20,200,1,1,420.690000000,421.310000000,200,15,1,1,420.640000000,421.460000000,13,39,1,1,420.580000000,421.490000000,10,6,1,1,420.520000000,421.570000000,1,40,1,1,420.400000000,421.600000000,858,10,1,1,420.380000000,421.700000000,100,359,1,1,420.100000000,421.800000000,100,7,1,1,420.000000000,422.100000000,534,7,7,1,419.730000000,422.400000000,3,500,1,1,MSFT
2025-01-03T10:31:24.139553758Z,2025-01-03T10:31:24.139387465Z,10,2,10888,A,B,1,420.700000000,200,130,166293,4877132,421.000000000,421.250000000,20,200,1,1,420.700000000,421.310000000,200,15,1,1,420.640000000,421.460000000,13,39,1,1,420.580000000,421.490000000,10,6,1,1,420.520000000,421.570000000,1,40,1,1,420.400000000,421.600000000,858,10,1,1,420.380000000,421.700000000,100,359,1,1,420.100000000,421.800000000,100,7,1,1,420.000000000,422.100000000,534,7,7,1,419.730000000,422.400000000,3,500,1,1,MSFT
2025-01-03T10:31:24.200731097Z,2025-01-03T10:31:24.200564959Z,10,2,38,A,B,7,242.800000000,30,130,166138,4877144,243.500000000,243.640000000,6,54,1,1,243.470000000,243.650000000,200,61,1,2,243.400000000,243.700000000,29,200,1,1,243.190000000,243.760000000,2,26,1,1,243.020000000,244.000000000,79,1,1,1,243.000000000,244.140000000,1243,79,9,1,242.990000000,244.200000000,1,1000,1,1,242.800000000,244.400000000,30,50,1,1,242.750000000,244.420000000,30,10,1,1,242.590000000,244.580000000,5,100,1,1,AAPL
2025-01-03T10:31:24.279942029Z,2025-01-03T10:31:24.279775949Z,10,2,10888,C,B,2,420.640000000,13,130,166080,4877175,421.000000000,421.250000000,20,200,1,1,420.700000000,421.310000000,200,15,1,1,420.580000000,421.460000000,10,39,1,1,420.520000000,421.490000000,1,6,1,1,420.400000000,421.570000000,858,40,1,1,420.380000000,421.600000000,100,10,1,1,420.100000000,421.700000000,100,359,1,1,420.000000000,421.800000000,534,7,7,1,419.730000000,422.100000000,3,7,1,1,419.650000000,422.400000000,39,500,1,1,MSFT
2025-01-03T10:31:24.280003293Z,2025-01-03T10:31:24.279837229Z,10,2,10888,A,B,2,420.670000000,13,130,166064,4877176,421.000000000,421.250000000,20,200,1,1,420.700000000,421.310000000,200,15,1,1,420.670000000,421.460000000,13,39,1,1,420.580000000,421.490000000,10,6,1,1,420.520000000,421.570000000,1,40,1,1,420.400000000,421.600000000,858,10,1,1,420.380000000,421.700000000,100,359,1,1,420.100000000,421.800000000,100,7,1,1,420.000000000,422.100000000,534,7,7,1,419.730000000,422.400000000,3,500,1,1,MSFT
2025-01-03T10:31:24.280261042Z,2025-01-03T10:31:24.280095187Z,10,2,10888,C,B,8,420.000000000,500,130,165855,4877178,421.000000000,421.250000000,20,200,1,1,420.700000000,421.310000000,200,15,1,1,420.670000000,421.460000000,13,39,1,1,420.580000000,421.490000000,10,6,1,1,420.520000000,421.570000000,1,40,1,1,420.400000000,421.600000000,858,10,1,1,420.380000000,421.700000000,100,359,1,1,420.100000000,421.800000000,100,7,1,1,420.000000000,422.100000000,34,7,6,1,419.730000000,422.400000000,3,500,1,1,MSFT
2025-01-03T10:31:24.316576230Z,2025-01-03T10:31:24.316409814Z,10,2,10888,A,B,1,420.710000000,200,130,166416,4877186,421.000000000,421.250000000,20,200,1,1,420.710000000,421.310000000,200,15,1,1,420.670000000,421.460000000,13,39,1,1,420.580000000,421.490000000,10,6,1,1,420.520000000,421.570000000,1,40,1,1,420.400000000,421.600000000,858,10,1,1,420.380000000,421.700000000,100,359,1,1,420.100000000,421.800000000,100,7,1,1,420.000000000,422.100000000,34,7,6,1,419.730000000,422.400000000,3,500,1,1,MSFT
2025-01-03T10:31:24.335577961Z,2025-01-03T10:31:24.335410989Z,10,2,10888,A,B,1,420.720000000,200,130,166972,4877188,421.000000000,421.250000000,20,200,1,1,420.720000000,421.310000000,200,15,1,1,420.670000000,421.460000000,13,39,1,1,420.580000000,421.490000000,10,6,1,1,420.520000000,421.570000000,1,40,1,1,420.400000000,421.600000000,858,10,1,1,420.380000000,421.700000000,100,359,1,1,420.100000000,421.800000000,100,7,1,1,420.000000000,422.100000000,34,7,6,1,419.730000000,422.400000000,3,500,1,1,MSFT
2025-01-03T10:31:25.023510292Z,2025-01-03T10:31:25.023344071Z,10,2,10888,A,B,3,420.620000000,15,130,166221,4877423,421.000000000,421.250000000,20,200,1,1,420.720000000,421.310000000,200,15,1,1,420.670000000,421.460000000,13,39,1,1,420.620000000,421.490000000,15,6,1,1,420.580000000,421.570000000,10,40,1,1,420.520000000,421.600000000,1,10,1,1,420.400000000,421.700000000,858,359,1,1,420.380000000,421.800000000,100,7,1,1,420.100000000,422.100000000,100,7,1,1,420.000000000,422.400000000,34,500,6,1,MSFT
2025-01-03T10:31:25.023547409Z,2025-01-03T10:31:25.023381549Z,10,2,10888,C,B,2,420.670000000,13,130,165860,4877424,421.000000000,421.250000000,20,200,1,1,420.720000000,421.310000000,200,15,1,1,420.620000000,421.460000000,15,39,1,1,420.580000000,421.490000000,10,6,1,1,420.520000000,421.570000000,1,40,1,1,420.400000000,421.600000000,858,10,1,1,420.380000000,421.700000000,100,359,1,1,420.100000000,421.800000000,100,7,1,1,420.000000000,422.100000000,34,7,6,1,419.730000000,422.400000000,3,500,1,1,MSFT
2025-01-03T10:31:25.052309600Z,2025-01-03T10:31:25.052142283Z,10,2,10888,A,B,8,420.000000000,500,130,167317,4877439,421.000000000,421.250000000,20,200,1,1,420.720000000,421.310000000,200,15,1,1,420.620000000,421.460000000,15,39,1,1,420.580000000,421.490000000,10,6,1,1,420.520000000,421.570000000,1,40,1,1,420.400000000,421.600000000,858,10,1,1,420.380000000,421.700000000,100,359,1,1,420.100000000,421.800000000,100,7,1,1,420.000000000,422.100000000,534,7,7,1,419.730000000,422.400000000,3,500,1,1,MSFT
2025-01-03T10:31:25.427308330Z,2025-01-03T10:31:25.427142308Z,10,2,16244,A,B,0,383.100000000,20,130,166022,4877602,383.100000000,383.420000000,40,140,2,1,383.090000000,383.500000000,3,20,1,1,383.060000000,383.540000000,23,19,1,1,382.810000000,383.600000000,20,1000,2,2,382.720000000,383.720000000,10,7085,1,8,382.700000000,383.740000000,50,37,1,1,382.680000000,383.800000000,20,10,1,1,382.500000000,383.880000000,3,4,1,1,382.400000000,384.000000000,500,1300,1,4,382.230000000,384.260000000,25,15,1,1,TSLA
2025-01-03T10:31:25.849574978Z,2025-01-03T10:31:25.849409287Z,10,2,10888,C,B,8,420.000000000,500,130,165691,4877725,421.000000000,421.250000000,20,200,1,1,420.720000000,421.310000000,200,15,1,1,420.620000000,421.460000000,15,39,1,1,420.580000000,421.490000000,10,6,1,1,420.520000000,421.570000000,1,40,1,1,420.400000000,421.600000000,858,10,1,1,420.380000000,421.700000000,100,359,1,1,420.100000000,421.800000000,100,7,1,1,420.000000000,422.100000000,34,7,6,1,419.730000000,422.400000000,3,500,1,1,MSFT
2025-01-03T10:31:25.939769523Z,2025-01-03T10:31:25.939603209Z,10,2,17709,A,B,1,107.560000000,16,130,166314,4877756,107.600000000,107.840000000,50,400,1,2,107.560000000,107.870000000,16,242,1,1,107.540000000,107.910000000,16,15,1,1,107.520000000,107.940000000,100,100,1,1,107.050000000,107.950000000,247,10,1,1,107.000000000,108.000000000,1,50,1,1,106.240000000,108.300000000,28,50,1,1,106.000000000,108.550000000,15,50,2,1,105.870000000,108.800000000,141,50,1,1,103.180000000,108.880000000,16,28,1,1,XOM
2025-01-03T10:31:25.939807372Z,2025-01-03T10:31:25.939641253Z,10,2,17709,C,B,2,107.540000000,16,130,166119,4877757,107.600000000,107.840000000,50,400,1,2,107.560000000,107.870000000,16,242,1,1,107.520000000,107.910000000,100,15,1,1,107.050000000,107.940000000,247,100,1,1,107.000000000,107.950000000,1,10,1,1,106.240000000,108.000000000,28,50,1,1,106.000000000,108.300000000,15,50,2,1,105.870000000,108.550000000,141,50,1,1,103.180000000,108.800000000,16,50,1,1,103.000000000,108.880000000,3,28,1,1,XOM
2025-01-03T10:31:26.937855236Z,2025-01-03T10:31:26.937689231Z,10,2,17709,A,A,1,107.860000000,15,130,166005,4878077,107.600000000,107.840000000,50,400,1,2,107.560000000,107.860000000,16,15,1,1,107.520000000,107.870000000,100,242,1,1,107.050000000,107.910000000,247,15,1,1,107.000000000,107.940000000,1,100,1,1,106.240000000,107.950000000,28,10,1,1,106.000000000,108.000000000,15,50,2,1,105.870000000,108.300000000,141,50,1,1,103.180000000,108.550000000,16,50,1,1,103.000000000,108.800000000,3,50,1,1,XOM
2025-01-03T10:31:26.937884115Z,2025-01-03T10:31:26.937718229Z,10,2,17709,C,A,3,107.910000000,15,130,165886,4878078,107.600000000,107.840000000,50,400,1,2,107.560000000,107.860000000,16,15,1,1,107.520000000,107.870000000,100,242,1,1,107.050000000,107.940000000,247,100,1,1,107.000000000,107.950000000,1,10,1,1,106.240000000,108.000000000,28,50,1,1,106.000000000,108.300000000,15,50,2,1,105.870000000,108.550000000,141,50,1,1,103.180000000,108.800000000,16,50,1,1,103.000000000,108.880000000,3,28,1,1,XOM
2025-01-03T10:31:26.938485956Z,2025-01-03T10:31:26.938320077Z,10,2,17709,C,A,1,107.860000000,15,130,165879,4878079,107.600000000,107.840000000,50,400,1,2,107.560000000,107.870000000,16,242,1,1,107.520000000,107.940000000,100,100,1,1,107.050000000,107.950000000,247,10,1,1,107.000000000,108.000000000,1,50,1,1,106.240000000,108.300000000,28,50,1,1,106.000000000,108.550000000,15,50,2,1,105.870000000,108.800000000,141,50,1,1,103.180000000,108.880000000,16,28,1,1,103.000000000,109.000000000,3,100,1,1,XOM
2025-01-03T10:31:29.195724155Z,2025-01-03T10:31:29.195558273Z,10,2,16244,C,B,7,382.500000000,3,130,165882,4879154,383.100000000,383.420000000,40,140,2,1,383.090000000,383.500000000,3,20,1,1,383.060000000,383.540000000,23,19,1,1,382.810000000,383.600000000,20,1000,2,2,382.720000000,383.720000000,10,7085,1,8,382.700000000,383.740000000,50,37,1,1,382.680000000,383.800000000,20,10,1,1,382.400000000,383.880000000,500,4,1,1,382.230000000,384.000000000,25,1300,1,4,382.110000000,384.260000000,300,15,1,1,TSLA
2025-01-03T10:31:29.197212281Z,2025-01-03T10:31:29.197045897Z,10,2,16244,A,B,3,383.000000000,3,130,166384,4879155,383.100000000,383.420000000,40,140,2,1,383.090000000,383.500000000,3,20,1,1,383.060000000,383.540000000,23,19,1,1,383.000000000,383.600000000,3,1000,1,2,382.810000000,383.720000000,20,7085,2,8,382.720000000,383.740000000,10,37,1,1,382.700000000,383.800000000,50,10,1,1,382.680000000,383.880000000,20,4,1,1,382.400000000,384.000000000,500,1300,1,4,382.230000000,384.260000000,25,15,1,1,TSLA
2025-01-03T10:31:29.877942908Z,2025-01-03T10:31:29.877776442Z,10,2,9155,A,B,1,241.590000000,8,130,166466,4879579,241.670000000,242.070000000,2,62,1,1,241.590000000,242.420000000,8,8,1,1,241.120000000,242.850000000,81,300,1,2,241.000000000,242.900000000,100,100,1,1,240.000000000,243.000000000,10,92,1,2,238.000000000,243.310000000,30,10,1,1,236.000000000,243.700000000,6,100,1,1,235.500000000,246.810000000,5,100,1,1,235.000000000,262.740000000,5,100,1,1,232.880000000,263.830000000,1,100,1,1,JPM
2025-01-03T10:31:30.941976198Z,2025-01-03T10:31:30.941809546Z,10,2,11667,A,B,0,139.160000000,100,130,166652,4880104,139.160000000,139.200000000,100,129,1,1,139.130000000,139.210000000,2200,400,2,1,139.120000000,139.220000000,30,110,1,2,139.110000000,139.230000000,1,25,1,1,139.090000000,139.250000000,400,1,1,1,139.080000000,139.270000000,57,37,1,2,139.070000000,139.300000000,100,507,1,4,139.030000000,139.320000000,126,39,2,1,139.010000000,139.330000000,100,503,1,2,139.000000000,139.360000000,420,14,5,3,NVDA
2025-01-03T10:31:31.057717774Z,2025-01-03T10:31:31.057551470Z,10,2,11667,C,B,4,139.090000000,400,130,166304,4880175,139.160000000,139.200000000,100,129,1,1,139.130000000,139.210000000,2200,400,2,1,139.120000000,139.220000000,30,110,1,2,139.110000000,139.230000000,1,25,1,1,139.080000000,139.250000000,57,1,1,1,139.070000000,139.270000000,100,37,1,2,139.030000000,139.300000000,126,507,2,4,139.010000000,139.320000000,100,39,1,1,139.000000000,139.330000000,420,503,5,2,138.980000000,139.360000000,300,14,1,3,NVDA
2025-01-03T10:31:31.057731954Z,2025-01-03T10:31:31.057565595Z,10,2,11667,A,B,4,139.080000000,400,130,166359,4880176,139.160000000,139.200000000,100,129,1,1,139.130000000,139.210000000,2200,400,2,1,139.120000000,139.220000000,30,110,1,2,139.110000000,139.230000000,1,25,1,1,139.080000000,139.250000000,457,1,2,1,139.070000000,139.270000000,100,37,1,2,139.030000000,139.300000000,126,507,2,4,139.010000000,139.320000000,100,39,1,1,139.000000000,139.330000000,420,503,5,2,138.980000000,139.360000000,300,14,1,3,NVDA
2025-01-03T10:31:31.067615147Z,2025-01-03T10:31:31.067448493Z,10,2,11667,C,B,4,139.080000000,400,130,166654,4880180,139.160000000,139.200000000,100,129,1,1,139.130000000,139.210000000,2200,400,2,1,139.120000000,139.220000000,30,110,1,2,139.110000000,139.230000000,1,25,1,1,139.080000000,139.250000000,57,1,1,1,139.070000000,139.270000000,100,37,1,2,139.030000000,139.300000000,126,507,2,4,139.010000000,139.320000000,100,39,1,1,139.000000000,139.330000000,420,503,5,2,138.980000000,139.360000000,300,14,1,3,NVDA
2025-01-03T10:31:31.067625818Z,2025-01-03T10:31:31.067459549Z,10,2,11667,A,B,5,139.070000000,400,130,166269,4880181,139.160000000,139.200000000,100,129,1,1,139.130000000,139.210000000,2200,400,2,1,139.120000000,139.220000000,30,110,1,2,139.110000000,139.230000000,1,25,1,1,139.080000000,139.250000000,57,1,1,1,139.070000000,139.270000000,500,37,2,2,139.030000000,139.300000000,126,507,2,4,139.010000000,139.320000000,100,39,1,1,139.000000000,139.330000000,420,503,5,2,138.980000000,139.360000000,300,14,1,3,NVDA
2025-01-03T10:31:31.581857116Z,2025-01-03T10:31:31.581691185Z,10,2,10888,C,B,2,420.620000000,15,130,165931,4881126,421.000000000,421.250000000,20,200,1,1,420.720000000,421.310000000,200,15,1,1,420.580000000,421.460000000,10,39,1,1,420.520000000,421.490000000,1,6,1,1,420.400000000,421.570000000,858,40,1,1,420.380000000,421.600000000,100,10,1,1,420.100000000,421.700000000,100,359,1,1,420.000000000,421.800000000,34,7,6,1,419.730000000,422.100000000,3,7,1,1,419.650000000,422.400000000,39,500,1,1,MSFT
2025-01-03T10:31:31.581917334Z,2025-01-03T10:31:31.581751064Z,10,2,10888,A,B,2,420.670000000,15,130,166270,4881127,421.000000000,421.250000000,20,200,1,1,420.720000000,421.310000000,200,15,1,1,420.670000000,421.460000000,15,39,1,1,420.580000000,421.490000000,10,6,1,1,420.520000000,421.570000000,1,40,1,1,420.400000000,421.600000000,858,10,1,1,420.380000000,421.700000000,100,359,1,1,420.100000000,421.800000000,100,7,1,1,420.000000000,422.100000000,34,7,6,1,419.730000000,422.400000000,3,500,1,1,MSFT
2025-01-03T10:31:31.817351900Z,2025-01-03T10:31:31.817184741Z,10,2,780,C,B,0,259.590000000,25,130,167159,4881289,259.010000000,261.290000000,181,25,2,1,258.100000000,270.990000000,25,203,1,2,257.700000000,294.170000000,1,100,1,1,255.920000000,295.390000000,1,100,1,1,250.000000000,,13,0,2,0,236.860000000,,100,0,1,0,235.690000000,,100,0,1,0,,,0,0,0,0,,,0,0,0,0,,,0,0,0,0,AMGN
2025-01-03T10:31:31.817535608Z,2025-01-03T10:31:31.817368498Z,10,2,780,C,A,3,295.390000000,100,130,167110,4881290,259.010000000,261.290000000,181,25,2,1,258.100000000,270.990000000,25,203,1,2,257.700000000,294.170000000,1,100,1,1,255.920000000,,1,0,1,0,250.000000000,,13,0,2,0,236.860000000,,100,0,1,0,235.690000000,,100,0,1,0,,,0,0,0,0,,,0,0,0,0,,,0,0,0,0,AMGN
2025-01-03T10:31:31.817545481Z,2025-01-03T10:31:31.817379347Z,10,2,780,A,A,2,284.270000000,100,130,166134,4881291,259.010000000,261.290000000,181,25,2,1,258.100000000,270.990000000,25,203,1,2,257.700000000,284.270000000,1,100,1,1,255.920000000,294.170000000,1,100,1,1,250.000000000,,13,0,2,0,236.860000000,,100,0,1,0,235.690000000,,100,0,1,0,,,0,0,0,0,,,0,0,0,0,,,0,0,0,0,AMGN
2025-01-03T10:31:31.817671863Z,2025-01-03T10:31:31.817505568Z,10,2,780,A,A,0,260.580000000,1,130,166295,4881292,259.010000000,260.580000000,181,1,2,1,258.100000000,261.290000000,25,25,1,1,257.700000000,270.990000000,1,203,1,2,255.920000000,284.270000000,1,100,1,1,250.000000000,294.170000000,13,100,2,1,236.860000000,,100,0,1,0,235.690000000,,100,0,1,0,,,0,0,0,0,,,0,0,0,0,,,0,0,0,0,AMGN
2025-01-03T10:31:31.817686133Z,2025-01-03T10:31:31.817519255Z,10,2,780,A,A,1,260.940000000,1,130,166878,4881293,259.010000000,260.580000000,181,1,2,1,258.100000000,260.940000000,25,1,1,1,257.700000000,261.290000000,1,25,1,1,255.920000000,270.990000000,1,203,1,2,250.000000000,284.270000000,13,100,2,1,236.860000000,294.170000000,100,100,1,1,235.690000000,,100,0,1,0,,,0,0,0,0,,,0,0,0,0,,,0,0,0,0,AMGN
2025-01-03T10:31:31.817712787Z,2025-01-03T10:31:31.817546526Z,10,2,780,A,B,0,259.250000000,25,130,166261,4881294,259.250000000,260.580000000,25,1,1,1,259.010000000,260.940000000,181,1,2,1,258.100000000,261.290000000,25,25,1,1,257.700000000,270.990000000,1,203,1,2,255.920000000,284.270000000,1,100,1,1,250.000000000,294.170000000,13,100,2,1,236.860000000,,100,0,1,0,235.690000000,,100,0,1,0,,,0,0,0,0,,,0,0,0,0,AMGN
2025-01-03T10:31:31.818819981Z,2025-01-03T10:31:31.818653360Z,10,2,780,C,B,1,259.010000000,6,130,166621,4881296,259.250000000,260.580000000,25,1,1,1,259.010000000,260.940000000,175,1,1,1,258.100000000,261.290000000,25,25,1,1,257.700000000,270.990000000,1,203,1,2,255.920000000,284.270000000,1,100,1,1,250.000000000,294.170000000,13,100,2,1,236.860000000,,100,0,1,0,235.690000000,,100,0,1,0,,,0,0,0,0,,,0,0,0,0,AMGN
2025-01-03T10:31:31.818839681Z,2025-01-03T10:31:31.818673499Z,10,2,780,C,A,3,270.990000000,28,130,166182,4881297,259.250000000,260.580000000,25,1,1,1,259.010000000,260.940000000,175,1,1,1,258.100000000,261.290000000,25,25,1,1,257.700000000,270.990000000,1,175,1,1,255.920000000,284.270000000,1,100,1,1,250.000000000,294.170000000,13,100,2,1,236.860000000,,100,0,1,0,235.690000000,,100,0,1,0,,,0,0,0,0,,,0,0,0,0,AMGN
2025-01-03T10:31:31.819767147Z,2025-01-03T10:31:31.819600578Z,10,2,780,C,A,3,270.990000000,175,130,166569,4881298,259.250000000,260.580000000,25,1,1,1,259.010000000,260.940000000,175,1,1,1,258.100000000,261.290000000,25,25,1,1,257.700000000,284.270000000,1,100,1,1,255.920000000,294.170000000,1,100,1,1,250.000000000,,13,0,2,0,236.860000000,,100,0,1,0,235.690000000,,100,0,1,0,,,0,0,0,0,,,0,0,0,0,AMGN
2025-01-03T10:31:31.824839459Z,2025-01-03T10:31:31.824673080Z,10,2,17709,A,A,2,107.900000000,16,130,166379,4881306,107.600000000,107.840000000,50,400,1,2,107.560000000,107.870000000,16,242,1,1,107.520000000,107.900000000,100,16,1,1,107.050000000,107.940000000,247,100,1,1,107.000000000,107.950000000,1,10,1,1,106.240000000,108.000000000,28,50,1,1,106.000000000,108.300000000,15,50,2,1,105.870000000,108.550000000,141,50,1,1,103.180000000,108.800000000,16,50,1,1,103.000000000,108.880000000,3,28,1,1,XOM
2025-01-03T10:31:31.826273179Z,2025-01-03T10:31:31.826106976Z,10,2,780,C,A,4,294.170000000,100,130,166203,4881308,259.250000000,260.580000000,25,1,1,1,259.010000000,260.940000000,175,1,1,1,258.100000000,261.290000000,25,25,1,1,257.700000000,284.270000000,1,100,1,1,255.920000000,,1,0,1,0,250.000000000,,13,0,2,0,236.860000000,,100,0,1,0,235.690000000,,100,0,1,0,,,0,0,0,0,,,0,0,0,0,AMGN
2025-01-03T10:31:31.826286689Z,2025-01-03T10:31:31.826120112Z,10,2,780,A,A,3,283.090000000,100,130,166577,4881309,259.250000000,260.580000000,25,1,1,1,259.010000000,260.940000000,175,1,1,1,258.100000000,261.290000000,25,25,1,1,257.700000000,283.090000000,1,100,1,1,255.920000000,284.270000000,1,100,1,1,250.000000000,,13,0,2,0,236.860000000,,100,0,1,0,235.690000000,,100,0,1,0,,,0,0,0,0,,,0,0,0,0,AMGN
2025-01-03T10:31:31.827501102Z,2025-01-03T10:31:31.827334862Z,10,2,780,C,A,4,284.270000000,100,130,166240,4881310,259.250000000,260.580000000,25,1,1,1,259.010000000,260.940000000,175,1,1,1,258.100000000,261.290000000,25,25,1,1,257.700000000,283.090000000,1,100,1,1,255.920000000,,1,0,1,0,250.000000000,,13,0,2,0,236.860000000,,100,0,1,0,235.690000000,,100,0,1,0,,,0,0,0,0,,,0,0,0,0,AMGN
2025-01-03T10:31:31.827512887Z,2025-01-03T10:31:31.827346680Z,10,2,780,A,A,4,295.390000000,100,130,166207,4881311,259.250000000,260.580000000,25,1,1,1,259.010000000,260.940000000,175,1,1,1,258.100000000,261.290000000,25,25,1,1,257.700000000,283.090000000,1,100,1,1,255.920000000,295.390000000,1,100,1,1,250.000000000,,13,0,2,0,236.860000000,,100,0,1,0,235.690000000,,100,0,1,0,,,0,0,0,0,,,0,0,0,0,AMGN
2025-01-03T10:31:31.827889136Z,2025-01-03T10:31:31.827723281Z,10,2,780,C,A,3,283.090000000,100,130,165855,4881312,259.250000000,260.580000000,25,1,1,1,259.010000000,260.940000000,175,1,1,1,258.100000000,261.290000000,25,25,1,1,257.700000000,295.390000000,1,100,1,1,255.920000000,,1,0,1,0,250.000000000,,13,0,2,0,236.860000000,,100,0,1,0,235.690000000,,100,0,1,0,,,0,0,0,0,,,0,0,0,0,AMGN
2025-01-03T10:31:31.827897784Z,2025-01-03T10:31:31.827731600Z,10,2,780,A,A,3,294.170000000,100,130,166184,4881313,259.250000000,260.580000000,25,1,1,1,259.010000000,260.940000000,175,1,1,1,258.100000000,261.290000000,25,25,1,1,257.700000000,294.170000000,1,100,1,1,255.920000000,295.390000000,1,100,1,1,250.000000000,,13,0,2,0,236.860000000,,100,0,1,0,235.690000000,,100,0,1,0,,,0,0,0,0,,,0,0,0,0,AMGN
2025-01-03T10:31:31.830225187Z,2025-01-03T10:31:31.830058304Z,10,2,780,C,A,0,260.580000000,1,130,166883,4881315,259.250000000,260.940000000,25,1,1,1,259.010000000,261.290000000,175,25,1,1,258.100000000,294.170000000,25,100,1,1,257.700000000,295.390000000,1,100,1,1,255.920000000,,1,0,1,0,250.000000000,,13,0,2,0,236.860000000,,100,0,1,0,235.690000000,,100,0,1,0,,,0,0,0,0,,,0,0,0,0,AMGN
2025-01-03T10:31:31.872572537Z,2025-01-03T10:31:31.872406310Z,10,2,780,C,A,0,260.940000000,1,130,166227,4881336,259.250000000,261.290000000,25,25,1,1,259.010000000,294.170000000,175,100,1,1,258.100000000,295.390000000,25,100,1,1,257.700000000,,1,0,1,0,255.920000000,,1,0,1,0,250.000000000,,13,0,2,0,236.860000000,,100,0,1,0,235.690000000,,100,0,1,0,,,0,0,0,0,,,0,0,0,0,AMGN
2025-01-03T10:31:32.031492954Z,2025-01-03T10:31:32.031325339Z,10,2,11667,T,N,0,139.170000000,100,130,167615,4881398,139.160000000,139.200000000,100,129,1,1,139.130000000,139.210000000,2200,400,2,1,139.120000000,139.220000000,30,110,1,2,139.110000000,139.230000000,1,25,1,1,139.080000000,139.250000000,57,1,1,1,139.070000000,139.270000000,500,37,2,2,139.030000000,139.300000000,126,507,2,4,139.010000000,139.320000000,100,39,1,1,139.000000000,139.330000000,420,503,5,2,138.980000000,139.360000000,300,14,1,3,NVDA
2025-01-03T10:31:32.068003698Z,2025-01-03T10:31:32.067836796Z,10,2,11667,A,B,4,139.090000000,400,130,166902,4881426,139.160000000,139.200000000,100,129,1,1,139.130000000,139.210000000,2200,400,2,1,139.120000000,139.220000000,30,110,1,2,139.110000000,139.230000000,1,25,1,1,139.090000000,139.250000000,400,1,1,1,139.080000000,139.270000000,57,37,1,2,139.070000000,139.300000000,100,507,1,4,139.030000000,139.320000000,126,39,2,1,139.010000000,139.330000000,100,503,1,2,139.000000000,139.360000000,420,14,5,3,NVDA
2025-01-03T10:31:33.369598730Z,2025-01-03T10:31:33.369432881Z,10,2,9155,C,B,1,241.590000000,8,130,165849,4882328,241.670000000,242.070000000,2,62,1,1,241.120000000,242.420000000,81,8,1,1,241.000000000,242.850000000,100,300,1,2,240.000000000,242.900000000,10,100,1,1,238.000000000,243.000000000,30,92,1,2,236.000000000,243.310000000,6,10,1,1,235.500000000,243.700000000,5,100,1,1,235.000000000,246.810000000,5,100,1,1,232.880000000,262.740000000,1,100,1,1,231.110000000,263.830000000,3,100,1,1,JPM
2025-01-03T10:31:33.369660053Z,2025-01-03T10:31:33.369493937Z,10,2,9155,A,A,1,242.410000000,8,130,166116,4882329,241.670000000,242.070000000,2,62,1,1,241.120000000,242.410000000,81,8,1,1,241.000000000,242.420000000,100,8,1,1,240.000000000,242.850000000,10,300,1,2,238.000000000,242.900000000,30,100,1,1,236.000000000,243.000000000,6,92,1,2,235.500000000,243.310000000,5,10,1,1,235.000000000,243.700000000,5,100,1,1,232.880000000,246.810000000,1,100,1,1,231.110000000,262.740000000,3,100,1,1,JPM
2025-01-03T10:31:33.369687200Z,2025-01-03T10:31:33.369521362Z,10,2,9155,C,A,2,242.420000000,8,130,165838,4882330,241.670000000,242.070000000,2,62,1,1,241.120000000,242.410000000,81,8,1,1,241.000000000,242.850000000,100,300,1,2,240.000000000,242.900000000,10,100,1,1,238.000000000,243.000000000,30,92,1,2,236.000000000,243.310000000,6,10,1,1,235.500000000,243.700000000,5,100,1,1,235.000000000,246.810000000,5,100,1,1,232.880000000,262.740000000,1,100,1,1,231.110000000,263.830000000,3,100,1,1,JPM
2025-01-03T10:31:33.369744812Z,2025-01-03T10:31:33.369578201Z,10,2,9155,A,B,1,241.490000000,8,130,166611,4882331,241.670000000,242.070000000,2,62,1,1,241.490000000,242.410000000,8,8,1,1,241.120000000,242.850000000,81,300,1,2,241.000000000,242.900000000,100,100,1,1,240.000000000,243.000000000,10,92,1,2,238.000000000,243.310000000,30,10,1,1,236.000000000,243.700000000,6,100,1,1,235.500000000,246.810000000,5,100,1,1,235.000000000,262.740000000,5,100,1,1,232.880000000,263.830000000,1,100,1,1,JPM
2025-01-03T10:31:33.567517227Z,2025-01-03T10:31:33.567349904Z,10,2,16244,T,N,0,383.170000000,2,130,167323,4882428,383.100000000,383.420000000,40,140,2,1,383.090000000,383.500000000,3,20,1,1,383.060000000,383.540000000,23,19,1,1,383.000000000,383.600000000,3,1000,1,2,382.810000000,383.720000000,20,7085,2,8,382.720000000,383.740000000,10,37,1,1,382.700000000,383.800000000,50,10,1,1,382.680000000,383.880000000,20,4,1,1,382.400000000,384.000000000,500,1300,1,4,382.230000000,384.260000000,25,15,1,1,TSLA
2025-01-03T10:31:33.612243536Z,2025-01-03T10:31:33.612077430Z,10,2,16244,C,B,5,382.720000000,10,130,166106,4882440,383.100000000,383.420000000,40,140,2,1,383.090000000,383.500000000,3,20,1,1,383.060000000,383.540000000,23,19,1,1,383.000000000,383.600000000,3,1000,1,2,382.810000000,383.720000000,20,7085,2,8,382.700000000,383.740000000,50,37,1,1,382.680000000,383.800000000,20,10,1,1,382.400000000,383.880000000,500,4,1,1,382.230000000,384.000000000,25,1300,1,4,382.110000000,384.260000000,300,15,1,1,TSLA
2025-01-03T10:31:33.613690527Z,2025-01-03T10:31:33.613524110Z,10,2,16244,A,B,3,383.000000000,10,130,166417,4882441,383.100000000,383.420000000,40,140,2,1,383.090000000,383.500000000,3,20,1,1,383.060000000,383.540000000,23,19,1,1,383.000000000,383.600000000,13,1000,2,2,382.810000000,383.720000000,20,7085,2,8,382.700000000,383.740000000,50,37,1,1,382.680000000,383.800000000,20,10,1,1,382.400000000,383.880000000,500,4,1,1,382.230000000,384.000000000,25,1300,1,4,382.110000000,384.260000000,300,15,1,1,TSLA
2025-01-03T10:31:33.749872702Z,2025-01-03T10:31:33.749706242Z,10,2,780,A,A,0,261.120000000,25,130,166460,4882503,259.250000000,261.120000000,25,25,1,1,259.010000000,294.170000000,175,100,1,1,258.100000000,295.390000000,25,100,1,1,257.700000000,,1,0,1,0,255.920000000,,1,0,1,0,250.000000000,,13,0,2,0,236.860000000,,100,0,1,0,235.690000000,,100,0,1,0,,,0,0,0,0,,,0,0,0,0,AMGN
2025-01-03T10:31:34.538036418Z,2025-01-03T10:31:34.537870152Z,10,2,11667,A,A,0,139.180000000,3,130,166266,4882940,139.160000000,139.180000000,100,3,1,1,139.130000000,139.200000000,2200,129,2,1,139.120000000,139.210000000,30,400,1,1,139.110000000,139.220000000,1,110,1,2,139.090000000,139.230000000,400,25,1,1,139.080000000,139.250000000,57,1,1,1,139.070000000,139.270000000,100,37,1,2,139.030000000,139.300000000,126,507,2,4,139.010000000,139.320000000,100,39,1,1,139.000000000,139.330000000,420,503,5,2,NVDA
2025-01-03T10:31:34.580071005Z,2025-01-03T10:31:34.579904588Z,10,2,780,A,A,0,260.950000000,25,130,166417,4882958,259.250000000,260.950000000,25,25,1,1,259.010000000,294.170000000,175,100,1,1,258.100000000,295.390000000,25,100,1,1,257.700000000,,1,0,1,0,255.920000000,,1,0,1,0,250.000000000,,13,0,2,0,236.860000000,,100,0,1,0,235.690000000,,100,0,1,0,,,0,0,0,0,,,0,0,0,0,AMGN
2025-01-03T10:31:34.611882730Z,2025-01-03T10:31:34.611716660Z,10,2,11667,C,A,2,139.210000000,400,130,166070,4882988,139.160000000,139.180000000,100,3,1,1,139.130000000,139.200000000,2200,129,2,1,139.120000000,139.220000000,30,110,1,2,139.110000000,139.230000000,1,25,1,1,139.090000000,139.250000000,400,1,1,1,139.080000000,139.270000000,57,37,1,2,139.070000000,139.300000000,100,507,1,4,139.030000000,139.320000000,126,39,2,1,139.010000000,139.330000000,100,503,1,2,139.000000000,139.360000000,420,14,5,3,NVDA
2025-01-03T10:31:34.611896998Z,2025-01-03T10:31:34.611730182Z,10,2,11667,A,A,2,139.220000000,400,130,166816,4882989,139.160000000,139.180000000,100,3,1,1,139.130000000,139.200000000,2200,129,2,1,139.120000000,139.220000000,30,510,1,3,139.110000000,139.230000000,1,25,1,1,139.090000000,139.250000000,400,1,1,1,139.080000000,139.270000000,57,37,1,2,139.070000000,139.300000000,100,507,1,4,139.030000000,139.320000000,126,39,2,1,139.010000000,139.330000000,100,503,1,2,139.000000000,139.360000000,420,14,5,3,NVDA
2025-01-03T10:31:34.612560917Z,2025-01-03T10:31:34.612394932Z,10,2,11667,C,A,9,139.360000000,10,130,165985,4882991,139.160000000,139.180000000,100,3,1,1,139.130000000,139.200000000,2200,129,2,1,139.120000000,139.220000000,30,510,1,3,139.110000000,139.230000000,1,25,1,1,139.090000000,139.250000000,400,1,1,1,139.080000000,139.270000000,57,37,1,2,139.070000000,139.300000000,100,507,1,4,139.030000000,139.320000000,126,39,2,1,139.010000000,139.330000000,100,503,1,2,139.000000000,139.360000000,420,4,5,2,NVDA
2025-01-03T10:31:34.660932527Z,2025-01-03T10:31:34.660765562Z,10,2,11667,T,A,0,139.160000000,100,130,166965,4883023,139.160000000,139.180000000,100,3,1,1,139.130000000,139.200000000,2200,129,2,1,139.120000000,139.220000000,30,510,1,3,139.110000000,139.230000000,1,25,1,1,139.090000000,139.250000000,400,1,1,1,139.080000000,139.270000000,57,37,1,2,139.070000000,139.300000000,100,507,1,4,139.030000000,139.320000000,126,39,2,1,139.010000000,139.330000000,100,503,1,2,139.000000000,139.360000000,420,4,5,2,NVDA
2025-01-03T10:31:34.660932527Z,2025-01-03T10:31:34.660765562Z,10,2,11667,C,B,0,139.160000000,100,130,166965,4883023,139.130000000,139.180000000,2200,3,2,1,139.120000000,139.200000000,30,129,1,1,139.110000000,139.220000000,1,510,1,3,139.090000000,139.230000000,400,25,1,1,139.080000000,139.250000000,57,1,1,1,139.070000000,139.270000000,100,37,1,2,139.030000000,139.300000000,126,507,2,4,139.010000000,139.320000000,100,39,1,1,139.000000000,139.330000000,420,503,5,2,138.980000000,139.360000000,300,4,1,2,NVDA
2025-01-03T10:31:34.660967754Z,2025-01-03T10:31:34.660801363Z,10,2,11667,C,B,3,139.090000000,400,130,166391,4883024,139.130000000,139.180000000,2200,3,2,1,139.120000000,139.200000000,30,129,1,1,139.110000000,139.220000000,1,510,1,3,139.080000000,139.230000000,57,25,1,1,139.070000000,139.250000000,100,1,1,1,139.030000000,139.270000000,126,37,2,2,139.010000000,139.300000000,100,507,1,4,139.000000000,139.320000000,420,39,5,1,138.980000000,139.330000000,300,503,1,2,138.970000000,139.360000000,800,4,2,2,NVDA
2025-01-03T10:31:34.661464188Z,2025-01-03T10:31:34.661298084Z,10,2,11667,A,B,2,139.110000000,400,130,166104,4883033,139.130000000,139.180000000,2200,3,2,1,139.120000000,139.200000000,30,129,1,1,139.110000000,139.220000000,401,510,2,3,139.080000000,139.230000000,57,25,1,1,139.070000000,139.250000000,100,1,1,1,139.030000000,139.270000000,126,37,2,2,139.010000000,139.300000000,100,507,1,4,139.000000000,139.320000000,420,39,5,1,138.980000000,139.330000000,300,503,1,2,138.970000000,139.360000000,800,4,2,2,NVDA
2025-01-03T10:31:34.721203689Z,2025-01-03T10:31:34.721037590Z,10,2,11667,A,B,0,139.160000000,100,130,166099,4883083,139.160000000,139.180000000,100,3,1,1,139.130000000,139.200000000,2200,129,2,1,139.120000000,139.220000000,30,510,1,3,139.110000000,139.230000000,401,25,2,1,139.080000000,139.250000000,57,1,1,1,139.070000000,139.270000000,100,37,1,2,139.030000000,139.300000000,126,507,2,4,139.010000000,139.320000000,100,39,1,1,139.000000000,139.330000000,420,503,5,2,138.980000000,139.360000000,300,4,1,2,NVDA
2025-01-03T10:31:34.732054650Z,2025-01-03T10:31:34.731888988Z,10,2,11667,C,B,3,139.110000000,400,130,165662,4883111,139.160000000,139.180000000,100,3,1,1,139.130000000,139.200000000,2200,129,2,1,139.120000000,139.220000000,30,510,1,3,139.110000000,139.230000000,1,25,1,1,139.080000000,139.250000000,57,1,1,1,139.070000000,139.270000000,100,37,1,2,139.030000000,139.300000000,126,507,2,4,139.010000000,139.320000000,100,39,1,1,139.000000000,139.330000000,420,503,5,2,138.980000000,139.360000000,300,4,1,2,NVDA
2025-01-03T10:31:34.733046289Z,2025-01-03T10:31:34.732879507Z,10,2,11667,A,A,0,139.180000000,100,130,166782,4883113,139.160000000,139.180000000,100,103,1,2,139.130000000,139.200000000,2200,129,2,1,139.120000000,139.220000000,30,510,1,3,139.110000000,139.230000000,1,25,1,1,139.080000000,139.250000000,57,1,1,1,139.070000000,139.270000000,100,37,1,2,139.030000000,139.300000000,126,507,2,4,139.010000000,139.320000000,100,39,1,1,139.000000000,139.330000000,420,503,5,2,138.980000000,139.360000000,300,4,1,2,NVDA
2025-01-03T10:31:34.761574855Z,2025-01-03T10:31:34.761408619Z,10,2,11667,A,B,6,139.050000000,400,130,166236,4883135,139.160000000,139.180000000,100,103,1,2,139.130000000,139.200000000,2200,129,2,1,139.120000000,139.220000000,30,510,1,3,139.110000000,139.230000000,1,25,1,1,139.080000000,139.250000000,57,1,1,1,139.070000000,139.270000000,100,37,1,2,139.050000000,139.300000000,400,507,1,4,139.030000000,139.320000000,126,39,2,1,139.010000000,139.330000000,100,503,1,2,139.000000000,139.360000000,420,4,5,2,NVDA
2025-01-03T10:31:34.791254692Z,2025-01-03T10:31:34.791088201Z,10,2,11667,A,A,1,139.200000000,400,130,166491,4883153,139.160000000,139.180000000,100,103,1,2,139.130000000,139.200000000,2200,529,2,2,139.120000000,139.220000000,30,110,1,2,139.110000000,139.230000000,1,25,1,1,139.080000000,139.250000000,57,1,1,1,139.070000000,139.270000000,100,37,1,2,139.050000000,139.300000000,400,507,1,4,139.030000000,139.320000000,126,39,2,1,139.010000000,139.330000000,100,503,1,2,139.000000000,139.360000000,420,4,5,2,NVDA
2025-01-03T10:31:34.792448641Z,2025-01-03T10:31:34.792282569Z,10,2,11667,C,A,1,139.200000000,400,130,166072,4883154,139.160000000,139.180000000,100,103,1,2,139.130000000,139.200000000,2200,129,2,1,139.120000000,139.220000000,30,110,1,2,139.110000000,139.230000000,1,25,1,1,139.080000000,139.250000000,57,1,1,1,139.070000000,139.270000000,100,37,1,2,139.050000000,139.300000000,400,507,1,4,139.030000000,139.320000000,126,39,2,1,139.010000000,139.330000000,100,503,1,2,139.000000000,139.360000000,420,4,5,2,NVDA
2025-01-03T10:31:34.792462880Z,2025-01-03T10:31:34.792296296Z,10,2,11667,A,A,2,139.210000000,400,130,166584,4883155,139.160000000,139.180000000,100,103,1,2,139.130000000,139.200000000,2200,129,2,1,139.120000000,139.210000000,30,400,1,1,139.110000000,139.220000000,1,110,1,2,139.080000000,139.230000000,57,25,1,1,139.070000000,139.250000000,100,1,1,1,139.050000000,139.270000000,400,37,1,2,139.030000000,139.300000000,126,507,2,4,139.010000000,139.320000000,100,39,1,1,139.000000000,139.330000000,420,503,5,2,NVDA
2025-01-03T10:31:34.832506417Z,2025-01-03T10:31:34.832340064Z,10,2,11667,A,B,6,139.060000000,400,130,166353,4883187,139.160000000,139.180000000,100,103,1,2,139.130000000,139.200000000,2200,129,2,1,139.120000000,139.210000000,30,400,1,1,139.110000000,139.220000000,1,110,1,2,139.080000000,139.230000000,57,25,1,1,139.070000000,139.250000000,100,1,1,1,139.060000000,139.270000000,400,37,1,2,139.030000000,139.300000000,126,507,2,4,139.010000000,139.320000000,100,39,1,1,139.000000000,139.330000000,420,503,5,2,NVDA
2025-01-03T10:31:34.898421429Z,2025-01-03T10:31:34.898253484Z,10,2,11667,T,N,0,139.170000000,100,130,167945,4883223,139.160000000,139.180000000,100,103,1,2,139.130000000,139.200000000,2200,129,2,1,139.120000000,139.210000000,30,400,1,1,139.110000000,139.220000000,1,110,1,2,139.080000000,139.230000000,57,25,1,1,139.070000000,139.250000000,100,1,1,1,139.060000000,139.270000000,400,37,1,2,139.030000000,139.300000000,126,507,2,4,139.010000000,139.320000000,100,39,1,1,139.000000000,139.330000000,420,503,5,2,NVDA
2025-01-03T10:31:34.898690786Z,2025-01-03T10:31:34.898524666Z,10,2,11667,C,A,0,139.180000000,100,130,166120,4883224,139.160000000,139.180000000,100,3,1,1,139.130000000,139.200000000,2200,129,2,1,139.120000000,139.210000000,30,400,1,1,139.110000000,139.220000000,1,110,1,2,139.080000000,139.230000000,57,25,1,1,139.070000000,139.250000000,100,1,1,1,139.060000000,139.270000000,400,37,1,2,139.030000000,139.300000000,126,507,2,4,139.010000000,139.320000000,100,39,1,1,139.000000000,139.330000000,420,503,5,2,NVDA
2025-01-03T10:31:34.998333989Z,2025-01-03T10:31:34.998168054Z,10,2,780,C,B,0,259.250000000,25,130,165935,4883278,259.010000000,260.950000000,175,25,1,1,258.100000000,294.170000000,25,100,1,1,257.700000000,295.390000000,1,100,1,1,255.920000000,,1,0,1,0,250.000000000,,13,0,2,0,236.860000000,,100,0,1,0,235.690000000,,100,0,1,0,,,0,0,0,0,,,0,0,0,0,,,0,0,0,0,AMGN
2025-01-03T10:31:34.998346103Z,2025-01-03T10:31:34.998179544Z,10,2,780,A,B,1,258.740000000,25,130,166559,4883279,259.010000000,260.950000000,175,25,1,1,258.740000000,294.170000000,25,100,1,1,258.100000000,295.390000000,25,100,1,1,257.700000000,,1,0,1,0,255.920000000,,1,0,1,0,250.000000000,,13,0,2,0,236.860000000,,100,0,1,0,235.690000000,,100,0,1,0,,,0,0,0,0,,,0,0,0,0,AMGN
2025-01-03T10:31:35.054219443Z,2025-01-03T10:31:35.054052928Z,10,2,780,A,B,1,258.910000000,25,130,166515,4883309,259.010000000,260.950000000,175,25,1,1,258.910000000,294.170000000,25,100,1,1,258.100000000,295.390000000,25,100,1,1,257.700000000,,1,0,1,0,255.920000000,,1,0,1,0,250.000000000,,13,0,2,0,236.860000000,,100,0,1,0,235.690000000,,100,0,1,0,,,0,0,0,0,,,0,0,0,0,AMGN
2025-01-03T10:31:35.478324566Z,2025-01-03T10:31:35.478158315Z,10,2,16244,A,A,1,383.480000000,30,130,166251,4883491,383.100000000,383.420000000,40,140,2,1,383.090000000,383.480000000,3,30,1,1,383.060000000,383.500000000,23,20,1,1,383.000000000,383.540000000,13,19,2,1,382.810000000,383.600000000,20,1000,2,2,382.700000000,383.720000000,50,7085,1,8,382.680000000,383.740000000,20,37,1,1,382.400000000,383.800000000,500,10,1,1,382.230000000,383.880000000,25,4,1,1,382.110000000,384.000000000,300,1300,1,4,TSLA
2025-01-03T10:31:35.600361603Z,2025-01-03T10:31:35.600195523Z,10,2,38,A,A,3,243.750000000,30,130,166080,4883549,243.500000000,243.640000000,6,54,1,1,243.470000000,243.650000000,200,61,1,2,243.400000000,243.700000000,29,200,1,1,243.190000000,243.750000000,2,30,1,1,243.020000000,243.760000000,79,26,1,1,243.000000000,244.000000000,1243,1,9,1,242.990000000,244.140000000,1,79,1,1,242.800000000,244.200000000,30,1000,1,1,242.750000000,244.400000000,30,50,1,1,242.590000000,244.420000000,5,10,1,1,AAPL
2025-01-03T10:31:35.600396312Z,2025-01-03T10:31:35.600230560Z,10,2,38,C,A,4,243.760000000,26,130,165752,4883550,243.500000000,243.640000000,6,54,1,1,243.470000000,243.650000000,200,61,1,2,243.400000000,243.700000000,29,200,1,1,243.190000000,243.750000000,2,30,1,1,243.020000000,244.000000000,79,1,1,1,243.000000000,244.140000000,1243,79,9,1,242.990000000,244.200000000,1,1000,1,1,242.800000000,244.400000000,30,50,1,1,242.750000000,244.420000000,30,10,1,1,242.590000000,244.580000000,5,100,1,1,AAPL
2025-01-03T10:31:35.638772261Z,2025-01-03T10:31:35.638606263Z,10,2,11667,A,A,1,139.200000000,400,130,165998,4883573,139.160000000,139.180000000,100,3,1,1,139.130000000,139.200000000,2200,529,2,2,139.120000000,139.220000000,30,110,1,2,139.110000000,139.230000000,1,25,1,1,139.080000000,139.250000000,57,1,1,1,139.070000000,139.270000000,100,37,1,2,139.060000000,139.300000000,400,507,1,4,139.030000000,139.320000000,126,39,2,1,139.010000000,139.330000000,100,503,1,2,139.000000000,139.360000000,420,4,5,2,NVDA
2025-01-03T10:31:35.648772760Z,2025-01-03T10:31:35.648606711Z,10,2,11667,A,A,1,139.190000000,400,130,166049,4883604,139.160000000,139.180000000,100,3,1,1,139.130000000,139.190000000,2200,400,2,1,139.120000000,139.200000000,30,129,1,1,139.110000000,139.220000000,1,110,1,2,139.080000000,139.230000000,57,25,1,1,139.070000000,139.250000000,100,1,1,1,139.060000000,139.270000000,400,37,1,2,139.030000000,139.300000000,126,507,2,4,139.010000000,139.320000000,100,39,1,1,139.000000000,139.330000000,420,503,5,2,NVDA
2025-01-03T10:31:35.798344362Z,2025-01-03T10:31:35.798178634Z,10,2,38,C,B,1,243.470000000,200,130,165728,4883809,243.500000000,243.640000000,6,54,1,1,243.400000000,243.650000000,29,61,1,2,243.190000000,243.700000000,2,200,1,1,243.020000000,243.750000000,79,30,1,1,243.000000000,244.000000000,1243,1,9,1,242.990000000,244.140000000,1,79,1,1,242.800000000,244.200000000,30,1000,1,1,242.750000000,244.400000000,30,50,1,1,242.590000000,244.420000000,5,10,1,1,242.280000000,244.580000000,100,100,1,1,AAPL
2025-01-03T10:31:35.798356596Z,2025-01-03T10:31:35.798190477Z,10,2,38,A,B,1,243.450000000,400,130,166119,4883811,243.500000000,243.640000000,6,54,1,1,243.450000000,243.650000000,400,61,1,2,243.400000000,243.700000000,29,200,1,1,243.190000000,243.750000000,2,30,1,1,243.020000000,244.000000000,79,1,1,1,243.000000000,244.140000000,1243,79,9,1,242.990000000,244.200000000,1,1000,1,1,242.800000000,244.400000000,30,50,1,1,242.750000000,244.420000000,30,10,1,1,242.590000000,244.580000000,5,100,1,1,AAPL
2025-01-03T10:31:35.851343470Z,2025-01-03T10:31:35.851177430Z,10,2,16244,C,A,3,383.540000000,19,130,166040,4884026,383.100000000,383.420000000,40,140,2,1,383.090000000,383.480000000,3,30,1,1,383.060000000,383.500000000,23,20,1,1,383.000000000,383.600000000,13,1000,2,2,382.810000000,383.720000000,20,7085,2,8,382.700000000,383.740000000,50,37,1,1,382.680000000,383.800000000,20,10,1,1,382.400000000,383.880000000,500,4,1,1,382.230000000,384.000000000,25,1300,1,4,382.110000000,384.260000000,300,15,1,1,TSLA
2025-01-03T10:31:35.851454551Z,2025-01-03T10:31:35.851288050Z,10,2,16244,A,A,3,383.530000000,20,130,166501,4884027,383.100000000,383.420000000,40,140,2,1,383.090000000,383.480000000,3,30,1,1,383.060000000,383.500000000,23,20,1,1,383.000000000,383.530000000,13,20,2,1,382.810000000,383.600000000,20,1000,2,2,382.700000000,383.720000000,50,7085,1,8,382.680000000,383.740000000,20,37,1,1,382.400000000,383.800000000,500,10,1,1,382.230000000,383.880000000,25,4,1,1,382.110000000,384.000000000,300,1300,1,4,TSLA
2025-01-03T10:31:35.852829269Z,2025-01-03T10:31:35.852662852Z,10,2,11667,A,A,0,139.180000000,400,130,166417,4884051,139.160000000,139.180000000,100,403,1,2,139.130000000,139.200000000,2200,129,2,1,139.120000000,139.220000000,30,110,1,2,139.110000000,139.230000000,1,25,1,1,139.080000000,139.250000000,57,1,1,1,139.070000000,139.270000000,100,37,1,2,139.060000000,139.300000000,400,507,1,4,139.030000000,139.320000000,126,39,2,1,139.010000000,139.330000000,100,503,1,2,139.000000000,139.360000000,420,4,5,2,NVDA
2025-01-03T10:31:35.852854158Z,2025-01-03T10:31:35.852687818Z,10,2,38,A,A,2,243.690000000,200,130,166340,4884052,243.500000000,243.640000000,6,54,1,1,243.450000000,243.650000000,400,61,1,2,243.400000000,243.690000000,29,200,1,1,243.190000000,243.750000000,2,30,1,1,243.020000000,244.000000000,79,1,1,1,243.000000000,244.140000000,1243,79,9,1,242.990000000,244.200000000,1,1000,1,1,242.800000000,244.400000000,30,50,1,1,242.750000000,244.420000000,30,10,1,1,242.590000000,244.580000000,5,100,1,1,AAPL
2025-01-03T10:31:35.858589776Z,2025-01-03T10:31:35.858423612Z,10,2,11667,A,A,0,139.180000000,100,130,166164,4884111,139.160000000,139.180000000,100,503,1,3,139.130000000,139.200000000,2200,129,2,1,139.120000000,139.220000000,30,110,1,2,139.110000000,139.230000000,1,25,1,1,139.080000000,139.250000000,57,1,1,1,139.070000000,139.270000000,100,37,1,2,139.060000000,139.300000000,400,507,1,4,139.030000000,139.320000000,126,39,2,1,139.010000000,139.330000000,100,503,1,2,139.000000000,139.360000000,420,4,5,2,NVDA
2025-01-03T10:31:35.869111168Z,2025-01-03T10:31:35.868944555Z,10,2,10888,C,A,0,421.250000000,200,130,166613,4884209,421.000000000,421.310000000,20,15,1,1,420.720000000,421.460000000,200,39,1,1,420.670000000,421.490000000,15,6,1,1,420.580000000,421.570000000,10,40,1,1,420.520000000,421.600000000,1,10,1,1,420.400000000,421.700000000,858,359,1,1,420.380000000,421.800000000,100,7,1,1,420.100000000,422.100000000,100,7,1,1,420.000000000,422.400000000,34,500,6,1,419.730000000,422.500000000,3,200,1,1,MSFT
2025-01-03T10:31:35.869124787Z,2025-01-03T10:31:35.868958420Z,10,2,10888,A,A,0,421.310000000,200,130,166367,4884210,421.000000000,421.310000000,20,215,1,2,420.720000000,421.460000000,200,39,1,1,420.670000000,421.490000000,15,6,1,1,420.580000000,421.570000000,10,40,1,1,420.520000000,421.600000000,1,10,1,1,420.400000000,421.700000000,858,359,1,1,420.380000000,421.800000000,100,7,1,1,420.100000000,422.100000000,100,7,1,1,420.000000000,422.400000000,34,500,6,1,419.730000000,422.500000000,3,200,1,1,MSFT
2025-01-03T10:31:35.869892660Z,2025-01-03T10:31:35.869726701Z,10,2,10888,C,B,1,420.720000000,200,130,165959,4884218,421.000000000,421.310000000,20,215,1,2,420.670000000,421.460000000,15,39,1,1,420.580000000,421.490000000,10,6,1,1,420.520000000,421.570000000,1,40,1,1,420.400000000,421.600000000,858,10,1,1,420.380000000,421.700000000,100,359,1,1,420.100000000,421.800000000,100,7,1,1,420.000000000,422.100000000,34,7,6,1,419.730000000,422.400000000,3,500,1,1,419.650000000,422.500000000,39,200,1,1,MSFT
2025-01-03T10:31:35.869905605Z,2025-01-03T10:31:35.869739448Z,10,2,10888,A,B,2,420.630000000,200,130,166157,4884221,421.000000000,421.310000000,20,215,1,2,420.670000000,421.460000000,15,39,1,1,420.630000000,421.490000000,200,6,1,1,420.580000000,421.570000000,10,40,1,1,420.520000000,421.600000000,1,10,1,1,420.400000000,421.700000000,858,359,1,1,420.380000000,421.800000000,100,7,1,1,420.100000000,422.100000000,100,7,1,1,420.000000000,422.400000000,34,500,6,1,419.730000000,422.500000000,3,200,1,1,MSFT
2025-01-03T10:31:35.886526733Z,2025-01-03T10:31:35.886360606Z,10,2,9155,C,A,1,242.410000000,8,130,166127,4884428,241.670000000,242.070000000,2,62,1,1,241.490000000,242.850000000,8,300,1,2,241.120000000,242.900000000,81,100,1,1,241.000000000,243.000000000,100,92,1,2,240.000000000,243.310000000,10,10,1,1,238.000000000,243.700000000,30,100,1,1,236.000000000,246.810000000,6,100,1,1,235.500000000,262.740000000,5,100,1,1,235.000000000,263.830000000,5,100,1,1,232.880000000,,1,0,1,0,JPM
2025-01-03T10:31:35.886618110Z,2025-01-03T10:31:35.886452156Z,10,2,9155,A,A,1,242.400000000,8,130,165954,4884429,241.670000000,242.070000000,2,62,1,1,241.490000000,242.400000000,8,8,1,1,241.120000000,242.850000000,81,300,1,2,241.000000000,242.900000000,100,100,1,1,240.000000000,243.000000000,10,92,1,2,238.000000000,243.310000000,30,10,1,1,236.000000000,243.700000000,6,100,1,1,235.500000000,246.810000000,5,100,1,1,235.000000000,262.740000000,5,100,1,1,232.880000000,263.830000000,1,100,1,1,JPM
2025-01-03T10:31:35.889220807Z,2025-01-03T10:31:35.889054568Z,10,2,38,C,B,2,243.400000000,29,130,166239,4884451,243.500000000,243.640000000,6,54,1,1,243.450000000,243.650000000,400,61,1,2,243.190000000,243.690000000,2,200,1,1,243.020000000,243.750000000,79,30,1,1,243.000000000,244.000000000,1243,1,9,1,242.990000000,244.140000000,1,79,1,1,242.800000000,244.200000000,30,1000,1,1,242.750000000,244.400000000,30,50,1,1,242.590000000,244.420000000,5,10,1,1,242.280000000,244.580000000,100,100,1,1,AAPL
2025-01-03T10:31:35.889254315Z,2025-01-03T10:31:35.889087992Z,10,2,38,A,B,2,243.380000000,27,130,166323,4884453,243.500000000,243.640000000,6,54,1,1,243.450000000,243.650000000,400,61,1,2,243.380000000,243.690000000,27,200,1,1,243.190000000,243.750000000,2,30,1,1,243.020000000,244.000000000,79,1,1,1,243.000000000,244.140000000,1243,79,9,1,242.990000000,244.200000000,1,1000,1,1,242.800000000,244.400000000,30,50,1,1,242.750000000,244.420000000,30,10,1,1,242.590000000,244.580000000,5,100,1,1,AAPL
2025-01-03T10:31:35.905762280Z,2025-01-03T10:31:35.905596461Z,10,2,17709,C,B,1,107.560000000,16,130,165819,4884501,107.600000000,107.840000000,50,400,1,2,107.520000000,107.870000000,100,242,1,1,107.050000000,107.900000000,247,16,1,1,107.000000000,107.940000000,1,100,1,1,106.240000000,107.950000000,28,10,1,1,106.000000000,108.000000000,15,50,2,1,105.870000000,108.300000000,141,50,1,1,103.180000000,108.550000000,16,50,1,1,103.000000000,108.800000000,3,50,1,1,102.000000000,108.880000000,2,28,1,1,XOM
2025-01-03T10:31:35.905848361Z,2025-01-03T10:31:35.905681530Z,10,2,17709,A,B,1,107.530000000,16,130,166831,4884502,107.600000000,107.840000000,50,400,1,2,107.530000000,107.870000000,16,242,1,1,107.520000000,107.900000000,100,16,1,1,107.050000000,107.940000000,247,100,1,1,107.000000000,107.950000000,1,10,1,1,106.240000000,108.000000000,28,50,1,1,106.000000000,108.300000000,15,50,2,1,105.870000000,108.550000000,141,50,1,1,103.180000000,108.800000000,16,50,1,1,103.000000000,108.880000000,3,28,1,1,XOM
2025-01-03T10:31:35.925583376Z,2025-01-03T10:31:35.925417608Z,10,2,11667,C,A,0,139.180000000,400,130,165768,4884613,139.160000000,139.180000000,100,103,1,2,139.130000000,139.200000000,2200,129,2,1,139.120000000,139.220000000,30,110,1,2,139.110000000,139.230000000,1,25,1,1,139.080000000,139.250000000,57,1,1,1,139.070000000,139.270000000,100,37,1,2,139.060000000,139.300000000,400,507,1,4,139.030000000,139.320000000,126,39,2,1,139.010000000,139.330000000,100,503,1,2,139.000000000,139.360000000,420,4,5,2,NVDA
2025-01-03T10:31:35.925596821Z,2025-01-03T10:31:35.925430848Z,10,2,11667,A,A,1,139.200000000,400,130,165973,4884614,139.160000000,139.180000000,100,103,1,2,139.130000000,139.200000000,2200,529,2,2,139.120000000,139.220000000,30,110,1,2,139.110000000,139.230000000,1,25,1,1,139.080000000,139.250000000,57,1,1,1,139.070000000,139.270000000,100,37,1,2,139.060000000,139.300000000,400,507,1,4,139.030000000,139.320000000,126,39,2,1,139.010000000,139.330000000,100,503,1,2,139.000000000,139.360000000,420,4,5,2,NVDA
2025-01-03T10:31:35.937117651Z,2025-01-03T10:31:35.936951416Z,10,2,10888,A,A,0,421.300000000,200,130,166235,4884706,421.000000000,421.300000000,20,200,1,1,420.670000000,421.310000000,15,15,1,1,420.630000000,421.460000000,200,39,1,1,420.580000000,421.490000000,10,6,1,1,420.520000000,421.570000000,1,40,1,1,420.400000000,421.600000000,858,10,1,1,420.380000000,421.700000000,100,359,1,1,420.100000000,421.800000000,100,7,1,1,420.000000000,422.100000000,34,7,6,1,419.730000000,422.400000000,3,500,1,1,MSFT
2025-01-03T10:31:35.940232546Z,2025-01-03T10:31:35.940066639Z,10,2,10888,C,B,2,420.630000000,200,130,165907,4884708,421.000000000,421.300000000,20,200,1,1,420.670000000,421.310000000,15,15,1,1,420.580000000,421.460000000,10,39,1,1,420.520000000,421.490000000,1,6,1,1,420.400000000,421.570000000,858,40,1,1,420.380000000,421.600000000,100,10,1,1,420.100000000,421.700000000,100,359,1,1,420.000000000,421.800000000,34,7,6,1,419.730000000,422.100000000,3,7,1,1,419.650000000,422.400000000,39,500,1,1,MSFT
2025-01-03T10:31:35.940245361Z,2025-01-03T10:31:35.940078711Z,10,2,10888,A,B,2,420.600000000,200,130,166650,4884709,421.000000000,421.300000000,20,200,1,1,420.670000000,421.310000000,15,15,1,1,420.600000000,421.460000000,200,39,1,1,420.580000000,421.490000000,10,6,1,1,420.520000000,421.570000000,1,40,1,1,420.400000000,421.600000000,858,10,1,1,420.380000000,421.700000000,100,359,1,1,420.100000000,421.800000000,100,7,1,1,420.000000000,422.100000000,34,7,6,1,419.730000000,422.400000000,3,500,1,1,MSFT
2025-01-03T10:31:35.948004900Z,2025-01-03T10:31:35.947838529Z,10,2,16727,C,B,0,314.930000000,8,130,166371,4884767,314.860000000,315.450000000,25,8,1,1,314.420000000,315.510000000,61,25,1,1,313.500000000,315.750000000,1,61,1,1,310.000000000,320.000000000,1,5,1,1,300.000000000,320.210000000,3,1,1,1,290.000000000,321.950000000,2,2,1,1,286.660000000,344.200000000,100,100,1,1,285.250000000,345.620000000,100,100,1,1,260.000000000,,2,0,1,0,,,0,0,0,0,V
2025-01-03T10:31:35.948173500Z,2025-01-03T10:31:35.948007703Z,10,2,16727,C,A,0,315.450000000,8,130,165797,4884768,314.860000000,315.510000000,25,25,1,1,314.420000000,315.750000000,61,61,1,1,313.500000000,320.000000000,1,5,1,1,310.000000000,320.210000000,1,1,1,1,300.000000000,321.950000000,3,2,1,1,290.000000000,344.200000000,2,100,1,1,286.660000000,345.620000000,100,100,1,1,285.250000000,,100,0,1,0,260.000000000,,2,0,1,0,,,0,0,0,0,V
2025-01-03T10:31:35.948318312Z,2025-01-03T10:31:35.948152133Z,10,2,16727,A,B,0,314.890000000,8,130,166179,4884770,314.890000000,315.510000000,8,25,1,1,314.860000000,315.750000000,25,61,1,1,314.420000000,320.000000000,61,5,1,1,313.500000000,320.210000000,1,1,1,1,310.000000000,321.950000000,1,2,1,1,300.000000000,344.200000000,3,100,1,1,290.000000000,345.620000000,2,100,1,1,286.660000000,,100,0,1,0,285.250000000,,100,0,1,0,260.000000000,,2,0,1,0,V
2025-01-03T10:31:35.948524935Z,2025-01-03T10:31:35.948358612Z,10,2,16727,A,A,0,315.440000000,8,130,166323,4884773,314.890000000,315.440000000,8,8,1,1,314.860000000,315.510000000,25,25,1,1,314.420000000,315.750000000,61,61,1,1,313.500000000,320.000000000,1,5,1,1,310.000000000,320.210000000,1,1,1,1,300.000000000,321.950000000,3,2,1,1,290.000000000,344.200000000,2,100,1,1,286.660000000,345.620000000,100,100,1,1,285.250000000,,100,0,1,0,260.000000000,,2,0,1,0,V
2025-01-03T10:31:35.948783730Z,2025-01-03T10:31:35.948617367Z,10,2,12463,A,A,0,150.800000000,9,130,166363,4884775,150.460000000,150.800000000,1,9,1,1,150.310000000,150.810000000,9,9,1,1,150.260000000,150.840000000,234,100,1,1,150.250000000,151.000000000,1,1,1,1,150.210000000,153.280000000,113,10,2,1,150.020000000,163.540000000,2,100,1,1,150.000000000,164.210000000,250,100,1,1,149.950000000,179.000000000,5,5,1,1,149.740000000,,10,0,1,0,149.000000000,,5,0,1,0,PEP
2025-01-03T10:31:35.948837307Z,2025-01-03T10:31:35.948671192Z,10,2,12463,C,A,1,150.810000000,9,130,166115,4884776,150.460000000,150.800000000,1,9,1,1,150.310000000,150.840000000,9,100,1,1,150.260000000,151.000000000,234,1,1,1,150.250000000,153.280000000,1,10,1,1,150.210000000,163.540000000,113,100,2,1,150.020000000,164.210000000,2,100,1,1,150.000000000,179.000000000,250,5,1,1,149.950000000,,5,0,1,0,149.740000000,,10,0,1,0,149.000000000,,5,0,1,0,PEP
2025-01-03T10:31:35.955931306Z,2025-01-03T10:31:35.955765234Z,10,2,10888,C,A,1,421.310000000,15,130,166072,4884808,421.000000000,421.300000000,20,200,1,1,420.670000000,421.460000000,15,39,1,1,420.600000000,421.490000000,200,6,1,1,420.580000000,421.570000000,10,40,1,1,420.520000000,421.600000000,1,10,1,1,420.400000000,421.700000000,858,359,1,1,420.380000000,421.800000000,100,7,1,1,420.100000000,422.100000000,100,7,1,1,420.000000000,422.400000000,34,500,6,1,419.730000000,422.500000000,3,200,1,1,MSFT
2025-01-03T10:31:35.955989281Z,2025-01-03T10:31:35.955822991Z,10,2,10888,A,A,0,421.300000000,13,130,166290,4884809,421.000000000,421.300000000,20,213,1,2,420.670000000,421.460000000,15,39,1,1,420.600000000,421.490000000,200,6,1,1,420.580000000,421.570000000,10,40,1,1,420.520000000,421.600000000,1,10,1,1,420.400000000,421.700000000,858,359,1,1,420.380000000,421.800000000,100,7,1,1,420.100000000,422.100000000,100,7,1,1,420.000000000,422.400000000,34,500,6,1,419.730000000,422.500000000,3,200,1,1,MSFT
2025-01-03T10:31:35.960979168Z,2025-01-03T10:31:35.960813204Z,10,2,10888,C,B,1,420.670000000,15,130,165964,4884810,421.000000000,421.300000000,20,213,1,2,420.600000000,421.460000000,200,39,1,1,420.580000000,421.490000000,10,6,1,1,420.520000000,421.570000000,1,40,1,1,420.400000000,421.600000000,858,10,1,1,420.380000000,421.700000000,100,359,1,1,420.100000000,421.800000000,100,7,1,1,420.000000000,422.100000000,34,7,6,1,419.730000000,422.400000000,3,500,1,1,419.650000000,422.500000000,39,200,1,1,MSFT
2025-01-03T10:31:35.961036736Z,2025-01-03T10:31:35.960870351Z,10,2,10888,A,B,1,420.690000000,13,130,166385,4884811,421.000000000,421.300000000,20,213,1,2,420.690000000,421.460000000,13,39,1,1,420.600000000,421.490000000,200,6,1,1,420.580000000,421.570000000,10,40,1,1,420.520000000,421.600000000,1,10,1,1,420.400000000,421.700000000,858,359,1,1,420.380000000,421.800000000,100,7,1,1,420.100000000,422.100000000,100,7,1,1,420.000000000,422.400000000,34,500,6,1,419.730000000,422.500000000,3,200,1,1,MSFT
2025-01-03T10:31:35.966967623Z,2025-01-03T10:31:35.966801308Z,10,2,11667,A,B,5,139.070000000,400,130,166315,4884819,139.160000000,139.180000000,100,103,1,2,139.130000000,139.200000000,2200,529,2,2,139.120000000,139.220000000,30,110,1,2,139.110000000,139.230000000,1,25,1,1,139.080000000,139.250000000,57,1,1,1,139.070000000,139.270000000,500,37,2,2,139.030000000,139.300000000,126,507,2,4,139.010000000,139.320000000,100,39,1,1,139.000000000,139.330000000,420,503,5,2,138.980000000,139.360000000,300,4,1,2,NVDA
2025-01-03T10:31:35.977968753Z,2025-01-03T10:31:35.977802390Z,10,2,11667,A,B,4,139.100000000,400,130,166363,4884851,139.160000000,139.180000000,100,103,1,2,139.130000000,139.200000000,2200,529,2,2,139.120000000,139.220000000,30,110,1,2,139.110000000,139.230000000,1,25,1,1,139.100000000,139.250000000,400,1,1,1,139.080000000,139.270000000,57,37,1,2,139.070000000,139.300000000,100,507,1,4,139.030000000,139.320000000,126,39,2,1,139.010000000,139.330000000,100,503,1,2,139.000000000,139.360000000,420,4,5,2,NVDA
2025-01-03T10:31:35.977995947Z,2025-01-03T10:31:35.977830012Z,10,2,11667,C,A,0,139.180000000,100,130,165935,4884852,139.160000000,139.180000000,100,3,1,1,139.130000000,139.200000000,2200,529,2,2,139.120000000,139.220000000,30,110,1,2,139.110000000,139.230000000,1,25,1,1,139.100000000,139.250000000,400,1,1,1,139.080000000,139.270000000,57,37,1,2,139.070000000,139.300000000,100,507,1,4,139.030000000,139.320000000,126,39,2,1,139.010000000,139.330000000,100,503,1,2,139.000000000,139.360000000,420,4,5,2,NVDA
2025-01-03T10:31:35.994212402Z,2025-01-03T10:31:35.994046001Z,10,2,10888,A,B,2,420.610000000,200,130,166401,4884858,421.000000000,421.300000000,20,213,1,2,420.690000000,421.460000000,13,39,1,1,420.610000000,421.490000000,200,6,1,1,420.580000000,421.570000000,10,40,1,1,420.520000000,421.600000000,1,10,1,1,420.400000000,421.700000000,858,359,1,1,420.380000000,421.800000000,100,7,1,1,420.100000000,422.100000000,100,7,1,1,420.000000000,422.400000000,34,500,6,1,419.730000000,422.500000000,3,200,1,1,MSFT
2025-01-03T10:31:36.014213318Z,2025-01-03T10:31:36.014046977Z,10,2,10888,A,B,2,420.640000000,200,130,166341,4884882,421.000000000,421.300000000,20,213,1,2,420.690000000,421.460000000,13,39,1,1,420.640000000,421.490000000,200,6,1,1,420.580000000,421.570000000,10,40,1,1,420.520000000,421.600000000,1,10,1,1,420.400000000,421.700000000,858,359,1,1,420.380000000,421.800000000,100,7,1,1,420.100000000,422.100000000,100,7,1,1,420.000000000,422.400000000,34,500,6,1,419.730000000,422.500000000,3,200,1,1,MSFT
2025-01-03T10:31:36.210344757Z,2025-01-03T10:31:36.210177667Z,10,2,10888,A,A,0,421.290000000,200,130,167090,4885101,421.000000000,421.290000000,20,200,1,1,420.690000000,421.300000000,13,13,1,1,420.640000000,421.460000000,200,39,1,1,420.580000000,421.490000000,10,6,1,1,420.520000000,421.570000000,1,40,1,1,420.400000000,421.600000000,858,10,1,1,420.380000000,421.700000000,100,359,1,1,420.100000000,421.800000000,100,7,1,1,420.000000000,422.100000000,34,7,6,1,419.730000000,422.400000000,3,500,1,1,MSFT
2025-01-03T10:31:36.211030360Z,2025-01-03T10:31:36.210864077Z,10,2,11667,A,A,1,139.190000000,400,130,166283,4885105,139.160000000,139.180000000,100,3,1,1,139.130000000,139.190000000,2200,400,2,1,139.120000000,139.200000000,30,129,1,1,139.110000000,139.220000000,1,110,1,2,139.100000000,139.230000000,400,25,1,1,139.080000000,139.250000000,57,1,1,1,139.070000000,139.270000000,100,37,1,2,139.030000000,139.300000000,126,507,2,4,139.010000000,139.320000000,100,39,1,1,139.000000000,139.330000000,420,503,5,2,NVDA
2025-01-03T10:31:36.219212617Z,2025-01-03T10:31:36.219046445Z,10,2,38,C,A,2,243.690000000,200,130,166172,4885113,243.500000000,243.640000000,6,54,1,1,243.450000000,243.650000000,400,61,1,2,243.380000000,243.750000000,27,30,1,1,243.190000000,244.000000000,2,1,1,1,243.020000000,244.140000000,79,79,1,1,243.000000000,244.200000000,1243,1000,9,1,242.990000000,244.400000000,1,50,1,1,242.800000000,244.420000000,30,10,1,1,242.750000000,244.580000000,30,100,1,1,242.590000000,245.000000000,5,79,1,2,AAPL
2025-01-03T10:31:36.219226000Z,2025-01-03T10:31:36.219059543Z,10,2,38,A,A,2,243.710000000,400,130,166457,4885114,243.500000000,243.640000000,6,54,1,1,243.450000000,243.650000000,400,61,1,2,243.380000000,243.710000000,27,400,1,1,243.190000000,243.750000000,2,30,1,1,243.020000000,244.000000000,79,1,1,1,243.000000000,244.140000000,1243,79,9,1,242.990000000,244.200000000,1,1000,1,1,242.800000000,244.400000000,30,50,1,1,242.750000000,244.420000000,30,10,1,1,242.590000000,244.580000000,5,100,1,1,AAPL
2025-01-03T10:31:36.219563798Z,2025-01-03T10:31:36.219397274Z,10,2,38,C,A,2,243.710000000,400,130,166524,4885115,243.500000000,243.640000000,6,54,1,1,243.450000000,243.650000000,400,61,1,2,243.380000000,243.750000000,27,30,1,1,243.190000000,244.000000000,2,1,1,1,243.020000000,244.140000000,79,79,1,1,243.000000000,244.200000000,1243,1000,9,1,242.990000000,244.400000000,1,50,1,1,242.800000000,244.420000000,30,10,1,1,242.750000000,244.580000000,30,100,1,1,242.590000000,245.000000000,5,79,1,2,AAPL
2025-01-03T10:31:36.219575049Z,2025-01-03T10:31:36.219408787Z,10,2,38,A,A,2,243.720000000,200,130,166262,4885116,243.500000000,243.640000000,6,54,1,1,243.450000000,243.650000000,400,61,1,2,243.380000000,243.720000000,27,200,1,1,243.190000000,243.750000000,2,30,1,1,243.020000000,244.000000000,79,1,1,1,243.000000000,244.140000000,1243,79,9,1,242.990000000,244.200000000,1,1000,1,1,242.800000000,244.400000000,30,50,1,1,242.750000000,244.420000000,30,10,1,1,242.590000000,244.580000000,5,100,1,1,AAPL
2025-01-03T10:31:36.224382731Z,2025-01-03T10:31:36.224216438Z,10,2,38,C,A,3,243.750000000,30,130,166293,4885119,243.500000000,243.640000000,6,54,1,1,243.450000000,243.650000000,400,61,1,2,243.380000000,243.720000000,27,200,1,1,243.190000000,244.000000000,2,1,1,1,243.020000000,244.140000000,79,79,1,1,243.000000000,244.200000000,1243,1000,9,1,242.990000000,244.400000000,1,50,1,1,242.800000000,244.420000000,30,10,1,1,242.750000000,244.580000000,30,100,1,1,242.590000000,245.000000000,5,79,1,2,AAPL
2025-01-03T10:31:36.224475182Z,2025-01-03T10:31:36.224308866Z,10,2,38,A,A,3,243.790000000,29,130,166316,4885120,243.500000000,243.640000000,6,54,1,1,243.450000000,243.650000000,400,61,1,2,243.380000000,243.720000000,27,200,1,1,243.190000000,243.790000000,2,29,1,1,243.020000000,244.000000000,79,1,1,1,243.000000000,244.140000000,1243,79,9,1,242.990000000,244.200000000,1,1000,1,1,242.800000000,244.400000000,30,50,1,1,242.750000000,244.420000000,30,10,1,1,242.590000000,244.580000000,5,100,1,1,AAPL
2025-01-03T10:31:36.273147311Z,2025-01-03T10:31:36.272980720Z,10,2,10888,A,A,0,421.290000000,14,130,166591,4885208,421.000000000,421.290000000,20,214,1,2,420.690000000,421.300000000,13,13,1,1,420.640000000,421.460000000,200,39,1,1,420.580000000,421.490000000,10,6,1,1,420.520000000,421.570000000,1,40,1,1,420.400000000,421.600000000,858,10,1,1,420.380000000,421.700000000,100,359,1,1,420.100000000,421.800000000,100,7,1,1,420.000000000,422.100000000,34,7,6,1,419.730000000,422.400000000,3,500,1,1,MSFT
2025-01-03T10:31:36.363376579Z,2025-01-03T10:31:36.363209738Z,10,2,10888,A,B,2,420.660000000,200,130,166841,4885313,421.000000000,421.290000000,20,214,1,2,420.690000000,421.300000000,13,13,1,1,420.660000000,421.460000000,200,39,1,1,420.580000000,421.490000000,10,6,1,1,420.520000000,421.570000000,1,40,1,1,420.400000000,421.600000000,858,10,1,1,420.380000000,421.700000000,100,359,1,1,420.100000000,421.800000000,100,7,1,1,420.000000000,422.100000000,34,7,6,1,419.730000000,422.400000000,3,500,1,1,MSFT
2025-01-03T10:31:36.372492194Z,2025-01-03T10:31:36.372326053Z,10,2,9155,C,B,1,241.490000000,8,130,166141,4885315,241.670000000,242.070000000,2,62,1,1,241.120000000,242.400000000,81,8,1,1,241.000000000,242.850000000,100,300,1,2,240.000000000,242.900000000,10,100,1,1,238.000000000,243.000000000,30,92,1,2,236.000000000,243.310000000,6,10,1,1,235.500000000,243.700000000,5,100,1,1,235.000000000,246.810000000,5,100,1,1,232.880000000,262.740000000,1,100,1,1,231.110000000,263.830000000,3,100,1,1,JPM
2025-01-03T10:31:36.435446548Z,2025-01-03T10:31:36.435280333Z,10,2,9155,C,A,1,242.400000000,8,130,166215,4885344,241.670000000,242.070000000,2,62,1,1,241.120000000,242.850000000,81,300,1,2,241.000000000,242.900000000,100,100,1,1,240.000000000,243.000000000,10,92,1,2,238.000000000,243.310000000,30,10,1,1,236.000000000,243.700000000,6,100,1,1,235.500000000,246.810000000,5,100,1,1,235.000000000,262.740000000,5,100,1,1,232.880000000,263.830000000,1,100,1,1,231.110000000,,3,0,1,0,JPM
2025-01-03T10:31:36.435510111Z,2025-01-03T10:31:36.435343991Z,10,2,9155,A,A,1,242.390000000,8,130,166120,4885345,241.670000000,242.070000000,2,62,1,1,241.120000000,242.390000000,81,8,1,1,241.000000000,242.850000000,100,300,1,2,240.000000000,242.900000000,10,100,1,1,238.000000000,243.000000000,30,92,1,2,236.000000000,243.310000000,6,10,1,1,235.500000000,243.700000000,5,100,1,1,235.000000000,246.810000000,5,100,1,1,232.880000000,262.740000000,1,100,1,1,231.110000000,263.830000000,3,100,1,1,JPM
2025-01-03T10:31:36.498422275Z,2025-01-03T10:31:36.498255917Z,10,2,9155,A,B,1,241.570000000,8,130,166358,4885370,241.670000000,242.070000000,2,62,1,1,241.570000000,242.390000000,8,8,1,1,241.120000000,242.850000000,81,300,1,2,241.000000000,242.900000000,100,100,1,1,240.000000000,243.000000000,10,92,1,2,238.000000000,243.310000000,30,10,1,1,236.000000000,243.700000000,6,100,1,1,235.500000000,246.810000000,5,100,1,1,235.000000000,262.740000000,5,100,1,1,232.880000000,263.830000000,1,100,1,1,JPM
2025-01-03T10:31:36.738365723Z,2025-01-03T10:31:36.738198952Z,10,2,780,A,A,0,260.780000000,25,130,166771,4885594,259.010000000,260.780000000,175,25,1,1,258.910000000,294.170000000,25,100,1,1,258.100000000,295.390000000,25,100,1,1,257.700000000,,1,0,1,0,255.920000000,,1,0,1,0,250.000000000,,13,0,2,0,236.860000000,,100,0,1,0,235.690000000,,100,0,1,0,,,0,0,0,0,,,0,0,0,0,AMGN
2025-01-03T10:31:37.212333489Z,2025-01-03T10:31:37.212167320Z,10,2,11667,A,A,0,139.180000000,100,130,166169,4885988,139.160000000,139.180000000,100,103,1,2,139.130000000,139.190000000,2200,400,2,1,139.120000000,139.200000000,30,129,1,1,139.110000000,139.220000000,1,110,1,2,139.100000000,139.230000000,400,25,1,1,139.080000000,139.250000000,57,1,1,1,139.070000000,139.270000000,100,37,1,2,139.030000000,139.300000000,126,507,2,4,139.010000000,139.320000000,100,39,1,1,139.000000000,139.330000000,420,503,5,2,NVDA
2025-01-03T10:31:37.216385165Z,2025-01-03T10:31:37.216216018Z,10,2,10888,T,A,0,421.000000000,20,0,169147,4886048,421.000000000,421.290000000,20,214,1,2,420.690000000,421.300000000,13,13,1,1,420.660000000,421.460000000,200,39,1,1,420.580000000,421.490000000,10,6,1,1,420.520000000,421.570000000,1,40,1,1,420.400000000,421.600000000,858,10,1,1,420.380000000,421.700000000,100,359,1,1,420.100000000,421.800000000,100,7,1,1,420.000000000,422.100000000,34,7,6,1,419.730000000,422.400000000,3,500,1,1,MSFT
2025-01-03T10:31:37.216385165Z,2025-01-03T10:31:37.216216018Z,10,2,10888,T,N,0,421.000000000,8,128,169147,4886049,420.690000000,421.290000000,13,214,1,2,420.660000000,421.300000000,200,13,1,1,420.580000000,421.460000000,10,39,1,1,420.520000000,421.490000000,1,6,1,1,420.400000000,421.570000000,858,40,1,1,420.380000000,421.600000000,100,10,1,1,420.100000000,421.700000000,100,359,1,1,420.000000000,421.800000000,34,7,6,1,419.730000000,422.100000000,3,7,1,1,419.650000000,422.400000000,39,500,1,1,MSFT
2025-01-03T10:31:37.216403907Z,2025-01-03T10:31:37.216237751Z,10,2,10888,A,A,0,421.280000000,32,130,166156,4886051,420.690000000,421.280000000,13,32,1,1,420.660000000,421.290000000,200,214,1,2,420.580000000,421.300000000,10,13,1,1,420.520000000,421.460000000,1,39,1,1,420.400000000,421.490000000,858,6,1,1,420.380000000,421.570000000,100,40,1,1,420.100000000,421.600000000,100,10,1,1,420.000000000,421.700000000,34,359,6,1,419.730000000,421.800000000,3,7,1,1,419.650000000,422.100000000,39,7,1,1,MSFT
2025-01-03T10:31:37.216410373Z,2025-01-03T10:31:37.216243188Z,10,2,10888,A,A,0,421.150000000,32,130,167185,4886052,420.690000000,421.150000000,13,32,1,1,420.660000000,421.280000000,200,32,1,1,420.580000000,421.290000000,10,214,1,2,420.520000000,421.300000000,1,13,1,1,420.400000000,421.460000000,858,39,1,1,420.380000000,421.490000000,100,6,1,1,420.100000000,421.570000000,100,40,1,1,420.000000000,421.600000000,34,10,6,1,419.730000000,421.700000000,3,359,1,1,419.650000000,421.800000000,39,7,1,1,MSFT
2025-01-03T10:31:37.216422872Z,2025-01-03T10:31:37.216256940Z,10,2,10888,A,A,1,421.240000000,32,130,165932,4886053,420.690000000,421.150000000,13,32,1,1,420.660000000,421.240000000,200,32,1,1,420.580000000,421.280000000,10,32,1,1,420.520000000,421.290000000,1,214,1,2,420.400000000,421.300000000,858,13,1,1,420.380000000,421.460000000,100,39,1,1,420.100000000,421.490000000,100,6,1,1,420.000000000,421.570000000,34,40,6,1,419.730000000,421.600000000,3,10,1,1,419.650000000,421.700000000,39,359,1,1,MSFT
2025-01-03T10:31:37.216446286Z,2025-01-03T10:31:37.216279049Z,10,2,10888,A,A,2,421.280000000,82,130,167237,4886055,420.690000000,421.150000000,13,32,1,1,420.660000000,421.240000000,200,32,1,1,420.580000000,421.280000000,10,114,1,2,420.520000000,421.290000000,1,214,1,2,420.400000000,421.300000000,858,13,1,1,420.380000000,421.460000000,100,39,1,1,420.100000000,421.490000000,100,6,1,1,420.000000000,421.570000000,34,40,6,1,419.730000000,421.600000000,3,10,1,1,419.650000000,421.700000000,39,359,1,1,MSFT
2025-01-03T10:31:37.216503662Z,2025-01-03T10:31:37.216337919Z,10,2,10888,C,B,1,420.660000000,200,130,165743,4886058,420.690000000,421.150000000,13,32,1,1,420.580000000,421.240000000,10,32,1,1,420.520000000,421.280000000,1,114,1,2,420.400000000,421.290000000,858,214,1,2,420.380000000,421.300000000,100,13,1,1,420.100000000,421.460000000,100,39,1,1,420.000000000,421.490000000,34,6,6,1,419.730000000,421.570000000,3,40,1,1,419.650000000,421.600000000,39,10,1,1,419.600000000,421.700000000,500,359,1,1,MSFT
2025-01-03T10:31:37.226886341Z,2025-01-03T10:31:37.226720064Z,10,2,10888,C,A,1,421.240000000,32,130,166277,4886118,420.690000000,421.150000000,13,32,1,1,420.580000000,421.280000000,10,114,1,2,420.520000000,421.290000000,1,214,1,2,420.400000000,421.300000000,858,13,1,1,420.380000000,421.460000000,100,39,1,1,420.100000000,421.490000000,100,6,1,1,420.000000000,421.570000000,34,40,6,1,419.730000000,421.600000000,3,10,1,1,419.650000000,421.700000000,39,359,1,1,419.600000000,421.800000000,500,7,1,1,MSFT
2025-01-03T10:31:37.226904881Z,2025-01-03T10:31:37.226739085Z,10,2,10888,C,A,0,421.150000000,32,130,165796,4886119,420.690000000,421.280000000,13,114,1,2,420.580000000,421.290000000,10,214,1,2,420.520000000,421.300000000,1,13,1,1,420.400000000,421.460000000,858,39,1,1,420.380000000,421.490000000,100,6,1,1,420.100000000,421.570000000,100,40,1,1,420.000000000,421.600000000,34,10,6,1,419.730000000,421.700000000,3,359,1,1,419.650000000,421.800000000,39,7,1,1,419.600000000,422.100000000,500,7,1,1,MSFT
2025-01-03T10:31:37.279170761Z,2025-01-03T10:31:37.279004836Z,10,2,10888,C,A,1,421.290000000,14,130,165925,4886179,420.690000000,421.280000000,13,114,1,2,420.580000000,421.290000000,10,200,1,1,420.520000000,421.300000000,1,13,1,1,420.400000000,421.460000000,858,39,1,1,420.380000000,421.490000000,100,6,1,1,420.100000000,421.570000000,100,40,1,1,420.000000000,421.600000000,34,10,6,1,419.730000000,421.700000000,3,359,1,1,419.650000000,421.800000000,39,7,1,1,419.600000000,422.100000000,500,7,1,1,MSFT
2025-01-03T10:31:37.279199888Z,2025-01-03T10:31:37.279034050Z,10,2,10888,C,A,2,421.300000000,13,130,165838,4886180,420.690000000,421.280000000,13,114,1,2,420.580000000,421.290000000,10,200,1,1,420.520000000,421.460000000,1,39,1,1,420.400000000,421.490000000,858,6,1,1,420.380000000,421.570000000,100,40,1,1,420.100000000,421.600000000,100,10,1,1,420.000000000,421.700000000,34,359,6,1,419.730000000,421.800000000,3,7,1,1,419.650000000,422.100000000,39,7,1,1,419.600000000,422.400000000,500,500,1,1,MSFT
2025-01-03T10:31:37.279297363Z,2025-01-03T10:31:37.279131042Z,10,2,10888,A,A,1,421.290000000,14,130,166321,4886181,420.690000000,421.280000000,13,114,1,2,420.580000000,421.290000000,10,214,1,2,420.520000000,421.460000000,1,39,1,1,420.400000000,421.490000000,858,6,1,1,420.380000000,421.570000000,100,40,1,1,420.100000000,421.600000000,100,10,1,1,420.000000000,421.700000000,34,359,6,1,419.730000000,421.800000000,3,7,1,1,419.650000000,422.100000000,39,7,1,1,419.600000000,422.400000000,500,500,1,1,MSFT
2025-01-03T10:31:37.279440568Z,2025-01-03T10:31:37.279274531Z,10,2,38,C,A,3,243.790000000,29,130,166037,4886182,243.500000000,243.640000000,6,54,1,1,243.450000000,243.650000000,400,61,1,2,243.380000000,243.720000000,27,200,1,1,243.190000000,244.000000000,2,1,1,1,243.020000000,244.140000000,79,79,1,1,243.000000000,244.200000000,1243,1000,9,1,242.990000000,244.400000000,1,50,1,1,242.800000000,244.420000000,30,10,1,1,242.750000000,244.580000000,30,100,1,1,242.590000000,245.000000000,5,79,1,2,AAPL
2025-01-03T10:31:37.279532352Z,2025-01-03T10:31:37.279365722Z,10,2,38,A,A,3,243.730000000,29,130,166630,4886183,243.500000000,243.640000000,6,54,1,1,243.450000000,243.650000000,400,61,1,2,243.380000000,243.720000000,27,200,1,1,243.190000000,243.730000000,2,29,1,1,243.020000000,244.000000000,79,1,1,1,243.000000000,244.140000000,1243,79,9,1,242.990000000,244.200000000,1,1000,1,1,242.800000000,244.400000000,30,50,1,1,242.750000000,244.420000000,30,10,1,1,242.590000000,244.580000000,5,100,1,1,AAPL
2025-01-03T10:31:37.289193525Z,2025-01-03T10:31:37.289027791Z,10,2,10888,C,B,0,420.690000000,13,130,165734,4886255,420.580000000,421.280000000,10,114,1,2,420.520000000,421.290000000,1,214,1,2,420.400000000,421.460000000,858,39,1,1,420.380000000,421.490000000,100,6,1,1,420.100000000,421.570000000,100,40,1,1,420.000000000,421.600000000,34,10,6,1,419.730000000,421.700000000,3,359,1,1,419.650000000,421.800000000,39,7,1,1,419.600000000,422.100000000,500,7,1,1,418.650000000,422.400000000,1,500,1,1,MSFT
2025-01-03T10:31:37.289251422Z,2025-01-03T10:31:37.289085277Z,10,2,10888,A,B,0,420.580000000,15,130,166145,4886256,420.580000000,421.280000000,25,114,2,2,420.520000000,421.290000000,1,214,1,2,420.400000000,421.460000000,858,39,1,1,420.380000000,421.490000000,100,6,1,1,420.100000000,421.570000000,100,40,1,1,420.000000000,421.600000000,34,10,6,1,419.730000000,421.700000000,3,359,1,1,419.650000000,421.800000000,39,7,1,1,419.600000000,422.100000000,500,7,1,1,418.650000000,422.400000000,1,500,1,1,MSFT
2025-01-03T10:31:37.334197734Z,2025-01-03T10:31:37.334031274Z,10,2,38,A,A,2,243.690000000,200,130,166460,4886348,243.500000000,243.640000000,6,54,1,1,243.450000000,243.650000000,400,61,1,2,243.380000000,243.690000000,27,200,1,1,243.190000000,243.730000000,2,29,1,1,243.020000000,244.000000000,79,1,1,1,243.000000000,244.140000000,1243,79,9,1,242.990000000,244.200000000,1,1000,1,1,242.800000000,244.400000000,30,50,1,1,242.750000000,244.420000000,30,10,1,1,242.590000000,244.580000000,5,100,1,1,AAPL
2025-01-03T10:31:37.339537160Z,2025-01-03T10:31:37.339370587Z,10,2,10888,A,B,1,420.550000000,200,130,166573,4886362,420.580000000,421.280000000,25,114,2,2,420.550000000,421.290000000,200,214,1,2,420.520000000,421.460000000,1,39,1,1,420.400000000,421.490000000,858,6,1,1,420.380000000,421.570000000,100,40,1,1,420.100000000,421.600000000,100,10,1,1,420.000000000,421.700000000,34,359,6,1,419.730000000,421.800000000,3,7,1,1,419.650000000,422.100000000,39,7,1,1,419.600000000,422.400000000,500,500,1,1,MSFT
2025-01-03T10:31:37.358215814Z,2025-01-03T10:31:37.358049606Z,10,2,10888,C,B,1,420.550000000,200,130,166208,4886378,420.580000000,421.280000000,25,114,2,2,420.520000000,421.290000000,1,214,1,2,420.400000000,421.460000000,858,39,1,1,420.380000000,421.490000000,100,6,1,1,420.100000000,421.570000000,100,40,1,1,420.000000000,421.600000000,34,10,6,1,419.730000000,421.700000000,3,359,1,1,419.650000000,421.800000000,39,7,1,1,419.600000000,422.100000000,500,7,1,1,418.650000000,422.400000000,1,500,1,1,MSFT
2025-01-03T10:31:37.358228973Z,2025-01-03T10:31:37.358062747Z,10,2,10888,A,B,1,420.520000000,200,130,166226,4886379,420.580000000,421.280000000,25,114,2,2,420.520000000,421.290000000,201,214,2,2,420.400000000,421.460000000,858,39,1,1,420.380000000,421.490000000,100,6,1,1,420.100000000,421.570000000,100,40,1,1,420.000000000,421.600000000,34,10,6,1,419.730000000,421.700000000,3,359,1,1,419.650000000,421.800000000,39,7,1,1,419.600000000,422.100000000,500,7,1,1,418.650000000,422.400000000,1,500,1,1,MSFT
2025-01-03T10:31:37.372346714Z,2025-01-03T10:31:37.372180850Z,10,2,9155,C,B,1,241.570000000,8,130,165864,4886389,241.670000000,242.070000000,2,62,1,1,241.120000000,242.390000000,81,8,1,1,241.000000000,242.850000000,100,300,1,2,240.000000000,242.900000000,10,100,1,1,238.000000000,243.000000000,30,92,1,2,236.000000000,243.310000000,6,10,1,1,235.500000000,243.700000000,5,100,1,1,235.000000000,246.810000000,5,100,1,1,232.880000000,262.740000000,1,100,1,1,231.110000000,263.830000000,3,100,1,1,JPM
2025-01-03T10:31:37.408546737Z,2025-01-03T10:31:37.408380286Z,10,2,10888,A,A,0,421.250000000,200,130,166451,4886413,420.580000000,421.250000000,25,200,2,1,420.520000000,421.280000000,201,114,2,2,420.400000000,421.290000000,858,14,1,1,420.380000000,421.460000000,100,39,1,1,420.100000000,421.490000000,100,6,1,1,420.000000000,421.570000000,34,40,6,1,419.730000000,421.600000000,3,10,1,1,419.650000000,421.700000000,39,359,1,1,419.600000000,421.800000000,500,7,1,1,418.650000000,422.100000000,1,7,1,1,MSFT
2025-01-03T10:31:37.742343890Z,2025-01-03T10:31:37.742178221Z,10,2,16727,C,A,0,315.440000000,8,130,165669,4886694,314.890000000,315.510000000,8,25,1,1,314.860000000,315.750000000,25,61,1,1,314.420000000,320.000000000,61,5,1,1,313.500000000,320.210000000,1,1,1,1,310.000000000,321.950000000,1,2,1,1,300.000000000,344.200000000,3,100,1,1,290.000000000,345.620000000,2,100,1,1,286.660000000,,100,0,1,0,285.250000000,,100,0,1,0,260.000000000,,2,0,1,0,V
2025-01-03T10:31:37.742429356Z,2025-01-03T10:31:37.742263026Z,10,2,16727,A,A,0,315.430000000,8,130,166330,4886695,314.890000000,315.430000000,8,8,1,1,314.860000000,315.510000000,25,25,1,1,314.420000000,315.750000000,61,61,1,1,313.500000000,320.000000000,1,5,1,1,310.000000000,320.210000000,1,1,1,1,300.000000000,321.950000000,3,2,1,1,290.000000000,344.200000000,2,100,1,1,286.660000000,345.620000000,100,100,1,1,285.250000000,,100,0,1,0,260.000000000,,2,0,1,0,V
2025-01-03T10:31:37.801617722Z,2025-01-03T10:31:37.801451300Z,10,2,10888,A,B,1,420.530000000,200,130,166422,4886708,420.580000000,421.250000000,25,200,2,1,420.530000000,421.280000000,200,114,1,2,420.520000000,421.290000000,1,14,1,1,420.400000000,421.460000000,858,39,1,1,420.380000000,421.490000000,100,6,1,1,420.100000000,421.570000000,100,40,1,1,420.000000000,421.600000000,34,10,6,1,419.730000000,421.700000000,3,359,1,1,419.650000000,421.800000000,39,7,1,1,419.600000000,422.100000000,500,7,1,1,MSFT
2025-01-03T10:31:37.817888695Z,2025-01-03T10:31:37.817722840Z,10,2,17709,C,A,2,107.900000000,16,130,165855,4886720,107.600000000,107.840000000,50,400,1,2,107.530000000,107.870000000,16,242,1,1,107.520000000,107.940000000,100,100,1,1,107.050000000,107.950000000,247,10,1,1,107.000000000,108.000000000,1,50,1,1,106.240000000,108.300000000,28,50,1,1,106.000000000,108.550000000,15,50,2,1,105.870000000,108.800000000,141,50,1,1,103.180000000,108.880000000,16,28,1,1,103.000000000,109.000000000,3,100,1,1,XOM
2025-01-03T10:31:37.817945745Z,2025-01-03T10:31:37.817779408Z,10,2,17709,A,A,1,107.870000000,16,130,166337,4886721,107.600000000,107.840000000,50,400,1,2,107.530000000,107.870000000,16,258,1,2,107.520000000,107.940000000,100,100,1,1,107.050000000,107.950000000,247,10,1,1,107.000000000,108.000000000,1,50,1,1,106.240000000,108.300000000,28,50,1,1,106.000000000,108.550000000,15,50,2,1,105.870000000,108.800000000,141,50,1,1,103.180000000,108.880000000,16,28,1,1,103.000000000,109.000000000,3,100,1,1,XOM
2025-01-03T10:31:37.825286515Z,2025-01-03T10:31:37.825118680Z,10,2,16244,T,A,0,383.100000000,20,0,167835,4886729,383.100000000,383.420000000,40,140,2,1,383.090000000,383.480000000,3,30,1,1,383.060000000,383.500000000,23,20,1,1,383.000000000,383.530000000,13,20,2,1,382.810000000,383.600000000,20,1000,2,2,382.700000000,383.720000000,50,7085,1,8,382.680000000,383.740000000,20,37,1,1,382.400000000,383.800000000,500,10,1,1,382.230000000,383.880000000,25,4,1,1,382.110000000,384.000000000,300,1300,1,4,TSLA
2025-01-03T10:31:37.825286515Z,2025-01-03T10:31:37.825118680Z,10,2,16244,T,A,0,383.100000000,20,130,167835,4886730,383.100000000,383.420000000,20,140,1,1,383.090000000,383.480000000,3,30,1,1,383.060000000,383.500000000,23,20,1,1,383.000000000,383.530000000,13,20,2,1,382.810000000,383.600000000,20,1000,2,2,382.700000000,383.720000000,50,7085,1,8,382.680000000,383.740000000,20,37,1,1,382.400000000,383.800000000,500,10,1,1,382.230000000,383.880000000,25,4,1,1,382.110000000,384.000000000,300,1300,1,4,TSLA
2025-01-03T10:31:37.825286515Z,2025-01-03T10:31:37.825118680Z,10,2,16244,C,B,0,383.100000000,20,130,167835,4886730,383.090000000,383.420000000,3,140,1,1,383.060000000,383.480000000,23,30,1,1,383.000000000,383.500000000,13,20,2,1,382.810000000,383.530000000,20,20,2,1,382.700000000,383.600000000,50,1000,1,2,382.680000000,383.720000000,20,7085,1,8,382.400000000,383.740000000,500,37,1,1,382.230000000,383.800000000,25,10,1,1,382.110000000,383.880000000,300,4,1,1,382.100000000,384.000000000,20,1300,2,4,TSLA
2025-01-03T10:31:37.825308623Z,2025-01-03T10:31:37.825140680Z,10,2,16244,A,A,0,383.410000000,5,130,167943,4886731,383.090000000,383.410000000,3,5,1,1,383.060000000,383.420000000,23,140,1,1,383.000000000,383.480000000,13,30,2,1,382.810000000,383.500000000,20,20,2,1,382.700000000,383.530000000,50,20,1,1,382.680000000,383.600000000,20,1000,1,2,382.400000000,383.720000000,500,7085,1,8,382.230000000,383.740000000,25,37,1,1,382.110000000,383.800000000,300,10,1,1,382.100000000,383.880000000,20,4,2,1,TSLA
2025-01-03T10:31:37.825311909Z,2025-01-03T10:31:37.825145721Z,10,2,16244,A,A,0,383.260000000,7,130,166188,4886732,383.090000000,383.260000000,3,7,1,1,383.060000000,383.410000000,23,5,1,1,383.000000000,383.420000000,13,140,2,1,382.810000000,383.480000000,20,30,2,1,382.700000000,383.500000000,50,20,1,1,382.680000000,383.530000000,20,20,1,1,382.400000000,383.600000000,500,1000,1,2,382.230000000,383.720000000,25,7085,1,8,382.110000000,383.740000000,300,37,1,1,382.100000000,383.800000000,20,10,2,1,TSLA
2025-01-03T10:31:37.825325872Z,2025-01-03T10:31:37.825159491Z,10,2,16244,A,A,1,383.360000000,7,130,166381,4886734,383.090000000,383.260000000,3,7,1,1,383.060000000,383.360000000,23,7,1,1,383.000000000,383.410000000,13,5,2,1,382.810000000,383.420000000,20,140,2,1,382.700000000,383.480000000,50,30,1,1,382.680000000,383.500000000,20,20,1,1,382.400000000,383.530000000,500,20,1,1,382.230000000,383.600000000,25,1000,1,2,382.110000000,383.720000000,300,7085,1,8,382.100000000,383.740000000,20,37,2,1,TSLA
2025-01-03T10:31:37.825347642Z,2025-01-03T10:31:37.825173579Z,10,2,16244,T,A,0,383.090000000,3,128,174063,4886737,383.090000000,383.260000000,3,7,1,1,383.060000000,383.360000000,23,7,1,1,383.000000000,383.410000000,13,5,2,1,382.810000000,383.420000000,20,140,2,1,382.700000000,383.480000000,50,30,1,1,382.680000000,383.500000000,20,20,1,1,382.400000000,383.530000000,500,20,1,1,382.230000000,383.600000000,25,1000,1,2,382.110000000,383.720000000,300,7085,1,8,382.100000000,383.740000000,20,37,2,1,TSLA
2025-01-03T10:31:37.825347642Z,2025-01-03T10:31:37.825173579Z,10,2,16244,C,B,0,383.090000000,3,128,174063,4886737,383.060000000,383.260000000,23,7,1,1,383.000000000,383.360000000,13,7,2,1,382.810000000,383.410000000,20,5,2,1,382.700000000,383.420000000,50,140,1,1,382.680000000,383.480000000,20,30,1,1,382.400000000,383.500000000,500,20,1,1,382.230000000,383.530000000,25,20,1,1,382.110000000,383.600000000,300,1000,1,2,382.100000000,383.720000000,20,7085,2,8,382.010000000,383.740000000,2,37,1,1,TSLA
2025-01-03T10:31:37.825349705Z,2025-01-03T10:31:37.825182295Z,10,2,16244,A,A,2,383.410000000,18,130,167410,4886739,383.060000000,383.260000000,23,7,1,1,383.000000000,383.360000000,13,7,2,1,382.810000000,383.410000000,20,23,2,2,382.700000000,383.420000000,50,140,1,1,382.680000000,383.480000000,20,30,1,1,382.400000000,383.500000000,500,20,1,1,382.230000000,383.530000000,25,20,1,1,382.110000000,383.600000000,300,1000,1,2,382.100000000,383.720000000,20,7085,2,8,382.010000000,383.740000000,2,37,1,1,TSLA
2025-01-03T10:31:37.825365096Z,2025-01-03T10:31:37.825197839Z,10,2,16244,A,A,0,383.180000000,7,130,167257,4886741,383.060000000,383.180000000,23,7,1,1,383.000000000,383.260000000,13,7,2,1,382.810000000,383.360000000,20,7,2,1,382.700000000,383.410000000,50,23,1,2,382.680000000,383.420000000,20,140,1,1,382.400000000,383.480000000,500,30,1,1,382.230000000,383.500000000,25,20,1,1,382.110000000,383.530000000,300,20,1,1,382.100000000,383.600000000,20,1000,2,2,382.010000000,383.720000000,2,7085,1,8,TSLA
2025-01-03T10:31:37.825376964Z,2025-01-03T10:31:37.825209948Z,10,2,16244,A,A,1,383.230000000,7,130,167016,4886742,383.060000000,383.180000000,23,7,1,1,383.000000000,383.230000000,13,7,2,1,382.810000000,383.260000000,20,7,2,1,382.700000000,383.360000000,50,7,1,1,382.680000000,383.410000000,20,23,1,2,382.400000000,383.420000000,500,140,1,1,382.230000000,383.480000000,25,30,1,1,382.110000000,383.500000000,300,20,1,1,382.100000000,383.530000000,20,20,2,1,382.010000000,383.600000000,2,1000,1,2,TSLA
2025-01-03T10:31:37.826024718Z,2025-01-03T10:31:37.825858457Z,10,2,16244,A,A,1,383.210000000,5,130,166261,4886770,383.060000000,383.180000000,23,7,1,1,383.000000000,383.210000000,13,5,2,1,382.810000000,383.230000000,20,7,2,1,382.700000000,383.260000000,50,7,1,1,382.680000000,383.360000000,20,7,1,1,382.400000000,383.410000000,500,23,1,2,382.230000000,383.420000000,25,140,1,1,382.110000000,383.480000000,300,30,1,1,382.100000000,383.500000000,20,20,2,1,382.010000000,383.530000000,2,20,1,1,TSLA
2025-01-03T10:31:37.835784144Z,2025-01-03T10:31:37.835618263Z,10,2,16244,C,A,4,383.360000000,7,130,165881,4886791,383.060000000,383.180000000,23,7,1,1,383.000000000,383.210000000,13,5,2,1,382.810000000,383.230000000,20,7,2,1,382.700000000,383.260000000,50,7,1,1,382.680000000,383.410000000,20,23,1,2,382.400000000,383.420000000,500,140,1,1,382.230000000,383.480000000,25,30,1,1,382.110000000,383.500000000,300,20,1,1,382.100000000,383.530000000,20,20,2,1,382.010000000,383.600000000,2,1000,1,2,TSLA
2025-01-03T10:31:37.835795495Z,2025-01-03T10:31:37.835629118Z,10,2,16244,C,A,2,383.230000000,7,130,166377,4886793,383.060000000,383.180000000,23,7,1,1,383.000000000,383.210000000,13,5,2,1,382.810000000,383.260000000,20,7,2,1,382.700000000,383.410000000,50,23,1,2,382.680000000,383.420000000,20,140,1,1,382.400000000,383.480000000,500,30,1,1,382.230000000,383.500000000,25,20,1,1,382.110000000,383.530000000,300,20,1,1,382.100000000,383.600000000,20,1000,2,2,382.010000000,383.720000000,2,7085,1,8,TSLA
2025-01-03T10:31:37.836353826Z,2025-01-03T10:31:37.836187274Z,10,2,16244,C,A,1,383.210000000,5,130,166552,4886799,383.060000000,383.180000000,23,7,1,1,383.000000000,383.260000000,13,7,2,1,382.810000000,383.410000000,20,23,2,2,382.700000000,383.420000000,50,140,1,1,382.680000000,383.480000000,20,30,1,1,382.400000000,383.500000000,500,20,1,1,382.230000000,383.530000000,25,20,1,1,382.110000000,383.600000000,300,1000,1,2,382.100000000,383.720000000,20,7085,2,8,382.010000000,383.740000000,2,37,1,1,TSLA
2025-01-03T10:31:37.836371519Z,2025-01-03T10:31:37.836205648Z,10,2,16244,C,A,1,383.260000000,7,130,165871,4886800,383.060000000,383.180000000,23,7,1,1,383.000000000,383.410000000,13,23,2,2,382.810000000,383.420000000,20,140,2,1,382.700000000,383.480000000,50,30,1,1,382.680000000,383.500000000,20,20,1,1,382.400000000,383.530000000,500,20,1,1,382.230000000,383.600000000,25,1000,1,2,382.110000000,383.720000000,300,7085,1,8,382.100000000,383.740000000,20,37,2,1,382.010000000,383.800000000,2,10,1,1,TSLA
2025-01-03T10:31:37.836381830Z,2025-01-03T10:31:37.836216106Z,10,2,16244,C,A,0,383.180000000,7,130,165724,4886801,383.060000000,383.410000000,23,23,1,2,383.000000000,383.420000000,13,140,2,1,382.810000000,383.480000000,20,30,2,1,382.700000000,383.500000000,50,20,1,1,382.680000000,383.530000000,20,20,1,1,382.400000000,383.600000000,500,1000,1,2,382.230000000,383.720000000,25,7085,1,8,382.110000000,383.740000000,300,37,1,1,382.100000000,383.800000000,20,10,2,1,382.010000000,383.880000000,2,4,1,1,TSLA
2025-01-03T10:31:37.888491661Z,2025-01-03T10:31:37.888325974Z,10,2,16244,C,A,4,383.530000000,20,130,165687,4886829,383.060000000,383.410000000,23,23,1,2,383.000000000,383.420000000,13,140,2,1,382.810000000,383.480000000,20,30,2,1,382.700000000,383.500000000,50,20,1,1,382.680000000,383.600000000,20,1000,1,2,382.400000000,383.720000000,500,7085,1,8,382.230000000,383.740000000,25,37,1,1,382.110000000,383.800000000,300,10,1,1,382.100000000,383.880000000,20,4,2,1,382.010000000,384.000000000,2,1300,1,4,TSLA
2025-01-03T10:31:37.888599785Z,2025-01-03T10:31:37.888433811Z,10,2,16244,A,A,3,383.500000000,23,130,165974,4886830,383.060000000,383.410000000,23,23,1,2,383.000000000,383.420000000,13,140,2,1,382.810000000,383.480000000,20,30,2,1,382.700000000,383.500000000,50,43,1,2,382.680000000,383.600000000,20,1000,1,2,382.400000000,383.720000000,500,7085,1,8,382.230000000,383.740000000,25,37,1,1,382.110000000,383.800000000,300,10,1,1,382.100000000,383.880000000,20,4,2,1,382.010000000,384.000000000,2,1300,1,4,TSLA
2025-01-03T10:31:37.892907802Z,2025-01-03T10:31:37.892742023Z,10,2,16244,C,B,0,383.060000000,23,130,165779,4886835,383.000000000,383.410000000,13,23,2,2,382.810000000,383.420000000,20,140,2,1,382.700000000,383.480000000,50,30,1,1,382.680000000,383.500000000,20,43,1,2,382.400000000,383.600000000,500,1000,1,2,382.230000000,383.720000000,25,7085,1,8,382.110000000,383.740000000,300,37,1,1,382.100000000,383.800000000,20,10,2,1,382.010000000,383.880000000,2,4,1,1,382.000000000,384.000000000,1192,1300,10,4,TSLA
2025-01-03T10:31:37.899115421Z,2025-01-03T10:31:37.898949234Z,10,2,16244,A,A,0,383.400000000,23,130,166187,4886845,383.000000000,383.400000000,13,23,2,1,382.810000000,383.410000000,20,23,2,2,382.700000000,383.420000000,50,140,1,1,382.680000000,383.480000000,20,30,1,1,382.400000000,383.500000000,500,43,1,2,382.230000000,383.600000000,25,1000,1,2,382.110000000,383.720000000,300,7085,1,8,382.100000000,383.740000000,20,37,2,1,382.010000000,383.800000000,2,10,1,1,382.000000000,383.880000000,1192,4,10,1,TSLA
2025-01-03T10:31:37.906692167Z,2025-01-03T10:31:37.906526411Z,10,2,16244,C,A,0,383.400000000,23,130,165756,4886851,383.000000000,383.410000000,13,23,2,2,382.810000000,383.420000000,20,140,2,1,382.700000000,383.480000000,50,30,1,1,382.680000000,383.500000000,20,43,1,2,382.400000000,383.600000000,500,1000,1,2,382.230000000,383.720000000,25,7085,1,8,382.110000000,383.740000000,300,37,1,1,382.100000000,383.800000000,20,10,2,1,382.010000000,383.880000000,2,4,1,1,382.000000000,384.000000000,1192,1300,10,4,TSLA
2025-01-03T10:31:38.216169250Z,2025-01-03T10:31:38.216003485Z,10,2,10888,C,A,1,421.280000000,82,130,165765,4886940,420.580000000,421.250000000,25,200,2,1,420.530000000,421.280000000,200,32,1,1,420.520000000,421.290000000,1,14,1,1,420.400000000,421.460000000,858,39,1,1,420.380000000,421.490000000,100,6,1,1,420.100000000,421.570000000,100,40,1,1,420.000000000,421.600000000,34,10,6,1,419.730000000,421.700000000,3,359,1,1,419.650000000,421.800000000,39,7,1,1,419.600000000,422.100000000,500,7,1,1,MSFT
2025-01-03T10:31:38.826168654Z,2025-01-03T10:31:38.826002612Z,10,2,16244,C,A,0,383.410000000,18,130,166042,4887100,383.000000000,383.410000000,13,5,2,1,382.810000000,383.420000000,20,140,2,1,382.700000000,383.480000000,50,30,1,1,382.680000000,383.500000000,20,43,1,2,382.400000000,383.600000000,500,1000,1,2,382.230000000,383.720000000,25,7085,1,8,382.110000000,383.740000000,300,37,1,1,382.100000000,383.800000000,20,10,2,1,382.010000000,383.880000000,2,4,1,1,382.000000000,384.000000000,1192,1300,10,4,TSLA
2025-01-03T10:31:38.888781291Z,2025-01-03T10:31:38.888614862Z,10,2,16244,A,B,1,382.900000000,22,130,166429,4887118,383.000000000,383.410000000,13,5,2,1,382.900000000,383.420000000,22,140,1,1,382.810000000,383.480000000,20,30,2,1,382.700000000,383.500000000,50,43,1,2,382.680000000,383.600000000,20,1000,1,2,382.400000000,383.720000000,500,7085,1,8,382.230000000,383.740000000,25,37,1,1,382.110000000,383.800000000,300,10,1,1,382.100000000,383.880000000,20,4,2,1,382.010000000,384.000000000,2,1300,1,4,TSLA
2025-01-03T10:31:38.928776263Z,2025-01-03T10:31:38.928609873Z,10,2,10888,A,B,0,420.710000000,200,130,166390,4887124,420.710000000,421.250000000,200,200,1,1,420.580000000,421.280000000,25,32,2,1,420.520000000,421.290000000,1,14,1,1,420.400000000,421.460000000,858,39,1,1,420.380000000,421.490000000,100,6,1,1,420.100000000,421.570000000,100,40,1,1,420.000000000,421.600000000,34,10,6,1,419.730000000,421.700000000,3,359,1,1,419.650000000,421.800000000,39,7,1,1,419.600000000,422.100000000,500,7,1,1,MSFT
2025-01-03T10:31:38.928791206Z,2025-01-03T10:31:38.928625105Z,10,2,10888,A,A,0,421.220000000,200,130,166101,4887125,420.710000000,421.220000000,200,200,1,1,420.580000000,421.280000000,25,32,2,1,420.520000000,421.290000000,1,14,1,1,420.400000000,421.460000000,858,39,1,1,420.380000000,421.490000000,100,6,1,1,420.100000000,421.570000000,100,40,1,1,420.000000000,421.600000000,34,10,6,1,419.730000000,421.700000000,3,359,1,1,419.650000000,421.800000000,39,7,1,1,419.600000000,422.100000000,500,7,1,1,MSFT
2025-01-03T10:31:39.194891595Z,2025-01-03T10:31:39.194724202Z,10,2,11667,C,B,0,139.160000000,100,130,167393,4887278,139.130000000,139.180000000,2200,103,2,2,139.120000000,139.190000000,30,400,1,1,139.110000000,139.200000000,1,129,1,1,139.100000000,139.220000000,400,110,1,2,139.080000000,139.230000000,57,25,1,1,139.070000000,139.250000000,100,1,1,1,139.030000000,139.270000000,126,37,2,2,139.010000000,139.300000000,100,507,1,4,139.000000000,139.320000000,420,39,5,1,138.980000000,139.330000000,300,503,1,2,NVDA
2025-01-03T10:31:39.195193406Z,2025-01-03T10:31:39.195027614Z,10,2,11667,C,B,3,139.100000000,400,130,165792,4887304,139.130000000,139.180000000,2200,103,2,2,139.120000000,139.190000000,30,400,1,1,139.110000000,139.200000000,1,129,1,1,139.080000000,139.220000000,57,110,1,2,139.070000000,139.230000000,100,25,1,1,139.030000000,139.250000000,126,1,2,1,139.010000000,139.270000000,100,37,1,2,139.000000000,139.300000000,420,507,5,4,138.980000000,139.320000000,300,39,1,1,138.970000000,139.330000000,800,503,2,2,NVDA
2025-01-03T10:31:39.418147665Z,2025-01-03T10:31:39.417981344Z,10,2,11667,A,A,0,139.180000000,400,130,166321,4888635,139.130000000,139.180000000,2200,503,2,3,139.120000000,139.200000000,30,129,1,1,139.110000000,139.220000000,1,110,1,2,139.080000000,139.230000000,57,25,1,1,139.070000000,139.250000000,100,1,1,1,139.030000000,139.270000000,126,37,2,2,139.010000000,139.300000000,100,507,1,4,139.000000000,139.320000000,420,39,5,1,138.980000000,139.330000000,300,503,1,2,138.970000000,139.360000000,800,4,2,2,NVDA
2025-01-03T10:31:39.501185110Z,2025-01-03T10:31:39.501018531Z,10,2,11667,A,B,5,139.030000000,400,130,166579,4888765,139.130000000,139.180000000,2200,503,2,3,139.120000000,139.200000000,30,129,1,1,139.110000000,139.220000000,1,110,1,2,139.080000000,139.230000000,57,25,1,1,139.070000000,139.250000000,100,1,1,1,139.030000000,139.270000000,526,37,3,2,139.010000000,139.300000000,100,507,1,4,139.000000000,139.320000000,420,39,5,1,138.980000000,139.330000000,300,503,1,2,138.970000000,139.360000000,800,4,2,2,NVDA
2025-01-03T10:31:39.590242840Z,2025-01-03T10:31:39.590076418Z,10,2,10888,C,B,0,420.710000000,200,130,166422,4888887,420.580000000,421.220000000,25,200,2,1,420.520000000,421.280000000,1,32,1,1,420.400000000,421.290000000,858,14,1,1,420.380000000,421.460000000,100,39,1,1,420.100000000,421.490000000,100,6,1,1,420.000000000,421.570000000,34,40,6,1,419.730000000,421.600000000,3,10,1,1,419.650000000,421.700000000,39,359,1,1,419.600000000,421.800000000,500,7,1,1,418.650000000,422.100000000,1,7,1,1,MSFT
2025-01-03T10:31:39.644881745Z,2025-01-03T10:31:39.644715560Z,10,2,10888,A,B,1,420.520000000,200,130,166185,4888922,420.580000000,421.220000000,25,200,2,1,420.520000000,421.280000000,201,32,2,1,420.400000000,421.290000000,858,14,1,1,420.380000000,421.460000000,100,39,1,1,420.100000000,421.490000000,100,6,1,1,420.000000000,421.570000000,34,40,6,1,419.730000000,421.600000000,3,10,1,1,419.650000000,421.700000000,39,359,1,1,419.600000000,421.800000000,500,7,1,1,418.650000000,422.100000000,1,7,1,1,MSFT
2025-01-03T10:31:39.722892236Z,2025-01-03T10:31:39.722725554Z,10,2,10888,A,B,1,420.530000000,200,130,166682,4889003,420.580000000,421.220000000,25,200,2,1,420.530000000,421.280000000,200,32,1,1,420.520000000,421.290000000,1,14,1,1,420.400000000,421.460000000,858,39,1,1,420.380000000,421.490000000,100,6,1,1,420.100000000,421.570000000,100,40,1,1,420.000000000,421.600000000,34,10,6,1,419.730000000,421.700000000,3,359,1,1,419.650000000,421.800000000,39,7,1,1,419.600000000,422.100000000,500,7,1,1,MSFT
2025-01-03T10:31:39.835739332Z,2025-01-03T10:31:39.835572738Z,10,2,16244,A,A,0,383.210000000,5,130,166594,4889060,383.000000000,383.210000000,13,5,2,1,382.900000000,383.410000000,22,5,1,1,382.810000000,383.420000000,20,140,2,1,382.700000000,383.480000000,50,30,1,1,382.680000000,383.500000000,20,43,1,2,382.400000000,383.600000000,500,1000,1,2,382.230000000,383.720000000,25,7085,1,8,382.110000000,383.740000000,300,37,1,1,382.100000000,383.800000000,20,10,2,1,382.010000000,383.880000000,2,4,1,1,TSLA
2025-01-03T10:31:39.835803379Z,2025-01-03T10:31:39.835637042Z,10,2,16244,A,A,1,383.310000000,17,130,166337,4889061,383.000000000,383.210000000,13,5,2,1,382.900000000,383.310000000,22,17,1,1,382.810000000,383.410000000,20,5,2,1,382.700000000,383.420000000,50,140,1,1,382.680000000,383.480000000,20,30,1,1,382.400000000,383.500000000,500,43,1,2,382.230000000,383.600000000,25,1000,1,2,382.110000000,383.720000000,300,7085,1,8,382.100000000,383.740000000,20,37,2,1,382.010000000,383.800000000,2,10,1,1,TSLA
2025-01-03T10:31:39.846643254Z,2025-01-03T10:31:39.846477074Z,10,2,16244,C,A,0,383.210000000,5,130,166180,4889096,383.000000000,383.310000000,13,17,2,1,382.900000000,383.410000000,22,5,1,1,382.810000000,383.420000000,20,140,2,1,382.700000000,383.480000000,50,30,1,1,382.680000000,383.500000000,20,43,1,2,382.400000000,383.600000000,500,1000,1,2,382.230000000,383.720000000,25,7085,1,8,382.110000000,383.740000000,300,37,1,1,382.100000000,383.800000000,20,10,2,1,382.010000000,383.880000000,2,4,1,1,TSLA
2025-01-03T10:31:39.886643028Z,2025-01-03T10:31:39.886477133Z,10,2,16244,C,A,0,383.310000000,17,130,165895,4889105,383.000000000,383.410000000,13,5,2,1,382.900000000,383.420000000,22,140,1,1,382.810000000,383.480000000,20,30,2,1,382.700000000,383.500000000,50,43,1,2,382.680000000,383.600000000,20,1000,1,2,382.400000000,383.720000000,500,7085,1,8,382.230000000,383.740000000,25,37,1,1,382.110000000,383.800000000,300,10,1,1,382.100000000,383.880000000,20,4,2,1,382.010000000,384.000000000,2,1300,1,4,TSLA
2025-01-03T10:31:39.917572043Z,2025-01-03T10:31:39.917405931Z,10,2,16244,C,A,3,383.500000000,23,130,166112,4889114,383.000000000,383.410000000,13,5,2,1,382.900000000,383.420000000,22,140,1,1,382.810000000,383.480000000,20,30,2,1,382.700000000,383.500000000,50,20,1,1,382.680000000,383.600000000,20,1000,1,2,382.400000000,383.720000000,500,7085,1,8,382.230000000,383.740000000,25,37,1,1,382.110000000,383.800000000,300,10,1,1,382.100000000,383.880000000,20,4,2,1,382.010000000,384.000000000,2,1300,1,4,TSLA
2025-01-03T10:31:39.917635187Z,2025-01-03T10:31:39.917468057Z,10,2,16244,A,A,2,383.450000000,22,130,167130,4889115,383.000000000,383.410000000,13,5,2,1,382.900000000,383.420000000,22,140,1,1,382.810000000,383.450000000,20,22,2,1,382.700000000,383.480000000,50,30,1,1,382.680000000,383.500000000,20,20,1,1,382.400000000,383.600000000,500,1000,1,2,382.230000000,383.720000000,25,7085,1,8,382.110000000,383.740000000,300,37,1,1,382.100000000,383.800000000,20,10,2,1,382.010000000,383.880000000,2,4,1,1,TSLA
2025-01-03T10:31:39.917798778Z,2025-01-03T10:31:39.917632677Z,10,2,16244,C,B,1,382.900000000,22,130,166101,4889117,383.000000000,383.410000000,13,5,2,1,382.810000000,383.420000000,20,140,2,1,382.700000000,383.450000000,50,22,1,1,382.680000000,383.480000000,20,30,1,1,382.400000000,383.500000000,500,20,1,1,382.230000000,383.600000000,25,1000,1,2,382.110000000,383.720000000,300,7085,1,8,382.100000000,383.740000000,20,37,2,1,382.010000000,383.800000000,2,10,1,1,382.000000000,383.880000000,1192,4,10,1,TSLA
2025-01-03T10:31:39.917897128Z,2025-01-03T10:31:39.917730707Z,10,2,16244,A,B,1,382.850000000,21,130,166421,4889118,383.000000000,383.410000000,13,5,2,1,382.850000000,383.420000000,21,140,1,1,382.810000000,383.450000000,20,22,2,1,382.700000000,383.480000000,50,30,1,1,382.680000000,383.500000000,20,20,1,1,382.400000000,383.600000000,500,1000,1,2,382.230000000,383.720000000,25,7085,1,8,382.110000000,383.740000000,300,37,1,1,382.100000000,383.800000000,20,10,2,1,382.010000000,383.880000000,2,4,1,1,TSLA
2025-01-03T10:31:41.501102312Z,2025-01-03T10:31:41.500936488Z,10,2,10888,C,B,1,420.530000000,200,130,165824,4890574,420.580000000,421.220000000,25,200,2,1,420.520000000,421.280000000,1,32,1,1,420.400000000,421.290000000,858,14,1,1,420.380000000,421.460000000,100,39,1,1,420.100000000,421.490000000,100,6,1,1,420.000000000,421.570000000,34,40,6,1,419.730000000,421.600000000,3,10,1,1,419.650000000,421.700000000,39,359,1,1,419.600000000,421.800000000,500,7,1,1,418.650000000,422.100000000,1,7,1,1,MSFT
2025-01-03T10:31:41.647788581Z,2025-01-03T10:31:41.647621946Z,10,2,38,A,A,0,243.590000000,120,130,166635,4890708,243.500000000,243.590000000,6,120,1,1,243.450000000,243.640000000,400,54,1,1,243.380000000,243.650000000,27,61,1,2,243.190000000,243.690000000,2,200,1,1,243.020000000,243.730000000,79,29,1,1,243.000000000,244.000000000,1243,1,9,1,242.990000000,244.140000000,1,79,1,1,242.800000000,244.200000000,30,1000,1,1,242.750000000,244.400000000,30,50,1,1,242.590000000,244.420000000,5,10,1,1,AAPL
2025-01-03T10:31:41.677330937Z,2025-01-03T10:31:41.677164584Z,10,2,38,A,A,5,244.000000000,1000,130,166353,4890727,243.500000000,243.590000000,6,120,1,1,243.450000000,243.640000000,400,54,1,1,243.380000000,243.650000000,27,61,1,2,243.190000000,243.690000000,2,200,1,1,243.020000000,243.730000000,79,29,1,1,243.000000000,244.000000000,1243,1001,9,2,242.990000000,244.140000000,1,79,1,1,242.800000000,244.200000000,30,1000,1,1,242.750000000,244.400000000,30,50,1,1,242.590000000,244.420000000,5,10,1,1,AAPL
2025-01-03T10:31:41.677361569Z,2025-01-03T10:31:41.677195281Z,10,2,38,C,A,7,244.200000000,1000,130,166288,4890728,243.500000000,243.590000000,6,120,1,1,243.450000000,243.640000000,400,54,1,1,243.380000000,243.650000000,27,61,1,2,243.190000000,243.690000000,2,200,1,1,243.020000000,243.730000000,79,29,1,1,243.000000000,244.000000000,1243,1001,9,2,242.990000000,244.140000000,1,79,1,1,242.800000000,244.400000000,30,50,1,1,242.750000000,244.420000000,30,10,1,1,242.590000000,244.580000000,5,100,1,1,AAPL
2025-01-03T10:31:41.820549745Z,2025-01-03T10:31:41.820382558Z,10,2,17709,T,N,0,107.750000000,1,130,167187,4890766,107.600000000,107.840000000,50,400,1,2,107.530000000,107.870000000,16,258,1,2,107.520000000,107.940000000,100,100,1,1,107.050000000,107.950000000,247,10,1,1,107.000000000,108.000000000,1,50,1,1,106.240000000,108.300000000,28,50,1,1,106.000000000,108.550000000,15,50,2,1,105.870000000,108.800000000,141,50,1,1,103.180000000,108.880000000,16,28,1,1,103.000000000,109.000000000,3,100,1,1,XOM
2025-01-03T10:31:41.878003073Z,2025-01-03T10:31:41.877836626Z,10,2,9155,A,B,1,241.570000000,8,130,166447,4890774,241.670000000,242.070000000,2,62,1,1,241.570000000,242.390000000,8,8,1,1,241.120000000,242.850000000,81,300,1,2,241.000000000,242.900000000,100,100,1,1,240.000000000,243.000000000,10,92,1,2,238.000000000,243.310000000,30,10,1,1,236.000000000,243.700000000,6,100,1,1,235.500000000,246.810000000,5,100,1,1,235.000000000,262.740000000,5,100,1,1,232.880000000,263.830000000,1,100,1,1,JPM
2025-01-03T10:31:42.216170057Z,2025-01-03T10:31:42.216003860Z,10,2,10888,C,A,1,421.280000000,32,130,166197,4891062,420.580000000,421.220000000,25,200,2,1,420.520000000,421.290000000,1,14,1,1,420.400000000,421.460000000,858,39,1,1,420.380000000,421.490000000,100,6,1,1,420.100000000,421.570000000,100,40,1,1,420.000000000,421.600000000,34,10,6,1,419.730000000,421.700000000,3,359,1,1,419.650000000,421.800000000,39,7,1,1,419.600000000,422.100000000,500,7,1,1,418.650000000,422.400000000,1,500,1,1,MSFT
2025-01-03T10:31:42.375969575Z,2025-01-03T10:31:42.375803703Z,10,2,9155,C,B,1,241.570000000,8,130,165872,4891138,241.670000000,242.070000000,2,62,1,1,241.120000000,242.390000000,81,8,1,1,241.000000000,242.850000000,100,300,1,2,240.000000000,242.900000000,10,100,1,1,238.000000000,243.000000000,30,92,1,2,236.000000000,243.310000000,6,10,1,1,235.500000000,243.700000000,5,100,1,1,235.000000000,246.810000000,5,100,1,1,232.880000000,262.740000000,1,100,1,1,231.110000000,263.830000000,3,100,1,1,JPM
2025-01-03T10:31:42.645448068Z,2025-01-03T10:31:42.645281359Z,10,2,10888,A,B,0,420.660000000,200,130,166709,4891211,420.660000000,421.220000000,200,200,1,1,420.580000000,421.290000000,25,14,2,1,420.520000000,421.460000000,1,39,1,1,420.400000000,421.490000000,858,6,1,1,420.380000000,421.570000000,100,40,1,1,420.100000000,421.600000000,100,10,1,1,420.000000000,421.700000000,34,359,6,1,419.730000000,421.800000000,3,7,1,1,419.650000000,422.100000000,39,7,1,1,419.600000000,422.400000000,500,500,1,1,MSFT
2025-01-03T10:31:42.826169571Z,2025-01-03T10:31:42.826003567Z,10,2,16244,C,A,0,383.410000000,5,130,166004,4891248,383.000000000,383.420000000,13,140,2,1,382.850000000,383.450000000,21,22,1,1,382.810000000,383.480000000,20,30,2,1,382.700000000,383.500000000,50,20,1,1,382.680000000,383.600000000,20,1000,1,2,382.400000000,383.720000000,500,7085,1,8,382.230000000,383.740000000,25,37,1,1,382.110000000,383.800000000,300,10,1,1,382.100000000,383.880000000,20,4,2,1,382.010000000,384.000000000,2,1300,1,4,TSLA
2025-01-03T10:31:43.006175466Z,2025-01-03T10:31:43.006009049Z,10,2,780,A,A,0,260.610000000,25,130,166417,4891298,259.010000000,260.610000000,175,25,1,1,258.910000000,294.170000000,25,100,1,1,258.100000000,295.390000000,25,100,1,1,257.700000000,,1,0,1,0,255.920000000,,1,0,1,0,250.000000000,,13,0,2,0,236.860000000,,100,0,1,0,235.690000000,,100,0,1,0,,,0,0,0,0,,,0,0,0,0,AMGN
2025-01-03T10:31:43.245713935Z,2025-01-03T10:31:43.245547741Z,10,2,11667,A,A,2,139.220000000,200,130,166194,4891437,139.130000000,139.180000000,2200,503,2,3,139.120000000,139.200000000,30,129,1,1,139.110000000,139.220000000,1,310,1,3,139.080000000,139.230000000,57,25,1,1,139.070000000,139.250000000,100,1,1,1,139.030000000,139.270000000,526,37,3,2,139.010000000,139.300000000,100,507,1,4,139.000000000,139.320000000,420,39,5,1,138.980000000,139.330000000,300,503,1,2,138.970000000,139.360000000,800,4,2,2,NVDA
2025-01-03T10:31:43.275088175Z,2025-01-03T10:31:43.274921796Z,10,2,11667,C,B,0,139.130000000,100,130,166379,4891463,139.130000000,139.180000000,2100,503,1,3,139.120000000,139.200000000,30,129,1,1,139.110000000,139.220000000,1,310,1,3,139.080000000,139.230000000,57,25,1,1,139.070000000,139.250000000,100,1,1,1,139.030000000,139.270000000,526,37,3,2,139.010000000,139.300000000,100,507,1,4,139.000000000,139.320000000,420,39,5,1,138.980000000,139.330000000,300,503,1,2,138.970000000,139.360000000,800,4,2,2,NVDA
2025-01-03T10:31:43.311402554Z,2025-01-03T10:31:43.311236016Z,10,2,11667,C,A,2,139.220000000,200,130,166538,4891495,139.130000000,139.180000000,2100,503,1,3,139.120000000,139.200000000,30,129,1,1,139.110000000,139.220000000,1,110,1,2,139.080000000,139.230000000,57,25,1,1,139.070000000,139.250000000,100,1,1,1,139.030000000,139.270000000,526,37,3,2,139.010000000,139.300000000,100,507,1,4,139.000000000,139.320000000,420,39,5,1,138.980000000,139.330000000,300,503,1,2,138.970000000,139.360000000,800,4,2,2,NVDA
2025-01-03T10:31:43.311414271Z,2025-01-03T10:31:43.311247877Z,10,2,11667,A,A,2,139.210000000,100,130,166394,4891496,139.130000000,139.180000000,2100,503,1,3,139.120000000,139.200000000,30,129,1,1,139.110000000,139.210000000,1,100,1,1,139.080000000,139.220000000,57,10,1,1,139.070000000,139.230000000,100,25,1,1,139.030000000,139.250000000,526,1,3,1,139.010000000,139.270000000,100,37,1,2,139.000000000,139.300000000,420,507,5,4,138.980000000,139.320000000,300,39,1,1,138.970000000,139.330000000,800,503,2,2,NVDA
2025-01-03T10:31:43.397005840Z,2025-01-03T10:31:43.396839361Z,10,2,11667,A,B,4,139.070000000,400,130,166479,4891536,139.130000000,139.180000000,2100,503,1,3,139.120000000,139.200000000,30,129,1,1,139.110000000,139.210000000,1,100,1,1,139.080000000,139.220000000,57,10,1,1,139.070000000,139.230000000,500,25,2,1,139.030000000,139.250000000,126,1,2,1,139.010000000,139.270000000,100,37,1,2,139.000000000,139.300000000,420,507,5,4,138.980000000,139.320000000,300,39,1,1,138.970000000,139.330000000,800,503,2,2,NVDA
2025-01-03T10:31:43.656213434Z,2025-01-03T10:31:43.656047161Z,10,2,16244,A,A,0,383.210000000,4,130,166273,4891634,383.000000000,383.210000000,13,4,2,1,382.850000000,383.420000000,21,140,1,1,382.810000000,383.450000000,20,22,2,1,382.700000000,383.480000000,50,30,1,1,382.680000000,383.500000000,20,20,1,1,382.400000000,383.600000000,500,1000,1,2,382.230000000,383.720000000,25,7085,1,8,382.110000000,383.740000000,300,37,1,1,382.100000000,383.800000000,20,10,2,1,382.010000000,383.880000000,2,4,1,1,TSLA
2025-01-03T10:31:43.666643226Z,2025-01-03T10:31:43.666477255Z,10,2,16244,C,A,0,383.210000000,4,130,165971,4891641,383.000000000,383.420000000,13,140,2,1,382.850000000,383.450000000,21,22,1,1,382.810000000,383.480000000,20,30,2,1,382.700000000,383.500000000,50,20,1,1,382.680000000,383.600000000,20,1000,1,2,382.400000000,383.720000000,500,7085,1,8,382.230000000,383.740000000,25,37,1,1,382.110000000,383.800000000,300,10,1,1,382.100000000,383.880000000,20,4,2,1,382.010000000,384.000000000,2,1300,1,4,TSLA
2025-01-03T10:31:44.346759665Z,2025-01-03T10:31:44.346593490Z,10,2,11667,C,B,4,139.070000000,400,130,166175,4891882,139.130000000,139.180000000,2100,503,1,3,139.120000000,139.200000000,30,129,1,1,139.110000000,139.210000000,1,100,1,1,139.080000000,139.220000000,57,10,1,1,139.070000000,139.230000000,100,25,1,1,139.030000000,139.250000000,126,1,2,1,139.010000000,139.270000000,100,37,1,2,139.000000000,139.300000000,420,507,5,4,138.980000000,139.320000000,300,39,1,1,138.970000000,139.330000000,800,503,2,2,NVDA
2025-01-03T10:31:44.346772492Z,2025-01-03T10:31:44.346606129Z,10,2,11667,A,B,5,139.030000000,400,130,166363,4891883,139.130000000,139.180000000,2100,503,1,3,139.120000000,139.200000000,30,129,1,1,139.110000000,139.210000000,1,100,1,1,139.080000000,139.220000000,57,10,1,1,139.070000000,139.230000000,100,25,1,1,139.030000000,139.250000000,526,1,3,1,139.010000000,139.270000000,100,37,1,2,139.000000000,139.300000000,420,507,5,4,138.980000000,139.320000000,300,39,1,1,138.970000000,139.330000000,800,503,2,2,NVDA
2025-01-03T10:31:44.364662905Z,2025-01-03T10:31:44.364496387Z,10,2,11667,A,B,0,139.130000000,100,130,166518,4891884,139.130000000,139.180000000,2200,503,2,3,139.120000000,139.200000000,30,129,1,1,139.110000000,139.210000000,1,100,1,1,139.080000000,139.220000000,57,10,1,1,139.070000000,139.230000000,100,25,1,1,139.030000000,139.250000000,526,1,3,1,139.010000000,139.270000000,100,37,1,2,139.000000000,139.300000000,420,507,5,4,138.980000000,139.320000000,300,39,1,1,138.970000000,139.330000000,800,503,2,2,NVDA
2025-01-03T10:31:44.419175920Z,2025-01-03T10:31:44.419008361Z,10,2,11667,A,B,5,139.050000000,400,130,167559,4891889,139.130000000,139.180000000,2200,503,2,3,139.120000000,139.200000000,30,129,1,1,139.110000000,139.210000000,1,100,1,1,139.080000000,139.220000000,57,10,1,1,139.070000000,139.230000000,100,25,1,1,139.050000000,139.250000000,400,1,1,1,139.030000000,139.270000000,126,37,2,2,139.010000000,139.300000000,100,507,1,4,139.000000000,139.320000000,420,39,5,1,138.980000000,139.330000000,300,503,1,2,NVDA
2025-01-03T10:31:44.745047387Z,2025-01-03T10:31:44.744881504Z,10,2,16244,C,B,1,382.850000000,21,130,165883,4892020,383.000000000,383.420000000,13,140,2,1,382.810000000,383.450000000,20,22,2,1,382.700000000,383.480000000,50,30,1,1,382.680000000,383.500000000,20,20,1,1,382.400000000,383.600000000,500,1000,1,2,382.230000000,383.720000000,25,7085,1,8,382.110000000,383.740000000,300,37,1,1,382.100000000,383.800000000,20,10,2,1,382.010000000,383.880000000,2,4,1,1,382.000000000,384.000000000,1192,1300,10,4,TSLA
2025-01-03T10:31:44.745136735Z,2025-01-03T10:31:44.744970379Z,10,2,16244,A,B,2,382.800000000,20,130,166356,4892021,383.000000000,383.420000000,13,140,2,1,382.810000000,383.450000000,20,22,2,1,382.800000000,383.480000000,20,30,1,1,382.700000000,383.500000000,50,20,1,1,382.680000000,383.600000000,20,1000,1,2,382.400000000,383.720000000,500,7085,1,8,382.230000000,383.740000000,25,37,1,1,382.110000000,383.800000000,300,10,1,1,382.100000000,383.880000000,20,4,2,1,382.010000000,384.000000000,2,1300,1,4,TSLA
2025-01-03T10:31:44.763817897Z,2025-01-03T10:31:44.763651756Z,10,2,16244,C,A,1,383.450000000,22,130,166141,4892026,383.000000000,383.420000000,13,140,2,1,382.810000000,383.480000000,20,30,2,1,382.800000000,383.500000000,20,20,1,1,382.700000000,383.600000000,50,1000,1,2,382.680000000,383.720000000,20,7085,1,8,382.400000000,383.740000000,500,37,1,1,382.230000000,383.800000000,25,10,1,1,382.110000000,383.880000000,300,4,1,1,382.100000000,384.000000000,20,1300,2,4,382.010000000,384.260000000,2,15,1,1,TSLA
2025-01-03T10:31:44.763914369Z,2025-01-03T10:31:44.763748362Z,10,2,16244,A,A,0,383.400000000,20,130,166007,4892027,383.000000000,383.400000000,13,20,2,1,382.810000000,383.420000000,20,140,2,1,382.800000000,383.480000000,20,30,1,1,382.700000000,383.500000000,50,20,1,1,382.680000000,383.600000000,20,1000,1,2,382.400000000,383.720000000,500,7085,1,8,382.230000000,383.740000000,25,37,1,1,382.110000000,383.800000000,300,10,1,1,382.100000000,383.880000000,20,4,2,1,382.010000000,384.000000000,2,1300,1,4,TSLA
2025-01-03T10:31:44.780006413Z,2025-01-03T10:31:44.779839854Z,10,2,11667,A,A,4,139.230000000,1952,130,166559,4892029,139.130000000,139.180000000,2200,503,2,3,139.120000000,139.200000000,30,129,1,1,139.110000000,139.210000000,1,100,1,1,139.080000000,139.220000000,57,10,1,1,139.070000000,139.230000000,100,1977,1,2,139.050000000,139.250000000,400,1,1,1,139.030000000,139.270000000,126,37,2,2,139.010000000,139.300000000,100,507,1,4,139.000000000,139.320000000,420,39,5,1,138.980000000,139.330000000,300,503,1,2,NVDA
2025-01-03T10:31:44.856537653Z,2025-01-03T10:31:44.856371731Z,10,2,16244,C,B,2,382.800000000,20,130,165922,4892054,383.000000000,383.400000000,13,20,2,1,382.810000000,383.420000000,20,140,2,1,382.700000000,383.480000000,50,30,1,1,382.680000000,383.500000000,20,20,1,1,382.400000000,383.600000000,500,1000,1,2,382.230000000,383.720000000,25,7085,1,8,382.110000000,383.740000000,300,37,1,1,382.100000000,383.800000000,20,10,2,1,382.010000000,383.880000000,2,4,1,1,382.000000000,384.000000000,1192,1300,10,4,TSLA
2025-01-03T10:31:44.890226175Z,2025-01-03T10:31:44.890056057Z,10,2,11667,T,N,0,139.150000000,70,0,170118,4892057,139.130000000,139.180000000,2200,503,2,3,139.120000000,139.200000000,30,129,1,1,139.110000000,139.210000000,1,100,1,1,139.080000000,139.220000000,57,10,1,1,139.070000000,139.230000000,100,1977,1,2,139.050000000,139.250000000,400,1,1,1,139.030000000,139.270000000,126,37,2,2,139.010000000,139.300000000,100,507,1,4,139.000000000,139.320000000,420,39,5,1,138.980000000,139.330000000,300,503,1,2,NVDA
2025-01-03T10:31:44.890226175Z,2025-01-03T10:31:44.890056057Z,10,2,11667,T,N,0,139.150000000,70,0,170118,4892058,139.130000000,139.180000000,2200,503,2,3,139.120000000,139.200000000,30,129,1,1,139.110000000,139.210000000,1,100,1,1,139.080000000,139.220000000,57,10,1,1,139.070000000,139.230000000,100,1977,1,2,139.050000000,139.250000000,400,1,1,1,139.030000000,139.270000000,126,37,2,2,139.010000000,139.300000000,100,507,1,4,139.000000000,139.320000000,420,39,5,1,138.980000000,139.330000000,300,503,1,2,NVDA
2025-01-03T10:31:44.890226175Z,2025-01-03T10:31:44.890056057Z,10,2,11667,T,N,0,139.150000000,100,0,170118,4892059,139.130000000,139.180000000,2200,503,2,3,139.120000000,139.200000000,30,129,1,1,139.110000000,139.210000000,1,100,1,1,139.080000000,139.220000000,57,10,1,1,139.070000000,139.230000000,100,1977,1,2,139.050000000,139.250000000,400,1,1,1,139.030000000,139.270000000,126,37,2,2,139.010000000,139.300000000,100,507,1,4,139.000000000,139.320000000,420,39,5,1,138.980000000,139.330000000,300,503,1,2,NVDA
2025-01-03T10:31:44.890226175Z,2025-01-03T10:31:44.890056057Z,10,2,11667,A,B,0,139.150000000,9760,130,170118,4892060,139.150000000,139.180000000,9760,503,1,3,139.130000000,139.200000000,2200,129,2,1,139.120000000,139.210000000,30,100,1,1,139.110000000,139.220000000,1,10,1,1,139.080000000,139.230000000,57,1977,1,2,139.070000000,139.250000000,100,1,1,1,139.050000000,139.270000000,400,37,1,2,139.030000000,139.300000000,126,507,2,4,139.010000000,139.320000000,100,39,1,1,139.000000000,139.330000000,420,503,5,2,NVDA
2025-01-03T10:31:45.002158489Z,2025-01-03T10:31:45.001992269Z,10,2,11667,A,B,4,139.090000000,400,130,166220,4892142,139.150000000,139.180000000,9760,503,1,3,139.130000000,139.200000000,2200,129,2,1,139.120000000,139.210000000,30,100,1,1,139.110000000,139.220000000,1,10,1,1,139.090000000,139.230000000,400,1977,1,2,139.080000000,139.250000000,57,1,1,1,139.070000000,139.270000000,100,37,1,2,139.030000000,139.300000000,126,507,2,4,139.010000000,139.320000000,100,39,1,1,139.000000000,139.330000000,420,503,5,2,NVDA
2025-01-03T10:31:45.211646749Z,2025-01-03T10:31:45.211480150Z,10,2,11667,A,B,0,139.150000000,100,130,166599,4892394,139.150000000,139.180000000,9860,503,2,3,139.130000000,139.200000000,2200,129,2,1,139.120000000,139.210000000,30,100,1,1,139.110000000,139.220000000,1,10,1,1,139.090000000,139.230000000,400,1977,1,2,139.080000000,139.250000000,57,1,1,1,139.070000000,139.270000000,100,37,1,2,139.030000000,139.300000000,126,507,2,4,139.010000000,139.320000000,100,39,1,1,139.000000000,139.330000000,420,503,5,2,NVDA
2025-01-03T10:31:45.211678355Z,2025-01-03T10:31:45.211511988Z,10,2,11667,C,A,0,139.180000000,400,130,166367,4892396,139.150000000,139.180000000,9860,103,2,2,139.130000000,139.200000000,2200,129,2,1,139.120000000,139.210000000,30,100,1,1,139.110000000,139.220000000,1,10,1,1,139.090000000,139.230000000,400,1977,1,2,139.080000000,139.250000000,57,1,1,1,139.070000000,139.270000000,100,37,1,2,139.030000000,139.300000000,126,507,2,4,139.010000000,139.320000000,100,39,1,1,139.000000000,139.330000000,420,503,5,2,NVDA
2025-01-03T10:31:45.248491601Z,2025-01-03T10:31:45.248325050Z,10,2,11667,A,A,0,139.180000000,400,130,166551,4892711,139.150000000,139.180000000,9860,503,2,3,139.130000000,139.200000000,2200,129,2,1,139.120000000,139.210000000,30,100,1,1,139.110000000,139.220000000,1,10,1,1,139.090000000,139.230000000,400,1977,1,2,139.080000000,139.250000000,57,1,1,1,139.070000000,139.270000000,100,37,1,2,139.030000000,139.300000000,126,507,2,4,139.010000000,139.320000000,100,39,1,1,139.000000000,139.330000000,420,503,5,2,NVDA
2025-01-03T10:31:45.318567984Z,2025-01-03T10:31:45.318402127Z,10,2,11667,C,A,0,139.180000000,400,130,165857,4893117,139.150000000,139.180000000,9860,103,2,2,139.130000000,139.200000000,2200,129,2,1,139.120000000,139.210000000,30,100,1,1,139.110000000,139.220000000,1,10,1,1,139.090000000,139.230000000,400,1977,1,2,139.080000000,139.250000000,57,1,1,1,139.070000000,139.270000000,100,37,1,2,139.030000000,139.300000000,126,507,2,4,139.010000000,139.320000000,100,39,1,1,139.000000000,139.330000000,420,503,5,2,NVDA
2025-01-03T10:31:45.318581416Z,2025-01-03T10:31:45.318414930Z,10,2,11667,A,A,1,139.190000000,400,130,166486,4893118,139.150000000,139.180000000,9860,103,2,2,139.130000000,139.190000000,2200,400,2,1,139.120000000,139.200000000,30,129,1,1,139.110000000,139.210000000,1,100,1,1,139.090000000,139.220000000,400,10,1,1,139.080000000,139.230000000,57,1977,1,2,139.070000000,139.250000000,100,1,1,1,139.030000000,139.270000000,126,37,2,2,139.010000000,139.300000000,100,507,1,4,139.000000000,139.320000000,420,39,5,1,NVDA
2025-01-03T10:31:45.447973947Z,2025-01-03T10:31:45.447803309Z,10,2,11667,T,B,0,139.180000000,3,0,170638,4893328,139.150000000,139.180000000,9860,103,2,2,139.130000000,139.190000000,2200,400,2,1,139.120000000,139.200000000,30,129,1,1,139.110000000,139.210000000,1,100,1,1,139.090000000,139.220000000,400,10,1,1,139.080000000,139.230000000,57,1977,1,2,139.070000000,139.250000000,100,1,1,1,139.030000000,139.270000000,126,37,2,2,139.010000000,139.300000000,100,507,1,4,139.000000000,139.320000000,420,39,5,1,NVDA
2025-01-03T10:31:45.447973947Z,2025-01-03T10:31:45.447803309Z,10,2,11667,T,B,0,139.180000000,67,0,170638,4893329,139.150000000,139.180000000,9860,100,2,1,139.130000000,139.190000000,2200,400,2,1,139.120000000,139.200000000,30,129,1,1,139.110000000,139.210000000,1,100,1,1,139.090000000,139.220000000,400,10,1,1,139.080000000,139.230000000,57,1977,1,2,139.070000000,139.250000000,100,1,1,1,139.030000000,139.270000000,126,37,2,2,139.010000000,139.300000000,100,507,1,4,139.000000000,139.320000000,420,39,5,1,NVDA
2025-01-03T10:31:45.447973947Z,2025-01-03T10:31:45.447803940Z,10,2,11667,T,B,0,139.180000000,33,130,170007,4893330,139.150000000,139.180000000,9860,33,2,1,139.130000000,139.190000000,2200,400,2,1,139.120000000,139.200000000,30,129,1,1,139.110000000,139.210000000,1,100,1,1,139.090000000,139.220000000,400,10,1,1,139.080000000,139.230000000,57,1977,1,2,139.070000000,139.250000000,100,1,1,1,139.030000000,139.270000000,126,37,2,2,139.010000000,139.300000000,100,507,1,4,139.000000000,139.320000000,420,39,5,1,NVDA
2025-01-03T10:31:45.447973947Z,2025-01-03T10:31:45.447803940Z,10,2,11667,C,A,0,139.180000000,33,130,170007,4893330,139.150000000,139.190000000,9860,400,2,1,139.130000000,139.200000000,2200,129,2,1,139.120000000,139.210000000,30,100,1,1,139.110000000,139.220000000,1,10,1,1,139.090000000,139.230000000,400,1977,1,2,139.080000000,139.250000000,57,1,1,1,139.070000000,139.270000000,100,37,1,2,139.030000000,139.300000000,126,507,2,4,139.010000000,139.320000000,100,39,1,1,139.000000000,139.330000000,420,503,5,2,NVDA
2025-01-03T10:31:45.447998649Z,2025-01-03T10:31:45.447830142Z,10,2,11667,C,A,0,139.190000000,400,128,168507,4893337,139.150000000,139.200000000,9860,129,2,1,139.130000000,139.210000000,2200,100,2,1,139.120000000,139.220000000,30,10,1,1,139.110000000,139.230000000,1,1977,1,2,139.090000000,139.250000000,400,1,1,1,139.080000000,139.270000000,57,37,1,2,139.070000000,139.300000000,100,507,1,4,139.030000000,139.320000000,126,39,2,1,139.010000000,139.330000000,100,503,1,2,139.000000000,139.360000000,420,4,5,2,NVDA
2025-01-03T10:31:45.448054114Z,2025-01-03T10:31:45.447883606Z,10,2,11667,T,N,0,139.190000000,2,128,170508,4893349,139.150000000,139.200000000,9860,129,2,1,139.130000000,139.210000000,2200,100,2,1,139.120000000,139.220000000,30,10,1,1,139.110000000,139.230000000,1,1977,1,2,139.090000000,139.250000000,400,1,1,1,139.080000000,139.270000000,57,37,1,2,139.070000000,139.300000000,100,507,1,4,139.030000000,139.320000000,126,39,2,1,139.010000000,139.330000000,100,503,1,2,139.000000000,139.360000000,420,4,5,2,NVDA
2025-01-03T10:31:45.448122049Z,2025-01-03T10:31:45.447954964Z,10,2,11667,C,A,1,139.210000000,100,130,167085,4893359,139.150000000,139.200000000,9860,129,2,1,139.130000000,139.220000000,2200,10,2,1,139.120000000,139.230000000,30,1977,1,2,139.110000000,139.250000000,1,1,1,1,139.090000000,139.270000000,400,37,1,2,139.080000000,139.300000000,57,507,1,4,139.070000000,139.320000000,100,39,1,1,139.030000000,139.330000000,126,503,2,2,139.010000000,139.360000000,100,4,1,2,139.000000000,139.370000000,420,86,5,2,NVDA
2025-01-03T10:31:45.448437503Z,2025-01-03T10:31:45.448270559Z,10,2,11667,A,A,3,139.240000000,200,130,166944,4893366,139.150000000,139.200000000,9860,129,2,1,139.130000000,139.220000000,2200,10,2,1,139.120000000,139.230000000,30,1977,1,2,139.110000000,139.240000000,1,200,1,1,139.090000000,139.250000000,400,1,1,1,139.080000000,139.270000000,57,37,1,2,139.070000000,139.300000000,100,507,1,4,139.030000000,139.320000000,126,39,2,1,139.010000000,139.330000000,100,503,1,2,139.000000000,139.360000000,420,4,5,2,NVDA
2025-01-03T10:31:45.649090920Z,2025-01-03T10:31:45.648923618Z,10,2,11667,T,B,0,139.200000000,69,130,167302,4893907,139.150000000,139.200000000,9860,129,2,1,139.130000000,139.220000000,2200,10,2,1,139.120000000,139.230000000,30,1977,1,2,139.110000000,139.240000000,1,200,1,1,139.090000000,139.250000000,400,1,1,1,139.080000000,139.270000000,57,37,1,2,139.070000000,139.300000000,100,507,1,4,139.030000000,139.320000000,126,39,2,1,139.010000000,139.330000000,100,503,1,2,139.000000000,139.360000000,420,4,5,2,NVDA
2025-01-03T10:31:45.649090920Z,2025-01-03T10:31:45.648923618Z,10,2,11667,C,A,0,139.200000000,69,130,167302,4893907,139.150000000,139.200000000,9860,60,2,1,139.130000000,139.220000000,2200,10,2,1,139.120000000,139.230000000,30,1977,1,2,139.110000000,139.240000000,1,200,1,1,139.090000000,139.250000000,400,1,1,1,139.080000000,139.270000000,57,37,1,2,139.070000000,139.300000000,100,507,1,4,139.030000000,139.320000000,126,39,2,1,139.010000000,139.330000000,100,503,1,2,139.000000000,139.360000000,420,4,5,2,NVDA
2025-01-03T10:31:45.700982538Z,2025-01-03T10:31:45.700816156Z,10,2,11667,A,A,3,139.240000000,100,130,166382,4894036,139.150000000,139.200000000,9860,60,2,1,139.130000000,139.220000000,2200,10,2,1,139.120000000,139.230000000,30,1977,1,2,139.110000000,139.240000000,1,300,1,2,139.090000000,139.250000000,400,1,1,1,139.080000000,139.270000000,57,37,1,2,139.070000000,139.300000000,100,507,1,4,139.030000000,139.320000000,126,39,2,1,139.010000000,139.330000000,100,503,1,2,139.000000000,139.360000000,420,4,5,2,NVDA
2025-01-03T10:31:45.761801171Z,2025-01-03T10:31:45.761634878Z,10,2,11667,A,A,1,139.210000000,400,130,166293,4894128,139.150000000,139.200000000,9860,60,2,1,139.130000000,139.210000000,2200,400,2,1,139.120000000,139.220000000,30,10,1,1,139.110000000,139.230000000,1,1977,1,2,139.090000000,139.240000000,400,300,1,2,139.080000000,139.250000000,57,1,1,1,139.070000000,139.270000000,100,37,1,2,139.030000000,139.300000000,126,507,2,4,139.010000000,139.320000000,100,39,1,1,139.000000000,139.330000000,420,503,5,2,NVDA
2025-01-03T10:31:45.794346536Z,2025-01-03T10:31:45.794180474Z,10,2,16244,C,A,0,383.400000000,20,130,166062,4894160,383.000000000,383.420000000,13,140,2,1,382.810000000,383.480000000,20,30,2,1,382.700000000,383.500000000,50,20,1,1,382.680000000,383.600000000,20,1000,1,2,382.400000000,383.720000000,500,7085,1,8,382.230000000,383.740000000,25,37,1,1,382.110000000,383.800000000,300,10,1,1,382.100000000,383.880000000,20,4,2,1,382.010000000,384.000000000,2,1300,1,4,382.000000000,384.260000000,1192,15,10,1,TSLA
2025-01-03T10:31:45.794430814Z,2025-01-03T10:31:45.794264626Z,10,2,16244,A,B,2,382.800000000,19,130,166188,4894161,383.000000000,383.420000000,13,140,2,1,382.810000000,383.480000000,20,30,2,1,382.800000000,383.500000000,19,20,1,1,382.700000000,383.600000000,50,1000,1,2,382.680000000,383.720000000,20,7085,1,8,382.400000000,383.740000000,500,37,1,1,382.230000000,383.800000000,25,10,1,1,382.110000000,383.880000000,300,4,1,1,382.100000000,384.000000000,20,1300,2,4,382.010000000,384.260000000,2,15,1,1,TSLA
2025-01-03T10:31:45.857098429Z,2025-01-03T10:31:45.856931924Z,10,2,16244,A,A,1,383.450000000,21,130,166505,4894235,383.000000000,383.420000000,13,140,2,1,382.810000000,383.450000000,20,21,2,1,382.800000000,383.480000000,19,30,1,1,382.700000000,383.500000000,50,20,1,1,382.680000000,383.600000000,20,1000,1,2,382.400000000,383.720000000,500,7085,1,8,382.230000000,383.740000000,25,37,1,1,382.110000000,383.800000000,300,10,1,1,382.100000000,383.880000000,20,4,2,1,382.010000000,384.000000000,2,1300,1,4,TSLA
2025-01-03T10:31:45.865544479Z,2025-01-03T10:31:45.865378621Z,10,2,16244,C,A,1,383.450000000,21,130,165858,4894244,383.000000000,383.420000000,13,140,2,1,382.810000000,383.480000000,20,30,2,1,382.800000000,383.500000000,19,20,1,1,382.700000000,383.600000000,50,1000,1,2,382.680000000,383.720000000,20,7085,1,8,382.400000000,383.740000000,500,37,1,1,382.230000000,383.800000000,25,10,1,1,382.110000000,383.880000000,300,4,1,1,382.100000000,384.000000000,20,1300,2,4,382.010000000,384.260000000,2,15,1,1,TSLA
2025-01-03T10:31:47.379305337Z,2025-01-03T10:31:47.379139120Z,10,2,9155,A,B,1,241.470000000,8,130,166217,4895133,241.670000000,242.070000000,2,62,1,1,241.470000000,242.390000000,8,8,1,1,241.120000000,242.850000000,81,300,1,2,241.000000000,242.900000000,100,100,1,1,240.000000000,243.000000000,10,92,1,2,238.000000000,243.310000000,30,10,1,1,236.000000000,243.700000000,6,100,1,1,235.500000000,246.810000000,5,100,1,1,235.000000000,262.740000000,5,100,1,1,232.880000000,263.830000000,1,100,1,1,JPM
2025-01-03T10:31:47.961820200Z,2025-01-03T10:31:47.961654378Z,10,2,780,C,A,0,260.610000000,25,130,165822,4895369,259.010000000,294.170000000,175,100,1,1,258.910000000,295.390000000,25,100,1,1,258.100000000,,25,0,1,0,257.700000000,,1,0,1,0,255.920000000,,1,0,1,0,250.000000000,,13,0,2,0,236.860000000,,100,0,1,0,235.690000000,,100,0,1,0,,,0,0,0,0,,,0,0,0,0,AMGN
2025-01-03T10:31:47.961833968Z,2025-01-03T10:31:47.961667681Z,10,2,780,A,A,0,260.780000000,25,130,166287,4895370,259.010000000,260.780000000,175,25,1,1,258.910000000,294.170000000,25,100,1,1,258.100000000,295.390000000,25,100,1,1,257.700000000,,1,0,1,0,255.920000000,,1,0,1,0,250.000000000,,13,0,2,0,236.860000000,,100,0,1,0,235.690000000,,100,0,1,0,,,0,0,0,0,,,0,0,0,0,AMGN
2025-01-03T10:31:48.032483111Z,2025-01-03T10:31:48.032316373Z,10,2,780,A,A,0,260.610000000,25,130,166738,4895379,259.010000000,260.610000000,175,25,1,1,258.910000000,294.170000000,25,100,1,1,258.100000000,295.390000000,25,100,1,1,257.700000000,,1,0,1,0,255.920000000,,1,0,1,0,250.000000000,,13,0,2,0,236.860000000,,100,0,1,0,235.690000000,,100,0,1,0,,,0,0,0,0,,,0,0,0,0,AMGN
2025-01-03T10:31:48.940574115Z,2025-01-03T10:31:48.940407959Z,10,2,11667,A,A,0,139.200000000,100,130,166156,4895685,139.150000000,139.200000000,9860,160,2,2,139.130000000,139.210000000,2200,400,2,1,139.120000000,139.220000000,30,10,1,1,139.110000000,139.230000000,1,1977,1,2,139.090000000,139.240000000,400,300,1,2,139.080000000,139.250000000,57,1,1,1,139.070000000,139.270000000,100,37,1,2,139.030000000,139.300000000,126,507,2,4,139.010000000,139.320000000,100,39,1,1,139.000000000,139.330000000,420,503,5,2,NVDA
2025-01-03T10:31:49.011729604Z,2025-01-03T10:31:49.011563631Z,10,2,11667,C,B,4,139.090000000,400,130,165973,4895708,139.150000000,139.200000000,9860,160,2,2,139.130000000,139.210000000,2200,400,2,1,139.120000000,139.220000000,30,10,1,1,139.110000000,139.230000000,1,1977,1,2,139.080000000,139.240000000,57,300,1,2,139.070000000,139.250000000,100,1,1,1,139.030000000,139.270000000,126,37,2,2,139.010000000,139.300000000,100,507,1,4,139.000000000,139.320000000,420,39,5,1,138.980000000,139.330000000,300,503,1,2,NVDA
2025-01-03T10:31:49.011743359Z,2025-01-03T10:31:49.011577220Z,10,2,11667,A,B,4,139.080000000,400,130,166139,4895709,139.150000000,139.200000000,9860,160,2,2,139.130000000,139.210000000,2200,400,2,1,139.120000000,139.220000000,30,10,1,1,139.110000000,139.230000000,1,1977,1,2,139.080000000,139.240000000,457,300,2,2,139.070000000,139.250000000,100,1,1,1,139.030000000,139.270000000,126,37,2,2,139.010000000,139.300000000,100,507,1,4,139.000000000,139.320000000,420,39,5,1,138.980000000,139.330000000,300,503,1,2,NVDA
2025-01-03T10:31:49.952460664Z,2025-01-03T10:31:49.952294835Z,10,2,16244,C,B,2,382.800000000,19,130,165829,4896174,383.000000000,383.420000000,13,140,2,1,382.810000000,383.480000000,20,30,2,1,382.700000000,383.500000000,50,20,1,1,382.680000000,383.600000000,20,1000,1,2,382.400000000,383.720000000,500,7085,1,8,382.230000000,383.740000000,25,37,1,1,382.110000000,383.800000000,300,10,1,1,382.100000000,383.880000000,20,4,2,1,382.010000000,384.000000000,2,1300,1,4,382.000000000,384.260000000,1242,15,11,1,TSLA
2025-01-03T10:31:49.952578192Z,2025-01-03T10:31:49.952411716Z,10,2,16244,A,B,1,382.850000000,19,130,166476,4896175,383.000000000,383.420000000,13,140,2,1,382.850000000,383.480000000,19,30,1,1,382.810000000,383.500000000,20,20,2,1,382.700000000,383.600000000,50,1000,1,2,382.680000000,383.720000000,20,7085,1,8,382.400000000,383.740000000,500,37,1,1,382.230000000,383.800000000,25,10,1,1,382.110000000,383.880000000,300,4,1,1,382.100000000,384.000000000,20,1300,2,4,382.010000000,384.260000000,2,15,1,1,TSLA
2025-01-03T10:31:51.134531639Z,2025-01-03T10:31:51.134365279Z,10,2,16244,A,A,1,383.450000000,23,130,166360,4896816,383.000000000,383.420000000,13,140,2,1,382.850000000,383.450000000,19,23,1,1,382.810000000,383.480000000,20,30,2,1,382.700000000,383.500000000,50,20,1,1,382.680000000,383.600000000,20,1000,1,2,382.400000000,383.720000000,500,7085,1,8,382.230000000,383.740000000,25,37,1,1,382.110000000,383.800000000,300,10,1,1,382.100000000,383.880000000,20,4,2,1,382.010000000,384.000000000,2,1300,1,4,TSLA
2025-01-03T10:31:51.137942586Z,2025-01-03T10:31:51.137776459Z,10,2,10888,A,B,1,420.590000000,13,130,166127,4896845,420.660000000,421.220000000,200,200,1,1,420.590000000,421.290000000,13,14,1,1,420.580000000,421.460000000,25,39,2,1,420.520000000,421.490000000,1,6,1,1,420.400000000,421.570000000,858,40,1,1,420.380000000,421.600000000,100,10,1,1,420.100000000,421.700000000,100,359,1,1,420.000000000,421.800000000,34,7,6,1,419.730000000,422.100000000,3,7,1,1,419.650000000,422.400000000,39,500,1,1,MSFT
2025-01-03T10:31:51.138112703Z,2025-01-03T10:31:51.137946769Z,10,2,10888,C,B,2,420.580000000,15,130,165934,4896847,420.660000000,421.220000000,200,200,1,1,420.590000000,421.290000000,13,14,1,1,420.580000000,421.460000000,10,39,1,1,420.520000000,421.490000000,1,6,1,1,420.400000000,421.570000000,858,40,1,1,420.380000000,421.600000000,100,10,1,1,420.100000000,421.700000000,100,359,1,1,420.000000000,421.800000000,34,7,6,1,419.730000000,422.100000000,3,7,1,1,419.650000000,422.400000000,39,500,1,1,MSFT
2025-01-03T10:31:51.139891240Z,2025-01-03T10:31:51.139725427Z,10,2,16727,C,B,0,314.890000000,8,130,165813,4896862,314.860000000,315.430000000,25,8,1,1,314.420000000,315.510000000,61,25,1,1,313.500000000,315.750000000,1,61,1,1,310.000000000,320.000000000,1,5,1,1,300.000000000,320.210000000,3,1,1,1,290.000000000,321.950000000,2,2,1,1,286.660000000,344.200000000,100,100,1,1,285.250000000,345.620000000,100,100,1,1,260.000000000,,2,0,1,0,,,0,0,0,0,V
2025-01-03T10:31:51.141177730Z,2025-01-03T10:31:51.141011679Z,10,2,16727,A,B,0,314.900000000,8,130,166051,4896869,314.900000000,315.430000000,8,8,1,1,314.860000000,315.510000000,25,25,1,1,314.420000000,315.750000000,61,61,1,1,313.500000000,320.000000000,1,5,1,1,310.000000000,320.210000000,1,1,1,1,300.000000000,321.950000000,3,2,1,1,290.000000000,344.200000000,2,100,1,1,286.660000000,345.620000000,100,100,1,1,285.250000000,,100,0,1,0,260.000000000,,2,0,1,0,V
2025-01-03T10:31:51.165665048Z,2025-01-03T10:31:51.165498415Z,10,2,10888,A,B,0,420.670000000,200,130,166633,4896970,420.670000000,421.220000000,200,200,1,1,420.590000000,421.290000000,13,14,1,1,420.580000000,421.460000000,10,39,1,1,420.520000000,421.490000000,1,6,1,1,420.400000000,421.570000000,858,40,1,1,420.380000000,421.600000000,100,10,1,1,420.100000000,421.700000000,100,359,1,1,420.000000000,421.800000000,34,7,6,1,419.730000000,422.100000000,3,7,1,1,419.650000000,422.400000000,39,500,1,1,MSFT
2025-01-03T10:31:51.567315535Z,2025-01-03T10:31:51.567149785Z,10,2,11667,C,A,1,139.210000000,400,130,165750,4897271,139.150000000,139.200000000,9860,160,2,2,139.130000000,139.220000000,2200,10,2,1,139.120000000,139.230000000,30,1977,1,2,139.110000000,139.240000000,1,300,1,2,139.080000000,139.250000000,457,1,2,1,139.070000000,139.270000000,100,37,1,2,139.030000000,139.300000000,126,507,2,4,139.010000000,139.320000000,100,39,1,1,139.000000000,139.330000000,420,503,5,2,138.980000000,139.360000000,300,4,1,2,NVDA
2025-01-03T10:31:51.567325958Z,2025-01-03T10:31:51.567160045Z,10,2,11667,A,A,1,139.220000000,400,130,165913,4897272,139.150000000,139.200000000,9860,160,2,2,139.130000000,139.220000000,2200,410,2,2,139.120000000,139.230000000,30,1977,1,2,139.110000000,139.240000000,1,300,1,2,139.080000000,139.250000000,457,1,2,1,139.070000000,139.270000000,100,37,1,2,139.030000000,139.300000000,126,507,2,4,139.010000000,139.320000000,100,39,1,1,139.000000000,139.330000000,420,503,5,2,138.980000000,139.360000000,300,4,1,2,NVDA
2025-01-03T10:31:51.623082002Z,2025-01-03T10:31:51.622915482Z,10,2,11667,A,A,1,139.210000000,400,130,166520,4897354,139.150000000,139.200000000,9860,160,2,2,139.130000000,139.210000000,2200,400,2,1,139.120000000,139.220000000,30,10,1,1,139.110000000,139.230000000,1,1977,1,2,139.080000000,139.240000000,457,300,2,2,139.070000000,139.250000000,100,1,1,1,139.030000000,139.270000000,126,37,2,2,139.010000000,139.300000000,100,507,1,4,139.000000000,139.320000000,420,39,5,1,138.980000000,139.330000000,300,503,1,2,NVDA
2025-01-03T10:31:51.627852458Z,2025-01-03T10:31:51.627686609Z,10,2,9155,C,B,1,241.470000000,8,130,165849,4897355,241.670000000,242.070000000,2,62,1,1,241.120000000,242.390000000,81,8,1,1,241.000000000,242.850000000,100,300,1,2,240.000000000,242.900000000,10,100,1,1,238.000000000,243.000000000,30,92,1,2,236.000000000,243.310000000,6,10,1,1,235.500000000,243.700000000,5,100,1,1,235.000000000,246.810000000,5,100,1,1,232.880000000,262.740000000,1,100,1,1,231.110000000,263.830000000,3,100,1,1,JPM
2025-01-03T10:31:51.627924104Z,2025-01-03T10:31:51.627757908Z,10,2,9155,A,B,1,241.580000000,8,130,166196,4897356,241.670000000,242.070000000,2,62,1,1,241.580000000,242.390000000,8,8,1,1,241.120000000,242.850000000,81,300,1,2,241.000000000,242.900000000,100,100,1,1,240.000000000,243.000000000,10,92,1,2,238.000000000,243.310000000,30,10,1,1,236.000000000,243.700000000,6,100,1,1,235.500000000,246.810000000,5,100,1,1,235.000000000,262.740000000,5,100,1,1,232.880000000,263.830000000,1,100,1,1,JPM
2025-01-03T10:31:51.725796830Z,2025-01-03T10:31:51.725630770Z,10,2,10888,A,A,5,421.600000000,500,130,166060,4897398,420.670000000,421.220000000,200,200,1,1,420.590000000,421.290000000,13,14,1,1,420.580000000,421.460000000,10,39,1,1,420.520000000,421.490000000,1,6,1,1,420.400000000,421.570000000,858,40,1,1,420.380000000,421.600000000,100,510,1,2,420.100000000,421.700000000,100,359,1,1,420.000000000,421.800000000,34,7,6,1,419.730000000,422.100000000,3,7,1,1,419.650000000,422.400000000,39,500,1,1,MSFT
2025-01-03T10:31:51.725974878Z,2025-01-03T10:31:51.725808551Z,10,2,10888,C,A,9,422.400000000,500,130,166327,4897399,420.670000000,421.220000000,200,200,1,1,420.590000000,421.290000000,13,14,1,1,420.580000000,421.460000000,10,39,1,1,420.520000000,421.490000000,1,6,1,1,420.400000000,421.570000000,858,40,1,1,420.380000000,421.600000000,100,510,1,2,420.100000000,421.700000000,100,359,1,1,420.000000000,421.800000000,34,7,6,1,419.730000000,422.100000000,3,7,1,1,419.650000000,422.500000000,39,200,1,1,MSFT
2025-01-03T10:31:51.726344856Z,2025-01-03T10:31:51.726178981Z,10,2,10888,C,A,5,421.600000000,500,130,165875,4897402,420.670000000,421.220000000,200,200,1,1,420.590000000,421.290000000,13,14,1,1,420.580000000,421.460000000,10,39,1,1,420.520000000,421.490000000,1,6,1,1,420.400000000,421.570000000,858,40,1,1,420.380000000,421.600000000,100,10,1,1,420.100000000,421.700000000,100,359,1,1,420.000000000,421.800000000,34,7,6,1,419.730000000,422.100000000,3,7,1,1,419.650000000,422.500000000,39,200,1,1,MSFT
2025-01-03T10:31:51.737348329Z,2025-01-03T10:31:51.737182025Z,10,2,10888,A,A,8,422.000000000,500,130,166304,4897416,420.670000000,421.220000000,200,200,1,1,420.590000000,421.290000000,13,14,1,1,420.580000000,421.460000000,10,39,1,1,420.520000000,421.490000000,1,6,1,1,420.400000000,421.570000000,858,40,1,1,420.380000000,421.600000000,100,10,1,1,420.100000000,421.700000000,100,359,1,1,420.000000000,421.800000000,34,7,6,1,419.730000000,422.000000000,3,500,1,1,419.650000000,422.100000000,39,7,1,1,MSFT
2025-01-03T10:31:51.990425052Z,2025-01-03T10:31:51.990259128Z,10,2,10888,C,B,1,420.590000000,13,130,165924,4897519,420.670000000,421.220000000,200,200,1,1,420.580000000,421.290000000,10,14,1,1,420.520000000,421.460000000,1,39,1,1,420.400000000,421.490000000,858,6,1,1,420.380000000,421.570000000,100,40,1,1,420.100000000,421.600000000,100,10,1,1,420.000000000,421.700000000,34,359,6,1,419.730000000,421.800000000,3,7,1,1,419.650000000,422.000000000,39,500,1,1,419.600000000,422.100000000,500,7,1,1,MSFT
2025-01-03T10:31:51.990521955Z,2025-01-03T10:31:51.990355666Z,10,2,10888,A,B,2,420.530000000,15,130,166289,4897520,420.670000000,421.220000000,200,200,1,1,420.580000000,421.290000000,10,14,1,1,420.530000000,421.460000000,15,39,1,1,420.520000000,421.490000000,1,6,1,1,420.400000000,421.570000000,858,40,1,1,420.380000000,421.600000000,100,10,1,1,420.100000000,421.700000000,100,359,1,1,420.000000000,421.800000000,34,7,6,1,419.730000000,422.000000000,3,500,1,1,419.650000000,422.100000000,39,7,1,1,MSFT
2025-01-03T10:31:52.012788060Z,2025-01-03T10:31:52.012621554Z,10,2,10888,A,A,0,421.210000000,200,130,166506,4897530,420.670000000,421.210000000,200,200,1,1,420.580000000,421.290000000,10,14,1,1,420.530000000,421.460000000,15,39,1,1,420.520000000,421.490000000,1,6,1,1,420.400000000,421.570000000,858,40,1,1,420.380000000,421.600000000,100,10,1,1,420.100000000,421.700000000,100,359,1,1,420.000000000,421.800000000,34,7,6,1,419.730000000,422.000000000,3,500,1,1,419.650000000,422.100000000,39,7,1,1,MSFT
2025-01-03T10:31:52.146266704Z,2025-01-03T10:31:52.146100091Z,10,2,10888,A,A,5,421.600000000,500,130,166613,4897620,420.670000000,421.210000000,200,200,1,1,420.580000000,421.290000000,10,14,1,1,420.530000000,421.460000000,15,39,1,1,420.520000000,421.490000000,1,6,1,1,420.400000000,421.570000000,858,40,1,1,420.380000000,421.600000000,100,510,1,2,420.100000000,421.700000000,100,359,1,1,420.000000000,421.800000000,34,7,6,1,419.730000000,422.000000000,3,500,1,1,419.650000000,422.100000000,39,7,1,1,MSFT
2025-01-03T10:31:52.146292458Z,2025-01-03T10:31:52.146126532Z,10,2,10888,C,A,8,422.000000000,500,130,165926,4897621,420.670000000,421.210000000,200,200,1,1,420.580000000,421.290000000,10,14,1,1,420.530000000,421.460000000,15,39,1,1,420.520000000,421.490000000,1,6,1,1,420.400000000,421.570000000,858,40,1,1,420.380000000,421.600000000,100,510,1,2,420.100000000,421.700000000,100,359,1,1,420.000000000,421.800000000,34,7,6,1,419.730000000,422.100000000,3,7,1,1,419.650000000,422.500000000,39,200,1,1,MSFT
2025-01-03T10:31:52.382848288Z,2025-01-03T10:31:52.382682481Z,10,2,9155,C,B,1,241.580000000,8,130,165807,4897761,241.670000000,242.070000000,2,62,1,1,241.120000000,242.390000000,81,8,1,1,241.000000000,242.850000000,100,300,1,2,240.000000000,242.900000000,10,100,1,1,238.000000000,243.000000000,30,92,1,2,236.000000000,243.310000000,6,10,1,1,235.500000000,243.700000000,5,100,1,1,235.000000000,246.810000000,5,100,1,1,232.880000000,262.740000000,1,100,1,1,231.110000000,263.830000000,3,100,1,1,JPM
2025-01-03T10:31:52.464632857Z,2025-01-03T10:31:52.464466525Z,10,2,38,C,A,1,243.640000000,54,130,166332,4897770,243.500000000,243.590000000,6,120,1,1,243.450000000,243.650000000,400,61,1,2,243.380000000,243.690000000,27,200,1,1,243.190000000,243.730000000,2,29,1,1,243.020000000,244.000000000,79,1001,1,2,243.000000000,244.140000000,1243,79,9,1,242.990000000,244.400000000,1,50,1,1,242.800000000,244.420000000,30,10,1,1,242.750000000,244.580000000,30,100,1,1,242.590000000,245.000000000,5,79,1,2,AAPL
2025-01-03T10:31:52.981112193Z,2025-01-03T10:31:52.980946007Z,10,2,780,C,A,0,260.610000000,25,130,166186,4897896,259.010000000,294.170000000,175,100,1,1,258.910000000,295.390000000,25,100,1,1,258.100000000,,25,0,1,0,257.700000000,,1,0,1,0,255.920000000,,1,0,1,0,250.000000000,,13,0,2,0,236.860000000,,100,0,1,0,235.690000000,,100,0,1,0,,,0,0,0,0,,,0,0,0,0,AMGN
2025-01-03T10:31:52.981124974Z,2025-01-03T10:31:52.980958816Z,10,2,780,A,A,0,260.780000000,25,130,166158,4897897,259.010000000,260.780000000,175,25,1,1,258.910000000,294.170000000,25,100,1,1,258.100000000,295.390000000,25,100,1,1,257.700000000,,1,0,1,0,255.920000000,,1,0,1,0,250.000000000,,13,0,2,0,236.860000000,,100,0,1,0,235.690000000,,100,0,1,0,,,0,0,0,0,,,0,0,0,0,AMGN
2025-01-03T10:31:53.052469132Z,2025-01-03T10:31:53.052302039Z,10,2,780,A,A,0,260.610000000,25,130,167093,4897908,259.010000000,260.610000000,175,25,1,1,258.910000000,294.170000000,25,100,1,1,258.100000000,295.390000000,25,100,1,1,257.700000000,,1,0,1,0,255.920000000,,1,0,1,0,250.000000000,,13,0,2,0,236.860000000,,100,0,1,0,235.690000000,,100,0,1,0,,,0,0,0,0,,,0,0,0,0,AMGN
2025-01-03T10:31:53.371710506Z,2025-01-03T10:31:53.371544544Z,10,2,780,C,B,1,258.910000000,25,130,165962,4897957,259.010000000,260.610000000,175,25,1,1,258.100000000,294.170000000,25,100,1,1,257.700000000,295.390000000,1,100,1,1,255.920000000,,1,0,1,0,250.000000000,,13,0,2,0,236.860000000,,100,0,1,0,235.690000000,,100,0,1,0,,,0,0,0,0,,,0,0,0,0,,,0,0,0,0,AMGN
2025-01-03T10:31:53.371725899Z,2025-01-03T10:31:53.371558977Z,10,2,780,A,B,1,258.740000000,25,130,166922,4897958,259.010000000,260.610000000,175,25,1,1,258.740000000,294.170000000,25,100,1,1,258.100000000,295.390000000,25,100,1,1,257.700000000,,1,0,1,0,255.920000000,,1,0,1,0,250.000000000,,13,0,2,0,236.860000000,,100,0,1,0,235.690000000,,100,0,1,0,,,0,0,0,0,,,0,0,0,0,AMGN
2025-01-03T10:31:53.534391262Z,2025-01-03T10:31:53.534224570Z,10,2,16244,C,A,1,383.450000000,23,130,166692,4898051,383.000000000,383.420000000,13,140,2,1,382.850000000,383.480000000,19,30,1,1,382.810000000,383.500000000,20,20,2,1,382.700000000,383.600000000,50,1000,1,2,382.680000000,383.720000000,20,7085,1,8,382.400000000,383.740000000,500,37,1,1,382.230000000,383.800000000,25,10,1,1,382.110000000,383.880000000,300,4,1,1,382.100000000,384.000000000,20,1300,2,4,382.010000000,384.260000000,2,15,1,1,TSLA
2025-01-03T10:31:54.096371474Z,2025-01-03T10:31:54.096205740Z,10,2,11667,C,A,0,139.200000000,100,130,165734,4898315,139.150000000,139.200000000,9860,60,2,1,139.130000000,139.210000000,2200,400,2,1,139.120000000,139.220000000,30,10,1,1,139.110000000,139.230000000,1,1977,1,2,139.080000000,139.240000000,457,300,2,2,139.070000000,139.250000000,100,1,1,1,139.030000000,139.270000000,126,37,2,2,139.010000000,139.300000000,100,507,1,4,139.000000000,139.320000000,420,39,5,1,138.980000000,139.330000000,300,503,1,2,NVDA
2025-01-03T10:31:54.419411505Z,2025-01-03T10:31:54.419245712Z,10,2,16244,C,B,1,382.850000000,19,130,165793,4898592,383.000000000,383.420000000,13,140,2,1,382.810000000,383.480000000,20,30,2,1,382.700000000,383.500000000,50,20,1,1,382.680000000,383.600000000,20,1000,1,2,382.400000000,383.720000000,500,7085,1,8,382.230000000,383.740000000,25,37,1,1,382.110000000,383.800000000,300,10,1,1,382.100000000,383.880000000,20,4,2,1,382.010000000,384.000000000,2,1300,1,4,382.000000000,384.260000000,1242,15,11,1,TSLA
2025-01-03T10:31:54.419475176Z,2025-01-03T10:31:54.419309161Z,10,2,16244,A,B,1,382.860000000,23,130,166015,4898593,383.000000000,383.420000000,13,140,2,1,382.860000000,383.480000000,23,30,1,1,382.810000000,383.500000000,20,20,2,1,382.700000000,383.600000000,50,1000,1,2,382.680000000,383.720000000,20,7085,1,8,382.400000000,383.740000000,500,37,1,1,382.230000000,383.800000000,25,10,1,1,382.110000000,383.880000000,300,4,1,1,382.100000000,384.000000000,20,1300,2,4,382.010000000,384.260000000,2,15,1,1,TSLA
2025-01-03T10:31:54.422457979Z,2025-01-03T10:31:54.422291988Z,10,2,10888,C,B,2,420.530000000,15,130,165991,4898599,420.670000000,421.210000000,200,200,1,1,420.580000000,421.290000000,10,14,1,1,420.520000000,421.460000000,1,39,1,1,420.400000000,421.490000000,858,6,1,1,420.380000000,421.570000000,100,40,1,1,420.100000000,421.600000000,100,510,1,2,420.000000000,421.700000000,34,359,6,1,419.730000000,421.800000000,3,7,1,1,419.650000000,422.100000000,39,7,1,1,419.600000000,422.500000000,500,200,1,1,MSFT
2025-01-03T10:31:54.422517436Z,2025-01-03T10:31:54.422351001Z,10,2,10888,A,B,2,420.540000000,13,130,166435,4898600,420.670000000,421.210000000,200,200,1,1,420.580000000,421.290000000,10,14,1,1,420.540000000,421.460000000,13,39,1,1,420.520000000,421.490000000,1,6,1,1,420.400000000,421.570000000,858,40,1,1,420.380000000,421.600000000,100,510,1,2,420.100000000,421.700000000,100,359,1,1,420.000000000,421.800000000,34,7,6,1,419.730000000,422.100000000,3,7,1,1,419.650000000,422.500000000,39,200,1,1,MSFT
2025-01-03T10:31:55.164533133Z,2025-01-03T10:31:55.164367632Z,10,2,11667,C,A,1,139.210000000,400,130,165501,4899166,139.150000000,139.200000000,9860,60,2,1,139.130000000,139.220000000,2200,10,2,1,139.120000000,139.230000000,30,1977,1,2,139.110000000,139.240000000,1,300,1,2,139.080000000,139.250000000,457,1,2,1,139.070000000,139.270000000,100,37,1,2,139.030000000,139.300000000,126,507,2,4,139.010000000,139.320000000,100,39,1,1,139.000000000,139.330000000,420,503,5,2,138.980000000,139.360000000,300,4,1,2,NVDA
2025-01-03T10:31:55.233843198Z,2025-01-03T10:31:55.233677020Z,10,2,11667,A,A,1,139.220000000,400,130,166178,4899219,139.150000000,139.200000000,9860,60,2,1,139.130000000,139.220000000,2200,410,2,2,139.120000000,139.230000000,30,1977,1,2,139.110000000,139.240000000,1,300,1,2,139.080000000,139.250000000,457,1,2,1,139.070000000,139.270000000,100,37,1,2,139.030000000,139.300000000,126,507,2,4,139.010000000,139.320000000,100,39,1,1,139.000000000,139.330000000,420,503,5,2,138.980000000,139.360000000,300,4,1,2,NVDA
2025-01-03T10:31:55.369682785Z,2025-01-03T10:31:55.369516916Z,10,2,10888,C,A,0,421.210000000,200,130,165869,4899303,420.670000000,421.290000000,200,14,1,1,420.580000000,421.460000000,10,39,1,1,420.540000000,421.490000000,13,6,1,1,420.520000000,421.570000000,1,40,1,1,420.400000000,421.600000000,858,510,1,2,420.380000000,421.700000000,100,359,1,1,420.100000000,421.800000000,100,7,1,1,420.000000000,422.100000000,34,7,6,1,419.730000000,422.500000000,3,200,1,1,419.650000000,423.500000000,39,600,1,2,MSFT
2025-01-03T10:31:55.369695085Z,2025-01-03T10:31:55.369529181Z,10,2,10888,A,A,0,421.240000000,200,130,165904,4899304,420.670000000,421.240000000,200,200,1,1,420.580000000,421.290000000,10,14,1,1,420.540000000,421.460000000,13,39,1,1,420.520000000,421.490000000,1,6,1,1,420.400000000,421.570000000,858,40,1,1,420.380000000,421.600000000,100,510,1,2,420.100000000,421.700000000,100,359,1,1,420.000000000,421.800000000,34,7,6,1,419.730000000,422.100000000,3,7,1,1,419.650000000,422.500000000,39,200,1,1,MSFT
2025-01-03T10:31:55.420078787Z,2025-01-03T10:31:55.419912308Z,10,2,11667,A,B,4,139.090000000,400,130,166479,4899353,139.150000000,139.200000000,9860,60,2,1,139.130000000,139.220000000,2200,410,2,2,139.120000000,139.230000000,30,1977,1,2,139.110000000,139.240000000,1,300,1,2,139.090000000,139.250000000,400,1,1,1,139.080000000,139.270000000,57,37,1,2,139.070000000,139.300000000,100,507,1,4,139.030000000,139.320000000,126,39,2,1,139.010000000,139.330000000,100,503,1,2,139.000000000,139.360000000,420,4,5,2,NVDA
2025-01-03T10:31:55.425893682Z,2025-01-03T10:31:55.425727743Z,10,2,16727,C,B,0,314.900000000,8,130,165939,4899398,314.860000000,315.430000000,25,8,1,1,314.420000000,315.510000000,61,25,1,1,313.500000000,315.750000000,1,61,1,1,310.000000000,320.000000000,1,5,1,1,300.000000000,320.210000000,3,1,1,1,290.000000000,321.950000000,2,2,1,1,286.660000000,344.200000000,100,100,1,1,285.250000000,345.620000000,100,100,1,1,260.000000000,,2,0,1,0,,,0,0,0,0,V
2025-01-03T10:31:55.425958791Z,2025-01-03T10:31:55.425792671Z,10,2,16727,A,B,0,314.910000000,8,130,166120,4899401,314.910000000,315.430000000,8,8,1,1,314.860000000,315.510000000,25,25,1,1,314.420000000,315.750000000,61,61,1,1,313.500000000,320.000000000,1,5,1,1,310.000000000,320.210000000,1,1,1,1,300.000000000,321.950000000,3,2,1,1,290.000000000,344.200000000,2,100,1,1,286.660000000,345.620000000,100,100,1,1,285.250000000,,100,0,1,0,260.000000000,,2,0,1,0,V
2025-01-03T10:31:55.427352663Z,2025-01-03T10:31:55.427186341Z,10,2,10888,A,B,0,420.680000000,200,130,166322,4899420,420.680000000,421.240000000,200,200,1,1,420.580000000,421.290000000,10,14,1,1,420.540000000,421.460000000,13,39,1,1,420.520000000,421.490000000,1,6,1,1,420.400000000,421.570000000,858,40,1,1,420.380000000,421.600000000,100,510,1,2,420.100000000,421.700000000,100,359,1,1,420.000000000,421.800000000,34,7,6,1,419.730000000,422.100000000,3,7,1,1,419.650000000,422.500000000,39,200,1,1,MSFT
2025-01-03T10:31:55.427407448Z,2025-01-03T10:31:55.427241075Z,10,2,38,A,B,1,243.460000000,400,130,166373,4899422,243.500000000,243.590000000,6,120,1,1,243.460000000,243.650000000,400,61,1,2,243.380000000,243.690000000,27,200,1,1,243.190000000,243.730000000,2,29,1,1,243.020000000,244.000000000,79,1001,1,2,243.000000000,244.140000000,1243,79,9,1,242.990000000,244.400000000,1,50,1,1,242.800000000,244.420000000,30,10,1,1,242.750000000,244.580000000,30,100,1,1,242.590000000,245.000000000,5,79,1,2,AAPL
2025-01-03T10:31:55.427585269Z,2025-01-03T10:31:55.427419488Z,10,2,17709,C,B,1,107.530000000,16,130,165781,4899424,107.600000000,107.840000000,50,400,1,2,107.520000000,107.870000000,100,258,1,2,107.050000000,107.940000000,247,100,1,1,107.000000000,107.950000000,1,10,1,1,106.240000000,108.000000000,28,50,1,1,106.000000000,108.300000000,15,50,2,1,105.870000000,108.550000000,141,50,1,1,103.180000000,108.800000000,16,50,1,1,103.000000000,108.880000000,3,28,1,1,102.000000000,109.000000000,2,100,1,1,XOM
2025-01-03T10:31:55.427614815Z,2025-01-03T10:31:55.427448531Z,10,2,17709,A,B,1,107.540000000,15,130,166284,4899425,107.600000000,107.840000000,50,400,1,2,107.540000000,107.870000000,15,258,1,2,107.520000000,107.940000000,100,100,1,1,107.050000000,107.950000000,247,10,1,1,107.000000000,108.000000000,1,50,1,1,106.240000000,108.300000000,28,50,1,1,106.000000000,108.550000000,15,50,2,1,105.870000000,108.800000000,141,50,1,1,103.180000000,108.880000000,16,28,1,1,103.000000000,109.000000000,3,100,1,1,XOM
2025-01-03T10:31:55.462201078Z,2025-01-03T10:31:55.462034877Z,10,2,10888,A,B,7,420.000000000,300,130,166201,4899706,420.680000000,421.240000000,200,200,1,1,420.580000000,421.290000000,10,14,1,1,420.540000000,421.460000000,13,39,1,1,420.520000000,421.490000000,1,6,1,1,420.400000000,421.570000000,858,40,1,1,420.380000000,421.600000000,100,510,1,2,420.100000000,421.700000000,100,359,1,1,420.000000000,421.800000000,334,7,7,1,419.730000000,422.100000000,3,7,1,1,419.650000000,422.500000000,39,200,1,1,MSFT
2025-01-03T10:31:55.649778849Z,2025-01-03T10:31:55.649612462Z,10,2,11667,A,B,0,139.160000000,100,130,166387,4900232,139.160000000,139.200000000,100,60,1,1,139.150000000,139.220000000,9860,410,2,2,139.130000000,139.230000000,2200,1977,2,2,139.120000000,139.240000000,30,300,1,2,139.110000000,139.250000000,1,1,1,1,139.090000000,139.270000000,400,37,1,2,139.080000000,139.300000000,57,507,1,4,139.070000000,139.320000000,100,39,1,1,139.030000000,139.330000000,126,503,2,2,139.010000000,139.360000000,100,4,1,2,NVDA
2025-01-03T10:31:56.476520558Z,2025-01-03T10:31:56.476354630Z,10,2,38,C,A,2,243.690000000,200,130,165928,4900773,243.500000000,243.590000000,6,120,1,1,243.460000000,243.650000000,400,61,1,2,243.380000000,243.730000000,27,29,1,1,243.190000000,244.000000000,2,1001,1,2,243.020000000,244.140000000,79,79,1,1,243.000000000,244.400000000,1243,50,9,1,242.990000000,244.420000000,1,10,1,1,242.800000000,244.580000000,30,100,1,1,242.750000000,245.000000000,30,79,1,2,242.590000000,245.190000000,5,83,1,1,AAPL
2025-01-03T10:31:56.476532787Z,2025-01-03T10:31:56.476366916Z,10,2,38,A,A,2,243.710000000,200,130,165871,4900774,243.500000000,243.590000000,6,120,1,1,243.460000000,243.650000000,400,61,1,2,243.380000000,243.710000000,27,200,1,1,243.190000000,243.730000000,2,29,1,1,243.020000000,244.000000000,79,1001,1,2,243.000000000,244.140000000,1243,79,9,1,242.990000000,244.400000000,1,50,1,1,242.800000000,244.420000000,30,10,1,1,242.750000000,244.580000000,30,100,1,1,242.590000000,245.000000000,5,79,1,2,AAPL
2025-01-03T10:31:56.526505076Z,2025-01-03T10:31:56.526338620Z,10,2,10888,A,B,0,420.690000000,200,130,166456,4900807,420.690000000,421.240000000,200,200,1,1,420.580000000,421.290000000,10,14,1,1,420.540000000,421.460000000,13,39,1,1,420.520000000,421.490000000,1,6,1,1,420.400000000,421.570000000,858,40,1,1,420.380000000,421.600000000,100,510,1,2,420.100000000,421.700000000,100,359,1,1,420.000000000,421.800000000,334,7,7,1,419.730000000,422.100000000,3,7,1,1,419.650000000,422.500000000,39,200,1,1,MSFT
2025-01-03T10:31:56.529786260Z,2025-01-03T10:31:56.529620104Z,10,2,16244,A,A,1,383.480000000,20,130,166156,4900813,383.000000000,383.420000000,13,140,2,1,382.860000000,383.480000000,23,50,1,2,382.810000000,383.500000000,20,20,2,1,382.700000000,383.600000000,50,1000,1,2,382.680000000,383.720000000,20,7085,1,8,382.400000000,383.740000000,500,37,1,1,382.230000000,383.800000000,25,10,1,1,382.110000000,383.880000000,300,4,1,1,382.100000000,384.000000000,20,1300,2,4,382.010000000,384.260000000,2,15,1,1,TSLA
2025-01-03T10:31:56.531991810Z,2025-01-03T10:31:56.531825906Z,10,2,10888,C,B,2,420.540000000,13,130,165904,4900840,420.690000000,421.240000000,200,200,1,1,420.580000000,421.290000000,10,14,1,1,420.520000000,421.460000000,1,39,1,1,420.400000000,421.490000000,858,6,1,1,420.380000000,421.570000000,100,40,1,1,420.100000000,421.600000000,100,510,1,2,420.000000000,421.700000000,334,359,7,1,419.730000000,421.800000000,3,7,1,1,419.650000000,422.100000000,39,7,1,1,419.600000000,422.500000000,500,200,1,1,MSFT
2025-01-03T10:31:56.532086517Z,2025-01-03T10:31:56.531920381Z,10,2,10888,A,B,2,420.570000000,14,130,166136,4900842,420.690000000,421.240000000,200,200,1,1,420.580000000,421.290000000,10,14,1,1,420.570000000,421.460000000,14,39,1,1,420.520000000,421.490000000,1,6,1,1,420.400000000,421.570000000,858,40,1,1,420.380000000,421.600000000,100,510,1,2,420.100000000,421.700000000,100,359,1,1,420.000000000,421.800000000,334,7,7,1,419.730000000,422.100000000,3,7,1,1,419.650000000,422.500000000,39,200,1,1,MSFT
2025-01-03T10:31:56.536423108Z,2025-01-03T10:31:56.536257179Z,10,2,38,C,B,2,243.380000000,27,130,165929,4900870,243.500000000,243.590000000,6,120,1,1,243.460000000,243.650000000,400,61,1,2,243.190000000,243.710000000,2,200,1,1,243.020000000,243.730000000,79,29,1,1,243.000000000,244.000000000,1243,1001,9,2,242.990000000,244.140000000,1,79,1,1,242.800000000,244.400000000,30,50,1,1,242.750000000,244.420000000,30,10,1,1,242.590000000,244.580000000,5,100,1,1,242.280000000,245.000000000,100,79,1,2,AAPL
2025-01-03T10:31:56.536496529Z,2025-01-03T10:31:56.536330058Z,10,2,38,A,B,2,243.390000000,29,130,166471,4900871,243.500000000,243.590000000,6,120,1,1,243.460000000,243.650000000,400,61,1,2,243.390000000,243.710000000,29,200,1,1,243.190000000,243.730000000,2,29,1,1,243.020000000,244.000000000,79,1001,1,2,243.000000000,244.140000000,1243,79,9,1,242.990000000,244.400000000,1,50,1,1,242.800000000,244.420000000,30,10,1,1,242.750000000,244.580000000,30,100,1,1,242.590000000,245.000000000,5,79,1,2,AAPL
2025-01-03T10:31:56.546323028Z,2025-01-03T10:31:56.546156580Z,10,2,16727,A,A,1,315.470000000,8,130,166448,4900903,314.910000000,315.430000000,8,8,1,1,314.860000000,315.470000000,25,8,1,1,314.420000000,315.510000000,61,25,1,1,313.500000000,315.750000000,1,61,1,1,310.000000000,320.000000000,1,5,1,1,300.000000000,320.210000000,3,1,1,1,290.000000000,321.950000000,2,2,1,1,286.660000000,344.200000000,100,100,1,1,285.250000000,345.620000000,100,100,1,1,260.000000000,,2,0,1,0,V
2025-01-03T10:31:56.546826257Z,2025-01-03T10:31:56.546660128Z,10,2,16727,C,A,0,315.430000000,8,130,166129,4900904,314.910000000,315.470000000,8,8,1,1,314.860000000,315.510000000,25,25,1,1,314.420000000,315.750000000,61,61,1,1,313.500000000,320.000000000,1,5,1,1,310.000000000,320.210000000,1,1,1,1,300.000000000,321.950000000,3,2,1,1,290.000000000,344.200000000,2,100,1,1,286.660000000,345.620000000,100,100,1,1,285.250000000,,100,0,1,0,260.000000000,,2,0,1,0,V
2025-01-03T10:31:56.546890264Z,2025-01-03T10:31:56.546723930Z,10,2,9155,C,A,1,242.390000000,8,130,166334,4900905,241.670000000,242.070000000,2,62,1,1,241.120000000,242.850000000,81,300,1,2,241.000000000,242.900000000,100,100,1,1,240.000000000,243.000000000,10,92,1,2,238.000000000,243.310000000,30,10,1,1,236.000000000,243.700000000,6,100,1,1,235.500000000,246.810000000,5,100,1,1,235.000000000,262.740000000,5,100,1,1,232.880000000,263.830000000,1,100,1,1,231.110000000,,3,0,1,0,JPM
