ts_recv,ts_event,rtype,publisher_id,instrument_id,action,side,depth,price,size,flags,ts_in_delta,sequence,bid_px_00,ask_px_00,bid_sz_00,ask_sz_00,bid_ct_00,ask_ct_00,bid_px_01,ask_px_01,bid_sz_01,ask_sz_01,bid_ct_01,ask_ct_01,bid_px_02,ask_px_02,bid_sz_02,ask_sz_02,bid_ct_02,ask_ct_02,bid_px_03,ask_px_03,bid_sz_03,ask_sz_03,bid_ct_03,ask_ct_03,bid_px_04,ask_px_04,bid_sz_04,ask_sz_04,bid_ct_04,ask_ct_04,bid_px_05,ask_px_05,bid_sz_05,ask_sz_05,bid_ct_05,ask_ct_05,bid_px_06,ask_px_06,bid_sz_06,ask_sz_06,bid_ct_06,ask_ct_06,bid_px_07,ask_px_07,bid_sz_07,ask_sz_07,bid_ct_07,ask_ct_07,bid_px_08,ask_px_08,bid_sz_08,ask_sz_08,bid_ct_08,ask_ct_08,bid_px_09,ask_px_09,bid_sz_09,ask_sz_09,bid_ct_09,ask_ct_09,symbol
2025-01-03T10:32:50.247733110Z,2025-01-03T10:32:50.247567230Z,10,2,11667,C,B,2,139.150000000,400,130,165880,4933584,139.170000000,139.200000000,100,2,1,1,139.160000000,139.220000000,100,10,1,1,139.150000000,139.230000000,9860,2277,2,4,139.130000000,139.250000000,2100,1,1,1,139.120000000,139.270000000,30,37,1,2,139.110000000,139.300000000,1,907,1,5,139.100000000,139.320000000,10,39,1,1,139.090000000,139.330000000,57,503,1,2,139.070000000,139.360000000,100,4,1,2,139.030000000,139.370000000,126,75,2,1,NVDA
2025-01-03T10:32:50.247821273Z,2025-01-03T10:32:50.247654711Z,10,2,11667,A,B,3,139.140000000,400,130,166562,4933585,139.170000000,139.200000000,100,2,1,1,139.160000000,139.220000000,100,10,1,1,139.150000000,139.230000000,9860,2277,2,4,139.140000000,139.250000000,400,1,1,1,139.130000000,139.270000000,2100,37,1,2,139.120000000,139.300000000,30,907,1,5,139.110000000,139.320000000,1,39,1,1,139.100000000,139.330000000,10,503,1,2,139.090000000,139.360000000,57,4,1,2,139.070000000,139.370000000,100,75,1,1,NVDA
2025-01-03T10:32:50.251641606Z,2025-01-03T10:32:50.251475634Z,10,2,11667,C,B,3,139.140000000,400,130,165972,4933587,139.170000000,139.200000000,100,2,1,1,139.160000000,139.220000000,100,10,1,1,139.150000000,139.230000000,9860,2277,2,4,139.130000000,139.250000000,2100,1,1,1,139.120000000,139.270000000,30,37,1,2,139.110000000,139.300000000,1,907,1,5,139.100000000,139.320000000,10,39,1,1,139.090000000,139.330000000,57,503,1,2,139.070000000,139.360000000,100,4,1,2,139.030000000,139.370000000,126,75,2,1,NVDA
2025-01-03T10:32:50.251655445Z,2025-01-03T10:32:50.251489125Z,10,2,11667,A,B,3,139.130000000,400,130,166320,4933588,139.170000000,139.200000000,100,2,1,1,139.160000000,139.220000000,100,10,1,1,139.150000000,139.230000000,9860,2277,2,4,139.130000000,139.250000000,2500,1,2,1,139.120000000,139.270000000,30,37,1,2,139.110000000,139.300000000,1,907,1,5,139.100000000,139.320000000,10,39,1,1,139.090000000,139.330000000,57,503,1,2,139.070000000,139.360000000,100,4,1,2,139.030000000,139.370000000,126,75,2,1,NVDA
2025-01-03T10:32:50.260251955Z,2025-01-03T10:32:50.260085987Z,10,2,11667,C,A,5,139.300000000,400,130,165968,4933596,139.170000000,139.200000000,100,2,1,1,139.160000000,139.220000000,100,10,1,1,139.150000000,139.230000000,9860,2277,2,4,139.130000000,139.250000000,2500,1,2,1,139.120000000,139.270000000,30,37,1,2,139.110000000,139.300000000,1,507,1,4,139.100000000,139.320000000,10,39,1,1,139.090000000,139.330000000,57,503,1,2,139.070000000,139.360000000,100,4,1,2,139.030000000,139.370000000,126,75,2,1,NVDA
2025-01-03T10:32:50.260266089Z,2025-01-03T10:32:50.260099618Z,10,2,11667,A,A,6,139.320000000,400,130,166471,4933597,139.170000000,139.200000000,100,2,1,1,139.160000000,139.220000000,100,10,1,1,139.150000000,139.230000000,9860,2277,2,4,139.130000000,139.250000000,2500,1,2,1,139.120000000,139.270000000,30,37,1,2,139.110000000,139.300000000,1,507,1,4,139.100000000,139.320000000,10,439,1,2,139.090000000,139.330000000,57,503,1,2,139.070000000,139.360000000,100,4,1,2,139.030000000,139.370000000,126,75,2,1,NVDA
2025-01-03T10:32:50.316473723Z,2025-01-03T10:32:50.316307092Z,10,2,11667,A,A,6,139.310000000,400,130,166631,4933619,139.170000000,139.200000000,100,2,1,1,139.160000000,139.220000000,100,10,1,1,139.150000000,139.230000000,9860,2277,2,4,139.130000000,139.250000000,2500,1,2,1,139.120000000,139.270000000,30,37,1,2,139.110000000,139.300000000,1,507,1,4,139.100000000,139.310000000,10,400,1,1,139.090000000,139.320000000,57,39,1,1,139.070000000,139.330000000,100,503,1,2,139.030000000,139.360000000,126,4,2,2,NVDA
2025-01-03T10:32:50.340813325Z,2025-01-03T10:32:50.340646457Z,10,2,11667,A,A,5,139.280000000,400,130,166868,4933629,139.170000000,139.200000000,100,2,1,1,139.160000000,139.220000000,100,10,1,1,139.150000000,139.230000000,9860,2277,2,4,139.130000000,139.250000000,2500,1,2,1,139.120000000,139.270000000,30,37,1,2,139.110000000,139.280000000,1,400,1,1,139.100000000,139.300000000,10,507,1,4,139.090000000,139.320000000,57,39,1,1,139.070000000,139.330000000,100,503,1,2,139.030000000,139.360000000,126,4,2,2,NVDA
2025-01-03T10:32:50.393490431Z,2025-01-03T10:32:50.393324054Z,10,2,11667,A,A,4,139.270000000,400,130,166377,4933700,139.170000000,139.200000000,100,2,1,1,139.160000000,139.220000000,100,10,1,1,139.150000000,139.230000000,9860,2277,2,4,139.130000000,139.250000000,2500,1,2,1,139.120000000,139.270000000,30,437,1,3,139.110000000,139.300000000,1,507,1,4,139.100000000,139.320000000,10,39,1,1,139.090000000,139.330000000,57,503,1,2,139.070000000,139.360000000,100,4,1,2,139.030000000,139.370000000,126,75,2,1,NVDA
2025-01-03T10:32:50.937810734Z,2025-01-03T10:32:50.937644576Z,10,2,16244,A,A,0,383.050000000,50,130,166158,4933875,382.850000000,383.050000000,23,50,1,1,382.840000000,383.090000000,300,30,1,1,382.820000000,383.100000000,1,370,1,1,382.810000000,383.140000000,39,3,3,1,382.700000000,383.200000000,50,10,1,1,382.230000000,383.250000000,25,47,1,1,382.100000000,383.350000000,10,19,1,1,382.010000000,383.420000000,2,140,1,1,382.000000000,383.600000000,1242,1000,11,2,381.900000000,383.720000000,23,7085,1,8,TSLA
2025-01-03T10:32:51.009461531Z,2025-01-03T10:32:51.009295485Z,10,2,16244,C,A,6,383.350000000,19,130,166046,4933886,382.850000000,383.050000000,23,50,1,1,382.840000000,383.090000000,300,30,1,1,382.820000000,383.100000000,1,370,1,1,382.810000000,383.140000000,39,3,3,1,382.700000000,383.200000000,50,10,1,1,382.230000000,383.250000000,25,47,1,1,382.100000000,383.420000000,10,140,1,1,382.010000000,383.600000000,2,1000,1,2,382.000000000,383.720000000,1242,7085,11,8,381.900000000,383.740000000,23,37,1,1,TSLA
2025-01-03T10:32:51.009565265Z,2025-01-03T10:32:51.009399223Z,10,2,16244,A,A,6,383.300000000,19,130,166042,4933887,382.850000000,383.050000000,23,50,1,1,382.840000000,383.090000000,300,30,1,1,382.820000000,383.100000000,1,370,1,1,382.810000000,383.140000000,39,3,3,1,382.700000000,383.200000000,50,10,1,1,382.230000000,383.250000000,25,47,1,1,382.100000000,383.300000000,10,19,1,1,382.010000000,383.420000000,2,140,1,1,382.000000000,383.600000000,1242,1000,11,2,381.900000000,383.720000000,23,7085,1,8,TSLA
2025-01-03T10:32:51.700180905Z,2025-01-03T10:32:51.700014775Z,10,2,16244,A,B,0,382.880000000,100,130,166130,4934069,382.880000000,383.050000000,100,50,1,1,382.850000000,383.090000000,23,30,1,1,382.840000000,383.100000000,300,370,1,1,382.820000000,383.140000000,1,3,1,1,382.810000000,383.200000000,39,10,3,1,382.700000000,383.250000000,50,47,1,1,382.230000000,383.300000000,25,19,1,1,382.100000000,383.420000000,10,140,1,1,382.010000000,383.600000000,2,1000,1,2,382.000000000,383.720000000,1242,7085,11,8,TSLA
2025-01-03T10:32:51.762921052Z,2025-01-03T10:32:51.762754956Z,10,2,16244,C,B,1,382.850000000,23,130,166096,4934089,382.880000000,383.050000000,100,50,1,1,382.840000000,383.090000000,300,30,1,1,382.820000000,383.100000000,1,370,1,1,382.810000000,383.140000000,39,3,3,1,382.700000000,383.200000000,50,10,1,1,382.230000000,383.250000000,25,47,1,1,382.100000000,383.300000000,10,19,1,1,382.010000000,383.420000000,2,140,1,1,382.000000000,383.600000000,1242,1000,11,2,381.900000000,383.720000000,23,7085,1,8,TSLA
2025-01-03T10:32:51.763061173Z,2025-01-03T10:32:51.762895005Z,10,2,16244,A,B,0,382.890000000,21,130,166168,4934090,382.890000000,383.050000000,21,50,1,1,382.880000000,383.090000000,100,30,1,1,382.840000000,383.100000000,300,370,1,1,382.820000000,383.140000000,1,3,1,1,382.810000000,383.200000000,39,10,3,1,382.700000000,383.250000000,50,47,1,1,382.230000000,383.300000000,25,19,1,1,382.100000000,383.420000000,10,140,1,1,382.010000000,383.600000000,2,1000,1,2,382.000000000,383.720000000,1242,7085,11,8,TSLA
2025-01-03T10:32:51.864741150Z,2025-01-03T10:32:51.864575084Z,10,2,38,A,A,4,244.200000000,1000,130,166066,4934253,243.520000000,243.730000000,200,100,1,1,243.500000000,243.750000000,6,427,1,2,243.450000000,244.000000000,29,1,1,1,243.190000000,244.140000000,2,79,1,1,243.020000000,244.200000000,79,1000,1,1,243.000000000,244.400000000,1243,1050,9,2,242.990000000,244.420000000,1,10,1,1,242.800000000,245.000000000,30,79,1,2,242.750000000,245.190000000,30,83,1,1,242.590000000,245.540000000,5,10,1,1,AAPL
2025-01-03T10:32:51.864773141Z,2025-01-03T10:32:51.864607272Z,10,2,38,C,A,5,244.400000000,1000,130,165869,4934254,243.520000000,243.730000000,200,100,1,1,243.500000000,243.750000000,6,427,1,2,243.450000000,244.000000000,29,1,1,1,243.190000000,244.140000000,2,79,1,1,243.020000000,244.200000000,79,1000,1,1,243.000000000,244.400000000,1243,50,9,1,242.990000000,244.420000000,1,10,1,1,242.800000000,245.000000000,30,79,1,2,242.750000000,245.190000000,30,83,1,1,242.590000000,245.540000000,5,10,1,1,AAPL
2025-01-03T10:32:52.427158755Z,2025-01-03T10:32:52.426992871Z,10,2,9155,C,B,1,241.500000000,8,130,165884,4934504,241.670000000,242.070000000,2,62,1,1,241.120000000,242.410000000,81,8,1,1,241.000000000,242.850000000,100,300,1,2,240.000000000,242.900000000,10,100,1,1,238.000000000,243.000000000,30,92,1,2,236.000000000,243.310000000,6,10,1,1,235.500000000,243.700000000,5,100,1,1,235.000000000,246.810000000,5,100,1,1,232.880000000,262.740000000,1,100,1,1,231.110000000,263.830000000,3,100,1,1,JPM
2025-01-03T10:32:52.427255001Z,2025-01-03T10:32:52.427088709Z,10,2,9155,A,B,1,241.550000000,8,130,166292,4934505,241.670000000,242.070000000,2,62,1,1,241.550000000,242.410000000,8,8,1,1,241.120000000,242.850000000,81,300,1,2,241.000000000,242.900000000,100,100,1,1,240.000000000,243.000000000,10,92,1,2,238.000000000,243.310000000,30,10,1,1,236.000000000,243.700000000,6,100,1,1,235.500000000,246.810000000,5,100,1,1,235.000000000,262.740000000,5,100,1,1,232.880000000,263.830000000,1,100,1,1,JPM
2025-01-03T10:32:53.301409162Z,2025-01-03T10:32:53.301243186Z,10,2,38,C,A,1,243.750000000,400,130,165976,4934912,243.520000000,243.730000000,200,100,1,1,243.500000000,243.750000000,6,27,1,1,243.450000000,244.000000000,29,1,1,1,243.190000000,244.140000000,2,79,1,1,243.020000000,244.200000000,79,1000,1,1,243.000000000,244.400000000,1243,50,9,1,242.990000000,244.420000000,1,10,1,1,242.800000000,245.000000000,30,79,1,2,242.750000000,245.190000000,30,83,1,1,242.590000000,245.540000000,5,10,1,1,AAPL
2025-01-03T10:32:53.301422784Z,2025-01-03T10:32:53.301256503Z,10,2,38,A,A,2,243.760000000,200,130,166281,4934913,243.520000000,243.730000000,200,100,1,1,243.500000000,243.750000000,6,27,1,1,243.450000000,243.760000000,29,200,1,1,243.190000000,244.000000000,2,1,1,1,243.020000000,244.140000000,79,79,1,1,243.000000000,244.200000000,1243,1000,9,1,242.990000000,244.400000000,1,50,1,1,242.800000000,244.420000000,30,10,1,1,242.750000000,245.000000000,30,79,1,2,242.590000000,245.190000000,5,83,1,1,AAPL
2025-01-03T10:32:53.301598641Z,2025-01-03T10:32:53.301432519Z,10,2,38,C,A,1,243.750000000,27,130,166122,4934914,243.520000000,243.730000000,200,100,1,1,243.500000000,243.760000000,6,200,1,1,243.450000000,244.000000000,29,1,1,1,243.190000000,244.140000000,2,79,1,1,243.020000000,244.200000000,79,1000,1,1,243.000000000,244.400000000,1243,50,9,1,242.990000000,244.420000000,1,10,1,1,242.800000000,245.000000000,30,79,1,2,242.750000000,245.190000000,30,83,1,1,242.590000000,245.540000000,5,10,1,1,AAPL
2025-01-03T10:32:53.301689991Z,2025-01-03T10:32:53.301523719Z,10,2,38,A,A,2,243.820000000,28,130,166272,4934915,243.520000000,243.730000000,200,100,1,1,243.500000000,243.760000000,6,200,1,1,243.450000000,243.820000000,29,28,1,1,243.190000000,244.000000000,2,1,1,1,243.020000000,244.140000000,79,79,1,1,243.000000000,244.200000000,1243,1000,9,1,242.990000000,244.400000000,1,50,1,1,242.800000000,244.420000000,30,10,1,1,242.750000000,245.000000000,30,79,1,2,242.590000000,245.190000000,5,83,1,1,AAPL
2025-01-03T10:32:53.306241955Z,2025-01-03T10:32:53.306075880Z,10,2,38,C,A,1,243.760000000,200,130,166075,4934918,243.520000000,243.730000000,200,100,1,1,243.500000000,243.820000000,6,28,1,1,243.450000000,244.000000000,29,1,1,1,243.190000000,244.140000000,2,79,1,1,243.020000000,244.200000000,79,1000,1,1,243.000000000,244.400000000,1243,50,9,1,242.990000000,244.420000000,1,10,1,1,242.800000000,245.000000000,30,79,1,2,242.750000000,245.190000000,30,83,1,1,242.590000000,245.540000000,5,10,1,1,AAPL
2025-01-03T10:32:53.306253324Z,2025-01-03T10:32:53.306087289Z,10,2,38,A,A,1,243.780000000,200,130,166035,4934919,243.520000000,243.730000000,200,100,1,1,243.500000000,243.780000000,6,200,1,1,243.450000000,243.820000000,29,28,1,1,243.190000000,244.000000000,2,1,1,1,243.020000000,244.140000000,79,79,1,1,243.000000000,244.200000000,1243,1000,9,1,242.990000000,244.400000000,1,50,1,1,242.800000000,244.420000000,30,10,1,1,242.750000000,245.000000000,30,79,1,2,242.590000000,245.190000000,5,83,1,1,AAPL
2025-01-03T10:32:53.427751330Z,2025-01-03T10:32:53.427585243Z,10,2,9155,C,B,1,241.550000000,8,130,166087,4934933,241.670000000,242.070000000,2,62,1,1,241.120000000,242.410000000,81,8,1,1,241.000000000,242.850000000,100,300,1,2,240.000000000,242.900000000,10,100,1,1,238.000000000,243.000000000,30,92,1,2,236.000000000,243.310000000,6,10,1,1,235.500000000,243.700000000,5,100,1,1,235.000000000,246.810000000,5,100,1,1,232.880000000,262.740000000,1,100,1,1,231.110000000,263.830000000,3,100,1,1,JPM
2025-01-03T10:32:53.657214605Z,2025-01-03T10:32:53.657047799Z,10,2,11667,A,A,3,139.250000000,400,130,166806,4934999,139.170000000,139.200000000,100,2,1,1,139.160000000,139.220000000,100,10,1,1,139.150000000,139.230000000,9860,2277,2,4,139.130000000,139.250000000,2500,401,2,2,139.120000000,139.270000000,30,37,1,2,139.110000000,139.300000000,1,507,1,4,139.100000000,139.320000000,10,39,1,1,139.090000000,139.330000000,57,503,1,2,139.070000000,139.360000000,100,4,1,2,139.030000000,139.370000000,126,75,2,1,NVDA
2025-01-03T10:32:53.817975715Z,2025-01-03T10:32:53.817809533Z,10,2,17709,C,A,2,107.890000000,16,130,166182,4935055,107.600000000,107.840000000,50,400,1,2,107.550000000,107.870000000,15,242,1,1,107.520000000,107.940000000,100,100,1,1,107.050000000,107.950000000,247,10,1,1,107.000000000,108.000000000,1,50,1,1,106.240000000,108.300000000,28,50,1,1,106.000000000,108.550000000,15,50,2,1,105.870000000,108.800000000,141,50,1,1,103.180000000,108.880000000,16,28,1,1,103.000000000,109.000000000,3,100,1,1,XOM
2025-01-03T10:32:53.818056046Z,2025-01-03T10:32:53.817889287Z,10,2,17709,A,A,1,107.870000000,17,130,166759,4935056,107.600000000,107.840000000,50,400,1,2,107.550000000,107.870000000,15,259,1,2,107.520000000,107.940000000,100,100,1,1,107.050000000,107.950000000,247,10,1,1,107.000000000,108.000000000,1,50,1,1,106.240000000,108.300000000,28,50,1,1,106.000000000,108.550000000,15,50,2,1,105.870000000,108.800000000,141,50,1,1,103.180000000,108.880000000,16,28,1,1,103.000000000,109.000000000,3,100,1,1,XOM
2025-01-03T10:32:53.952456712Z,2025-01-03T10:32:53.952290746Z,10,2,16244,C,B,4,382.810000000,19,130,165966,4935105,382.890000000,383.050000000,21,50,1,1,382.880000000,383.090000000,100,30,1,1,382.840000000,383.100000000,300,370,1,1,382.820000000,383.140000000,1,3,1,1,382.810000000,383.200000000,20,10,2,1,382.700000000,383.250000000,50,47,1,1,382.230000000,383.300000000,25,19,1,1,382.100000000,383.420000000,10,140,1,1,382.010000000,383.600000000,2,1000,1,2,382.000000000,383.720000000,1242,7085,11,8,TSLA
2025-01-03T10:32:53.952548492Z,2025-01-03T10:32:53.952381809Z,10,2,16244,A,B,2,382.850000000,21,130,166683,4935106,382.890000000,383.050000000,21,50,1,1,382.880000000,383.090000000,100,30,1,1,382.850000000,383.100000000,21,370,1,1,382.840000000,383.140000000,300,3,1,1,382.820000000,383.200000000,1,10,1,1,382.810000000,383.250000000,20,47,2,1,382.700000000,383.300000000,50,19,1,1,382.230000000,383.420000000,25,140,1,1,382.100000000,383.600000000,10,1000,1,2,382.010000000,383.720000000,2,7085,1,8,TSLA
2025-01-03T10:32:55.370966503Z,2025-01-03T10:32:55.370800221Z,10,2,38,A,B,0,243.520000000,200,130,166282,4935788,243.520000000,243.730000000,400,100,2,1,243.500000000,243.780000000,6,200,1,1,243.450000000,243.820000000,29,28,1,1,243.190000000,244.000000000,2,1,1,1,243.020000000,244.140000000,79,79,1,1,243.000000000,244.200000000,1243,1000,9,1,242.990000000,244.400000000,1,50,1,1,242.800000000,244.420000000,30,10,1,1,242.750000000,245.000000000,30,79,1,2,242.590000000,245.190000000,5,83,1,1,AAPL
2025-01-03T10:32:55.636924757Z,2025-01-03T10:32:55.636758650Z,10,2,16244,C,A,1,383.090000000,30,130,166107,4936392,382.890000000,383.050000000,21,50,1,1,382.880000000,383.100000000,100,370,1,1,382.850000000,383.140000000,21,3,1,1,382.840000000,383.200000000,300,10,1,1,382.820000000,383.250000000,1,47,1,1,382.810000000,383.300000000,20,19,2,1,382.700000000,383.420000000,50,140,1,1,382.230000000,383.600000000,25,1000,1,2,382.100000000,383.720000000,10,7085,1,8,382.010000000,383.740000000,2,37,1,1,TSLA
2025-01-03T10:32:55.638078976Z,2025-01-03T10:32:55.637912941Z,10,2,16244,A,A,3,383.190000000,30,130,166035,4936395,382.890000000,383.050000000,21,50,1,1,382.880000000,383.100000000,100,370,1,1,382.850000000,383.140000000,21,3,1,1,382.840000000,383.190000000,300,30,1,1,382.820000000,383.200000000,1,10,1,1,382.810000000,383.250000000,20,47,2,1,382.700000000,383.300000000,50,19,1,1,382.230000000,383.420000000,25,140,1,1,382.100000000,383.600000000,10,1000,1,2,382.010000000,383.720000000,2,7085,1,8,TSLA
2025-01-03T10:32:55.771597907Z,2025-01-03T10:32:55.771431139Z,10,2,11667,A,B,3,139.140000000,400,130,166768,4936422,139.170000000,139.200000000,100,2,1,1,139.160000000,139.220000000,100,10,1,1,139.150000000,139.230000000,9860,2277,2,4,139.140000000,139.250000000,400,401,1,2,139.130000000,139.270000000,2100,37,1,2,139.120000000,139.300000000,30,507,1,4,139.110000000,139.320000000,1,39,1,1,139.100000000,139.330000000,10,503,1,2,139.090000000,139.360000000,57,4,1,2,139.070000000,139.370000000,100,75,1,1,NVDA
2025-01-03T10:32:55.968528129Z,2025-01-03T10:32:55.968361926Z,10,2,16244,A,B,0,382.990000000,30,130,166203,4936455,382.990000000,383.050000000,30,50,1,1,382.890000000,383.100000000,21,370,1,1,382.880000000,383.140000000,100,3,1,1,382.850000000,383.190000000,21,30,1,1,382.840000000,383.200000000,300,10,1,1,382.820000000,383.250000000,1,47,1,1,382.810000000,383.300000000,20,19,2,1,382.700000000,383.420000000,50,140,1,1,382.230000000,383.600000000,25,1000,1,2,382.100000000,383.720000000,10,7085,1,8,TSLA
2025-01-03T10:32:56.031272200Z,2025-01-03T10:32:56.031106247Z,10,2,16244,C,B,1,382.890000000,21,130,165953,4936485,382.990000000,383.050000000,30,50,1,1,382.880000000,383.100000000,100,370,1,1,382.850000000,383.140000000,21,3,1,1,382.840000000,383.190000000,300,30,1,1,382.820000000,383.200000000,1,10,1,1,382.810000000,383.250000000,20,47,2,1,382.700000000,383.300000000,50,19,1,1,382.230000000,383.420000000,25,140,1,1,382.100000000,383.600000000,10,1000,1,2,382.010000000,383.720000000,2,7085,1,8,TSLA
2025-01-03T10:32:57.147345640Z,2025-01-03T10:32:57.147178400Z,10,2,11667,T,A,0,139.170000000,99,130,167240,4936799,139.170000000,139.200000000,100,2,1,1,139.160000000,139.220000000,100,10,1,1,139.150000000,139.230000000,9860,2277,2,4,139.140000000,139.250000000,400,401,1,2,139.130000000,139.270000000,2100,37,1,2,139.120000000,139.300000000,30,507,1,4,139.110000000,139.320000000,1,39,1,1,139.100000000,139.330000000,10,503,1,2,139.090000000,139.360000000,57,4,1,2,139.070000000,139.370000000,100,75,1,1,NVDA
2025-01-03T10:32:57.147345640Z,2025-01-03T10:32:57.147178400Z,10,2,11667,C,B,0,139.170000000,99,130,167240,4936799,139.170000000,139.200000000,1,2,1,1,139.160000000,139.220000000,100,10,1,1,139.150000000,139.230000000,9860,2277,2,4,139.140000000,139.250000000,400,401,1,2,139.130000000,139.270000000,2100,37,1,2,139.120000000,139.300000000,30,507,1,4,139.110000000,139.320000000,1,39,1,1,139.100000000,139.330000000,10,503,1,2,139.090000000,139.360000000,57,4,1,2,139.070000000,139.370000000,100,75,1,1,NVDA
2025-01-03T10:32:57.147408967Z,2025-01-03T10:32:57.147242856Z,10,2,11667,A,A,0,139.200000000,100,130,166111,4936802,139.170000000,139.200000000,1,102,1,2,139.160000000,139.220000000,100,10,1,1,139.150000000,139.230000000,9860,2277,2,4,139.140000000,139.250000000,400,401,1,2,139.130000000,139.270000000,2100,37,1,2,139.120000000,139.300000000,30,507,1,4,139.110000000,139.320000000,1,39,1,1,139.100000000,139.330000000,10,503,1,2,139.090000000,139.360000000,57,4,1,2,139.070000000,139.370000000,100,75,1,1,NVDA
2025-01-03T10:32:57.147450769Z,2025-01-03T10:32:57.147283256Z,10,2,11667,C,B,3,139.140000000,400,130,167513,4936807,139.170000000,139.200000000,1,102,1,2,139.160000000,139.220000000,100,10,1,1,139.150000000,139.230000000,9860,2277,2,4,139.130000000,139.250000000,2100,401,1,2,139.120000000,139.270000000,30,37,1,2,139.110000000,139.300000000,1,507,1,4,139.100000000,139.320000000,10,39,1,1,139.090000000,139.330000000,57,503,1,2,139.070000000,139.360000000,100,4,1,2,139.030000000,139.370000000,126,75,2,1,NVDA
2025-01-03T10:32:57.255877598Z,2025-01-03T10:32:57.255711516Z,10,2,11667,A,B,3,139.130000000,400,130,166082,4936854,139.170000000,139.200000000,1,102,1,2,139.160000000,139.220000000,100,10,1,1,139.150000000,139.230000000,9860,2277,2,4,139.130000000,139.250000000,2500,401,2,2,139.120000000,139.270000000,30,37,1,2,139.110000000,139.300000000,1,507,1,4,139.100000000,139.320000000,10,39,1,1,139.090000000,139.330000000,57,503,1,2,139.070000000,139.360000000,100,4,1,2,139.030000000,139.370000000,126,75,2,1,NVDA
2025-01-03T10:32:57.430719715Z,2025-01-03T10:32:57.430553458Z,10,2,9155,A,B,1,241.500000000,8,130,166257,4936929,241.670000000,242.070000000,2,62,1,1,241.500000000,242.410000000,8,8,1,1,241.120000000,242.850000000,81,300,1,2,241.000000000,242.900000000,100,100,1,1,240.000000000,243.000000000,10,92,1,2,238.000000000,243.310000000,30,10,1,1,236.000000000,243.700000000,6,100,1,1,235.500000000,246.810000000,5,100,1,1,235.000000000,262.740000000,5,100,1,1,232.880000000,263.830000000,1,100,1,1,JPM
2025-01-03T10:32:58.834285200Z,2025-01-03T10:32:58.834119351Z,10,2,11667,C,A,0,139.200000000,100,130,165849,4937370,139.170000000,139.200000000,1,2,1,1,139.160000000,139.220000000,100,10,1,1,139.150000000,139.230000000,9860,2277,2,4,139.130000000,139.250000000,2500,401,2,2,139.120000000,139.270000000,30,37,1,2,139.110000000,139.300000000,1,507,1,4,139.100000000,139.320000000,10,39,1,1,139.090000000,139.330000000,57,503,1,2,139.070000000,139.360000000,100,4,1,2,139.030000000,139.370000000,126,75,2,1,NVDA
2025-01-03T10:32:59.894633756Z,2025-01-03T10:32:59.894467798Z,10,2,11667,A,A,0,139.200000000,100,130,165958,4937942,139.170000000,139.200000000,1,102,1,2,139.160000000,139.220000000,100,10,1,1,139.150000000,139.230000000,9860,2277,2,4,139.130000000,139.250000000,2500,401,2,2,139.120000000,139.270000000,30,37,1,2,139.110000000,139.300000000,1,507,1,4,139.100000000,139.320000000,10,39,1,1,139.090000000,139.330000000,57,503,1,2,139.070000000,139.360000000,100,4,1,2,139.030000000,139.370000000,126,75,2,1,NVDA
2025-01-03T10:33:00.006541216Z,2025-01-03T10:33:00.006373503Z,10,2,16244,T,B,0,383.050000000,50,130,167713,4937971,382.990000000,383.050000000,30,50,1,1,382.880000000,383.100000000,100,370,1,1,382.850000000,383.140000000,21,3,1,1,382.840000000,383.190000000,300,30,1,1,382.820000000,383.200000000,1,10,1,1,382.810000000,383.250000000,20,47,2,1,382.700000000,383.300000000,50,19,1,1,382.230000000,383.420000000,25,140,1,1,382.100000000,383.600000000,10,1000,1,2,382.010000000,383.720000000,2,7085,1,8,TSLA
2025-01-03T10:33:00.006541216Z,2025-01-03T10:33:00.006373503Z,10,2,16244,C,A,0,383.050000000,50,130,167713,4937971,382.990000000,383.100000000,30,370,1,1,382.880000000,383.140000000,100,3,1,1,382.850000000,383.190000000,21,30,1,1,382.840000000,383.200000000,300,10,1,1,382.820000000,383.250000000,1,47,1,1,382.810000000,383.300000000,20,19,2,1,382.700000000,383.420000000,50,140,1,1,382.230000000,383.600000000,25,1000,1,2,382.100000000,383.720000000,10,7085,1,8,382.010000000,383.740000000,2,37,1,1,TSLA
2025-01-03T10:33:00.011353271Z,2025-01-03T10:33:00.011185441Z,10,2,16244,T,N,0,383.090000000,100,130,167830,4937982,382.990000000,383.100000000,30,370,1,1,382.880000000,383.140000000,100,3,1,1,382.850000000,383.190000000,21,30,1,1,382.840000000,383.200000000,300,10,1,1,382.820000000,383.250000000,1,47,1,1,382.810000000,383.300000000,20,19,2,1,382.700000000,383.420000000,50,140,1,1,382.230000000,383.600000000,25,1000,1,2,382.100000000,383.720000000,10,7085,1,8,382.010000000,383.740000000,2,37,1,1,TSLA
2025-01-03T10:33:00.013354314Z,2025-01-03T10:33:00.013185548Z,10,2,16244,T,N,0,383.090000000,100,130,168766,4937988,382.990000000,383.100000000,30,370,1,1,382.880000000,383.140000000,100,3,1,1,382.850000000,383.190000000,21,30,1,1,382.840000000,383.200000000,300,10,1,1,382.820000000,383.250000000,1,47,1,1,382.810000000,383.300000000,20,19,2,1,382.700000000,383.420000000,50,140,1,1,382.230000000,383.600000000,25,1000,1,2,382.100000000,383.720000000,10,7085,1,8,382.010000000,383.740000000,2,37,1,1,TSLA
2025-01-03T10:33:00.014033242Z,2025-01-03T10:33:00.013865893Z,10,2,16244,T,B,0,383.100000000,370,130,167349,4937989,382.990000000,383.100000000,30,370,1,1,382.880000000,383.140000000,100,3,1,1,382.850000000,383.190000000,21,30,1,1,382.840000000,383.200000000,300,10,1,1,382.820000000,383.250000000,1,47,1,1,382.810000000,383.300000000,20,19,2,1,382.700000000,383.420000000,50,140,1,1,382.230000000,383.600000000,25,1000,1,2,382.100000000,383.720000000,10,7085,1,8,382.010000000,383.740000000,2,37,1,1,TSLA
2025-01-03T10:33:00.014033242Z,2025-01-03T10:33:00.013865893Z,10,2,16244,C,A,0,383.100000000,370,130,167349,4937989,382.990000000,383.140000000,30,3,1,1,382.880000000,383.190000000,100,30,1,1,382.850000000,383.200000000,21,10,1,1,382.840000000,383.250000000,300,47,1,1,382.820000000,383.300000000,1,19,1,1,382.810000000,383.420000000,20,140,2,1,382.700000000,383.600000000,50,1000,1,2,382.230000000,383.720000000,25,7085,1,8,382.100000000,383.740000000,10,37,1,1,382.010000000,383.800000000,2,10,1,1,TSLA
2025-01-03T10:33:00.014054236Z,2025-01-03T10:33:00.013887170Z,10,2,16244,A,B,0,383.020000000,100,130,167066,4937990,383.020000000,383.140000000,100,3,1,1,382.990000000,383.190000000,30,30,1,1,382.880000000,383.200000000,100,10,1,1,382.850000000,383.250000000,21,47,1,1,382.840000000,383.300000000,300,19,1,1,382.820000000,383.420000000,1,140,1,1,382.810000000,383.600000000,20,1000,2,2,382.700000000,383.720000000,50,7085,1,8,382.230000000,383.740000000,25,37,1,1,382.100000000,383.800000000,10,10,1,1,TSLA
2025-01-03T10:33:00.014074970Z,2025-01-03T10:33:00.013906484Z,10,2,16244,T,B,0,383.140000000,3,130,168486,4937992,383.020000000,383.140000000,100,3,1,1,382.990000000,383.190000000,30,30,1,1,382.880000000,383.200000000,100,10,1,1,382.850000000,383.250000000,21,47,1,1,382.840000000,383.300000000,300,19,1,1,382.820000000,383.420000000,1,140,1,1,382.810000000,383.600000000,20,1000,2,2,382.700000000,383.720000000,50,7085,1,8,382.230000000,383.740000000,25,37,1,1,382.100000000,383.800000000,10,10,1,1,TSLA
2025-01-03T10:33:00.014074970Z,2025-01-03T10:33:00.013906484Z,10,2,16244,C,A,0,383.140000000,3,130,168486,4937992,383.020000000,383.190000000,100,30,1,1,382.990000000,383.200000000,30,10,1,1,382.880000000,383.250000000,100,47,1,1,382.850000000,383.300000000,21,19,1,1,382.840000000,383.420000000,300,140,1,1,382.820000000,383.600000000,1,1000,1,2,382.810000000,383.720000000,20,7085,2,8,382.700000000,383.740000000,50,37,1,1,382.230000000,383.800000000,25,10,1,1,382.100000000,383.880000000,10,4,1,1,TSLA
2025-01-03T10:33:00.014097358Z,2025-01-03T10:33:00.013931186Z,10,2,16244,A,B,0,383.080000000,16,130,166172,4937995,383.080000000,383.190000000,16,30,1,1,383.020000000,383.200000000,100,10,1,1,382.990000000,383.250000000,30,47,1,1,382.880000000,383.300000000,100,19,1,1,382.850000000,383.420000000,21,140,1,1,382.840000000,383.600000000,300,1000,1,2,382.820000000,383.720000000,1,7085,1,8,382.810000000,383.740000000,20,37,2,1,382.700000000,383.800000000,50,10,1,1,382.230000000,383.880000000,25,4,1,1,TSLA
2025-01-03T10:33:00.014139355Z,2025-01-03T10:33:00.013969620Z,10,2,16244,T,B,0,383.190000000,30,130,169735,4937998,383.080000000,383.190000000,16,30,1,1,383.020000000,383.200000000,100,10,1,1,382.990000000,383.250000000,30,47,1,1,382.880000000,383.300000000,100,19,1,1,382.850000000,383.420000000,21,140,1,1,382.840000000,383.600000000,300,1000,1,2,382.820000000,383.720000000,1,7085,1,8,382.810000000,383.740000000,20,37,2,1,382.700000000,383.800000000,50,10,1,1,382.230000000,383.880000000,25,4,1,1,TSLA
2025-01-03T10:33:00.014139355Z,2025-01-03T10:33:00.013969620Z,10,2,16244,C,A,0,383.190000000,30,130,169735,4937998,383.080000000,383.200000000,16,10,1,1,383.020000000,383.250000000,100,47,1,1,382.990000000,383.300000000,30,19,1,1,382.880000000,383.420000000,100,140,1,1,382.850000000,383.600000000,21,1000,1,2,382.840000000,383.720000000,300,7085,1,8,382.820000000,383.740000000,1,37,1,1,382.810000000,383.800000000,20,10,2,1,382.700000000,383.880000000,50,4,1,1,382.230000000,384.000000000,25,1300,1,4,TSLA
2025-01-03T10:33:00.014158305Z,2025-01-03T10:33:00.013991166Z,10,2,16244,T,B,0,383.200000000,10,130,167139,4938001,383.080000000,383.200000000,16,10,1,1,383.020000000,383.250000000,100,47,1,1,382.990000000,383.300000000,30,19,1,1,382.880000000,383.420000000,100,140,1,1,382.850000000,383.600000000,21,1000,1,2,382.840000000,383.720000000,300,7085,1,8,382.820000000,383.740000000,1,37,1,1,382.810000000,383.800000000,20,10,2,1,382.700000000,383.880000000,50,4,1,1,382.230000000,384.000000000,25,1300,1,4,TSLA
2025-01-03T10:33:00.014158305Z,2025-01-03T10:33:00.013991166Z,10,2,16244,C,A,0,383.200000000,10,130,167139,4938001,383.080000000,383.250000000,16,47,1,1,383.020000000,383.300000000,100,19,1,1,382.990000000,383.420000000,30,140,1,1,382.880000000,383.600000000,100,1000,1,2,382.850000000,383.720000000,21,7085,1,8,382.840000000,383.740000000,300,37,1,1,382.820000000,383.800000000,1,10,1,1,382.810000000,383.880000000,20,4,2,1,382.700000000,384.000000000,50,1300,1,4,382.230000000,384.260000000,25,15,1,1,TSLA
2025-01-03T10:33:00.014179854Z,2025-01-03T10:33:00.014013791Z,10,2,16244,A,B,0,383.140000000,16,130,166063,4938002,383.140000000,383.250000000,16,47,1,1,383.080000000,383.300000000,16,19,1,1,383.020000000,383.420000000,100,140,1,1,382.990000000,383.600000000,30,1000,1,2,382.880000000,383.720000000,100,7085,1,8,382.850000000,383.740000000,21,37,1,1,382.840000000,383.800000000,300,10,1,1,382.820000000,383.880000000,1,4,1,1,382.810000000,384.000000000,20,1300,2,4,382.700000000,384.260000000,50,15,1,1,TSLA
2025-01-03T10:33:00.014660737Z,2025-01-03T10:33:00.014494735Z,10,2,16244,A,B,4,382.930000000,14,130,166002,4938014,383.140000000,383.250000000,16,47,1,1,383.080000000,383.300000000,16,19,1,1,383.020000000,383.420000000,100,140,1,1,382.990000000,383.600000000,30,1000,1,2,382.930000000,383.720000000,14,7085,1,8,382.880000000,383.740000000,100,37,1,1,382.850000000,383.800000000,21,10,1,1,382.840000000,383.880000000,300,4,1,1,382.820000000,384.000000000,1,1300,1,4,382.810000000,384.260000000,20,15,2,1,TSLA
2025-01-03T10:33:00.014918527Z,2025-01-03T10:33:00.014752465Z,10,2,16244,C,A,3,383.600000000,500,130,166062,4938017,383.140000000,383.250000000,16,47,1,1,383.080000000,383.300000000,16,19,1,1,383.020000000,383.420000000,100,140,1,1,382.990000000,383.600000000,30,500,1,1,382.930000000,383.720000000,14,7085,1,8,382.880000000,383.740000000,100,37,1,1,382.850000000,383.800000000,21,10,1,1,382.840000000,383.880000000,300,4,1,1,382.820000000,384.000000000,1,1300,1,4,382.810000000,384.260000000,20,15,2,1,TSLA
2025-01-03T10:33:00.015003301Z,2025-01-03T10:33:00.014836642Z,10,2,16244,A,B,1,383.080000000,2,130,166659,4938018,383.140000000,383.250000000,16,47,1,1,383.080000000,383.300000000,18,19,2,1,383.020000000,383.420000000,100,140,1,1,382.990000000,383.600000000,30,500,1,1,382.930000000,383.720000000,14,7085,1,8,382.880000000,383.740000000,100,37,1,1,382.850000000,383.800000000,21,10,1,1,382.840000000,383.880000000,300,4,1,1,382.820000000,384.000000000,1,1300,1,4,382.810000000,384.260000000,20,15,2,1,TSLA
2025-01-03T10:33:00.019052715Z,2025-01-03T10:33:00.018886804Z,10,2,16244,C,B,2,383.020000000,100,130,165911,4938027,383.140000000,383.250000000,16,47,1,1,383.080000000,383.300000000,18,19,2,1,382.990000000,383.420000000,30,140,1,1,382.930000000,383.600000000,14,500,1,1,382.880000000,383.720000000,100,7085,1,8,382.850000000,383.740000000,21,37,1,1,382.840000000,383.800000000,300,10,1,1,382.820000000,383.880000000,1,4,1,1,382.810000000,384.000000000,20,1300,2,4,382.700000000,384.260000000,50,15,1,1,TSLA
2025-01-03T10:33:00.024761675Z,2025-01-03T10:33:00.024595945Z,10,2,16244,C,B,3,382.930000000,14,130,165730,4938139,383.140000000,383.250000000,16,47,1,1,383.080000000,383.300000000,18,19,2,1,382.990000000,383.420000000,30,140,1,1,382.880000000,383.600000000,100,500,1,1,382.850000000,383.720000000,21,7085,1,8,382.840000000,383.740000000,300,37,1,1,382.820000000,383.800000000,1,10,1,1,382.810000000,383.880000000,20,4,2,1,382.700000000,384.000000000,50,1300,1,4,382.230000000,384.260000000,25,15,1,1,TSLA
2025-01-03T10:33:00.025012201Z,2025-01-03T10:33:00.024846327Z,10,2,16244,C,B,1,383.080000000,2,130,165874,4938145,383.140000000,383.250000000,16,47,1,1,383.080000000,383.300000000,16,19,1,1,382.990000000,383.420000000,30,140,1,1,382.880000000,383.600000000,100,500,1,1,382.850000000,383.720000000,21,7085,1,8,382.840000000,383.740000000,300,37,1,1,382.820000000,383.800000000,1,10,1,1,382.810000000,383.880000000,20,4,2,1,382.700000000,384.000000000,50,1300,1,4,382.230000000,384.260000000,25,15,1,1,TSLA
2025-01-03T10:33:00.025031001Z,2025-01-03T10:33:00.024864922Z,10,2,16244,C,B,0,383.140000000,16,130,166079,4938146,383.080000000,383.250000000,16,47,1,1,382.990000000,383.300000000,30,19,1,1,382.880000000,383.420000000,100,140,1,1,382.850000000,383.600000000,21,500,1,1,382.840000000,383.720000000,300,7085,1,8,382.820000000,383.740000000,1,37,1,1,382.810000000,383.800000000,20,10,2,1,382.700000000,383.880000000,50,4,1,1,382.230000000,384.000000000,25,1300,1,4,382.100000000,384.260000000,10,15,1,1,TSLA
2025-01-03T10:33:00.069288233Z,2025-01-03T10:33:00.069122140Z,10,2,16244,C,B,3,382.850000000,21,130,166093,4938236,383.080000000,383.250000000,16,47,1,1,382.990000000,383.300000000,30,19,1,1,382.880000000,383.420000000,100,140,1,1,382.840000000,383.600000000,300,500,1,1,382.820000000,383.720000000,1,7085,1,8,382.810000000,383.740000000,20,37,2,1,382.700000000,383.800000000,50,10,1,1,382.230000000,383.880000000,25,4,1,1,382.100000000,384.000000000,10,1300,1,4,382.010000000,384.260000000,2,15,1,1,TSLA
2025-01-03T10:33:00.069391721Z,2025-01-03T10:33:00.069225750Z,10,2,16244,A,B,2,382.900000000,20,130,165971,4938237,383.080000000,383.250000000,16,47,1,1,382.990000000,383.300000000,30,19,1,1,382.900000000,383.420000000,20,140,1,1,382.880000000,383.600000000,100,500,1,1,382.840000000,383.720000000,300,7085,1,8,382.820000000,383.740000000,1,37,1,1,382.810000000,383.800000000,20,10,2,1,382.700000000,383.880000000,50,4,1,1,382.230000000,384.000000000,25,1300,1,4,382.100000000,384.260000000,10,15,1,1,TSLA
2025-01-03T10:33:00.078219270Z,2025-01-03T10:33:00.078052716Z,10,2,16244,C,A,1,383.300000000,19,130,166554,4938244,383.080000000,383.250000000,16,47,1,1,382.990000000,383.420000000,30,140,1,1,382.900000000,383.600000000,20,500,1,1,382.880000000,383.720000000,100,7085,1,8,382.840000000,383.740000000,300,37,1,1,382.820000000,383.800000000,1,10,1,1,382.810000000,383.880000000,20,4,2,1,382.700000000,384.000000000,50,1300,1,4,382.230000000,384.260000000,25,15,1,1,382.100000000,384.400000000,10,1000,1,2,TSLA
2025-01-03T10:33:00.078283466Z,2025-01-03T10:33:00.078116418Z,10,2,16244,A,A,1,383.350000000,21,130,167048,4938245,383.080000000,383.250000000,16,47,1,1,382.990000000,383.350000000,30,21,1,1,382.900000000,383.420000000,20,140,1,1,382.880000000,383.600000000,100,500,1,1,382.840000000,383.720000000,300,7085,1,8,382.820000000,383.740000000,1,37,1,1,382.810000000,383.800000000,20,10,2,1,382.700000000,383.880000000,50,4,1,1,382.230000000,384.000000000,25,1300,1,4,382.100000000,384.260000000,10,15,1,1,TSLA
2025-01-03T10:33:00.078880716Z,2025-01-03T10:33:00.078714852Z,10,2,16244,C,A,1,383.350000000,21,130,165864,4938247,383.080000000,383.250000000,16,47,1,1,382.990000000,383.420000000,30,140,1,1,382.900000000,383.600000000,20,500,1,1,382.880000000,383.720000000,100,7085,1,8,382.840000000,383.740000000,300,37,1,1,382.820000000,383.800000000,1,10,1,1,382.810000000,383.880000000,20,4,2,1,382.700000000,384.000000000,50,1300,1,4,382.230000000,384.260000000,25,15,1,1,382.100000000,384.400000000,10,1000,1,2,TSLA
2025-01-03T10:33:00.120254017Z,2025-01-03T10:33:00.120087858Z,10,2,6905,C,A,0,91.930000000,7,130,166159,4938318,91.520000000,91.960000000,7,100,1,1,91.480000000,93.000000000,150,1,1,1,91.440000000,94.000000000,100,1,1,1,90.000000000,95.000000000,122,2,1,2,89.000000000,96.000000000,1,1,1,1,83.810000000,97.000000000,100,2,1,2,83.400000000,99.950000000,100,100,1,1,,100.360000000,0,100,0,1,,,0,0,0,0,,,0,0,0,0,GILD
2025-01-03T10:33:00.120323764Z,2025-01-03T10:33:00.120157377Z,10,2,6905,A,A,0,91.950000000,7,130,166387,4938319,91.520000000,91.950000000,7,7,1,1,91.480000000,91.960000000,150,100,1,1,91.440000000,93.000000000,100,1,1,1,90.000000000,94.000000000,122,1,1,1,89.000000000,95.000000000,1,2,1,2,83.810000000,96.000000000,100,1,1,1,83.400000000,97.000000000,100,2,1,2,,99.950000000,0,100,0,1,,100.360000000,0,100,0,1,,,0,0,0,0,GILD
2025-01-03T10:33:00.236713912Z,2025-01-03T10:33:00.236548012Z,10,2,11667,C,A,0,139.200000000,100,130,165900,4938483,139.170000000,139.200000000,1,2,1,1,139.160000000,139.220000000,100,10,1,1,139.150000000,139.230000000,9860,2277,2,4,139.130000000,139.250000000,2500,401,2,2,139.120000000,139.270000000,30,37,1,2,139.110000000,139.300000000,1,507,1,4,139.100000000,139.320000000,10,39,1,1,139.090000000,139.330000000,57,503,1,2,139.070000000,139.360000000,100,4,1,2,139.030000000,139.370000000,126,75,2,1,NVDA
2025-01-03T10:33:00.270426682Z,2025-01-03T10:33:00.270260861Z,10,2,16244,C,B,0,383.080000000,16,130,165821,4938565,382.990000000,383.250000000,30,47,1,1,382.900000000,383.420000000,20,140,1,1,382.880000000,383.600000000,100,500,1,1,382.840000000,383.720000000,300,7085,1,8,382.820000000,383.740000000,1,37,1,1,382.810000000,383.800000000,20,10,2,1,382.700000000,383.880000000,50,4,1,1,382.230000000,384.000000000,25,1300,1,4,382.100000000,384.260000000,10,15,1,1,382.010000000,384.400000000,2,1000,1,2,TSLA
2025-01-03T10:33:00.333262760Z,2025-01-03T10:33:00.333096129Z,10,2,16244,A,B,0,383.000000000,19,130,166631,4938609,383.000000000,383.250000000,19,47,1,1,382.990000000,383.420000000,30,140,1,1,382.900000000,383.600000000,20,500,1,1,382.880000000,383.720000000,100,7085,1,8,382.840000000,383.740000000,300,37,1,1,382.820000000,383.800000000,1,10,1,1,382.810000000,383.880000000,20,4,2,1,382.700000000,384.000000000,50,1300,1,4,382.230000000,384.260000000,25,15,1,1,382.100000000,384.400000000,10,1000,1,2,TSLA
2025-01-03T10:33:01.212314408Z,2025-01-03T10:33:01.212148156Z,10,2,9155,C,A,1,242.410000000,8,130,166252,4939461,241.670000000,242.070000000,2,62,1,1,241.500000000,242.850000000,8,300,1,2,241.120000000,242.900000000,81,100,1,1,241.000000000,243.000000000,100,92,1,2,240.000000000,243.310000000,10,10,1,1,238.000000000,243.700000000,30,100,1,1,236.000000000,246.810000000,6,100,1,1,235.500000000,262.740000000,5,100,1,1,235.000000000,263.830000000,5,100,1,1,232.880000000,,1,0,1,0,JPM
2025-01-03T10:33:01.212378297Z,2025-01-03T10:33:01.212212259Z,10,2,9155,A,A,1,242.370000000,8,130,166038,4939462,241.670000000,242.070000000,2,62,1,1,241.500000000,242.370000000,8,8,1,1,241.120000000,242.850000000,81,300,1,2,241.000000000,242.900000000,100,100,1,1,240.000000000,243.000000000,10,92,1,2,238.000000000,243.310000000,30,10,1,1,236.000000000,243.700000000,6,100,1,1,235.500000000,246.810000000,5,100,1,1,235.000000000,262.740000000,5,100,1,1,232.880000000,263.830000000,1,100,1,1,JPM
2025-01-03T10:33:01.360131403Z,2025-01-03T10:33:01.359965215Z,10,2,16244,A,A,2,383.500000000,23,130,166188,4939519,383.000000000,383.250000000,19,47,1,1,382.990000000,383.420000000,30,140,1,1,382.900000000,383.500000000,20,23,1,1,382.880000000,383.600000000,100,500,1,1,382.840000000,383.720000000,300,7085,1,8,382.820000000,383.740000000,1,37,1,1,382.810000000,383.800000000,20,10,2,1,382.700000000,383.880000000,50,4,1,1,382.230000000,384.000000000,25,1300,1,4,382.100000000,384.260000000,10,15,1,1,TSLA
2025-01-03T10:33:01.689870252Z,2025-01-03T10:33:01.689701794Z,10,2,11667,T,B,0,139.200000000,2,0,168458,4939815,139.170000000,139.200000000,1,2,1,1,139.160000000,139.220000000,100,10,1,1,139.150000000,139.230000000,9860,2277,2,4,139.130000000,139.250000000,2500,401,2,2,139.120000000,139.270000000,30,37,1,2,139.110000000,139.300000000,1,507,1,4,139.100000000,139.320000000,10,39,1,1,139.090000000,139.330000000,57,503,1,2,139.070000000,139.360000000,100,4,1,2,139.030000000,139.370000000,126,75,2,1,NVDA
2025-01-03T10:33:01.689870252Z,2025-01-03T10:33:01.689701794Z,10,2,11667,T,N,0,139.200000000,18,130,168458,4939816,139.170000000,139.220000000,1,10,1,1,139.160000000,139.230000000,100,2277,1,4,139.150000000,139.250000000,9860,401,2,2,139.130000000,139.270000000,2500,37,2,2,139.120000000,139.300000000,30,507,1,4,139.110000000,139.320000000,1,39,1,1,139.100000000,139.330000000,10,503,1,2,139.090000000,139.360000000,57,4,1,2,139.070000000,139.370000000,100,75,1,1,139.030000000,139.380000000,126,100,2,1,NVDA
2025-01-03T10:33:01.760992011Z,2025-01-03T10:33:01.760825871Z,10,2,11667,C,A,2,139.250000000,400,130,166140,4939847,139.170000000,139.220000000,1,10,1,1,139.160000000,139.230000000,100,2277,1,4,139.150000000,139.250000000,9860,1,2,1,139.130000000,139.270000000,2500,37,2,2,139.120000000,139.300000000,30,507,1,4,139.110000000,139.320000000,1,39,1,1,139.100000000,139.330000000,10,503,1,2,139.090000000,139.360000000,57,4,1,2,139.070000000,139.370000000,100,75,1,1,139.030000000,139.380000000,126,100,2,1,NVDA
2025-01-03T10:33:01.761005937Z,2025-01-03T10:33:01.760839636Z,10,2,11667,A,A,3,139.270000000,400,130,166301,4939848,139.170000000,139.220000000,1,10,1,1,139.160000000,139.230000000,100,2277,1,4,139.150000000,139.250000000,9860,1,2,1,139.130000000,139.270000000,2500,437,2,3,139.120000000,139.300000000,30,507,1,4,139.110000000,139.320000000,1,39,1,1,139.100000000,139.330000000,10,503,1,2,139.090000000,139.360000000,57,4,1,2,139.070000000,139.370000000,100,75,1,1,139.030000000,139.380000000,126,100,2,1,NVDA
2025-01-03T10:33:01.761325711Z,2025-01-03T10:33:01.761159629Z,10,2,9155,C,B,1,241.500000000,8,130,166082,4939849,241.670000000,242.070000000,2,62,1,1,241.120000000,242.370000000,81,8,1,1,241.000000000,242.850000000,100,300,1,2,240.000000000,242.900000000,10,100,1,1,238.000000000,243.000000000,30,92,1,2,236.000000000,243.310000000,6,10,1,1,235.500000000,243.700000000,5,100,1,1,235.000000000,246.810000000,5,100,1,1,232.880000000,262.740000000,1,100,1,1,231.110000000,263.830000000,3,100,1,1,JPM
2025-01-03T10:33:01.761385203Z,2025-01-03T10:33:01.761219099Z,10,2,9155,A,B,1,241.600000000,8,130,166104,4939850,241.670000000,242.070000000,2,62,1,1,241.600000000,242.370000000,8,8,1,1,241.120000000,242.850000000,81,300,1,2,241.000000000,242.900000000,100,100,1,1,240.000000000,243.000000000,10,92,1,2,238.000000000,243.310000000,30,10,1,1,236.000000000,243.700000000,6,100,1,1,235.500000000,246.810000000,5,100,1,1,235.000000000,262.740000000,5,100,1,1,232.880000000,263.830000000,1,100,1,1,JPM
2025-01-03T10:33:01.765703827Z,2025-01-03T10:33:01.765537296Z,10,2,11667,C,A,3,139.270000000,400,130,166531,4939853,139.170000000,139.220000000,1,10,1,1,139.160000000,139.230000000,100,2277,1,4,139.150000000,139.250000000,9860,1,2,1,139.130000000,139.270000000,2500,37,2,2,139.120000000,139.300000000,30,507,1,4,139.110000000,139.320000000,1,39,1,1,139.100000000,139.330000000,10,503,1,2,139.090000000,139.360000000,57,4,1,2,139.070000000,139.370000000,100,75,1,1,139.030000000,139.380000000,126,100,2,1,NVDA
2025-01-03T10:33:01.765716881Z,2025-01-03T10:33:01.765550464Z,10,2,11667,A,A,4,139.280000000,400,130,166417,4939854,139.170000000,139.220000000,1,10,1,1,139.160000000,139.230000000,100,2277,1,4,139.150000000,139.250000000,9860,1,2,1,139.130000000,139.270000000,2500,37,2,2,139.120000000,139.280000000,30,400,1,1,139.110000000,139.300000000,1,507,1,4,139.100000000,139.320000000,10,39,1,1,139.090000000,139.330000000,57,503,1,2,139.070000000,139.360000000,100,4,1,2,139.030000000,139.370000000,126,75,2,1,NVDA
2025-01-03T10:33:02.024638979Z,2025-01-03T10:33:02.024473007Z,10,2,38,C,A,0,243.730000000,100,130,165972,4939970,243.520000000,243.780000000,400,200,2,1,243.500000000,243.820000000,6,28,1,1,243.450000000,244.000000000,29,1,1,1,243.190000000,244.140000000,2,79,1,1,243.020000000,244.200000000,79,1000,1,1,243.000000000,244.400000000,1243,50,9,1,242.990000000,244.420000000,1,10,1,1,242.800000000,245.000000000,30,79,1,2,242.750000000,245.190000000,30,83,1,1,242.590000000,245.540000000,5,10,1,1,AAPL
2025-01-03T10:33:02.024838604Z,2025-01-03T10:33:02.024672559Z,10,2,38,C,A,4,244.200000000,1000,130,166045,4939972,243.520000000,243.780000000,400,200,2,1,243.500000000,243.820000000,6,28,1,1,243.450000000,244.000000000,29,1,1,1,243.190000000,244.140000000,2,79,1,1,243.020000000,244.400000000,79,50,1,1,243.000000000,244.420000000,1243,10,9,1,242.990000000,245.000000000,1,79,1,2,242.800000000,245.190000000,30,83,1,1,242.750000000,245.540000000,30,10,1,1,242.590000000,245.550000000,5,6,1,1,AAPL
2025-01-03T10:33:02.025632079Z,2025-01-03T10:33:02.025465715Z,10,2,38,A,A,0,243.680000000,100,130,166364,4939973,243.520000000,243.680000000,400,100,2,1,243.500000000,243.780000000,6,200,1,1,243.450000000,243.820000000,29,28,1,1,243.190000000,244.000000000,2,1,1,1,243.020000000,244.140000000,79,79,1,1,243.000000000,244.400000000,1243,50,9,1,242.990000000,244.420000000,1,10,1,1,242.800000000,245.000000000,30,79,1,2,242.750000000,245.190000000,30,83,1,1,242.590000000,245.540000000,5,10,1,1,AAPL
2025-01-03T10:33:02.036007693Z,2025-01-03T10:33:02.035841452Z,10,2,38,A,A,5,244.200000000,1000,130,166241,4939978,243.520000000,243.680000000,400,100,2,1,243.500000000,243.780000000,6,200,1,1,243.450000000,243.820000000,29,28,1,1,243.190000000,244.000000000,2,1,1,1,243.020000000,244.140000000,79,79,1,1,243.000000000,244.200000000,1243,1000,9,1,242.990000000,244.400000000,1,50,1,1,242.800000000,244.420000000,30,10,1,1,242.750000000,245.000000000,30,79,1,2,242.590000000,245.190000000,5,83,1,1,AAPL
2025-01-03T10:33:02.119441740Z,2025-01-03T10:33:02.119275862Z,10,2,16244,A,B,8,382.400000000,500,130,165878,4940066,383.000000000,383.250000000,19,47,1,1,382.990000000,383.420000000,30,140,1,1,382.900000000,383.500000000,20,23,1,1,382.880000000,383.600000000,100,500,1,1,382.840000000,383.720000000,300,7085,1,8,382.820000000,383.740000000,1,37,1,1,382.810000000,383.800000000,20,10,2,1,382.700000000,383.880000000,50,4,1,1,382.400000000,384.000000000,500,1300,1,4,382.230000000,384.260000000,25,15,1,1,TSLA
2025-01-03T10:33:03.737065110Z,2025-01-03T10:33:03.736898991Z,10,2,11667,A,A,2,139.250000000,400,130,166119,4940605,139.170000000,139.220000000,1,10,1,1,139.160000000,139.230000000,100,2277,1,4,139.150000000,139.250000000,9860,401,2,2,139.130000000,139.270000000,2500,37,2,2,139.120000000,139.300000000,30,507,1,4,139.110000000,139.320000000,1,39,1,1,139.100000000,139.330000000,10,503,1,2,139.090000000,139.360000000,57,4,1,2,139.070000000,139.370000000,100,75,1,1,139.030000000,139.380000000,126,100,2,1,NVDA
2025-01-03T10:33:03.832741001Z,2025-01-03T10:33:03.832573872Z,10,2,10888,T,N,0,420.960000000,2,130,167129,4940640,420.700000000,421.190000000,200,200,1,1,420.580000000,421.220000000,25,13,2,1,420.520000000,421.460000000,1,39,1,1,420.400000000,421.490000000,858,6,1,1,420.380000000,421.570000000,100,40,1,1,420.100000000,421.600000000,100,510,1,2,420.000000000,421.700000000,834,359,8,1,419.730000000,421.800000000,3,7,1,1,419.650000000,422.100000000,39,7,1,1,418.650000000,422.500000000,1,200,1,1,MSFT
2025-01-03T10:33:03.878093123Z,2025-01-03T10:33:03.877927145Z,10,2,11667,C,B,3,139.130000000,400,130,165978,4940657,139.170000000,139.220000000,1,10,1,1,139.160000000,139.230000000,100,2277,1,4,139.150000000,139.250000000,9860,401,2,2,139.130000000,139.270000000,2100,37,1,2,139.120000000,139.300000000,30,507,1,4,139.110000000,139.320000000,1,39,1,1,139.100000000,139.330000000,10,503,1,2,139.090000000,139.360000000,57,4,1,2,139.070000000,139.370000000,100,75,1,1,139.030000000,139.380000000,126,100,2,1,NVDA
2025-01-03T10:33:03.878186523Z,2025-01-03T10:33:03.878016201Z,10,2,11667,T,A,0,139.170000000,1,0,170322,4940658,139.170000000,139.220000000,1,10,1,1,139.160000000,139.230000000,100,2277,1,4,139.150000000,139.250000000,9860,401,2,2,139.130000000,139.270000000,2100,37,1,2,139.120000000,139.300000000,30,507,1,4,139.110000000,139.320000000,1,39,1,1,139.100000000,139.330000000,10,503,1,2,139.090000000,139.360000000,57,4,1,2,139.070000000,139.370000000,100,75,1,1,139.030000000,139.380000000,126,100,2,1,NVDA
2025-01-03T10:33:03.878186523Z,2025-01-03T10:33:03.878016201Z,10,2,11667,T,N,0,139.170000000,100,0,170322,4940659,139.160000000,139.220000000,100,10,1,1,139.150000000,139.230000000,9860,2277,2,4,139.130000000,139.250000000,2100,401,1,2,139.120000000,139.270000000,30,37,1,2,139.110000000,139.300000000,1,507,1,4,139.100000000,139.320000000,10,39,1,1,139.090000000,139.330000000,57,503,1,2,139.070000000,139.360000000,100,4,1,2,139.030000000,139.370000000,126,75,2,1,139.010000000,139.380000000,100,100,1,1,NVDA
2025-01-03T10:33:03.878186523Z,2025-01-03T10:33:03.878016201Z,10,2,11667,T,N,0,139.170000000,70,0,170322,4940660,139.160000000,139.220000000,100,10,1,1,139.150000000,139.230000000,9860,2277,2,4,139.130000000,139.250000000,2100,401,1,2,139.120000000,139.270000000,30,37,1,2,139.110000000,139.300000000,1,507,1,4,139.100000000,139.320000000,10,39,1,1,139.090000000,139.330000000,57,503,1,2,139.070000000,139.360000000,100,4,1,2,139.030000000,139.370000000,126,75,2,1,139.010000000,139.380000000,100,100,1,1,NVDA
2025-01-03T10:33:03.878186523Z,2025-01-03T10:33:03.878016201Z,10,2,11667,T,A,0,139.160000000,84,130,170322,4940661,139.160000000,139.220000000,100,10,1,1,139.150000000,139.230000000,9860,2277,2,4,139.130000000,139.250000000,2100,401,1,2,139.120000000,139.270000000,30,37,1,2,139.110000000,139.300000000,1,507,1,4,139.100000000,139.320000000,10,39,1,1,139.090000000,139.330000000,57,503,1,2,139.070000000,139.360000000,100,4,1,2,139.030000000,139.370000000,126,75,2,1,139.010000000,139.380000000,100,100,1,1,NVDA
2025-01-03T10:33:03.878186523Z,2025-01-03T10:33:03.878016201Z,10,2,11667,C,B,0,139.160000000,84,130,170322,4940661,139.160000000,139.220000000,16,10,1,1,139.150000000,139.230000000,9860,2277,2,4,139.130000000,139.250000000,2100,401,1,2,139.120000000,139.270000000,30,37,1,2,139.110000000,139.300000000,1,507,1,4,139.100000000,139.320000000,10,39,1,1,139.090000000,139.330000000,57,503,1,2,139.070000000,139.360000000,100,4,1,2,139.030000000,139.370000000,126,75,2,1,139.010000000,139.380000000,100,100,1,1,NVDA
2025-01-03T10:33:03.878213584Z,2025-01-03T10:33:03.878045960Z,10,2,11667,A,A,0,139.200000000,86,130,167624,4940662,139.160000000,139.200000000,16,86,1,1,139.150000000,139.220000000,9860,10,2,1,139.130000000,139.230000000,2100,2277,1,4,139.120000000,139.250000000,30,401,1,2,139.110000000,139.270000000,1,37,1,2,139.100000000,139.300000000,10,507,1,4,139.090000000,139.320000000,57,39,1,1,139.070000000,139.330000000,100,503,1,2,139.030000000,139.360000000,126,4,2,2,139.010000000,139.370000000,100,75,1,1,NVDA
2025-01-03T10:33:03.878226712Z,2025-01-03T10:33:03.878059697Z,10,2,11667,A,A,0,139.200000000,100,130,167015,4940664,139.160000000,139.200000000,16,186,1,2,139.150000000,139.220000000,9860,10,2,1,139.130000000,139.230000000,2100,2277,1,4,139.120000000,139.250000000,30,401,1,2,139.110000000,139.270000000,1,37,1,2,139.100000000,139.300000000,10,507,1,4,139.090000000,139.320000000,57,39,1,1,139.070000000,139.330000000,100,503,1,2,139.030000000,139.360000000,126,4,2,2,139.010000000,139.370000000,100,75,1,1,NVDA
2025-01-03T10:33:03.878230613Z,2025-01-03T10:33:03.878060860Z,10,2,11667,A,A,1,139.210000000,86,130,169753,4940665,139.160000000,139.200000000,16,186,1,2,139.150000000,139.210000000,9860,86,2,1,139.130000000,139.220000000,2100,10,1,1,139.120000000,139.230000000,30,2277,1,4,139.110000000,139.250000000,1,401,1,2,139.100000000,139.270000000,10,37,1,2,139.090000000,139.300000000,57,507,1,4,139.070000000,139.320000000,100,39,1,1,139.030000000,139.330000000,126,503,2,2,139.010000000,139.360000000,100,4,1,2,NVDA
2025-01-03T10:33:03.888454582Z,2025-01-03T10:33:03.888287878Z,10,2,11667,C,A,1,139.210000000,86,128,166704,4940800,139.160000000,139.200000000,16,186,1,2,139.150000000,139.220000000,9860,10,2,1,139.130000000,139.230000000,2100,2277,1,4,139.120000000,139.250000000,30,401,1,2,139.110000000,139.270000000,1,37,1,2,139.100000000,139.300000000,10,507,1,4,139.090000000,139.320000000,57,39,1,1,139.070000000,139.330000000,100,503,1,2,139.030000000,139.360000000,126,4,2,2,139.010000000,139.370000000,100,75,1,1,NVDA
2025-01-03T10:33:03.936204798Z,2025-01-03T10:33:03.936038325Z,10,2,11667,A,A,3,139.240000000,400,130,166473,4940859,139.160000000,139.200000000,16,186,1,2,139.150000000,139.220000000,9860,10,2,1,139.130000000,139.230000000,2100,2277,1,4,139.120000000,139.240000000,30,400,1,1,139.110000000,139.250000000,1,1,1,1,139.100000000,139.270000000,10,37,1,2,139.090000000,139.300000000,57,507,1,4,139.070000000,139.320000000,100,39,1,1,139.030000000,139.330000000,126,503,2,2,139.010000000,139.360000000,100,4,1,2,NVDA
2025-01-03T10:33:03.945304708Z,2025-01-03T10:33:03.945138283Z,10,2,11667,A,A,0,139.200000000,400,130,166425,4940866,139.160000000,139.200000000,16,586,1,3,139.150000000,139.220000000,9860,10,2,1,139.130000000,139.230000000,2100,2277,1,4,139.120000000,139.250000000,30,1,1,1,139.110000000,139.270000000,1,37,1,2,139.100000000,139.300000000,10,507,1,4,139.090000000,139.320000000,57,39,1,1,139.070000000,139.330000000,100,503,1,2,139.030000000,139.360000000,126,4,2,2,139.010000000,139.370000000,100,75,1,1,NVDA
2025-01-03T10:33:03.975632748Z,2025-01-03T10:33:03.975466491Z,10,2,38,A,A,2,243.810000000,29,130,166257,4940888,243.520000000,243.680000000,400,100,2,1,243.500000000,243.780000000,6,200,1,1,243.450000000,243.810000000,29,29,1,1,243.190000000,243.820000000,2,28,1,1,243.020000000,244.000000000,79,1,1,1,243.000000000,244.140000000,1243,79,9,1,242.990000000,244.200000000,1,1000,1,1,242.800000000,244.400000000,30,50,1,1,242.750000000,244.420000000,30,10,1,1,242.590000000,245.000000000,5,79,1,2,AAPL
2025-01-03T10:33:03.975659722Z,2025-01-03T10:33:03.975493818Z,10,2,38,C,A,3,243.820000000,28,130,165904,4940889,243.520000000,243.680000000,400,100,2,1,243.500000000,243.780000000,6,200,1,1,243.450000000,243.810000000,29,29,1,1,243.190000000,244.000000000,2,1,1,1,243.020000000,244.140000000,79,79,1,1,243.000000000,244.200000000,1243,1000,9,1,242.990000000,244.400000000,1,50,1,1,242.800000000,244.420000000,30,10,1,1,242.750000000,245.000000000,30,79,1,2,242.590000000,245.190000000,5,83,1,1,AAPL
2025-01-03T10:33:03.978994962Z,2025-01-03T10:33:03.978828609Z,10,2,11667,A,B,8,139.040000000,400,130,166353,4940890,139.160000000,139.200000000,16,586,1,3,139.150000000,139.220000000,9860,10,2,1,139.130000000,139.230000000,2100,2277,1,4,139.120000000,139.250000000,30,1,1,1,139.110000000,139.270000000,1,37,1,2,139.100000000,139.300000000,10,507,1,4,139.090000000,139.320000000,57,39,1,1,139.070000000,139.330000000,100,503,1,2,139.040000000,139.360000000,400,4,1,2,139.030000000,139.370000000,126,75,2,1,NVDA
2025-01-03T10:33:04.050706668Z,2025-01-03T10:33:04.050540842Z,10,2,11667,C,A,0,139.200000000,400,130,165826,4940952,139.160000000,139.200000000,16,186,1,2,139.150000000,139.220000000,9860,10,2,1,139.130000000,139.230000000,2100,2277,1,4,139.120000000,139.250000000,30,1,1,1,139.110000000,139.270000000,1,37,1,2,139.100000000,139.300000000,10,507,1,4,139.090000000,139.320000000,57,39,1,1,139.070000000,139.330000000,100,503,1,2,139.040000000,139.360000000,400,4,1,2,139.030000000,139.370000000,126,75,2,1,NVDA
2025-01-03T10:33:04.050720166Z,2025-01-03T10:33:04.050554060Z,10,2,11667,A,A,1,139.220000000,400,130,166106,4940953,139.160000000,139.200000000,16,186,1,2,139.150000000,139.220000000,9860,410,2,2,139.130000000,139.230000000,2100,2277,1,4,139.120000000,139.250000000,30,1,1,1,139.110000000,139.270000000,1,37,1,2,139.100000000,139.300000000,10,507,1,4,139.090000000,139.320000000,57,39,1,1,139.070000000,139.330000000,100,503,1,2,139.040000000,139.360000000,400,4,1,2,139.030000000,139.370000000,126,75,2,1,NVDA
2025-01-03T10:33:04.072264699Z,2025-01-03T10:33:04.072098416Z,10,2,11667,A,B,8,139.050000000,400,130,166283,4940975,139.160000000,139.200000000,16,186,1,2,139.150000000,139.220000000,9860,410,2,2,139.130000000,139.230000000,2100,2277,1,4,139.120000000,139.250000000,30,1,1,1,139.110000000,139.270000000,1,37,1,2,139.100000000,139.300000000,10,507,1,4,139.090000000,139.320000000,57,39,1,1,139.070000000,139.330000000,100,503,1,2,139.050000000,139.360000000,400,4,1,2,139.030000000,139.370000000,126,75,2,1,NVDA
2025-01-03T10:33:04.112270858Z,2025-01-03T10:33:04.112104564Z,10,2,11667,A,B,7,139.070000000,400,130,166294,4941001,139.160000000,139.200000000,16,186,1,2,139.150000000,139.220000000,9860,410,2,2,139.130000000,139.230000000,2100,2277,1,4,139.120000000,139.250000000,30,1,1,1,139.110000000,139.270000000,1,37,1,2,139.100000000,139.300000000,10,507,1,4,139.090000000,139.320000000,57,39,1,1,139.070000000,139.330000000,500,503,2,2,139.030000000,139.360000000,126,4,2,2,139.010000000,139.370000000,100,75,1,1,NVDA
2025-01-03T10:33:04.126256413Z,2025-01-03T10:33:04.126090359Z,10,2,10888,C,B,1,420.580000000,15,130,166054,4941023,420.700000000,421.190000000,200,200,1,1,420.580000000,421.220000000,10,13,1,1,420.520000000,421.460000000,1,39,1,1,420.400000000,421.490000000,858,6,1,1,420.380000000,421.570000000,100,40,1,1,420.100000000,421.600000000,100,510,1,2,420.000000000,421.700000000,834,359,8,1,419.730000000,421.800000000,3,7,1,1,419.650000000,422.100000000,39,7,1,1,418.650000000,422.500000000,1,200,1,1,MSFT
2025-01-03T10:33:04.126314605Z,2025-01-03T10:33:04.126148384Z,10,2,10888,A,B,1,420.590000000,13,130,166221,4941024,420.700000000,421.190000000,200,200,1,1,420.590000000,421.220000000,13,13,1,1,420.580000000,421.460000000,10,39,1,1,420.520000000,421.490000000,1,6,1,1,420.400000000,421.570000000,858,40,1,1,420.380000000,421.600000000,100,510,1,2,420.100000000,421.700000000,100,359,1,1,420.000000000,421.800000000,834,7,8,1,419.730000000,422.100000000,3,7,1,1,419.650000000,422.500000000,39,200,1,1,MSFT
2025-01-03T10:33:04.128453624Z,2025-01-03T10:33:04.128287779Z,10,2,11667,C,A,0,139.200000000,86,130,165845,4941029,139.160000000,139.200000000,16,100,1,1,139.150000000,139.220000000,9860,410,2,2,139.130000000,139.230000000,2100,2277,1,4,139.120000000,139.250000000,30,1,1,1,139.110000000,139.270000000,1,37,1,2,139.100000000,139.300000000,10,507,1,4,139.090000000,139.320000000,57,39,1,1,139.070000000,139.330000000,500,503,2,2,139.030000000,139.360000000,126,4,2,2,139.010000000,139.370000000,100,75,1,1,NVDA
2025-01-03T10:33:04.488164645Z,2025-01-03T10:33:04.487998235Z,10,2,16244,C,B,2,382.900000000,20,130,166410,4941267,383.000000000,383.250000000,19,47,1,1,382.990000000,383.420000000,30,140,1,1,382.880000000,383.500000000,100,23,1,1,382.840000000,383.600000000,300,500,1,1,382.820000000,383.720000000,1,7085,1,8,382.810000000,383.740000000,20,37,2,1,382.700000000,383.800000000,50,10,1,1,382.400000000,383.880000000,500,4,1,1,382.230000000,384.000000000,25,1300,1,4,382.100000000,384.260000000,10,15,1,1,TSLA
2025-01-03T10:33:04.488253078Z,2025-01-03T10:33:04.488086753Z,10,2,16244,A,B,2,382.960000000,19,130,166325,4941268,383.000000000,383.250000000,19,47,1,1,382.990000000,383.420000000,30,140,1,1,382.960000000,383.500000000,19,23,1,1,382.880000000,383.600000000,100,500,1,1,382.840000000,383.720000000,300,7085,1,8,382.820000000,383.740000000,1,37,1,1,382.810000000,383.800000000,20,10,2,1,382.700000000,383.880000000,50,4,1,1,382.400000000,384.000000000,500,1300,1,4,382.230000000,384.260000000,25,15,1,1,TSLA
2025-01-03T10:33:04.895442690Z,2025-01-03T10:33:04.895276759Z,10,2,11667,C,A,1,139.220000000,400,130,165931,4941460,139.160000000,139.200000000,16,100,1,1,139.150000000,139.220000000,9860,10,2,1,139.130000000,139.230000000,2100,2277,1,4,139.120000000,139.250000000,30,1,1,1,139.110000000,139.270000000,1,37,1,2,139.100000000,139.300000000,10,507,1,4,139.090000000,139.320000000,57,39,1,1,139.070000000,139.330000000,500,503,2,2,139.030000000,139.360000000,126,4,2,2,139.010000000,139.370000000,100,75,1,1,NVDA
2025-01-03T10:33:04.895456368Z,2025-01-03T10:33:04.895290232Z,10,2,11667,A,A,2,139.230000000,400,130,166136,4941461,139.160000000,139.200000000,16,100,1,1,139.150000000,139.220000000,9860,10,2,1,139.130000000,139.230000000,2100,2677,1,5,139.120000000,139.250000000,30,1,1,1,139.110000000,139.270000000,1,37,1,2,139.100000000,139.300000000,10,507,1,4,139.090000000,139.320000000,57,39,1,1,139.070000000,139.330000000,500,503,2,2,139.030000000,139.360000000,126,4,2,2,139.010000000,139.370000000,100,75,1,1,NVDA
2025-01-03T10:33:04.937410840Z,2025-01-03T10:33:04.937244258Z,10,2,11667,A,B,4,139.110000000,400,130,166582,4941550,139.160000000,139.200000000,16,100,1,1,139.150000000,139.220000000,9860,10,2,1,139.130000000,139.230000000,2100,2677,1,5,139.120000000,139.250000000,30,1,1,1,139.110000000,139.270000000,401,37,2,2,139.100000000,139.300000000,10,507,1,4,139.090000000,139.320000000,57,39,1,1,139.070000000,139.330000000,100,503,1,2,139.030000000,139.360000000,126,4,2,2,139.010000000,139.370000000,100,75,1,1,NVDA
2025-01-03T10:33:04.986972601Z,2025-01-03T10:33:04.986806760Z,10,2,10888,C,B,0,420.700000000,200,130,165841,4941573,420.590000000,421.190000000,13,200,1,1,420.580000000,421.220000000,10,13,1,1,420.520000000,421.460000000,1,39,1,1,420.400000000,421.490000000,858,6,1,1,420.380000000,421.570000000,100,40,1,1,420.100000000,421.600000000,100,510,1,2,420.000000000,421.700000000,834,359,8,1,419.730000000,421.800000000,3,7,1,1,419.650000000,422.100000000,39,7,1,1,418.650000000,422.500000000,1,200,1,1,MSFT
2025-01-03T10:33:04.986986381Z,2025-01-03T10:33:04.986820174Z,10,2,10888,A,B,2,420.530000000,200,130,166207,4941574,420.590000000,421.190000000,13,200,1,1,420.580000000,421.220000000,10,13,1,1,420.530000000,421.460000000,200,39,1,1,420.520000000,421.490000000,1,6,1,1,420.400000000,421.570000000,858,40,1,1,420.380000000,421.600000000,100,510,1,2,420.100000000,421.700000000,100,359,1,1,420.000000000,421.800000000,834,7,8,1,419.730000000,422.100000000,3,7,1,1,419.650000000,422.500000000,39,200,1,1,MSFT
2025-01-03T10:33:04.987490926Z,2025-01-03T10:33:04.987325127Z,10,2,10888,C,B,0,420.590000000,13,130,165799,4941575,420.580000000,421.190000000,10,200,1,1,420.530000000,421.220000000,200,13,1,1,420.520000000,421.460000000,1,39,1,1,420.400000000,421.490000000,858,6,1,1,420.380000000,421.570000000,100,40,1,1,420.100000000,421.600000000,100,510,1,2,420.000000000,421.700000000,834,359,8,1,419.730000000,421.800000000,3,7,1,1,419.650000000,422.100000000,39,7,1,1,418.650000000,422.500000000,1,200,1,1,MSFT
2025-01-03T10:33:04.987549307Z,2025-01-03T10:33:04.987382997Z,10,2,10888,A,B,1,420.530000000,13,130,166310,4941576,420.580000000,421.190000000,10,200,1,1,420.530000000,421.220000000,213,13,2,1,420.520000000,421.460000000,1,39,1,1,420.400000000,421.490000000,858,6,1,1,420.380000000,421.570000000,100,40,1,1,420.100000000,421.600000000,100,510,1,2,420.000000000,421.700000000,834,359,8,1,419.730000000,421.800000000,3,7,1,1,419.650000000,422.100000000,39,7,1,1,418.650000000,422.500000000,1,200,1,1,MSFT
2025-01-03T10:33:05.868466282Z,2025-01-03T10:33:05.868300253Z,10,2,17709,C,A,1,107.870000000,17,130,166029,4942050,107.600000000,107.840000000,50,400,1,2,107.550000000,107.870000000,15,242,1,1,107.520000000,107.940000000,100,100,1,1,107.050000000,107.950000000,247,10,1,1,107.000000000,108.000000000,1,50,1,1,106.240000000,108.300000000,28,50,1,1,106.000000000,108.550000000,15,50,2,1,105.870000000,108.800000000,141,50,1,1,103.180000000,108.880000000,16,28,1,1,103.000000000,109.000000000,3,100,1,1,XOM
2025-01-03T10:33:05.868527866Z,2025-01-03T10:33:05.868361743Z,10,2,17709,A,A,1,107.850000000,16,130,166123,4942051,107.600000000,107.840000000,50,400,1,2,107.550000000,107.850000000,15,16,1,1,107.520000000,107.870000000,100,242,1,1,107.050000000,107.940000000,247,100,1,1,107.000000000,107.950000000,1,10,1,1,106.240000000,108.000000000,28,50,1,1,106.000000000,108.300000000,15,50,2,1,105.870000000,108.550000000,141,50,1,1,103.180000000,108.800000000,16,50,1,1,103.000000000,108.880000000,3,28,1,1,XOM
2025-01-03T10:33:05.869223861Z,2025-01-03T10:33:05.869057970Z,10,2,17709,C,A,1,107.850000000,16,130,165891,4942052,107.600000000,107.840000000,50,400,1,2,107.550000000,107.870000000,15,242,1,1,107.520000000,107.940000000,100,100,1,1,107.050000000,107.950000000,247,10,1,1,107.000000000,108.000000000,1,50,1,1,106.240000000,108.300000000,28,50,1,1,106.000000000,108.550000000,15,50,2,1,105.870000000,108.800000000,141,50,1,1,103.180000000,108.880000000,16,28,1,1,103.000000000,109.000000000,3,100,1,1,XOM
2025-01-03T10:33:06.986036378Z,2025-01-03T10:33:06.985869722Z,10,2,10888,A,A,0,421.180000000,200,130,166656,4942623,420.580000000,421.180000000,10,200,1,1,420.530000000,421.220000000,213,13,2,1,420.520000000,421.460000000,1,39,1,1,420.400000000,421.490000000,858,6,1,1,420.380000000,421.570000000,100,40,1,1,420.100000000,421.600000000,100,510,1,2,420.000000000,421.700000000,834,359,8,1,419.730000000,421.800000000,3,7,1,1,419.650000000,422.100000000,39,7,1,1,418.650000000,422.500000000,1,200,1,1,MSFT
2025-01-03T10:33:06.986926375Z,2025-01-03T10:33:06.986759370Z,10,2,38,A,A,1,243.770000000,200,130,167005,4942627,243.520000000,243.680000000,400,100,2,1,243.500000000,243.770000000,6,200,1,1,243.450000000,243.810000000,29,29,1,1,243.190000000,244.000000000,2,1,1,1,243.020000000,244.140000000,79,79,1,1,243.000000000,244.200000000,1243,1000,9,1,242.990000000,244.400000000,1,50,1,1,242.800000000,244.420000000,30,10,1,1,242.750000000,245.000000000,30,79,1,2,242.590000000,245.190000000,5,83,1,1,AAPL
2025-01-03T10:33:07.069680319Z,2025-01-03T10:33:07.069514229Z,10,2,17709,A,A,1,107.870000000,15,130,166090,4942731,107.600000000,107.840000000,50,400,1,2,107.550000000,107.870000000,15,257,1,2,107.520000000,107.940000000,100,100,1,1,107.050000000,107.950000000,247,10,1,1,107.000000000,108.000000000,1,50,1,1,106.240000000,108.300000000,28,50,1,1,106.000000000,108.550000000,15,50,2,1,105.870000000,108.800000000,141,50,1,1,103.180000000,108.880000000,16,28,1,1,103.000000000,109.000000000,3,100,1,1,XOM
2025-01-03T10:33:07.078947190Z,2025-01-03T10:33:07.078781375Z,10,2,16244,C,A,2,383.500000000,23,130,165815,4942733,383.000000000,383.250000000,19,47,1,1,382.990000000,383.420000000,30,140,1,1,382.960000000,383.600000000,19,500,1,1,382.880000000,383.720000000,100,7085,1,8,382.840000000,383.740000000,300,37,1,1,382.820000000,383.800000000,1,10,1,1,382.810000000,383.880000000,20,4,2,1,382.700000000,384.000000000,50,1300,1,4,382.400000000,384.260000000,500,15,1,1,382.230000000,384.400000000,25,1000,1,2,TSLA
2025-01-03T10:33:07.079007613Z,2025-01-03T10:33:07.078841671Z,10,2,16244,A,A,2,383.490000000,21,130,165942,4942734,383.000000000,383.250000000,19,47,1,1,382.990000000,383.420000000,30,140,1,1,382.960000000,383.490000000,19,21,1,1,382.880000000,383.600000000,100,500,1,1,382.840000000,383.720000000,300,7085,1,8,382.820000000,383.740000000,1,37,1,1,382.810000000,383.800000000,20,10,2,1,382.700000000,383.880000000,50,4,1,1,382.400000000,384.000000000,500,1300,1,4,382.230000000,384.260000000,25,15,1,1,TSLA
2025-01-03T10:33:07.777820715Z,2025-01-03T10:33:07.777654958Z,10,2,10888,C,B,1,420.530000000,200,130,165757,4943220,420.580000000,421.180000000,10,200,1,1,420.530000000,421.220000000,13,13,1,1,420.520000000,421.460000000,1,39,1,1,420.400000000,421.490000000,858,6,1,1,420.380000000,421.570000000,100,40,1,1,420.100000000,421.600000000,100,510,1,2,420.000000000,421.700000000,834,359,8,1,419.730000000,421.800000000,3,7,1,1,419.650000000,422.100000000,39,7,1,1,418.650000000,422.500000000,1,200,1,1,MSFT
2025-01-03T10:33:07.777830787Z,2025-01-03T10:33:07.777664774Z,10,2,10888,A,B,3,420.500000000,200,130,166013,4943221,420.580000000,421.180000000,10,200,1,1,420.530000000,421.220000000,13,13,1,1,420.520000000,421.460000000,1,39,1,1,420.500000000,421.490000000,200,6,1,1,420.400000000,421.570000000,858,40,1,1,420.380000000,421.600000000,100,510,1,2,420.100000000,421.700000000,100,359,1,1,420.000000000,421.800000000,834,7,8,1,419.730000000,422.100000000,3,7,1,1,419.650000000,422.500000000,39,200,1,1,MSFT
2025-01-03T10:33:07.832177581Z,2025-01-03T10:33:07.832011453Z,10,2,10888,A,A,0,421.170000000,200,130,166128,4943364,420.580000000,421.170000000,10,200,1,1,420.530000000,421.220000000,13,13,1,1,420.520000000,421.460000000,1,39,1,1,420.500000000,421.490000000,200,6,1,1,420.400000000,421.570000000,858,40,1,1,420.380000000,421.600000000,100,510,1,2,420.100000000,421.700000000,100,359,1,1,420.000000000,421.800000000,834,7,8,1,419.730000000,422.100000000,3,7,1,1,419.650000000,422.500000000,39,200,1,1,MSFT
2025-01-03T10:33:07.838492469Z,2025-01-03T10:33:07.838326697Z,10,2,17709,C,A,1,107.870000000,15,130,165772,4943410,107.600000000,107.840000000,50,400,1,2,107.550000000,107.870000000,15,242,1,1,107.520000000,107.940000000,100,100,1,1,107.050000000,107.950000000,247,10,1,1,107.000000000,108.000000000,1,50,1,1,106.240000000,108.300000000,28,50,1,1,106.000000000,108.550000000,15,50,2,1,105.870000000,108.800000000,141,50,1,1,103.180000000,108.880000000,16,28,1,1,103.000000000,109.000000000,3,100,1,1,XOM
2025-01-03T10:33:07.838555541Z,2025-01-03T10:33:07.838389473Z,10,2,17709,A,A,1,107.860000000,16,130,166068,4943411,107.600000000,107.840000000,50,400,1,2,107.550000000,107.860000000,15,16,1,1,107.520000000,107.870000000,100,242,1,1,107.050000000,107.940000000,247,100,1,1,107.000000000,107.950000000,1,10,1,1,106.240000000,108.000000000,28,50,1,1,106.000000000,108.300000000,15,50,2,1,105.870000000,108.550000000,141,50,1,1,103.180000000,108.800000000,16,50,1,1,103.000000000,108.880000000,3,28,1,1,XOM
2025-01-03T10:33:07.852330564Z,2025-01-03T10:33:07.852164568Z,10,2,9155,C,A,1,242.370000000,8,130,165996,4943451,241.670000000,242.070000000,2,62,1,1,241.600000000,242.850000000,8,300,1,2,241.120000000,242.900000000,81,100,1,1,241.000000000,243.000000000,100,92,1,2,240.000000000,243.310000000,10,10,1,1,238.000000000,243.700000000,30,100,1,1,236.000000000,246.810000000,6,100,1,1,235.500000000,262.740000000,5,100,1,1,235.000000000,263.830000000,5,100,1,1,232.880000000,,1,0,1,0,JPM
2025-01-03T10:33:07.852388749Z,2025-01-03T10:33:07.852222617Z,10,2,9155,A,A,1,242.360000000,8,130,166132,4943452,241.670000000,242.070000000,2,62,1,1,241.600000000,242.360000000,8,8,1,1,241.120000000,242.850000000,81,300,1,2,241.000000000,242.900000000,100,100,1,1,240.000000000,243.000000000,10,92,1,2,238.000000000,243.310000000,30,10,1,1,236.000000000,243.700000000,6,100,1,1,235.500000000,246.810000000,5,100,1,1,235.000000000,262.740000000,5,100,1,1,232.880000000,263.830000000,1,100,1,1,JPM
2025-01-03T10:33:07.954254131Z,2025-01-03T10:33:07.954087797Z,10,2,10888,A,B,3,420.510000000,200,130,166334,4943561,420.580000000,421.170000000,10,200,1,1,420.530000000,421.220000000,13,13,1,1,420.520000000,421.460000000,1,39,1,1,420.510000000,421.490000000,200,6,1,1,420.400000000,421.570000000,858,40,1,1,420.380000000,421.600000000,100,510,1,2,420.100000000,421.700000000,100,359,1,1,420.000000000,421.800000000,834,7,8,1,419.730000000,422.100000000,3,7,1,1,419.650000000,422.500000000,39,200,1,1,MSFT
2025-01-03T10:33:07.964252137Z,2025-01-03T10:33:07.964086090Z,10,2,10888,A,B,2,420.520000000,200,130,166047,4943581,420.580000000,421.170000000,10,200,1,1,420.530000000,421.220000000,13,13,1,1,420.520000000,421.460000000,201,39,2,1,420.400000000,421.490000000,858,6,1,1,420.380000000,421.570000000,100,40,1,1,420.100000000,421.600000000,100,510,1,2,420.000000000,421.700000000,834,359,8,1,419.730000000,421.800000000,3,7,1,1,419.650000000,422.100000000,39,7,1,1,418.650000000,422.500000000,1,200,1,1,MSFT
2025-01-03T10:33:07.980073332Z,2025-01-03T10:33:07.979907507Z,10,2,10888,C,B,1,420.530000000,13,130,165825,4943660,420.580000000,421.170000000,10,200,1,1,420.520000000,421.220000000,201,13,2,1,420.400000000,421.460000000,858,39,1,1,420.380000000,421.490000000,100,6,1,1,420.100000000,421.570000000,100,40,1,1,420.000000000,421.600000000,834,510,8,2,419.730000000,421.700000000,3,359,1,1,419.650000000,421.800000000,39,7,1,1,418.650000000,422.100000000,1,7,1,1,418.500000000,422.500000000,1,200,1,1,MSFT
2025-01-03T10:33:07.980135775Z,2025-01-03T10:33:07.979969392Z,10,2,10888,A,B,1,420.540000000,14,130,166383,4943661,420.580000000,421.170000000,10,200,1,1,420.540000000,421.220000000,14,13,1,1,420.520000000,421.460000000,201,39,2,1,420.400000000,421.490000000,858,6,1,1,420.380000000,421.570000000,100,40,1,1,420.100000000,421.600000000,100,510,1,2,420.000000000,421.700000000,834,359,8,1,419.730000000,421.800000000,3,7,1,1,419.650000000,422.100000000,39,7,1,1,418.650000000,422.500000000,1,200,1,1,MSFT
2025-01-03T10:33:07.982303738Z,2025-01-03T10:33:07.982137442Z,10,2,9155,A,B,1,241.610000000,8,130,166296,4943676,241.670000000,242.070000000,2,62,1,1,241.610000000,242.360000000,8,8,1,1,241.600000000,242.850000000,8,300,1,2,241.120000000,242.900000000,81,100,1,1,241.000000000,243.000000000,100,92,1,2,240.000000000,243.310000000,10,10,1,1,238.000000000,243.700000000,30,100,1,1,236.000000000,246.810000000,6,100,1,1,235.500000000,262.740000000,5,100,1,1,235.000000000,263.830000000,5,100,1,1,JPM
2025-01-03T10:33:07.982355848Z,2025-01-03T10:33:07.982189918Z,10,2,9155,C,B,2,241.600000000,8,130,165930,4943677,241.670000000,242.070000000,2,62,1,1,241.610000000,242.360000000,8,8,1,1,241.120000000,242.850000000,81,300,1,2,241.000000000,242.900000000,100,100,1,1,240.000000000,243.000000000,10,92,1,2,238.000000000,243.310000000,30,10,1,1,236.000000000,243.700000000,6,100,1,1,235.500000000,246.810000000,5,100,1,1,235.000000000,262.740000000,5,100,1,1,232.880000000,263.830000000,1,100,1,1,JPM
2025-01-03T10:33:07.997050541Z,2025-01-03T10:33:07.996884256Z,10,2,16727,C,B,0,314.930000000,8,130,166285,4943736,314.860000000,315.460000000,25,8,1,1,314.420000000,315.510000000,61,25,1,1,313.500000000,315.750000000,1,61,1,1,310.000000000,320.000000000,1,5,1,1,300.000000000,320.210000000,3,1,1,1,290.000000000,321.950000000,2,2,1,1,286.660000000,344.200000000,100,100,1,1,285.250000000,345.620000000,100,100,1,1,260.000000000,,2,0,1,0,,,0,0,0,0,V
2025-01-03T10:33:07.997110763Z,2025-01-03T10:33:07.996944048Z,10,2,16727,A,B,0,314.940000000,8,130,166715,4943737,314.940000000,315.460000000,8,8,1,1,314.860000000,315.510000000,25,25,1,1,314.420000000,315.750000000,61,61,1,1,313.500000000,320.000000000,1,5,1,1,310.000000000,320.210000000,1,1,1,1,300.000000000,321.950000000,3,2,1,1,290.000000000,344.200000000,2,100,1,1,286.660000000,345.620000000,100,100,1,1,285.250000000,,100,0,1,0,260.000000000,,2,0,1,0,V
2025-01-03T10:33:07.997310180Z,2025-01-03T10:33:07.997143974Z,10,2,12463,C,A,0,150.800000000,9,130,166206,4943738,150.460000000,150.840000000,1,100,1,1,150.310000000,151.000000000,9,1,1,1,150.260000000,153.280000000,234,10,1,1,150.250000000,163.540000000,1,100,1,1,150.210000000,164.210000000,113,100,2,1,150.020000000,179.000000000,2,5,1,1,150.000000000,,250,0,1,0,149.950000000,,5,0,1,0,149.740000000,,10,0,1,0,149.000000000,,5,0,1,0,PEP
2025-01-03T10:33:07.997490971Z,2025-01-03T10:33:07.997324859Z,10,2,12463,A,A,0,150.820000000,9,130,166112,4943739,150.460000000,150.820000000,1,9,1,1,150.310000000,150.840000000,9,100,1,1,150.260000000,151.000000000,234,1,1,1,150.250000000,153.280000000,1,10,1,1,150.210000000,163.540000000,113,100,2,1,150.020000000,164.210000000,2,100,1,1,150.000000000,179.000000000,250,5,1,1,149.950000000,,5,0,1,0,149.740000000,,10,0,1,0,149.000000000,,5,0,1,0,PEP
2025-01-03T10:33:08.042266134Z,2025-01-03T10:33:08.042099485Z,10,2,10888,A,B,0,420.670000000,200,130,166649,4943809,420.670000000,421.170000000,200,200,1,1,420.580000000,421.220000000,10,13,1,1,420.540000000,421.460000000,14,39,1,1,420.520000000,421.490000000,1,6,1,1,420.400000000,421.570000000,858,40,1,1,420.380000000,421.600000000,100,510,1,2,420.100000000,421.700000000,100,359,1,1,420.000000000,421.800000000,834,7,8,1,419.730000000,422.100000000,3,7,1,1,419.650000000,422.500000000,39,200,1,1,MSFT
2025-01-03T10:33:08.412158797Z,2025-01-03T10:33:08.411992465Z,10,2,16244,C,A,2,383.490000000,21,130,166332,4943945,383.000000000,383.250000000,19,47,1,1,382.990000000,383.420000000,30,140,1,1,382.960000000,383.600000000,19,500,1,1,382.880000000,383.720000000,100,7085,1,8,382.840000000,383.740000000,300,37,1,1,382.820000000,383.800000000,1,10,1,1,382.810000000,383.880000000,20,4,2,1,382.700000000,384.000000000,50,1300,1,4,382.400000000,384.260000000,500,15,1,1,382.230000000,384.400000000,25,1000,1,2,TSLA
2025-01-03T10:33:08.412266890Z,2025-01-03T10:33:08.412100568Z,10,2,16244,A,A,2,383.460000000,20,130,166322,4943946,383.000000000,383.250000000,19,47,1,1,382.990000000,383.420000000,30,140,1,1,382.960000000,383.460000000,19,20,1,1,382.880000000,383.600000000,100,500,1,1,382.840000000,383.720000000,300,7085,1,8,382.820000000,383.740000000,1,37,1,1,382.810000000,383.800000000,20,10,2,1,382.700000000,383.880000000,50,4,1,1,382.400000000,384.000000000,500,1300,1,4,382.230000000,384.260000000,25,15,1,1,TSLA
2025-01-03T10:33:09.375500324Z,2025-01-03T10:33:09.375334012Z,10,2,16244,C,A,2,383.460000000,20,130,166312,4944243,383.000000000,383.250000000,19,47,1,1,382.990000000,383.420000000,30,140,1,1,382.960000000,383.600000000,19,500,1,1,382.880000000,383.720000000,100,7085,1,8,382.840000000,383.740000000,300,37,1,1,382.820000000,383.800000000,1,10,1,1,382.810000000,383.880000000,20,4,2,1,382.700000000,384.000000000,50,1300,1,4,382.400000000,384.260000000,500,15,1,1,382.230000000,384.400000000,25,1000,1,2,TSLA
2025-01-03T10:33:09.891592471Z,2025-01-03T10:33:09.891426024Z,10,2,10888,C,B,2,420.540000000,14,130,166447,4944394,420.670000000,421.170000000,200,200,1,1,420.580000000,421.220000000,10,13,1,1,420.520000000,421.460000000,1,39,1,1,420.400000000,421.490000000,858,6,1,1,420.380000000,421.570000000,100,40,1,1,420.100000000,421.600000000,100,510,1,2,420.000000000,421.700000000,834,359,8,1,419.730000000,421.800000000,3,7,1,1,419.650000000,422.100000000,39,7,1,1,418.650000000,422.500000000,1,200,1,1,MSFT
2025-01-03T10:33:09.891681971Z,2025-01-03T10:33:09.891515555Z,10,2,10888,A,B,1,420.590000000,14,130,166416,4944395,420.670000000,421.170000000,200,200,1,1,420.590000000,421.220000000,14,13,1,1,420.580000000,421.460000000,10,39,1,1,420.520000000,421.490000000,1,6,1,1,420.400000000,421.570000000,858,40,1,1,420.380000000,421.600000000,100,510,1,2,420.100000000,421.700000000,100,359,1,1,420.000000000,421.800000000,834,7,8,1,419.730000000,422.100000000,3,7,1,1,419.650000000,422.500000000,39,200,1,1,MSFT
2025-01-03T10:33:10.299104712Z,2025-01-03T10:33:10.298938130Z,10,2,38,A,A,1,243.760000000,200,130,166582,4944537,243.520000000,243.680000000,400,100,2,1,243.500000000,243.760000000,6,200,1,1,243.450000000,243.810000000,29,29,1,1,243.190000000,244.000000000,2,1,1,1,243.020000000,244.140000000,79,79,1,1,243.000000000,244.200000000,1243,1000,9,1,242.990000000,244.400000000,1,50,1,1,242.800000000,244.420000000,30,10,1,1,242.750000000,245.000000000,30,79,1,2,242.590000000,245.190000000,5,83,1,1,AAPL
2025-01-03T10:33:10.418943362Z,2025-01-03T10:33:10.418775919Z,10,2,16244,T,N,0,383.210000000,40,130,167443,4944647,383.000000000,383.250000000,19,47,1,1,382.990000000,383.420000000,30,140,1,1,382.960000000,383.600000000,19,500,1,1,382.880000000,383.720000000,100,7085,1,8,382.840000000,383.740000000,300,37,1,1,382.820000000,383.800000000,1,10,1,1,382.810000000,383.880000000,20,4,2,1,382.700000000,384.000000000,50,1300,1,4,382.400000000,384.260000000,500,15,1,1,382.230000000,384.400000000,25,1000,1,2,TSLA
2025-01-03T10:33:10.868827988Z,2025-01-03T10:33:10.868662052Z,10,2,17709,C,A,1,107.860000000,16,130,165936,4944782,107.600000000,107.840000000,50,400,1,2,107.550000000,107.870000000,15,242,1,1,107.520000000,107.940000000,100,100,1,1,107.050000000,107.950000000,247,10,1,1,107.000000000,108.000000000,1,50,1,1,106.240000000,108.300000000,28,50,1,1,106.000000000,108.550000000,15,50,2,1,105.870000000,108.800000000,141,50,1,1,103.180000000,108.880000000,16,28,1,1,103.000000000,109.000000000,3,100,1,1,XOM
2025-01-03T10:33:10.909287632Z,2025-01-03T10:33:10.909121686Z,10,2,38,C,A,0,243.680000000,100,130,165946,4944787,243.520000000,243.760000000,400,200,2,1,243.500000000,243.810000000,6,29,1,1,243.450000000,244.000000000,29,1,1,1,243.190000000,244.140000000,2,79,1,1,243.020000000,244.200000000,79,1000,1,1,243.000000000,244.400000000,1243,50,9,1,242.990000000,244.420000000,1,10,1,1,242.800000000,245.000000000,30,79,1,2,242.750000000,245.190000000,30,83,1,1,242.590000000,245.540000000,5,10,1,1,AAPL
2025-01-03T10:33:10.910445947Z,2025-01-03T10:33:10.910279507Z,10,2,38,A,A,0,243.660000000,100,130,166440,4944788,243.520000000,243.660000000,400,100,2,1,243.500000000,243.760000000,6,200,1,1,243.450000000,243.810000000,29,29,1,1,243.190000000,244.000000000,2,1,1,1,243.020000000,244.140000000,79,79,1,1,243.000000000,244.200000000,1243,1000,9,1,242.990000000,244.400000000,1,50,1,1,242.800000000,244.420000000,30,10,1,1,242.750000000,245.000000000,30,79,1,2,242.590000000,245.190000000,5,83,1,1,AAPL
2025-01-03T10:33:10.982314277Z,2025-01-03T10:33:10.982148111Z,10,2,38,C,B,0,243.520000000,200,130,166166,4944812,243.520000000,243.660000000,200,100,1,1,243.500000000,243.760000000,6,200,1,1,243.450000000,243.810000000,29,29,1,1,243.190000000,244.000000000,2,1,1,1,243.020000000,244.140000000,79,79,1,1,243.000000000,244.200000000,1243,1000,9,1,242.990000000,244.400000000,1,50,1,1,242.800000000,244.420000000,30,10,1,1,242.750000000,245.000000000,30,79,1,2,242.590000000,245.190000000,5,83,1,1,AAPL
2025-01-03T10:33:10.982325044Z,2025-01-03T10:33:10.982158857Z,10,2,38,C,B,0,243.520000000,200,130,166187,4944813,243.500000000,243.660000000,6,100,1,1,243.450000000,243.760000000,29,200,1,1,243.190000000,243.810000000,2,29,1,1,243.020000000,244.000000000,79,1,1,1,243.000000000,244.140000000,1243,79,9,1,242.990000000,244.200000000,1,1000,1,1,242.800000000,244.400000000,30,50,1,1,242.750000000,244.420000000,30,10,1,1,242.590000000,245.000000000,5,79,1,2,242.280000000,245.190000000,100,83,1,1,AAPL
2025-01-03T10:33:11.019541080Z,2025-01-03T10:33:11.019375099Z,10,2,38,A,B,0,243.510000000,200,130,165981,4944815,243.510000000,243.660000000,200,100,1,1,243.500000000,243.760000000,6,200,1,1,243.450000000,243.810000000,29,29,1,1,243.190000000,244.000000000,2,1,1,1,243.020000000,244.140000000,79,79,1,1,243.000000000,244.200000000,1243,1000,9,1,242.990000000,244.400000000,1,50,1,1,242.800000000,244.420000000,30,10,1,1,242.750000000,245.000000000,30,79,1,2,242.590000000,245.190000000,5,83,1,1,AAPL
2025-01-03T10:33:11.038291784Z,2025-01-03T10:33:11.038125943Z,10,2,38,C,A,2,243.810000000,29,130,165841,4944818,243.510000000,243.660000000,200,100,1,1,243.500000000,243.760000000,6,200,1,1,243.450000000,244.000000000,29,1,1,1,243.190000000,244.140000000,2,79,1,1,243.020000000,244.200000000,79,1000,1,1,243.000000000,244.400000000,1243,50,9,1,242.990000000,244.420000000,1,10,1,1,242.800000000,245.000000000,30,79,1,2,242.750000000,245.190000000,30,83,1,1,242.590000000,245.540000000,5,10,1,1,AAPL
2025-01-03T10:33:11.038401649Z,2025-01-03T10:33:11.038235321Z,10,2,38,A,A,2,243.770000000,28,130,166328,4944819,243.510000000,243.660000000,200,100,1,1,243.500000000,243.760000000,6,200,1,1,243.450000000,243.770000000,29,28,1,1,243.190000000,244.000000000,2,1,1,1,243.020000000,244.140000000,79,79,1,1,243.000000000,244.200000000,1243,1000,9,1,242.990000000,244.400000000,1,50,1,1,242.800000000,244.420000000,30,10,1,1,242.750000000,245.000000000,30,79,1,2,242.590000000,245.190000000,5,83,1,1,AAPL
2025-01-03T10:33:11.089381608Z,2025-01-03T10:33:11.089214867Z,10,2,38,A,A,1,243.720000000,200,130,166741,4944901,243.510000000,243.660000000,200,100,1,1,243.500000000,243.720000000,6,200,1,1,243.450000000,243.770000000,29,28,1,1,243.190000000,244.000000000,2,1,1,1,243.020000000,244.140000000,79,79,1,1,243.000000000,244.200000000,1243,1000,9,1,242.990000000,244.400000000,1,50,1,1,242.800000000,244.420000000,30,10,1,1,242.750000000,245.000000000,30,79,1,2,242.590000000,245.190000000,5,83,1,1,AAPL
2025-01-03T10:33:11.462573411Z,2025-01-03T10:33:11.462406747Z,10,2,16244,A,A,2,383.510000000,20,130,166664,4945295,383.000000000,383.250000000,19,47,1,1,382.990000000,383.420000000,30,140,1,1,382.960000000,383.510000000,19,20,1,1,382.880000000,383.600000000,100,500,1,1,382.840000000,383.720000000,300,7085,1,8,382.820000000,383.740000000,1,37,1,1,382.810000000,383.800000000,20,10,2,1,382.700000000,383.880000000,50,4,1,1,382.400000000,384.000000000,500,1300,1,4,382.230000000,384.260000000,25,15,1,1,TSLA
2025-01-03T10:33:11.698327422Z,2025-01-03T10:33:11.698160868Z,10,2,11667,A,A,1,139.220000000,400,130,166554,4945638,139.160000000,139.200000000,16,100,1,1,139.150000000,139.220000000,9860,410,2,2,139.130000000,139.230000000,2100,2277,1,4,139.120000000,139.250000000,30,1,1,1,139.110000000,139.270000000,401,37,2,2,139.100000000,139.300000000,10,507,1,4,139.090000000,139.320000000,57,39,1,1,139.070000000,139.330000000,100,503,1,2,139.030000000,139.360000000,126,4,2,2,139.010000000,139.370000000,100,75,1,1,NVDA
2025-01-03T10:33:11.744914620Z,2025-01-03T10:33:11.744748867Z,10,2,16244,C,B,0,383.000000000,19,130,165753,4945667,382.990000000,383.250000000,30,47,1,1,382.960000000,383.420000000,19,140,1,1,382.880000000,383.510000000,100,20,1,1,382.840000000,383.600000000,300,500,1,1,382.820000000,383.720000000,1,7085,1,8,382.810000000,383.740000000,20,37,2,1,382.700000000,383.800000000,50,10,1,1,382.400000000,383.880000000,500,4,1,1,382.230000000,384.000000000,25,1300,1,4,382.100000000,384.260000000,10,15,1,1,TSLA
2025-01-03T10:33:11.988509589Z,2025-01-03T10:33:11.988340070Z,10,2,11667,T,A,0,139.160000000,16,128,169519,4945894,139.160000000,139.200000000,16,100,1,1,139.150000000,139.220000000,9860,410,2,2,139.130000000,139.230000000,2100,2277,1,4,139.120000000,139.250000000,30,1,1,1,139.110000000,139.270000000,401,37,2,2,139.100000000,139.300000000,10,507,1,4,139.090000000,139.320000000,57,39,1,1,139.070000000,139.330000000,100,503,1,2,139.030000000,139.360000000,126,4,2,2,139.010000000,139.370000000,100,75,1,1,NVDA
2025-01-03T10:33:11.988509589Z,2025-01-03T10:33:11.988340070Z,10,2,11667,C,B,0,139.160000000,16,128,169519,4945894,139.150000000,139.200000000,9860,100,2,1,139.130000000,139.220000000,2100,410,1,2,139.120000000,139.230000000,30,2277,1,4,139.110000000,139.250000000,401,1,2,1,139.100000000,139.270000000,10,37,1,2,139.090000000,139.300000000,57,507,1,4,139.070000000,139.320000000,100,39,1,1,139.030000000,139.330000000,126,503,2,2,139.010000000,139.360000000,100,4,1,2,139.000000000,139.370000000,910,75,5,1,NVDA
2025-01-03T10:33:11.988533413Z,2025-01-03T10:33:11.988367365Z,10,2,11667,A,A,0,139.190000000,78,130,166048,4945899,139.150000000,139.190000000,9860,78,2,1,139.130000000,139.200000000,2100,100,1,1,139.120000000,139.220000000,30,410,1,2,139.110000000,139.230000000,401,2277,2,4,139.100000000,139.250000000,10,1,1,1,139.090000000,139.270000000,57,37,1,2,139.070000000,139.300000000,100,507,1,4,139.030000000,139.320000000,126,39,2,1,139.010000000,139.330000000,100,503,1,2,139.000000000,139.360000000,910,4,5,2,NVDA
2025-01-03T10:33:11.998542481Z,2025-01-03T10:33:11.998376763Z,10,2,11667,C,A,0,139.190000000,78,130,165718,4946131,139.150000000,139.200000000,9860,100,2,1,139.130000000,139.220000000,2100,410,1,2,139.120000000,139.230000000,30,2277,1,4,139.110000000,139.250000000,401,1,2,1,139.100000000,139.270000000,10,37,1,2,139.090000000,139.300000000,57,507,1,4,139.070000000,139.320000000,100,39,1,1,139.030000000,139.330000000,126,503,2,2,139.010000000,139.360000000,100,4,1,2,139.000000000,139.370000000,910,75,5,1,NVDA
2025-01-03T10:33:12.048370511Z,2025-01-03T10:33:12.048204696Z,10,2,11667,C,B,3,139.110000000,400,130,165815,4946378,139.150000000,139.200000000,9860,100,2,1,139.130000000,139.220000000,2100,410,1,2,139.120000000,139.230000000,30,2277,1,4,139.110000000,139.250000000,1,1,1,1,139.100000000,139.270000000,10,37,1,2,139.090000000,139.300000000,57,507,1,4,139.070000000,139.320000000,100,39,1,1,139.030000000,139.330000000,126,503,2,2,139.010000000,139.360000000,100,4,1,2,139.000000000,139.370000000,910,75,5,1,NVDA
2025-01-03T10:33:12.048383928Z,2025-01-03T10:33:12.048217757Z,10,2,11667,A,B,5,139.090000000,400,130,166171,4946379,139.150000000,139.200000000,9860,100,2,1,139.130000000,139.220000000,2100,410,1,2,139.120000000,139.230000000,30,2277,1,4,139.110000000,139.250000000,1,1,1,1,139.100000000,139.270000000,10,37,1,2,139.090000000,139.300000000,457,507,2,4,139.070000000,139.320000000,100,39,1,1,139.030000000,139.330000000,126,503,2,2,139.010000000,139.360000000,100,4,1,2,139.000000000,139.370000000,910,75,5,1,NVDA
2025-01-03T10:33:12.049394281Z,2025-01-03T10:33:12.049228180Z,10,2,11667,C,A,2,139.230000000,100,130,166101,4946382,139.150000000,139.200000000,9860,100,2,1,139.130000000,139.220000000,2100,410,1,2,139.120000000,139.230000000,30,2177,1,3,139.110000000,139.250000000,1,1,1,1,139.100000000,139.270000000,10,37,1,2,139.090000000,139.300000000,457,507,2,4,139.070000000,139.320000000,100,39,1,1,139.030000000,139.330000000,126,503,2,2,139.010000000,139.360000000,100,4,1,2,139.000000000,139.370000000,910,75,5,1,NVDA
2025-01-03T10:33:12.049408697Z,2025-01-03T10:33:12.049242018Z,10,2,11667,A,A,1,139.220000000,100,130,166679,4946383,139.150000000,139.200000000,9860,100,2,1,139.130000000,139.220000000,2100,510,1,3,139.120000000,139.230000000,30,1977,1,2,139.110000000,139.250000000,1,1,1,1,139.100000000,139.270000000,10,37,1,2,139.090000000,139.300000000,457,507,2,4,139.070000000,139.320000000,100,39,1,1,139.030000000,139.330000000,126,503,2,2,139.010000000,139.360000000,100,4,1,2,139.000000000,139.370000000,910,75,5,1,NVDA
2025-01-03T10:33:12.060107616Z,2025-01-03T10:33:12.059941755Z,10,2,11667,C,B,5,139.090000000,400,130,165861,4946396,139.150000000,139.200000000,9860,100,2,1,139.130000000,139.220000000,2100,510,1,3,139.120000000,139.230000000,30,1977,1,2,139.110000000,139.250000000,1,1,1,1,139.100000000,139.270000000,10,37,1,2,139.090000000,139.300000000,57,507,1,4,139.070000000,139.320000000,100,39,1,1,139.030000000,139.330000000,126,503,2,2,139.010000000,139.360000000,100,4,1,2,139.000000000,139.370000000,910,75,5,1,NVDA
2025-01-03T10:33:12.060121219Z,2025-01-03T10:33:12.059954876Z,10,2,11667,A,B,6,139.070000000,400,130,166343,4946397,139.150000000,139.200000000,9860,100,2,1,139.130000000,139.220000000,2100,510,1,3,139.120000000,139.230000000,30,1977,1,2,139.110000000,139.250000000,1,1,1,1,139.100000000,139.270000000,10,37,1,2,139.090000000,139.300000000,57,507,1,4,139.070000000,139.320000000,500,39,2,1,139.030000000,139.330000000,126,503,2,2,139.010000000,139.360000000,100,4,1,2,139.000000000,139.370000000,910,75,5,1,NVDA
2025-01-03T10:33:12.065832380Z,2025-01-03T10:33:12.065666791Z,10,2,11667,C,B,6,139.070000000,400,130,165589,4946402,139.150000000,139.200000000,9860,100,2,1,139.130000000,139.220000000,2100,510,1,3,139.120000000,139.230000000,30,1977,1,2,139.110000000,139.250000000,1,1,1,1,139.100000000,139.270000000,10,37,1,2,139.090000000,139.300000000,57,507,1,4,139.070000000,139.320000000,100,39,1,1,139.030000000,139.330000000,126,503,2,2,139.010000000,139.360000000,100,4,1,2,139.000000000,139.370000000,910,75,5,1,NVDA
2025-01-03T10:33:12.065845524Z,2025-01-03T10:33:12.065679517Z,10,2,11667,A,B,7,139.060000000,400,130,166007,4946403,139.150000000,139.200000000,9860,100,2,1,139.130000000,139.220000000,2100,510,1,3,139.120000000,139.230000000,30,1977,1,2,139.110000000,139.250000000,1,1,1,1,139.100000000,139.270000000,10,37,1,2,139.090000000,139.300000000,57,507,1,4,139.070000000,139.320000000,100,39,1,1,139.060000000,139.330000000,400,503,1,2,139.030000000,139.360000000,126,4,2,2,139.010000000,139.370000000,100,75,1,1,NVDA
2025-01-03T10:33:12.256509721Z,2025-01-03T10:33:12.256343131Z,10,2,11667,A,B,3,139.110000000,400,130,166590,4946681,139.150000000,139.200000000,9860,100,2,1,139.130000000,139.220000000,2100,510,1,3,139.120000000,139.230000000,30,1977,1,2,139.110000000,139.250000000,401,1,2,1,139.100000000,139.270000000,10,37,1,2,139.090000000,139.300000000,57,507,1,4,139.070000000,139.320000000,100,39,1,1,139.030000000,139.330000000,126,503,2,2,139.010000000,139.360000000,100,4,1,2,139.000000000,139.370000000,910,75,5,1,NVDA
2025-01-03T10:33:12.317134842Z,2025-01-03T10:33:12.316968676Z,10,2,16244,A,A,3,383.600000000,500,130,166166,4946852,382.990000000,383.250000000,30,47,1,1,382.960000000,383.420000000,19,140,1,1,382.880000000,383.510000000,100,20,1,1,382.840000000,383.600000000,300,1000,1,2,382.820000000,383.720000000,1,7085,1,8,382.810000000,383.740000000,20,37,2,1,382.700000000,383.800000000,50,10,1,1,382.400000000,383.880000000,500,4,1,1,382.230000000,384.000000000,25,1300,1,4,382.100000000,384.260000000,10,15,1,1,TSLA
2025-01-03T10:33:13.109251985Z,2025-01-03T10:33:13.109085901Z,10,2,16244,C,B,1,382.960000000,19,130,166084,4947537,382.990000000,383.250000000,30,47,1,1,382.880000000,383.420000000,100,140,1,1,382.840000000,383.510000000,300,20,1,1,382.820000000,383.600000000,1,1000,1,2,382.810000000,383.720000000,20,7085,2,8,382.700000000,383.740000000,50,37,1,1,382.400000000,383.800000000,500,10,1,1,382.230000000,383.880000000,25,4,1,1,382.100000000,384.000000000,10,1300,1,4,382.010000000,384.260000000,2,15,1,1,TSLA
2025-01-03T10:33:13.109373727Z,2025-01-03T10:33:13.109207337Z,10,2,16244,A,B,1,382.910000000,21,130,166390,4947538,382.990000000,383.250000000,30,47,1,1,382.910000000,383.420000000,21,140,1,1,382.880000000,383.510000000,100,20,1,1,382.840000000,383.600000000,300,1000,1,2,382.820000000,383.720000000,1,7085,1,8,382.810000000,383.740000000,20,37,2,1,382.700000000,383.800000000,50,10,1,1,382.400000000,383.880000000,500,4,1,1,382.230000000,384.000000000,25,1300,1,4,382.100000000,384.260000000,10,15,1,1,TSLA
2025-01-03T10:33:13.191156578Z,2025-01-03T10:33:13.190989536Z,10,2,16244,C,A,3,383.600000000,500,130,167042,4947618,382.990000000,383.250000000,30,47,1,1,382.910000000,383.420000000,21,140,1,1,382.880000000,383.510000000,100,20,1,1,382.840000000,383.600000000,300,500,1,1,382.820000000,383.720000000,1,7085,1,8,382.810000000,383.740000000,20,37,2,1,382.700000000,383.800000000,50,10,1,1,382.400000000,383.880000000,500,4,1,1,382.230000000,384.000000000,25,1300,1,4,382.100000000,384.260000000,10,15,1,1,TSLA
2025-01-03T10:33:13.386770241Z,2025-01-03T10:33:13.386603999Z,10,2,17709,A,A,2,107.890000000,17,130,166242,4947680,107.600000000,107.840000000,50,400,1,2,107.550000000,107.870000000,15,242,1,1,107.520000000,107.890000000,100,17,1,1,107.050000000,107.940000000,247,100,1,1,107.000000000,107.950000000,1,10,1,1,106.240000000,108.000000000,28,50,1,1,106.000000000,108.300000000,15,50,2,1,105.870000000,108.550000000,141,50,1,1,103.180000000,108.800000000,16,50,1,1,103.000000000,108.880000000,3,28,1,1,XOM
2025-01-03T10:33:13.444754313Z,2025-01-03T10:33:13.444587338Z,10,2,17709,A,A,2,107.880000000,100,130,166975,4947705,107.600000000,107.840000000,50,400,1,2,107.550000000,107.870000000,15,242,1,1,107.520000000,107.880000000,100,100,1,1,107.050000000,107.890000000,247,17,1,1,107.000000000,107.950000000,1,10,1,1,106.240000000,108.000000000,28,50,1,1,106.000000000,108.300000000,15,50,2,1,105.870000000,108.550000000,141,50,1,1,103.180000000,108.800000000,16,50,1,1,103.000000000,108.880000000,3,28,1,1,XOM
2025-01-03T10:33:14.271284797Z,2025-01-03T10:33:14.271117790Z,10,2,16244,T,N,0,383.200000000,1,130,167007,4948037,382.990000000,383.250000000,30,47,1,1,382.910000000,383.420000000,21,140,1,1,382.880000000,383.510000000,100,20,1,1,382.840000000,383.600000000,300,500,1,1,382.820000000,383.720000000,1,7085,1,8,382.810000000,383.740000000,20,37,2,1,382.700000000,383.800000000,50,10,1,1,382.400000000,383.880000000,500,4,1,1,382.230000000,384.000000000,25,1300,1,4,382.100000000,384.260000000,10,15,1,1,TSLA
2025-01-03T10:33:15.609742196Z,2025-01-03T10:33:15.609576318Z,10,2,11667,C,B,3,139.110000000,400,130,165878,4948738,139.150000000,139.200000000,9860,100,2,1,139.130000000,139.220000000,2100,510,1,3,139.120000000,139.230000000,30,1977,1,2,139.110000000,139.250000000,1,1,1,1,139.100000000,139.270000000,10,37,1,2,139.090000000,139.300000000,57,507,1,4,139.070000000,139.320000000,100,39,1,1,139.030000000,139.330000000,126,503,2,2,139.010000000,139.360000000,100,4,1,2,139.000000000,139.370000000,910,75,5,1,NVDA
2025-01-03T10:33:15.609755706Z,2025-01-03T10:33:15.609589435Z,10,2,11667,A,B,6,139.080000000,400,130,166271,4948739,139.150000000,139.200000000,9860,100,2,1,139.130000000,139.220000000,2100,510,1,3,139.120000000,139.230000000,30,1977,1,2,139.110000000,139.250000000,1,1,1,1,139.100000000,139.270000000,10,37,1,2,139.090000000,139.300000000,57,507,1,4,139.080000000,139.320000000,400,39,1,1,139.070000000,139.330000000,100,503,1,2,139.030000000,139.360000000,126,4,2,2,139.010000000,139.370000000,100,75,1,1,NVDA
2025-01-03T10:33:15.609768902Z,2025-01-03T10:33:15.609603279Z,10,2,11667,C,B,6,139.080000000,400,130,165623,4948740,139.150000000,139.200000000,9860,100,2,1,139.130000000,139.220000000,2100,510,1,3,139.120000000,139.230000000,30,1977,1,2,139.110000000,139.250000000,1,1,1,1,139.100000000,139.270000000,10,37,1,2,139.090000000,139.300000000,57,507,1,4,139.070000000,139.320000000,100,39,1,1,139.030000000,139.330000000,126,503,2,2,139.010000000,139.360000000,100,4,1,2,139.000000000,139.370000000,910,75,5,1,NVDA
2025-01-03T10:33:15.656160537Z,2025-01-03T10:33:15.655994182Z,10,2,11667,A,B,6,139.070000000,400,130,166355,4948751,139.150000000,139.200000000,9860,100,2,1,139.130000000,139.220000000,2100,510,1,3,139.120000000,139.230000000,30,1977,1,2,139.110000000,139.250000000,1,1,1,1,139.100000000,139.270000000,10,37,1,2,139.090000000,139.300000000,57,507,1,4,139.070000000,139.320000000,500,39,2,1,139.030000000,139.330000000,126,503,2,2,139.010000000,139.360000000,100,4,1,2,139.000000000,139.370000000,910,75,5,1,NVDA
2025-01-03T10:33:16.434884559Z,2025-01-03T10:33:16.434718424Z,10,2,10888,C,A,0,421.170000000,200,130,166135,4949057,420.670000000,421.220000000,200,13,1,1,420.590000000,421.460000000,14,39,1,1,420.580000000,421.490000000,10,6,1,1,420.520000000,421.570000000,1,40,1,1,420.400000000,421.600000000,858,510,1,2,420.380000000,421.700000000,100,359,1,1,420.100000000,421.800000000,100,7,1,1,420.000000000,422.100000000,834,7,8,1,419.730000000,422.500000000,3,200,1,1,419.650000000,423.500000000,39,600,1,2,MSFT
2025-01-03T10:33:16.434895181Z,2025-01-03T10:33:16.434729116Z,10,2,10888,A,A,0,421.200000000,200,130,166065,4949058,420.670000000,421.200000000,200,200,1,1,420.590000000,421.220000000,14,13,1,1,420.580000000,421.460000000,10,39,1,1,420.520000000,421.490000000,1,6,1,1,420.400000000,421.570000000,858,40,1,1,420.380000000,421.600000000,100,510,1,2,420.100000000,421.700000000,100,359,1,1,420.000000000,421.800000000,834,7,8,1,419.730000000,422.100000000,3,7,1,1,419.650000000,422.500000000,39,200,1,1,MSFT
2025-01-03T10:33:16.479816150Z,2025-01-03T10:33:16.479650458Z,10,2,11667,C,A,1,139.220000000,400,130,165692,4949160,139.150000000,139.200000000,9860,100,2,1,139.130000000,139.220000000,2100,110,1,2,139.120000000,139.230000000,30,1977,1,2,139.110000000,139.250000000,1,1,1,1,139.100000000,139.270000000,10,37,1,2,139.090000000,139.300000000,57,507,1,4,139.070000000,139.320000000,500,39,2,1,139.030000000,139.330000000,126,503,2,2,139.010000000,139.360000000,100,4,1,2,139.000000000,139.370000000,910,75,5,1,NVDA
2025-01-03T10:33:16.479827420Z,2025-01-03T10:33:16.479661232Z,10,2,11667,A,A,2,139.230000000,400,130,166188,4949161,139.150000000,139.200000000,9860,100,2,1,139.130000000,139.220000000,2100,110,1,2,139.120000000,139.230000000,30,2377,1,3,139.110000000,139.250000000,1,1,1,1,139.100000000,139.270000000,10,37,1,2,139.090000000,139.300000000,57,507,1,4,139.070000000,139.320000000,500,39,2,1,139.030000000,139.330000000,126,503,2,2,139.010000000,139.360000000,100,4,1,2,139.000000000,139.370000000,910,75,5,1,NVDA
2025-01-03T10:33:16.489483504Z,2025-01-03T10:33:16.489317409Z,10,2,10888,A,B,0,420.680000000,200,130,166095,4949277,420.680000000,421.200000000,200,200,1,1,420.590000000,421.220000000,14,13,1,1,420.580000000,421.460000000,10,39,1,1,420.520000000,421.490000000,1,6,1,1,420.400000000,421.570000000,858,40,1,1,420.380000000,421.600000000,100,510,1,2,420.100000000,421.700000000,100,359,1,1,420.000000000,421.800000000,834,7,8,1,419.730000000,422.100000000,3,7,1,1,419.650000000,422.500000000,39,200,1,1,MSFT
2025-01-03T10:33:16.490004083Z,2025-01-03T10:33:16.489838288Z,10,2,16244,C,A,2,383.510000000,20,130,165795,4949291,382.990000000,383.250000000,30,47,1,1,382.910000000,383.420000000,21,140,1,1,382.880000000,383.600000000,100,500,1,1,382.840000000,383.720000000,300,7085,1,8,382.820000000,383.740000000,1,37,1,1,382.810000000,383.800000000,20,10,2,1,382.700000000,383.880000000,50,4,1,1,382.400000000,384.000000000,500,1300,1,4,382.230000000,384.260000000,25,15,1,1,382.100000000,384.400000000,10,1000,1,2,TSLA
2025-01-03T10:33:16.490143623Z,2025-01-03T10:33:16.489977447Z,10,2,16244,A,B,1,382.920000000,22,130,166176,4949294,382.990000000,383.250000000,30,47,1,1,382.920000000,383.420000000,22,140,1,1,382.910000000,383.600000000,21,500,1,1,382.880000000,383.720000000,100,7085,1,8,382.840000000,383.740000000,300,37,1,1,382.820000000,383.800000000,1,10,1,1,382.810000000,383.880000000,20,4,2,1,382.700000000,384.000000000,50,1300,1,4,382.400000000,384.260000000,500,15,1,1,382.230000000,384.400000000,25,1000,1,2,TSLA
2025-01-03T10:33:16.490233580Z,2025-01-03T10:33:16.490067675Z,10,2,16244,C,B,2,382.910000000,21,130,165905,4949295,382.990000000,383.250000000,30,47,1,1,382.920000000,383.420000000,22,140,1,1,382.880000000,383.600000000,100,500,1,1,382.840000000,383.720000000,300,7085,1,8,382.820000000,383.740000000,1,37,1,1,382.810000000,383.800000000,20,10,2,1,382.700000000,383.880000000,50,4,1,1,382.400000000,384.000000000,500,1300,1,4,382.230000000,384.260000000,25,15,1,1,382.100000000,384.400000000,10,1000,1,2,TSLA
2025-01-03T10:33:16.490311441Z,2025-01-03T10:33:16.490144677Z,10,2,16244,A,A,2,383.460000000,20,130,166764,4949297,382.990000000,383.250000000,30,47,1,1,382.920000000,383.420000000,22,140,1,1,382.880000000,383.460000000,100,20,1,1,382.840000000,383.600000000,300,500,1,1,382.820000000,383.720000000,1,7085,1,8,382.810000000,383.740000000,20,37,2,1,382.700000000,383.800000000,50,10,1,1,382.400000000,383.880000000,500,4,1,1,382.230000000,384.000000000,25,1300,1,4,382.100000000,384.260000000,10,15,1,1,TSLA
2025-01-03T10:33:16.492472299Z,2025-01-03T10:33:16.492306083Z,10,2,6905,A,B,0,91.530000000,7,130,166216,4949314,91.530000000,91.950000000,7,7,1,1,91.520000000,91.960000000,7,100,1,1,91.480000000,93.000000000,150,1,1,1,91.440000000,94.000000000,100,1,1,1,90.000000000,95.000000000,122,2,1,2,89.000000000,96.000000000,1,1,1,1,83.810000000,97.000000000,100,2,1,2,83.400000000,99.950000000,100,100,1,1,,100.360000000,0,100,0,1,,,0,0,0,0,GILD
2025-01-03T10:33:16.492551848Z,2025-01-03T10:33:16.492385762Z,10,2,6905,C,B,1,91.520000000,7,130,166086,4949315,91.530000000,91.950000000,7,7,1,1,91.480000000,91.960000000,150,100,1,1,91.440000000,93.000000000,100,1,1,1,90.000000000,94.000000000,122,1,1,1,89.000000000,95.000000000,1,2,1,2,83.810000000,96.000000000,100,1,1,1,83.400000000,97.000000000,100,2,1,2,,99.950000000,0,100,0,1,,100.360000000,0,100,0,1,,,0,0,0,0,GILD
2025-01-03T10:33:16.495559651Z,2025-01-03T10:33:16.495393747Z,10,2,10888,C,B,1,420.590000000,14,130,165904,4949354,420.680000000,421.200000000,200,200,1,1,420.580000000,421.220000000,10,13,1,1,420.520000000,421.460000000,1,39,1,1,420.400000000,421.490000000,858,6,1,1,420.380000000,421.570000000,100,40,1,1,420.100000000,421.600000000,100,510,1,2,420.000000000,421.700000000,834,359,8,1,419.730000000,421.800000000,3,7,1,1,419.650000000,422.100000000,39,7,1,1,418.650000000,422.500000000,1,200,1,1,MSFT
2025-01-03T10:33:16.495657234Z,2025-01-03T10:33:16.495491066Z,10,2,10888,A,B,1,420.600000000,15,130,166168,4949355,420.680000000,421.200000000,200,200,1,1,420.600000000,421.220000000,15,13,1,1,420.580000000,421.460000000,10,39,1,1,420.520000000,421.490000000,1,6,1,1,420.400000000,421.570000000,858,40,1,1,420.380000000,421.600000000,100,510,1,2,420.100000000,421.700000000,100,359,1,1,420.000000000,421.800000000,834,7,8,1,419.730000000,422.100000000,3,7,1,1,419.650000000,422.500000000,39,200,1,1,MSFT
2025-01-03T10:33:16.498687918Z,2025-01-03T10:33:16.498521416Z,10,2,12463,A,B,1,150.320000000,9,130,166502,4949430,150.460000000,150.820000000,1,9,1,1,150.320000000,150.840000000,9,100,1,1,150.310000000,151.000000000,9,1,1,1,150.260000000,153.280000000,234,10,1,1,150.250000000,163.540000000,1,100,1,1,150.210000000,164.210000000,113,100,2,1,150.020000000,179.000000000,2,5,1,1,150.000000000,,250,0,1,0,149.950000000,,5,0,1,0,149.740000000,,10,0,1,0,PEP
2025-01-03T10:33:16.498927223Z,2025-01-03T10:33:16.498761390Z,10,2,12463,C,B,2,150.310000000,9,130,165833,4949436,150.460000000,150.820000000,1,9,1,1,150.320000000,150.840000000,9,100,1,1,150.260000000,151.000000000,234,1,1,1,150.250000000,153.280000000,1,10,1,1,150.210000000,163.540000000,113,100,2,1,150.020000000,164.210000000,2,100,1,1,150.000000000,179.000000000,250,5,1,1,149.950000000,,5,0,1,0,149.740000000,,10,0,1,0,149.000000000,,5,0,1,0,PEP
2025-01-03T10:33:16.502164713Z,2025-01-03T10:33:16.501998257Z,10,2,38,C,B,2,243.450000000,29,130,166456,4949471,243.510000000,243.660000000,200,100,1,1,243.500000000,243.720000000,6,200,1,1,243.190000000,243.770000000,2,28,1,1,243.020000000,244.000000000,79,1,1,1,243.000000000,244.140000000,1243,79,9,1,242.990000000,244.200000000,1,1000,1,1,242.800000000,244.400000000,30,50,1,1,242.750000000,244.420000000,30,10,1,1,242.590000000,245.000000000,5,79,1,2,242.280000000,245.190000000,100,83,1,1,AAPL
2025-01-03T10:33:16.502194243Z,2025-01-03T10:33:16.502028045Z,10,2,38,A,B,2,243.460000000,28,130,166198,4949472,243.510000000,243.660000000,200,100,1,1,243.500000000,243.720000000,6,200,1,1,243.460000000,243.770000000,28,28,1,1,243.190000000,244.000000000,2,1,1,1,243.020000000,244.140000000,79,79,1,1,243.000000000,244.200000000,1243,1000,9,1,242.990000000,244.400000000,1,50,1,1,242.800000000,244.420000000,30,10,1,1,242.750000000,245.000000000,30,79,1,2,242.590000000,245.190000000,5,83,1,1,AAPL
2025-01-03T10:33:16.522029001Z,2025-01-03T10:33:16.521862795Z,10,2,10888,C,A,1,421.220000000,13,130,166206,4949555,420.680000000,421.200000000,200,200,1,1,420.600000000,421.460000000,15,39,1,1,420.580000000,421.490000000,10,6,1,1,420.520000000,421.570000000,1,40,1,1,420.400000000,421.600000000,858,510,1,2,420.380000000,421.700000000,100,359,1,1,420.100000000,421.800000000,100,7,1,1,420.000000000,422.100000000,834,7,8,1,419.730000000,422.500000000,3,200,1,1,419.650000000,423.500000000,39,600,1,2,MSFT
2025-01-03T10:33:16.522089808Z,2025-01-03T10:33:16.521923561Z,10,2,10888,A,A,1,421.260000000,13,130,166247,4949556,420.680000000,421.200000000,200,200,1,1,420.600000000,421.260000000,15,13,1,1,420.580000000,421.460000000,10,39,1,1,420.520000000,421.490000000,1,6,1,1,420.400000000,421.570000000,858,40,1,1,420.380000000,421.600000000,100,510,1,2,420.100000000,421.700000000,100,359,1,1,420.000000000,421.800000000,834,7,8,1,419.730000000,422.100000000,3,7,1,1,419.650000000,422.500000000,39,200,1,1,MSFT
2025-01-03T10:33:16.524477412Z,2025-01-03T10:33:16.524310920Z,10,2,16727,C,A,0,315.460000000,8,130,166492,4949585,314.940000000,315.510000000,8,25,1,1,314.860000000,315.750000000,25,61,1,1,314.420000000,320.000000000,61,5,1,1,313.500000000,320.210000000,1,1,1,1,310.000000000,321.950000000,1,2,1,1,300.000000000,344.200000000,3,100,1,1,290.000000000,345.620000000,2,100,1,1,286.660000000,,100,0,1,0,285.250000000,,100,0,1,0,260.000000000,,2,0,1,0,V
2025-01-03T10:33:16.524532650Z,2025-01-03T10:33:16.524366970Z,10,2,16727,C,B,0,314.940000000,8,130,165680,4949586,314.860000000,315.510000000,25,25,1,1,314.420000000,315.750000000,61,61,1,1,313.500000000,320.000000000,1,5,1,1,310.000000000,320.210000000,1,1,1,1,300.000000000,321.950000000,3,2,1,1,290.000000000,344.200000000,2,100,1,1,286.660000000,345.620000000,100,100,1,1,285.250000000,,100,0,1,0,260.000000000,,2,0,1,0,,,0,0,0,0,V
2025-01-03T10:33:16.524658488Z,2025-01-03T10:33:16.524491938Z,10,2,16727,A,A,0,315.490000000,8,130,166550,4949587,314.860000000,315.490000000,25,8,1,1,314.420000000,315.510000000,61,25,1,1,313.500000000,315.750000000,1,61,1,1,310.000000000,320.000000000,1,5,1,1,300.000000000,320.210000000,3,1,1,1,290.000000000,321.950000000,2,2,1,1,286.660000000,344.200000000,100,100,1,1,285.250000000,345.620000000,100,100,1,1,260.000000000,,2,0,1,0,,,0,0,0,0,V
2025-01-03T10:33:16.524716348Z,2025-01-03T10:33:16.524550510Z,10,2,16727,A,B,0,314.950000000,8,130,165838,4949588,314.950000000,315.490000000,8,8,1,1,314.860000000,315.510000000,25,25,1,1,314.420000000,315.750000000,61,61,1,1,313.500000000,320.000000000,1,5,1,1,310.000000000,320.210000000,1,1,1,1,300.000000000,321.950000000,3,2,1,1,290.000000000,344.200000000,2,100,1,1,286.660000000,345.620000000,100,100,1,1,285.250000000,,100,0,1,0,260.000000000,,2,0,1,0,V
2025-01-03T10:33:16.525023232Z,2025-01-03T10:33:16.524857255Z,10,2,9155,C,B,1,241.610000000,8,130,165977,4949589,241.670000000,242.070000000,2,62,1,1,241.120000000,242.360000000,81,8,1,1,241.000000000,242.850000000,100,300,1,2,240.000000000,242.900000000,10,100,1,1,238.000000000,243.000000000,30,92,1,2,236.000000000,243.310000000,6,10,1,1,235.500000000,243.700000000,5,100,1,1,235.000000000,246.810000000,5,100,1,1,232.880000000,262.740000000,1,100,1,1,231.110000000,263.830000000,3,100,1,1,JPM
2025-01-03T10:33:16.525118851Z,2025-01-03T10:33:16.524952718Z,10,2,9155,A,B,1,241.620000000,8,130,166133,4949590,241.670000000,242.070000000,2,62,1,1,241.620000000,242.360000000,8,8,1,1,241.120000000,242.850000000,81,300,1,2,241.000000000,242.900000000,100,100,1,1,240.000000000,243.000000000,10,92,1,2,238.000000000,243.310000000,30,10,1,1,236.000000000,243.700000000,6,100,1,1,235.500000000,246.810000000,5,100,1,1,235.000000000,262.740000000,5,100,1,1,232.880000000,263.830000000,1,100,1,1,JPM
2025-01-03T10:33:16.525214855Z,2025-01-03T10:33:16.525049005Z,10,2,9155,C,A,1,242.360000000,8,130,165850,4949591,241.670000000,242.070000000,2,62,1,1,241.620000000,242.850000000,8,300,1,2,241.120000000,242.900000000,81,100,1,1,241.000000000,243.000000000,100,92,1,2,240.000000000,243.310000000,10,10,1,1,238.000000000,243.700000000,30,100,1,1,236.000000000,246.810000000,6,100,1,1,235.500000000,262.740000000,5,100,1,1,235.000000000,263.830000000,5,100,1,1,232.880000000,,1,0,1,0,JPM
2025-01-03T10:33:16.525241676Z,2025-01-03T10:33:16.525075455Z,10,2,9155,A,A,1,242.380000000,8,130,166221,4949592,241.670000000,242.070000000,2,62,1,1,241.620000000,242.380000000,8,8,1,1,241.120000000,242.850000000,81,300,1,2,241.000000000,242.900000000,100,100,1,1,240.000000000,243.000000000,10,92,1,2,238.000000000,243.310000000,30,10,1,1,236.000000000,243.700000000,6,100,1,1,235.500000000,246.810000000,5,100,1,1,235.000000000,262.740000000,5,100,1,1,232.880000000,263.830000000,1,100,1,1,JPM
2025-01-03T10:33:16.530383677Z,2025-01-03T10:33:16.530217316Z,10,2,38,A,B,0,243.520000000,200,130,166361,4949626,243.520000000,243.660000000,200,100,1,1,243.500000000,243.720000000,6,200,1,1,243.460000000,243.770000000,28,28,1,1,243.190000000,244.000000000,2,1,1,1,243.020000000,244.140000000,79,79,1,1,243.000000000,244.200000000,1243,1000,9,1,242.990000000,244.400000000,1,50,1,1,242.800000000,244.420000000,30,10,1,1,242.750000000,245.000000000,30,79,1,2,242.590000000,245.190000000,5,83,1,1,AAPL
2025-01-03T10:33:16.531447459Z,2025-01-03T10:33:16.531281343Z,10,2,11667,A,B,6,139.080000000,400,130,166116,4949633,139.150000000,139.200000000,9860,100,2,1,139.130000000,139.220000000,2100,110,1,2,139.120000000,139.230000000,30,2377,1,3,139.110000000,139.250000000,1,1,1,1,139.100000000,139.270000000,10,37,1,2,139.090000000,139.300000000,57,507,1,4,139.080000000,139.320000000,400,39,1,1,139.070000000,139.330000000,100,503,1,2,139.030000000,139.360000000,126,4,2,2,139.010000000,139.370000000,100,75,1,1,NVDA
2025-01-03T10:33:16.531491434Z,2025-01-03T10:33:16.531325336Z,10,2,10888,A,B,0,420.690000000,200,130,166098,4949634,420.690000000,421.200000000,200,200,1,1,420.600000000,421.260000000,15,13,1,1,420.580000000,421.460000000,10,39,1,1,420.520000000,421.490000000,1,6,1,1,420.400000000,421.570000000,858,40,1,1,420.380000000,421.600000000,100,510,1,2,420.100000000,421.700000000,100,359,1,1,420.000000000,421.800000000,834,7,8,1,419.730000000,422.100000000,3,7,1,1,419.650000000,422.500000000,39,200,1,1,MSFT
2025-01-03T10:33:16.576729764Z,2025-01-03T10:33:16.576563525Z,10,2,6905,C,A,0,91.950000000,7,130,166239,4949808,91.530000000,91.960000000,7,100,1,1,91.480000000,93.000000000,150,1,1,1,91.440000000,94.000000000,100,1,1,1,90.000000000,95.000000000,122,2,1,2,89.000000000,96.000000000,1,1,1,1,83.810000000,97.000000000,100,2,1,2,83.400000000,99.950000000,100,100,1,1,,100.360000000,0,100,0,1,,,0,0,0,0,,,0,0,0,0,GILD
2025-01-03T10:33:16.576847548Z,2025-01-03T10:33:16.576681316Z,10,2,6905,A,A,0,91.930000000,7,130,166232,4949809,91.530000000,91.930000000,7,7,1,1,91.480000000,91.960000000,150,100,1,1,91.440000000,93.000000000,100,1,1,1,90.000000000,94.000000000,122,1,1,1,89.000000000,95.000000000,1,2,1,2,83.810000000,96.000000000,100,1,1,1,83.400000000,97.000000000,100,2,1,2,,99.950000000,0,100,0,1,,100.360000000,0,100,0,1,,,0,0,0,0,GILD
2025-01-03T10:33:16.599479790Z,2025-01-03T10:33:16.599313202Z,10,2,11667,A,A,1,139.220000000,400,130,166588,4949842,139.150000000,139.200000000,9860,100,2,1,139.130000000,139.220000000,2100,510,1,3,139.120000000,139.230000000,30,1977,1,2,139.110000000,139.250000000,1,1,1,1,139.100000000,139.270000000,10,37,1,2,139.090000000,139.300000000,57,507,1,4,139.080000000,139.320000000,400,39,1,1,139.070000000,139.330000000,100,503,1,2,139.030000000,139.360000000,126,4,2,2,139.010000000,139.370000000,100,75,1,1,NVDA
2025-01-03T10:33:16.801084241Z,2025-01-03T10:33:16.800917601Z,10,2,11667,C,B,6,139.080000000,400,130,166640,4950319,139.150000000,139.200000000,9860,100,2,1,139.130000000,139.220000000,2100,510,1,3,139.120000000,139.230000000,30,1977,1,2,139.110000000,139.250000000,1,1,1,1,139.100000000,139.270000000,10,37,1,2,139.090000000,139.300000000,57,507,1,4,139.070000000,139.320000000,100,39,1,1,139.030000000,139.330000000,126,503,2,2,139.010000000,139.360000000,100,4,1,2,139.000000000,139.370000000,910,75,5,1,NVDA
2025-01-03T10:33:16.801096764Z,2025-01-03T10:33:16.800930548Z,10,2,11667,A,B,6,139.070000000,400,130,166216,4950320,139.150000000,139.200000000,9860,100,2,1,139.130000000,139.220000000,2100,510,1,3,139.120000000,139.230000000,30,1977,1,2,139.110000000,139.250000000,1,1,1,1,139.100000000,139.270000000,10,37,1,2,139.090000000,139.300000000,57,507,1,4,139.070000000,139.320000000,500,39,2,1,139.030000000,139.330000000,126,503,2,2,139.010000000,139.360000000,100,4,1,2,139.000000000,139.370000000,910,75,5,1,NVDA
2025-01-03T10:33:17.024723243Z,2025-01-03T10:33:17.024557443Z,10,2,11667,C,A,1,139.220000000,400,130,165800,4951112,139.150000000,139.200000000,9860,100,2,1,139.130000000,139.220000000,2100,110,1,2,139.120000000,139.230000000,30,1977,1,2,139.110000000,139.250000000,1,1,1,1,139.100000000,139.270000000,10,37,1,2,139.090000000,139.300000000,57,507,1,4,139.070000000,139.320000000,500,39,2,1,139.030000000,139.330000000,126,503,2,2,139.010000000,139.360000000,100,4,1,2,139.000000000,139.370000000,910,75,5,1,NVDA
2025-01-03T10:33:17.024736536Z,2025-01-03T10:33:17.024570235Z,10,2,11667,A,A,2,139.230000000,400,130,166301,4951113,139.150000000,139.200000000,9860,100,2,1,139.130000000,139.220000000,2100,110,1,2,139.120000000,139.230000000,30,2377,1,3,139.110000000,139.250000000,1,1,1,1,139.100000000,139.270000000,10,37,1,2,139.090000000,139.300000000,57,507,1,4,139.070000000,139.320000000,500,39,2,1,139.030000000,139.330000000,126,503,2,2,139.010000000,139.360000000,100,4,1,2,139.000000000,139.370000000,910,75,5,1,NVDA
2025-01-03T10:33:17.075771718Z,2025-01-03T10:33:17.075605372Z,10,2,11667,A,B,6,139.080000000,400,130,166346,4951172,139.150000000,139.200000000,9860,100,2,1,139.130000000,139.220000000,2100,110,1,2,139.120000000,139.230000000,30,2377,1,3,139.110000000,139.250000000,1,1,1,1,139.100000000,139.270000000,10,37,1,2,139.090000000,139.300000000,57,507,1,4,139.080000000,139.320000000,400,39,1,1,139.070000000,139.330000000,100,503,1,2,139.030000000,139.360000000,126,4,2,2,139.010000000,139.370000000,100,75,1,1,NVDA
2025-01-03T10:33:17.139720460Z,2025-01-03T10:33:17.139554662Z,10,2,9155,C,B,1,241.620000000,8,130,165798,4951295,241.670000000,242.070000000,2,62,1,1,241.120000000,242.380000000,81,8,1,1,241.000000000,242.850000000,100,300,1,2,240.000000000,242.900000000,10,100,1,1,238.000000000,243.000000000,30,92,1,2,236.000000000,243.310000000,6,10,1,1,235.500000000,243.700000000,5,100,1,1,235.000000000,246.810000000,5,100,1,1,232.880000000,262.740000000,1,100,1,1,231.110000000,263.830000000,3,100,1,1,JPM
2025-01-03T10:33:17.139814252Z,2025-01-03T10:33:17.139648020Z,10,2,9155,A,B,1,241.510000000,8,130,166232,4951296,241.670000000,242.070000000,2,62,1,1,241.510000000,242.380000000,8,8,1,1,241.120000000,242.850000000,81,300,1,2,241.000000000,242.900000000,100,100,1,1,240.000000000,243.000000000,10,92,1,2,238.000000000,243.310000000,30,10,1,1,236.000000000,243.700000000,6,100,1,1,235.500000000,246.810000000,5,100,1,1,235.000000000,262.740000000,5,100,1,1,232.880000000,263.830000000,1,100,1,1,JPM
2025-01-03T10:33:17.158325307Z,2025-01-03T10:33:17.158158763Z,10,2,38,C,B,2,243.460000000,28,130,166544,4951369,243.520000000,243.660000000,200,100,1,1,243.500000000,243.720000000,6,200,1,1,243.190000000,243.770000000,2,28,1,1,243.020000000,244.000000000,79,1,1,1,243.000000000,244.140000000,1243,79,9,1,242.990000000,244.200000000,1,1000,1,1,242.800000000,244.400000000,30,50,1,1,242.750000000,244.420000000,30,10,1,1,242.590000000,245.000000000,5,79,1,2,242.280000000,245.190000000,100,83,1,1,AAPL
2025-01-03T10:33:17.158387678Z,2025-01-03T10:33:17.158221413Z,10,2,38,A,B,2,243.470000000,28,130,166265,4951370,243.520000000,243.660000000,200,100,1,1,243.500000000,243.720000000,6,200,1,1,243.470000000,243.770000000,28,28,1,1,243.190000000,244.000000000,2,1,1,1,243.020000000,244.140000000,79,79,1,1,243.000000000,244.200000000,1243,1000,9,1,242.990000000,244.400000000,1,50,1,1,242.800000000,244.420000000,30,10,1,1,242.750000000,245.000000000,30,79,1,2,242.590000000,245.190000000,5,83,1,1,AAPL
2025-01-03T10:33:17.308619921Z,2025-01-03T10:33:17.308454054Z,10,2,17709,C,A,2,107.880000000,100,130,165867,4951478,107.600000000,107.840000000,50,400,1,2,107.550000000,107.870000000,15,242,1,1,107.520000000,107.890000000,100,17,1,1,107.050000000,107.950000000,247,10,1,1,107.000000000,108.000000000,1,50,1,1,106.240000000,108.300000000,28,50,1,1,106.000000000,108.550000000,15,50,2,1,105.870000000,108.800000000,141,50,1,1,103.180000000,108.880000000,16,28,1,1,103.000000000,109.000000000,3,100,1,1,XOM
2025-01-03T10:33:17.308633326Z,2025-01-03T10:33:17.308466313Z,10,2,17709,A,A,3,107.940000000,100,130,167013,4951480,107.600000000,107.840000000,50,400,1,2,107.550000000,107.870000000,15,242,1,1,107.520000000,107.890000000,100,17,1,1,107.050000000,107.940000000,247,100,1,1,107.000000000,107.950000000,1,10,1,1,106.240000000,108.000000000,28,50,1,1,106.000000000,108.300000000,15,50,2,1,105.870000000,108.550000000,141,50,1,1,103.180000000,108.800000000,16,50,1,1,103.000000000,108.880000000,3,28,1,1,XOM
2025-01-03T10:33:17.308994110Z,2025-01-03T10:33:17.308828427Z,10,2,17709,C,A,2,107.890000000,17,130,165683,4951487,107.600000000,107.840000000,50,400,1,2,107.550000000,107.870000000,15,242,1,1,107.520000000,107.940000000,100,100,1,1,107.050000000,107.950000000,247,10,1,1,107.000000000,108.000000000,1,50,1,1,106.240000000,108.300000000,28,50,1,1,106.000000000,108.550000000,15,50,2,1,105.870000000,108.800000000,141,50,1,1,103.180000000,108.880000000,16,28,1,1,103.000000000,109.000000000,3,100,1,1,XOM
2025-01-03T10:33:17.409593754Z,2025-01-03T10:33:17.409426992Z,10,2,17709,A,A,2,107.920000000,15,130,166762,4951730,107.600000000,107.840000000,50,400,1,2,107.550000000,107.870000000,15,242,1,1,107.520000000,107.920000000,100,15,1,1,107.050000000,107.940000000,247,100,1,1,107.000000000,107.950000000,1,10,1,1,106.240000000,108.000000000,28,50,1,1,106.000000000,108.300000000,15,50,2,1,105.870000000,108.550000000,141,50,1,1,103.180000000,108.800000000,16,50,1,1,103.000000000,108.880000000,3,28,1,1,XOM
2025-01-03T10:33:18.136013327Z,2025-01-03T10:33:18.135847231Z,10,2,9155,C,B,1,241.510000000,8,130,166096,4952893,241.670000000,242.070000000,2,62,1,1,241.120000000,242.380000000,81,8,1,1,241.000000000,242.850000000,100,300,1,2,240.000000000,242.900000000,10,100,1,1,238.000000000,243.000000000,30,92,1,2,236.000000000,243.310000000,6,10,1,1,235.500000000,243.700000000,5,100,1,1,235.000000000,246.810000000,5,100,1,1,232.880000000,262.740000000,1,100,1,1,231.110000000,263.830000000,3,100,1,1,JPM
2025-01-03T10:33:20.344240001Z,2025-01-03T10:33:20.344074096Z,10,2,11667,C,B,6,139.080000000,400,130,165905,4955211,139.150000000,139.200000000,9860,100,2,1,139.130000000,139.220000000,2100,110,1,2,139.120000000,139.230000000,30,2377,1,3,139.110000000,139.250000000,1,1,1,1,139.100000000,139.270000000,10,37,1,2,139.090000000,139.300000000,57,507,1,4,139.070000000,139.320000000,100,39,1,1,139.030000000,139.330000000,126,503,2,2,139.010000000,139.360000000,100,4,1,2,139.000000000,139.370000000,910,75,5,1,NVDA
2025-01-03T10:33:20.344252825Z,2025-01-03T10:33:20.344086464Z,10,2,11667,A,B,6,139.070000000,400,130,166361,4955212,139.150000000,139.200000000,9860,100,2,1,139.130000000,139.220000000,2100,110,1,2,139.120000000,139.230000000,30,2377,1,3,139.110000000,139.250000000,1,1,1,1,139.100000000,139.270000000,10,37,1,2,139.090000000,139.300000000,57,507,1,4,139.070000000,139.320000000,500,39,2,1,139.030000000,139.330000000,126,503,2,2,139.010000000,139.360000000,100,4,1,2,139.000000000,139.370000000,910,75,5,1,NVDA
2025-01-03T10:33:20.377505805Z,2025-01-03T10:33:20.377337545Z,10,2,11667,T,N,0,139.160000000,70,0,168260,4955321,139.150000000,139.200000000,9860,100,2,1,139.130000000,139.220000000,2100,110,1,2,139.120000000,139.230000000,30,2377,1,3,139.110000000,139.250000000,1,1,1,1,139.100000000,139.270000000,10,37,1,2,139.090000000,139.300000000,57,507,1,4,139.070000000,139.320000000,500,39,2,1,139.030000000,139.330000000,126,503,2,2,139.010000000,139.360000000,100,4,1,2,139.000000000,139.370000000,910,75,5,1,NVDA
2025-01-03T10:33:20.377505805Z,2025-01-03T10:33:20.377337545Z,10,2,11667,T,N,0,139.160000000,30,130,168260,4955322,139.150000000,139.200000000,9860,100,2,1,139.130000000,139.220000000,2100,110,1,2,139.120000000,139.230000000,30,2377,1,3,139.110000000,139.250000000,1,1,1,1,139.100000000,139.270000000,10,37,1,2,139.090000000,139.300000000,57,507,1,4,139.070000000,139.320000000,500,39,2,1,139.030000000,139.330000000,126,503,2,2,139.010000000,139.360000000,100,4,1,2,139.000000000,139.370000000,910,75,5,1,NVDA
2025-01-03T10:33:20.405690150Z,2025-01-03T10:33:20.405523845Z,10,2,11667,A,A,1,139.210000000,400,130,166305,4955535,139.150000000,139.200000000,9860,100,2,1,139.130000000,139.210000000,2100,400,1,1,139.120000000,139.220000000,30,110,1,2,139.110000000,139.230000000,1,1977,1,2,139.100000000,139.250000000,10,1,1,1,139.090000000,139.270000000,57,37,1,2,139.070000000,139.300000000,500,507,2,4,139.030000000,139.320000000,126,39,2,1,139.010000000,139.330000000,100,503,1,2,139.000000000,139.360000000,910,4,5,2,NVDA
2025-01-03T10:33:20.895811574Z,2025-01-03T10:33:20.895645543Z,10,2,11667,A,B,6,139.080000000,400,130,166031,4956152,139.150000000,139.200000000,9860,100,2,1,139.130000000,139.210000000,2100,400,1,1,139.120000000,139.220000000,30,110,1,2,139.110000000,139.230000000,1,1977,1,2,139.100000000,139.250000000,10,1,1,1,139.090000000,139.270000000,57,37,1,2,139.080000000,139.300000000,400,507,1,4,139.070000000,139.320000000,100,39,1,1,139.030000000,139.330000000,126,503,2,2,139.010000000,139.360000000,100,4,1,2,NVDA
2025-01-03T10:33:20.936453371Z,2025-01-03T10:33:20.936287163Z,10,2,17709,A,B,2,107.530000000,15,130,166208,4956270,107.600000000,107.840000000,50,400,1,2,107.550000000,107.870000000,15,242,1,1,107.530000000,107.920000000,15,15,1,1,107.520000000,107.940000000,100,100,1,1,107.050000000,107.950000000,247,10,1,1,107.000000000,108.000000000,1,50,1,1,106.240000000,108.300000000,28,50,1,1,106.000000000,108.550000000,15,50,2,1,105.870000000,108.800000000,141,50,1,1,103.180000000,108.880000000,16,28,1,1,XOM
2025-01-03T10:33:20.936484878Z,2025-01-03T10:33:20.936318934Z,10,2,17709,C,B,1,107.550000000,15,130,165944,4956271,107.600000000,107.840000000,50,400,1,2,107.530000000,107.870000000,15,242,1,1,107.520000000,107.920000000,100,15,1,1,107.050000000,107.940000000,247,100,1,1,107.000000000,107.950000000,1,10,1,1,106.240000000,108.000000000,28,50,1,1,106.000000000,108.300000000,15,50,2,1,105.870000000,108.550000000,141,50,1,1,103.180000000,108.800000000,16,50,1,1,103.000000000,108.880000000,3,28,1,1,XOM
2025-01-03T10:33:20.973186161Z,2025-01-03T10:33:20.973019944Z,10,2,16244,A,B,2,382.900000000,50,130,166217,4956319,382.990000000,383.250000000,30,47,1,1,382.920000000,383.420000000,22,140,1,1,382.900000000,383.460000000,50,20,1,1,382.880000000,383.600000000,100,500,1,1,382.840000000,383.720000000,300,7085,1,8,382.820000000,383.740000000,1,37,1,1,382.810000000,383.800000000,20,10,2,1,382.700000000,383.880000000,50,4,1,1,382.400000000,384.000000000,500,1300,1,4,382.230000000,384.260000000,25,15,1,1,TSLA
2025-01-03T10:33:21.251535469Z,2025-01-03T10:33:21.251368288Z,10,2,11667,T,A,0,139.150000000,70,130,167181,4956643,139.150000000,139.200000000,9860,100,2,1,139.130000000,139.210000000,2100,400,1,1,139.120000000,139.220000000,30,110,1,2,139.110000000,139.230000000,1,1977,1,2,139.100000000,139.250000000,10,1,1,1,139.090000000,139.270000000,57,37,1,2,139.080000000,139.300000000,400,507,1,4,139.070000000,139.320000000,100,39,1,1,139.030000000,139.330000000,126,503,2,2,139.010000000,139.360000000,100,4,1,2,NVDA
2025-01-03T10:33:21.251535469Z,2025-01-03T10:33:21.251368288Z,10,2,11667,C,B,0,139.150000000,70,130,167181,4956643,139.150000000,139.200000000,9790,100,2,1,139.130000000,139.210000000,2100,400,1,1,139.120000000,139.220000000,30,110,1,2,139.110000000,139.230000000,1,1977,1,2,139.100000000,139.250000000,10,1,1,1,139.090000000,139.270000000,57,37,1,2,139.080000000,139.300000000,400,507,1,4,139.070000000,139.320000000,100,39,1,1,139.030000000,139.330000000,126,503,2,2,139.010000000,139.360000000,100,4,1,2,NVDA
2025-01-03T10:33:21.251539571Z,2025-01-03T10:33:21.251369658Z,10,2,11667,T,A,0,139.150000000,70,0,169913,4956644,139.150000000,139.200000000,9790,100,2,1,139.130000000,139.210000000,2100,400,1,1,139.120000000,139.220000000,30,110,1,2,139.110000000,139.230000000,1,1977,1,2,139.100000000,139.250000000,10,1,1,1,139.090000000,139.270000000,57,37,1,2,139.080000000,139.300000000,400,507,1,4,139.070000000,139.320000000,100,39,1,1,139.030000000,139.330000000,126,503,2,2,139.010000000,139.360000000,100,4,1,2,NVDA
2025-01-03T10:33:21.251539571Z,2025-01-03T10:33:21.251371392Z,10,2,11667,T,A,0,139.150000000,70,130,168179,4956646,139.150000000,139.200000000,9720,100,2,1,139.130000000,139.210000000,2100,400,1,1,139.120000000,139.220000000,30,110,1,2,139.110000000,139.230000000,1,1977,1,2,139.100000000,139.250000000,10,1,1,1,139.090000000,139.270000000,57,37,1,2,139.080000000,139.300000000,400,507,1,4,139.070000000,139.320000000,100,39,1,1,139.030000000,139.330000000,126,503,2,2,139.010000000,139.360000000,100,4,1,2,NVDA
2025-01-03T10:33:21.251539571Z,2025-01-03T10:33:21.251371392Z,10,2,11667,C,B,0,139.150000000,70,130,168179,4956646,139.150000000,139.200000000,9650,100,2,1,139.130000000,139.210000000,2100,400,1,1,139.120000000,139.220000000,30,110,1,2,139.110000000,139.230000000,1,1977,1,2,139.100000000,139.250000000,10,1,1,1,139.090000000,139.270000000,57,37,1,2,139.080000000,139.300000000,400,507,1,4,139.070000000,139.320000000,100,39,1,1,139.030000000,139.330000000,126,503,2,2,139.010000000,139.360000000,100,4,1,2,NVDA
2025-01-03T10:33:21.251542000Z,2025-01-03T10:33:21.251372922Z,10,2,11667,T,A,0,139.150000000,100,0,169078,4956647,139.150000000,139.200000000,9650,100,2,1,139.130000000,139.210000000,2100,400,1,1,139.120000000,139.220000000,30,110,1,2,139.110000000,139.230000000,1,1977,1,2,139.100000000,139.250000000,10,1,1,1,139.090000000,139.270000000,57,37,1,2,139.080000000,139.300000000,400,507,1,4,139.070000000,139.320000000,100,39,1,1,139.030000000,139.330000000,126,503,2,2,139.010000000,139.360000000,100,4,1,2,NVDA
2025-01-03T10:33:21.251542000Z,2025-01-03T10:33:21.251374903Z,10,2,11667,C,B,0,139.080000000,400,130,167097,4956648,139.150000000,139.200000000,9550,100,2,1,139.130000000,139.210000000,2100,400,1,1,139.120000000,139.220000000,30,110,1,2,139.110000000,139.230000000,1,1977,1,2,139.100000000,139.250000000,10,1,1,1,139.090000000,139.270000000,57,37,1,2,139.070000000,139.300000000,100,507,1,4,139.030000000,139.320000000,126,39,2,1,139.010000000,139.330000000,100,503,1,2,139.000000000,139.360000000,910,4,5,2,NVDA
2025-01-03T10:33:21.251550527Z,2025-01-03T10:33:21.251382022Z,10,2,11667,T,A,0,139.150000000,53,130,168505,4956649,139.150000000,139.200000000,9550,100,2,1,139.130000000,139.210000000,2100,400,1,1,139.120000000,139.220000000,30,110,1,2,139.110000000,139.230000000,1,1977,1,2,139.100000000,139.250000000,10,1,1,1,139.090000000,139.270000000,57,37,1,2,139.070000000,139.300000000,100,507,1,4,139.030000000,139.320000000,126,39,2,1,139.010000000,139.330000000,100,503,1,2,139.000000000,139.360000000,910,4,5,2,NVDA
2025-01-03T10:33:21.251550527Z,2025-01-03T10:33:21.251382022Z,10,2,11667,C,B,0,139.150000000,53,130,168505,4956649,139.150000000,139.200000000,9497,100,2,1,139.130000000,139.210000000,2100,400,1,1,139.120000000,139.220000000,30,110,1,2,139.110000000,139.230000000,1,1977,1,2,139.100000000,139.250000000,10,1,1,1,139.090000000,139.270000000,57,37,1,2,139.070000000,139.300000000,100,507,1,4,139.030000000,139.320000000,126,39,2,1,139.010000000,139.330000000,100,503,1,2,139.000000000,139.360000000,910,4,5,2,NVDA
2025-01-03T10:33:21.323200703Z,2025-01-03T10:33:21.323034751Z,10,2,11667,C,A,1,139.210000000,400,130,165952,4956955,139.150000000,139.200000000,9497,100,2,1,139.130000000,139.220000000,2100,110,1,2,139.120000000,139.230000000,30,1977,1,2,139.110000000,139.250000000,1,1,1,1,139.100000000,139.270000000,10,37,1,2,139.090000000,139.300000000,57,507,1,4,139.070000000,139.320000000,100,39,1,1,139.030000000,139.330000000,126,503,2,2,139.010000000,139.360000000,100,4,1,2,139.000000000,139.370000000,910,75,5,1,NVDA
2025-01-03T10:33:21.323214322Z,2025-01-03T10:33:21.323047813Z,10,2,11667,A,A,2,139.230000000,400,130,166509,4956956,139.150000000,139.200000000,9497,100,2,1,139.130000000,139.220000000,2100,110,1,2,139.120000000,139.230000000,30,2377,1,3,139.110000000,139.250000000,1,1,1,1,139.100000000,139.270000000,10,37,1,2,139.090000000,139.300000000,57,507,1,4,139.070000000,139.320000000,100,39,1,1,139.030000000,139.330000000,126,503,2,2,139.010000000,139.360000000,100,4,1,2,139.000000000,139.370000000,910,75,5,1,NVDA
2025-01-03T10:33:21.352042490Z,2025-01-03T10:33:21.351875501Z,10,2,11667,T,A,0,139.150000000,45,130,166989,4956985,139.150000000,139.200000000,9497,100,2,1,139.130000000,139.220000000,2100,110,1,2,139.120000000,139.230000000,30,2377,1,3,139.110000000,139.250000000,1,1,1,1,139.100000000,139.270000000,10,37,1,2,139.090000000,139.300000000,57,507,1,4,139.070000000,139.320000000,100,39,1,1,139.030000000,139.330000000,126,503,2,2,139.010000000,139.360000000,100,4,1,2,139.000000000,139.370000000,910,75,5,1,NVDA
2025-01-03T10:33:21.352042490Z,2025-01-03T10:33:21.351875501Z,10,2,11667,C,B,0,139.150000000,45,130,166989,4956985,139.150000000,139.200000000,9452,100,2,1,139.130000000,139.220000000,2100,110,1,2,139.120000000,139.230000000,30,2377,1,3,139.110000000,139.250000000,1,1,1,1,139.100000000,139.270000000,10,37,1,2,139.090000000,139.300000000,57,507,1,4,139.070000000,139.320000000,100,39,1,1,139.030000000,139.330000000,126,503,2,2,139.010000000,139.360000000,100,4,1,2,139.000000000,139.370000000,910,75,5,1,NVDA
2025-01-03T10:33:21.352084811Z,2025-01-03T10:33:21.351918055Z,10,2,11667,T,A,0,139.150000000,24,130,166756,4956986,139.150000000,139.200000000,9452,100,2,1,139.130000000,139.220000000,2100,110,1,2,139.120000000,139.230000000,30,2377,1,3,139.110000000,139.250000000,1,1,1,1,139.100000000,139.270000000,10,37,1,2,139.090000000,139.300000000,57,507,1,4,139.070000000,139.320000000,100,39,1,1,139.030000000,139.330000000,126,503,2,2,139.010000000,139.360000000,100,4,1,2,139.000000000,139.370000000,910,75,5,1,NVDA
2025-01-03T10:33:21.352084811Z,2025-01-03T10:33:21.351918055Z,10,2,11667,C,B,0,139.150000000,24,130,166756,4956986,139.150000000,139.200000000,9428,100,2,1,139.130000000,139.220000000,2100,110,1,2,139.120000000,139.230000000,30,2377,1,3,139.110000000,139.250000000,1,1,1,1,139.100000000,139.270000000,10,37,1,2,139.090000000,139.300000000,57,507,1,4,139.070000000,139.320000000,100,39,1,1,139.030000000,139.330000000,126,503,2,2,139.010000000,139.360000000,100,4,1,2,139.000000000,139.370000000,910,75,5,1,NVDA
2025-01-03T10:33:21.352089034Z,2025-01-03T10:33:21.351919615Z,10,2,11667,T,A,0,139.150000000,3,0,169419,4956987,139.150000000,139.200000000,9428,100,2,1,139.130000000,139.220000000,2100,110,1,2,139.120000000,139.230000000,30,2377,1,3,139.110000000,139.250000000,1,1,1,1,139.100000000,139.270000000,10,37,1,2,139.090000000,139.300000000,57,507,1,4,139.070000000,139.320000000,100,39,1,1,139.030000000,139.330000000,126,503,2,2,139.010000000,139.360000000,100,4,1,2,139.000000000,139.370000000,910,75,5,1,NVDA
2025-01-03T10:33:21.352089034Z,2025-01-03T10:33:21.351920120Z,10,2,11667,T,A,0,139.150000000,13,130,168914,4956988,139.150000000,139.200000000,9425,100,2,1,139.130000000,139.220000000,2100,110,1,2,139.120000000,139.230000000,30,2377,1,3,139.110000000,139.250000000,1,1,1,1,139.100000000,139.270000000,10,37,1,2,139.090000000,139.300000000,57,507,1,4,139.070000000,139.320000000,100,39,1,1,139.030000000,139.330000000,126,503,2,2,139.010000000,139.360000000,100,4,1,2,139.000000000,139.370000000,910,75,5,1,NVDA
2025-01-03T10:33:21.352089034Z,2025-01-03T10:33:21.351920120Z,10,2,11667,C,B,0,139.150000000,13,130,168914,4956988,139.150000000,139.200000000,9412,100,2,1,139.130000000,139.220000000,2100,110,1,2,139.120000000,139.230000000,30,2377,1,3,139.110000000,139.250000000,1,1,1,1,139.100000000,139.270000000,10,37,1,2,139.090000000,139.300000000,57,507,1,4,139.070000000,139.320000000,100,39,1,1,139.030000000,139.330000000,126,503,2,2,139.010000000,139.360000000,100,4,1,2,139.000000000,139.370000000,910,75,5,1,NVDA
2025-01-03T10:33:21.380069053Z,2025-01-03T10:33:21.379902714Z,10,2,11667,A,A,1,139.210000000,400,130,166339,4957073,139.150000000,139.200000000,9412,100,2,1,139.130000000,139.210000000,2100,400,1,1,139.120000000,139.220000000,30,110,1,2,139.110000000,139.230000000,1,1977,1,2,139.100000000,139.250000000,10,1,1,1,139.090000000,139.270000000,57,37,1,2,139.070000000,139.300000000,100,507,1,4,139.030000000,139.320000000,126,39,2,1,139.010000000,139.330000000,100,503,1,2,139.000000000,139.360000000,910,4,5,2,NVDA
2025-01-03T10:33:21.470078667Z,2025-01-03T10:33:21.469912276Z,10,2,11667,A,B,7,139.050000000,400,130,166391,4957185,139.150000000,139.200000000,9412,100,2,1,139.130000000,139.210000000,2100,400,1,1,139.120000000,139.220000000,30,110,1,2,139.110000000,139.230000000,1,1977,1,2,139.100000000,139.250000000,10,1,1,1,139.090000000,139.270000000,57,37,1,2,139.070000000,139.300000000,100,507,1,4,139.050000000,139.320000000,400,39,1,1,139.030000000,139.330000000,126,503,2,2,139.010000000,139.360000000,100,4,1,2,NVDA
2025-01-03T10:33:21.561628553Z,2025-01-03T10:33:21.561462594Z,10,2,10888,C,A,0,421.200000000,200,130,165959,4957367,420.690000000,421.260000000,200,13,1,1,420.600000000,421.460000000,15,39,1,1,420.580000000,421.490000000,10,6,1,1,420.520000000,421.570000000,1,40,1,1,420.400000000,421.600000000,858,510,1,2,420.380000000,421.700000000,100,359,1,1,420.100000000,421.800000000,100,7,1,1,420.000000000,422.100000000,834,7,8,1,419.730000000,422.500000000,3,200,1,1,419.650000000,423.500000000,39,600,1,2,MSFT
2025-01-03T10:33:21.561641817Z,2025-01-03T10:33:21.561475567Z,10,2,10888,A,A,0,421.230000000,200,130,166250,4957368,420.690000000,421.230000000,200,200,1,1,420.600000000,421.260000000,15,13,1,1,420.580000000,421.460000000,10,39,1,1,420.520000000,421.490000000,1,6,1,1,420.400000000,421.570000000,858,40,1,1,420.380000000,421.600000000,100,510,1,2,420.100000000,421.700000000,100,359,1,1,420.000000000,421.800000000,834,7,8,1,419.730000000,422.100000000,3,7,1,1,419.650000000,422.500000000,39,200,1,1,MSFT
2025-01-03T10:33:21.624633120Z,2025-01-03T10:33:21.624467041Z,10,2,10888,C,B,1,420.600000000,15,130,166079,4957404,420.690000000,421.230000000,200,200,1,1,420.580000000,421.260000000,10,13,1,1,420.520000000,421.460000000,1,39,1,1,420.400000000,421.490000000,858,6,1,1,420.380000000,421.570000000,100,40,1,1,420.100000000,421.600000000,100,510,1,2,420.000000000,421.700000000,834,359,8,1,419.730000000,421.800000000,3,7,1,1,419.650000000,422.100000000,39,7,1,1,418.650000000,422.500000000,1,200,1,1,MSFT
2025-01-03T10:33:21.624704803Z,2025-01-03T10:33:21.624538607Z,10,2,10888,A,B,1,420.610000000,13,130,166196,4957405,420.690000000,421.230000000,200,200,1,1,420.610000000,421.260000000,13,13,1,1,420.580000000,421.460000000,10,39,1,1,420.520000000,421.490000000,1,6,1,1,420.400000000,421.570000000,858,40,1,1,420.380000000,421.600000000,100,510,1,2,420.100000000,421.700000000,100,359,1,1,420.000000000,421.800000000,834,7,8,1,419.730000000,422.100000000,3,7,1,1,419.650000000,422.500000000,39,200,1,1,MSFT
2025-01-03T10:33:21.877866500Z,2025-01-03T10:33:21.877700309Z,10,2,9155,A,B,1,241.510000000,8,130,166191,4957526,241.670000000,242.070000000,2,62,1,1,241.510000000,242.380000000,8,8,1,1,241.120000000,242.850000000,81,300,1,2,241.000000000,242.900000000,100,100,1,1,240.000000000,243.000000000,10,92,1,2,238.000000000,243.310000000,30,10,1,1,236.000000000,243.700000000,6,100,1,1,235.500000000,246.810000000,5,100,1,1,235.000000000,262.740000000,5,100,1,1,232.880000000,263.830000000,1,100,1,1,JPM
2025-01-03T10:33:22.964051303Z,2025-01-03T10:33:22.963884717Z,10,2,16244,A,A,3,383.600000000,500,130,166586,4958271,382.990000000,383.250000000,30,47,1,1,382.920000000,383.420000000,22,140,1,1,382.900000000,383.460000000,50,20,1,1,382.880000000,383.600000000,100,1000,1,2,382.840000000,383.720000000,300,7085,1,8,382.820000000,383.740000000,1,37,1,1,382.810000000,383.800000000,20,10,2,1,382.700000000,383.880000000,50,4,1,1,382.400000000,384.000000000,500,1300,1,4,382.230000000,384.260000000,25,15,1,1,TSLA
2025-01-03T10:33:23.253447353Z,2025-01-03T10:33:23.253281097Z,10,2,11667,A,B,7,139.060000000,400,130,166256,4958479,139.150000000,139.200000000,9412,100,2,1,139.130000000,139.210000000,2100,400,1,1,139.120000000,139.220000000,30,110,1,2,139.110000000,139.230000000,1,1977,1,2,139.100000000,139.250000000,10,1,1,1,139.090000000,139.270000000,57,37,1,2,139.070000000,139.300000000,100,507,1,4,139.060000000,139.320000000,400,39,1,1,139.030000000,139.330000000,126,503,2,2,139.010000000,139.360000000,100,4,1,2,NVDA
2025-01-03T10:33:24.616683439Z,2025-01-03T10:33:24.616516967Z,10,2,10888,A,A,0,421.170000000,200,130,166472,4959454,420.690000000,421.170000000,200,200,1,1,420.610000000,421.260000000,13,13,1,1,420.580000000,421.460000000,10,39,1,1,420.520000000,421.490000000,1,6,1,1,420.400000000,421.570000000,858,40,1,1,420.380000000,421.600000000,100,510,1,2,420.100000000,421.700000000,100,359,1,1,420.000000000,421.800000000,834,7,8,1,419.730000000,422.100000000,3,7,1,1,419.650000000,422.500000000,39,200,1,1,MSFT
2025-01-03T10:33:25.008699289Z,2025-01-03T10:33:25.008533223Z,10,2,10888,C,B,0,420.690000000,200,130,166066,4959831,420.610000000,421.170000000,13,200,1,1,420.580000000,421.260000000,10,13,1,1,420.520000000,421.460000000,1,39,1,1,420.400000000,421.490000000,858,6,1,1,420.380000000,421.570000000,100,40,1,1,420.100000000,421.600000000,100,510,1,2,420.000000000,421.700000000,834,359,8,1,419.730000000,421.800000000,3,7,1,1,419.650000000,422.100000000,39,7,1,1,418.650000000,422.500000000,1,200,1,1,MSFT
2025-01-03T10:33:25.009234426Z,2025-01-03T10:33:25.009068556Z,10,2,10888,C,A,1,421.260000000,13,130,165870,4959833,420.610000000,421.170000000,13,200,1,1,420.580000000,421.460000000,10,39,1,1,420.520000000,421.490000000,1,6,1,1,420.400000000,421.570000000,858,40,1,1,420.380000000,421.600000000,100,510,1,2,420.100000000,421.700000000,100,359,1,1,420.000000000,421.800000000,834,7,8,1,419.730000000,422.100000000,3,7,1,1,419.650000000,422.500000000,39,200,1,1,418.650000000,423.500000000,1,600,1,2,MSFT
2025-01-03T10:33:25.009354496Z,2025-01-03T10:33:25.009188327Z,10,2,10888,A,A,1,421.220000000,14,130,166169,4959835,420.610000000,421.170000000,13,200,1,1,420.580000000,421.220000000,10,14,1,1,420.520000000,421.460000000,1,39,1,1,420.400000000,421.490000000,858,6,1,1,420.380000000,421.570000000,100,40,1,1,420.100000000,421.600000000,100,510,1,2,420.000000000,421.700000000,834,359,8,1,419.730000000,421.800000000,3,7,1,1,419.650000000,422.100000000,39,7,1,1,418.650000000,422.500000000,1,200,1,1,MSFT
2025-01-03T10:33:25.009480217Z,2025-01-03T10:33:25.009314218Z,10,2,10888,C,B,0,420.610000000,13,130,165999,4959836,420.580000000,421.170000000,10,200,1,1,420.520000000,421.220000000,1,14,1,1,420.400000000,421.460000000,858,39,1,1,420.380000000,421.490000000,100,6,1,1,420.100000000,421.570000000,100,40,1,1,420.000000000,421.600000000,834,510,8,2,419.730000000,421.700000000,3,359,1,1,419.650000000,421.800000000,39,7,1,1,418.650000000,422.100000000,1,7,1,1,418.500000000,422.500000000,1,200,1,1,MSFT
2025-01-03T10:33:25.009568026Z,2025-01-03T10:33:25.009401792Z,10,2,10888,A,B,1,420.560000000,14,130,166234,4959837,420.580000000,421.170000000,10,200,1,1,420.560000000,421.220000000,14,14,1,1,420.520000000,421.460000000,1,39,1,1,420.400000000,421.490000000,858,6,1,1,420.380000000,421.570000000,100,40,1,1,420.100000000,421.600000000,100,510,1,2,420.000000000,421.700000000,834,359,8,1,419.730000000,421.800000000,3,7,1,1,419.650000000,422.100000000,39,7,1,1,418.650000000,422.500000000,1,200,1,1,MSFT
2025-01-03T10:33:25.010143429Z,2025-01-03T10:33:25.009977600Z,10,2,10888,C,B,1,420.560000000,14,130,165829,4959838,420.580000000,421.170000000,10,200,1,1,420.520000000,421.220000000,1,14,1,1,420.400000000,421.460000000,858,39,1,1,420.380000000,421.490000000,100,6,1,1,420.100000000,421.570000000,100,40,1,1,420.000000000,421.600000000,834,510,8,2,419.730000000,421.700000000,3,359,1,1,419.650000000,421.800000000,39,7,1,1,418.650000000,422.100000000,1,7,1,1,418.500000000,422.500000000,1,200,1,1,MSFT
2025-01-03T10:33:25.060762001Z,2025-01-03T10:33:25.060595823Z,10,2,10888,A,B,1,420.530000000,200,130,166178,4959889,420.580000000,421.170000000,10,200,1,1,420.530000000,421.220000000,200,14,1,1,420.520000000,421.460000000,1,39,1,1,420.400000000,421.490000000,858,6,1,1,420.380000000,421.570000000,100,40,1,1,420.100000000,421.600000000,100,510,1,2,420.000000000,421.700000000,834,359,8,1,419.730000000,421.800000000,3,7,1,1,419.650000000,422.100000000,39,7,1,1,418.650000000,422.500000000,1,200,1,1,MSFT
2025-01-03T10:33:25.060777224Z,2025-01-03T10:33:25.060610777Z,10,2,10888,A,A,0,421.160000000,200,130,166447,4959890,420.580000000,421.160000000,10,200,1,1,420.530000000,421.220000000,200,14,1,1,420.520000000,421.460000000,1,39,1,1,420.400000000,421.490000000,858,6,1,1,420.380000000,421.570000000,100,40,1,1,420.100000000,421.600000000,100,510,1,2,420.000000000,421.700000000,834,359,8,1,419.730000000,421.800000000,3,7,1,1,419.650000000,422.100000000,39,7,1,1,418.650000000,422.500000000,1,200,1,1,MSFT
2025-01-03T10:33:25.071761889Z,2025-01-03T10:33:25.071595526Z,10,2,10888,A,A,0,421.110000000,200,130,166363,4959896,420.580000000,421.110000000,10,200,1,1,420.530000000,421.220000000,200,14,1,1,420.520000000,421.460000000,1,39,1,1,420.400000000,421.490000000,858,6,1,1,420.380000000,421.570000000,100,40,1,1,420.100000000,421.600000000,100,510,1,2,420.000000000,421.700000000,834,359,8,1,419.730000000,421.800000000,3,7,1,1,419.650000000,422.100000000,39,7,1,1,418.650000000,422.500000000,1,200,1,1,MSFT
2025-01-03T10:33:25.684662440Z,2025-01-03T10:33:25.684494515Z,10,2,11667,T,N,0,139.170000000,15,130,167925,4960338,139.150000000,139.200000000,9412,100,2,1,139.130000000,139.210000000,2100,400,1,1,139.120000000,139.220000000,30,110,1,2,139.110000000,139.230000000,1,1977,1,2,139.100000000,139.250000000,10,1,1,1,139.090000000,139.270000000,57,37,1,2,139.070000000,139.300000000,100,507,1,4,139.060000000,139.320000000,400,39,1,1,139.030000000,139.330000000,126,503,2,2,139.010000000,139.360000000,100,4,1,2,NVDA
2025-01-03T10:33:25.817877267Z,2025-01-03T10:33:25.817711255Z,10,2,17709,C,A,2,107.920000000,15,130,166012,4960377,107.600000000,107.840000000,50,400,1,2,107.530000000,107.870000000,15,242,1,1,107.520000000,107.940000000,100,100,1,1,107.050000000,107.950000000,247,10,1,1,107.000000000,108.000000000,1,50,1,1,106.240000000,108.300000000,28,50,1,1,106.000000000,108.550000000,15,50,2,1,105.870000000,108.800000000,141,50,1,1,103.180000000,108.880000000,16,28,1,1,103.000000000,109.000000000,3,100,1,1,XOM
2025-01-03T10:33:25.817967394Z,2025-01-03T10:33:25.817801018Z,10,2,17709,A,A,1,107.870000000,16,130,166376,4960378,107.600000000,107.840000000,50,400,1,2,107.530000000,107.870000000,15,258,1,2,107.520000000,107.940000000,100,100,1,1,107.050000000,107.950000000,247,10,1,1,107.000000000,108.000000000,1,50,1,1,106.240000000,108.300000000,28,50,1,1,106.000000000,108.550000000,15,50,2,1,105.870000000,108.800000000,141,50,1,1,103.180000000,108.880000000,16,28,1,1,103.000000000,109.000000000,3,100,1,1,XOM
2025-01-03T10:33:25.891674143Z,2025-01-03T10:33:25.891507772Z,10,2,10888,C,A,1,421.220000000,14,130,166371,4960393,420.580000000,421.110000000,10,200,1,1,420.530000000,421.460000000,200,39,1,1,420.520000000,421.490000000,1,6,1,1,420.400000000,421.570000000,858,40,1,1,420.380000000,421.600000000,100,510,1,2,420.100000000,421.700000000,100,359,1,1,420.000000000,421.800000000,834,7,8,1,419.730000000,422.100000000,3,7,1,1,419.650000000,422.500000000,39,200,1,1,418.650000000,423.500000000,1,600,1,2,MSFT
2025-01-03T10:33:25.891743760Z,2025-01-03T10:33:25.891577402Z,10,2,10888,A,A,1,421.170000000,14,130,166358,4960394,420.580000000,421.110000000,10,200,1,1,420.530000000,421.170000000,200,14,1,1,420.520000000,421.460000000,1,39,1,1,420.400000000,421.490000000,858,6,1,1,420.380000000,421.570000000,100,40,1,1,420.100000000,421.600000000,100,510,1,2,420.000000000,421.700000000,834,359,8,1,419.730000000,421.800000000,3,7,1,1,419.650000000,422.100000000,39,7,1,1,418.650000000,422.500000000,1,200,1,1,MSFT
2025-01-03T10:33:26.017287905Z,2025-01-03T10:33:26.017121960Z,10,2,10888,C,B,1,420.530000000,200,130,165945,4960420,420.580000000,421.110000000,10,200,1,1,420.520000000,421.170000000,1,14,1,1,420.400000000,421.460000000,858,39,1,1,420.380000000,421.490000000,100,6,1,1,420.100000000,421.570000000,100,40,1,1,420.000000000,421.600000000,834,510,8,2,419.730000000,421.700000000,3,359,1,1,419.650000000,421.800000000,39,7,1,1,418.650000000,422.100000000,1,7,1,1,418.500000000,422.500000000,1,200,1,1,MSFT
2025-01-03T10:33:26.017301651Z,2025-01-03T10:33:26.017135385Z,10,2,10888,A,B,2,420.500000000,200,130,166266,4960421,420.580000000,421.110000000,10,200,1,1,420.520000000,421.170000000,1,14,1,1,420.500000000,421.460000000,200,39,1,1,420.400000000,421.490000000,858,6,1,1,420.380000000,421.570000000,100,40,1,1,420.100000000,421.600000000,100,510,1,2,420.000000000,421.700000000,834,359,8,1,419.730000000,421.800000000,3,7,1,1,419.650000000,422.100000000,39,7,1,1,418.650000000,422.500000000,1,200,1,1,MSFT
2025-01-03T10:33:26.168682228Z,2025-01-03T10:33:26.168516240Z,10,2,16244,C,A,2,383.460000000,20,130,165988,4960505,382.990000000,383.250000000,30,47,1,1,382.920000000,383.420000000,22,140,1,1,382.900000000,383.600000000,50,1000,1,2,382.880000000,383.720000000,100,7085,1,8,382.840000000,383.740000000,300,37,1,1,382.820000000,383.800000000,1,10,1,1,382.810000000,383.880000000,20,4,2,1,382.700000000,384.000000000,50,1300,1,4,382.400000000,384.260000000,500,15,1,1,382.230000000,384.400000000,25,1000,1,2,TSLA
2025-01-03T10:33:26.168793911Z,2025-01-03T10:33:26.168627569Z,10,2,16244,A,A,1,383.420000000,21,130,166342,4960506,382.990000000,383.250000000,30,47,1,1,382.920000000,383.420000000,22,161,1,2,382.900000000,383.600000000,50,1000,1,2,382.880000000,383.720000000,100,7085,1,8,382.840000000,383.740000000,300,37,1,1,382.820000000,383.800000000,1,10,1,1,382.810000000,383.880000000,20,4,2,1,382.700000000,384.000000000,50,1300,1,4,382.400000000,384.260000000,500,15,1,1,382.230000000,384.400000000,25,1000,1,2,TSLA
2025-01-03T10:33:26.177235334Z,2025-01-03T10:33:26.177069508Z,10,2,16244,C,A,1,383.420000000,21,130,165826,4960517,382.990000000,383.250000000,30,47,1,1,382.920000000,383.420000000,22,140,1,1,382.900000000,383.600000000,50,1000,1,2,382.880000000,383.720000000,100,7085,1,8,382.840000000,383.740000000,300,37,1,1,382.820000000,383.800000000,1,10,1,1,382.810000000,383.880000000,20,4,2,1,382.700000000,384.000000000,50,1300,1,4,382.400000000,384.260000000,500,15,1,1,382.230000000,384.400000000,25,1000,1,2,TSLA
2025-01-03T10:33:26.281795026Z,2025-01-03T10:33:26.281629109Z,10,2,16244,C,B,1,382.920000000,22,130,165917,4960584,382.990000000,383.250000000,30,47,1,1,382.900000000,383.420000000,50,140,1,1,382.880000000,383.600000000,100,1000,1,2,382.840000000,383.720000000,300,7085,1,8,382.820000000,383.740000000,1,37,1,1,382.810000000,383.800000000,20,10,2,1,382.700000000,383.880000000,50,4,1,1,382.400000000,384.000000000,500,1300,1,4,382.230000000,384.260000000,25,15,1,1,382.100000000,384.400000000,10,1000,1,2,TSLA
2025-01-03T10:33:26.281878503Z,2025-01-03T10:33:26.281712242Z,10,2,16244,A,B,1,382.930000000,22,130,166261,4960585,382.990000000,383.250000000,30,47,1,1,382.930000000,383.420000000,22,140,1,1,382.900000000,383.600000000,50,1000,1,2,382.880000000,383.720000000,100,7085,1,8,382.840000000,383.740000000,300,37,1,1,382.820000000,383.800000000,1,10,1,1,382.810000000,383.880000000,20,4,2,1,382.700000000,384.000000000,50,1300,1,4,382.400000000,384.260000000,500,15,1,1,382.230000000,384.400000000,25,1000,1,2,TSLA
2025-01-03T10:33:26.444123103Z,2025-01-03T10:33:26.443954438Z,10,2,11667,C,B,0,139.150000000,100,128,168665,4960648,139.150000000,139.200000000,9312,100,1,1,139.130000000,139.210000000,2100,400,1,1,139.120000000,139.220000000,30,110,1,2,139.110000000,139.230000000,1,1977,1,2,139.100000000,139.250000000,10,1,1,1,139.090000000,139.270000000,57,37,1,2,139.070000000,139.300000000,100,507,1,4,139.060000000,139.320000000,400,39,1,1,139.030000000,139.330000000,126,503,2,2,139.010000000,139.360000000,100,4,1,2,NVDA
2025-01-03T10:33:26.647017179Z,2025-01-03T10:33:26.646850879Z,10,2,11667,A,B,6,139.070000000,400,130,166300,4960800,139.150000000,139.200000000,9312,100,1,1,139.130000000,139.210000000,2100,400,1,1,139.120000000,139.220000000,30,110,1,2,139.110000000,139.230000000,1,1977,1,2,139.100000000,139.250000000,10,1,1,1,139.090000000,139.270000000,57,37,1,2,139.070000000,139.300000000,500,507,2,4,139.030000000,139.320000000,126,39,2,1,139.010000000,139.330000000,100,503,1,2,139.000000000,139.360000000,910,4,5,2,NVDA
2025-01-03T10:33:26.699535159Z,2025-01-03T10:33:26.699368827Z,10,2,11667,A,B,0,139.150000000,100,130,166332,4960820,139.150000000,139.200000000,9412,100,2,1,139.130000000,139.210000000,2100,400,1,1,139.120000000,139.220000000,30,110,1,2,139.110000000,139.230000000,1,1977,1,2,139.100000000,139.250000000,10,1,1,1,139.090000000,139.270000000,57,37,1,2,139.070000000,139.300000000,500,507,2,4,139.030000000,139.320000000,126,39,2,1,139.010000000,139.330000000,100,503,1,2,139.000000000,139.360000000,910,4,5,2,NVDA
2025-01-03T10:33:27.005977955Z,2025-01-03T10:33:27.005811810Z,10,2,11667,A,A,2,139.220000000,200,130,166145,4960975,139.150000000,139.200000000,9412,100,2,1,139.130000000,139.210000000,2100,400,1,1,139.120000000,139.220000000,30,310,1,3,139.110000000,139.230000000,1,1977,1,2,139.100000000,139.250000000,10,1,1,1,139.090000000,139.270000000,57,37,1,2,139.070000000,139.300000000,500,507,2,4,139.030000000,139.320000000,126,39,2,1,139.010000000,139.330000000,100,503,1,2,139.000000000,139.360000000,910,4,5,2,NVDA
2025-01-03T10:33:27.006038884Z,2025-01-03T10:33:27.005872585Z,10,2,11667,C,B,0,139.150000000,100,130,166299,4960976,139.150000000,139.200000000,9312,100,1,1,139.130000000,139.210000000,2100,400,1,1,139.120000000,139.220000000,30,310,1,3,139.110000000,139.230000000,1,1977,1,2,139.100000000,139.250000000,10,1,1,1,139.090000000,139.270000000,57,37,1,2,139.070000000,139.300000000,500,507,2,4,139.030000000,139.320000000,126,39,2,1,139.010000000,139.330000000,100,503,1,2,139.000000000,139.360000000,910,4,5,2,NVDA
2025-01-03T10:33:27.066532701Z,2025-01-03T10:33:27.066366345Z,10,2,11667,C,B,6,139.070000000,400,130,166356,4961008,139.150000000,139.200000000,9312,100,1,1,139.130000000,139.210000000,2100,400,1,1,139.120000000,139.220000000,30,310,1,3,139.110000000,139.230000000,1,1977,1,2,139.100000000,139.250000000,10,1,1,1,139.090000000,139.270000000,57,37,1,2,139.070000000,139.300000000,100,507,1,4,139.030000000,139.320000000,126,39,2,1,139.010000000,139.330000000,100,503,1,2,139.000000000,139.360000000,910,4,5,2,NVDA
2025-01-03T10:33:27.066544458Z,2025-01-03T10:33:27.066378002Z,10,2,11667,A,B,7,139.060000000,400,130,166456,4961009,139.150000000,139.200000000,9312,100,1,1,139.130000000,139.210000000,2100,400,1,1,139.120000000,139.220000000,30,310,1,3,139.110000000,139.230000000,1,1977,1,2,139.100000000,139.250000000,10,1,1,1,139.090000000,139.270000000,57,37,1,2,139.070000000,139.300000000,100,507,1,4,139.060000000,139.320000000,400,39,1,1,139.030000000,139.330000000,126,503,2,2,139.010000000,139.360000000,100,4,1,2,NVDA
2025-01-03T10:33:27.140089879Z,2025-01-03T10:33:27.139923605Z,10,2,11667,A,B,6,139.070000000,400,130,166274,4961030,139.150000000,139.200000000,9312,100,1,1,139.130000000,139.210000000,2100,400,1,1,139.120000000,139.220000000,30,310,1,3,139.110000000,139.230000000,1,1977,1,2,139.100000000,139.250000000,10,1,1,1,139.090000000,139.270000000,57,37,1,2,139.070000000,139.300000000,500,507,2,4,139.030000000,139.320000000,126,39,2,1,139.010000000,139.330000000,100,503,1,2,139.000000000,139.360000000,910,4,5,2,NVDA
2025-01-03T10:33:27.230102232Z,2025-01-03T10:33:27.229935942Z,10,2,11667,A,B,6,139.080000000,400,130,166290,4961088,139.150000000,139.200000000,9312,100,1,1,139.130000000,139.210000000,2100,400,1,1,139.120000000,139.220000000,30,310,1,3,139.110000000,139.230000000,1,1977,1,2,139.100000000,139.250000000,10,1,1,1,139.090000000,139.270000000,57,37,1,2,139.080000000,139.300000000,400,507,1,4,139.070000000,139.320000000,100,39,1,1,139.030000000,139.330000000,126,503,2,2,139.010000000,139.360000000,100,4,1,2,NVDA
2025-01-03T10:33:28.064177055Z,2025-01-03T10:33:28.064010543Z,10,2,10888,A,B,0,420.660000000,200,130,166512,4961706,420.660000000,421.110000000,200,200,1,1,420.580000000,421.170000000,10,14,1,1,420.520000000,421.460000000,1,39,1,1,420.400000000,421.490000000,858,6,1,1,420.380000000,421.570000000,100,40,1,1,420.100000000,421.600000000,100,510,1,2,420.000000000,421.700000000,834,359,8,1,419.730000000,421.800000000,3,7,1,1,419.650000000,422.100000000,39,7,1,1,418.650000000,422.500000000,1,200,1,1,MSFT
2025-01-03T10:33:29.047905068Z,2025-01-03T10:33:29.047738963Z,10,2,11667,C,B,6,139.080000000,400,130,166105,4962267,139.150000000,139.200000000,9312,100,1,1,139.130000000,139.210000000,2100,400,1,1,139.120000000,139.220000000,30,310,1,3,139.110000000,139.230000000,1,1977,1,2,139.100000000,139.250000000,10,1,1,1,139.090000000,139.270000000,57,37,1,2,139.070000000,139.300000000,100,507,1,4,139.030000000,139.320000000,126,39,2,1,139.010000000,139.330000000,100,503,1,2,139.000000000,139.360000000,910,4,5,2,NVDA
2025-01-03T10:33:29.047918982Z,2025-01-03T10:33:29.047752387Z,10,2,11667,A,B,6,139.070000000,400,130,166595,4962268,139.150000000,139.200000000,9312,100,1,1,139.130000000,139.210000000,2100,400,1,1,139.120000000,139.220000000,30,310,1,3,139.110000000,139.230000000,1,1977,1,2,139.100000000,139.250000000,10,1,1,1,139.090000000,139.270000000,57,37,1,2,139.070000000,139.300000000,500,507,2,4,139.030000000,139.320000000,126,39,2,1,139.010000000,139.330000000,100,503,1,2,139.000000000,139.360000000,910,4,5,2,NVDA
2025-01-03T10:33:29.100776621Z,2025-01-03T10:33:29.100609468Z,10,2,11667,T,A,0,139.150000000,1000,130,167153,4962289,139.150000000,139.200000000,9312,100,1,1,139.130000000,139.210000000,2100,400,1,1,139.120000000,139.220000000,30,310,1,3,139.110000000,139.230000000,1,1977,1,2,139.100000000,139.250000000,10,1,1,1,139.090000000,139.270000000,57,37,1,2,139.070000000,139.300000000,500,507,2,4,139.030000000,139.320000000,126,39,2,1,139.010000000,139.330000000,100,503,1,2,139.000000000,139.360000000,910,4,5,2,NVDA
2025-01-03T10:33:29.100776621Z,2025-01-03T10:33:29.100609468Z,10,2,11667,C,B,0,139.150000000,1000,130,167153,4962289,139.150000000,139.200000000,8312,100,1,1,139.130000000,139.210000000,2100,400,1,1,139.120000000,139.220000000,30,310,1,3,139.110000000,139.230000000,1,1977,1,2,139.100000000,139.250000000,10,1,1,1,139.090000000,139.270000000,57,37,1,2,139.070000000,139.300000000,500,507,2,4,139.030000000,139.320000000,126,39,2,1,139.010000000,139.330000000,100,503,1,2,139.000000000,139.360000000,910,4,5,2,NVDA
2025-01-03T10:33:29.100857907Z,2025-01-03T10:33:29.100691050Z,10,2,11667,C,B,6,139.070000000,400,130,166857,4962294,139.150000000,139.200000000,8312,100,1,1,139.130000000,139.210000000,2100,400,1,1,139.120000000,139.220000000,30,310,1,3,139.110000000,139.230000000,1,1977,1,2,139.100000000,139.250000000,10,1,1,1,139.090000000,139.270000000,57,37,1,2,139.070000000,139.300000000,100,507,1,4,139.030000000,139.320000000,126,39,2,1,139.010000000,139.330000000,100,503,1,2,139.000000000,139.360000000,910,4,5,2,NVDA
2025-01-03T10:33:29.207465927Z,2025-01-03T10:33:29.207299399Z,10,2,11667,A,B,6,139.070000000,400,130,166528,4962364,139.150000000,139.200000000,8312,100,1,1,139.130000000,139.210000000,2100,400,1,1,139.120000000,139.220000000,30,310,1,3,139.110000000,139.230000000,1,1977,1,2,139.100000000,139.250000000,10,1,1,1,139.090000000,139.270000000,57,37,1,2,139.070000000,139.300000000,500,507,2,4,139.030000000,139.320000000,126,39,2,1,139.010000000,139.330000000,100,503,1,2,139.000000000,139.360000000,910,4,5,2,NVDA
2025-01-03T10:33:29.437718749Z,2025-01-03T10:33:29.437552771Z,10,2,16244,C,A,2,383.600000000,500,130,165978,4962451,382.990000000,383.250000000,30,47,1,1,382.930000000,383.420000000,22,140,1,1,382.900000000,383.600000000,50,500,1,1,382.880000000,383.720000000,100,7085,1,8,382.840000000,383.740000000,300,37,1,1,382.820000000,383.800000000,1,10,1,1,382.810000000,383.880000000,20,4,2,1,382.700000000,384.000000000,50,1300,1,4,382.400000000,384.260000000,500,15,1,1,382.230000000,384.400000000,25,1000,1,2,TSLA
2025-01-03T10:33:29.579183516Z,2025-01-03T10:33:29.579017539Z,10,2,10888,C,A,1,421.170000000,14,130,165977,4962587,420.660000000,421.110000000,200,200,1,1,420.580000000,421.460000000,10,39,1,1,420.520000000,421.490000000,1,6,1,1,420.400000000,421.570000000,858,40,1,1,420.380000000,421.600000000,100,510,1,2,420.100000000,421.700000000,100,359,1,1,420.000000000,421.800000000,834,7,8,1,419.730000000,422.100000000,3,7,1,1,419.650000000,422.500000000,39,200,1,1,418.650000000,423.500000000,1,600,1,2,MSFT
2025-01-03T10:33:29.579214579Z,2025-01-03T10:33:29.579048267Z,10,2,10888,A,B,2,420.560000000,14,130,166312,4962588,420.660000000,421.110000000,200,200,1,1,420.580000000,421.460000000,10,39,1,1,420.560000000,421.490000000,14,6,1,1,420.520000000,421.570000000,1,40,1,1,420.400000000,421.600000000,858,510,1,2,420.380000000,421.700000000,100,359,1,1,420.100000000,421.800000000,100,7,1,1,420.000000000,422.100000000,834,7,8,1,419.730000000,422.500000000,3,200,1,1,419.650000000,423.500000000,39,600,1,2,MSFT
2025-01-03T10:33:29.579243395Z,2025-01-03T10:33:29.579077255Z,10,2,10888,A,A,1,421.160000000,14,130,166140,4962589,420.660000000,421.110000000,200,200,1,1,420.580000000,421.160000000,10,14,1,1,420.560000000,421.460000000,14,39,1,1,420.520000000,421.490000000,1,6,1,1,420.400000000,421.570000000,858,40,1,1,420.380000000,421.600000000,100,510,1,2,420.100000000,421.700000000,100,359,1,1,420.000000000,421.800000000,834,7,8,1,419.730000000,422.100000000,3,7,1,1,419.650000000,422.500000000,39,200,1,1,MSFT
2025-01-03T10:33:29.596528718Z,2025-01-03T10:33:29.596361958Z,10,2,11667,A,B,6,139.080000000,400,130,166760,4962602,139.150000000,139.200000000,8312,100,1,1,139.130000000,139.210000000,2100,400,1,1,139.120000000,139.220000000,30,310,1,3,139.110000000,139.230000000,1,1977,1,2,139.100000000,139.250000000,10,1,1,1,139.090000000,139.270000000,57,37,1,2,139.080000000,139.300000000,400,507,1,4,139.070000000,139.320000000,100,39,1,1,139.030000000,139.330000000,126,503,2,2,139.010000000,139.360000000,100,4,1,2,NVDA
2025-01-03T10:33:29.952455052Z,2025-01-03T10:33:29.952288620Z,10,2,16244,A,A,2,383.470000000,19,130,166432,4962837,382.990000000,383.250000000,30,47,1,1,382.930000000,383.420000000,22,140,1,1,382.900000000,383.470000000,50,19,1,1,382.880000000,383.600000000,100,500,1,1,382.840000000,383.720000000,300,7085,1,8,382.820000000,383.740000000,1,37,1,1,382.810000000,383.800000000,20,10,2,1,382.700000000,383.880000000,50,4,1,1,382.400000000,384.000000000,500,1300,1,4,382.230000000,384.260000000,25,15,1,1,TSLA
2025-01-03T10:33:30.390096000Z,2025-01-03T10:33:30.389929842Z,10,2,10888,C,A,5,421.600000000,500,130,166158,4963128,420.660000000,421.110000000,200,200,1,1,420.580000000,421.160000000,10,14,1,1,420.560000000,421.460000000,14,39,1,1,420.520000000,421.490000000,1,6,1,1,420.400000000,421.570000000,858,40,1,1,420.380000000,421.600000000,100,10,1,1,420.100000000,421.700000000,100,359,1,1,420.000000000,421.800000000,834,7,8,1,419.730000000,422.100000000,3,7,1,1,419.650000000,422.500000000,39,200,1,1,MSFT
2025-01-03T10:33:30.400852060Z,2025-01-03T10:33:30.400685601Z,10,2,10888,A,A,5,421.600000000,500,130,166459,4963147,420.660000000,421.110000000,200,200,1,1,420.580000000,421.160000000,10,14,1,1,420.560000000,421.460000000,14,39,1,1,420.520000000,421.490000000,1,6,1,1,420.400000000,421.570000000,858,40,1,1,420.380000000,421.600000000,100,510,1,2,420.100000000,421.700000000,100,359,1,1,420.000000000,421.800000000,834,7,8,1,419.730000000,422.100000000,3,7,1,1,419.650000000,422.500000000,39,200,1,1,MSFT
2025-01-03T10:33:30.502502823Z,2025-01-03T10:33:30.502336073Z,10,2,10888,A,A,0,421.090000000,200,130,166750,4963263,420.660000000,421.090000000,200,200,1,1,420.580000000,421.160000000,10,14,1,1,420.560000000,421.460000000,14,39,1,1,420.520000000,421.490000000,1,6,1,1,420.400000000,421.570000000,858,40,1,1,420.380000000,421.600000000,100,510,1,2,420.100000000,421.700000000,100,359,1,1,420.000000000,421.800000000,834,7,8,1,419.730000000,422.100000000,3,7,1,1,419.650000000,422.500000000,39,200,1,1,MSFT
2025-01-03T10:33:31.253176529Z,2025-01-03T10:33:31.253010083Z,10,2,16244,A,A,3,383.600000000,500,130,166446,4963541,382.990000000,383.250000000,30,47,1,1,382.930000000,383.420000000,22,140,1,1,382.900000000,383.470000000,50,19,1,1,382.880000000,383.600000000,100,1000,1,2,382.840000000,383.720000000,300,7085,1,8,382.820000000,383.740000000,1,37,1,1,382.810000000,383.800000000,20,10,2,1,382.700000000,383.880000000,50,4,1,1,382.400000000,384.000000000,500,1300,1,4,382.230000000,384.260000000,25,15,1,1,TSLA
2025-01-03T10:33:31.700827534Z,2025-01-03T10:33:31.700661186Z,10,2,16244,C,B,6,382.810000000,10,130,166348,4963852,382.990000000,383.250000000,30,47,1,1,382.930000000,383.420000000,22,140,1,1,382.900000000,383.470000000,50,19,1,1,382.880000000,383.600000000,100,1000,1,2,382.840000000,383.720000000,300,7085,1,8,382.820000000,383.740000000,1,37,1,1,382.810000000,383.800000000,10,10,1,1,382.700000000,383.880000000,50,4,1,1,382.400000000,384.000000000,500,1300,1,4,382.230000000,384.260000000,25,15,1,1,TSLA
2025-01-03T10:33:31.701855071Z,2025-01-03T10:33:31.701688680Z,10,2,16244,A,B,8,382.510000000,10,130,166391,4963853,382.990000000,383.250000000,30,47,1,1,382.930000000,383.420000000,22,140,1,1,382.900000000,383.470000000,50,19,1,1,382.880000000,383.600000000,100,1000,1,2,382.840000000,383.720000000,300,7085,1,8,382.820000000,383.740000000,1,37,1,1,382.810000000,383.800000000,10,10,1,1,382.700000000,383.880000000,50,4,1,1,382.510000000,384.000000000,10,1300,1,4,382.400000000,384.260000000,500,15,1,1,TSLA
2025-01-03T10:33:32.225064167Z,2025-01-03T10:33:32.224897607Z,10,2,16244,C,A,2,383.470000000,19,130,166560,4964044,382.990000000,383.250000000,30,47,1,1,382.930000000,383.420000000,22,140,1,1,382.900000000,383.600000000,50,1000,1,2,382.880000000,383.720000000,100,7085,1,8,382.840000000,383.740000000,300,37,1,1,382.820000000,383.800000000,1,10,1,1,382.810000000,383.880000000,10,4,1,1,382.700000000,384.000000000,50,1300,1,4,382.510000000,384.260000000,10,15,1,1,382.400000000,384.400000000,500,1000,1,2,TSLA
2025-01-03T10:33:32.225156900Z,2025-01-03T10:33:32.224990482Z,10,2,16244,A,A,1,383.420000000,19,130,166418,4964045,382.990000000,383.250000000,30,47,1,1,382.930000000,383.420000000,22,159,1,2,382.900000000,383.600000000,50,1000,1,2,382.880000000,383.720000000,100,7085,1,8,382.840000000,383.740000000,300,37,1,1,382.820000000,383.800000000,1,10,1,1,382.810000000,383.880000000,10,4,1,1,382.700000000,384.000000000,50,1300,1,4,382.510000000,384.260000000,10,15,1,1,382.400000000,384.400000000,500,1000,1,2,TSLA
2025-01-03T10:33:32.233663491Z,2025-01-03T10:33:32.233497414Z,10,2,16244,C,A,1,383.420000000,19,130,166077,4964064,382.990000000,383.250000000,30,47,1,1,382.930000000,383.420000000,22,140,1,1,382.900000000,383.600000000,50,1000,1,2,382.880000000,383.720000000,100,7085,1,8,382.840000000,383.740000000,300,37,1,1,382.820000000,383.800000000,1,10,1,1,382.810000000,383.880000000,10,4,1,1,382.700000000,384.000000000,50,1300,1,4,382.510000000,384.260000000,10,15,1,1,382.400000000,384.400000000,500,1000,1,2,TSLA
2025-01-03T10:33:33.833053383Z,2025-01-03T10:33:33.832885990Z,10,2,11667,T,A,0,139.150000000,100,130,167393,4964913,139.150000000,139.200000000,8312,100,1,1,139.130000000,139.210000000,2100,400,1,1,139.120000000,139.220000000,30,310,1,3,139.110000000,139.230000000,1,1977,1,2,139.100000000,139.250000000,10,1,1,1,139.090000000,139.270000000,57,37,1,2,139.080000000,139.300000000,400,507,1,4,139.070000000,139.320000000,100,39,1,1,139.030000000,139.330000000,126,503,2,2,139.010000000,139.360000000,100,4,1,2,NVDA
2025-01-03T10:33:33.833053383Z,2025-01-03T10:33:33.832885990Z,10,2,11667,C,B,0,139.150000000,100,130,167393,4964913,139.150000000,139.200000000,8212,100,1,1,139.130000000,139.210000000,2100,400,1,1,139.120000000,139.220000000,30,310,1,3,139.110000000,139.230000000,1,1977,1,2,139.100000000,139.250000000,10,1,1,1,139.090000000,139.270000000,57,37,1,2,139.080000000,139.300000000,400,507,1,4,139.070000000,139.320000000,100,39,1,1,139.030000000,139.330000000,126,503,2,2,139.010000000,139.360000000,100,4,1,2,NVDA
2025-01-03T10:33:33.833136376Z,2025-01-03T10:33:33.832970028Z,10,2,11667,C,B,6,139.080000000,400,130,166348,4964915,139.150000000,139.200000000,8212,100,1,1,139.130000000,139.210000000,2100,400,1,1,139.120000000,139.220000000,30,310,1,3,139.110000000,139.230000000,1,1977,1,2,139.100000000,139.250000000,10,1,1,1,139.090000000,139.270000000,57,37,1,2,139.070000000,139.300000000,100,507,1,4,139.030000000,139.320000000,126,39,2,1,139.010000000,139.330000000,100,503,1,2,139.000000000,139.360000000,910,4,5,2,NVDA
2025-01-03T10:33:33.942355041Z,2025-01-03T10:33:33.942188385Z,10,2,11667,A,B,6,139.080000000,400,130,166656,4964931,139.150000000,139.200000000,8212,100,1,1,139.130000000,139.210000000,2100,400,1,1,139.120000000,139.220000000,30,310,1,3,139.110000000,139.230000000,1,1977,1,2,139.100000000,139.250000000,10,1,1,1,139.090000000,139.270000000,57,37,1,2,139.080000000,139.300000000,400,507,1,4,139.070000000,139.320000000,100,39,1,1,139.030000000,139.330000000,126,503,2,2,139.010000000,139.360000000,100,4,1,2,NVDA
2025-01-03T10:33:34.000454693Z,2025-01-03T10:33:34.000288223Z,10,2,11667,A,B,1,139.130000000,5,130,166470,4964960,139.150000000,139.200000000,8212,100,1,1,139.130000000,139.210000000,2105,400,2,1,139.120000000,139.220000000,30,310,1,3,139.110000000,139.230000000,1,1977,1,2,139.100000000,139.250000000,10,1,1,1,139.090000000,139.270000000,57,37,1,2,139.080000000,139.300000000,400,507,1,4,139.070000000,139.320000000,100,39,1,1,139.030000000,139.330000000,126,503,2,2,139.010000000,139.360000000,100,4,1,2,NVDA
2025-01-03T10:33:34.001185713Z,2025-01-03T10:33:34.001019489Z,10,2,11667,A,B,0,139.150000000,100,130,166224,4964962,139.150000000,139.200000000,8312,100,2,1,139.130000000,139.210000000,2105,400,2,1,139.120000000,139.220000000,30,310,1,3,139.110000000,139.230000000,1,1977,1,2,139.100000000,139.250000000,10,1,1,1,139.090000000,139.270000000,57,37,1,2,139.080000000,139.300000000,400,507,1,4,139.070000000,139.320000000,100,39,1,1,139.030000000,139.330000000,126,503,2,2,139.010000000,139.360000000,100,4,1,2,NVDA
2025-01-03T10:33:34.001195767Z,2025-01-03T10:33:34.001030027Z,10,2,11667,C,A,1,139.210000000,400,130,165740,4964963,139.150000000,139.200000000,8312,100,2,1,139.130000000,139.220000000,2105,310,2,3,139.120000000,139.230000000,30,1977,1,2,139.110000000,139.250000000,1,1,1,1,139.100000000,139.270000000,10,37,1,2,139.090000000,139.300000000,57,507,1,4,139.080000000,139.320000000,400,39,1,1,139.070000000,139.330000000,100,503,1,2,139.030000000,139.360000000,126,4,2,2,139.010000000,139.370000000,100,75,1,1,NVDA
2025-01-03T10:33:34.001517246Z,2025-01-03T10:33:34.001351282Z,10,2,11667,C,B,1,139.130000000,5,130,165964,4964967,139.150000000,139.200000000,8312,100,2,1,139.130000000,139.220000000,2100,310,1,3,139.120000000,139.230000000,30,1977,1,2,139.110000000,139.250000000,1,1,1,1,139.100000000,139.270000000,10,37,1,2,139.090000000,139.300000000,57,507,1,4,139.080000000,139.320000000,400,39,1,1,139.070000000,139.330000000,100,503,1,2,139.030000000,139.360000000,126,4,2,2,139.010000000,139.370000000,100,75,1,1,NVDA
2025-01-03T10:33:34.071867915Z,2025-01-03T10:33:34.071701664Z,10,2,11667,A,A,2,139.230000000,400,130,166251,4965021,139.150000000,139.200000000,8312,100,2,1,139.130000000,139.220000000,2100,310,1,3,139.120000000,139.230000000,30,2377,1,3,139.110000000,139.250000000,1,1,1,1,139.100000000,139.270000000,10,37,1,2,139.090000000,139.300000000,57,507,1,4,139.080000000,139.320000000,400,39,1,1,139.070000000,139.330000000,100,503,1,2,139.030000000,139.360000000,126,4,2,2,139.010000000,139.370000000,100,75,1,1,NVDA
2025-01-03T10:33:34.116489260Z,2025-01-03T10:33:34.116322234Z,10,2,11667,A,B,2,139.120000000,400,130,167026,4965039,139.150000000,139.200000000,8312,100,2,1,139.130000000,139.220000000,2100,310,1,3,139.120000000,139.230000000,430,2377,2,3,139.110000000,139.250000000,1,1,1,1,139.100000000,139.270000000,10,37,1,2,139.090000000,139.300000000,57,507,1,4,139.070000000,139.320000000,100,39,1,1,139.030000000,139.330000000,126,503,2,2,139.010000000,139.360000000,100,4,1,2,139.000000000,139.370000000,910,75,5,1,NVDA
2025-01-03T10:33:36.458834001Z,2025-01-03T10:33:36.458667769Z,10,2,16244,A,A,1,383.420000000,19,130,166232,4965918,382.990000000,383.250000000,30,47,1,1,382.930000000,383.420000000,22,159,1,2,382.900000000,383.600000000,50,1000,1,2,382.880000000,383.720000000,100,7085,1,8,382.840000000,383.740000000,300,37,1,1,382.820000000,383.800000000,1,10,1,1,382.810000000,383.880000000,10,4,1,1,382.700000000,384.000000000,50,1300,1,4,382.510000000,384.260000000,10,15,1,1,382.400000000,384.400000000,500,1000,1,2,TSLA
2025-01-03T10:33:36.622192914Z,2025-01-03T10:33:36.622026744Z,10,2,11667,C,B,0,139.150000000,100,130,166170,4965956,139.150000000,139.200000000,8212,100,1,1,139.130000000,139.220000000,2100,310,1,3,139.120000000,139.230000000,430,2377,2,3,139.110000000,139.250000000,1,1,1,1,139.100000000,139.270000000,10,37,1,2,139.090000000,139.300000000,57,507,1,4,139.070000000,139.320000000,100,39,1,1,139.030000000,139.330000000,126,503,2,2,139.010000000,139.360000000,100,4,1,2,139.000000000,139.370000000,910,75,5,1,NVDA
2025-01-03T10:33:36.683166182Z,2025-01-03T10:33:36.683000186Z,10,2,11667,C,B,2,139.120000000,400,130,165996,4965999,139.150000000,139.200000000,8212,100,1,1,139.130000000,139.220000000,2100,310,1,3,139.120000000,139.230000000,30,2377,1,3,139.110000000,139.250000000,1,1,1,1,139.100000000,139.270000000,10,37,1,2,139.090000000,139.300000000,57,507,1,4,139.070000000,139.320000000,100,39,1,1,139.030000000,139.330000000,126,503,2,2,139.010000000,139.360000000,100,4,1,2,139.000000000,139.370000000,910,75,5,1,NVDA
2025-01-03T10:33:36.683179695Z,2025-01-03T10:33:36.683013331Z,10,2,11667,A,B,5,139.090000000,400,130,166364,4966000,139.150000000,139.200000000,8212,100,1,1,139.130000000,139.220000000,2100,310,1,3,139.120000000,139.230000000,30,2377,1,3,139.110000000,139.250000000,1,1,1,1,139.100000000,139.270000000,10,37,1,2,139.090000000,139.300000000,457,507,2,4,139.070000000,139.320000000,100,39,1,1,139.030000000,139.330000000,126,503,2,2,139.010000000,139.360000000,100,4,1,2,139.000000000,139.370000000,910,75,5,1,NVDA
2025-01-03T10:33:36.683192513Z,2025-01-03T10:33:36.683026079Z,10,2,11667,C,B,5,139.090000000,400,130,166434,4966001,139.150000000,139.200000000,8212,100,1,1,139.130000000,139.220000000,2100,310,1,3,139.120000000,139.230000000,30,2377,1,3,139.110000000,139.250000000,1,1,1,1,139.100000000,139.270000000,10,37,1,2,139.090000000,139.300000000,57,507,1,4,139.070000000,139.320000000,100,39,1,1,139.030000000,139.330000000,126,503,2,2,139.010000000,139.360000000,100,4,1,2,139.000000000,139.370000000,910,75,5,1,NVDA
2025-01-03T10:33:36.684280839Z,2025-01-03T10:33:36.684114320Z,10,2,11667,A,B,6,139.080000000,400,130,166519,4966002,139.150000000,139.200000000,8212,100,1,1,139.130000000,139.220000000,2100,310,1,3,139.120000000,139.230000000,30,2377,1,3,139.110000000,139.250000000,1,1,1,1,139.100000000,139.270000000,10,37,1,2,139.090000000,139.300000000,57,507,1,4,139.080000000,139.320000000,400,39,1,1,139.070000000,139.330000000,100,503,1,2,139.030000000,139.360000000,126,4,2,2,139.010000000,139.370000000,100,75,1,1,NVDA
2025-01-03T10:33:37.159648858Z,2025-01-03T10:33:37.159481106Z,10,2,11667,T,N,0,139.170000000,1,0,167752,4966204,139.150000000,139.200000000,8212,100,1,1,139.130000000,139.220000000,2100,310,1,3,139.120000000,139.230000000,30,2377,1,3,139.110000000,139.250000000,1,1,1,1,139.100000000,139.270000000,10,37,1,2,139.090000000,139.300000000,57,507,1,4,139.080000000,139.320000000,400,39,1,1,139.070000000,139.330000000,100,503,1,2,139.030000000,139.360000000,126,4,2,2,139.010000000,139.370000000,100,75,1,1,NVDA
2025-01-03T10:33:37.159648858Z,2025-01-03T10:33:37.159481106Z,10,2,11667,A,B,0,139.170000000,149,130,167752,4966205,139.170000000,139.200000000,149,100,1,1,139.150000000,139.220000000,8212,310,1,3,139.130000000,139.230000000,2100,2377,1,3,139.120000000,139.250000000,30,1,1,1,139.110000000,139.270000000,1,37,1,2,139.100000000,139.300000000,10,507,1,4,139.090000000,139.320000000,57,39,1,1,139.080000000,139.330000000,400,503,1,2,139.070000000,139.360000000,100,4,1,2,139.030000000,139.370000000,126,75,2,1,NVDA
2025-01-03T10:33:37.276174666Z,2025-01-03T10:33:37.276008433Z,10,2,11667,A,B,3,139.120000000,400,130,166233,4966257,139.170000000,139.200000000,149,100,1,1,139.150000000,139.220000000,8212,310,1,3,139.130000000,139.230000000,2100,2377,1,3,139.120000000,139.250000000,430,1,2,1,139.110000000,139.270000000,1,37,1,2,139.100000000,139.300000000,10,507,1,4,139.090000000,139.320000000,57,39,1,1,139.070000000,139.330000000,100,503,1,2,139.030000000,139.360000000,126,4,2,2,139.010000000,139.370000000,100,75,1,1,NVDA
2025-01-03T10:33:37.331174845Z,2025-01-03T10:33:37.331008654Z,10,2,11667,C,A,7,139.330000000,500,130,166191,4966288,139.170000000,139.200000000,149,100,1,1,139.150000000,139.220000000,8212,310,1,3,139.130000000,139.230000000,2100,2377,1,3,139.120000000,139.250000000,430,1,2,1,139.110000000,139.270000000,1,37,1,2,139.100000000,139.300000000,10,507,1,4,139.090000000,139.320000000,57,39,1,1,139.070000000,139.330000000,100,3,1,1,139.030000000,139.360000000,126,4,2,2,139.010000000,139.370000000,100,75,1,1,NVDA
2025-01-03T10:33:37.892080933Z,2025-01-03T10:33:37.891913341Z,10,2,11667,T,A,0,139.170000000,1,130,167592,4966399,139.170000000,139.200000000,149,100,1,1,139.150000000,139.220000000,8212,310,1,3,139.130000000,139.230000000,2100,2377,1,3,139.120000000,139.250000000,430,1,2,1,139.110000000,139.270000000,1,37,1,2,139.100000000,139.300000000,10,507,1,4,139.090000000,139.320000000,57,39,1,1,139.070000000,139.330000000,100,3,1,1,139.030000000,139.360000000,126,4,2,2,139.010000000,139.370000000,100,75,1,1,NVDA
2025-01-03T10:33:37.892080933Z,2025-01-03T10:33:37.891913341Z,10,2,11667,C,B,0,139.170000000,1,130,167592,4966399,139.170000000,139.200000000,148,100,1,1,139.150000000,139.220000000,8212,310,1,3,139.130000000,139.230000000,2100,2377,1,3,139.120000000,139.250000000,430,1,2,1,139.110000000,139.270000000,1,37,1,2,139.100000000,139.300000000,10,507,1,4,139.090000000,139.320000000,57,39,1,1,139.070000000,139.330000000,100,3,1,1,139.030000000,139.360000000,126,4,2,2,139.010000000,139.370000000,100,75,1,1,NVDA
2025-01-03T10:33:38.572989224Z,2025-01-03T10:33:38.572821922Z,10,2,11667,T,A,0,139.170000000,50,130,167302,4966600,139.170000000,139.200000000,148,100,1,1,139.150000000,139.220000000,8212,310,1,3,139.130000000,139.230000000,2100,2377,1,3,139.120000000,139.250000000,430,1,2,1,139.110000000,139.270000000,1,37,1,2,139.100000000,139.300000000,10,507,1,4,139.090000000,139.320000000,57,39,1,1,139.070000000,139.330000000,100,3,1,1,139.030000000,139.360000000,126,4,2,2,139.010000000,139.370000000,100,75,1,1,NVDA
2025-01-03T10:33:38.572989224Z,2025-01-03T10:33:38.572821922Z,10,2,11667,C,B,0,139.170000000,50,130,167302,4966600,139.170000000,139.200000000,98,100,1,1,139.150000000,139.220000000,8212,310,1,3,139.130000000,139.230000000,2100,2377,1,3,139.120000000,139.250000000,430,1,2,1,139.110000000,139.270000000,1,37,1,2,139.100000000,139.300000000,10,507,1,4,139.090000000,139.320000000,57,39,1,1,139.070000000,139.330000000,100,3,1,1,139.030000000,139.360000000,126,4,2,2,139.010000000,139.370000000,100,75,1,1,NVDA
2025-01-03T10:33:39.242427325Z,2025-01-03T10:33:39.242261209Z,10,2,10888,A,A,0,421.090000000,5,130,166116,4966760,420.660000000,421.090000000,200,205,1,2,420.580000000,421.160000000,10,14,1,1,420.560000000,421.460000000,14,39,1,1,420.520000000,421.490000000,1,6,1,1,420.400000000,421.570000000,858,40,1,1,420.380000000,421.600000000,100,510,1,2,420.100000000,421.700000000,100,359,1,1,420.000000000,421.800000000,834,7,8,1,419.730000000,422.100000000,3,7,1,1,419.650000000,422.500000000,39,200,1,1,MSFT
2025-01-03T10:33:39.259988617Z,2025-01-03T10:33:39.259822865Z,10,2,10888,C,A,0,421.090000000,5,130,165752,4966763,420.660000000,421.090000000,200,200,1,1,420.580000000,421.160000000,10,14,1,1,420.560000000,421.460000000,14,39,1,1,420.520000000,421.490000000,1,6,1,1,420.400000000,421.570000000,858,40,1,1,420.380000000,421.600000000,100,510,1,2,420.100000000,421.700000000,100,359,1,1,420.000000000,421.800000000,834,7,8,1,419.730000000,422.100000000,3,7,1,1,419.650000000,422.500000000,39,200,1,1,MSFT
2025-01-03T10:33:39.313870666Z,2025-01-03T10:33:39.313704731Z,10,2,10888,C,B,0,420.660000000,200,130,165935,4966765,420.580000000,421.090000000,10,200,1,1,420.560000000,421.160000000,14,14,1,1,420.520000000,421.460000000,1,39,1,1,420.400000000,421.490000000,858,6,1,1,420.380000000,421.570000000,100,40,1,1,420.100000000,421.600000000,100,510,1,2,420.000000000,421.700000000,834,359,8,1,419.730000000,421.800000000,3,7,1,1,419.650000000,422.100000000,39,7,1,1,418.650000000,422.500000000,1,200,1,1,MSFT
2025-01-03T10:33:39.314346028Z,2025-01-03T10:33:39.314179597Z,10,2,10888,C,B,1,420.560000000,14,130,166431,4966766,420.580000000,421.090000000,10,200,1,1,420.520000000,421.160000000,1,14,1,1,420.400000000,421.460000000,858,39,1,1,420.380000000,421.490000000,100,6,1,1,420.100000000,421.570000000,100,40,1,1,420.000000000,421.600000000,834,510,8,2,419.730000000,421.700000000,3,359,1,1,419.650000000,421.800000000,39,7,1,1,418.650000000,422.100000000,1,7,1,1,418.500000000,422.500000000,1,200,1,1,MSFT
2025-01-03T10:33:39.314441355Z,2025-01-03T10:33:39.314275319Z,10,2,10888,A,B,2,420.510000000,15,130,166036,4966767,420.580000000,421.090000000,10,200,1,1,420.520000000,421.160000000,1,14,1,1,420.510000000,421.460000000,15,39,1,1,420.400000000,421.490000000,858,6,1,1,420.380000000,421.570000000,100,40,1,1,420.100000000,421.600000000,100,510,1,2,420.000000000,421.700000000,834,359,8,1,419.730000000,421.800000000,3,7,1,1,419.650000000,422.100000000,39,7,1,1,418.650000000,422.500000000,1,200,1,1,MSFT
2025-01-03T10:33:39.328703827Z,2025-01-03T10:33:39.328537824Z,10,2,10888,A,B,3,420.480000000,200,130,166003,4966776,420.580000000,421.090000000,10,200,1,1,420.520000000,421.160000000,1,14,1,1,420.510000000,421.460000000,15,39,1,1,420.480000000,421.490000000,200,6,1,1,420.400000000,421.570000000,858,40,1,1,420.380000000,421.600000000,100,510,1,2,420.100000000,421.700000000,100,359,1,1,420.000000000,421.800000000,834,7,8,1,419.730000000,422.100000000,3,7,1,1,419.650000000,422.500000000,39,200,1,1,MSFT
2025-01-03T10:33:39.780182938Z,2025-01-03T10:33:39.780017128Z,10,2,16244,C,A,2,383.600000000,500,130,165810,4966884,382.990000000,383.250000000,30,47,1,1,382.930000000,383.420000000,22,159,1,2,382.900000000,383.600000000,50,500,1,1,382.880000000,383.720000000,100,7085,1,8,382.840000000,383.740000000,300,37,1,1,382.820000000,383.800000000,1,10,1,1,382.810000000,383.880000000,10,4,1,1,382.700000000,384.000000000,50,1300,1,4,382.510000000,384.260000000,10,15,1,1,382.400000000,384.400000000,500,1000,1,2,TSLA
2025-01-03T10:33:39.796411172Z,2025-01-03T10:33:39.796245123Z,10,2,11667,C,B,6,139.090000000,57,130,166049,4966886,139.170000000,139.200000000,98,100,1,1,139.150000000,139.220000000,8212,310,1,3,139.130000000,139.230000000,2100,2377,1,3,139.120000000,139.250000000,430,1,2,1,139.110000000,139.270000000,1,37,1,2,139.100000000,139.300000000,10,507,1,4,139.070000000,139.320000000,100,39,1,1,139.030000000,139.330000000,126,3,2,1,139.010000000,139.360000000,100,4,1,2,139.000000000,139.370000000,910,75,5,1,NVDA
2025-01-03T10:33:40.675424808Z,2025-01-03T10:33:40.675258909Z,10,2,16244,C,B,8,382.510000000,10,130,165899,4967376,382.990000000,383.250000000,30,47,1,1,382.930000000,383.420000000,22,159,1,2,382.900000000,383.600000000,50,500,1,1,382.880000000,383.720000000,100,7085,1,8,382.840000000,383.740000000,300,37,1,1,382.820000000,383.800000000,1,10,1,1,382.810000000,383.880000000,10,4,1,1,382.700000000,384.000000000,50,1300,1,4,382.400000000,384.260000000,500,15,1,1,382.230000000,384.400000000,25,1000,1,2,TSLA
2025-01-03T10:33:40.676456651Z,2025-01-03T10:33:40.676289577Z,10,2,16244,A,B,8,382.410000000,10,130,167074,4967377,382.990000000,383.250000000,30,47,1,1,382.930000000,383.420000000,22,159,1,2,382.900000000,383.600000000,50,500,1,1,382.880000000,383.720000000,100,7085,1,8,382.840000000,383.740000000,300,37,1,1,382.820000000,383.800000000,1,10,1,1,382.810000000,383.880000000,10,4,1,1,382.700000000,384.000000000,50,1300,1,4,382.410000000,384.260000000,10,15,1,1,382.400000000,384.400000000,500,1000,1,2,TSLA
2025-01-03T10:33:42.369124686Z,2025-01-03T10:33:42.368958038Z,10,2,10888,A,B,0,420.620000000,200,130,166648,4967813,420.620000000,421.090000000,200,200,1,1,420.580000000,421.160000000,10,14,1,1,420.520000000,421.460000000,1,39,1,1,420.510000000,421.490000000,15,6,1,1,420.400000000,421.570000000,858,40,1,1,420.380000000,421.600000000,100,510,1,2,420.100000000,421.700000000,100,359,1,1,420.000000000,421.800000000,834,7,8,1,419.730000000,422.100000000,3,7,1,1,419.650000000,422.500000000,39,200,1,1,MSFT
2025-01-03T10:33:43.055378033Z,2025-01-03T10:33:43.055211615Z,10,2,16244,A,A,2,383.470000000,19,130,166418,4968161,382.990000000,383.250000000,30,47,1,1,382.930000000,383.420000000,22,159,1,2,382.900000000,383.470000000,50,19,1,1,382.880000000,383.600000000,100,500,1,1,382.840000000,383.720000000,300,7085,1,8,382.820000000,383.740000000,1,37,1,1,382.810000000,383.800000000,10,10,1,1,382.700000000,383.880000000,50,4,1,1,382.410000000,384.000000000,10,1300,1,4,382.400000000,384.260000000,500,15,1,1,TSLA
2025-01-03T10:33:43.055406198Z,2025-01-03T10:33:43.055239675Z,10,2,16244,C,A,1,383.420000000,19,130,166523,4968162,382.990000000,383.250000000,30,47,1,1,382.930000000,383.420000000,22,140,1,1,382.900000000,383.470000000,50,19,1,1,382.880000000,383.600000000,100,500,1,1,382.840000000,383.720000000,300,7085,1,8,382.820000000,383.740000000,1,37,1,1,382.810000000,383.800000000,10,10,1,1,382.700000000,383.880000000,50,4,1,1,382.410000000,384.000000000,10,1300,1,4,382.400000000,384.260000000,500,15,1,1,TSLA
2025-01-03T10:33:45.100657700Z,2025-01-03T10:33:45.100491723Z,10,2,11667,A,B,9,139.000000000,1000,130,165977,4969381,139.170000000,139.200000000,98,100,1,1,139.150000000,139.220000000,8212,310,1,3,139.130000000,139.230000000,2100,2377,1,3,139.120000000,139.250000000,430,1,2,1,139.110000000,139.270000000,1,37,1,2,139.100000000,139.300000000,10,507,1,4,139.070000000,139.320000000,100,39,1,1,139.030000000,139.330000000,126,3,2,1,139.010000000,139.360000000,100,4,1,2,139.000000000,139.370000000,1910,75,6,1,NVDA
2025-01-03T10:33:46.558240945Z,2025-01-03T10:33:46.558074879Z,10,2,16244,C,B,8,382.410000000,10,130,166066,4969862,382.990000000,383.250000000,30,47,1,1,382.930000000,383.420000000,22,140,1,1,382.900000000,383.470000000,50,19,1,1,382.880000000,383.600000000,100,500,1,1,382.840000000,383.720000000,300,7085,1,8,382.820000000,383.740000000,1,37,1,1,382.810000000,383.800000000,10,10,1,1,382.700000000,383.880000000,50,4,1,1,382.400000000,384.000000000,500,1300,1,4,382.230000000,384.260000000,25,15,1,1,TSLA
2025-01-03T10:33:46.559515473Z,2025-01-03T10:33:46.559348740Z,10,2,16244,A,B,9,382.310000000,10,130,166733,4969863,382.990000000,383.250000000,30,47,1,1,382.930000000,383.420000000,22,140,1,1,382.900000000,383.470000000,50,19,1,1,382.880000000,383.600000000,100,500,1,1,382.840000000,383.720000000,300,7085,1,8,382.820000000,383.740000000,1,37,1,1,382.810000000,383.800000000,10,10,1,1,382.700000000,383.880000000,50,4,1,1,382.400000000,384.000000000,500,1300,1,4,382.310000000,384.260000000,10,15,1,1,TSLA
2025-01-03T10:33:46.819488782Z,2025-01-03T10:33:46.819322653Z,10,2,10888,C,B,0,420.620000000,200,130,166129,4970006,420.580000000,421.090000000,10,200,1,1,420.520000000,421.160000000,1,14,1,1,420.510000000,421.460000000,15,39,1,1,420.400000000,421.490000000,858,6,1,1,420.380000000,421.570000000,100,40,1,1,420.100000000,421.600000000,100,510,1,2,420.000000000,421.700000000,834,359,8,1,419.730000000,421.800000000,3,7,1,1,419.650000000,422.100000000,39,7,1,1,418.650000000,422.500000000,1,200,1,1,MSFT
2025-01-03T10:33:46.819500272Z,2025-01-03T10:33:46.819334022Z,10,2,10888,A,B,3,420.470000000,200,130,166250,4970007,420.580000000,421.090000000,10,200,1,1,420.520000000,421.160000000,1,14,1,1,420.510000000,421.460000000,15,39,1,1,420.470000000,421.490000000,200,6,1,1,420.400000000,421.570000000,858,40,1,1,420.380000000,421.600000000,100,510,1,2,420.100000000,421.700000000,100,359,1,1,420.000000000,421.800000000,834,7,8,1,419.730000000,422.100000000,3,7,1,1,419.650000000,422.500000000,39,200,1,1,MSFT
2025-01-03T10:33:46.874752000Z,2025-01-03T10:33:46.874585461Z,10,2,10888,A,B,3,420.480000000,200,130,166539,4970052,420.580000000,421.090000000,10,200,1,1,420.520000000,421.160000000,1,14,1,1,420.510000000,421.460000000,15,39,1,1,420.480000000,421.490000000,200,6,1,1,420.400000000,421.570000000,858,40,1,1,420.380000000,421.600000000,100,510,1,2,420.100000000,421.700000000,100,359,1,1,420.000000000,421.800000000,834,7,8,1,419.730000000,422.100000000,3,7,1,1,419.650000000,422.500000000,39,200,1,1,MSFT
2025-01-03T10:33:47.617853840Z,2025-01-03T10:33:47.617687503Z,10,2,10888,A,A,0,421.070000000,200,130,166337,4970348,420.580000000,421.070000000,10,200,1,1,420.520000000,421.160000000,1,14,1,1,420.510000000,421.460000000,15,39,1,1,420.480000000,421.490000000,200,6,1,1,420.400000000,421.570000000,858,40,1,1,420.380000000,421.600000000,100,510,1,2,420.100000000,421.700000000,100,359,1,1,420.000000000,421.800000000,834,7,8,1,419.730000000,422.100000000,3,7,1,1,419.650000000,422.500000000,39,200,1,1,MSFT
2025-01-03T10:33:48.371273235Z,2025-01-03T10:33:48.371107115Z,10,2,16244,A,A,2,383.460000000,23,130,166120,4970592,382.990000000,383.250000000,30,47,1,1,382.930000000,383.420000000,22,140,1,1,382.900000000,383.460000000,50,23,1,1,382.880000000,383.470000000,100,19,1,1,382.840000000,383.600000000,300,500,1,1,382.820000000,383.720000000,1,7085,1,8,382.810000000,383.740000000,10,37,1,1,382.700000000,383.800000000,50,10,1,1,382.400000000,383.880000000,500,4,1,1,382.310000000,384.000000000,10,1300,1,4,TSLA
2025-01-03T10:33:48.371372042Z,2025-01-03T10:33:48.371205965Z,10,2,16244,C,A,3,383.470000000,19,130,166077,4970594,382.990000000,383.250000000,30,47,1,1,382.930000000,383.420000000,22,140,1,1,382.900000000,383.460000000,50,23,1,1,382.880000000,383.600000000,100,500,1,1,382.840000000,383.720000000,300,7085,1,8,382.820000000,383.740000000,1,37,1,1,382.810000000,383.800000000,10,10,1,1,382.700000000,383.880000000,50,4,1,1,382.400000000,384.000000000,500,1300,1,4,382.310000000,384.260000000,10,15,1,1,TSLA
2025-01-03T10:33:48.914508341Z,2025-01-03T10:33:48.914341098Z,10,2,11667,C,A,2,139.230000000,400,130,167243,4970870,139.170000000,139.200000000,98,100,1,1,139.150000000,139.220000000,8212,310,1,3,139.130000000,139.230000000,2100,1977,1,2,139.120000000,139.250000000,430,1,2,1,139.110000000,139.270000000,1,37,1,2,139.100000000,139.300000000,10,507,1,4,139.070000000,139.320000000,100,39,1,1,139.030000000,139.330000000,126,3,2,1,139.010000000,139.360000000,100,4,1,2,139.000000000,139.370000000,1910,75,6,1,NVDA
2025-01-03T10:33:49.022644716Z,2025-01-03T10:33:49.022478339Z,10,2,11667,A,A,4,139.260000000,400,130,166377,4970914,139.170000000,139.200000000,98,100,1,1,139.150000000,139.220000000,8212,310,1,3,139.130000000,139.230000000,2100,1977,1,2,139.120000000,139.250000000,430,1,2,1,139.110000000,139.260000000,1,400,1,1,139.100000000,139.270000000,10,37,1,2,139.070000000,139.300000000,100,507,1,4,139.030000000,139.320000000,126,39,2,1,139.010000000,139.330000000,100,3,1,1,139.000000000,139.360000000,1910,4,6,2,NVDA
2025-01-03T10:33:49.120027006Z,2025-01-03T10:33:49.119860753Z,10,2,11667,A,A,3,139.250000000,400,130,166253,4970947,139.170000000,139.200000000,98,100,1,1,139.150000000,139.220000000,8212,310,1,3,139.130000000,139.230000000,2100,1977,1,2,139.120000000,139.250000000,430,401,2,2,139.110000000,139.270000000,1,37,1,2,139.100000000,139.300000000,10,507,1,4,139.070000000,139.320000000,100,39,1,1,139.030000000,139.330000000,126,3,2,1,139.010000000,139.360000000,100,4,1,2,139.000000000,139.370000000,1910,75,6,1,NVDA
2025-01-03T10:33:49.364736178Z,2025-01-03T10:33:49.364569616Z,10,2,11667,A,A,3,139.240000000,400,130,166562,4971313,139.170000000,139.200000000,98,100,1,1,139.150000000,139.220000000,8212,310,1,3,139.130000000,139.230000000,2100,1977,1,2,139.120000000,139.240000000,430,400,2,1,139.110000000,139.250000000,1,1,1,1,139.100000000,139.270000000,10,37,1,2,139.070000000,139.300000000,100,507,1,4,139.030000000,139.320000000,126,39,2,1,139.010000000,139.330000000,100,3,1,1,139.000000000,139.360000000,1910,4,6,2,NVDA
2025-01-03T10:33:49.374736252Z,2025-01-03T10:33:49.374569613Z,10,2,11667,A,A,2,139.230000000,400,130,166639,4971314,139.170000000,139.200000000,98,100,1,1,139.150000000,139.220000000,8212,310,1,3,139.130000000,139.230000000,2100,2377,1,3,139.120000000,139.250000000,430,1,2,1,139.110000000,139.270000000,1,37,1,2,139.100000000,139.300000000,10,507,1,4,139.070000000,139.320000000,100,39,1,1,139.030000000,139.330000000,126,3,2,1,139.010000000,139.360000000,100,4,1,2,139.000000000,139.370000000,1910,75,6,1,NVDA
2025-01-03T10:33:49.478749468Z,2025-01-03T10:33:49.478582233Z,10,2,11667,A,A,1,139.220000000,400,130,167235,4971378,139.170000000,139.200000000,98,100,1,1,139.150000000,139.220000000,8212,710,1,4,139.130000000,139.230000000,2100,1977,1,2,139.120000000,139.250000000,430,1,2,1,139.110000000,139.270000000,1,37,1,2,139.100000000,139.300000000,10,507,1,4,139.070000000,139.320000000,100,39,1,1,139.030000000,139.330000000,126,3,2,1,139.010000000,139.360000000,100,4,1,2,139.000000000,139.370000000,1910,75,6,1,NVDA
2025-01-03T10:33:49.516147557Z,2025-01-03T10:33:49.515979399Z,10,2,11667,T,N,0,139.180000000,100,130,168158,4971431,139.170000000,139.200000000,98,100,1,1,139.150000000,139.220000000,8212,710,1,4,139.130000000,139.230000000,2100,1977,1,2,139.120000000,139.250000000,430,1,2,1,139.110000000,139.270000000,1,37,1,2,139.100000000,139.300000000,10,507,1,4,139.070000000,139.320000000,100,39,1,1,139.030000000,139.330000000,126,3,2,1,139.010000000,139.360000000,100,4,1,2,139.000000000,139.370000000,1910,75,6,1,NVDA
2025-01-03T10:33:49.875160425Z,2025-01-03T10:33:49.874993950Z,10,2,10888,A,B,0,420.580000000,200,130,166475,4971574,420.580000000,421.070000000,210,200,2,1,420.520000000,421.160000000,1,14,1,1,420.510000000,421.460000000,15,39,1,1,420.400000000,421.490000000,858,6,1,1,420.380000000,421.570000000,100,40,1,1,420.100000000,421.600000000,100,510,1,2,420.000000000,421.700000000,834,359,8,1,419.730000000,421.800000000,3,7,1,1,419.650000000,422.100000000,39,7,1,1,418.650000000,422.500000000,1,200,1,1,MSFT
2025-01-03T10:33:50.541252811Z,2025-01-03T10:33:50.541085671Z,10,2,10888,A,B,0,420.590000000,200,130,167140,4972236,420.590000000,421.070000000,200,200,1,1,420.580000000,421.160000000,10,14,1,1,420.520000000,421.460000000,1,39,1,1,420.510000000,421.490000000,15,6,1,1,420.400000000,421.570000000,858,40,1,1,420.380000000,421.600000000,100,510,1,2,420.100000000,421.700000000,100,359,1,1,420.000000000,421.800000000,834,7,8,1,419.730000000,422.100000000,3,7,1,1,419.650000000,422.500000000,39,200,1,1,MSFT
2025-01-03T10:33:50.556413356Z,2025-01-03T10:33:50.556247277Z,10,2,38,C,A,1,243.720000000,200,130,166079,4972245,243.520000000,243.660000000,200,100,1,1,243.500000000,243.770000000,6,28,1,1,243.470000000,244.000000000,28,1,1,1,243.190000000,244.140000000,2,79,1,1,243.020000000,244.200000000,79,1000,1,1,243.000000000,244.400000000,1243,50,9,1,242.990000000,244.420000000,1,10,1,1,242.800000000,245.000000000,30,79,1,2,242.750000000,245.190000000,30,83,1,1,242.590000000,245.540000000,5,10,1,1,AAPL
2025-01-03T10:33:50.556426444Z,2025-01-03T10:33:50.556260071Z,10,2,38,A,A,1,243.740000000,200,130,166373,4972246,243.520000000,243.660000000,200,100,1,1,243.500000000,243.740000000,6,200,1,1,243.470000000,243.770000000,28,28,1,1,243.190000000,244.000000000,2,1,1,1,243.020000000,244.140000000,79,79,1,1,243.000000000,244.200000000,1243,1000,9,1,242.990000000,244.400000000,1,50,1,1,242.800000000,244.420000000,30,10,1,1,242.750000000,245.000000000,30,79,1,2,242.590000000,245.190000000,5,83,1,1,AAPL
2025-01-03T10:33:50.556487404Z,2025-01-03T10:33:50.556320656Z,10,2,38,C,A,1,243.740000000,200,130,166748,4972247,243.520000000,243.660000000,200,100,1,1,243.500000000,243.770000000,6,28,1,1,243.470000000,244.000000000,28,1,1,1,243.190000000,244.140000000,2,79,1,1,243.020000000,244.200000000,79,1000,1,1,243.000000000,244.400000000,1243,50,9,1,242.990000000,244.420000000,1,10,1,1,242.800000000,245.000000000,30,79,1,2,242.750000000,245.190000000,30,83,1,1,242.590000000,245.540000000,5,10,1,1,AAPL
2025-01-03T10:33:50.556498456Z,2025-01-03T10:33:50.556332061Z,10,2,38,A,A,1,243.760000000,400,130,166395,4972248,243.520000000,243.660000000,200,100,1,1,243.500000000,243.760000000,6,400,1,1,243.470000000,243.770000000,28,28,1,1,243.190000000,244.000000000,2,1,1,1,243.020000000,244.140000000,79,79,1,1,243.000000000,244.200000000,1243,1000,9,1,242.990000000,244.400000000,1,50,1,1,242.800000000,244.420000000,30,10,1,1,242.750000000,245.000000000,30,79,1,2,242.590000000,245.190000000,5,83,1,1,AAPL
2025-01-03T10:33:50.557067670Z,2025-01-03T10:33:50.556901596Z,10,2,38,C,A,2,243.770000000,28,130,166074,4972249,243.520000000,243.660000000,200,100,1,1,243.500000000,243.760000000,6,400,1,1,243.470000000,244.000000000,28,1,1,1,243.190000000,244.140000000,2,79,1,1,243.020000000,244.200000000,79,1000,1,1,243.000000000,244.400000000,1243,50,9,1,242.990000000,244.420000000,1,10,1,1,242.800000000,245.000000000,30,79,1,2,242.750000000,245.190000000,30,83,1,1,242.590000000,245.540000000,5,10,1,1,AAPL
2025-01-03T10:33:50.557127069Z,2025-01-03T10:33:50.556960509Z,10,2,38,A,A,2,243.830000000,28,130,166560,4972250,243.520000000,243.660000000,200,100,1,1,243.500000000,243.760000000,6,400,1,1,243.470000000,243.830000000,28,28,1,1,243.190000000,244.000000000,2,1,1,1,243.020000000,244.140000000,79,79,1,1,243.000000000,244.200000000,1243,1000,9,1,242.990000000,244.400000000,1,50,1,1,242.800000000,244.420000000,30,10,1,1,242.750000000,245.000000000,30,79,1,2,242.590000000,245.190000000,5,83,1,1,AAPL
2025-01-03T10:33:50.760902634Z,2025-01-03T10:33:50.760736005Z,10,2,38,A,A,1,243.730000000,200,130,166629,4972369,243.520000000,243.660000000,200,100,1,1,243.500000000,243.730000000,6,200,1,1,243.470000000,243.830000000,28,28,1,1,243.190000000,244.000000000,2,1,1,1,243.020000000,244.140000000,79,79,1,1,243.000000000,244.200000000,1243,1000,9,1,242.990000000,244.400000000,1,50,1,1,242.800000000,244.420000000,30,10,1,1,242.750000000,245.000000000,30,79,1,2,242.590000000,245.190000000,5,83,1,1,AAPL
2025-01-03T10:33:51.356895564Z,2025-01-03T10:33:51.356729365Z,10,2,11667,C,A,1,139.220000000,400,130,166199,4972633,139.170000000,139.200000000,98,100,1,1,139.150000000,139.220000000,8212,310,1,3,139.130000000,139.230000000,2100,1977,1,2,139.120000000,139.250000000,430,1,2,1,139.110000000,139.270000000,1,37,1,2,139.100000000,139.300000000,10,507,1,4,139.070000000,139.320000000,100,39,1,1,139.030000000,139.330000000,126,3,2,1,139.010000000,139.360000000,100,4,1,2,139.000000000,139.370000000,1910,75,6,1,NVDA
2025-01-03T10:33:51.356909545Z,2025-01-03T10:33:51.356743022Z,10,2,11667,A,A,2,139.230000000,400,130,166523,4972634,139.170000000,139.200000000,98,100,1,1,139.150000000,139.220000000,8212,310,1,3,139.130000000,139.230000000,2100,2377,1,3,139.120000000,139.250000000,430,1,2,1,139.110000000,139.270000000,1,37,1,2,139.100000000,139.300000000,10,507,1,4,139.070000000,139.320000000,100,39,1,1,139.030000000,139.330000000,126,3,2,1,139.010000000,139.360000000,100,4,1,2,139.000000000,139.370000000,1910,75,6,1,NVDA
2025-01-03T10:33:51.356970527Z,2025-01-03T10:33:51.356804819Z,10,2,11667,C,A,2,139.230000000,400,130,165708,4972635,139.170000000,139.200000000,98,100,1,1,139.150000000,139.220000000,8212,310,1,3,139.130000000,139.230000000,2100,1977,1,2,139.120000000,139.250000000,430,1,2,1,139.110000000,139.270000000,1,37,1,2,139.100000000,139.300000000,10,507,1,4,139.070000000,139.320000000,100,39,1,1,139.030000000,139.330000000,126,3,2,1,139.010000000,139.360000000,100,4,1,2,139.000000000,139.370000000,1910,75,6,1,NVDA
